Workbook

Sheet 사용안내
B2: 거래처 · 명단 중복 정리
B4: 핵심 | C4: 명단을 붙여넣기만 하면 이름·연락처·사업자번호가 겹치는 건을 자동으로 찾아 표시합니다.
B5: 입력 규칙 | C5: 파란색 글씨 칸만 입력하세요. 검은색은 자동 계산입니다.
B6: ① 원본명단 | C6: 가지고 있는 명단을 A~F열에 그대로 붙여넣으세요. 정리 전 원본입니다.
C7: 띄어쓰기나 하이픈이 달라도 같은 것으로 잡아냅니다. (주)·주식회사도 무시합니다.
B8: ② 중복검사 | C8: 어떤 기준으로 몇 건이 겹치는지 한 줄씩 표시됩니다.
B9: ③ 중복목록 | C9: 겹치는 건만 모아서 보여줍니다. 눈으로 확인하고 지울 것을 고르세요.
B10: ④ 정리결과 | C10: 같은 건 중 첫 번째만 남긴 깨끗한 명단입니다. 이걸 복사해서 쓰세요.
B11: ⑤ 요약 | C11: 전체 건수·중복 건수·정리 후 건수를 보여줍니다.
B12: 판정 기준 | C12: 연락처 일치 / 사업자번호 일치 / 이름+주소 일치 중 하나라도 맞으면 중복으로 봅니다.
B13: 주의 | C13: 동명이인이나 같은 건물의 다른 업체가 중복으로 잡힐 수 있습니다. 반드시 눈으로 확인하세요.
B15: ※ 이 파일은 6,000건까지 처리하도록 만들어졌습니다.
B16: ※ 자동으로 지우지 않습니다. 무엇이 겹치는지 보여줄 뿐이니 삭제는 직접 판단하세요.

Sheet 원본명단
A1: 원본명단 (A~F열에 그대로 붙여넣으세요)
A2: 업체명 | B2: 사업자번호 | C2: 대표자 | D2: 연락처 | E2: 주소 | F2: 비고 | G2: 업체명정규화(자동) | H2: 번호정규화(자동) | I2: 연락처정규화(자동) | J2: 주소정규화(자동) | K2: 이름+주소키(자동) | L2: 순번(자동) | M2: 원본행(자동)
A3: (주)가나상사 | B3: 123-45-67890 | C3: 김대표 | D3: 010-1111-2222 | E3: 서울시 강남구 테헤란로 1 | F3: ← 예시 5건 (2·5번이 중복) | G3: =IF($A3="","",UPPER(SUBSTITUTE(SUBSTITUTE(SUBSTITUTE(SUBSTITUTE($A3," ",""),"(주)",""),"주식회사",""),"㈜",""))) -> 가나상사 | H3: =IF($B3="","",SUBSTITUTE(SUBSTITUTE(SUBSTITUTE($B3,"-","")," ",""),".","")) -> 1234567890 | I3: =IF($D3="","",SUBSTITUTE(SUBSTITUTE(SUBSTITUTE($D3,"-","")," ",""),".","")) -> 01011112222 | J3: =IF($E3="","",UPPER(SUBSTITUTE($E3," ",""))) -> 서울시강남구테헤란로1 | K3: =IF($A3="","",$G3&"|"&$J3) -> 가나상사|서울시강남구테헤란로1 | L3: =IF($A3="","",ROW()-2) -> 1 | M3: =IF($A3="","",ROW()) -> 3
A4: 가나상사 | B4: 1234567890 | C4: 김대표 | D4: 01011112222 | E4: 서울시 강남구 테헤란로1 | G4: =IF($A4="","",UPPER(SUBSTITUTE(SUBSTITUTE(SUBSTITUTE(SUBSTITUTE($A4," ",""),"(주)",""),"주식회사",""),"㈜",""))) -> 가나상사 | H4: =IF($B4="","",SUBSTITUTE(SUBSTITUTE(SUBSTITUTE($B4,"-","")," ",""),".","")) -> 1234567890 | I4: =IF($D4="","",SUBSTITUTE(SUBSTITUTE(SUBSTITUTE($D4,"-","")," ",""),".","")) -> 01011112222 | J4: =IF($E4="","",UPPER(SUBSTITUTE($E4," ",""))) -> 서울시강남구테헤란로1 | K4: =IF($A4="","",$G4&"|"&$J4) -> 가나상사|서울시강남구테헤란로1 | L4: =IF($A4="","",ROW()-2) -> 2 | M4: =IF($A4="","",ROW()) -> 4
A5: 다라유통 | B5: 222-22-22222 | C5: 이대표 | D5: 031-222-3333 | E5: 경기도 성남시 분당구 2 | G5: =IF($A5="","",UPPER(SUBSTITUTE(SUBSTITUTE(SUBSTITUTE(SUBSTITUTE($A5," ",""),"(주)",""),"주식회사",""),"㈜",""))) -> 다라유통 | H5: =IF($B5="","",SUBSTITUTE(SUBSTITUTE(SUBSTITUTE($B5,"-","")," ",""),".","")) -> 2222222222 | I5: =IF($D5="","",SUBSTITUTE(SUBSTITUTE(SUBSTITUTE($D5,"-","")," ",""),".","")) -> 0312223333 | J5: =IF($E5="","",UPPER(SUBSTITUTE($E5," ",""))) -> 경기도성남시분당구2 | K5: =IF($A5="","",$G5&"|"&$J5) -> 다라유통|경기도성남시분당구2 | L5: =IF($A5="","",ROW()-2) -> 3 | M5: =IF($A5="","",ROW()) -> 5
A6: 마바물산 주식회사 | B6: 333-33-33333 | C6: 박대표 | D6: 02-333-4444 | E6: 부산시 해운대구 3 | G6: =IF($A6="","",UPPER(SUBSTITUTE(SUBSTITUTE(SUBSTITUTE(SUBSTITUTE($A6," ",""),"(주)",""),"주식회사",""),"㈜",""))) -> 마바물산 | H6: =IF($B6="","",SUBSTITUTE(SUBSTITUTE(SUBSTITUTE($B6,"-","")," ",""),".","")) -> 3333333333 | I6: =IF($D6="","",SUBSTITUTE(SUBSTITUTE(SUBSTITUTE($D6,"-","")," ",""),".","")) -> 023334444 | J6: =IF($E6="","",UPPER(SUBSTITUTE($E6," ",""))) -> 부산시해운대구3 | K6: =IF($A6="","",$G6&"|"&$J6) -> 마바물산|부산시해운대구3 | L6: =IF($A6="","",ROW()-2) -> 4 | M6: =IF($A6="","",ROW()) -> 6
A7: 마바물산 | B7: 333-33-33333 | C7: 박대표 | D7: 051-999-8888 | E7: 부산시 해운대구 3 | G7: =IF($A7="","",UPPER(SUBSTITUTE(SUBSTITUTE(SUBSTITUTE(SUBSTITUTE($A7," ",""),"(주)",""),"주식회사",""),"㈜",""))) -> 마바물산 | H7: =IF($B7="","",SUBSTITUTE(SUBSTITUTE(SUBSTITUTE($B7,"-","")," ",""),".","")) -> 3333333333 | I7: =IF($D7="","",SUBSTITUTE(SUBSTITUTE(SUBSTITUTE($D7,"-","")," ",""),".","")) -> 0519998888 | J7: =IF($E7="","",UPPER(SUBSTITUTE($E7," ",""))) -> 부산시해운대구3 | K7: =IF($A7="","",$G7&"|"&$J7) -> 마바물산|부산시해운대구3 | L7: =IF($A7="","",ROW()-2) -> 5 | M7: =IF($A7="","",ROW()) -> 7
G8: =IF($A8="","",UPPER(SUBSTITUTE(SUBSTITUTE(SUBSTITUTE(SUBSTITUTE($A8," ",""),"(주)",""),"주식회사",""),"㈜",""))) | H8: =IF($B8="","",SUBSTITUTE(SUBSTITUTE(SUBSTITUTE($B8,"-","")," ",""),".","")) | I8: =IF($D8="","",SUBSTITUTE(SUBSTITUTE(SUBSTITUTE($D8,"-","")," ",""),".","")) | J8: =IF($E8="","",UPPER(SUBSTITUTE($E8," ",""))) | K8: =IF($A8="","",$G8&"|"&$J8) | L8: =IF($A8="","",ROW()-2) | M8: =IF($A8="","",ROW())
G9: =IF($A9="","",UPPER(SUBSTITUTE(SUBSTITUTE(SUBSTITUTE(SUBSTITUTE($A9," ",""),"(주)",""),"주식회사",""),"㈜",""))) | H9: =IF($B9="","",SUBSTITUTE(SUBSTITUTE(SUBSTITUTE($B9,"-","")," ",""),".","")) | I9: =IF($D9="","",SUBSTITUTE(SUBSTITUTE(SUBSTITUTE($D9,"-","")," ",""),".","")) | J9: =IF($E9="","",UPPER(SUBSTITUTE($E9," ",""))) | K9: =IF($A9="","",$G9&"|"&$J9) | L9: =IF($A9="","",ROW()-2) | M9: =IF($A9="","",ROW())
G10: =IF($A10="","",UPPER(SUBSTITUTE(SUBSTITUTE(SUBSTITUTE(SUBSTITUTE($A10," ",""),"(주)",""),"주식회사",""),"㈜",""))) | H10: =IF($B10="","",SUBSTITUTE(SUBSTITUTE(SUBSTITUTE($B10,"-","")," ",""),".","")) | I10: =IF($D10="","",SUBSTITUTE(SUBSTITUTE(SUBSTITUTE($D10,"-","")," ",""),".","")) | J10: =IF($E10="","",UPPER(SUBSTITUTE($E10," ",""))) | K10: =IF($A10="","",$G10&"|"&$J10) | L10: =IF($A10="","",ROW()-2) | M10: =IF($A10="","",ROW())
G11: =IF($A11="","",UPPER(SUBSTITUTE(SUBSTITUTE(SUBSTITUTE(SUBSTITUTE($A11," ",""),"(주)",""),"주식회사",""),"㈜",""))) | H11: =IF($B11="","",SUBSTITUTE(SUBSTITUTE(SUBSTITUTE($B11,"-","")," ",""),".","")) | I11: =IF($D11="","",SUBSTITUTE(SUBSTITUTE(SUBSTITUTE($D11,"-","")," ",""),".","")) | J11: =IF($E11="","",UPPER(SUBSTITUTE($E11," ",""))) | K11: =IF($A11="","",$G11&"|"&$J11) | L11: =IF($A11="","",ROW()-2) | M11: =IF($A11="","",ROW())
G12: =IF($A12="","",UPPER(SUBSTITUTE(SUBSTITUTE(SUBSTITUTE(SUBSTITUTE($A12," ",""),"(주)",""),"주식회사",""),"㈜",""))) | H12: =IF($B12="","",SUBSTITUTE(SUBSTITUTE(SUBSTITUTE($B12,"-","")," ",""),".","")) | I12: =IF($D12="","",SUBSTITUTE(SUBSTITUTE(SUBSTITUTE($D12,"-","")," ",""),".","")) | J12: =IF($E12="","",UPPER(SUBSTITUTE($E12," ",""))) | K12: =IF($A12="","",$G12&"|"&$J12) | L12: =IF($A12="","",ROW()-2) | M12: =IF($A12="","",ROW())
G13: =IF($A13="","",UPPER(SUBSTITUTE(SUBSTITUTE(SUBSTITUTE(SUBSTITUTE($A13," ",""),"(주)",""),"주식회사",""),"㈜",""))) | H13: =IF($B13="","",SUBSTITUTE(SUBSTITUTE(SUBSTITUTE($B13,"-","")," ",""),".","")) | I13: =IF($D13="","",SUBSTITUTE(SUBSTITUTE(SUBSTITUTE($D13,"-","")," ",""),".","")) | J13: =IF($E13="","",UPPER(SUBSTITUTE($E13," ",""))) | K13: =IF($A13="","",$G13&"|"&$J13) | L13: =IF($A13="","",ROW()-2) | M13: =IF($A13="","",ROW())
G14: =IF($A14="","",UPPER(SUBSTITUTE(SUBSTITUTE(SUBSTITUTE(SUBSTITUTE($A14," ",""),"(주)",""),"주식회사",""),"㈜",""))) | H14: =IF($B14="","",SUBSTITUTE(SUBSTITUTE(SUBSTITUTE($B14,"-","")," ",""),".","")) | I14: =IF($D14="","",SUBSTITUTE(SUBSTITUTE(SUBSTITUTE($D14,"-","")," ",""),".","")) | J14: =IF($E14="","",UPPER(SUBSTITUTE($E14," ",""))) | K14: =IF($A14="","",$G14&"|"&$J14) | L14: =IF($A14="","",ROW()-2) | M14: =IF($A14="","",ROW())
G15: =IF($A15="","",UPPER(SUBSTITUTE(SUBSTITUTE(SUBSTITUTE(SUBSTITUTE($A15," ",""),"(주)",""),"주식회사",""),"㈜",""))) | H15: =IF($B15="","",SUBSTITUTE(SUBSTITUTE(SUBSTITUTE($B15,"-","")," ",""),".","")) | I15: =IF($D15="","",SUBSTITUTE(SUBSTITUTE(SUBSTITUTE($D15,"-","")," ",""),".","")) | J15: =IF($E15="","",UPPER(SUBSTITUTE($E15," ",""))) | K15: =IF($A15="","",$G15&"|"&$J15) | L15: =IF($A15="","",ROW()-2) | M15: =IF($A15="","",ROW())
G16: =IF($A16="","",UPPER(SUBSTITUTE(SUBSTITUTE(SUBSTITUTE(SUBSTITUTE($A16," ",""),"(주)",""),"주식회사",""),"㈜",""))) | H16: =IF($B16="","",SUBSTITUTE(SUBSTITUTE(SUBSTITUTE($B16,"-","")," ",""),".","")) | I16: =IF($D16="","",SUBSTITUTE(SUBSTITUTE(SUBSTITUTE($D16,"-","")," ",""),".","")) | J16: =IF($E16="","",UPPER(SUBSTITUTE($E16," ",""))) | K16: =IF($A16="","",$G16&"|"&$J16) | L16: =IF($A16="","",ROW()-2) | M16: =IF($A16="","",ROW())
G17: =IF($A17="","",UPPER(SUBSTITUTE(SUBSTITUTE(SUBSTITUTE(SUBSTITUTE($A17," ",""),"(주)",""),"주식회사",""),"㈜",""))) | H17: =IF($B17="","",SUBSTITUTE(SUBSTITUTE(SUBSTITUTE($B17,"-","")," ",""),".","")) | I17: =IF($D17="","",SUBSTITUTE(SUBSTITUTE(SUBSTITUTE($D17,"-","")," ",""),".","")) | J17: =IF($E17="","",UPPER(SUBSTITUTE($E17," ",""))) | K17: =IF($A17="","",$G17&"|"&$J17) | L17: =IF($A17="","",ROW()-2) | M17: =IF($A17="","",ROW())
G18: =IF($A18="","",UPPER(SUBSTITUTE(SUBSTITUTE(SUBSTITUTE(SUBSTITUTE($A18," ",""),"(주)",""),"주식회사",""),"㈜",""))) | H18: =IF($B18="","",SUBSTITUTE(SUBSTITUTE(SUBSTITUTE($B18,"-","")," ",""),".","")) | I18: =IF($D18="","",SUBSTITUTE(SUBSTITUTE(SUBSTITUTE($D18,"-","")," ",""),".","")) | J18: =IF($E18="","",UPPER(SUBSTITUTE($E18," ",""))) | K18: =IF($A18="","",$G18&"|"&$J18) | L18: =IF($A18="","",ROW()-2) | M18: =IF($A18="","",ROW())
G19: =IF($A19="","",UPPER(SUBSTITUTE(SUBSTITUTE(SUBSTITUTE(SUBSTITUTE($A19," ",""),"(주)",""),"주식회사",""),"㈜",""))) | H19: =IF($B19="","",SUBSTITUTE(SUBSTITUTE(SUBSTITUTE($B19,"-","")," ",""),".","")) | I19: =IF($D19="","",SUBSTITUTE(SUBSTITUTE(SUBSTITUTE($D19,"-","")," ",""),".","")) | J19: =IF($E19="","",UPPER(SUBSTITUTE($E19," ",""))) | K19: =IF($A19="","",$G19&"|"&$J19) | L19: =IF($A19="","",ROW()-2) | M19: =IF($A19="","",ROW())
... G6002: =IF($A6002="","",UPPER(SUBSTITUTE(SUBSTITUTE(SUBSTITUTE(SUBSTITUTE($A6002," ",""),"(주)",""),"주식회사",""),"㈜",""))) | H6002: =IF($B6002="","",SUBSTITUTE(SUBSTITUTE(SUBSTITUTE($B6002,"-","")," ",""),".","")) | I6002: =IF($D6002="","",SUBSTITUTE(SUBSTITUTE(SUBSTITUTE($D6002,"-","")," ",""),".","")) | J6002: =IF($E6002="","",UPPER(SUBSTITUTE($E6002," ",""))) | K6002: =IF($A6002="","",$G6002&"|"&$J6002) | L6002: =IF($A6002="","",ROW()-2) | M6002: =IF($A6002="","",ROW())

Sheet 중복검사
A1: 중복검사 (전부 자동)
A2: 판정 기준 | B2: 사업자번호 / 연락처 / (업체명+주소) 중 하나라도 겹치면 중복
A3: 순번 | B3: 업체명 | C3: 사업자번호 | D3: 연락처 | E3: 번호중복 | F3: 연락처중복 | G3: 이름+주소중복 | H3: 중복여부 | I3: 최초 등장 | J3: 처리
A4: =IF(원본명단!$A3="","",1) -> 1 | B4: =IF($A4="","",원본명단!$A3) -> (주)가나상사 | C4: =IF($A4="","",원본명단!$B3) -> 123-45-67890 | D4: =IF($A4="","",원본명단!$D3) -> 010-1111-2222 | E4: =IF($A4="","",IF(원본명단!$H3="",0,COUNTIF(원본명단!$H$3:$H$6002,원본명단!$H3))) -> 2 | F4: =IF($A4="","",IF(원본명단!$I3="",0,COUNTIF(원본명단!$I$3:$I$6002,원본명단!$I3))) -> 2 | G4: =IF($A4="","",IF(원본명단!$K3="",0,COUNTIF(원본명단!$K$3:$K$6002,원본명단!$K3))) -> 2 | H4: =IF($A4="","",IF(MAX($E4,$F4,$G4)>1,"중복","-")) -> 중복 | I4: =IF($A4="","",IF($H4="-","-",IF(AND(IF(원본명단!$H3="",TRUE(),COUNTIF(원본명단!$H$3:$H3,원본명단!$H3)=1),IF(원본명단!$I3="",TRUE(),COUNTIF(원본명단!$I$3:$I3,원본명단!$I3)=1),IF(원본명단!$K3="",TRUE(),COUNTIF(원본명단!$K$3:$K3,원본명단!$K3)=1)),"첫 건","중복 건"))) -> 첫 건 | J4: =IF($A4="","",IF($H4="-","유지",IF($I4="첫 건","유지","확인 필요"))) -> 유지
A5: =IF(원본명단!$A4="","",2) -> 2 | B5: =IF($A5="","",원본명단!$A4) -> 가나상사 | C5: =IF($A5="","",원본명단!$B4) -> 1234567890 | D5: =IF($A5="","",원본명단!$D4) -> 01011112222 | E5: =IF($A5="","",IF(원본명단!$H4="",0,COUNTIF(원본명단!$H$3:$H$6002,원본명단!$H4))) -> 2 | F5: =IF($A5="","",IF(원본명단!$I4="",0,COUNTIF(원본명단!$I$3:$I$6002,원본명단!$I4))) -> 2 | G5: =IF($A5="","",IF(원본명단!$K4="",0,COUNTIF(원본명단!$K$3:$K$6002,원본명단!$K4))) -> 2 | H5: =IF($A5="","",IF(MAX($E5,$F5,$G5)>1,"중복","-")) -> 중복 | I5: =IF($A5="","",IF($H5="-","-",IF(AND(IF(원본명단!$H4="",TRUE(),COUNTIF(원본명단!$H$3:$H4,원본명단!$H4)=1),IF(원본명단!$I4="",TRUE(),COUNTIF(원본명단!$I$3:$I4,원본명단!$I4)=1),IF(원본명단!$K4="",TRUE(),COUNTIF(원본명단!$K$3:$K4,원본명단!$K4)=1)),"첫 건","중복 건"))) -> 중복 건 | J5: =IF($A5="","",IF($H5="-","유지",IF($I5="첫 건","유지","확인 필요"))) -> 확인 필요
A6: =IF(원본명단!$A5="","",3) -> 3 | B6: =IF($A6="","",원본명단!$A5) -> 다라유통 | C6: =IF($A6="","",원본명단!$B5) -> 222-22-22222 | D6: =IF($A6="","",원본명단!$D5) -> 031-222-3333 | E6: =IF($A6="","",IF(원본명단!$H5="",0,COUNTIF(원본명단!$H$3:$H$6002,원본명단!$H5))) -> 1 | F6: =IF($A6="","",IF(원본명단!$I5="",0,COUNTIF(원본명단!$I$3:$I$6002,원본명단!$I5))) -> 1 | G6: =IF($A6="","",IF(원본명단!$K5="",0,COUNTIF(원본명단!$K$3:$K$6002,원본명단!$K5))) -> 1 | H6: =IF($A6="","",IF(MAX($E6,$F6,$G6)>1,"중복","-")) -> - | I6: =IF($A6="","",IF($H6="-","-",IF(AND(IF(원본명단!$H5="",TRUE(),COUNTIF(원본명단!$H$3:$H5,원본명단!$H5)=1),IF(원본명단!$I5="",TRUE(),COUNTIF(원본명단!$I$3:$I5,원본명단!$I5)=1),IF(원본명단!$K5="",TRUE(),COUNTIF(원본명단!$K$3:$K5,원본명단!$K5)=1)),"첫 건","중복 건"))) -> - | J6: =IF($A6="","",IF($H6="-","유지",IF($I6="첫 건","유지","확인 필요"))) -> 유지
A7: =IF(원본명단!$A6="","",4) -> 4 | B7: =IF($A7="","",원본명단!$A6) -> 마바물산 주식회사 | C7: =IF($A7="","",원본명단!$B6) -> 333-33-33333 | D7: =IF($A7="","",원본명단!$D6) -> 02-333-4444 | E7: =IF($A7="","",IF(원본명단!$H6="",0,COUNTIF(원본명단!$H$3:$H$6002,원본명단!$H6))) -> 2 | F7: =IF($A7="","",IF(원본명단!$I6="",0,COUNTIF(원본명단!$I$3:$I$6002,원본명단!$I6))) -> 1 | G7: =IF($A7="","",IF(원본명단!$K6="",0,COUNTIF(원본명단!$K$3:$K$6002,원본명단!$K6))) -> 2 | H7: =IF($A7="","",IF(MAX($E7,$F7,$G7)>1,"중복","-")) -> 중복 | I7: =IF($A7="","",IF($H7="-","-",IF(AND(IF(원본명단!$H6="",TRUE(),COUNTIF(원본명단!$H$3:$H6,원본명단!$H6)=1),IF(원본명단!$I6="",TRUE(),COUNTIF(원본명단!$I$3:$I6,원본명단!$I6)=1),IF(원본명단!$K6="",TRUE(),COUNTIF(원본명단!$K$3:$K6,원본명단!$K6)=1)),"첫 건","중복 건"))) -> 첫 건 | J7: =IF($A7="","",IF($H7="-","유지",IF($I7="첫 건","유지","확인 필요"))) -> 유지
A8: =IF(원본명단!$A7="","",5) -> 5 | B8: =IF($A8="","",원본명단!$A7) -> 마바물산 | C8: =IF($A8="","",원본명단!$B7) -> 333-33-33333 | D8: =IF($A8="","",원본명단!$D7) -> 051-999-8888 | E8: =IF($A8="","",IF(원본명단!$H7="",0,COUNTIF(원본명단!$H$3:$H$6002,원본명단!$H7))) -> 2 | F8: =IF($A8="","",IF(원본명단!$I7="",0,COUNTIF(원본명단!$I$3:$I$6002,원본명단!$I7))) -> 1 | G8: =IF($A8="","",IF(원본명단!$K7="",0,COUNTIF(원본명단!$K$3:$K$6002,원본명단!$K7))) -> 2 | H8: =IF($A8="","",IF(MAX($E8,$F8,$G8)>1,"중복","-")) -> 중복 | I8: =IF($A8="","",IF($H8="-","-",IF(AND(IF(원본명단!$H7="",TRUE(),COUNTIF(원본명단!$H$3:$H7,원본명단!$H7)=1),IF(원본명단!$I7="",TRUE(),COUNTIF(원본명단!$I$3:$I7,원본명단!$I7)=1),IF(원본명단!$K7="",TRUE(),COUNTIF(원본명단!$K$3:$K7,원본명단!$K7)=1)),"첫 건","중복 건"))) -> 중복 건 | J8: =IF($A8="","",IF($H8="-","유지",IF($I8="첫 건","유지","확인 필요"))) -> 확인 필요
A9: =IF(원본명단!$A8="","",6) | B9: =IF($A9="","",원본명단!$A8) | C9: =IF($A9="","",원본명단!$B8) | D9: =IF($A9="","",원본명단!$D8) | E9: =IF($A9="","",IF(원본명단!$H8="",0,COUNTIF(원본명단!$H$3:$H$6002,원본명단!$H8))) | F9: =IF($A9="","",IF(원본명단!$I8="",0,COUNTIF(원본명단!$I$3:$I$6002,원본명단!$I8))) | G9: =IF($A9="","",IF(원본명단!$K8="",0,COUNTIF(원본명단!$K$3:$K$6002,원본명단!$K8))) | H9: =IF($A9="","",IF(MAX($E9,$F9,$G9)>1,"중복","-")) | I9: =IF($A9="","",IF($H9="-","-",IF(AND(IF(원본명단!$H8="",TRUE(),COUNTIF(원본명단!$H$3:$H8,원본명단!$H8)=1),IF(원본명단!$I8="",TRUE(),COUNTIF(원본명단!$I$3:$I8,원본명단!$I8)=1),IF(원본명단!$K8="",TRUE(),COUNTIF(원본명단!$K$3:$K8,원본명단!$K8)=1)),"첫 건","중복 건"))) | J9: =IF($A9="","",IF($H9="-","유지",IF($I9="첫 건","유지","확인 필요")))
A10: =IF(원본명단!$A9="","",7) | B10: =IF($A10="","",원본명단!$A9) | C10: =IF($A10="","",원본명단!$B9) | D10: =IF($A10="","",원본명단!$D9) | E10: =IF($A10="","",IF(원본명단!$H9="",0,COUNTIF(원본명단!$H$3:$H$6002,원본명단!$H9))) | F10: =IF($A10="","",IF(원본명단!$I9="",0,COUNTIF(원본명단!$I$3:$I$6002,원본명단!$I9))) | G10: =IF($A10="","",IF(원본명단!$K9="",0,COUNTIF(원본명단!$K$3:$K$6002,원본명단!$K9))) | H10: =IF($A10="","",IF(MAX($E10,$F10,$G10)>1,"중복","-")) | I10: =IF($A10="","",IF($H10="-","-",IF(AND(IF(원본명단!$H9="",TRUE(),COUNTIF(원본명단!$H$3:$H9,원본명단!$H9)=1),IF(원본명단!$I9="",TRUE(),COUNTIF(원본명단!$I$3:$I9,원본명단!$I9)=1),IF(원본명단!$K9="",TRUE(),COUNTIF(원본명단!$K$3:$K9,원본명단!$K9)=1)),"첫 건","중복 건"))) | J10: =IF($A10="","",IF($H10="-","유지",IF($I10="첫 건","유지","확인 필요")))
A11: =IF(원본명단!$A10="","",8) | B11: =IF($A11="","",원본명단!$A10) | C11: =IF($A11="","",원본명단!$B10) | D11: =IF($A11="","",원본명단!$D10) | E11: =IF($A11="","",IF(원본명단!$H10="",0,COUNTIF(원본명단!$H$3:$H$6002,원본명단!$H10))) | F11: =IF($A11="","",IF(원본명단!$I10="",0,COUNTIF(원본명단!$I$3:$I$6002,원본명단!$I10))) | G11: =IF($A11="","",IF(원본명단!$K10="",0,COUNTIF(원본명단!$K$3:$K$6002,원본명단!$K10))) | H11: =IF($A11="","",IF(MAX($E11,$F11,$G11)>1,"중복","-")) | I11: =IF($A11="","",IF($H11="-","-",IF(AND(IF(원본명단!$H10="",TRUE(),COUNTIF(원본명단!$H$3:$H10,원본명단!$H10)=1),IF(원본명단!$I10="",TRUE(),COUNTIF(원본명단!$I$3:$I10,원본명단!$I10)=1),IF(원본명단!$K10="",TRUE(),COUNTIF(원본명단!$K$3:$K10,원본명단!$K10)=1)),"첫 건","중복 건"))) | J11: =IF($A11="","",IF($H11="-","유지",IF($I11="첫 건","유지","확인 필요")))
A12: =IF(원본명단!$A11="","",9) | B12: =IF($A12="","",원본명단!$A11) | C12: =IF($A12="","",원본명단!$B11) | D12: =IF($A12="","",원본명단!$D11) | E12: =IF($A12="","",IF(원본명단!$H11="",0,COUNTIF(원본명단!$H$3:$H$6002,원본명단!$H11))) | F12: =IF($A12="","",IF(원본명단!$I11="",0,COUNTIF(원본명단!$I$3:$I$6002,원본명단!$I11))) | G12: =IF($A12="","",IF(원본명단!$K11="",0,COUNTIF(원본명단!$K$3:$K$6002,원본명단!$K11))) | H12: =IF($A12="","",IF(MAX($E12,$F12,$G12)>1,"중복","-")) | I12: =IF($A12="","",IF($H12="-","-",IF(AND(IF(원본명단!$H11="",TRUE(),COUNTIF(원본명단!$H$3:$H11,원본명단!$H11)=1),IF(원본명단!$I11="",TRUE(),COUNTIF(원본명단!$I$3:$I11,원본명단!$I11)=1),IF(원본명단!$K11="",TRUE(),COUNTIF(원본명단!$K$3:$K11,원본명단!$K11)=1)),"첫 건","중복 건"))) | J12: =IF($A12="","",IF($H12="-","유지",IF($I12="첫 건","유지","확인 필요")))
A13: =IF(원본명단!$A12="","",10) | B13: =IF($A13="","",원본명단!$A12) | C13: =IF($A13="","",원본명단!$B12) | D13: =IF($A13="","",원본명단!$D12) | E13: =IF($A13="","",IF(원본명단!$H12="",0,COUNTIF(원본명단!$H$3:$H$6002,원본명단!$H12))) | F13: =IF($A13="","",IF(원본명단!$I12="",0,COUNTIF(원본명단!$I$3:$I$6002,원본명단!$I12))) | G13: =IF($A13="","",IF(원본명단!$K12="",0,COUNTIF(원본명단!$K$3:$K$6002,원본명단!$K12))) | H13: =IF($A13="","",IF(MAX($E13,$F13,$G13)>1,"중복","-")) | I13: =IF($A13="","",IF($H13="-","-",IF(AND(IF(원본명단!$H12="",TRUE(),COUNTIF(원본명단!$H$3:$H12,원본명단!$H12)=1),IF(원본명단!$I12="",TRUE(),COUNTIF(원본명단!$I$3:$I12,원본명단!$I12)=1),IF(원본명단!$K12="",TRUE(),COUNTIF(원본명단!$K$3:$K12,원본명단!$K12)=1)),"첫 건","중복 건"))) | J13: =IF($A13="","",IF($H13="-","유지",IF($I13="첫 건","유지","확인 필요")))
A14: =IF(원본명단!$A13="","",11) | B14: =IF($A14="","",원본명단!$A13) | C14: =IF($A14="","",원본명단!$B13) | D14: =IF($A14="","",원본명단!$D13) | E14: =IF($A14="","",IF(원본명단!$H13="",0,COUNTIF(원본명단!$H$3:$H$6002,원본명단!$H13))) | F14: =IF($A14="","",IF(원본명단!$I13="",0,COUNTIF(원본명단!$I$3:$I$6002,원본명단!$I13))) | G14: =IF($A14="","",IF(원본명단!$K13="",0,COUNTIF(원본명단!$K$3:$K$6002,원본명단!$K13))) | H14: =IF($A14="","",IF(MAX($E14,$F14,$G14)>1,"중복","-")) | I14: =IF($A14="","",IF($H14="-","-",IF(AND(IF(원본명단!$H13="",TRUE(),COUNTIF(원본명단!$H$3:$H13,원본명단!$H13)=1),IF(원본명단!$I13="",TRUE(),COUNTIF(원본명단!$I$3:$I13,원본명단!$I13)=1),IF(원본명단!$K13="",TRUE(),COUNTIF(원본명단!$K$3:$K13,원본명단!$K13)=1)),"첫 건","중복 건"))) | J14: =IF($A14="","",IF($H14="-","유지",IF($I14="첫 건","유지","확인 필요")))
A15: =IF(원본명단!$A14="","",12) | B15: =IF($A15="","",원본명단!$A14) | C15: =IF($A15="","",원본명단!$B14) | D15: =IF($A15="","",원본명단!$D14) | E15: =IF($A15="","",IF(원본명단!$H14="",0,COUNTIF(원본명단!$H$3:$H$6002,원본명단!$H14))) | F15: =IF($A15="","",IF(원본명단!$I14="",0,COUNTIF(원본명단!$I$3:$I$6002,원본명단!$I14))) | G15: =IF($A15="","",IF(원본명단!$K14="",0,COUNTIF(원본명단!$K$3:$K$6002,원본명단!$K14))) | H15: =IF($A15="","",IF(MAX($E15,$F15,$G15)>1,"중복","-")) | I15: =IF($A15="","",IF($H15="-","-",IF(AND(IF(원본명단!$H14="",TRUE(),COUNTIF(원본명단!$H$3:$H14,원본명단!$H14)=1),IF(원본명단!$I14="",TRUE(),COUNTIF(원본명단!$I$3:$I14,원본명단!$I14)=1),IF(원본명단!$K14="",TRUE(),COUNTIF(원본명단!$K$3:$K14,원본명단!$K14)=1)),"첫 건","중복 건"))) | J15: =IF($A15="","",IF($H15="-","유지",IF($I15="첫 건","유지","확인 필요")))
A16: =IF(원본명단!$A15="","",13) | B16: =IF($A16="","",원본명단!$A15) | C16: =IF($A16="","",원본명단!$B15) | D16: =IF($A16="","",원본명단!$D15) | E16: =IF($A16="","",IF(원본명단!$H15="",0,COUNTIF(원본명단!$H$3:$H$6002,원본명단!$H15))) | F16: =IF($A16="","",IF(원본명단!$I15="",0,COUNTIF(원본명단!$I$3:$I$6002,원본명단!$I15))) | G16: =IF($A16="","",IF(원본명단!$K15="",0,COUNTIF(원본명단!$K$3:$K$6002,원본명단!$K15))) | H16: =IF($A16="","",IF(MAX($E16,$F16,$G16)>1,"중복","-")) | I16: =IF($A16="","",IF($H16="-","-",IF(AND(IF(원본명단!$H15="",TRUE(),COUNTIF(원본명단!$H$3:$H15,원본명단!$H15)=1),IF(원본명단!$I15="",TRUE(),COUNTIF(원본명단!$I$3:$I15,원본명단!$I15)=1),IF(원본명단!$K15="",TRUE(),COUNTIF(원본명단!$K$3:$K15,원본명단!$K15)=1)),"첫 건","중복 건"))) | J16: =IF($A16="","",IF($H16="-","유지",IF($I16="첫 건","유지","확인 필요")))
A17: =IF(원본명단!$A16="","",14) | B17: =IF($A17="","",원본명단!$A16) | C17: =IF($A17="","",원본명단!$B16) | D17: =IF($A17="","",원본명단!$D16) | E17: =IF($A17="","",IF(원본명단!$H16="",0,COUNTIF(원본명단!$H$3:$H$6002,원본명단!$H16))) | F17: =IF($A17="","",IF(원본명단!$I16="",0,COUNTIF(원본명단!$I$3:$I$6002,원본명단!$I16))) | G17: =IF($A17="","",IF(원본명단!$K16="",0,COUNTIF(원본명단!$K$3:$K$6002,원본명단!$K16))) | H17: =IF($A17="","",IF(MAX($E17,$F17,$G17)>1,"중복","-")) | I17: =IF($A17="","",IF($H17="-","-",IF(AND(IF(원본명단!$H16="",TRUE(),COUNTIF(원본명단!$H$3:$H16,원본명단!$H16)=1),IF(원본명단!$I16="",TRUE(),COUNTIF(원본명단!$I$3:$I16,원본명단!$I16)=1),IF(원본명단!$K16="",TRUE(),COUNTIF(원본명단!$K$3:$K16,원본명단!$K16)=1)),"첫 건","중복 건"))) | J17: =IF($A17="","",IF($H17="-","유지",IF($I17="첫 건","유지","확인 필요")))
A18: =IF(원본명단!$A17="","",15) | B18: =IF($A18="","",원본명단!$A17) | C18: =IF($A18="","",원본명단!$B17) | D18: =IF($A18="","",원본명단!$D17) | E18: =IF($A18="","",IF(원본명단!$H17="",0,COUNTIF(원본명단!$H$3:$H$6002,원본명단!$H17))) | F18: =IF($A18="","",IF(원본명단!$I17="",0,COUNTIF(원본명단!$I$3:$I$6002,원본명단!$I17))) | G18: =IF($A18="","",IF(원본명단!$K17="",0,COUNTIF(원본명단!$K$3:$K$6002,원본명단!$K17))) | H18: =IF($A18="","",IF(MAX($E18,$F18,$G18)>1,"중복","-")) | I18: =IF($A18="","",IF($H18="-","-",IF(AND(IF(원본명단!$H17="",TRUE(),COUNTIF(원본명단!$H$3:$H17,원본명단!$H17)=1),IF(원본명단!$I17="",TRUE(),COUNTIF(원본명단!$I$3:$I17,원본명단!$I17)=1),IF(원본명단!$K17="",TRUE(),COUNTIF(원본명단!$K$3:$K17,원본명단!$K17)=1)),"첫 건","중복 건"))) | J18: =IF($A18="","",IF($H18="-","유지",IF($I18="첫 건","유지","확인 필요")))
A19: =IF(원본명단!$A18="","",16) | B19: =IF($A19="","",원본명단!$A18) | C19: =IF($A19="","",원본명단!$B18) | D19: =IF($A19="","",원본명단!$D18) | E19: =IF($A19="","",IF(원본명단!$H18="",0,COUNTIF(원본명단!$H$3:$H$6002,원본명단!$H18))) | F19: =IF($A19="","",IF(원본명단!$I18="",0,COUNTIF(원본명단!$I$3:$I$6002,원본명단!$I18))) | G19: =IF($A19="","",IF(원본명단!$K18="",0,COUNTIF(원본명단!$K$3:$K$6002,원본명단!$K18))) | H19: =IF($A19="","",IF(MAX($E19,$F19,$G19)>1,"중복","-")) | I19: =IF($A19="","",IF($H19="-","-",IF(AND(IF(원본명단!$H18="",TRUE(),COUNTIF(원본명단!$H$3:$H18,원본명단!$H18)=1),IF(원본명단!$I18="",TRUE(),COUNTIF(원본명단!$I$3:$I18,원본명단!$I18)=1),IF(원본명단!$K18="",TRUE(),COUNTIF(원본명단!$K$3:$K18,원본명단!$K18)=1)),"첫 건","중복 건"))) | J19: =IF($A19="","",IF($H19="-","유지",IF($I19="첫 건","유지","확인 필요")))
A20: =IF(원본명단!$A19="","",17) | B20: =IF($A20="","",원본명단!$A19) | C20: =IF($A20="","",원본명단!$B19) | D20: =IF($A20="","",원본명단!$D19) | E20: =IF($A20="","",IF(원본명단!$H19="",0,COUNTIF(원본명단!$H$3:$H$6002,원본명단!$H19))) | F20: =IF($A20="","",IF(원본명단!$I19="",0,COUNTIF(원본명단!$I$3:$I$6002,원본명단!$I19))) | G20: =IF($A20="","",IF(원본명단!$K19="",0,COUNTIF(원본명단!$K$3:$K$6002,원본명단!$K19))) | H20: =IF($A20="","",IF(MAX($E20,$F20,$G20)>1,"중복","-")) | I20: =IF($A20="","",IF($H20="-","-",IF(AND(IF(원본명단!$H19="",TRUE(),COUNTIF(원본명단!$H$3:$H19,원본명단!$H19)=1),IF(원본명단!$I19="",TRUE(),COUNTIF(원본명단!$I$3:$I19,원본명단!$I19)=1),IF(원본명단!$K19="",TRUE(),COUNTIF(원본명단!$K$3:$K19,원본명단!$K19)=1)),"첫 건","중복 건"))) | J20: =IF($A20="","",IF($H20="-","유지",IF($I20="첫 건","유지","확인 필요")))
A21: =IF(원본명단!$A20="","",18) | B21: =IF($A21="","",원본명단!$A20) | C21: =IF($A21="","",원본명단!$B20) | D21: =IF($A21="","",원본명단!$D20) | E21: =IF($A21="","",IF(원본명단!$H20="",0,COUNTIF(원본명단!$H$3:$H$6002,원본명단!$H20))) | F21: =IF($A21="","",IF(원본명단!$I20="",0,COUNTIF(원본명단!$I$3:$I$6002,원본명단!$I20))) | G21: =IF($A21="","",IF(원본명단!$K20="",0,COUNTIF(원본명단!$K$3:$K$6002,원본명단!$K20))) | H21: =IF($A21="","",IF(MAX($E21,$F21,$G21)>1,"중복","-")) | I21: =IF($A21="","",IF($H21="-","-",IF(AND(IF(원본명단!$H20="",TRUE(),COUNTIF(원본명단!$H$3:$H20,원본명단!$H20)=1),IF(원본명단!$I20="",TRUE(),COUNTIF(원본명단!$I$3:$I20,원본명단!$I20)=1),IF(원본명단!$K20="",TRUE(),COUNTIF(원본명단!$K$3:$K20,원본명단!$K20)=1)),"첫 건","중복 건"))) | J21: =IF($A21="","",IF($H21="-","유지",IF($I21="첫 건","유지","확인 필요")))
A22: =IF(원본명단!$A21="","",19) | B22: =IF($A22="","",원본명단!$A21) | C22: =IF($A22="","",원본명단!$B21) | D22: =IF($A22="","",원본명단!$D21) | E22: =IF($A22="","",IF(원본명단!$H21="",0,COUNTIF(원본명단!$H$3:$H$6002,원본명단!$H21))) | F22: =IF($A22="","",IF(원본명단!$I21="",0,COUNTIF(원본명단!$I$3:$I$6002,원본명단!$I21))) | G22: =IF($A22="","",IF(원본명단!$K21="",0,COUNTIF(원본명단!$K$3:$K$6002,원본명단!$K21))) | H22: =IF($A22="","",IF(MAX($E22,$F22,$G22)>1,"중복","-")) | I22: =IF($A22="","",IF($H22="-","-",IF(AND(IF(원본명단!$H21="",TRUE(),COUNTIF(원본명단!$H$3:$H21,원본명단!$H21)=1),IF(원본명단!$I21="",TRUE(),COUNTIF(원본명단!$I$3:$I21,원본명단!$I21)=1),IF(원본명단!$K21="",TRUE(),COUNTIF(원본명단!$K$3:$K21,원본명단!$K21)=1)),"첫 건","중복 건"))) | J22: =IF($A22="","",IF($H22="-","유지",IF($I22="첫 건","유지","확인 필요")))
A23: =IF(원본명단!$A22="","",20) | B23: =IF($A23="","",원본명단!$A22) | C23: =IF($A23="","",원본명단!$B22) | D23: =IF($A23="","",원본명단!$D22) | E23: =IF($A23="","",IF(원본명단!$H22="",0,COUNTIF(원본명단!$H$3:$H$6002,원본명단!$H22))) | F23: =IF($A23="","",IF(원본명단!$I22="",0,COUNTIF(원본명단!$I$3:$I$6002,원본명단!$I22))) | G23: =IF($A23="","",IF(원본명단!$K22="",0,COUNTIF(원본명단!$K$3:$K$6002,원본명단!$K22))) | H23: =IF($A23="","",IF(MAX($E23,$F23,$G23)>1,"중복","-")) | I23: =IF($A23="","",IF($H23="-","-",IF(AND(IF(원본명단!$H22="",TRUE(),COUNTIF(원본명단!$H$3:$H22,원본명단!$H22)=1),IF(원본명단!$I22="",TRUE(),COUNTIF(원본명단!$I$3:$I22,원본명단!$I22)=1),IF(원본명단!$K22="",TRUE(),COUNTIF(원본명단!$K$3:$K22,원본명단!$K22)=1)),"첫 건","중복 건"))) | J23: =IF($A23="","",IF($H23="-","유지",IF($I23="첫 건","유지","확인 필요")))
A24: =IF(원본명단!$A23="","",21) | B24: =IF($A24="","",원본명단!$A23) | C24: =IF($A24="","",원본명단!$B23) | D24: =IF($A24="","",원본명단!$D23) | E24: =IF($A24="","",IF(원본명단!$H23="",0,COUNTIF(원본명단!$H$3:$H$6002,원본명단!$H23))) | F24: =IF($A24="","",IF(원본명단!$I23="",0,COUNTIF(원본명단!$I$3:$I$6002,원본명단!$I23))) | G24: =IF($A24="","",IF(원본명단!$K23="",0,COUNTIF(원본명단!$K$3:$K$6002,원본명단!$K23))) | H24: =IF($A24="","",IF(MAX($E24,$F24,$G24)>1,"중복","-")) | I24: =IF($A24="","",IF($H24="-","-",IF(AND(IF(원본명단!$H23="",TRUE(),COUNTIF(원본명단!$H$3:$H23,원본명단!$H23)=1),IF(원본명단!$I23="",TRUE(),COUNTIF(원본명단!$I$3:$I23,원본명단!$I23)=1),IF(원본명단!$K23="",TRUE(),COUNTIF(원본명단!$K$3:$K23,원본명단!$K23)=1)),"첫 건","중복 건"))) | J24: =IF($A24="","",IF($H24="-","유지",IF($I24="첫 건","유지","확인 필요")))
A25: =IF(원본명단!$A24="","",22) | B25: =IF($A25="","",원본명단!$A24) | C25: =IF($A25="","",원본명단!$B24) | D25: =IF($A25="","",원본명단!$D24) | E25: =IF($A25="","",IF(원본명단!$H24="",0,COUNTIF(원본명단!$H$3:$H$6002,원본명단!$H24))) | F25: =IF($A25="","",IF(원본명단!$I24="",0,COUNTIF(원본명단!$I$3:$I$6002,원본명단!$I24))) | G25: =IF($A25="","",IF(원본명단!$K24="",0,COUNTIF(원본명단!$K$3:$K$6002,원본명단!$K24))) | H25: =IF($A25="","",IF(MAX($E25,$F25,$G25)>1,"중복","-")) | I25: =IF($A25="","",IF($H25="-","-",IF(AND(IF(원본명단!$H24="",TRUE(),COUNTIF(원본명단!$H$3:$H24,원본명단!$H24)=1),IF(원본명단!$I24="",TRUE(),COUNTIF(원본명단!$I$3:$I24,원본명단!$I24)=1),IF(원본명단!$K24="",TRUE(),COUNTIF(원본명단!$K$3:$K24,원본명단!$K24)=1)),"첫 건","중복 건"))) | J25: =IF($A25="","",IF($H25="-","유지",IF($I25="첫 건","유지","확인 필요")))
A26: =IF(원본명단!$A25="","",23) | B26: =IF($A26="","",원본명단!$A25) | C26: =IF($A26="","",원본명단!$B25) | D26: =IF($A26="","",원본명단!$D25) | E26: =IF($A26="","",IF(원본명단!$H25="",0,COUNTIF(원본명단!$H$3:$H$6002,원본명단!$H25))) | F26: =IF($A26="","",IF(원본명단!$I25="",0,COUNTIF(원본명단!$I$3:$I$6002,원본명단!$I25))) | G26: =IF($A26="","",IF(원본명단!$K25="",0,COUNTIF(원본명단!$K$3:$K$6002,원본명단!$K25))) | H26: =IF($A26="","",IF(MAX($E26,$F26,$G26)>1,"중복","-")) | I26: =IF($A26="","",IF($H26="-","-",IF(AND(IF(원본명단!$H25="",TRUE(),COUNTIF(원본명단!$H$3:$H25,원본명단!$H25)=1),IF(원본명단!$I25="",TRUE(),COUNTIF(원본명단!$I$3:$I25,원본명단!$I25)=1),IF(원본명단!$K25="",TRUE(),COUNTIF(원본명단!$K$3:$K25,원본명단!$K25)=1)),"첫 건","중복 건"))) | J26: =IF($A26="","",IF($H26="-","유지",IF($I26="첫 건","유지","확인 필요")))
A27: =IF(원본명단!$A26="","",24) | B27: =IF($A27="","",원본명단!$A26) | C27: =IF($A27="","",원본명단!$B26) | D27: =IF($A27="","",원본명단!$D26) | E27: =IF($A27="","",IF(원본명단!$H26="",0,COUNTIF(원본명단!$H$3:$H$6002,원본명단!$H26))) | F27: =IF($A27="","",IF(원본명단!$I26="",0,COUNTIF(원본명단!$I$3:$I$6002,원본명단!$I26))) | G27: =IF($A27="","",IF(원본명단!$K26="",0,COUNTIF(원본명단!$K$3:$K$6002,원본명단!$K26))) | H27: =IF($A27="","",IF(MAX($E27,$F27,$G27)>1,"중복","-")) | I27: =IF($A27="","",IF($H27="-","-",IF(AND(IF(원본명단!$H26="",TRUE(),COUNTIF(원본명단!$H$3:$H26,원본명단!$H26)=1),IF(원본명단!$I26="",TRUE(),COUNTIF(원본명단!$I$3:$I26,원본명단!$I26)=1),IF(원본명단!$K26="",TRUE(),COUNTIF(원본명단!$K$3:$K26,원본명단!$K26)=1)),"첫 건","중복 건"))) | J27: =IF($A27="","",IF($H27="-","유지",IF($I27="첫 건","유지","확인 필요")))
A28: =IF(원본명단!$A27="","",25) | B28: =IF($A28="","",원본명단!$A27) | C28: =IF($A28="","",원본명단!$B27) | D28: =IF($A28="","",원본명단!$D27) | E28: =IF($A28="","",IF(원본명단!$H27="",0,COUNTIF(원본명단!$H$3:$H$6002,원본명단!$H27))) | F28: =IF($A28="","",IF(원본명단!$I27="",0,COUNTIF(원본명단!$I$3:$I$6002,원본명단!$I27))) | G28: =IF($A28="","",IF(원본명단!$K27="",0,COUNTIF(원본명단!$K$3:$K$6002,원본명단!$K27))) | H28: =IF($A28="","",IF(MAX($E28,$F28,$G28)>1,"중복","-")) | I28: =IF($A28="","",IF($H28="-","-",IF(AND(IF(원본명단!$H27="",TRUE(),COUNTIF(원본명단!$H$3:$H27,원본명단!$H27)=1),IF(원본명단!$I27="",TRUE(),COUNTIF(원본명단!$I$3:$I27,원본명단!$I27)=1),IF(원본명단!$K27="",TRUE(),COUNTIF(원본명단!$K$3:$K27,원본명단!$K27)=1)),"첫 건","중복 건"))) | J28: =IF($A28="","",IF($H28="-","유지",IF($I28="첫 건","유지","확인 필요")))
A29: =IF(원본명단!$A28="","",26) | B29: =IF($A29="","",원본명단!$A28) | C29: =IF($A29="","",원본명단!$B28) | D29: =IF($A29="","",원본명단!$D28) | E29: =IF($A29="","",IF(원본명단!$H28="",0,COUNTIF(원본명단!$H$3:$H$6002,원본명단!$H28))) | F29: =IF($A29="","",IF(원본명단!$I28="",0,COUNTIF(원본명단!$I$3:$I$6002,원본명단!$I28))) | G29: =IF($A29="","",IF(원본명단!$K28="",0,COUNTIF(원본명단!$K$3:$K$6002,원본명단!$K28))) | H29: =IF($A29="","",IF(MAX($E29,$F29,$G29)>1,"중복","-")) | I29: =IF($A29="","",IF($H29="-","-",IF(AND(IF(원본명단!$H28="",TRUE(),COUNTIF(원본명단!$H$3:$H28,원본명단!$H28)=1),IF(원본명단!$I28="",TRUE(),COUNTIF(원본명단!$I$3:$I28,원본명단!$I28)=1),IF(원본명단!$K28="",TRUE(),COUNTIF(원본명단!$K$3:$K28,원본명단!$K28)=1)),"첫 건","중복 건"))) | J29: =IF($A29="","",IF($H29="-","유지",IF($I29="첫 건","유지","확인 필요")))
A30: =IF(원본명단!$A29="","",27) | B30: =IF($A30="","",원본명단!$A29) | C30: =IF($A30="","",원본명단!$B29) | D30: =IF($A30="","",원본명단!$D29) | E30: =IF($A30="","",IF(원본명단!$H29="",0,COUNTIF(원본명단!$H$3:$H$6002,원본명단!$H29))) | F30: =IF($A30="","",IF(원본명단!$I29="",0,COUNTIF(원본명단!$I$3:$I$6002,원본명단!$I29))) | G30: =IF($A30="","",IF(원본명단!$K29="",0,COUNTIF(원본명단!$K$3:$K$6002,원본명단!$K29))) | H30: =IF($A30="","",IF(MAX($E30,$F30,$G30)>1,"중복","-")) | I30: =IF($A30="","",IF($H30="-","-",IF(AND(IF(원본명단!$H29="",TRUE(),COUNTIF(원본명단!$H$3:$H29,원본명단!$H29)=1),IF(원본명단!$I29="",TRUE(),COUNTIF(원본명단!$I$3:$I29,원본명단!$I29)=1),IF(원본명단!$K29="",TRUE(),COUNTIF(원본명단!$K$3:$K29,원본명단!$K29)=1)),"첫 건","중복 건"))) | J30: =IF($A30="","",IF($H30="-","유지",IF($I30="첫 건","유지","확인 필요")))
A31: =IF(원본명단!$A30="","",28) | B31: =IF($A31="","",원본명단!$A30) | C31: =IF($A31="","",원본명단!$B30) | D31: =IF($A31="","",원본명단!$D30) | E31: =IF($A31="","",IF(원본명단!$H30="",0,COUNTIF(원본명단!$H$3:$H$6002,원본명단!$H30))) | F31: =IF($A31="","",IF(원본명단!$I30="",0,COUNTIF(원본명단!$I$3:$I$6002,원본명단!$I30))) | G31: =IF($A31="","",IF(원본명단!$K30="",0,COUNTIF(원본명단!$K$3:$K$6002,원본명단!$K30))) | H31: =IF($A31="","",IF(MAX($E31,$F31,$G31)>1,"중복","-")) | I31: =IF($A31="","",IF($H31="-","-",IF(AND(IF(원본명단!$H30="",TRUE(),COUNTIF(원본명단!$H$3:$H30,원본명단!$H30)=1),IF(원본명단!$I30="",TRUE(),COUNTIF(원본명단!$I$3:$I30,원본명단!$I30)=1),IF(원본명단!$K30="",TRUE(),COUNTIF(원본명단!$K$3:$K30,원본명단!$K30)=1)),"첫 건","중복 건"))) | J31: =IF($A31="","",IF($H31="-","유지",IF($I31="첫 건","유지","확인 필요")))
A32: =IF(원본명단!$A31="","",29) | B32: =IF($A32="","",원본명단!$A31) | C32: =IF($A32="","",원본명단!$B31) | D32: =IF($A32="","",원본명단!$D31) | E32: =IF($A32="","",IF(원본명단!$H31="",0,COUNTIF(원본명단!$H$3:$H$6002,원본명단!$H31))) | F32: =IF($A32="","",IF(원본명단!$I31="",0,COUNTIF(원본명단!$I$3:$I$6002,원본명단!$I31))) | G32: =IF($A32="","",IF(원본명단!$K31="",0,COUNTIF(원본명단!$K$3:$K$6002,원본명단!$K31))) | H32: =IF($A32="","",IF(MAX($E32,$F32,$G32)>1,"중복","-")) | I32: =IF($A32="","",IF($H32="-","-",IF(AND(IF(원본명단!$H31="",TRUE(),COUNTIF(원본명단!$H$3:$H31,원본명단!$H31)=1),IF(원본명단!$I31="",TRUE(),COUNTIF(원본명단!$I$3:$I31,원본명단!$I31)=1),IF(원본명단!$K31="",TRUE(),COUNTIF(원본명단!$K$3:$K31,원본명단!$K31)=1)),"첫 건","중복 건"))) | J32: =IF($A32="","",IF($H32="-","유지",IF($I32="첫 건","유지","확인 필요")))
A33: =IF(원본명단!$A32="","",30) | B33: =IF($A33="","",원본명단!$A32) | C33: =IF($A33="","",원본명단!$B32) | D33: =IF($A33="","",원본명단!$D32) | E33: =IF($A33="","",IF(원본명단!$H32="",0,COUNTIF(원본명단!$H$3:$H$6002,원본명단!$H32))) | F33: =IF($A33="","",IF(원본명단!$I32="",0,COUNTIF(원본명단!$I$3:$I$6002,원본명단!$I32))) | G33: =IF($A33="","",IF(원본명단!$K32="",0,COUNTIF(원본명단!$K$3:$K$6002,원본명단!$K32))) | H33: =IF($A33="","",IF(MAX($E33,$F33,$G33)>1,"중복","-")) | I33: =IF($A33="","",IF($H33="-","-",IF(AND(IF(원본명단!$H32="",TRUE(),COUNTIF(원본명단!$H$3:$H32,원본명단!$H32)=1),IF(원본명단!$I32="",TRUE(),COUNTIF(원본명단!$I$3:$I32,원본명단!$I32)=1),IF(원본명단!$K32="",TRUE(),COUNTIF(원본명단!$K$3:$K32,원본명단!$K32)=1)),"첫 건","중복 건"))) | J33: =IF($A33="","",IF($H33="-","유지",IF($I33="첫 건","유지","확인 필요")))
A34: =IF(원본명단!$A33="","",31) | B34: =IF($A34="","",원본명단!$A33) | C34: =IF($A34="","",원본명단!$B33) | D34: =IF($A34="","",원본명단!$D33) | E34: =IF($A34="","",IF(원본명단!$H33="",0,COUNTIF(원본명단!$H$3:$H$6002,원본명단!$H33))) | F34: =IF($A34="","",IF(원본명단!$I33="",0,COUNTIF(원본명단!$I$3:$I$6002,원본명단!$I33))) | G34: =IF($A34="","",IF(원본명단!$K33="",0,COUNTIF(원본명단!$K$3:$K$6002,원본명단!$K33))) | H34: =IF($A34="","",IF(MAX($E34,$F34,$G34)>1,"중복","-")) | I34: =IF($A34="","",IF($H34="-","-",IF(AND(IF(원본명단!$H33="",TRUE(),COUNTIF(원본명단!$H$3:$H33,원본명단!$H33)=1),IF(원본명단!$I33="",TRUE(),COUNTIF(원본명단!$I$3:$I33,원본명단!$I33)=1),IF(원본명단!$K33="",TRUE(),COUNTIF(원본명단!$K$3:$K33,원본명단!$K33)=1)),"첫 건","중복 건"))) | J34: =IF($A34="","",IF($H34="-","유지",IF($I34="첫 건","유지","확인 필요")))
A35: =IF(원본명단!$A34="","",32) | B35: =IF($A35="","",원본명단!$A34) | C35: =IF($A35="","",원본명단!$B34) | D35: =IF($A35="","",원본명단!$D34) | E35: =IF($A35="","",IF(원본명단!$H34="",0,COUNTIF(원본명단!$H$3:$H$6002,원본명단!$H34))) | F35: =IF($A35="","",IF(원본명단!$I34="",0,COUNTIF(원본명단!$I$3:$I$6002,원본명단!$I34))) | G35: =IF($A35="","",IF(원본명단!$K34="",0,COUNTIF(원본명단!$K$3:$K$6002,원본명단!$K34))) | H35: =IF($A35="","",IF(MAX($E35,$F35,$G35)>1,"중복","-")) | I35: =IF($A35="","",IF($H35="-","-",IF(AND(IF(원본명단!$H34="",TRUE(),COUNTIF(원본명단!$H$3:$H34,원본명단!$H34)=1),IF(원본명단!$I34="",TRUE(),COUNTIF(원본명단!$I$3:$I34,원본명단!$I34)=1),IF(원본명단!$K34="",TRUE(),COUNTIF(원본명단!$K$3:$K34,원본명단!$K34)=1)),"첫 건","중복 건"))) | J35: =IF($A35="","",IF($H35="-","유지",IF($I35="첫 건","유지","확인 필요")))
A36: =IF(원본명단!$A35="","",33) | B36: =IF($A36="","",원본명단!$A35) | C36: =IF($A36="","",원본명단!$B35) | D36: =IF($A36="","",원본명단!$D35) | E36: =IF($A36="","",IF(원본명단!$H35="",0,COUNTIF(원본명단!$H$3:$H$6002,원본명단!$H35))) | F36: =IF($A36="","",IF(원본명단!$I35="",0,COUNTIF(원본명단!$I$3:$I$6002,원본명단!$I35))) | G36: =IF($A36="","",IF(원본명단!$K35="",0,COUNTIF(원본명단!$K$3:$K$6002,원본명단!$K35))) | H36: =IF($A36="","",IF(MAX($E36,$F36,$G36)>1,"중복","-")) | I36: =IF($A36="","",IF($H36="-","-",IF(AND(IF(원본명단!$H35="",TRUE(),COUNTIF(원본명단!$H$3:$H35,원본명단!$H35)=1),IF(원본명단!$I35="",TRUE(),COUNTIF(원본명단!$I$3:$I35,원본명단!$I35)=1),IF(원본명단!$K35="",TRUE(),COUNTIF(원본명단!$K$3:$K35,원본명단!$K35)=1)),"첫 건","중복 건"))) | J36: =IF($A36="","",IF($H36="-","유지",IF($I36="첫 건","유지","확인 필요")))
A37: =IF(원본명단!$A36="","",34) | B37: =IF($A37="","",원본명단!$A36) | C37: =IF($A37="","",원본명단!$B36) | D37: =IF($A37="","",원본명단!$D36) | E37: =IF($A37="","",IF(원본명단!$H36="",0,COUNTIF(원본명단!$H$3:$H$6002,원본명단!$H36))) | F37: =IF($A37="","",IF(원본명단!$I36="",0,COUNTIF(원본명단!$I$3:$I$6002,원본명단!$I36))) | G37: =IF($A37="","",IF(원본명단!$K36="",0,COUNTIF(원본명단!$K$3:$K$6002,원본명단!$K36))) | H37: =IF($A37="","",IF(MAX($E37,$F37,$G37)>1,"중복","-")) | I37: =IF($A37="","",IF($H37="-","-",IF(AND(IF(원본명단!$H36="",TRUE(),COUNTIF(원본명단!$H$3:$H36,원본명단!$H36)=1),IF(원본명단!$I36="",TRUE(),COUNTIF(원본명단!$I$3:$I36,원본명단!$I36)=1),IF(원본명단!$K36="",TRUE(),COUNTIF(원본명단!$K$3:$K36,원본명단!$K36)=1)),"첫 건","중복 건"))) | J37: =IF($A37="","",IF($H37="-","유지",IF($I37="첫 건","유지","확인 필요")))
A38: =IF(원본명단!$A37="","",35) | B38: =IF($A38="","",원본명단!$A37) | C38: =IF($A38="","",원본명단!$B37) | D38: =IF($A38="","",원본명단!$D37) | E38: =IF($A38="","",IF(원본명단!$H37="",0,COUNTIF(원본명단!$H$3:$H$6002,원본명단!$H37))) | F38: =IF($A38="","",IF(원본명단!$I37="",0,COUNTIF(원본명단!$I$3:$I$6002,원본명단!$I37))) | G38: =IF($A38="","",IF(원본명단!$K37="",0,COUNTIF(원본명단!$K$3:$K$6002,원본명단!$K37))) | H38: =IF($A38="","",IF(MAX($E38,$F38,$G38)>1,"중복","-")) | I38: =IF($A38="","",IF($H38="-","-",IF(AND(IF(원본명단!$H37="",TRUE(),COUNTIF(원본명단!$H$3:$H37,원본명단!$H37)=1),IF(원본명단!$I37="",TRUE(),COUNTIF(원본명단!$I$3:$I37,원본명단!$I37)=1),IF(원본명단!$K37="",TRUE(),COUNTIF(원본명단!$K$3:$K37,원본명단!$K37)=1)),"첫 건","중복 건"))) | J38: =IF($A38="","",IF($H38="-","유지",IF($I38="첫 건","유지","확인 필요")))
A39: =IF(원본명단!$A38="","",36) | B39: =IF($A39="","",원본명단!$A38) | C39: =IF($A39="","",원본명단!$B38) | D39: =IF($A39="","",원본명단!$D38) | E39: =IF($A39="","",IF(원본명단!$H38="",0,COUNTIF(원본명단!$H$3:$H$6002,원본명단!$H38))) | F39: =IF($A39="","",IF(원본명단!$I38="",0,COUNTIF(원본명단!$I$3:$I$6002,원본명단!$I38))) | G39: =IF($A39="","",IF(원본명단!$K38="",0,COUNTIF(원본명단!$K$3:$K$6002,원본명단!$K38))) | H39: =IF($A39="","",IF(MAX($E39,$F39,$G39)>1,"중복","-")) | I39: =IF($A39="","",IF($H39="-","-",IF(AND(IF(원본명단!$H38="",TRUE(),COUNTIF(원본명단!$H$3:$H38,원본명단!$H38)=1),IF(원본명단!$I38="",TRUE(),COUNTIF(원본명단!$I$3:$I38,원본명단!$I38)=1),IF(원본명단!$K38="",TRUE(),COUNTIF(원본명단!$K$3:$K38,원본명단!$K38)=1)),"첫 건","중복 건"))) | J39: =IF($A39="","",IF($H39="-","유지",IF($I39="첫 건","유지","확인 필요")))
A40: =IF(원본명단!$A39="","",37) | B40: =IF($A40="","",원본명단!$A39) | C40: =IF($A40="","",원본명단!$B39) | D40: =IF($A40="","",원본명단!$D39) | E40: =IF($A40="","",IF(원본명단!$H39="",0,COUNTIF(원본명단!$H$3:$H$6002,원본명단!$H39))) | F40: =IF($A40="","",IF(원본명단!$I39="",0,COUNTIF(원본명단!$I$3:$I$6002,원본명단!$I39))) | G40: =IF($A40="","",IF(원본명단!$K39="",0,COUNTIF(원본명단!$K$3:$K$6002,원본명단!$K39))) | H40: =IF($A40="","",IF(MAX($E40,$F40,$G40)>1,"중복","-")) | I40: =IF($A40="","",IF($H40="-","-",IF(AND(IF(원본명단!$H39="",TRUE(),COUNTIF(원본명단!$H$3:$H39,원본명단!$H39)=1),IF(원본명단!$I39="",TRUE(),COUNTIF(원본명단!$I$3:$I39,원본명단!$I39)=1),IF(원본명단!$K39="",TRUE(),COUNTIF(원본명단!$K$3:$K39,원본명단!$K39)=1)),"첫 건","중복 건"))) | J40: =IF($A40="","",IF($H40="-","유지",IF($I40="첫 건","유지","확인 필요")))
...

Sheet 중복목록
A1: 중복목록 (겹치는 건만 모아보기)
A3: 중복 건수 | B3: =COUNTIF(중복검사!$H$4:$H$6003,"중복") -> 4 | D3: ※ 사업자번호 순으로 정렬해서 보면 짝이 눈에 잘 띕니다.
A5: 순번 | B5: 업체명 | C5: 사업자번호 | D5: 연락처 | E5: 주소 | F5: 중복 개수 | G5: 구분 | H5: 처리 | J5: 대상(자동) | K5: 순번(자동) | L5: 키(자동)
A6: =IFERROR(INDEX(중복검사!$A$4:$A$6003,MATCH("R"&1,중복목록!$L$6:$L$6005,0)),"") -> 1 | B6: =IF($A6="","",IFERROR(INDEX(중복검사!$B$4:$B$6003,MATCH("R"&1,중복목록!$L$6:$L$6005,0)),"")) -> (주)가나상사 | C6: =IF($A6="","",IFERROR(INDEX(중복검사!$C$4:$C$6003,MATCH("R"&1,중복목록!$L$6:$L$6005,0)),"")) -> 123-45-67890 | D6: =IF($A6="","",IFERROR(INDEX(중복검사!$D$4:$D$6003,MATCH("R"&1,중복목록!$L$6:$L$6005,0)),"")) -> 010-1111-2222 | E6: =IF($A6="","",IFERROR(IF(INDEX(원본명단!$E$3:$E$6002,MATCH("R"&1,중복목록!$L$6:$L$6005,0))="","",INDEX(원본명단!$E$3:$E$6002,MATCH("R"&1,중복목록!$L$6:$L$6005,0))),"")) -> 서울시 강남구 테헤란로 1 | F6: =IF($A6="","",IFERROR(MAX(INDEX(중복검사!$E$4:$E$6003,MATCH("R"&1,중복목록!$L$6:$L$6005,0)),INDEX(중복검사!$F$4:$F$6003,MATCH("R"&1,중복목록!$L$6:$L$6005,0)),INDEX(중복검사!$G$4:$G$6003,MATCH("R"&1,중복목록!$L$6:$L$6005,0))),"")) -> 2 | G6: =IF($A6="","",IFERROR(INDEX(중복검사!$I$4:$I$6003,MATCH("R"&1,중복목록!$L$6:$L$6005,0)),"")) -> 첫 건 | H6: =IF($A6="","",IFERROR(INDEX(중복검사!$J$4:$J$6003,MATCH("R"&1,중복목록!$L$6:$L$6005,0)),"")) -> 유지 | J6: =IF(중복검사!$A4="",FALSE(),중복검사!$H4="중복") -> TRUE | K6: =IF($J6=FALSE(),"",COUNTIF($J$6:$J6,TRUE())) -> 1 | L6: =IF($K6="","","R"&$K6) -> R1
A7: =IFERROR(INDEX(중복검사!$A$4:$A$6003,MATCH("R"&2,중복목록!$L$6:$L$6005,0)),"") -> 2 | B7: =IF($A7="","",IFERROR(INDEX(중복검사!$B$4:$B$6003,MATCH("R"&2,중복목록!$L$6:$L$6005,0)),"")) -> 가나상사 | C7: =IF($A7="","",IFERROR(INDEX(중복검사!$C$4:$C$6003,MATCH("R"&2,중복목록!$L$6:$L$6005,0)),"")) -> 1234567890 | D7: =IF($A7="","",IFERROR(INDEX(중복검사!$D$4:$D$6003,MATCH("R"&2,중복목록!$L$6:$L$6005,0)),"")) -> 01011112222 | E7: =IF($A7="","",IFERROR(IF(INDEX(원본명단!$E$3:$E$6002,MATCH("R"&2,중복목록!$L$6:$L$6005,0))="","",INDEX(원본명단!$E$3:$E$6002,MATCH("R"&2,중복목록!$L$6:$L$6005,0))),"")) -> 서울시 강남구 테헤란로1 | F7: =IF($A7="","",IFERROR(MAX(INDEX(중복검사!$E$4:$E$6003,MATCH("R"&2,중복목록!$L$6:$L$6005,0)),INDEX(중복검사!$F$4:$F$6003,MATCH("R"&2,중복목록!$L$6:$L$6005,0)),INDEX(중복검사!$G$4:$G$6003,MATCH("R"&2,중복목록!$L$6:$L$6005,0))),"")) -> 2 | G7: =IF($A7="","",IFERROR(INDEX(중복검사!$I$4:$I$6003,MATCH("R"&2,중복목록!$L$6:$L$6005,0)),"")) -> 중복 건 | H7: =IF($A7="","",IFERROR(INDEX(중복검사!$J$4:$J$6003,MATCH("R"&2,중복목록!$L$6:$L$6005,0)),"")) -> 확인 필요 | J7: =IF(중복검사!$A5="",FALSE(),중복검사!$H5="중복") -> TRUE | K7: =IF($J7=FALSE(),"",COUNTIF($J$6:$J7,TRUE())) -> 2 | L7: =IF($K7="","","R"&$K7) -> R2
A8: =IFERROR(INDEX(중복검사!$A$4:$A$6003,MATCH("R"&3,중복목록!$L$6:$L$6005,0)),"") -> 4 | B8: =IF($A8="","",IFERROR(INDEX(중복검사!$B$4:$B$6003,MATCH("R"&3,중복목록!$L$6:$L$6005,0)),"")) -> 마바물산 주식회사 | C8: =IF($A8="","",IFERROR(INDEX(중복검사!$C$4:$C$6003,MATCH("R"&3,중복목록!$L$6:$L$6005,0)),"")) -> 333-33-33333 | D8: =IF($A8="","",IFERROR(INDEX(중복검사!$D$4:$D$6003,MATCH("R"&3,중복목록!$L$6:$L$6005,0)),"")) -> 02-333-4444 | E8: =IF($A8="","",IFERROR(IF(INDEX(원본명단!$E$3:$E$6002,MATCH("R"&3,중복목록!$L$6:$L$6005,0))="","",INDEX(원본명단!$E$3:$E$6002,MATCH("R"&3,중복목록!$L$6:$L$6005,0))),"")) -> 부산시 해운대구 3 | F8: =IF($A8="","",IFERROR(MAX(INDEX(중복검사!$E$4:$E$6003,MATCH("R"&3,중복목록!$L$6:$L$6005,0)),INDEX(중복검사!$F$4:$F$6003,MATCH("R"&3,중복목록!$L$6:$L$6005,0)),INDEX(중복검사!$G$4:$G$6003,MATCH("R"&3,중복목록!$L$6:$L$6005,0))),"")) -> 2 | G8: =IF($A8="","",IFERROR(INDEX(중복검사!$I$4:$I$6003,MATCH("R"&3,중복목록!$L$6:$L$6005,0)),"")) -> 첫 건 | H8: =IF($A8="","",IFERROR(INDEX(중복검사!$J$4:$J$6003,MATCH("R"&3,중복목록!$L$6:$L$6005,0)),"")) -> 유지 | J8: =IF(중복검사!$A6="",FALSE(),중복검사!$H6="중복") -> FALSE | K8: =IF($J8=FALSE(),"",COUNTIF($J$6:$J8,TRUE())) | L8: =IF($K8="","","R"&$K8)
A9: =IFERROR(INDEX(중복검사!$A$4:$A$6003,MATCH("R"&4,중복목록!$L$6:$L$6005,0)),"") -> 5 | B9: =IF($A9="","",IFERROR(INDEX(중복검사!$B$4:$B$6003,MATCH("R"&4,중복목록!$L$6:$L$6005,0)),"")) -> 마바물산 | C9: =IF($A9="","",IFERROR(INDEX(중복검사!$C$4:$C$6003,MATCH("R"&4,중복목록!$L$6:$L$6005,0)),"")) -> 333-33-33333 | D9: =IF($A9="","",IFERROR(INDEX(중복검사!$D$4:$D$6003,MATCH("R"&4,중복목록!$L$6:$L$6005,0)),"")) -> 051-999-8888 | E9: =IF($A9="","",IFERROR(IF(INDEX(원본명단!$E$3:$E$6002,MATCH("R"&4,중복목록!$L$6:$L$6005,0))="","",INDEX(원본명단!$E$3:$E$6002,MATCH("R"&4,중복목록!$L$6:$L$6005,0))),"")) -> 부산시 해운대구 3 | F9: =IF($A9="","",IFERROR(MAX(INDEX(중복검사!$E$4:$E$6003,MATCH("R"&4,중복목록!$L$6:$L$6005,0)),INDEX(중복검사!$F$4:$F$6003,MATCH("R"&4,중복목록!$L$6:$L$6005,0)),INDEX(중복검사!$G$4:$G$6003,MATCH("R"&4,중복목록!$L$6:$L$6005,0))),"")) -> 2 | G9: =IF($A9="","",IFERROR(INDEX(중복검사!$I$4:$I$6003,MATCH("R"&4,중복목록!$L$6:$L$6005,0)),"")) -> 중복 건 | H9: =IF($A9="","",IFERROR(INDEX(중복검사!$J$4:$J$6003,MATCH("R"&4,중복목록!$L$6:$L$6005,0)),"")) -> 확인 필요 | J9: =IF(중복검사!$A7="",FALSE(),중복검사!$H7="중복") -> TRUE | K9: =IF($J9=FALSE(),"",COUNTIF($J$6:$J9,TRUE())) -> 3 | L9: =IF($K9="","","R"&$K9) -> R3
A10: =IFERROR(INDEX(중복검사!$A$4:$A$6003,MATCH("R"&5,중복목록!$L$6:$L$6005,0)),"") | B10: =IF($A10="","",IFERROR(INDEX(중복검사!$B$4:$B$6003,MATCH("R"&5,중복목록!$L$6:$L$6005,0)),"")) | C10: =IF($A10="","",IFERROR(INDEX(중복검사!$C$4:$C$6003,MATCH("R"&5,중복목록!$L$6:$L$6005,0)),"")) | D10: =IF($A10="","",IFERROR(INDEX(중복검사!$D$4:$D$6003,MATCH("R"&5,중복목록!$L$6:$L$6005,0)),"")) | E10: =IF($A10="","",IFERROR(IF(INDEX(원본명단!$E$3:$E$6002,MATCH("R"&5,중복목록!$L$6:$L$6005,0))="","",INDEX(원본명단!$E$3:$E$6002,MATCH("R"&5,중복목록!$L$6:$L$6005,0))),"")) | F10: =IF($A10="","",IFERROR(MAX(INDEX(중복검사!$E$4:$E$6003,MATCH("R"&5,중복목록!$L$6:$L$6005,0)),INDEX(중복검사!$F$4:$F$6003,MATCH("R"&5,중복목록!$L$6:$L$6005,0)),INDEX(중복검사!$G$4:$G$6003,MATCH("R"&5,중복목록!$L$6:$L$6005,0))),"")) | G10: =IF($A10="","",IFERROR(INDEX(중복검사!$I$4:$I$6003,MATCH("R"&5,중복목록!$L$6:$L$6005,0)),"")) | H10: =IF($A10="","",IFERROR(INDEX(중복검사!$J$4:$J$6003,MATCH("R"&5,중복목록!$L$6:$L$6005,0)),"")) | J10: =IF(중복검사!$A8="",FALSE(),중복검사!$H8="중복") -> TRUE | K10: =IF($J10=FALSE(),"",COUNTIF($J$6:$J10,TRUE())) -> 4 | L10: =IF($K10="","","R"&$K10) -> R4
A11: =IFERROR(INDEX(중복검사!$A$4:$A$6003,MATCH("R"&6,중복목록!$L$6:$L$6005,0)),"") | B11: =IF($A11="","",IFERROR(INDEX(중복검사!$B$4:$B$6003,MATCH("R"&6,중복목록!$L$6:$L$6005,0)),"")) | C11: =IF($A11="","",IFERROR(INDEX(중복검사!$C$4:$C$6003,MATCH("R"&6,중복목록!$L$6:$L$6005,0)),"")) | D11: =IF($A11="","",IFERROR(INDEX(중복검사!$D$4:$D$6003,MATCH("R"&6,중복목록!$L$6:$L$6005,0)),"")) | E11: =IF($A11="","",IFERROR(IF(INDEX(원본명단!$E$3:$E$6002,MATCH("R"&6,중복목록!$L$6:$L$6005,0))="","",INDEX(원본명단!$E$3:$E$6002,MATCH("R"&6,중복목록!$L$6:$L$6005,0))),"")) | F11: =IF($A11="","",IFERROR(MAX(INDEX(중복검사!$E$4:$E$6003,MATCH("R"&6,중복목록!$L$6:$L$6005,0)),INDEX(중복검사!$F$4:$F$6003,MATCH("R"&6,중복목록!$L$6:$L$6005,0)),INDEX(중복검사!$G$4:$G$6003,MATCH("R"&6,중복목록!$L$6:$L$6005,0))),"")) | G11: =IF($A11="","",IFERROR(INDEX(중복검사!$I$4:$I$6003,MATCH("R"&6,중복목록!$L$6:$L$6005,0)),"")) | H11: =IF($A11="","",IFERROR(INDEX(중복검사!$J$4:$J$6003,MATCH("R"&6,중복목록!$L$6:$L$6005,0)),"")) | J11: =IF(중복검사!$A9="",FALSE(),중복검사!$H9="중복") -> FALSE | K11: =IF($J11=FALSE(),"",COUNTIF($J$6:$J11,TRUE())) | L11: =IF($K11="","","R"&$K11)
A12: =IFERROR(INDEX(중복검사!$A$4:$A$6003,MATCH("R"&7,중복목록!$L$6:$L$6005,0)),"") | B12: =IF($A12="","",IFERROR(INDEX(중복검사!$B$4:$B$6003,MATCH("R"&7,중복목록!$L$6:$L$6005,0)),"")) | C12: =IF($A12="","",IFERROR(INDEX(중복검사!$C$4:$C$6003,MATCH("R"&7,중복목록!$L$6:$L$6005,0)),"")) | D12: =IF($A12="","",IFERROR(INDEX(중복검사!$D$4:$D$6003,MATCH("R"&7,중복목록!$L$6:$L$6005,0)),"")) | E12: =IF($A12="","",IFERROR(IF(INDEX(원본명단!$E$3:$E$6002,MATCH("R"&7,중복목록!$L$6:$L$6005,0))="","",INDEX(원본명단!$E$3:$E$6002,MATCH("R"&7,중복목록!$L$6:$L$6005,0))),"")) | F12: =IF($A12="","",IFERROR(MAX(INDEX(중복검사!$E$4:$E$6003,MATCH("R"&7,중복목록!$L$6:$L$6005,0)),INDEX(중복검사!$F$4:$F$6003,MATCH("R"&7,중복목록!$L$6:$L$6005,0)),INDEX(중복검사!$G$4:$G$6003,MATCH("R"&7,중복목록!$L$6:$L$6005,0))),"")) | G12: =IF($A12="","",IFERROR(INDEX(중복검사!$I$4:$I$6003,MATCH("R"&7,중복목록!$L$6:$L$6005,0)),"")) | H12: =IF($A12="","",IFERROR(INDEX(중복검사!$J$4:$J$6003,MATCH("R"&7,중복목록!$L$6:$L$6005,0)),"")) | J12: =IF(중복검사!$A10="",FALSE(),중복검사!$H10="중복") -> FALSE | K12: =IF($J12=FALSE(),"",COUNTIF($J$6:$J12,TRUE())) | L12: =IF($K12="","","R"&$K12)
A13: =IFERROR(INDEX(중복검사!$A$4:$A$6003,MATCH("R"&8,중복목록!$L$6:$L$6005,0)),"") | B13: =IF($A13="","",IFERROR(INDEX(중복검사!$B$4:$B$6003,MATCH("R"&8,중복목록!$L$6:$L$6005,0)),"")) | C13: =IF($A13="","",IFERROR(INDEX(중복검사!$C$4:$C$6003,MATCH("R"&8,중복목록!$L$6:$L$6005,0)),"")) | D13: =IF($A13="","",IFERROR(INDEX(중복검사!$D$4:$D$6003,MATCH("R"&8,중복목록!$L$6:$L$6005,0)),"")) | E13: =IF($A13="","",IFERROR(IF(INDEX(원본명단!$E$3:$E$6002,MATCH("R"&8,중복목록!$L$6:$L$6005,0))="","",INDEX(원본명단!$E$3:$E$6002,MATCH("R"&8,중복목록!$L$6:$L$6005,0))),"")) | F13: =IF($A13="","",IFERROR(MAX(INDEX(중복검사!$E$4:$E$6003,MATCH("R"&8,중복목록!$L$6:$L$6005,0)),INDEX(중복검사!$F$4:$F$6003,MATCH("R"&8,중복목록!$L$6:$L$6005,0)),INDEX(중복검사!$G$4:$G$6003,MATCH("R"&8,중복목록!$L$6:$L$6005,0))),"")) | G13: =IF($A13="","",IFERROR(INDEX(중복검사!$I$4:$I$6003,MATCH("R"&8,중복목록!$L$6:$L$6005,0)),"")) | H13: =IF($A13="","",IFERROR(INDEX(중복검사!$J$4:$J$6003,MATCH("R"&8,중복목록!$L$6:$L$6005,0)),"")) | J13: =IF(중복검사!$A11="",FALSE(),중복검사!$H11="중복") -> FALSE | K13: =IF($J13=FALSE(),"",COUNTIF($J$6:$J13,TRUE())) | L13: =IF($K13="","","R"&$K13)
A14: =IFERROR(INDEX(중복검사!$A$4:$A$6003,MATCH("R"&9,중복목록!$L$6:$L$6005,0)),"") | B14: =IF($A14="","",IFERROR(INDEX(중복검사!$B$4:$B$6003,MATCH("R"&9,중복목록!$L$6:$L$6005,0)),"")) | C14: =IF($A14="","",IFERROR(INDEX(중복검사!$C$4:$C$6003,MATCH("R"&9,중복목록!$L$6:$L$6005,0)),"")) | D14: =IF($A14="","",IFERROR(INDEX(중복검사!$D$4:$D$6003,MATCH("R"&9,중복목록!$L$6:$L$6005,0)),"")) | E14: =IF($A14="","",IFERROR(IF(INDEX(원본명단!$E$3:$E$6002,MATCH("R"&9,중복목록!$L$6:$L$6005,0))="","",INDEX(원본명단!$E$3:$E$6002,MATCH("R"&9,중복목록!$L$6:$L$6005,0))),"")) | F14: =IF($A14="","",IFERROR(MAX(INDEX(중복검사!$E$4:$E$6003,MATCH("R"&9,중복목록!$L$6:$L$6005,0)),INDEX(중복검사!$F$4:$F$6003,MATCH("R"&9,중복목록!$L$6:$L$6005,0)),INDEX(중복검사!$G$4:$G$6003,MATCH("R"&9,중복목록!$L$6:$L$6005,0))),"")) | G14: =IF($A14="","",IFERROR(INDEX(중복검사!$I$4:$I$6003,MATCH("R"&9,중복목록!$L$6:$L$6005,0)),"")) | H14: =IF($A14="","",IFERROR(INDEX(중복검사!$J$4:$J$6003,MATCH("R"&9,중복목록!$L$6:$L$6005,0)),"")) | J14: =IF(중복검사!$A12="",FALSE(),중복검사!$H12="중복") -> FALSE | K14: =IF($J14=FALSE(),"",COUNTIF($J$6:$J14,TRUE())) | L14: =IF($K14="","","R"&$K14)
A15: =IFERROR(INDEX(중복검사!$A$4:$A$6003,MATCH("R"&10,중복목록!$L$6:$L$6005,0)),"") | B15: =IF($A15="","",IFERROR(INDEX(중복검사!$B$4:$B$6003,MATCH("R"&10,중복목록!$L$6:$L$6005,0)),"")) | C15: =IF($A15="","",IFERROR(INDEX(중복검사!$C$4:$C$6003,MATCH("R"&10,중복목록!$L$6:$L$6005,0)),"")) | D15: =IF($A15="","",IFERROR(INDEX(중복검사!$D$4:$D$6003,MATCH("R"&10,중복목록!$L$6:$L$6005,0)),"")) | E15: =IF($A15="","",IFERROR(IF(INDEX(원본명단!$E$3:$E$6002,MATCH("R"&10,중복목록!$L$6:$L$6005,0))="","",INDEX(원본명단!$E$3:$E$6002,MATCH("R"&10,중복목록!$L$6:$L$6005,0))),"")) | F15: =IF($A15="","",IFERROR(MAX(INDEX(중복검사!$E$4:$E$6003,MATCH("R"&10,중복목록!$L$6:$L$6005,0)),INDEX(중복검사!$F$4:$F$6003,MATCH("R"&10,중복목록!$L$6:$L$6005,0)),INDEX(중복검사!$G$4:$G$6003,MATCH("R"&10,중복목록!$L$6:$L$6005,0))),"")) | G15: =IF($A15="","",IFERROR(INDEX(중복검사!$I$4:$I$6003,MATCH("R"&10,중복목록!$L$6:$L$6005,0)),"")) | H15: =IF($A15="","",IFERROR(INDEX(중복검사!$J$4:$J$6003,MATCH("R"&10,중복목록!$L$6:$L$6005,0)),"")) | J15: =IF(중복검사!$A13="",FALSE(),중복검사!$H13="중복") -> FALSE | K15: =IF($J15=FALSE(),"",COUNTIF($J$6:$J15,TRUE())) | L15: =IF($K15="","","R"&$K15)
A16: =IFERROR(INDEX(중복검사!$A$4:$A$6003,MATCH("R"&11,중복목록!$L$6:$L$6005,0)),"") | B16: =IF($A16="","",IFERROR(INDEX(중복검사!$B$4:$B$6003,MATCH("R"&11,중복목록!$L$6:$L$6005,0)),"")) | C16: =IF($A16="","",IFERROR(INDEX(중복검사!$C$4:$C$6003,MATCH("R"&11,중복목록!$L$6:$L$6005,0)),"")) | D16: =IF($A16="","",IFERROR(INDEX(중복검사!$D$4:$D$6003,MATCH("R"&11,중복목록!$L$6:$L$6005,0)),"")) | E16: =IF($A16="","",IFERROR(IF(INDEX(원본명단!$E$3:$E$6002,MATCH("R"&11,중복목록!$L$6:$L$6005,0))="","",INDEX(원본명단!$E$3:$E$6002,MATCH("R"&11,중복목록!$L$6:$L$6005,0))),"")) | F16: =IF($A16="","",IFERROR(MAX(INDEX(중복검사!$E$4:$E$6003,MATCH("R"&11,중복목록!$L$6:$L$6005,0)),INDEX(중복검사!$F$4:$F$6003,MATCH("R"&11,중복목록!$L$6:$L$6005,0)),INDEX(중복검사!$G$4:$G$6003,MATCH("R"&11,중복목록!$L$6:$L$6005,0))),"")) | G16: =IF($A16="","",IFERROR(INDEX(중복검사!$I$4:$I$6003,MATCH("R"&11,중복목록!$L$6:$L$6005,0)),"")) | H16: =IF($A16="","",IFERROR(INDEX(중복검사!$J$4:$J$6003,MATCH("R"&11,중복목록!$L$6:$L$6005,0)),"")) | J16: =IF(중복검사!$A14="",FALSE(),중복검사!$H14="중복") -> FALSE | K16: =IF($J16=FALSE(),"",COUNTIF($J$6:$J16,TRUE())) | L16: =IF($K16="","","R"&$K16)
A17: =IFERROR(INDEX(중복검사!$A$4:$A$6003,MATCH("R"&12,중복목록!$L$6:$L$6005,0)),"") | B17: =IF($A17="","",IFERROR(INDEX(중복검사!$B$4:$B$6003,MATCH("R"&12,중복목록!$L$6:$L$6005,0)),"")) | C17: =IF($A17="","",IFERROR(INDEX(중복검사!$C$4:$C$6003,MATCH("R"&12,중복목록!$L$6:$L$6005,0)),"")) | D17: =IF($A17="","",IFERROR(INDEX(중복검사!$D$4:$D$6003,MATCH("R"&12,중복목록!$L$6:$L$6005,0)),"")) | E17: =IF($A17="","",IFERROR(IF(INDEX(원본명단!$E$3:$E$6002,MATCH("R"&12,중복목록!$L$6:$L$6005,0))="","",INDEX(원본명단!$E$3:$E$6002,MATCH("R"&12,중복목록!$L$6:$L$6005,0))),"")) | F17: =IF($A17="","",IFERROR(MAX(INDEX(중복검사!$E$4:$E$6003,MATCH("R"&12,중복목록!$L$6:$L$6005,0)),INDEX(중복검사!$F$4:$F$6003,MATCH("R"&12,중복목록!$L$6:$L$6005,0)),INDEX(중복검사!$G$4:$G$6003,MATCH("R"&12,중복목록!$L$6:$L$6005,0))),"")) | G17: =IF($A17="","",IFERROR(INDEX(중복검사!$I$4:$I$6003,MATCH("R"&12,중복목록!$L$6:$L$6005,0)),"")) | H17: =IF($A17="","",IFERROR(INDEX(중복검사!$J$4:$J$6003,MATCH("R"&12,중복목록!$L$6:$L$6005,0)),"")) | J17: =IF(중복검사!$A15="",FALSE(),중복검사!$H15="중복") -> FALSE | K17: =IF($J17=FALSE(),"",COUNTIF($J$6:$J17,TRUE())) | L17: =IF($K17="","","R"&$K17)
A18: =IFERROR(INDEX(중복검사!$A$4:$A$6003,MATCH("R"&13,중복목록!$L$6:$L$6005,0)),"") | B18: =IF($A18="","",IFERROR(INDEX(중복검사!$B$4:$B$6003,MATCH("R"&13,중복목록!$L$6:$L$6005,0)),"")) | C18: =IF($A18="","",IFERROR(INDEX(중복검사!$C$4:$C$6003,MATCH("R"&13,중복목록!$L$6:$L$6005,0)),"")) | D18: =IF($A18="","",IFERROR(INDEX(중복검사!$D$4:$D$6003,MATCH("R"&13,중복목록!$L$6:$L$6005,0)),"")) | E18: =IF($A18="","",IFERROR(IF(INDEX(원본명단!$E$3:$E$6002,MATCH("R"&13,중복목록!$L$6:$L$6005,0))="","",INDEX(원본명단!$E$3:$E$6002,MATCH("R"&13,중복목록!$L$6:$L$6005,0))),"")) | F18: =IF($A18="","",IFERROR(MAX(INDEX(중복검사!$E$4:$E$6003,MATCH("R"&13,중복목록!$L$6:$L$6005,0)),INDEX(중복검사!$F$4:$F$6003,MATCH("R"&13,중복목록!$L$6:$L$6005,0)),INDEX(중복검사!$G$4:$G$6003,MATCH("R"&13,중복목록!$L$6:$L$6005,0))),"")) | G18: =IF($A18="","",IFERROR(INDEX(중복검사!$I$4:$I$6003,MATCH("R"&13,중복목록!$L$6:$L$6005,0)),"")) | H18: =IF($A18="","",IFERROR(INDEX(중복검사!$J$4:$J$6003,MATCH("R"&13,중복목록!$L$6:$L$6005,0)),"")) | J18: =IF(중복검사!$A16="",FALSE(),중복검사!$H16="중복") -> FALSE | K18: =IF($J18=FALSE(),"",COUNTIF($J$6:$J18,TRUE())) | L18: =IF($K18="","","R"&$K18)
A19: =IFERROR(INDEX(중복검사!$A$4:$A$6003,MATCH("R"&14,중복목록!$L$6:$L$6005,0)),"") | B19: =IF($A19="","",IFERROR(INDEX(중복검사!$B$4:$B$6003,MATCH("R"&14,중복목록!$L$6:$L$6005,0)),"")) | C19: =IF($A19="","",IFERROR(INDEX(중복검사!$C$4:$C$6003,MATCH("R"&14,중복목록!$L$6:$L$6005,0)),"")) | D19: =IF($A19="","",IFERROR(INDEX(중복검사!$D$4:$D$6003,MATCH("R"&14,중복목록!$L$6:$L$6005,0)),"")) | E19: =IF($A19="","",IFERROR(IF(INDEX(원본명단!$E$3:$E$6002,MATCH("R"&14,중복목록!$L$6:$L$6005,0))="","",INDEX(원본명단!$E$3:$E$6002,MATCH("R"&14,중복목록!$L$6:$L$6005,0))),"")) | F19: =IF($A19="","",IFERROR(MAX(INDEX(중복검사!$E$4:$E$6003,MATCH("R"&14,중복목록!$L$6:$L$6005,0)),INDEX(중복검사!$F$4:$F$6003,MATCH("R"&14,중복목록!$L$6:$L$6005,0)),INDEX(중복검사!$G$4:$G$6003,MATCH("R"&14,중복목록!$L$6:$L$6005,0))),"")) | G19: =IF($A19="","",IFERROR(INDEX(중복검사!$I$4:$I$6003,MATCH("R"&14,중복목록!$L$6:$L$6005,0)),"")) | H19: =IF($A19="","",IFERROR(INDEX(중복검사!$J$4:$J$6003,MATCH("R"&14,중복목록!$L$6:$L$6005,0)),"")) | J19: =IF(중복검사!$A17="",FALSE(),중복검사!$H17="중복") -> FALSE | K19: =IF($J19=FALSE(),"",COUNTIF($J$6:$J19,TRUE())) | L19: =IF($K19="","","R"&$K19)
A20: =IFERROR(INDEX(중복검사!$A$4:$A$6003,MATCH("R"&15,중복목록!$L$6:$L$6005,0)),"") | B20: =IF($A20="","",IFERROR(INDEX(중복검사!$B$4:$B$6003,MATCH("R"&15,중복목록!$L$6:$L$6005,0)),"")) | C20: =IF($A20="","",IFERROR(INDEX(중복검사!$C$4:$C$6003,MATCH("R"&15,중복목록!$L$6:$L$6005,0)),"")) | D20: =IF($A20="","",IFERROR(INDEX(중복검사!$D$4:$D$6003,MATCH("R"&15,중복목록!$L$6:$L$6005,0)),"")) | E20: =IF($A20="","",IFERROR(IF(INDEX(원본명단!$E$3:$E$6002,MATCH("R"&15,중복목록!$L$6:$L$6005,0))="","",INDEX(원본명단!$E$3:$E$6002,MATCH("R"&15,중복목록!$L$6:$L$6005,0))),"")) | F20: =IF($A20="","",IFERROR(MAX(INDEX(중복검사!$E$4:$E$6003,MATCH("R"&15,중복목록!$L$6:$L$6005,0)),INDEX(중복검사!$F$4:$F$6003,MATCH("R"&15,중복목록!$L$6:$L$6005,0)),INDEX(중복검사!$G$4:$G$6003,MATCH("R"&15,중복목록!$L$6:$L$6005,0))),"")) | G20: =IF($A20="","",IFERROR(INDEX(중복검사!$I$4:$I$6003,MATCH("R"&15,중복목록!$L$6:$L$6005,0)),"")) | H20: =IF($A20="","",IFERROR(INDEX(중복검사!$J$4:$J$6003,MATCH("R"&15,중복목록!$L$6:$L$6005,0)),"")) | J20: =IF(중복검사!$A18="",FALSE(),중복검사!$H18="중복") -> FALSE | K20: =IF($J20=FALSE(),"",COUNTIF($J$6:$J20,TRUE())) | L20: =IF($K20="","","R"&$K20)
A21: =IFERROR(INDEX(중복검사!$A$4:$A$6003,MATCH("R"&16,중복목록!$L$6:$L$6005,0)),"") | B21: =IF($A21="","",IFERROR(INDEX(중복검사!$B$4:$B$6003,MATCH("R"&16,중복목록!$L$6:$L$6005,0)),"")) | C21: =IF($A21="","",IFERROR(INDEX(중복검사!$C$4:$C$6003,MATCH("R"&16,중복목록!$L$6:$L$6005,0)),"")) | D21: =IF($A21="","",IFERROR(INDEX(중복검사!$D$4:$D$6003,MATCH("R"&16,중복목록!$L$6:$L$6005,0)),"")) | E21: =IF($A21="","",IFERROR(IF(INDEX(원본명단!$E$3:$E$6002,MATCH("R"&16,중복목록!$L$6:$L$6005,0))="","",INDEX(원본명단!$E$3:$E$6002,MATCH("R"&16,중복목록!$L$6:$L$6005,0))),"")) | F21: =IF($A21="","",IFERROR(MAX(INDEX(중복검사!$E$4:$E$6003,MATCH("R"&16,중복목록!$L$6:$L$6005,0)),INDEX(중복검사!$F$4:$F$6003,MATCH("R"&16,중복목록!$L$6:$L$6005,0)),INDEX(중복검사!$G$4:$G$6003,MATCH("R"&16,중복목록!$L$6:$L$6005,0))),"")) | G21: =IF($A21="","",IFERROR(INDEX(중복검사!$I$4:$I$6003,MATCH("R"&16,중복목록!$L$6:$L$6005,0)),"")) | H21: =IF($A21="","",IFERROR(INDEX(중복검사!$J$4:$J$6003,MATCH("R"&16,중복목록!$L$6:$L$6005,0)),"")) | J21: =IF(중복검사!$A19="",FALSE(),중복검사!$H19="중복") -> FALSE | K21: =IF($J21=FALSE(),"",COUNTIF($J$6:$J21,TRUE())) | L21: =IF($K21="","","R"&$K21)
A22: =IFERROR(INDEX(중복검사!$A$4:$A$6003,MATCH("R"&17,중복목록!$L$6:$L$6005,0)),"") | B22: =IF($A22="","",IFERROR(INDEX(중복검사!$B$4:$B$6003,MATCH("R"&17,중복목록!$L$6:$L$6005,0)),"")) | C22: =IF($A22="","",IFERROR(INDEX(중복검사!$C$4:$C$6003,MATCH("R"&17,중복목록!$L$6:$L$6005,0)),"")) | D22: =IF($A22="","",IFERROR(INDEX(중복검사!$D$4:$D$6003,MATCH("R"&17,중복목록!$L$6:$L$6005,0)),"")) | E22: =IF($A22="","",IFERROR(IF(INDEX(원본명단!$E$3:$E$6002,MATCH("R"&17,중복목록!$L$6:$L$6005,0))="","",INDEX(원본명단!$E$3:$E$6002,MATCH("R"&17,중복목록!$L$6:$L$6005,0))),"")) | F22: =IF($A22="","",IFERROR(MAX(INDEX(중복검사!$E$4:$E$6003,MATCH("R"&17,중복목록!$L$6:$L$6005,0)),INDEX(중복검사!$F$4:$F$6003,MATCH("R"&17,중복목록!$L$6:$L$6005,0)),INDEX(중복검사!$G$4:$G$6003,MATCH("R"&17,중복목록!$L$6:$L$6005,0))),"")) | G22: =IF($A22="","",IFERROR(INDEX(중복검사!$I$4:$I$6003,MATCH("R"&17,중복목록!$L$6:$L$6005,0)),"")) | H22: =IF($A22="","",IFERROR(INDEX(중복검사!$J$4:$J$6003,MATCH("R"&17,중복목록!$L$6:$L$6005,0)),"")) | J22: =IF(중복검사!$A20="",FALSE(),중복검사!$H20="중복") -> FALSE | K22: =IF($J22=FALSE(),"",COUNTIF($J$6:$J22,TRUE())) | L22: =IF($K22="","","R"&$K22)
A23: =IFERROR(INDEX(중복검사!$A$4:$A$6003,MATCH("R"&18,중복목록!$L$6:$L$6005,0)),"") | B23: =IF($A23="","",IFERROR(INDEX(중복검사!$B$4:$B$6003,MATCH("R"&18,중복목록!$L$6:$L$6005,0)),"")) | C23: =IF($A23="","",IFERROR(INDEX(중복검사!$C$4:$C$6003,MATCH("R"&18,중복목록!$L$6:$L$6005,0)),"")) | D23: =IF($A23="","",IFERROR(INDEX(중복검사!$D$4:$D$6003,MATCH("R"&18,중복목록!$L$6:$L$6005,0)),"")) | E23: =IF($A23="","",IFERROR(IF(INDEX(원본명단!$E$3:$E$6002,MATCH("R"&18,중복목록!$L$6:$L$6005,0))="","",INDEX(원본명단!$E$3:$E$6002,MATCH("R"&18,중복목록!$L$6:$L$6005,0))),"")) | F23: =IF($A23="","",IFERROR(MAX(INDEX(중복검사!$E$4:$E$6003,MATCH("R"&18,중복목록!$L$6:$L$6005,0)),INDEX(중복검사!$F$4:$F$6003,MATCH("R"&18,중복목록!$L$6:$L$6005,0)),INDEX(중복검사!$G$4:$G$6003,MATCH("R"&18,중복목록!$L$6:$L$6005,0))),"")) | G23: =IF($A23="","",IFERROR(INDEX(중복검사!$I$4:$I$6003,MATCH("R"&18,중복목록!$L$6:$L$6005,0)),"")) | H23: =IF($A23="","",IFERROR(INDEX(중복검사!$J$4:$J$6003,MATCH("R"&18,중복목록!$L$6:$L$6005,0)),"")) | J23: =IF(중복검사!$A21="",FALSE(),중복검사!$H21="중복") -> FALSE | K23: =IF($J23=FALSE(),"",COUNTIF($J$6:$J23,TRUE())) | L23: =IF($K23="","","R"&$K23)
A24: =IFERROR(INDEX(중복검사!$A$4:$A$6003,MATCH("R"&19,중복목록!$L$6:$L$6005,0)),"") | B24: =IF($A24="","",IFERROR(INDEX(중복검사!$B$4:$B$6003,MATCH("R"&19,중복목록!$L$6:$L$6005,0)),"")) | C24: =IF($A24="","",IFERROR(INDEX(중복검사!$C$4:$C$6003,MATCH("R"&19,중복목록!$L$6:$L$6005,0)),"")) | D24: =IF($A24="","",IFERROR(INDEX(중복검사!$D$4:$D$6003,MATCH("R"&19,중복목록!$L$6:$L$6005,0)),"")) | E24: =IF($A24="","",IFERROR(IF(INDEX(원본명단!$E$3:$E$6002,MATCH("R"&19,중복목록!$L$6:$L$6005,0))="","",INDEX(원본명단!$E$3:$E$6002,MATCH("R"&19,중복목록!$L$6:$L$6005,0))),"")) | F24: =IF($A24="","",IFERROR(MAX(INDEX(중복검사!$E$4:$E$6003,MATCH("R"&19,중복목록!$L$6:$L$6005,0)),INDEX(중복검사!$F$4:$F$6003,MATCH("R"&19,중복목록!$L$6:$L$6005,0)),INDEX(중복검사!$G$4:$G$6003,MATCH("R"&19,중복목록!$L$6:$L$6005,0))),"")) | G24: =IF($A24="","",IFERROR(INDEX(중복검사!$I$4:$I$6003,MATCH("R"&19,중복목록!$L$6:$L$6005,0)),"")) | H24: =IF($A24="","",IFERROR(INDEX(중복검사!$J$4:$J$6003,MATCH("R"&19,중복목록!$L$6:$L$6005,0)),"")) | J24: =IF(중복검사!$A22="",FALSE(),중복검사!$H22="중복") -> FALSE | K24: =IF($J24=FALSE(),"",COUNTIF($J$6:$J24,TRUE())) | L24: =IF($K24="","","R"&$K24)
A25: =IFERROR(INDEX(중복검사!$A$4:$A$6003,MATCH("R"&20,중복목록!$L$6:$L$6005,0)),"") | B25: =IF($A25="","",IFERROR(INDEX(중복검사!$B$4:$B$6003,MATCH("R"&20,중복목록!$L$6:$L$6005,0)),"")) | C25: =IF($A25="","",IFERROR(INDEX(중복검사!$C$4:$C$6003,MATCH("R"&20,중복목록!$L$6:$L$6005,0)),"")) | D25: =IF($A25="","",IFERROR(INDEX(중복검사!$D$4:$D$6003,MATCH("R"&20,중복목록!$L$6:$L$6005,0)),"")) | E25: =IF($A25="","",IFERROR(IF(INDEX(원본명단!$E$3:$E$6002,MATCH("R"&20,중복목록!$L$6:$L$6005,0))="","",INDEX(원본명단!$E$3:$E$6002,MATCH("R"&20,중복목록!$L$6:$L$6005,0))),"")) | F25: =IF($A25="","",IFERROR(MAX(INDEX(중복검사!$E$4:$E$6003,MATCH("R"&20,중복목록!$L$6:$L$6005,0)),INDEX(중복검사!$F$4:$F$6003,MATCH("R"&20,중복목록!$L$6:$L$6005,0)),INDEX(중복검사!$G$4:$G$6003,MATCH("R"&20,중복목록!$L$6:$L$6005,0))),"")) | G25: =IF($A25="","",IFERROR(INDEX(중복검사!$I$4:$I$6003,MATCH("R"&20,중복목록!$L$6:$L$6005,0)),"")) | H25: =IF($A25="","",IFERROR(INDEX(중복검사!$J$4:$J$6003,MATCH("R"&20,중복목록!$L$6:$L$6005,0)),"")) | J25: =IF(중복검사!$A23="",FALSE(),중복검사!$H23="중복") -> FALSE | K25: =IF($J25=FALSE(),"",COUNTIF($J$6:$J25,TRUE())) | L25: =IF($K25="","","R"&$K25)
A26: =IFERROR(INDEX(중복검사!$A$4:$A$6003,MATCH("R"&21,중복목록!$L$6:$L$6005,0)),"") | B26: =IF($A26="","",IFERROR(INDEX(중복검사!$B$4:$B$6003,MATCH("R"&21,중복목록!$L$6:$L$6005,0)),"")) | C26: =IF($A26="","",IFERROR(INDEX(중복검사!$C$4:$C$6003,MATCH("R"&21,중복목록!$L$6:$L$6005,0)),"")) | D26: =IF($A26="","",IFERROR(INDEX(중복검사!$D$4:$D$6003,MATCH("R"&21,중복목록!$L$6:$L$6005,0)),"")) | E26: =IF($A26="","",IFERROR(IF(INDEX(원본명단!$E$3:$E$6002,MATCH("R"&21,중복목록!$L$6:$L$6005,0))="","",INDEX(원본명단!$E$3:$E$6002,MATCH("R"&21,중복목록!$L$6:$L$6005,0))),"")) | F26: =IF($A26="","",IFERROR(MAX(INDEX(중복검사!$E$4:$E$6003,MATCH("R"&21,중복목록!$L$6:$L$6005,0)),INDEX(중복검사!$F$4:$F$6003,MATCH("R"&21,중복목록!$L$6:$L$6005,0)),INDEX(중복검사!$G$4:$G$6003,MATCH("R"&21,중복목록!$L$6:$L$6005,0))),"")) | G26: =IF($A26="","",IFERROR(INDEX(중복검사!$I$4:$I$6003,MATCH("R"&21,중복목록!$L$6:$L$6005,0)),"")) | H26: =IF($A26="","",IFERROR(INDEX(중복검사!$J$4:$J$6003,MATCH("R"&21,중복목록!$L$6:$L$6005,0)),"")) | J26: =IF(중복검사!$A24="",FALSE(),중복검사!$H24="중복") -> FALSE | K26: =IF($J26=FALSE(),"",COUNTIF($J$6:$J26,TRUE())) | L26: =IF($K26="","","R"&$K26)
