Workbook

Sheet 사용안내
B2: 간트차트 일정관리
B4: 핵심 | C4: 시작일과 종료일만 넣으면 달력 위에 막대가 자동으로 그려집니다.
B5: 입력 규칙 | C5: 파란색 글씨 칸만 입력하세요. 검은색은 자동 계산입니다.
B6: ① 담당자목록 | C6: 담당자와 소속을 등록합니다.
B7: ② 작업목록 | C7: 작업명·담당자·시작일·종료일·진행률을 넣습니다. 여기가 유일한 입력 시트입니다.
B8: ③ 간트차트(일) | C8: 기준일부터 60일간을 하루 한 칸으로 보여줍니다. 상세 일정용입니다.
B9: ④ 간트차트(주) | C9: 기준일부터 26주간을 한 주 한 칸으로 보여줍니다. 전체 흐름용입니다.
B10: ⑤ 담당자별현황 | C10: 담당자별 작업 수와 진행 상황입니다.
B11: ⑥ 지연현황 | C11: 종료일이 지났는데 100%가 아닌 작업만 모아 보여줍니다.
B12: 막대 색 구분 | C12: 완료(100%)는 회색, 진행 중은 파랑, 지연은 빨강으로 칠해집니다.
B13: 오늘 표시 | C13: 오늘 날짜 칸은 세로로 노란 선이 들어갑니다.
B15: ※ 작업 100건, 일 단위 60일 / 주 단위 26주까지 표시됩니다.
B16: ※ 기준일을 바꾸면 차트가 그 날짜부터 다시 그려집니다.

Sheet 담당자목록
A1: 담당자목록
A2: 담당자 | B2: 소속 | C2: 연락처 | D2: 비고
A3: 김담당 | B3: 기획팀 | C3: 010-0000-0001
A4: 이담당 | B4: 개발팀 | C4: 010-0000-0002
A5: 박담당 | B5: 디자인팀 | C5: 010-0000-0003

Sheet 작업목록
A1: 작업목록 (여기가 유일한 입력 시트입니다)
A2: No(자동) | B2: 구분 | C2: 작업명 | D2: 담당자 | E2: 시작일 | F2: 종료일 | G2: 기간(일,자동) | H2: 진행률 | I2: 상태(자동) | J2: 남은일수(자동) | K2: 비고
A3: =IF($C3="","",ROW()-2) -> 1 | B3: 기획 | C3: 요구사항 정리 | D3: 김담당 | E3: 46266 | F3: 46275 | G3: =IF(OR($E3="",$F3=""),"",$F3-$E3+1) -> 10 | H3: 1 | I3: =IF($C3="","",IF($H3>=1,"완료",IF($F3="","미정",IF($F3<TODAY(),"지연",IF($E3>TODAY(),"예정","진행중"))))) -> 완료 | J3: =IF(OR($C3="",$F3=""),"",IF($H3>=1,"-",$F3-TODAY())) -> -
A4: =IF($C4="","",ROW()-2) -> 2 | B4: 설계 | C4: 화면 설계 | D4: 박담당 | E4: 46273 | F4: 46285 | G4: =IF(OR($E4="",$F4=""),"",$F4-$E4+1) -> 13 | H4: 0.6 | I4: =IF($C4="","",IF($H4>=1,"완료",IF($F4="","미정",IF($F4<TODAY(),"지연",IF($E4>TODAY(),"예정","진행중"))))) -> 진행중 | J4: =IF(OR($C4="",$F4=""),"",IF($H4>=1,"-",$F4-TODAY())) -> 6
A5: =IF($C5="","",ROW()-2) -> 3 | B5: 개발 | C5: 백엔드 구축 | D5: 이담당 | E5: 46280 | F5: 46310 | G5: =IF(OR($E5="",$F5=""),"",$F5-$E5+1) -> 31 | H5: 0.2 | I5: =IF($C5="","",IF($H5>=1,"완료",IF($F5="","미정",IF($F5<TODAY(),"지연",IF($E5>TODAY(),"예정","진행중"))))) -> 예정 | J5: =IF(OR($C5="",$F5=""),"",IF($H5>=1,"-",$F5-TODAY())) -> 31
A6: =IF($C6="","",ROW()-2) -> 4 | B6: 개발 | C6: 프론트 구축 | D6: 이담당 | E6: 46290 | F6: 46320 | G6: =IF(OR($E6="",$F6=""),"",$F6-$E6+1) -> 31 | H6: 0 | I6: =IF($C6="","",IF($H6>=1,"완료",IF($F6="","미정",IF($F6<TODAY(),"지연",IF($E6>TODAY(),"예정","진행중"))))) -> 예정 | J6: =IF(OR($C6="",$F6=""),"",IF($H6>=1,"-",$F6-TODAY())) -> 41
A7: =IF($C7="","",ROW()-2) -> 5 | B7: 검수 | C7: 통합 테스트 | D7: 김담당 | E7: 46315 | F7: 46325 | G7: =IF(OR($E7="",$F7=""),"",$F7-$E7+1) -> 11 | H7: 0 | I7: =IF($C7="","",IF($H7>=1,"완료",IF($F7="","미정",IF($F7<TODAY(),"지연",IF($E7>TODAY(),"예정","진행중"))))) -> 예정 | J7: =IF(OR($C7="",$F7=""),"",IF($H7>=1,"-",$F7-TODAY())) -> 46
A8: =IF($C8="","",ROW()-2) -> 6 | B8: 검수 | C8: 테스트 시나리오 작성 | D8: 박담당 | E8: 46254 | F8: 46270 | G8: =IF(OR($E8="",$F8=""),"",$F8-$E8+1) -> 17 | H8: 0.7 | I8: =IF($C8="","",IF($H8>=1,"완료",IF($F8="","미정",IF($F8<TODAY(),"지연",IF($E8>TODAY(),"예정","진행중"))))) -> 지연 | J8: =IF(OR($C8="",$F8=""),"",IF($H8>=1,"-",$F8-TODAY())) -> -9 | K8: 기한이 지났습니다
A9: =IF($C9="","",ROW()-2) | G9: =IF(OR($E9="",$F9=""),"",$F9-$E9+1) | I9: =IF($C9="","",IF($H9>=1,"완료",IF($F9="","미정",IF($F9<TODAY(),"지연",IF($E9>TODAY(),"예정","진행중"))))) | J9: =IF(OR($C9="",$F9=""),"",IF($H9>=1,"-",$F9-TODAY()))
A10: =IF($C10="","",ROW()-2) | G10: =IF(OR($E10="",$F10=""),"",$F10-$E10+1) | I10: =IF($C10="","",IF($H10>=1,"완료",IF($F10="","미정",IF($F10<TODAY(),"지연",IF($E10>TODAY(),"예정","진행중"))))) | J10: =IF(OR($C10="",$F10=""),"",IF($H10>=1,"-",$F10-TODAY()))
A11: =IF($C11="","",ROW()-2) | G11: =IF(OR($E11="",$F11=""),"",$F11-$E11+1) | I11: =IF($C11="","",IF($H11>=1,"완료",IF($F11="","미정",IF($F11<TODAY(),"지연",IF($E11>TODAY(),"예정","진행중"))))) | J11: =IF(OR($C11="",$F11=""),"",IF($H11>=1,"-",$F11-TODAY()))
A12: =IF($C12="","",ROW()-2) | G12: =IF(OR($E12="",$F12=""),"",$F12-$E12+1) | I12: =IF($C12="","",IF($H12>=1,"완료",IF($F12="","미정",IF($F12<TODAY(),"지연",IF($E12>TODAY(),"예정","진행중"))))) | J12: =IF(OR($C12="",$F12=""),"",IF($H12>=1,"-",$F12-TODAY()))
A13: =IF($C13="","",ROW()-2) | G13: =IF(OR($E13="",$F13=""),"",$F13-$E13+1) | I13: =IF($C13="","",IF($H13>=1,"완료",IF($F13="","미정",IF($F13<TODAY(),"지연",IF($E13>TODAY(),"예정","진행중"))))) | J13: =IF(OR($C13="",$F13=""),"",IF($H13>=1,"-",$F13-TODAY()))
A14: =IF($C14="","",ROW()-2) | G14: =IF(OR($E14="",$F14=""),"",$F14-$E14+1) | I14: =IF($C14="","",IF($H14>=1,"완료",IF($F14="","미정",IF($F14<TODAY(),"지연",IF($E14>TODAY(),"예정","진행중"))))) | J14: =IF(OR($C14="",$F14=""),"",IF($H14>=1,"-",$F14-TODAY()))
A15: =IF($C15="","",ROW()-2) | G15: =IF(OR($E15="",$F15=""),"",$F15-$E15+1) | I15: =IF($C15="","",IF($H15>=1,"완료",IF($F15="","미정",IF($F15<TODAY(),"지연",IF($E15>TODAY(),"예정","진행중"))))) | J15: =IF(OR($C15="",$F15=""),"",IF($H15>=1,"-",$F15-TODAY()))
A16: =IF($C16="","",ROW()-2) | G16: =IF(OR($E16="",$F16=""),"",$F16-$E16+1) | I16: =IF($C16="","",IF($H16>=1,"완료",IF($F16="","미정",IF($F16<TODAY(),"지연",IF($E16>TODAY(),"예정","진행중"))))) | J16: =IF(OR($C16="",$F16=""),"",IF($H16>=1,"-",$F16-TODAY()))
A17: =IF($C17="","",ROW()-2) | G17: =IF(OR($E17="",$F17=""),"",$F17-$E17+1) | I17: =IF($C17="","",IF($H17>=1,"완료",IF($F17="","미정",IF($F17<TODAY(),"지연",IF($E17>TODAY(),"예정","진행중"))))) | J17: =IF(OR($C17="",$F17=""),"",IF($H17>=1,"-",$F17-TODAY()))
A18: =IF($C18="","",ROW()-2) | G18: =IF(OR($E18="",$F18=""),"",$F18-$E18+1) | I18: =IF($C18="","",IF($H18>=1,"완료",IF($F18="","미정",IF($F18<TODAY(),"지연",IF($E18>TODAY(),"예정","진행중"))))) | J18: =IF(OR($C18="",$F18=""),"",IF($H18>=1,"-",$F18-TODAY()))
A19: =IF($C19="","",ROW()-2) | G19: =IF(OR($E19="",$F19=""),"",$F19-$E19+1) | I19: =IF($C19="","",IF($H19>=1,"완료",IF($F19="","미정",IF($F19<TODAY(),"지연",IF($E19>TODAY(),"예정","진행중"))))) | J19: =IF(OR($C19="",$F19=""),"",IF($H19>=1,"-",$F19-TODAY()))
A20: =IF($C20="","",ROW()-2) | G20: =IF(OR($E20="",$F20=""),"",$F20-$E20+1) | I20: =IF($C20="","",IF($H20>=1,"완료",IF($F20="","미정",IF($F20<TODAY(),"지연",IF($E20>TODAY(),"예정","진행중"))))) | J20: =IF(OR($C20="",$F20=""),"",IF($H20>=1,"-",$F20-TODAY()))
... A102: =IF($C102="","",ROW()-2) | G102: =IF(OR($E102="",$F102=""),"",$F102-$E102+1) | I102: =IF($C102="","",IF($H102>=1,"완료",IF($F102="","미정",IF($F102<TODAY(),"지연",IF($E102>TODAY(),"예정","진행중"))))) | J102: =IF(OR($C102="",$F102=""),"",IF($H102>=1,"-",$F102-TODAY()))
A104: ※ 진행률은 0~1 사이로 넣으세요. 60%면 0.6 또는 60% 입력.

Sheet 간트차트_일
A1: 간트차트 (일 단위 · 60일)
A3: 기준일 | B3: 46266 | D3: ← 이 날짜부터 그려집니다
E4: =$B$3+0 -> 46266 | F4: =$B$3+1 -> 46267 | G4: =$B$3+2 -> 46268 | H4: =$B$3+3 -> 46269 | I4: =$B$3+4 -> 46270 | J4: =$B$3+5 -> 46271 | K4: =$B$3+6 -> 46272 | L4: =$B$3+7 -> 46273 | M4: =$B$3+8 -> 46274 | N4: =$B$3+9 -> 46275 | O4: =$B$3+10 -> 46276 | P4: =$B$3+11 -> 46277 | Q4: =$B$3+12 -> 46278 | R4: =$B$3+13 -> 46279 | S4: =$B$3+14 -> 46280 | T4: =$B$3+15 -> 46281 | U4: =$B$3+16 -> 46282 | V4: =$B$3+17 -> 46283 | W4: =$B$3+18 -> 46284 | X4: =$B$3+19 -> 46285 | Y4: =$B$3+20 -> 46286 | Z4: =$B$3+21 -> 46287 | AA4: =$B$3+22 -> 46288 | AB4: =$B$3+23 -> 46289 | AC4: =$B$3+24 -> 46290 | AD4: =$B$3+25 -> 46291 | AE4: =$B$3+26 -> 46292 | AF4: =$B$3+27 -> 46293 | AG4: =$B$3+28 -> 46294 | AH4: =$B$3+29 -> 46295 | AI4: =$B$3+30 -> 46296 | AJ4: =$B$3+31 -> 46297 | AK4: =$B$3+32 -> 46298 | AL4: =$B$3+33 -> 46299 | AM4: =$B$3+34 -> 46300 | AN4: =$B$3+35 -> 46301 | AO4: =$B$3+36 -> 46302 | AP4: =$B$3+37 -> 46303 | AQ4: =$B$3+38 -> 46304 | AR4: =$B$3+39 -> 46305 | AS4: =$B$3+40 -> 46306 | AT4: =$B$3+41 -> 46307 | AU4: =$B$3+42 -> 46308 | AV4: =$B$3+43 -> 46309 | AW4: =$B$3+44 -> 46310 | AX4: =$B$3+45 -> 46311 | AY4: =$B$3+46 -> 46312 | AZ4: =$B$3+47 -> 46313 | BA4: =$B$3+48 -> 46314 | BB4: =$B$3+49 -> 46315 | BC4: =$B$3+50 -> 46316 | BD4: =$B$3+51 -> 46317 | BE4: =$B$3+52 -> 46318 | BF4: =$B$3+53 -> 46319 | BG4: =$B$3+54 -> 46320 | BH4: =$B$3+55 -> 46321 | BI4: =$B$3+56 -> 46322 | BJ4: =$B$3+57 -> 46323 | BK4: =$B$3+58 -> 46324 | BL4: =$B$3+59 -> 46325
A5: 작업명 | B5: 담당자 | C5: 시작 | D5: 종료 | E5: =$B$3+0 -> 46266 | F5: =$B$3+1 -> 46267 | G5: =$B$3+2 -> 46268 | H5: =$B$3+3 -> 46269 | I5: =$B$3+4 -> 46270 | J5: =$B$3+5 -> 46271 | K5: =$B$3+6 -> 46272 | L5: =$B$3+7 -> 46273 | M5: =$B$3+8 -> 46274 | N5: =$B$3+9 -> 46275 | O5: =$B$3+10 -> 46276 | P5: =$B$3+11 -> 46277 | Q5: =$B$3+12 -> 46278 | R5: =$B$3+13 -> 46279 | S5: =$B$3+14 -> 46280 | T5: =$B$3+15 -> 46281 | U5: =$B$3+16 -> 46282 | V5: =$B$3+17 -> 46283 | W5: =$B$3+18 -> 46284 | X5: =$B$3+19 -> 46285 | Y5: =$B$3+20 -> 46286 | Z5: =$B$3+21 -> 46287 | AA5: =$B$3+22 -> 46288 | AB5: =$B$3+23 -> 46289 | AC5: =$B$3+24 -> 46290 | AD5: =$B$3+25 -> 46291 | AE5: =$B$3+26 -> 46292 | AF5: =$B$3+27 -> 46293 | AG5: =$B$3+28 -> 46294 | AH5: =$B$3+29 -> 46295 | AI5: =$B$3+30 -> 46296 | AJ5: =$B$3+31 -> 46297 | AK5: =$B$3+32 -> 46298 | AL5: =$B$3+33 -> 46299 | AM5: =$B$3+34 -> 46300 | AN5: =$B$3+35 -> 46301 | AO5: =$B$3+36 -> 46302 | AP5: =$B$3+37 -> 46303 | AQ5: =$B$3+38 -> 46304 | AR5: =$B$3+39 -> 46305 | AS5: =$B$3+40 -> 46306 | AT5: =$B$3+41 -> 46307 | AU5: =$B$3+42 -> 46308 | AV5: =$B$3+43 -> 46309 | AW5: =$B$3+44 -> 46310 | AX5: =$B$3+45 -> 46311 | AY5: =$B$3+46 -> 46312 | AZ5: =$B$3+47 -> 46313 | BA5: =$B$3+48 -> 46314 | BB5: =$B$3+49 -> 46315 | BC5: =$B$3+50 -> 46316 | BD5: =$B$3+51 -> 46317 | BE5: =$B$3+52 -> 46318 | BF5: =$B$3+53 -> 46319 | BG5: =$B$3+54 -> 46320 | BH5: =$B$3+55 -> 46321 | BI5: =$B$3+56 -> 46322 | BJ5: =$B$3+57 -> 46323 | BK5: =$B$3+58 -> 46324 | BL5: =$B$3+59 -> 46325
A6: =IF(작업목록!$C3="","",작업목록!$C3) -> 요구사항 정리 | B6: =IF($A6="","",작업목록!$D3) -> 김담당 | C6: =IF($A6="","",작업목록!$E3) -> 46266 | D6: =IF($A6="","",작업목록!$F3) -> 46275
A7: =IF(작업목록!$C4="","",작업목록!$C4) -> 화면 설계 | B7: =IF($A7="","",작업목록!$D4) -> 박담당 | C7: =IF($A7="","",작업목록!$E4) -> 46273 | D7: =IF($A7="","",작업목록!$F4) -> 46285
A8: =IF(작업목록!$C5="","",작업목록!$C5) -> 백엔드 구축 | B8: =IF($A8="","",작업목록!$D5) -> 이담당 | C8: =IF($A8="","",작업목록!$E5) -> 46280 | D8: =IF($A8="","",작업목록!$F5) -> 46310
A9: =IF(작업목록!$C6="","",작업목록!$C6) -> 프론트 구축 | B9: =IF($A9="","",작업목록!$D6) -> 이담당 | C9: =IF($A9="","",작업목록!$E6) -> 46290 | D9: =IF($A9="","",작업목록!$F6) -> 46320
A10: =IF(작업목록!$C7="","",작업목록!$C7) -> 통합 테스트 | B10: =IF($A10="","",작업목록!$D7) -> 김담당 | C10: =IF($A10="","",작업목록!$E7) -> 46315 | D10: =IF($A10="","",작업목록!$F7) -> 46325
A11: =IF(작업목록!$C8="","",작업목록!$C8) -> 테스트 시나리오 작성 | B11: =IF($A11="","",작업목록!$D8) -> 박담당 | C11: =IF($A11="","",작업목록!$E8) -> 46254 | D11: =IF($A11="","",작업목록!$F8) -> 46270
A12: =IF(작업목록!$C9="","",작업목록!$C9) | B12: =IF($A12="","",작업목록!$D9) | C12: =IF($A12="","",작업목록!$E9) | D12: =IF($A12="","",작업목록!$F9)
A13: =IF(작업목록!$C10="","",작업목록!$C10) | B13: =IF($A13="","",작업목록!$D10) | C13: =IF($A13="","",작업목록!$E10) | D13: =IF($A13="","",작업목록!$F10)
A14: =IF(작업목록!$C11="","",작업목록!$C11) | B14: =IF($A14="","",작업목록!$D11) | C14: =IF($A14="","",작업목록!$E11) | D14: =IF($A14="","",작업목록!$F11)
A15: =IF(작업목록!$C12="","",작업목록!$C12) | B15: =IF($A15="","",작업목록!$D12) | C15: =IF($A15="","",작업목록!$E12) | D15: =IF($A15="","",작업목록!$F12)
A16: =IF(작업목록!$C13="","",작업목록!$C13) | B16: =IF($A16="","",작업목록!$D13) | C16: =IF($A16="","",작업목록!$E13) | D16: =IF($A16="","",작업목록!$F13)
A17: =IF(작업목록!$C14="","",작업목록!$C14) | B17: =IF($A17="","",작업목록!$D14) | C17: =IF($A17="","",작업목록!$E14) | D17: =IF($A17="","",작업목록!$F14)
... A105: =IF(작업목록!$C102="","",작업목록!$C102) | B105: =IF($A105="","",작업목록!$D102) | C105: =IF($A105="","",작업목록!$E102) | D105: =IF($A105="","",작업목록!$F102)
A107: ※ 파랑=진행/예정, 회색=완료, 빨강=지연, 노랑 세로줄=오늘

Sheet 간트차트_주
A1: 간트차트 (주 단위 · 26주)
A3: 기준일 | B3: 46266 | D3: ← 이 날짜부터 그려집니다
E4: =$B$3+0 -> 46266 | F4: =$B$3+7 -> 46273 | G4: =$B$3+14 -> 46280 | H4: =$B$3+21 -> 46287 | I4: =$B$3+28 -> 46294 | J4: =$B$3+35 -> 46301 | K4: =$B$3+42 -> 46308 | L4: =$B$3+49 -> 46315 | M4: =$B$3+56 -> 46322 | N4: =$B$3+63 -> 46329 | O4: =$B$3+70 -> 46336 | P4: =$B$3+77 -> 46343 | Q4: =$B$3+84 -> 46350 | R4: =$B$3+91 -> 46357 | S4: =$B$3+98 -> 46364 | T4: =$B$3+105 -> 46371 | U4: =$B$3+112 -> 46378 | V4: =$B$3+119 -> 46385 | W4: =$B$3+126 -> 46392 | X4: =$B$3+133 -> 46399 | Y4: =$B$3+140 -> 46406 | Z4: =$B$3+147 -> 46413 | AA4: =$B$3+154 -> 46420 | AB4: =$B$3+161 -> 46427 | AC4: =$B$3+168 -> 46434 | AD4: =$B$3+175 -> 46441
A5: 작업명 | B5: 담당자 | C5: 시작 | D5: 종료 | E5: =$B$3+0 -> 46266 | F5: =$B$3+7 -> 46273 | G5: =$B$3+14 -> 46280 | H5: =$B$3+21 -> 46287 | I5: =$B$3+28 -> 46294 | J5: =$B$3+35 -> 46301 | K5: =$B$3+42 -> 46308 | L5: =$B$3+49 -> 46315 | M5: =$B$3+56 -> 46322 | N5: =$B$3+63 -> 46329 | O5: =$B$3+70 -> 46336 | P5: =$B$3+77 -> 46343 | Q5: =$B$3+84 -> 46350 | R5: =$B$3+91 -> 46357 | S5: =$B$3+98 -> 46364 | T5: =$B$3+105 -> 46371 | U5: =$B$3+112 -> 46378 | V5: =$B$3+119 -> 46385 | W5: =$B$3+126 -> 46392 | X5: =$B$3+133 -> 46399 | Y5: =$B$3+140 -> 46406 | Z5: =$B$3+147 -> 46413 | AA5: =$B$3+154 -> 46420 | AB5: =$B$3+161 -> 46427 | AC5: =$B$3+168 -> 46434 | AD5: =$B$3+175 -> 46441
A6: =IF(작업목록!$C3="","",작업목록!$C3) -> 요구사항 정리 | B6: =IF($A6="","",작업목록!$D3) -> 김담당 | C6: =IF($A6="","",작업목록!$E3) -> 46266 | D6: =IF($A6="","",작업목록!$F3) -> 46275
A7: =IF(작업목록!$C4="","",작업목록!$C4) -> 화면 설계 | B7: =IF($A7="","",작업목록!$D4) -> 박담당 | C7: =IF($A7="","",작업목록!$E4) -> 46273 | D7: =IF($A7="","",작업목록!$F4) -> 46285
A8: =IF(작업목록!$C5="","",작업목록!$C5) -> 백엔드 구축 | B8: =IF($A8="","",작업목록!$D5) -> 이담당 | C8: =IF($A8="","",작업목록!$E5) -> 46280 | D8: =IF($A8="","",작업목록!$F5) -> 46310
A9: =IF(작업목록!$C6="","",작업목록!$C6) -> 프론트 구축 | B9: =IF($A9="","",작업목록!$D6) -> 이담당 | C9: =IF($A9="","",작업목록!$E6) -> 46290 | D9: =IF($A9="","",작업목록!$F6) -> 46320
A10: =IF(작업목록!$C7="","",작업목록!$C7) -> 통합 테스트 | B10: =IF($A10="","",작업목록!$D7) -> 김담당 | C10: =IF($A10="","",작업목록!$E7) -> 46315 | D10: =IF($A10="","",작업목록!$F7) -> 46325
A11: =IF(작업목록!$C8="","",작업목록!$C8) -> 테스트 시나리오 작성 | B11: =IF($A11="","",작업목록!$D8) -> 박담당 | C11: =IF($A11="","",작업목록!$E8) -> 46254 | D11: =IF($A11="","",작업목록!$F8) -> 46270
A12: =IF(작업목록!$C9="","",작업목록!$C9) | B12: =IF($A12="","",작업목록!$D9) | C12: =IF($A12="","",작업목록!$E9) | D12: =IF($A12="","",작업목록!$F9)
A13: =IF(작업목록!$C10="","",작업목록!$C10) | B13: =IF($A13="","",작업목록!$D10) | C13: =IF($A13="","",작업목록!$E10) | D13: =IF($A13="","",작업목록!$F10)
A14: =IF(작업목록!$C11="","",작업목록!$C11) | B14: =IF($A14="","",작업목록!$D11) | C14: =IF($A14="","",작업목록!$E11) | D14: =IF($A14="","",작업목록!$F11)
A15: =IF(작업목록!$C12="","",작업목록!$C12) | B15: =IF($A15="","",작업목록!$D12) | C15: =IF($A15="","",작업목록!$E12) | D15: =IF($A15="","",작업목록!$F12)
A16: =IF(작업목록!$C13="","",작업목록!$C13) | B16: =IF($A16="","",작업목록!$D13) | C16: =IF($A16="","",작업목록!$E13) | D16: =IF($A16="","",작업목록!$F13)
A17: =IF(작업목록!$C14="","",작업목록!$C14) | B17: =IF($A17="","",작업목록!$D14) | C17: =IF($A17="","",작업목록!$E14) | D17: =IF($A17="","",작업목록!$F14)
... A105: =IF(작업목록!$C102="","",작업목록!$C102) | B105: =IF($A105="","",작업목록!$D102) | C105: =IF($A105="","",작업목록!$E102) | D105: =IF($A105="","",작업목록!$F102)
A107: ※ 한 칸이 7일입니다. 기준일이 속한 주부터 그려집니다.

Sheet 담당자별현황
A1: 담당자별현황
A3: 담당자 | B3: 소속 | C3: 작업 수 | D3: 완료 | E3: 진행중 | F3: 지연 | G3: 평균 진행률
A4: =IF(담당자목록!$A3="","",담당자목록!$A3) -> 김담당 | B4: =IF($A4="","",담당자목록!$B3) -> 기획팀 | C4: =IF($A4="","",COUNTIFS(작업목록!$D$3:$D$102,$A4)) -> 2 | D4: =IF($A4="","",COUNTIFS(작업목록!$D$3:$D$102,$A4,작업목록!$I$3:$I$102,"완료")) -> 1 | E4: =IF($A4="","",COUNTIFS(작업목록!$D$3:$D$102,$A4,작업목록!$I$3:$I$102,"진행중")) -> 0 | F4: =IF($A4="","",COUNTIFS(작업목록!$D$3:$D$102,$A4,작업목록!$I$3:$I$102,"지연")) -> 0 | G4: =IF($A4="","",IF($C4=0,"",ROUND(SUMIFS(작업목록!$H$3:$H$102,작업목록!$D$3:$D$102,$A4)/$C4,3))) -> 0.5
A5: =IF(담당자목록!$A4="","",담당자목록!$A4) -> 이담당 | B5: =IF($A5="","",담당자목록!$B4) -> 개발팀 | C5: =IF($A5="","",COUNTIFS(작업목록!$D$3:$D$102,$A5)) -> 2 | D5: =IF($A5="","",COUNTIFS(작업목록!$D$3:$D$102,$A5,작업목록!$I$3:$I$102,"완료")) -> 0 | E5: =IF($A5="","",COUNTIFS(작업목록!$D$3:$D$102,$A5,작업목록!$I$3:$I$102,"진행중")) -> 0 | F5: =IF($A5="","",COUNTIFS(작업목록!$D$3:$D$102,$A5,작업목록!$I$3:$I$102,"지연")) -> 0 | G5: =IF($A5="","",IF($C5=0,"",ROUND(SUMIFS(작업목록!$H$3:$H$102,작업목록!$D$3:$D$102,$A5)/$C5,3))) -> 0.1
A6: =IF(담당자목록!$A5="","",담당자목록!$A5) -> 박담당 | B6: =IF($A6="","",담당자목록!$B5) -> 디자인팀 | C6: =IF($A6="","",COUNTIFS(작업목록!$D$3:$D$102,$A6)) -> 2 | D6: =IF($A6="","",COUNTIFS(작업목록!$D$3:$D$102,$A6,작업목록!$I$3:$I$102,"완료")) -> 0 | E6: =IF($A6="","",COUNTIFS(작업목록!$D$3:$D$102,$A6,작업목록!$I$3:$I$102,"진행중")) -> 1 | F6: =IF($A6="","",COUNTIFS(작업목록!$D$3:$D$102,$A6,작업목록!$I$3:$I$102,"지연")) -> 1 | G6: =IF($A6="","",IF($C6=0,"",ROUND(SUMIFS(작업목록!$H$3:$H$102,작업목록!$D$3:$D$102,$A6)/$C6,3))) -> 0.65
A7: =IF(담당자목록!$A6="","",담당자목록!$A6) | B7: =IF($A7="","",담당자목록!$B6) | C7: =IF($A7="","",COUNTIFS(작업목록!$D$3:$D$102,$A7)) | D7: =IF($A7="","",COUNTIFS(작업목록!$D$3:$D$102,$A7,작업목록!$I$3:$I$102,"완료")) | E7: =IF($A7="","",COUNTIFS(작업목록!$D$3:$D$102,$A7,작업목록!$I$3:$I$102,"진행중")) | F7: =IF($A7="","",COUNTIFS(작업목록!$D$3:$D$102,$A7,작업목록!$I$3:$I$102,"지연")) | G7: =IF($A7="","",IF($C7=0,"",ROUND(SUMIFS(작업목록!$H$3:$H$102,작업목록!$D$3:$D$102,$A7)/$C7,3)))
A8: =IF(담당자목록!$A7="","",담당자목록!$A7) | B8: =IF($A8="","",담당자목록!$B7) | C8: =IF($A8="","",COUNTIFS(작업목록!$D$3:$D$102,$A8)) | D8: =IF($A8="","",COUNTIFS(작업목록!$D$3:$D$102,$A8,작업목록!$I$3:$I$102,"완료")) | E8: =IF($A8="","",COUNTIFS(작업목록!$D$3:$D$102,$A8,작업목록!$I$3:$I$102,"진행중")) | F8: =IF($A8="","",COUNTIFS(작업목록!$D$3:$D$102,$A8,작업목록!$I$3:$I$102,"지연")) | G8: =IF($A8="","",IF($C8=0,"",ROUND(SUMIFS(작업목록!$H$3:$H$102,작업목록!$D$3:$D$102,$A8)/$C8,3)))
A9: =IF(담당자목록!$A8="","",담당자목록!$A8) | B9: =IF($A9="","",담당자목록!$B8) | C9: =IF($A9="","",COUNTIFS(작업목록!$D$3:$D$102,$A9)) | D9: =IF($A9="","",COUNTIFS(작업목록!$D$3:$D$102,$A9,작업목록!$I$3:$I$102,"완료")) | E9: =IF($A9="","",COUNTIFS(작업목록!$D$3:$D$102,$A9,작업목록!$I$3:$I$102,"진행중")) | F9: =IF($A9="","",COUNTIFS(작업목록!$D$3:$D$102,$A9,작업목록!$I$3:$I$102,"지연")) | G9: =IF($A9="","",IF($C9=0,"",ROUND(SUMIFS(작업목록!$H$3:$H$102,작업목록!$D$3:$D$102,$A9)/$C9,3)))
A10: =IF(담당자목록!$A9="","",담당자목록!$A9) | B10: =IF($A10="","",담당자목록!$B9) | C10: =IF($A10="","",COUNTIFS(작업목록!$D$3:$D$102,$A10)) | D10: =IF($A10="","",COUNTIFS(작업목록!$D$3:$D$102,$A10,작업목록!$I$3:$I$102,"완료")) | E10: =IF($A10="","",COUNTIFS(작업목록!$D$3:$D$102,$A10,작업목록!$I$3:$I$102,"진행중")) | F10: =IF($A10="","",COUNTIFS(작업목록!$D$3:$D$102,$A10,작업목록!$I$3:$I$102,"지연")) | G10: =IF($A10="","",IF($C10=0,"",ROUND(SUMIFS(작업목록!$H$3:$H$102,작업목록!$D$3:$D$102,$A10)/$C10,3)))
A11: =IF(담당자목록!$A10="","",담당자목록!$A10) | B11: =IF($A11="","",담당자목록!$B10) | C11: =IF($A11="","",COUNTIFS(작업목록!$D$3:$D$102,$A11)) | D11: =IF($A11="","",COUNTIFS(작업목록!$D$3:$D$102,$A11,작업목록!$I$3:$I$102,"완료")) | E11: =IF($A11="","",COUNTIFS(작업목록!$D$3:$D$102,$A11,작업목록!$I$3:$I$102,"진행중")) | F11: =IF($A11="","",COUNTIFS(작업목록!$D$3:$D$102,$A11,작업목록!$I$3:$I$102,"지연")) | G11: =IF($A11="","",IF($C11=0,"",ROUND(SUMIFS(작업목록!$H$3:$H$102,작업목록!$D$3:$D$102,$A11)/$C11,3)))
A12: =IF(담당자목록!$A11="","",담당자목록!$A11) | B12: =IF($A12="","",담당자목록!$B11) | C12: =IF($A12="","",COUNTIFS(작업목록!$D$3:$D$102,$A12)) | D12: =IF($A12="","",COUNTIFS(작업목록!$D$3:$D$102,$A12,작업목록!$I$3:$I$102,"완료")) | E12: =IF($A12="","",COUNTIFS(작업목록!$D$3:$D$102,$A12,작업목록!$I$3:$I$102,"진행중")) | F12: =IF($A12="","",COUNTIFS(작업목록!$D$3:$D$102,$A12,작업목록!$I$3:$I$102,"지연")) | G12: =IF($A12="","",IF($C12=0,"",ROUND(SUMIFS(작업목록!$H$3:$H$102,작업목록!$D$3:$D$102,$A12)/$C12,3)))
A13: =IF(담당자목록!$A12="","",담당자목록!$A12) | B13: =IF($A13="","",담당자목록!$B12) | C13: =IF($A13="","",COUNTIFS(작업목록!$D$3:$D$102,$A13)) | D13: =IF($A13="","",COUNTIFS(작업목록!$D$3:$D$102,$A13,작업목록!$I$3:$I$102,"완료")) | E13: =IF($A13="","",COUNTIFS(작업목록!$D$3:$D$102,$A13,작업목록!$I$3:$I$102,"진행중")) | F13: =IF($A13="","",COUNTIFS(작업목록!$D$3:$D$102,$A13,작업목록!$I$3:$I$102,"지연")) | G13: =IF($A13="","",IF($C13=0,"",ROUND(SUMIFS(작업목록!$H$3:$H$102,작업목록!$D$3:$D$102,$A13)/$C13,3)))
A14: =IF(담당자목록!$A13="","",담당자목록!$A13) | B14: =IF($A14="","",담당자목록!$B13) | C14: =IF($A14="","",COUNTIFS(작업목록!$D$3:$D$102,$A14)) | D14: =IF($A14="","",COUNTIFS(작업목록!$D$3:$D$102,$A14,작업목록!$I$3:$I$102,"완료")) | E14: =IF($A14="","",COUNTIFS(작업목록!$D$3:$D$102,$A14,작업목록!$I$3:$I$102,"진행중")) | F14: =IF($A14="","",COUNTIFS(작업목록!$D$3:$D$102,$A14,작업목록!$I$3:$I$102,"지연")) | G14: =IF($A14="","",IF($C14=0,"",ROUND(SUMIFS(작업목록!$H$3:$H$102,작업목록!$D$3:$D$102,$A14)/$C14,3)))
A15: =IF(담당자목록!$A14="","",담당자목록!$A14) | B15: =IF($A15="","",담당자목록!$B14) | C15: =IF($A15="","",COUNTIFS(작업목록!$D$3:$D$102,$A15)) | D15: =IF($A15="","",COUNTIFS(작업목록!$D$3:$D$102,$A15,작업목록!$I$3:$I$102,"완료")) | E15: =IF($A15="","",COUNTIFS(작업목록!$D$3:$D$102,$A15,작업목록!$I$3:$I$102,"진행중")) | F15: =IF($A15="","",COUNTIFS(작업목록!$D$3:$D$102,$A15,작업목록!$I$3:$I$102,"지연")) | G15: =IF($A15="","",IF($C15=0,"",ROUND(SUMIFS(작업목록!$H$3:$H$102,작업목록!$D$3:$D$102,$A15)/$C15,3)))
... A103: =IF(담당자목록!$A102="","",담당자목록!$A102) | B103: =IF($A103="","",담당자목록!$B102) | C103: =IF($A103="","",COUNTIFS(작업목록!$D$3:$D$102,$A103)) | D103: =IF($A103="","",COUNTIFS(작업목록!$D$3:$D$102,$A103,작업목록!$I$3:$I$102,"완료")) | E103: =IF($A103="","",COUNTIFS(작업목록!$D$3:$D$102,$A103,작업목록!$I$3:$I$102,"진행중")) | F103: =IF($A103="","",COUNTIFS(작업목록!$D$3:$D$102,$A103,작업목록!$I$3:$I$102,"지연")) | G103: =IF($A103="","",IF($C103=0,"",ROUND(SUMIFS(작업목록!$H$3:$H$102,작업목록!$D$3:$D$102,$A103)/$C103,3)))
B105: 합계 | C105: =SUM(C4:C103) -> 6 | D105: =SUM(D4:D103) -> 1 | E105: =SUM(E4:E103) -> 1 | F105: =SUM(F4:F103) -> 1

Sheet 지연현황
A1: 지연현황 (종료일이 지났는데 안 끝난 작업)
A3: 지연 작업 수 | B3: =COUNTIF(작업목록!$I$3:$I$102,"지연") -> 1 | D3: 오늘 | E3: =TODAY() -> 46279
A5: 순번 | B5: 구분 | C5: 작업명 | D5: 담당자 | E5: 종료일 | F5: 지연일수 | G5: 진행률 | I5: 대상(자동) | J5: 순번(자동) | K5: 키(자동)
A6: =IF($C6="","",1) -> 1 | B6: =IFERROR(INDEX(작업목록!$B$3:$B$102,MATCH("R"&1,지연현황!$K$6:$K$105,0)),"") -> 검수 | C6: =IFERROR(INDEX(작업목록!$C$3:$C$102,MATCH("R"&1,지연현황!$K$6:$K$105,0)),"") -> 테스트 시나리오 작성 | D6: =IF($C6="","",IFERROR(INDEX(작업목록!$D$3:$D$102,MATCH("R"&1,지연현황!$K$6:$K$105,0)),"")) -> 박담당 | E6: =IF($C6="","",IFERROR(INDEX(작업목록!$F$3:$F$102,MATCH("R"&1,지연현황!$K$6:$K$105,0)),"")) -> 46270 | F6: =IF($E6="","",TODAY()-$E6) -> 9 | G6: =IF($C6="","",IFERROR(INDEX(작업목록!$H$3:$H$102,MATCH("R"&1,지연현황!$K$6:$K$105,0)),"")) -> 0.7 | I6: =IF(작업목록!$C3="",FALSE(),작업목록!$I3="지연") -> FALSE | J6: =IF($I6=FALSE(),"",COUNTIF($I$6:$I6,TRUE())) | K6: =IF($J6="","","R"&$J6)
A7: =IF($C7="","",2) | B7: =IFERROR(INDEX(작업목록!$B$3:$B$102,MATCH("R"&2,지연현황!$K$6:$K$105,0)),"") | C7: =IFERROR(INDEX(작업목록!$C$3:$C$102,MATCH("R"&2,지연현황!$K$6:$K$105,0)),"") | D7: =IF($C7="","",IFERROR(INDEX(작업목록!$D$3:$D$102,MATCH("R"&2,지연현황!$K$6:$K$105,0)),"")) | E7: =IF($C7="","",IFERROR(INDEX(작업목록!$F$3:$F$102,MATCH("R"&2,지연현황!$K$6:$K$105,0)),"")) | F7: =IF($E7="","",TODAY()-$E7) | G7: =IF($C7="","",IFERROR(INDEX(작업목록!$H$3:$H$102,MATCH("R"&2,지연현황!$K$6:$K$105,0)),"")) | I7: =IF(작업목록!$C4="",FALSE(),작업목록!$I4="지연") -> FALSE | J7: =IF($I7=FALSE(),"",COUNTIF($I$6:$I7,TRUE())) | K7: =IF($J7="","","R"&$J7)
A8: =IF($C8="","",3) | B8: =IFERROR(INDEX(작업목록!$B$3:$B$102,MATCH("R"&3,지연현황!$K$6:$K$105,0)),"") | C8: =IFERROR(INDEX(작업목록!$C$3:$C$102,MATCH("R"&3,지연현황!$K$6:$K$105,0)),"") | D8: =IF($C8="","",IFERROR(INDEX(작업목록!$D$3:$D$102,MATCH("R"&3,지연현황!$K$6:$K$105,0)),"")) | E8: =IF($C8="","",IFERROR(INDEX(작업목록!$F$3:$F$102,MATCH("R"&3,지연현황!$K$6:$K$105,0)),"")) | F8: =IF($E8="","",TODAY()-$E8) | G8: =IF($C8="","",IFERROR(INDEX(작업목록!$H$3:$H$102,MATCH("R"&3,지연현황!$K$6:$K$105,0)),"")) | I8: =IF(작업목록!$C5="",FALSE(),작업목록!$I5="지연") -> FALSE | J8: =IF($I8=FALSE(),"",COUNTIF($I$6:$I8,TRUE())) | K8: =IF($J8="","","R"&$J8)
A9: =IF($C9="","",4) | B9: =IFERROR(INDEX(작업목록!$B$3:$B$102,MATCH("R"&4,지연현황!$K$6:$K$105,0)),"") | C9: =IFERROR(INDEX(작업목록!$C$3:$C$102,MATCH("R"&4,지연현황!$K$6:$K$105,0)),"") | D9: =IF($C9="","",IFERROR(INDEX(작업목록!$D$3:$D$102,MATCH("R"&4,지연현황!$K$6:$K$105,0)),"")) | E9: =IF($C9="","",IFERROR(INDEX(작업목록!$F$3:$F$102,MATCH("R"&4,지연현황!$K$6:$K$105,0)),"")) | F9: =IF($E9="","",TODAY()-$E9) | G9: =IF($C9="","",IFERROR(INDEX(작업목록!$H$3:$H$102,MATCH("R"&4,지연현황!$K$6:$K$105,0)),"")) | I9: =IF(작업목록!$C6="",FALSE(),작업목록!$I6="지연") -> FALSE | J9: =IF($I9=FALSE(),"",COUNTIF($I$6:$I9,TRUE())) | K9: =IF($J9="","","R"&$J9)
A10: =IF($C10="","",5) | B10: =IFERROR(INDEX(작업목록!$B$3:$B$102,MATCH("R"&5,지연현황!$K$6:$K$105,0)),"") | C10: =IFERROR(INDEX(작업목록!$C$3:$C$102,MATCH("R"&5,지연현황!$K$6:$K$105,0)),"") | D10: =IF($C10="","",IFERROR(INDEX(작업목록!$D$3:$D$102,MATCH("R"&5,지연현황!$K$6:$K$105,0)),"")) | E10: =IF($C10="","",IFERROR(INDEX(작업목록!$F$3:$F$102,MATCH("R"&5,지연현황!$K$6:$K$105,0)),"")) | F10: =IF($E10="","",TODAY()-$E10) | G10: =IF($C10="","",IFERROR(INDEX(작업목록!$H$3:$H$102,MATCH("R"&5,지연현황!$K$6:$K$105,0)),"")) | I10: =IF(작업목록!$C7="",FALSE(),작업목록!$I7="지연") -> FALSE | J10: =IF($I10=FALSE(),"",COUNTIF($I$6:$I10,TRUE())) | K10: =IF($J10="","","R"&$J10)
A11: =IF($C11="","",6) | B11: =IFERROR(INDEX(작업목록!$B$3:$B$102,MATCH("R"&6,지연현황!$K$6:$K$105,0)),"") | C11: =IFERROR(INDEX(작업목록!$C$3:$C$102,MATCH("R"&6,지연현황!$K$6:$K$105,0)),"") | D11: =IF($C11="","",IFERROR(INDEX(작업목록!$D$3:$D$102,MATCH("R"&6,지연현황!$K$6:$K$105,0)),"")) | E11: =IF($C11="","",IFERROR(INDEX(작업목록!$F$3:$F$102,MATCH("R"&6,지연현황!$K$6:$K$105,0)),"")) | F11: =IF($E11="","",TODAY()-$E11) | G11: =IF($C11="","",IFERROR(INDEX(작업목록!$H$3:$H$102,MATCH("R"&6,지연현황!$K$6:$K$105,0)),"")) | I11: =IF(작업목록!$C8="",FALSE(),작업목록!$I8="지연") -> TRUE | J11: =IF($I11=FALSE(),"",COUNTIF($I$6:$I11,TRUE())) -> 1 | K11: =IF($J11="","","R"&$J11) -> R1
A12: =IF($C12="","",7) | B12: =IFERROR(INDEX(작업목록!$B$3:$B$102,MATCH("R"&7,지연현황!$K$6:$K$105,0)),"") | C12: =IFERROR(INDEX(작업목록!$C$3:$C$102,MATCH("R"&7,지연현황!$K$6:$K$105,0)),"") | D12: =IF($C12="","",IFERROR(INDEX(작업목록!$D$3:$D$102,MATCH("R"&7,지연현황!$K$6:$K$105,0)),"")) | E12: =IF($C12="","",IFERROR(INDEX(작업목록!$F$3:$F$102,MATCH("R"&7,지연현황!$K$6:$K$105,0)),"")) | F12: =IF($E12="","",TODAY()-$E12) | G12: =IF($C12="","",IFERROR(INDEX(작업목록!$H$3:$H$102,MATCH("R"&7,지연현황!$K$6:$K$105,0)),"")) | I12: =IF(작업목록!$C9="",FALSE(),작업목록!$I9="지연") -> FALSE | J12: =IF($I12=FALSE(),"",COUNTIF($I$6:$I12,TRUE())) | K12: =IF($J12="","","R"&$J12)
A13: =IF($C13="","",8) | B13: =IFERROR(INDEX(작업목록!$B$3:$B$102,MATCH("R"&8,지연현황!$K$6:$K$105,0)),"") | C13: =IFERROR(INDEX(작업목록!$C$3:$C$102,MATCH("R"&8,지연현황!$K$6:$K$105,0)),"") | D13: =IF($C13="","",IFERROR(INDEX(작업목록!$D$3:$D$102,MATCH("R"&8,지연현황!$K$6:$K$105,0)),"")) | E13: =IF($C13="","",IFERROR(INDEX(작업목록!$F$3:$F$102,MATCH("R"&8,지연현황!$K$6:$K$105,0)),"")) | F13: =IF($E13="","",TODAY()-$E13) | G13: =IF($C13="","",IFERROR(INDEX(작업목록!$H$3:$H$102,MATCH("R"&8,지연현황!$K$6:$K$105,0)),"")) | I13: =IF(작업목록!$C10="",FALSE(),작업목록!$I10="지연") -> FALSE | J13: =IF($I13=FALSE(),"",COUNTIF($I$6:$I13,TRUE())) | K13: =IF($J13="","","R"&$J13)
A14: =IF($C14="","",9) | B14: =IFERROR(INDEX(작업목록!$B$3:$B$102,MATCH("R"&9,지연현황!$K$6:$K$105,0)),"") | C14: =IFERROR(INDEX(작업목록!$C$3:$C$102,MATCH("R"&9,지연현황!$K$6:$K$105,0)),"") | D14: =IF($C14="","",IFERROR(INDEX(작업목록!$D$3:$D$102,MATCH("R"&9,지연현황!$K$6:$K$105,0)),"")) | E14: =IF($C14="","",IFERROR(INDEX(작업목록!$F$3:$F$102,MATCH("R"&9,지연현황!$K$6:$K$105,0)),"")) | F14: =IF($E14="","",TODAY()-$E14) | G14: =IF($C14="","",IFERROR(INDEX(작업목록!$H$3:$H$102,MATCH("R"&9,지연현황!$K$6:$K$105,0)),"")) | I14: =IF(작업목록!$C11="",FALSE(),작업목록!$I11="지연") -> FALSE | J14: =IF($I14=FALSE(),"",COUNTIF($I$6:$I14,TRUE())) | K14: =IF($J14="","","R"&$J14)
A15: =IF($C15="","",10) | B15: =IFERROR(INDEX(작업목록!$B$3:$B$102,MATCH("R"&10,지연현황!$K$6:$K$105,0)),"") | C15: =IFERROR(INDEX(작업목록!$C$3:$C$102,MATCH("R"&10,지연현황!$K$6:$K$105,0)),"") | D15: =IF($C15="","",IFERROR(INDEX(작업목록!$D$3:$D$102,MATCH("R"&10,지연현황!$K$6:$K$105,0)),"")) | E15: =IF($C15="","",IFERROR(INDEX(작업목록!$F$3:$F$102,MATCH("R"&10,지연현황!$K$6:$K$105,0)),"")) | F15: =IF($E15="","",TODAY()-$E15) | G15: =IF($C15="","",IFERROR(INDEX(작업목록!$H$3:$H$102,MATCH("R"&10,지연현황!$K$6:$K$105,0)),"")) | I15: =IF(작업목록!$C12="",FALSE(),작업목록!$I12="지연") -> FALSE | J15: =IF($I15=FALSE(),"",COUNTIF($I$6:$I15,TRUE())) | K15: =IF($J15="","","R"&$J15)
A16: =IF($C16="","",11) | B16: =IFERROR(INDEX(작업목록!$B$3:$B$102,MATCH("R"&11,지연현황!$K$6:$K$105,0)),"") | C16: =IFERROR(INDEX(작업목록!$C$3:$C$102,MATCH("R"&11,지연현황!$K$6:$K$105,0)),"") | D16: =IF($C16="","",IFERROR(INDEX(작업목록!$D$3:$D$102,MATCH("R"&11,지연현황!$K$6:$K$105,0)),"")) | E16: =IF($C16="","",IFERROR(INDEX(작업목록!$F$3:$F$102,MATCH("R"&11,지연현황!$K$6:$K$105,0)),"")) | F16: =IF($E16="","",TODAY()-$E16) | G16: =IF($C16="","",IFERROR(INDEX(작업목록!$H$3:$H$102,MATCH("R"&11,지연현황!$K$6:$K$105,0)),"")) | I16: =IF(작업목록!$C13="",FALSE(),작업목록!$I13="지연") -> FALSE | J16: =IF($I16=FALSE(),"",COUNTIF($I$6:$I16,TRUE())) | K16: =IF($J16="","","R"&$J16)
A17: =IF($C17="","",12) | B17: =IFERROR(INDEX(작업목록!$B$3:$B$102,MATCH("R"&12,지연현황!$K$6:$K$105,0)),"") | C17: =IFERROR(INDEX(작업목록!$C$3:$C$102,MATCH("R"&12,지연현황!$K$6:$K$105,0)),"") | D17: =IF($C17="","",IFERROR(INDEX(작업목록!$D$3:$D$102,MATCH("R"&12,지연현황!$K$6:$K$105,0)),"")) | E17: =IF($C17="","",IFERROR(INDEX(작업목록!$F$3:$F$102,MATCH("R"&12,지연현황!$K$6:$K$105,0)),"")) | F17: =IF($E17="","",TODAY()-$E17) | G17: =IF($C17="","",IFERROR(INDEX(작업목록!$H$3:$H$102,MATCH("R"&12,지연현황!$K$6:$K$105,0)),"")) | I17: =IF(작업목록!$C14="",FALSE(),작업목록!$I14="지연") -> FALSE | J17: =IF($I17=FALSE(),"",COUNTIF($I$6:$I17,TRUE())) | K17: =IF($J17="","","R"&$J17)
A18: =IF($C18="","",13) | B18: =IFERROR(INDEX(작업목록!$B$3:$B$102,MATCH("R"&13,지연현황!$K$6:$K$105,0)),"") | C18: =IFERROR(INDEX(작업목록!$C$3:$C$102,MATCH("R"&13,지연현황!$K$6:$K$105,0)),"") | D18: =IF($C18="","",IFERROR(INDEX(작업목록!$D$3:$D$102,MATCH("R"&13,지연현황!$K$6:$K$105,0)),"")) | E18: =IF($C18="","",IFERROR(INDEX(작업목록!$F$3:$F$102,MATCH("R"&13,지연현황!$K$6:$K$105,0)),"")) | F18: =IF($E18="","",TODAY()-$E18) | G18: =IF($C18="","",IFERROR(INDEX(작업목록!$H$3:$H$102,MATCH("R"&13,지연현황!$K$6:$K$105,0)),"")) | I18: =IF(작업목록!$C15="",FALSE(),작업목록!$I15="지연") -> FALSE | J18: =IF($I18=FALSE(),"",COUNTIF($I$6:$I18,TRUE())) | K18: =IF($J18="","","R"&$J18)
A19: =IF($C19="","",14) | B19: =IFERROR(INDEX(작업목록!$B$3:$B$102,MATCH("R"&14,지연현황!$K$6:$K$105,0)),"") | C19: =IFERROR(INDEX(작업목록!$C$3:$C$102,MATCH("R"&14,지연현황!$K$6:$K$105,0)),"") | D19: =IF($C19="","",IFERROR(INDEX(작업목록!$D$3:$D$102,MATCH("R"&14,지연현황!$K$6:$K$105,0)),"")) | E19: =IF($C19="","",IFERROR(INDEX(작업목록!$F$3:$F$102,MATCH("R"&14,지연현황!$K$6:$K$105,0)),"")) | F19: =IF($E19="","",TODAY()-$E19) | G19: =IF($C19="","",IFERROR(INDEX(작업목록!$H$3:$H$102,MATCH("R"&14,지연현황!$K$6:$K$105,0)),"")) | I19: =IF(작업목록!$C16="",FALSE(),작업목록!$I16="지연") -> FALSE | J19: =IF($I19=FALSE(),"",COUNTIF($I$6:$I19,TRUE())) | K19: =IF($J19="","","R"&$J19)
A20: =IF($C20="","",15) | B20: =IFERROR(INDEX(작업목록!$B$3:$B$102,MATCH("R"&15,지연현황!$K$6:$K$105,0)),"") | C20: =IFERROR(INDEX(작업목록!$C$3:$C$102,MATCH("R"&15,지연현황!$K$6:$K$105,0)),"") | D20: =IF($C20="","",IFERROR(INDEX(작업목록!$D$3:$D$102,MATCH("R"&15,지연현황!$K$6:$K$105,0)),"")) | E20: =IF($C20="","",IFERROR(INDEX(작업목록!$F$3:$F$102,MATCH("R"&15,지연현황!$K$6:$K$105,0)),"")) | F20: =IF($E20="","",TODAY()-$E20) | G20: =IF($C20="","",IFERROR(INDEX(작업목록!$H$3:$H$102,MATCH("R"&15,지연현황!$K$6:$K$105,0)),"")) | I20: =IF(작업목록!$C17="",FALSE(),작업목록!$I17="지연") -> FALSE | J20: =IF($I20=FALSE(),"",COUNTIF($I$6:$I20,TRUE())) | K20: =IF($J20="","","R"&$J20)
A21: =IF($C21="","",16) | B21: =IFERROR(INDEX(작업목록!$B$3:$B$102,MATCH("R"&16,지연현황!$K$6:$K$105,0)),"") | C21: =IFERROR(INDEX(작업목록!$C$3:$C$102,MATCH("R"&16,지연현황!$K$6:$K$105,0)),"") | D21: =IF($C21="","",IFERROR(INDEX(작업목록!$D$3:$D$102,MATCH("R"&16,지연현황!$K$6:$K$105,0)),"")) | E21: =IF($C21="","",IFERROR(INDEX(작업목록!$F$3:$F$102,MATCH("R"&16,지연현황!$K$6:$K$105,0)),"")) | F21: =IF($E21="","",TODAY()-$E21) | G21: =IF($C21="","",IFERROR(INDEX(작업목록!$H$3:$H$102,MATCH("R"&16,지연현황!$K$6:$K$105,0)),"")) | I21: =IF(작업목록!$C18="",FALSE(),작업목록!$I18="지연") -> FALSE | J21: =IF($I21=FALSE(),"",COUNTIF($I$6:$I21,TRUE())) | K21: =IF($J21="","","R"&$J21)
A22: =IF($C22="","",17) | B22: =IFERROR(INDEX(작업목록!$B$3:$B$102,MATCH("R"&17,지연현황!$K$6:$K$105,0)),"") | C22: =IFERROR(INDEX(작업목록!$C$3:$C$102,MATCH("R"&17,지연현황!$K$6:$K$105,0)),"") | D22: =IF($C22="","",IFERROR(INDEX(작업목록!$D$3:$D$102,MATCH("R"&17,지연현황!$K$6:$K$105,0)),"")) | E22: =IF($C22="","",IFERROR(INDEX(작업목록!$F$3:$F$102,MATCH("R"&17,지연현황!$K$6:$K$105,0)),"")) | F22: =IF($E22="","",TODAY()-$E22) | G22: =IF($C22="","",IFERROR(INDEX(작업목록!$H$3:$H$102,MATCH("R"&17,지연현황!$K$6:$K$105,0)),"")) | I22: =IF(작업목록!$C19="",FALSE(),작업목록!$I19="지연") -> FALSE | J22: =IF($I22=FALSE(),"",COUNTIF($I$6:$I22,TRUE())) | K22: =IF($J22="","","R"&$J22)
A23: =IF($C23="","",18) | B23: =IFERROR(INDEX(작업목록!$B$3:$B$102,MATCH("R"&18,지연현황!$K$6:$K$105,0)),"") | C23: =IFERROR(INDEX(작업목록!$C$3:$C$102,MATCH("R"&18,지연현황!$K$6:$K$105,0)),"") | D23: =IF($C23="","",IFERROR(INDEX(작업목록!$D$3:$D$102,MATCH("R"&18,지연현황!$K$6:$K$105,0)),"")) | E23: =IF($C23="","",IFERROR(INDEX(작업목록!$F$3:$F$102,MATCH("R"&18,지연현황!$K$6:$K$105,0)),"")) | F23: =IF($E23="","",TODAY()-$E23) | G23: =IF($C23="","",IFERROR(INDEX(작업목록!$H$3:$H$102,MATCH("R"&18,지연현황!$K$6:$K$105,0)),"")) | I23: =IF(작업목록!$C20="",FALSE(),작업목록!$I20="지연") -> FALSE | J23: =IF($I23=FALSE(),"",COUNTIF($I$6:$I23,TRUE())) | K23: =IF($J23="","","R"&$J23)
A24: =IF($C24="","",19) | B24: =IFERROR(INDEX(작업목록!$B$3:$B$102,MATCH("R"&19,지연현황!$K$6:$K$105,0)),"") | C24: =IFERROR(INDEX(작업목록!$C$3:$C$102,MATCH("R"&19,지연현황!$K$6:$K$105,0)),"") | D24: =IF($C24="","",IFERROR(INDEX(작업목록!$D$3:$D$102,MATCH("R"&19,지연현황!$K$6:$K$105,0)),"")) | E24: =IF($C24="","",IFERROR(INDEX(작업목록!$F$3:$F$102,MATCH("R"&19,지연현황!$K$6:$K$105,0)),"")) | F24: =IF($E24="","",TODAY()-$E24) | G24: =IF($C24="","",IFERROR(INDEX(작업목록!$H$3:$H$102,MATCH("R"&19,지연현황!$K$6:$K$105,0)),"")) | I24: =IF(작업목록!$C21="",FALSE(),작업목록!$I21="지연") -> FALSE | J24: =IF($I24=FALSE(),"",COUNTIF($I$6:$I24,TRUE())) | K24: =IF($J24="","","R"&$J24)
A25: =IF($C25="","",20) | B25: =IFERROR(INDEX(작업목록!$B$3:$B$102,MATCH("R"&20,지연현황!$K$6:$K$105,0)),"") | C25: =IFERROR(INDEX(작업목록!$C$3:$C$102,MATCH("R"&20,지연현황!$K$6:$K$105,0)),"") | D25: =IF($C25="","",IFERROR(INDEX(작업목록!$D$3:$D$102,MATCH("R"&20,지연현황!$K$6:$K$105,0)),"")) | E25: =IF($C25="","",IFERROR(INDEX(작업목록!$F$3:$F$102,MATCH("R"&20,지연현황!$K$6:$K$105,0)),"")) | F25: =IF($E25="","",TODAY()-$E25) | G25: =IF($C25="","",IFERROR(INDEX(작업목록!$H$3:$H$102,MATCH("R"&20,지연현황!$K$6:$K$105,0)),"")) | I25: =IF(작업목록!$C22="",FALSE(),작업목록!$I22="지연") -> FALSE | J25: =IF($I25=FALSE(),"",COUNTIF($I$6:$I25,TRUE())) | K25: =IF($J25="","","R"&$J25)
A26: =IF($C26="","",21) | B26: =IFERROR(INDEX(작업목록!$B$3:$B$102,MATCH("R"&21,지연현황!$K$6:$K$105,0)),"") | C26: =IFERROR(INDEX(작업목록!$C$3:$C$102,MATCH("R"&21,지연현황!$K$6:$K$105,0)),"") | D26: =IF($C26="","",IFERROR(INDEX(작업목록!$D$3:$D$102,MATCH("R"&21,지연현황!$K$6:$K$105,0)),"")) | E26: =IF($C26="","",IFERROR(INDEX(작업목록!$F$3:$F$102,MATCH("R"&21,지연현황!$K$6:$K$105,0)),"")) | F26: =IF($E26="","",TODAY()-$E26) | G26: =IF($C26="","",IFERROR(INDEX(작업목록!$H$3:$H$102,MATCH("R"&21,지연현황!$K$6:$K$105,0)),"")) | I26: =IF(작업목록!$C23="",FALSE(),작업목록!$I23="지연") -> FALSE | J26: =IF($I26=FALSE(),"",COUNTIF($I$6:$I26,TRUE())) | K26: =IF($J26="","","R"&$J26)
A27: =IF($C27="","",22) | B27: =IFERROR(INDEX(작업목록!$B$3:$B$102,MATCH("R"&22,지연현황!$K$6:$K$105,0)),"") | C27: =IFERROR(INDEX(작업목록!$C$3:$C$102,MATCH("R"&22,지연현황!$K$6:$K$105,0)),"") | D27: =IF($C27="","",IFERROR(INDEX(작업목록!$D$3:$D$102,MATCH("R"&22,지연현황!$K$6:$K$105,0)),"")) | E27: =IF($C27="","",IFERROR(INDEX(작업목록!$F$3:$F$102,MATCH("R"&22,지연현황!$K$6:$K$105,0)),"")) | F27: =IF($E27="","",TODAY()-$E27) | G27: =IF($C27="","",IFERROR(INDEX(작업목록!$H$3:$H$102,MATCH("R"&22,지연현황!$K$6:$K$105,0)),"")) | I27: =IF(작업목록!$C24="",FALSE(),작업목록!$I24="지연") -> FALSE | J27: =IF($I27=FALSE(),"",COUNTIF($I$6:$I27,TRUE())) | K27: =IF($J27="","","R"&$J27)
A28: =IF($C28="","",23) | B28: =IFERROR(INDEX(작업목록!$B$3:$B$102,MATCH("R"&23,지연현황!$K$6:$K$105,0)),"") | C28: =IFERROR(INDEX(작업목록!$C$3:$C$102,MATCH("R"&23,지연현황!$K$6:$K$105,0)),"") | D28: =IF($C28="","",IFERROR(INDEX(작업목록!$D$3:$D$102,MATCH("R"&23,지연현황!$K$6:$K$105,0)),"")) | E28: =IF($C28="","",IFERROR(INDEX(작업목록!$F$3:$F$102,MATCH("R"&23,지연현황!$K$6:$K$105,0)),"")) | F28: =IF($E28="","",TODAY()-$E28) | G28: =IF($C28="","",IFERROR(INDEX(작업목록!$H$3:$H$102,MATCH("R"&23,지연현황!$K$6:$K$105,0)),"")) | I28: =IF(작업목록!$C25="",FALSE(),작업목록!$I25="지연") -> FALSE | J28: =IF($I28=FALSE(),"",COUNTIF($I$6:$I28,TRUE())) | K28: =IF($J28="","","R"&$J28)
A29: =IF($C29="","",24) | B29: =IFERROR(INDEX(작업목록!$B$3:$B$102,MATCH("R"&24,지연현황!$K$6:$K$105,0)),"") | C29: =IFERROR(INDEX(작업목록!$C$3:$C$102,MATCH("R"&24,지연현황!$K$6:$K$105,0)),"") | D29: =IF($C29="","",IFERROR(INDEX(작업목록!$D$3:$D$102,MATCH("R"&24,지연현황!$K$6:$K$105,0)),"")) | E29: =IF($C29="","",IFERROR(INDEX(작업목록!$F$3:$F$102,MATCH("R"&24,지연현황!$K$6:$K$105,0)),"")) | F29: =IF($E29="","",TODAY()-$E29) | G29: =IF($C29="","",IFERROR(INDEX(작업목록!$H$3:$H$102,MATCH("R"&24,지연현황!$K$6:$K$105,0)),"")) | I29: =IF(작업목록!$C26="",FALSE(),작업목록!$I26="지연") -> FALSE | J29: =IF($I29=FALSE(),"",COUNTIF($I$6:$I29,TRUE())) | K29: =IF($J29="","","R"&$J29)
A30: =IF($C30="","",25) | B30: =IFERROR(INDEX(작업목록!$B$3:$B$102,MATCH("R"&25,지연현황!$K$6:$K$105,0)),"") | C30: =IFERROR(INDEX(작업목록!$C$3:$C$102,MATCH("R"&25,지연현황!$K$6:$K$105,0)),"") | D30: =IF($C30="","",IFERROR(INDEX(작업목록!$D$3:$D$102,MATCH("R"&25,지연현황!$K$6:$K$105,0)),"")) | E30: =IF($C30="","",IFERROR(INDEX(작업목록!$F$3:$F$102,MATCH("R"&25,지연현황!$K$6:$K$105,0)),"")) | F30: =IF($E30="","",TODAY()-$E30) | G30: =IF($C30="","",IFERROR(INDEX(작업목록!$H$3:$H$102,MATCH("R"&25,지연현황!$K$6:$K$105,0)),"")) | I30: =IF(작업목록!$C27="",FALSE(),작업목록!$I27="지연") -> FALSE | J30: =IF($I30=FALSE(),"",COUNTIF($I$6:$I30,TRUE())) | K30: =IF($J30="","","R"&$J30)
A31: =IF($C31="","",26) | B31: =IFERROR(INDEX(작업목록!$B$3:$B$102,MATCH("R"&26,지연현황!$K$6:$K$105,0)),"") | C31: =IFERROR(INDEX(작업목록!$C$3:$C$102,MATCH("R"&26,지연현황!$K$6:$K$105,0)),"") | D31: =IF($C31="","",IFERROR(INDEX(작업목록!$D$3:$D$102,MATCH("R"&26,지연현황!$K$6:$K$105,0)),"")) | E31: =IF($C31="","",IFERROR(INDEX(작업목록!$F$3:$F$102,MATCH("R"&26,지연현황!$K$6:$K$105,0)),"")) | F31: =IF($E31="","",TODAY()-$E31) | G31: =IF($C31="","",IFERROR(INDEX(작업목록!$H$3:$H$102,MATCH("R"&26,지연현황!$K$6:$K$105,0)),"")) | I31: =IF(작업목록!$C28="",FALSE(),작업목록!$I28="지연") -> FALSE | J31: =IF($I31=FALSE(),"",COUNTIF($I$6:$I31,TRUE())) | K31: =IF($J31="","","R"&$J31)
A32: =IF($C32="","",27) | B32: =IFERROR(INDEX(작업목록!$B$3:$B$102,MATCH("R"&27,지연현황!$K$6:$K$105,0)),"") | C32: =IFERROR(INDEX(작업목록!$C$3:$C$102,MATCH("R"&27,지연현황!$K$6:$K$105,0)),"") | D32: =IF($C32="","",IFERROR(INDEX(작업목록!$D$3:$D$102,MATCH("R"&27,지연현황!$K$6:$K$105,0)),"")) | E32: =IF($C32="","",IFERROR(INDEX(작업목록!$F$3:$F$102,MATCH("R"&27,지연현황!$K$6:$K$105,0)),"")) | F32: =IF($E32="","",TODAY()-$E32) | G32: =IF($C32="","",IFERROR(INDEX(작업목록!$H$3:$H$102,MATCH("R"&27,지연현황!$K$6:$K$105,0)),"")) | I32: =IF(작업목록!$C29="",FALSE(),작업목록!$I29="지연") -> FALSE | J32: =IF($I32=FALSE(),"",COUNTIF($I$6:$I32,TRUE())) | K32: =IF($J32="","","R"&$J32)
A33: =IF($C33="","",28) | B33: =IFERROR(INDEX(작업목록!$B$3:$B$102,MATCH("R"&28,지연현황!$K$6:$K$105,0)),"") | C33: =IFERROR(INDEX(작업목록!$C$3:$C$102,MATCH("R"&28,지연현황!$K$6:$K$105,0)),"") | D33: =IF($C33="","",IFERROR(INDEX(작업목록!$D$3:$D$102,MATCH("R"&28,지연현황!$K$6:$K$105,0)),"")) | E33: =IF($C33="","",IFERROR(INDEX(작업목록!$F$3:$F$102,MATCH("R"&28,지연현황!$K$6:$K$105,0)),"")) | F33: =IF($E33="","",TODAY()-$E33) | G33: =IF($C33="","",IFERROR(INDEX(작업목록!$H$3:$H$102,MATCH("R"&28,지연현황!$K$6:$K$105,0)),"")) | I33: =IF(작업목록!$C30="",FALSE(),작업목록!$I30="지연") -> FALSE | J33: =IF($I33=FALSE(),"",COUNTIF($I$6:$I33,TRUE())) | K33: =IF($J33="","","R"&$J33)
A34: =IF($C34="","",29) | B34: =IFERROR(INDEX(작업목록!$B$3:$B$102,MATCH("R"&29,지연현황!$K$6:$K$105,0)),"") | C34: =IFERROR(INDEX(작업목록!$C$3:$C$102,MATCH("R"&29,지연현황!$K$6:$K$105,0)),"") | D34: =IF($C34="","",IFERROR(INDEX(작업목록!$D$3:$D$102,MATCH("R"&29,지연현황!$K$6:$K$105,0)),"")) | E34: =IF($C34="","",IFERROR(INDEX(작업목록!$F$3:$F$102,MATCH("R"&29,지연현황!$K$6:$K$105,0)),"")) | F34: =IF($E34="","",TODAY()-$E34) | G34: =IF($C34="","",IFERROR(INDEX(작업목록!$H$3:$H$102,MATCH("R"&29,지연현황!$K$6:$K$105,0)),"")) | I34: =IF(작업목록!$C31="",FALSE(),작업목록!$I31="지연") -> FALSE | J34: =IF($I34=FALSE(),"",COUNTIF($I$6:$I34,TRUE())) | K34: =IF($J34="","","R"&$J34)
A35: =IF($C35="","",30) | B35: =IFERROR(INDEX(작업목록!$B$3:$B$102,MATCH("R"&30,지연현황!$K$6:$K$105,0)),"") | C35: =IFERROR(INDEX(작업목록!$C$3:$C$102,MATCH("R"&30,지연현황!$K$6:$K$105,0)),"") | D35: =IF($C35="","",IFERROR(INDEX(작업목록!$D$3:$D$102,MATCH("R"&30,지연현황!$K$6:$K$105,0)),"")) | E35: =IF($C35="","",IFERROR(INDEX(작업목록!$F$3:$F$102,MATCH("R"&30,지연현황!$K$6:$K$105,0)),"")) | F35: =IF($E35="","",TODAY()-$E35) | G35: =IF($C35="","",IFERROR(INDEX(작업목록!$H$3:$H$102,MATCH("R"&30,지연현황!$K$6:$K$105,0)),"")) | I35: =IF(작업목록!$C32="",FALSE(),작업목록!$I32="지연") -> FALSE | J35: =IF($I35=FALSE(),"",COUNTIF($I$6:$I35,TRUE())) | K35: =IF($J35="","","R"&$J35)
A36: =IF($C36="","",31) | B36: =IFERROR(INDEX(작업목록!$B$3:$B$102,MATCH("R"&31,지연현황!$K$6:$K$105,0)),"") | C36: =IFERROR(INDEX(작업목록!$C$3:$C$102,MATCH("R"&31,지연현황!$K$6:$K$105,0)),"") | D36: =IF($C36="","",IFERROR(INDEX(작업목록!$D$3:$D$102,MATCH("R"&31,지연현황!$K$6:$K$105,0)),"")) | E36: =IF($C36="","",IFERROR(INDEX(작업목록!$F$3:$F$102,MATCH("R"&31,지연현황!$K$6:$K$105,0)),"")) | F36: =IF($E36="","",TODAY()-$E36) | G36: =IF($C36="","",IFERROR(INDEX(작업목록!$H$3:$H$102,MATCH("R"&31,지연현황!$K$6:$K$105,0)),"")) | I36: =IF(작업목록!$C33="",FALSE(),작업목록!$I33="지연") -> FALSE | J36: =IF($I36=FALSE(),"",COUNTIF($I$6:$I36,TRUE())) | K36: =IF($J36="","","R"&$J36)
A37: =IF($C37="","",32) | B37: =IFERROR(INDEX(작업목록!$B$3:$B$102,MATCH("R"&32,지연현황!$K$6:$K$105,0)),"") | C37: =IFERROR(INDEX(작업목록!$C$3:$C$102,MATCH("R"&32,지연현황!$K$6:$K$105,0)),"") | D37: =IF($C37="","",IFERROR(INDEX(작업목록!$D$3:$D$102,MATCH("R"&32,지연현황!$K$6:$K$105,0)),"")) | E37: =IF($C37="","",IFERROR(INDEX(작업목록!$F$3:$F$102,MATCH("R"&32,지연현황!$K$6:$K$105,0)),"")) | F37: =IF($E37="","",TODAY()-$E37) | G37: =IF($C37="","",IFERROR(INDEX(작업목록!$H$3:$H$102,MATCH("R"&32,지연현황!$K$6:$K$105,0)),"")) | I37: =IF(작업목록!$C34="",FALSE(),작업목록!$I34="지연") -> FALSE | J37: =IF($I37=FALSE(),"",COUNTIF($I$6:$I37,TRUE())) | K37: =IF($J37="","","R"&$J37)
A38: =IF($C38="","",33) | B38: =IFERROR(INDEX(작업목록!$B$3:$B$102,MATCH("R"&33,지연현황!$K$6:$K$105,0)),"") | C38: =IFERROR(INDEX(작업목록!$C$3:$C$102,MATCH("R"&33,지연현황!$K$6:$K$105,0)),"") | D38: =IF($C38="","",IFERROR(INDEX(작업목록!$D$3:$D$102,MATCH("R"&33,지연현황!$K$6:$K$105,0)),"")) | E38: =IF($C38="","",IFERROR(INDEX(작업목록!$F$3:$F$102,MATCH("R"&33,지연현황!$K$6:$K$105,0)),"")) | F38: =IF($E38="","",TODAY()-$E38) | G38: =IF($C38="","",IFERROR(INDEX(작업목록!$H$3:$H$102,MATCH("R"&33,지연현황!$K$6:$K$105,0)),"")) | I38: =IF(작업목록!$C35="",FALSE(),작업목록!$I35="지연") -> FALSE | J38: =IF($I38=FALSE(),"",COUNTIF($I$6:$I38,TRUE())) | K38: =IF($J38="","","R"&$J38)
A39: =IF($C39="","",34) | B39: =IFERROR(INDEX(작업목록!$B$3:$B$102,MATCH("R"&34,지연현황!$K$6:$K$105,0)),"") | C39: =IFERROR(INDEX(작업목록!$C$3:$C$102,MATCH("R"&34,지연현황!$K$6:$K$105,0)),"") | D39: =IF($C39="","",IFERROR(INDEX(작업목록!$D$3:$D$102,MATCH("R"&34,지연현황!$K$6:$K$105,0)),"")) | E39: =IF($C39="","",IFERROR(INDEX(작업목록!$F$3:$F$102,MATCH("R"&34,지연현황!$K$6:$K$105,0)),"")) | F39: =IF($E39="","",TODAY()-$E39) | G39: =IF($C39="","",IFERROR(INDEX(작업목록!$H$3:$H$102,MATCH("R"&34,지연현황!$K$6:$K$105,0)),"")) | I39: =IF(작업목록!$C36="",FALSE(),작업목록!$I36="지연") -> FALSE | J39: =IF($I39=FALSE(),"",COUNTIF($I$6:$I39,TRUE())) | K39: =IF($J39="","","R"&$J39)
A40: =IF($C40="","",35) | B40: =IFERROR(INDEX(작업목록!$B$3:$B$102,MATCH("R"&35,지연현황!$K$6:$K$105,0)),"") | C40: =IFERROR(INDEX(작업목록!$C$3:$C$102,MATCH("R"&35,지연현황!$K$6:$K$105,0)),"") | D40: =IF($C40="","",IFERROR(INDEX(작업목록!$D$3:$D$102,MATCH("R"&35,지연현황!$K$6:$K$105,0)),"")) | E40: =IF($C40="","",IFERROR(INDEX(작업목록!$F$3:$F$102,MATCH("R"&35,지연현황!$K$6:$K$105,0)),"")) | F40: =IF($E40="","",TODAY()-$E40) | G40: =IF($C40="","",IFERROR(INDEX(작업목록!$H$3:$H$102,MATCH("R"&35,지연현황!$K$6:$K$105,0)),"")) | I40: =IF(작업목록!$C37="",FALSE(),작업목록!$I37="지연") -> FALSE | J40: =IF($I40=FALSE(),"",COUNTIF($I$6:$I40,TRUE())) | K40: =IF($J40="","","R"&$J40)
A41: =IF($C41="","",36) | B41: =IFERROR(INDEX(작업목록!$B$3:$B$102,MATCH("R"&36,지연현황!$K$6:$K$105,0)),"") | C41: =IFERROR(INDEX(작업목록!$C$3:$C$102,MATCH("R"&36,지연현황!$K$6:$K$105,0)),"") | D41: =IF($C41="","",IFERROR(INDEX(작업목록!$D$3:$D$102,MATCH("R"&36,지연현황!$K$6:$K$105,0)),"")) | E41: =IF($C41="","",IFERROR(INDEX(작업목록!$F$3:$F$102,MATCH("R"&36,지연현황!$K$6:$K$105,0)),"")) | F41: =IF($E41="","",TODAY()-$E41) | G41: =IF($C41="","",IFERROR(INDEX(작업목록!$H$3:$H$102,MATCH("R"&36,지연현황!$K$6:$K$105,0)),"")) | I41: =IF(작업목록!$C38="",FALSE(),작업목록!$I38="지연") -> FALSE | J41: =IF($I41=FALSE(),"",COUNTIF($I$6:$I41,TRUE())) | K41: =IF($J41="","","R"&$J41)
A42: =IF($C42="","",37) | B42: =IFERROR(INDEX(작업목록!$B$3:$B$102,MATCH("R"&37,지연현황!$K$6:$K$105,0)),"") | C42: =IFERROR(INDEX(작업목록!$C$3:$C$102,MATCH("R"&37,지연현황!$K$6:$K$105,0)),"") | D42: =IF($C42="","",IFERROR(INDEX(작업목록!$D$3:$D$102,MATCH("R"&37,지연현황!$K$6:$K$105,0)),"")) | E42: =IF($C42="","",IFERROR(INDEX(작업목록!$F$3:$F$102,MATCH("R"&37,지연현황!$K$6:$K$105,0)),"")) | F42: =IF($E42="","",TODAY()-$E42) | G42: =IF($C42="","",IFERROR(INDEX(작업목록!$H$3:$H$102,MATCH("R"&37,지연현황!$K$6:$K$105,0)),"")) | I42: =IF(작업목록!$C39="",FALSE(),작업목록!$I39="지연") -> FALSE | J42: =IF($I42=FALSE(),"",COUNTIF($I$6:$I42,TRUE())) | K42: =IF($J42="","","R"&$J42)
...
