Workbook

Sheet 사용안내
B2: 차량 정비 · 소모품 교체 주기 관리
B4: 핵심 | C4: 마지막 교체일과 주행거리를 넣으면 다음 교체 시점이 자동으로 계산됩니다.
B5: 입력 규칙 | C5: 파란색 글씨 칸만 입력하세요. 검은색은 자동 계산입니다.
B6: ① 차량목록 | C6: 차량번호·차종·현재 주행거리를 등록합니다. 주행거리는 계기판 숫자를 그대로요.
B7: ② 정비항목 | C7: 엔진오일·타이어 등 교체 주기를 등록합니다. km 주기와 개월 주기를 둘 다 넣을 수 있습니다.
C8: 둘 다 넣으면 먼저 오는 쪽이 기준이 됩니다. 하나만 넣어도 됩니다.
B9: ③ 정비이력 | C9: 정비할 때마다 한 줄. 날짜·주행거리·항목·비용을 넣습니다.
B10: ④ 정비현황 | C10: 차량 × 항목별로 다음 교체 시점과 남은 거리·날짜가 나옵니다.
B11: ⑤ 교체대상 | C11: 지금 교체해야 하는 것만 모아서 보여줍니다.
B12: ⑥ 차량별 비용 | C12: 차량별 정비 횟수와 누적 비용입니다.
B13: 주행거리 갱신 | C13: 차량목록의 현재 주행거리를 주기적으로 직접 갱신해야 정확합니다.
B15: 설정 | C15: 값을 바꾸면 모든 계산에 반영됩니다
B16: km 경고 기준 | C16: 1000
B17: 일수 경고 기준 | C17: 30
B19: ※ 교체 주기는 제조사 권장값이나 회사 규정을 확인하고 직접 넣으세요. 이 파일은 주기를 검증하지 않습니다.

Sheet 차량목록
A1: 차량목록
A2: 차량번호 | B2: 차종 | C2: 연식 | D2: 담당자 | E2: 현재 주행거리(km) | F2: 등록일 | G2: 상태
A3: 12가3456 | B3: 포터2 | C3: 2022 | D3: 김기사 | E3: 81800 | F3: 44621 | G3: 운행
A4: 34나5678 | B4: 봉고3 | C4: 2023 | D4: 이기사 | E4: 42300 | F4: 45056 | G4: 운행
A5: 56다7890 | B5: 스타렉스 | C5: 2021 | D5: 박기사 | E5: 125000 | F5: 44242 | G5: 운행

Sheet 정비항목
A1: 정비항목 (주기는 제조사 권장값을 확인하고 넣으세요)
A2: 항목코드 | B2: 정비항목 | C2: 주기(km) | D2: 주기(개월) | E2: 비고
A3: M01 | B3: 엔진오일 | C3: 10000 | D3: 6
A4: M02 | B4: 에어크리너 | C4: 20000 | D4: 12
A5: M03 | B5: 타이어 | C5: 50000 | D5: 36
A6: M04 | B6: 브레이크 패드 | C6: 40000 | D6: 24
A7: M05 | B7: 정기검사 | C7: 0 | D7: 12
A54: ※ km 주기만 있으면 개월은 비우고, 날짜 기준만 있으면 km를 비우거나 0으로 넣으세요.

Sheet 정비이력
A1: 정비이력 (정비할 때마다 한 줄)
A2: 정비일 | B2: 차량번호 | C2: 차종(자동) | D2: 항목코드 | E2: 정비항목(자동) | F2: 정비 시 주행거리 | G2: 비용 | H2: 정비소/비고
A3: 46183 | B3: 12가3456 | C3: =IF($B3="","",IFERROR(INDEX(차량목록!$B$3:$B$102,MATCH($B3,차량목록!$A$3:$A$102,0)),"미등록차량")) -> 포터2 | D3: M01 | E3: =IF($D3="","",IFERROR(INDEX(정비항목!$B$3:$B$52,MATCH($D3,정비항목!$A$3:$A$52,0)),"미등록항목")) -> 엔진오일 | F3: 72000 | G3: 85000
A4: 46086 | B4: 12가3456 | C4: =IF($B4="","",IFERROR(INDEX(차량목록!$B$3:$B$102,MATCH($B4,차량목록!$A$3:$A$102,0)),"미등록차량")) -> 포터2 | D4: M02 | E4: =IF($D4="","",IFERROR(INDEX(정비항목!$B$3:$B$52,MATCH($D4,정비항목!$A$3:$A$52,0)),"미등록항목")) -> 에어크리너 | F4: 65000 | G4: 45000
A5: 46235 | B5: 34나5678 | C5: =IF($B5="","",IFERROR(INDEX(차량목록!$B$3:$B$102,MATCH($B5,차량목록!$A$3:$A$102,0)),"미등록차량")) -> 봉고3 | D5: M01 | E5: =IF($D5="","",IFERROR(INDEX(정비항목!$B$3:$B$52,MATCH($D5,정비항목!$A$3:$A$52,0)),"미등록항목")) -> 엔진오일 | F5: 38000 | G5: 85000
A6: 45536 | B6: 56다7890 | C6: =IF($B6="","",IFERROR(INDEX(차량목록!$B$3:$B$102,MATCH($B6,차량목록!$A$3:$A$102,0)),"미등록차량")) -> 스타렉스 | D6: M03 | E6: =IF($D6="","",IFERROR(INDEX(정비항목!$B$3:$B$52,MATCH($D6,정비항목!$A$3:$A$52,0)),"미등록항목")) -> 타이어 | F6: 95000 | G6: 620000
C7: =IF($B7="","",IFERROR(INDEX(차량목록!$B$3:$B$102,MATCH($B7,차량목록!$A$3:$A$102,0)),"미등록차량")) | E7: =IF($D7="","",IFERROR(INDEX(정비항목!$B$3:$B$52,MATCH($D7,정비항목!$A$3:$A$52,0)),"미등록항목"))
C8: =IF($B8="","",IFERROR(INDEX(차량목록!$B$3:$B$102,MATCH($B8,차량목록!$A$3:$A$102,0)),"미등록차량")) | E8: =IF($D8="","",IFERROR(INDEX(정비항목!$B$3:$B$52,MATCH($D8,정비항목!$A$3:$A$52,0)),"미등록항목"))
C9: =IF($B9="","",IFERROR(INDEX(차량목록!$B$3:$B$102,MATCH($B9,차량목록!$A$3:$A$102,0)),"미등록차량")) | E9: =IF($D9="","",IFERROR(INDEX(정비항목!$B$3:$B$52,MATCH($D9,정비항목!$A$3:$A$52,0)),"미등록항목"))
C10: =IF($B10="","",IFERROR(INDEX(차량목록!$B$3:$B$102,MATCH($B10,차량목록!$A$3:$A$102,0)),"미등록차량")) | E10: =IF($D10="","",IFERROR(INDEX(정비항목!$B$3:$B$52,MATCH($D10,정비항목!$A$3:$A$52,0)),"미등록항목"))
C11: =IF($B11="","",IFERROR(INDEX(차량목록!$B$3:$B$102,MATCH($B11,차량목록!$A$3:$A$102,0)),"미등록차량")) | E11: =IF($D11="","",IFERROR(INDEX(정비항목!$B$3:$B$52,MATCH($D11,정비항목!$A$3:$A$52,0)),"미등록항목"))
C12: =IF($B12="","",IFERROR(INDEX(차량목록!$B$3:$B$102,MATCH($B12,차량목록!$A$3:$A$102,0)),"미등록차량")) | E12: =IF($D12="","",IFERROR(INDEX(정비항목!$B$3:$B$52,MATCH($D12,정비항목!$A$3:$A$52,0)),"미등록항목"))
C13: =IF($B13="","",IFERROR(INDEX(차량목록!$B$3:$B$102,MATCH($B13,차량목록!$A$3:$A$102,0)),"미등록차량")) | E13: =IF($D13="","",IFERROR(INDEX(정비항목!$B$3:$B$52,MATCH($D13,정비항목!$A$3:$A$52,0)),"미등록항목"))
C14: =IF($B14="","",IFERROR(INDEX(차량목록!$B$3:$B$102,MATCH($B14,차량목록!$A$3:$A$102,0)),"미등록차량")) | E14: =IF($D14="","",IFERROR(INDEX(정비항목!$B$3:$B$52,MATCH($D14,정비항목!$A$3:$A$52,0)),"미등록항목"))
C15: =IF($B15="","",IFERROR(INDEX(차량목록!$B$3:$B$102,MATCH($B15,차량목록!$A$3:$A$102,0)),"미등록차량")) | E15: =IF($D15="","",IFERROR(INDEX(정비항목!$B$3:$B$52,MATCH($D15,정비항목!$A$3:$A$52,0)),"미등록항목"))
C16: =IF($B16="","",IFERROR(INDEX(차량목록!$B$3:$B$102,MATCH($B16,차량목록!$A$3:$A$102,0)),"미등록차량")) | E16: =IF($D16="","",IFERROR(INDEX(정비항목!$B$3:$B$52,MATCH($D16,정비항목!$A$3:$A$52,0)),"미등록항목"))
C17: =IF($B17="","",IFERROR(INDEX(차량목록!$B$3:$B$102,MATCH($B17,차량목록!$A$3:$A$102,0)),"미등록차량")) | E17: =IF($D17="","",IFERROR(INDEX(정비항목!$B$3:$B$52,MATCH($D17,정비항목!$A$3:$A$52,0)),"미등록항목"))
C18: =IF($B18="","",IFERROR(INDEX(차량목록!$B$3:$B$102,MATCH($B18,차량목록!$A$3:$A$102,0)),"미등록차량")) | E18: =IF($D18="","",IFERROR(INDEX(정비항목!$B$3:$B$52,MATCH($D18,정비항목!$A$3:$A$52,0)),"미등록항목"))
... C1002: =IF($B1002="","",IFERROR(INDEX(차량목록!$B$3:$B$102,MATCH($B1002,차량목록!$A$3:$A$102,0)),"미등록차량")) | E1002: =IF($D1002="","",IFERROR(INDEX(정비항목!$B$3:$B$52,MATCH($D1002,정비항목!$A$3:$A$52,0)),"미등록항목"))

Sheet 정비현황
A1: 정비현황 (차량 × 항목)
A3: 오늘 | B3: =TODAY() -> 46279 | D3: 교체 대상 | E3: =COUNTIF($M$6:$M$365,"교체") -> 0 | G3: 임박 | H3: =COUNTIF($M$6:$M$365,"임박") -> 1
A5: 차량번호 | B5: 차종 | C5: 항목 | D5: 주기(km) | E5: 주기(개월) | F5: 최근 정비일 | G5: 최근 정비 km | H5: 현재 km | I5: 다음 교체 km | J5: 남은 km | K5: 다음 교체일 | L5: D-Day | M5: 상태
A6: =IF(OR(차량목록!$A3="",정비항목!$A3="",차량목록!$G3="매각"),"",차량목록!$A3) -> 12가3456 | B6: =IF($A6="","",차량목록!$B3) -> 포터2 | C6: =IF($A6="","",정비항목!$B3) -> 엔진오일 | D6: =IF($A6="","",IF(정비항목!$C3="",0,정비항목!$C3)) -> 10000 | E6: =IF($A6="","",IF(정비항목!$D3="",0,정비항목!$D3)) -> 6 | F6: =IF($A6="","",IF(COUNTIFS(정비이력!$B$3:$B$1002,$A6,정비이력!$D$3:$D$1002,정비항목!$A3)=0,"",SUMPRODUCT(MAX((정비이력!$B$3:$B$1002=$A6)*(정비이력!$D$3:$D$1002=정비항목!$A3)*정비이력!$A$3:$A$1002)))) -> 46183 | G6: =IF($A6="","",IF($F6="","",SUMPRODUCT(MAX((정비이력!$B$3:$B$1002=$A6)*(정비이력!$D$3:$D$1002=정비항목!$A3)*정비이력!$F$3:$F$1002)))) -> 72000 | H6: =IF($A6="","",IF(차량목록!$E3="",0,차량목록!$E3)) -> 81800 | I6: =IF(OR($A6="",$D6=0),"",IF($G6="",$H6+$D6,$G6+$D6)) -> 82000 | J6: =IF($I6="","",$I6-$H6) -> 200 | K6: =IF(OR($A6="",$E6=0),"",IF($F6="",EDATE(TODAY(),$E6),EDATE($F6,$E6))) -> 46366 | L6: =IF($K6="","",$K6-TODAY()) -> 87 | M6: =IF($A6="","",IF(AND($J6="",$L6=""),"-",IF(OR(AND($J6<>"",$J6<=0),AND($L6<>"",$L6<0)),"교체",IF(OR(AND($J6<>"",$J6<=사용안내!$C$16),AND($L6<>"",$L6<=사용안내!$C$17)),"임박","정상")))) -> 임박
A7: =IF(OR(차량목록!$A3="",정비항목!$A4="",차량목록!$G3="매각"),"",차량목록!$A3) -> 12가3456 | B7: =IF($A7="","",차량목록!$B3) -> 포터2 | C7: =IF($A7="","",정비항목!$B4) -> 에어크리너 | D7: =IF($A7="","",IF(정비항목!$C4="",0,정비항목!$C4)) -> 20000 | E7: =IF($A7="","",IF(정비항목!$D4="",0,정비항목!$D4)) -> 12 | F7: =IF($A7="","",IF(COUNTIFS(정비이력!$B$3:$B$1002,$A7,정비이력!$D$3:$D$1002,정비항목!$A4)=0,"",SUMPRODUCT(MAX((정비이력!$B$3:$B$1002=$A7)*(정비이력!$D$3:$D$1002=정비항목!$A4)*정비이력!$A$3:$A$1002)))) -> 46086 | G7: =IF($A7="","",IF($F7="","",SUMPRODUCT(MAX((정비이력!$B$3:$B$1002=$A7)*(정비이력!$D$3:$D$1002=정비항목!$A4)*정비이력!$F$3:$F$1002)))) -> 65000 | H7: =IF($A7="","",IF(차량목록!$E3="",0,차량목록!$E3)) -> 81800 | I7: =IF(OR($A7="",$D7=0),"",IF($G7="",$H7+$D7,$G7+$D7)) -> 85000 | J7: =IF($I7="","",$I7-$H7) -> 3200 | K7: =IF(OR($A7="",$E7=0),"",IF($F7="",EDATE(TODAY(),$E7),EDATE($F7,$E7))) -> 46451 | L7: =IF($K7="","",$K7-TODAY()) -> 172 | M7: =IF($A7="","",IF(AND($J7="",$L7=""),"-",IF(OR(AND($J7<>"",$J7<=0),AND($L7<>"",$L7<0)),"교체",IF(OR(AND($J7<>"",$J7<=사용안내!$C$16),AND($L7<>"",$L7<=사용안내!$C$17)),"임박","정상")))) -> 정상
A8: =IF(OR(차량목록!$A3="",정비항목!$A5="",차량목록!$G3="매각"),"",차량목록!$A3) -> 12가3456 | B8: =IF($A8="","",차량목록!$B3) -> 포터2 | C8: =IF($A8="","",정비항목!$B5) -> 타이어 | D8: =IF($A8="","",IF(정비항목!$C5="",0,정비항목!$C5)) -> 50000 | E8: =IF($A8="","",IF(정비항목!$D5="",0,정비항목!$D5)) -> 36 | F8: =IF($A8="","",IF(COUNTIFS(정비이력!$B$3:$B$1002,$A8,정비이력!$D$3:$D$1002,정비항목!$A5)=0,"",SUMPRODUCT(MAX((정비이력!$B$3:$B$1002=$A8)*(정비이력!$D$3:$D$1002=정비항목!$A5)*정비이력!$A$3:$A$1002)))) | G8: =IF($A8="","",IF($F8="","",SUMPRODUCT(MAX((정비이력!$B$3:$B$1002=$A8)*(정비이력!$D$3:$D$1002=정비항목!$A5)*정비이력!$F$3:$F$1002)))) | H8: =IF($A8="","",IF(차량목록!$E3="",0,차량목록!$E3)) -> 81800 | I8: =IF(OR($A8="",$D8=0),"",IF($G8="",$H8+$D8,$G8+$D8)) -> 131800 | J8: =IF($I8="","",$I8-$H8) -> 50000 | K8: =IF(OR($A8="",$E8=0),"",IF($F8="",EDATE(TODAY(),$E8),EDATE($F8,$E8))) -> 47375 | L8: =IF($K8="","",$K8-TODAY()) -> 1096 | M8: =IF($A8="","",IF(AND($J8="",$L8=""),"-",IF(OR(AND($J8<>"",$J8<=0),AND($L8<>"",$L8<0)),"교체",IF(OR(AND($J8<>"",$J8<=사용안내!$C$16),AND($L8<>"",$L8<=사용안내!$C$17)),"임박","정상")))) -> 정상
A9: =IF(OR(차량목록!$A3="",정비항목!$A6="",차량목록!$G3="매각"),"",차량목록!$A3) -> 12가3456 | B9: =IF($A9="","",차량목록!$B3) -> 포터2 | C9: =IF($A9="","",정비항목!$B6) -> 브레이크 패드 | D9: =IF($A9="","",IF(정비항목!$C6="",0,정비항목!$C6)) -> 40000 | E9: =IF($A9="","",IF(정비항목!$D6="",0,정비항목!$D6)) -> 24 | F9: =IF($A9="","",IF(COUNTIFS(정비이력!$B$3:$B$1002,$A9,정비이력!$D$3:$D$1002,정비항목!$A6)=0,"",SUMPRODUCT(MAX((정비이력!$B$3:$B$1002=$A9)*(정비이력!$D$3:$D$1002=정비항목!$A6)*정비이력!$A$3:$A$1002)))) | G9: =IF($A9="","",IF($F9="","",SUMPRODUCT(MAX((정비이력!$B$3:$B$1002=$A9)*(정비이력!$D$3:$D$1002=정비항목!$A6)*정비이력!$F$3:$F$1002)))) | H9: =IF($A9="","",IF(차량목록!$E3="",0,차량목록!$E3)) -> 81800 | I9: =IF(OR($A9="",$D9=0),"",IF($G9="",$H9+$D9,$G9+$D9)) -> 121800 | J9: =IF($I9="","",$I9-$H9) -> 40000 | K9: =IF(OR($A9="",$E9=0),"",IF($F9="",EDATE(TODAY(),$E9),EDATE($F9,$E9))) -> 47010 | L9: =IF($K9="","",$K9-TODAY()) -> 731 | M9: =IF($A9="","",IF(AND($J9="",$L9=""),"-",IF(OR(AND($J9<>"",$J9<=0),AND($L9<>"",$L9<0)),"교체",IF(OR(AND($J9<>"",$J9<=사용안내!$C$16),AND($L9<>"",$L9<=사용안내!$C$17)),"임박","정상")))) -> 정상
A10: =IF(OR(차량목록!$A3="",정비항목!$A7="",차량목록!$G3="매각"),"",차량목록!$A3) -> 12가3456 | B10: =IF($A10="","",차량목록!$B3) -> 포터2 | C10: =IF($A10="","",정비항목!$B7) -> 정기검사 | D10: =IF($A10="","",IF(정비항목!$C7="",0,정비항목!$C7)) -> 0 | E10: =IF($A10="","",IF(정비항목!$D7="",0,정비항목!$D7)) -> 12 | F10: =IF($A10="","",IF(COUNTIFS(정비이력!$B$3:$B$1002,$A10,정비이력!$D$3:$D$1002,정비항목!$A7)=0,"",SUMPRODUCT(MAX((정비이력!$B$3:$B$1002=$A10)*(정비이력!$D$3:$D$1002=정비항목!$A7)*정비이력!$A$3:$A$1002)))) | G10: =IF($A10="","",IF($F10="","",SUMPRODUCT(MAX((정비이력!$B$3:$B$1002=$A10)*(정비이력!$D$3:$D$1002=정비항목!$A7)*정비이력!$F$3:$F$1002)))) | H10: =IF($A10="","",IF(차량목록!$E3="",0,차량목록!$E3)) -> 81800 | I10: =IF(OR($A10="",$D10=0),"",IF($G10="",$H10+$D10,$G10+$D10)) | J10: =IF($I10="","",$I10-$H10) | K10: =IF(OR($A10="",$E10=0),"",IF($F10="",EDATE(TODAY(),$E10),EDATE($F10,$E10))) -> 46644 | L10: =IF($K10="","",$K10-TODAY()) -> 365 | M10: =IF($A10="","",IF(AND($J10="",$L10=""),"-",IF(OR(AND($J10<>"",$J10<=0),AND($L10<>"",$L10<0)),"교체",IF(OR(AND($J10<>"",$J10<=사용안내!$C$16),AND($L10<>"",$L10<=사용안내!$C$17)),"임박","정상")))) -> 정상
A11: =IF(OR(차량목록!$A3="",정비항목!$A8="",차량목록!$G3="매각"),"",차량목록!$A3) | B11: =IF($A11="","",차량목록!$B3) | C11: =IF($A11="","",정비항목!$B8) | D11: =IF($A11="","",IF(정비항목!$C8="",0,정비항목!$C8)) | E11: =IF($A11="","",IF(정비항목!$D8="",0,정비항목!$D8)) | F11: =IF($A11="","",IF(COUNTIFS(정비이력!$B$3:$B$1002,$A11,정비이력!$D$3:$D$1002,정비항목!$A8)=0,"",SUMPRODUCT(MAX((정비이력!$B$3:$B$1002=$A11)*(정비이력!$D$3:$D$1002=정비항목!$A8)*정비이력!$A$3:$A$1002)))) | G11: =IF($A11="","",IF($F11="","",SUMPRODUCT(MAX((정비이력!$B$3:$B$1002=$A11)*(정비이력!$D$3:$D$1002=정비항목!$A8)*정비이력!$F$3:$F$1002)))) | H11: =IF($A11="","",IF(차량목록!$E3="",0,차량목록!$E3)) | I11: =IF(OR($A11="",$D11=0),"",IF($G11="",$H11+$D11,$G11+$D11)) | J11: =IF($I11="","",$I11-$H11) | K11: =IF(OR($A11="",$E11=0),"",IF($F11="",EDATE(TODAY(),$E11),EDATE($F11,$E11))) | L11: =IF($K11="","",$K11-TODAY()) | M11: =IF($A11="","",IF(AND($J11="",$L11=""),"-",IF(OR(AND($J11<>"",$J11<=0),AND($L11<>"",$L11<0)),"교체",IF(OR(AND($J11<>"",$J11<=사용안내!$C$16),AND($L11<>"",$L11<=사용안내!$C$17)),"임박","정상"))))
A12: =IF(OR(차량목록!$A3="",정비항목!$A9="",차량목록!$G3="매각"),"",차량목록!$A3) | B12: =IF($A12="","",차량목록!$B3) | C12: =IF($A12="","",정비항목!$B9) | D12: =IF($A12="","",IF(정비항목!$C9="",0,정비항목!$C9)) | E12: =IF($A12="","",IF(정비항목!$D9="",0,정비항목!$D9)) | F12: =IF($A12="","",IF(COUNTIFS(정비이력!$B$3:$B$1002,$A12,정비이력!$D$3:$D$1002,정비항목!$A9)=0,"",SUMPRODUCT(MAX((정비이력!$B$3:$B$1002=$A12)*(정비이력!$D$3:$D$1002=정비항목!$A9)*정비이력!$A$3:$A$1002)))) | G12: =IF($A12="","",IF($F12="","",SUMPRODUCT(MAX((정비이력!$B$3:$B$1002=$A12)*(정비이력!$D$3:$D$1002=정비항목!$A9)*정비이력!$F$3:$F$1002)))) | H12: =IF($A12="","",IF(차량목록!$E3="",0,차량목록!$E3)) | I12: =IF(OR($A12="",$D12=0),"",IF($G12="",$H12+$D12,$G12+$D12)) | J12: =IF($I12="","",$I12-$H12) | K12: =IF(OR($A12="",$E12=0),"",IF($F12="",EDATE(TODAY(),$E12),EDATE($F12,$E12))) | L12: =IF($K12="","",$K12-TODAY()) | M12: =IF($A12="","",IF(AND($J12="",$L12=""),"-",IF(OR(AND($J12<>"",$J12<=0),AND($L12<>"",$L12<0)),"교체",IF(OR(AND($J12<>"",$J12<=사용안내!$C$16),AND($L12<>"",$L12<=사용안내!$C$17)),"임박","정상"))))
A13: =IF(OR(차량목록!$A3="",정비항목!$A10="",차량목록!$G3="매각"),"",차량목록!$A3) | B13: =IF($A13="","",차량목록!$B3) | C13: =IF($A13="","",정비항목!$B10) | D13: =IF($A13="","",IF(정비항목!$C10="",0,정비항목!$C10)) | E13: =IF($A13="","",IF(정비항목!$D10="",0,정비항목!$D10)) | F13: =IF($A13="","",IF(COUNTIFS(정비이력!$B$3:$B$1002,$A13,정비이력!$D$3:$D$1002,정비항목!$A10)=0,"",SUMPRODUCT(MAX((정비이력!$B$3:$B$1002=$A13)*(정비이력!$D$3:$D$1002=정비항목!$A10)*정비이력!$A$3:$A$1002)))) | G13: =IF($A13="","",IF($F13="","",SUMPRODUCT(MAX((정비이력!$B$3:$B$1002=$A13)*(정비이력!$D$3:$D$1002=정비항목!$A10)*정비이력!$F$3:$F$1002)))) | H13: =IF($A13="","",IF(차량목록!$E3="",0,차량목록!$E3)) | I13: =IF(OR($A13="",$D13=0),"",IF($G13="",$H13+$D13,$G13+$D13)) | J13: =IF($I13="","",$I13-$H13) | K13: =IF(OR($A13="",$E13=0),"",IF($F13="",EDATE(TODAY(),$E13),EDATE($F13,$E13))) | L13: =IF($K13="","",$K13-TODAY()) | M13: =IF($A13="","",IF(AND($J13="",$L13=""),"-",IF(OR(AND($J13<>"",$J13<=0),AND($L13<>"",$L13<0)),"교체",IF(OR(AND($J13<>"",$J13<=사용안내!$C$16),AND($L13<>"",$L13<=사용안내!$C$17)),"임박","정상"))))
A14: =IF(OR(차량목록!$A3="",정비항목!$A11="",차량목록!$G3="매각"),"",차량목록!$A3) | B14: =IF($A14="","",차량목록!$B3) | C14: =IF($A14="","",정비항목!$B11) | D14: =IF($A14="","",IF(정비항목!$C11="",0,정비항목!$C11)) | E14: =IF($A14="","",IF(정비항목!$D11="",0,정비항목!$D11)) | F14: =IF($A14="","",IF(COUNTIFS(정비이력!$B$3:$B$1002,$A14,정비이력!$D$3:$D$1002,정비항목!$A11)=0,"",SUMPRODUCT(MAX((정비이력!$B$3:$B$1002=$A14)*(정비이력!$D$3:$D$1002=정비항목!$A11)*정비이력!$A$3:$A$1002)))) | G14: =IF($A14="","",IF($F14="","",SUMPRODUCT(MAX((정비이력!$B$3:$B$1002=$A14)*(정비이력!$D$3:$D$1002=정비항목!$A11)*정비이력!$F$3:$F$1002)))) | H14: =IF($A14="","",IF(차량목록!$E3="",0,차량목록!$E3)) | I14: =IF(OR($A14="",$D14=0),"",IF($G14="",$H14+$D14,$G14+$D14)) | J14: =IF($I14="","",$I14-$H14) | K14: =IF(OR($A14="",$E14=0),"",IF($F14="",EDATE(TODAY(),$E14),EDATE($F14,$E14))) | L14: =IF($K14="","",$K14-TODAY()) | M14: =IF($A14="","",IF(AND($J14="",$L14=""),"-",IF(OR(AND($J14<>"",$J14<=0),AND($L14<>"",$L14<0)),"교체",IF(OR(AND($J14<>"",$J14<=사용안내!$C$16),AND($L14<>"",$L14<=사용안내!$C$17)),"임박","정상"))))
A15: =IF(OR(차량목록!$A3="",정비항목!$A12="",차량목록!$G3="매각"),"",차량목록!$A3) | B15: =IF($A15="","",차량목록!$B3) | C15: =IF($A15="","",정비항목!$B12) | D15: =IF($A15="","",IF(정비항목!$C12="",0,정비항목!$C12)) | E15: =IF($A15="","",IF(정비항목!$D12="",0,정비항목!$D12)) | F15: =IF($A15="","",IF(COUNTIFS(정비이력!$B$3:$B$1002,$A15,정비이력!$D$3:$D$1002,정비항목!$A12)=0,"",SUMPRODUCT(MAX((정비이력!$B$3:$B$1002=$A15)*(정비이력!$D$3:$D$1002=정비항목!$A12)*정비이력!$A$3:$A$1002)))) | G15: =IF($A15="","",IF($F15="","",SUMPRODUCT(MAX((정비이력!$B$3:$B$1002=$A15)*(정비이력!$D$3:$D$1002=정비항목!$A12)*정비이력!$F$3:$F$1002)))) | H15: =IF($A15="","",IF(차량목록!$E3="",0,차량목록!$E3)) | I15: =IF(OR($A15="",$D15=0),"",IF($G15="",$H15+$D15,$G15+$D15)) | J15: =IF($I15="","",$I15-$H15) | K15: =IF(OR($A15="",$E15=0),"",IF($F15="",EDATE(TODAY(),$E15),EDATE($F15,$E15))) | L15: =IF($K15="","",$K15-TODAY()) | M15: =IF($A15="","",IF(AND($J15="",$L15=""),"-",IF(OR(AND($J15<>"",$J15<=0),AND($L15<>"",$L15<0)),"교체",IF(OR(AND($J15<>"",$J15<=사용안내!$C$16),AND($L15<>"",$L15<=사용안내!$C$17)),"임박","정상"))))
A16: =IF(OR(차량목록!$A3="",정비항목!$A13="",차량목록!$G3="매각"),"",차량목록!$A3) | B16: =IF($A16="","",차량목록!$B3) | C16: =IF($A16="","",정비항목!$B13) | D16: =IF($A16="","",IF(정비항목!$C13="",0,정비항목!$C13)) | E16: =IF($A16="","",IF(정비항목!$D13="",0,정비항목!$D13)) | F16: =IF($A16="","",IF(COUNTIFS(정비이력!$B$3:$B$1002,$A16,정비이력!$D$3:$D$1002,정비항목!$A13)=0,"",SUMPRODUCT(MAX((정비이력!$B$3:$B$1002=$A16)*(정비이력!$D$3:$D$1002=정비항목!$A13)*정비이력!$A$3:$A$1002)))) | G16: =IF($A16="","",IF($F16="","",SUMPRODUCT(MAX((정비이력!$B$3:$B$1002=$A16)*(정비이력!$D$3:$D$1002=정비항목!$A13)*정비이력!$F$3:$F$1002)))) | H16: =IF($A16="","",IF(차량목록!$E3="",0,차량목록!$E3)) | I16: =IF(OR($A16="",$D16=0),"",IF($G16="",$H16+$D16,$G16+$D16)) | J16: =IF($I16="","",$I16-$H16) | K16: =IF(OR($A16="",$E16=0),"",IF($F16="",EDATE(TODAY(),$E16),EDATE($F16,$E16))) | L16: =IF($K16="","",$K16-TODAY()) | M16: =IF($A16="","",IF(AND($J16="",$L16=""),"-",IF(OR(AND($J16<>"",$J16<=0),AND($L16<>"",$L16<0)),"교체",IF(OR(AND($J16<>"",$J16<=사용안내!$C$16),AND($L16<>"",$L16<=사용안내!$C$17)),"임박","정상"))))
A17: =IF(OR(차량목록!$A3="",정비항목!$A14="",차량목록!$G3="매각"),"",차량목록!$A3) | B17: =IF($A17="","",차량목록!$B3) | C17: =IF($A17="","",정비항목!$B14) | D17: =IF($A17="","",IF(정비항목!$C14="",0,정비항목!$C14)) | E17: =IF($A17="","",IF(정비항목!$D14="",0,정비항목!$D14)) | F17: =IF($A17="","",IF(COUNTIFS(정비이력!$B$3:$B$1002,$A17,정비이력!$D$3:$D$1002,정비항목!$A14)=0,"",SUMPRODUCT(MAX((정비이력!$B$3:$B$1002=$A17)*(정비이력!$D$3:$D$1002=정비항목!$A14)*정비이력!$A$3:$A$1002)))) | G17: =IF($A17="","",IF($F17="","",SUMPRODUCT(MAX((정비이력!$B$3:$B$1002=$A17)*(정비이력!$D$3:$D$1002=정비항목!$A14)*정비이력!$F$3:$F$1002)))) | H17: =IF($A17="","",IF(차량목록!$E3="",0,차량목록!$E3)) | I17: =IF(OR($A17="",$D17=0),"",IF($G17="",$H17+$D17,$G17+$D17)) | J17: =IF($I17="","",$I17-$H17) | K17: =IF(OR($A17="",$E17=0),"",IF($F17="",EDATE(TODAY(),$E17),EDATE($F17,$E17))) | L17: =IF($K17="","",$K17-TODAY()) | M17: =IF($A17="","",IF(AND($J17="",$L17=""),"-",IF(OR(AND($J17<>"",$J17<=0),AND($L17<>"",$L17<0)),"교체",IF(OR(AND($J17<>"",$J17<=사용안내!$C$16),AND($L17<>"",$L17<=사용안내!$C$17)),"임박","정상"))))
A18: =IF(OR(차량목록!$A4="",정비항목!$A3="",차량목록!$G4="매각"),"",차량목록!$A4) -> 34나5678 | B18: =IF($A18="","",차량목록!$B4) -> 봉고3 | C18: =IF($A18="","",정비항목!$B3) -> 엔진오일 | D18: =IF($A18="","",IF(정비항목!$C3="",0,정비항목!$C3)) -> 10000 | E18: =IF($A18="","",IF(정비항목!$D3="",0,정비항목!$D3)) -> 6 | F18: =IF($A18="","",IF(COUNTIFS(정비이력!$B$3:$B$1002,$A18,정비이력!$D$3:$D$1002,정비항목!$A3)=0,"",SUMPRODUCT(MAX((정비이력!$B$3:$B$1002=$A18)*(정비이력!$D$3:$D$1002=정비항목!$A3)*정비이력!$A$3:$A$1002)))) -> 46235 | G18: =IF($A18="","",IF($F18="","",SUMPRODUCT(MAX((정비이력!$B$3:$B$1002=$A18)*(정비이력!$D$3:$D$1002=정비항목!$A3)*정비이력!$F$3:$F$1002)))) -> 38000 | H18: =IF($A18="","",IF(차량목록!$E4="",0,차량목록!$E4)) -> 42300 | I18: =IF(OR($A18="",$D18=0),"",IF($G18="",$H18+$D18,$G18+$D18)) -> 48000 | J18: =IF($I18="","",$I18-$H18) -> 5700 | K18: =IF(OR($A18="",$E18=0),"",IF($F18="",EDATE(TODAY(),$E18),EDATE($F18,$E18))) -> 46419 | L18: =IF($K18="","",$K18-TODAY()) -> 140 | M18: =IF($A18="","",IF(AND($J18="",$L18=""),"-",IF(OR(AND($J18<>"",$J18<=0),AND($L18<>"",$L18<0)),"교체",IF(OR(AND($J18<>"",$J18<=사용안내!$C$16),AND($L18<>"",$L18<=사용안내!$C$17)),"임박","정상")))) -> 정상
A19: =IF(OR(차량목록!$A4="",정비항목!$A4="",차량목록!$G4="매각"),"",차량목록!$A4) -> 34나5678 | B19: =IF($A19="","",차량목록!$B4) -> 봉고3 | C19: =IF($A19="","",정비항목!$B4) -> 에어크리너 | D19: =IF($A19="","",IF(정비항목!$C4="",0,정비항목!$C4)) -> 20000 | E19: =IF($A19="","",IF(정비항목!$D4="",0,정비항목!$D4)) -> 12 | F19: =IF($A19="","",IF(COUNTIFS(정비이력!$B$3:$B$1002,$A19,정비이력!$D$3:$D$1002,정비항목!$A4)=0,"",SUMPRODUCT(MAX((정비이력!$B$3:$B$1002=$A19)*(정비이력!$D$3:$D$1002=정비항목!$A4)*정비이력!$A$3:$A$1002)))) | G19: =IF($A19="","",IF($F19="","",SUMPRODUCT(MAX((정비이력!$B$3:$B$1002=$A19)*(정비이력!$D$3:$D$1002=정비항목!$A4)*정비이력!$F$3:$F$1002)))) | H19: =IF($A19="","",IF(차량목록!$E4="",0,차량목록!$E4)) -> 42300 | I19: =IF(OR($A19="",$D19=0),"",IF($G19="",$H19+$D19,$G19+$D19)) -> 62300 | J19: =IF($I19="","",$I19-$H19) -> 20000 | K19: =IF(OR($A19="",$E19=0),"",IF($F19="",EDATE(TODAY(),$E19),EDATE($F19,$E19))) -> 46644 | L19: =IF($K19="","",$K19-TODAY()) -> 365 | M19: =IF($A19="","",IF(AND($J19="",$L19=""),"-",IF(OR(AND($J19<>"",$J19<=0),AND($L19<>"",$L19<0)),"교체",IF(OR(AND($J19<>"",$J19<=사용안내!$C$16),AND($L19<>"",$L19<=사용안내!$C$17)),"임박","정상")))) -> 정상
A20: =IF(OR(차량목록!$A4="",정비항목!$A5="",차량목록!$G4="매각"),"",차량목록!$A4) -> 34나5678 | B20: =IF($A20="","",차량목록!$B4) -> 봉고3 | C20: =IF($A20="","",정비항목!$B5) -> 타이어 | D20: =IF($A20="","",IF(정비항목!$C5="",0,정비항목!$C5)) -> 50000 | E20: =IF($A20="","",IF(정비항목!$D5="",0,정비항목!$D5)) -> 36 | F20: =IF($A20="","",IF(COUNTIFS(정비이력!$B$3:$B$1002,$A20,정비이력!$D$3:$D$1002,정비항목!$A5)=0,"",SUMPRODUCT(MAX((정비이력!$B$3:$B$1002=$A20)*(정비이력!$D$3:$D$1002=정비항목!$A5)*정비이력!$A$3:$A$1002)))) | G20: =IF($A20="","",IF($F20="","",SUMPRODUCT(MAX((정비이력!$B$3:$B$1002=$A20)*(정비이력!$D$3:$D$1002=정비항목!$A5)*정비이력!$F$3:$F$1002)))) | H20: =IF($A20="","",IF(차량목록!$E4="",0,차량목록!$E4)) -> 42300 | I20: =IF(OR($A20="",$D20=0),"",IF($G20="",$H20+$D20,$G20+$D20)) -> 92300 | J20: =IF($I20="","",$I20-$H20) -> 50000 | K20: =IF(OR($A20="",$E20=0),"",IF($F20="",EDATE(TODAY(),$E20),EDATE($F20,$E20))) -> 47375 | L20: =IF($K20="","",$K20-TODAY()) -> 1096 | M20: =IF($A20="","",IF(AND($J20="",$L20=""),"-",IF(OR(AND($J20<>"",$J20<=0),AND($L20<>"",$L20<0)),"교체",IF(OR(AND($J20<>"",$J20<=사용안내!$C$16),AND($L20<>"",$L20<=사용안내!$C$17)),"임박","정상")))) -> 정상
A21: =IF(OR(차량목록!$A4="",정비항목!$A6="",차량목록!$G4="매각"),"",차량목록!$A4) -> 34나5678 | B21: =IF($A21="","",차량목록!$B4) -> 봉고3 | C21: =IF($A21="","",정비항목!$B6) -> 브레이크 패드 | D21: =IF($A21="","",IF(정비항목!$C6="",0,정비항목!$C6)) -> 40000 | E21: =IF($A21="","",IF(정비항목!$D6="",0,정비항목!$D6)) -> 24 | F21: =IF($A21="","",IF(COUNTIFS(정비이력!$B$3:$B$1002,$A21,정비이력!$D$3:$D$1002,정비항목!$A6)=0,"",SUMPRODUCT(MAX((정비이력!$B$3:$B$1002=$A21)*(정비이력!$D$3:$D$1002=정비항목!$A6)*정비이력!$A$3:$A$1002)))) | G21: =IF($A21="","",IF($F21="","",SUMPRODUCT(MAX((정비이력!$B$3:$B$1002=$A21)*(정비이력!$D$3:$D$1002=정비항목!$A6)*정비이력!$F$3:$F$1002)))) | H21: =IF($A21="","",IF(차량목록!$E4="",0,차량목록!$E4)) -> 42300 | I21: =IF(OR($A21="",$D21=0),"",IF($G21="",$H21+$D21,$G21+$D21)) -> 82300 | J21: =IF($I21="","",$I21-$H21) -> 40000 | K21: =IF(OR($A21="",$E21=0),"",IF($F21="",EDATE(TODAY(),$E21),EDATE($F21,$E21))) -> 47010 | L21: =IF($K21="","",$K21-TODAY()) -> 731 | M21: =IF($A21="","",IF(AND($J21="",$L21=""),"-",IF(OR(AND($J21<>"",$J21<=0),AND($L21<>"",$L21<0)),"교체",IF(OR(AND($J21<>"",$J21<=사용안내!$C$16),AND($L21<>"",$L21<=사용안내!$C$17)),"임박","정상")))) -> 정상
A22: =IF(OR(차량목록!$A4="",정비항목!$A7="",차량목록!$G4="매각"),"",차량목록!$A4) -> 34나5678 | B22: =IF($A22="","",차량목록!$B4) -> 봉고3 | C22: =IF($A22="","",정비항목!$B7) -> 정기검사 | D22: =IF($A22="","",IF(정비항목!$C7="",0,정비항목!$C7)) -> 0 | E22: =IF($A22="","",IF(정비항목!$D7="",0,정비항목!$D7)) -> 12 | F22: =IF($A22="","",IF(COUNTIFS(정비이력!$B$3:$B$1002,$A22,정비이력!$D$3:$D$1002,정비항목!$A7)=0,"",SUMPRODUCT(MAX((정비이력!$B$3:$B$1002=$A22)*(정비이력!$D$3:$D$1002=정비항목!$A7)*정비이력!$A$3:$A$1002)))) | G22: =IF($A22="","",IF($F22="","",SUMPRODUCT(MAX((정비이력!$B$3:$B$1002=$A22)*(정비이력!$D$3:$D$1002=정비항목!$A7)*정비이력!$F$3:$F$1002)))) | H22: =IF($A22="","",IF(차량목록!$E4="",0,차량목록!$E4)) -> 42300 | I22: =IF(OR($A22="",$D22=0),"",IF($G22="",$H22+$D22,$G22+$D22)) | J22: =IF($I22="","",$I22-$H22) | K22: =IF(OR($A22="",$E22=0),"",IF($F22="",EDATE(TODAY(),$E22),EDATE($F22,$E22))) -> 46644 | L22: =IF($K22="","",$K22-TODAY()) -> 365 | M22: =IF($A22="","",IF(AND($J22="",$L22=""),"-",IF(OR(AND($J22<>"",$J22<=0),AND($L22<>"",$L22<0)),"교체",IF(OR(AND($J22<>"",$J22<=사용안내!$C$16),AND($L22<>"",$L22<=사용안내!$C$17)),"임박","정상")))) -> 정상
A23: =IF(OR(차량목록!$A4="",정비항목!$A8="",차량목록!$G4="매각"),"",차량목록!$A4) | B23: =IF($A23="","",차량목록!$B4) | C23: =IF($A23="","",정비항목!$B8) | D23: =IF($A23="","",IF(정비항목!$C8="",0,정비항목!$C8)) | E23: =IF($A23="","",IF(정비항목!$D8="",0,정비항목!$D8)) | F23: =IF($A23="","",IF(COUNTIFS(정비이력!$B$3:$B$1002,$A23,정비이력!$D$3:$D$1002,정비항목!$A8)=0,"",SUMPRODUCT(MAX((정비이력!$B$3:$B$1002=$A23)*(정비이력!$D$3:$D$1002=정비항목!$A8)*정비이력!$A$3:$A$1002)))) | G23: =IF($A23="","",IF($F23="","",SUMPRODUCT(MAX((정비이력!$B$3:$B$1002=$A23)*(정비이력!$D$3:$D$1002=정비항목!$A8)*정비이력!$F$3:$F$1002)))) | H23: =IF($A23="","",IF(차량목록!$E4="",0,차량목록!$E4)) | I23: =IF(OR($A23="",$D23=0),"",IF($G23="",$H23+$D23,$G23+$D23)) | J23: =IF($I23="","",$I23-$H23) | K23: =IF(OR($A23="",$E23=0),"",IF($F23="",EDATE(TODAY(),$E23),EDATE($F23,$E23))) | L23: =IF($K23="","",$K23-TODAY()) | M23: =IF($A23="","",IF(AND($J23="",$L23=""),"-",IF(OR(AND($J23<>"",$J23<=0),AND($L23<>"",$L23<0)),"교체",IF(OR(AND($J23<>"",$J23<=사용안내!$C$16),AND($L23<>"",$L23<=사용안내!$C$17)),"임박","정상"))))
A24: =IF(OR(차량목록!$A4="",정비항목!$A9="",차량목록!$G4="매각"),"",차량목록!$A4) | B24: =IF($A24="","",차량목록!$B4) | C24: =IF($A24="","",정비항목!$B9) | D24: =IF($A24="","",IF(정비항목!$C9="",0,정비항목!$C9)) | E24: =IF($A24="","",IF(정비항목!$D9="",0,정비항목!$D9)) | F24: =IF($A24="","",IF(COUNTIFS(정비이력!$B$3:$B$1002,$A24,정비이력!$D$3:$D$1002,정비항목!$A9)=0,"",SUMPRODUCT(MAX((정비이력!$B$3:$B$1002=$A24)*(정비이력!$D$3:$D$1002=정비항목!$A9)*정비이력!$A$3:$A$1002)))) | G24: =IF($A24="","",IF($F24="","",SUMPRODUCT(MAX((정비이력!$B$3:$B$1002=$A24)*(정비이력!$D$3:$D$1002=정비항목!$A9)*정비이력!$F$3:$F$1002)))) | H24: =IF($A24="","",IF(차량목록!$E4="",0,차량목록!$E4)) | I24: =IF(OR($A24="",$D24=0),"",IF($G24="",$H24+$D24,$G24+$D24)) | J24: =IF($I24="","",$I24-$H24) | K24: =IF(OR($A24="",$E24=0),"",IF($F24="",EDATE(TODAY(),$E24),EDATE($F24,$E24))) | L24: =IF($K24="","",$K24-TODAY()) | M24: =IF($A24="","",IF(AND($J24="",$L24=""),"-",IF(OR(AND($J24<>"",$J24<=0),AND($L24<>"",$L24<0)),"교체",IF(OR(AND($J24<>"",$J24<=사용안내!$C$16),AND($L24<>"",$L24<=사용안내!$C$17)),"임박","정상"))))
A25: =IF(OR(차량목록!$A4="",정비항목!$A10="",차량목록!$G4="매각"),"",차량목록!$A4) | B25: =IF($A25="","",차량목록!$B4) | C25: =IF($A25="","",정비항목!$B10) | D25: =IF($A25="","",IF(정비항목!$C10="",0,정비항목!$C10)) | E25: =IF($A25="","",IF(정비항목!$D10="",0,정비항목!$D10)) | F25: =IF($A25="","",IF(COUNTIFS(정비이력!$B$3:$B$1002,$A25,정비이력!$D$3:$D$1002,정비항목!$A10)=0,"",SUMPRODUCT(MAX((정비이력!$B$3:$B$1002=$A25)*(정비이력!$D$3:$D$1002=정비항목!$A10)*정비이력!$A$3:$A$1002)))) | G25: =IF($A25="","",IF($F25="","",SUMPRODUCT(MAX((정비이력!$B$3:$B$1002=$A25)*(정비이력!$D$3:$D$1002=정비항목!$A10)*정비이력!$F$3:$F$1002)))) | H25: =IF($A25="","",IF(차량목록!$E4="",0,차량목록!$E4)) | I25: =IF(OR($A25="",$D25=0),"",IF($G25="",$H25+$D25,$G25+$D25)) | J25: =IF($I25="","",$I25-$H25) | K25: =IF(OR($A25="",$E25=0),"",IF($F25="",EDATE(TODAY(),$E25),EDATE($F25,$E25))) | L25: =IF($K25="","",$K25-TODAY()) | M25: =IF($A25="","",IF(AND($J25="",$L25=""),"-",IF(OR(AND($J25<>"",$J25<=0),AND($L25<>"",$L25<0)),"교체",IF(OR(AND($J25<>"",$J25<=사용안내!$C$16),AND($L25<>"",$L25<=사용안내!$C$17)),"임박","정상"))))
A26: =IF(OR(차량목록!$A4="",정비항목!$A11="",차량목록!$G4="매각"),"",차량목록!$A4) | B26: =IF($A26="","",차량목록!$B4) | C26: =IF($A26="","",정비항목!$B11) | D26: =IF($A26="","",IF(정비항목!$C11="",0,정비항목!$C11)) | E26: =IF($A26="","",IF(정비항목!$D11="",0,정비항목!$D11)) | F26: =IF($A26="","",IF(COUNTIFS(정비이력!$B$3:$B$1002,$A26,정비이력!$D$3:$D$1002,정비항목!$A11)=0,"",SUMPRODUCT(MAX((정비이력!$B$3:$B$1002=$A26)*(정비이력!$D$3:$D$1002=정비항목!$A11)*정비이력!$A$3:$A$1002)))) | G26: =IF($A26="","",IF($F26="","",SUMPRODUCT(MAX((정비이력!$B$3:$B$1002=$A26)*(정비이력!$D$3:$D$1002=정비항목!$A11)*정비이력!$F$3:$F$1002)))) | H26: =IF($A26="","",IF(차량목록!$E4="",0,차량목록!$E4)) | I26: =IF(OR($A26="",$D26=0),"",IF($G26="",$H26+$D26,$G26+$D26)) | J26: =IF($I26="","",$I26-$H26) | K26: =IF(OR($A26="",$E26=0),"",IF($F26="",EDATE(TODAY(),$E26),EDATE($F26,$E26))) | L26: =IF($K26="","",$K26-TODAY()) | M26: =IF($A26="","",IF(AND($J26="",$L26=""),"-",IF(OR(AND($J26<>"",$J26<=0),AND($L26<>"",$L26<0)),"교체",IF(OR(AND($J26<>"",$J26<=사용안내!$C$16),AND($L26<>"",$L26<=사용안내!$C$17)),"임박","정상"))))
A27: =IF(OR(차량목록!$A4="",정비항목!$A12="",차량목록!$G4="매각"),"",차량목록!$A4) | B27: =IF($A27="","",차량목록!$B4) | C27: =IF($A27="","",정비항목!$B12) | D27: =IF($A27="","",IF(정비항목!$C12="",0,정비항목!$C12)) | E27: =IF($A27="","",IF(정비항목!$D12="",0,정비항목!$D12)) | F27: =IF($A27="","",IF(COUNTIFS(정비이력!$B$3:$B$1002,$A27,정비이력!$D$3:$D$1002,정비항목!$A12)=0,"",SUMPRODUCT(MAX((정비이력!$B$3:$B$1002=$A27)*(정비이력!$D$3:$D$1002=정비항목!$A12)*정비이력!$A$3:$A$1002)))) | G27: =IF($A27="","",IF($F27="","",SUMPRODUCT(MAX((정비이력!$B$3:$B$1002=$A27)*(정비이력!$D$3:$D$1002=정비항목!$A12)*정비이력!$F$3:$F$1002)))) | H27: =IF($A27="","",IF(차량목록!$E4="",0,차량목록!$E4)) | I27: =IF(OR($A27="",$D27=0),"",IF($G27="",$H27+$D27,$G27+$D27)) | J27: =IF($I27="","",$I27-$H27) | K27: =IF(OR($A27="",$E27=0),"",IF($F27="",EDATE(TODAY(),$E27),EDATE($F27,$E27))) | L27: =IF($K27="","",$K27-TODAY()) | M27: =IF($A27="","",IF(AND($J27="",$L27=""),"-",IF(OR(AND($J27<>"",$J27<=0),AND($L27<>"",$L27<0)),"교체",IF(OR(AND($J27<>"",$J27<=사용안내!$C$16),AND($L27<>"",$L27<=사용안내!$C$17)),"임박","정상"))))
A28: =IF(OR(차량목록!$A4="",정비항목!$A13="",차량목록!$G4="매각"),"",차량목록!$A4) | B28: =IF($A28="","",차량목록!$B4) | C28: =IF($A28="","",정비항목!$B13) | D28: =IF($A28="","",IF(정비항목!$C13="",0,정비항목!$C13)) | E28: =IF($A28="","",IF(정비항목!$D13="",0,정비항목!$D13)) | F28: =IF($A28="","",IF(COUNTIFS(정비이력!$B$3:$B$1002,$A28,정비이력!$D$3:$D$1002,정비항목!$A13)=0,"",SUMPRODUCT(MAX((정비이력!$B$3:$B$1002=$A28)*(정비이력!$D$3:$D$1002=정비항목!$A13)*정비이력!$A$3:$A$1002)))) | G28: =IF($A28="","",IF($F28="","",SUMPRODUCT(MAX((정비이력!$B$3:$B$1002=$A28)*(정비이력!$D$3:$D$1002=정비항목!$A13)*정비이력!$F$3:$F$1002)))) | H28: =IF($A28="","",IF(차량목록!$E4="",0,차량목록!$E4)) | I28: =IF(OR($A28="",$D28=0),"",IF($G28="",$H28+$D28,$G28+$D28)) | J28: =IF($I28="","",$I28-$H28) | K28: =IF(OR($A28="",$E28=0),"",IF($F28="",EDATE(TODAY(),$E28),EDATE($F28,$E28))) | L28: =IF($K28="","",$K28-TODAY()) | M28: =IF($A28="","",IF(AND($J28="",$L28=""),"-",IF(OR(AND($J28<>"",$J28<=0),AND($L28<>"",$L28<0)),"교체",IF(OR(AND($J28<>"",$J28<=사용안내!$C$16),AND($L28<>"",$L28<=사용안내!$C$17)),"임박","정상"))))
A29: =IF(OR(차량목록!$A4="",정비항목!$A14="",차량목록!$G4="매각"),"",차량목록!$A4) | B29: =IF($A29="","",차량목록!$B4) | C29: =IF($A29="","",정비항목!$B14) | D29: =IF($A29="","",IF(정비항목!$C14="",0,정비항목!$C14)) | E29: =IF($A29="","",IF(정비항목!$D14="",0,정비항목!$D14)) | F29: =IF($A29="","",IF(COUNTIFS(정비이력!$B$3:$B$1002,$A29,정비이력!$D$3:$D$1002,정비항목!$A14)=0,"",SUMPRODUCT(MAX((정비이력!$B$3:$B$1002=$A29)*(정비이력!$D$3:$D$1002=정비항목!$A14)*정비이력!$A$3:$A$1002)))) | G29: =IF($A29="","",IF($F29="","",SUMPRODUCT(MAX((정비이력!$B$3:$B$1002=$A29)*(정비이력!$D$3:$D$1002=정비항목!$A14)*정비이력!$F$3:$F$1002)))) | H29: =IF($A29="","",IF(차량목록!$E4="",0,차량목록!$E4)) | I29: =IF(OR($A29="",$D29=0),"",IF($G29="",$H29+$D29,$G29+$D29)) | J29: =IF($I29="","",$I29-$H29) | K29: =IF(OR($A29="",$E29=0),"",IF($F29="",EDATE(TODAY(),$E29),EDATE($F29,$E29))) | L29: =IF($K29="","",$K29-TODAY()) | M29: =IF($A29="","",IF(AND($J29="",$L29=""),"-",IF(OR(AND($J29<>"",$J29<=0),AND($L29<>"",$L29<0)),"교체",IF(OR(AND($J29<>"",$J29<=사용안내!$C$16),AND($L29<>"",$L29<=사용안내!$C$17)),"임박","정상"))))
A30: =IF(OR(차량목록!$A5="",정비항목!$A3="",차량목록!$G5="매각"),"",차량목록!$A5) -> 56다7890 | B30: =IF($A30="","",차량목록!$B5) -> 스타렉스 | C30: =IF($A30="","",정비항목!$B3) -> 엔진오일 | D30: =IF($A30="","",IF(정비항목!$C3="",0,정비항목!$C3)) -> 10000 | E30: =IF($A30="","",IF(정비항목!$D3="",0,정비항목!$D3)) -> 6 | F30: =IF($A30="","",IF(COUNTIFS(정비이력!$B$3:$B$1002,$A30,정비이력!$D$3:$D$1002,정비항목!$A3)=0,"",SUMPRODUCT(MAX((정비이력!$B$3:$B$1002=$A30)*(정비이력!$D$3:$D$1002=정비항목!$A3)*정비이력!$A$3:$A$1002)))) | G30: =IF($A30="","",IF($F30="","",SUMPRODUCT(MAX((정비이력!$B$3:$B$1002=$A30)*(정비이력!$D$3:$D$1002=정비항목!$A3)*정비이력!$F$3:$F$1002)))) | H30: =IF($A30="","",IF(차량목록!$E5="",0,차량목록!$E5)) -> 125000 | I30: =IF(OR($A30="",$D30=0),"",IF($G30="",$H30+$D30,$G30+$D30)) -> 135000 | J30: =IF($I30="","",$I30-$H30) -> 10000 | K30: =IF(OR($A30="",$E30=0),"",IF($F30="",EDATE(TODAY(),$E30),EDATE($F30,$E30))) -> 46460 | L30: =IF($K30="","",$K30-TODAY()) -> 181 | M30: =IF($A30="","",IF(AND($J30="",$L30=""),"-",IF(OR(AND($J30<>"",$J30<=0),AND($L30<>"",$L30<0)),"교체",IF(OR(AND($J30<>"",$J30<=사용안내!$C$16),AND($L30<>"",$L30<=사용안내!$C$17)),"임박","정상")))) -> 정상
A31: =IF(OR(차량목록!$A5="",정비항목!$A4="",차량목록!$G5="매각"),"",차량목록!$A5) -> 56다7890 | B31: =IF($A31="","",차량목록!$B5) -> 스타렉스 | C31: =IF($A31="","",정비항목!$B4) -> 에어크리너 | D31: =IF($A31="","",IF(정비항목!$C4="",0,정비항목!$C4)) -> 20000 | E31: =IF($A31="","",IF(정비항목!$D4="",0,정비항목!$D4)) -> 12 | F31: =IF($A31="","",IF(COUNTIFS(정비이력!$B$3:$B$1002,$A31,정비이력!$D$3:$D$1002,정비항목!$A4)=0,"",SUMPRODUCT(MAX((정비이력!$B$3:$B$1002=$A31)*(정비이력!$D$3:$D$1002=정비항목!$A4)*정비이력!$A$3:$A$1002)))) | G31: =IF($A31="","",IF($F31="","",SUMPRODUCT(MAX((정비이력!$B$3:$B$1002=$A31)*(정비이력!$D$3:$D$1002=정비항목!$A4)*정비이력!$F$3:$F$1002)))) | H31: =IF($A31="","",IF(차량목록!$E5="",0,차량목록!$E5)) -> 125000 | I31: =IF(OR($A31="",$D31=0),"",IF($G31="",$H31+$D31,$G31+$D31)) -> 145000 | J31: =IF($I31="","",$I31-$H31) -> 20000 | K31: =IF(OR($A31="",$E31=0),"",IF($F31="",EDATE(TODAY(),$E31),EDATE($F31,$E31))) -> 46644 | L31: =IF($K31="","",$K31-TODAY()) -> 365 | M31: =IF($A31="","",IF(AND($J31="",$L31=""),"-",IF(OR(AND($J31<>"",$J31<=0),AND($L31<>"",$L31<0)),"교체",IF(OR(AND($J31<>"",$J31<=사용안내!$C$16),AND($L31<>"",$L31<=사용안내!$C$17)),"임박","정상")))) -> 정상
A32: =IF(OR(차량목록!$A5="",정비항목!$A5="",차량목록!$G5="매각"),"",차량목록!$A5) -> 56다7890 | B32: =IF($A32="","",차량목록!$B5) -> 스타렉스 | C32: =IF($A32="","",정비항목!$B5) -> 타이어 | D32: =IF($A32="","",IF(정비항목!$C5="",0,정비항목!$C5)) -> 50000 | E32: =IF($A32="","",IF(정비항목!$D5="",0,정비항목!$D5)) -> 36 | F32: =IF($A32="","",IF(COUNTIFS(정비이력!$B$3:$B$1002,$A32,정비이력!$D$3:$D$1002,정비항목!$A5)=0,"",SUMPRODUCT(MAX((정비이력!$B$3:$B$1002=$A32)*(정비이력!$D$3:$D$1002=정비항목!$A5)*정비이력!$A$3:$A$1002)))) -> 45536 | G32: =IF($A32="","",IF($F32="","",SUMPRODUCT(MAX((정비이력!$B$3:$B$1002=$A32)*(정비이력!$D$3:$D$1002=정비항목!$A5)*정비이력!$F$3:$F$1002)))) -> 95000 | H32: =IF($A32="","",IF(차량목록!$E5="",0,차량목록!$E5)) -> 125000 | I32: =IF(OR($A32="",$D32=0),"",IF($G32="",$H32+$D32,$G32+$D32)) -> 145000 | J32: =IF($I32="","",$I32-$H32) -> 20000 | K32: =IF(OR($A32="",$E32=0),"",IF($F32="",EDATE(TODAY(),$E32),EDATE($F32,$E32))) -> 46631 | L32: =IF($K32="","",$K32-TODAY()) -> 352 | M32: =IF($A32="","",IF(AND($J32="",$L32=""),"-",IF(OR(AND($J32<>"",$J32<=0),AND($L32<>"",$L32<0)),"교체",IF(OR(AND($J32<>"",$J32<=사용안내!$C$16),AND($L32<>"",$L32<=사용안내!$C$17)),"임박","정상")))) -> 정상
A33: =IF(OR(차량목록!$A5="",정비항목!$A6="",차량목록!$G5="매각"),"",차량목록!$A5) -> 56다7890 | B33: =IF($A33="","",차량목록!$B5) -> 스타렉스 | C33: =IF($A33="","",정비항목!$B6) -> 브레이크 패드 | D33: =IF($A33="","",IF(정비항목!$C6="",0,정비항목!$C6)) -> 40000 | E33: =IF($A33="","",IF(정비항목!$D6="",0,정비항목!$D6)) -> 24 | F33: =IF($A33="","",IF(COUNTIFS(정비이력!$B$3:$B$1002,$A33,정비이력!$D$3:$D$1002,정비항목!$A6)=0,"",SUMPRODUCT(MAX((정비이력!$B$3:$B$1002=$A33)*(정비이력!$D$3:$D$1002=정비항목!$A6)*정비이력!$A$3:$A$1002)))) | G33: =IF($A33="","",IF($F33="","",SUMPRODUCT(MAX((정비이력!$B$3:$B$1002=$A33)*(정비이력!$D$3:$D$1002=정비항목!$A6)*정비이력!$F$3:$F$1002)))) | H33: =IF($A33="","",IF(차량목록!$E5="",0,차량목록!$E5)) -> 125000 | I33: =IF(OR($A33="",$D33=0),"",IF($G33="",$H33+$D33,$G33+$D33)) -> 165000 | J33: =IF($I33="","",$I33-$H33) -> 40000 | K33: =IF(OR($A33="",$E33=0),"",IF($F33="",EDATE(TODAY(),$E33),EDATE($F33,$E33))) -> 47010 | L33: =IF($K33="","",$K33-TODAY()) -> 731 | M33: =IF($A33="","",IF(AND($J33="",$L33=""),"-",IF(OR(AND($J33<>"",$J33<=0),AND($L33<>"",$L33<0)),"교체",IF(OR(AND($J33<>"",$J33<=사용안내!$C$16),AND($L33<>"",$L33<=사용안내!$C$17)),"임박","정상")))) -> 정상
A34: =IF(OR(차량목록!$A5="",정비항목!$A7="",차량목록!$G5="매각"),"",차량목록!$A5) -> 56다7890 | B34: =IF($A34="","",차량목록!$B5) -> 스타렉스 | C34: =IF($A34="","",정비항목!$B7) -> 정기검사 | D34: =IF($A34="","",IF(정비항목!$C7="",0,정비항목!$C7)) -> 0 | E34: =IF($A34="","",IF(정비항목!$D7="",0,정비항목!$D7)) -> 12 | F34: =IF($A34="","",IF(COUNTIFS(정비이력!$B$3:$B$1002,$A34,정비이력!$D$3:$D$1002,정비항목!$A7)=0,"",SUMPRODUCT(MAX((정비이력!$B$3:$B$1002=$A34)*(정비이력!$D$3:$D$1002=정비항목!$A7)*정비이력!$A$3:$A$1002)))) | G34: =IF($A34="","",IF($F34="","",SUMPRODUCT(MAX((정비이력!$B$3:$B$1002=$A34)*(정비이력!$D$3:$D$1002=정비항목!$A7)*정비이력!$F$3:$F$1002)))) | H34: =IF($A34="","",IF(차량목록!$E5="",0,차량목록!$E5)) -> 125000 | I34: =IF(OR($A34="",$D34=0),"",IF($G34="",$H34+$D34,$G34+$D34)) | J34: =IF($I34="","",$I34-$H34) | K34: =IF(OR($A34="",$E34=0),"",IF($F34="",EDATE(TODAY(),$E34),EDATE($F34,$E34))) -> 46644 | L34: =IF($K34="","",$K34-TODAY()) -> 365 | M34: =IF($A34="","",IF(AND($J34="",$L34=""),"-",IF(OR(AND($J34<>"",$J34<=0),AND($L34<>"",$L34<0)),"교체",IF(OR(AND($J34<>"",$J34<=사용안내!$C$16),AND($L34<>"",$L34<=사용안내!$C$17)),"임박","정상")))) -> 정상
A35: =IF(OR(차량목록!$A5="",정비항목!$A8="",차량목록!$G5="매각"),"",차량목록!$A5) | B35: =IF($A35="","",차량목록!$B5) | C35: =IF($A35="","",정비항목!$B8) | D35: =IF($A35="","",IF(정비항목!$C8="",0,정비항목!$C8)) | E35: =IF($A35="","",IF(정비항목!$D8="",0,정비항목!$D8)) | F35: =IF($A35="","",IF(COUNTIFS(정비이력!$B$3:$B$1002,$A35,정비이력!$D$3:$D$1002,정비항목!$A8)=0,"",SUMPRODUCT(MAX((정비이력!$B$3:$B$1002=$A35)*(정비이력!$D$3:$D$1002=정비항목!$A8)*정비이력!$A$3:$A$1002)))) | G35: =IF($A35="","",IF($F35="","",SUMPRODUCT(MAX((정비이력!$B$3:$B$1002=$A35)*(정비이력!$D$3:$D$1002=정비항목!$A8)*정비이력!$F$3:$F$1002)))) | H35: =IF($A35="","",IF(차량목록!$E5="",0,차량목록!$E5)) | I35: =IF(OR($A35="",$D35=0),"",IF($G35="",$H35+$D35,$G35+$D35)) | J35: =IF($I35="","",$I35-$H35) | K35: =IF(OR($A35="",$E35=0),"",IF($F35="",EDATE(TODAY(),$E35),EDATE($F35,$E35))) | L35: =IF($K35="","",$K35-TODAY()) | M35: =IF($A35="","",IF(AND($J35="",$L35=""),"-",IF(OR(AND($J35<>"",$J35<=0),AND($L35<>"",$L35<0)),"교체",IF(OR(AND($J35<>"",$J35<=사용안내!$C$16),AND($L35<>"",$L35<=사용안내!$C$17)),"임박","정상"))))
A36: =IF(OR(차량목록!$A5="",정비항목!$A9="",차량목록!$G5="매각"),"",차량목록!$A5) | B36: =IF($A36="","",차량목록!$B5) | C36: =IF($A36="","",정비항목!$B9) | D36: =IF($A36="","",IF(정비항목!$C9="",0,정비항목!$C9)) | E36: =IF($A36="","",IF(정비항목!$D9="",0,정비항목!$D9)) | F36: =IF($A36="","",IF(COUNTIFS(정비이력!$B$3:$B$1002,$A36,정비이력!$D$3:$D$1002,정비항목!$A9)=0,"",SUMPRODUCT(MAX((정비이력!$B$3:$B$1002=$A36)*(정비이력!$D$3:$D$1002=정비항목!$A9)*정비이력!$A$3:$A$1002)))) | G36: =IF($A36="","",IF($F36="","",SUMPRODUCT(MAX((정비이력!$B$3:$B$1002=$A36)*(정비이력!$D$3:$D$1002=정비항목!$A9)*정비이력!$F$3:$F$1002)))) | H36: =IF($A36="","",IF(차량목록!$E5="",0,차량목록!$E5)) | I36: =IF(OR($A36="",$D36=0),"",IF($G36="",$H36+$D36,$G36+$D36)) | J36: =IF($I36="","",$I36-$H36) | K36: =IF(OR($A36="",$E36=0),"",IF($F36="",EDATE(TODAY(),$E36),EDATE($F36,$E36))) | L36: =IF($K36="","",$K36-TODAY()) | M36: =IF($A36="","",IF(AND($J36="",$L36=""),"-",IF(OR(AND($J36<>"",$J36<=0),AND($L36<>"",$L36<0)),"교체",IF(OR(AND($J36<>"",$J36<=사용안내!$C$16),AND($L36<>"",$L36<=사용안내!$C$17)),"임박","정상"))))
A37: =IF(OR(차량목록!$A5="",정비항목!$A10="",차량목록!$G5="매각"),"",차량목록!$A5) | B37: =IF($A37="","",차량목록!$B5) | C37: =IF($A37="","",정비항목!$B10) | D37: =IF($A37="","",IF(정비항목!$C10="",0,정비항목!$C10)) | E37: =IF($A37="","",IF(정비항목!$D10="",0,정비항목!$D10)) | F37: =IF($A37="","",IF(COUNTIFS(정비이력!$B$3:$B$1002,$A37,정비이력!$D$3:$D$1002,정비항목!$A10)=0,"",SUMPRODUCT(MAX((정비이력!$B$3:$B$1002=$A37)*(정비이력!$D$3:$D$1002=정비항목!$A10)*정비이력!$A$3:$A$1002)))) | G37: =IF($A37="","",IF($F37="","",SUMPRODUCT(MAX((정비이력!$B$3:$B$1002=$A37)*(정비이력!$D$3:$D$1002=정비항목!$A10)*정비이력!$F$3:$F$1002)))) | H37: =IF($A37="","",IF(차량목록!$E5="",0,차량목록!$E5)) | I37: =IF(OR($A37="",$D37=0),"",IF($G37="",$H37+$D37,$G37+$D37)) | J37: =IF($I37="","",$I37-$H37) | K37: =IF(OR($A37="",$E37=0),"",IF($F37="",EDATE(TODAY(),$E37),EDATE($F37,$E37))) | L37: =IF($K37="","",$K37-TODAY()) | M37: =IF($A37="","",IF(AND($J37="",$L37=""),"-",IF(OR(AND($J37<>"",$J37<=0),AND($L37<>"",$L37<0)),"교체",IF(OR(AND($J37<>"",$J37<=사용안내!$C$16),AND($L37<>"",$L37<=사용안내!$C$17)),"임박","정상"))))
A38: =IF(OR(차량목록!$A5="",정비항목!$A11="",차량목록!$G5="매각"),"",차량목록!$A5) | B38: =IF($A38="","",차량목록!$B5) | C38: =IF($A38="","",정비항목!$B11) | D38: =IF($A38="","",IF(정비항목!$C11="",0,정비항목!$C11)) | E38: =IF($A38="","",IF(정비항목!$D11="",0,정비항목!$D11)) | F38: =IF($A38="","",IF(COUNTIFS(정비이력!$B$3:$B$1002,$A38,정비이력!$D$3:$D$1002,정비항목!$A11)=0,"",SUMPRODUCT(MAX((정비이력!$B$3:$B$1002=$A38)*(정비이력!$D$3:$D$1002=정비항목!$A11)*정비이력!$A$3:$A$1002)))) | G38: =IF($A38="","",IF($F38="","",SUMPRODUCT(MAX((정비이력!$B$3:$B$1002=$A38)*(정비이력!$D$3:$D$1002=정비항목!$A11)*정비이력!$F$3:$F$1002)))) | H38: =IF($A38="","",IF(차량목록!$E5="",0,차량목록!$E5)) | I38: =IF(OR($A38="",$D38=0),"",IF($G38="",$H38+$D38,$G38+$D38)) | J38: =IF($I38="","",$I38-$H38) | K38: =IF(OR($A38="",$E38=0),"",IF($F38="",EDATE(TODAY(),$E38),EDATE($F38,$E38))) | L38: =IF($K38="","",$K38-TODAY()) | M38: =IF($A38="","",IF(AND($J38="",$L38=""),"-",IF(OR(AND($J38<>"",$J38<=0),AND($L38<>"",$L38<0)),"교체",IF(OR(AND($J38<>"",$J38<=사용안내!$C$16),AND($L38<>"",$L38<=사용안내!$C$17)),"임박","정상"))))
A39: =IF(OR(차량목록!$A5="",정비항목!$A12="",차량목록!$G5="매각"),"",차량목록!$A5) | B39: =IF($A39="","",차량목록!$B5) | C39: =IF($A39="","",정비항목!$B12) | D39: =IF($A39="","",IF(정비항목!$C12="",0,정비항목!$C12)) | E39: =IF($A39="","",IF(정비항목!$D12="",0,정비항목!$D12)) | F39: =IF($A39="","",IF(COUNTIFS(정비이력!$B$3:$B$1002,$A39,정비이력!$D$3:$D$1002,정비항목!$A12)=0,"",SUMPRODUCT(MAX((정비이력!$B$3:$B$1002=$A39)*(정비이력!$D$3:$D$1002=정비항목!$A12)*정비이력!$A$3:$A$1002)))) | G39: =IF($A39="","",IF($F39="","",SUMPRODUCT(MAX((정비이력!$B$3:$B$1002=$A39)*(정비이력!$D$3:$D$1002=정비항목!$A12)*정비이력!$F$3:$F$1002)))) | H39: =IF($A39="","",IF(차량목록!$E5="",0,차량목록!$E5)) | I39: =IF(OR($A39="",$D39=0),"",IF($G39="",$H39+$D39,$G39+$D39)) | J39: =IF($I39="","",$I39-$H39) | K39: =IF(OR($A39="",$E39=0),"",IF($F39="",EDATE(TODAY(),$E39),EDATE($F39,$E39))) | L39: =IF($K39="","",$K39-TODAY()) | M39: =IF($A39="","",IF(AND($J39="",$L39=""),"-",IF(OR(AND($J39<>"",$J39<=0),AND($L39<>"",$L39<0)),"교체",IF(OR(AND($J39<>"",$J39<=사용안내!$C$16),AND($L39<>"",$L39<=사용안내!$C$17)),"임박","정상"))))
A40: =IF(OR(차량목록!$A5="",정비항목!$A13="",차량목록!$G5="매각"),"",차량목록!$A5) | B40: =IF($A40="","",차량목록!$B5) | C40: =IF($A40="","",정비항목!$B13) | D40: =IF($A40="","",IF(정비항목!$C13="",0,정비항목!$C13)) | E40: =IF($A40="","",IF(정비항목!$D13="",0,정비항목!$D13)) | F40: =IF($A40="","",IF(COUNTIFS(정비이력!$B$3:$B$1002,$A40,정비이력!$D$3:$D$1002,정비항목!$A13)=0,"",SUMPRODUCT(MAX((정비이력!$B$3:$B$1002=$A40)*(정비이력!$D$3:$D$1002=정비항목!$A13)*정비이력!$A$3:$A$1002)))) | G40: =IF($A40="","",IF($F40="","",SUMPRODUCT(MAX((정비이력!$B$3:$B$1002=$A40)*(정비이력!$D$3:$D$1002=정비항목!$A13)*정비이력!$F$3:$F$1002)))) | H40: =IF($A40="","",IF(차량목록!$E5="",0,차량목록!$E5)) | I40: =IF(OR($A40="",$D40=0),"",IF($G40="",$H40+$D40,$G40+$D40)) | J40: =IF($I40="","",$I40-$H40) | K40: =IF(OR($A40="",$E40=0),"",IF($F40="",EDATE(TODAY(),$E40),EDATE($F40,$E40))) | L40: =IF($K40="","",$K40-TODAY()) | M40: =IF($A40="","",IF(AND($J40="",$L40=""),"-",IF(OR(AND($J40<>"",$J40<=0),AND($L40<>"",$L40<0)),"교체",IF(OR(AND($J40<>"",$J40<=사용안내!$C$16),AND($L40<>"",$L40<=사용안내!$C$17)),"임박","정상"))))
A41: =IF(OR(차량목록!$A5="",정비항목!$A14="",차량목록!$G5="매각"),"",차량목록!$A5) | B41: =IF($A41="","",차량목록!$B5) | C41: =IF($A41="","",정비항목!$B14) | D41: =IF($A41="","",IF(정비항목!$C14="",0,정비항목!$C14)) | E41: =IF($A41="","",IF(정비항목!$D14="",0,정비항목!$D14)) | F41: =IF($A41="","",IF(COUNTIFS(정비이력!$B$3:$B$1002,$A41,정비이력!$D$3:$D$1002,정비항목!$A14)=0,"",SUMPRODUCT(MAX((정비이력!$B$3:$B$1002=$A41)*(정비이력!$D$3:$D$1002=정비항목!$A14)*정비이력!$A$3:$A$1002)))) | G41: =IF($A41="","",IF($F41="","",SUMPRODUCT(MAX((정비이력!$B$3:$B$1002=$A41)*(정비이력!$D$3:$D$1002=정비항목!$A14)*정비이력!$F$3:$F$1002)))) | H41: =IF($A41="","",IF(차량목록!$E5="",0,차량목록!$E5)) | I41: =IF(OR($A41="",$D41=0),"",IF($G41="",$H41+$D41,$G41+$D41)) | J41: =IF($I41="","",$I41-$H41) | K41: =IF(OR($A41="",$E41=0),"",IF($F41="",EDATE(TODAY(),$E41),EDATE($F41,$E41))) | L41: =IF($K41="","",$K41-TODAY()) | M41: =IF($A41="","",IF(AND($J41="",$L41=""),"-",IF(OR(AND($J41<>"",$J41<=0),AND($L41<>"",$L41<0)),"교체",IF(OR(AND($J41<>"",$J41<=사용안내!$C$16),AND($L41<>"",$L41<=사용안내!$C$17)),"임박","정상"))))
A42: =IF(OR(차량목록!$A6="",정비항목!$A3="",차량목록!$G6="매각"),"",차량목록!$A6) | B42: =IF($A42="","",차량목록!$B6) | C42: =IF($A42="","",정비항목!$B3) | D42: =IF($A42="","",IF(정비항목!$C3="",0,정비항목!$C3)) | E42: =IF($A42="","",IF(정비항목!$D3="",0,정비항목!$D3)) | F42: =IF($A42="","",IF(COUNTIFS(정비이력!$B$3:$B$1002,$A42,정비이력!$D$3:$D$1002,정비항목!$A3)=0,"",SUMPRODUCT(MAX((정비이력!$B$3:$B$1002=$A42)*(정비이력!$D$3:$D$1002=정비항목!$A3)*정비이력!$A$3:$A$1002)))) | G42: =IF($A42="","",IF($F42="","",SUMPRODUCT(MAX((정비이력!$B$3:$B$1002=$A42)*(정비이력!$D$3:$D$1002=정비항목!$A3)*정비이력!$F$3:$F$1002)))) | H42: =IF($A42="","",IF(차량목록!$E6="",0,차량목록!$E6)) | I42: =IF(OR($A42="",$D42=0),"",IF($G42="",$H42+$D42,$G42+$D42)) | J42: =IF($I42="","",$I42-$H42) | K42: =IF(OR($A42="",$E42=0),"",IF($F42="",EDATE(TODAY(),$E42),EDATE($F42,$E42))) | L42: =IF($K42="","",$K42-TODAY()) | M42: =IF($A42="","",IF(AND($J42="",$L42=""),"-",IF(OR(AND($J42<>"",$J42<=0),AND($L42<>"",$L42<0)),"교체",IF(OR(AND($J42<>"",$J42<=사용안내!$C$16),AND($L42<>"",$L42<=사용안내!$C$17)),"임박","정상"))))
...

Sheet 교체대상
A1: 교체대상 (지금 해야 하는 것)
A3: 해당 건수 | B3: =COUNTIF($J$6:$J$365,TRUE()) -> 1
A5: 순번 | B5: 차량번호 | C5: 차종 | D5: 항목 | E5: 남은 km | F5: 다음 교체일 | G5: D-Day | H5: 상태
A6: =IF($B6="","",1) -> 1 | B6: =IFERROR(INDEX(정비현황!$A$6:$A$365,MATCH("R"&1,교체대상!$L$6:$L$365,0)),"") -> 12가3456 | C6: =IF($B6="","",IFERROR(INDEX(정비현황!$B$6:$B$365,MATCH("R"&1,교체대상!$L$6:$L$365,0)),"")) -> 포터2 | D6: =IF($B6="","",IFERROR(INDEX(정비현황!$C$6:$C$365,MATCH("R"&1,교체대상!$L$6:$L$365,0)),"")) -> 엔진오일 | E6: =IF($B6="","",IFERROR(INDEX(정비현황!$J$6:$J$365,MATCH("R"&1,교체대상!$L$6:$L$365,0)),"")) -> 200 | F6: =IF($B6="","",IFERROR(INDEX(정비현황!$K$6:$K$365,MATCH("R"&1,교체대상!$L$6:$L$365,0)),"")) -> 46366 | G6: =IF($B6="","",IFERROR(INDEX(정비현황!$L$6:$L$365,MATCH("R"&1,교체대상!$L$6:$L$365,0)),"")) -> 87 | H6: =IF($B6="","",IFERROR(INDEX(정비현황!$M$6:$M$365,MATCH("R"&1,교체대상!$L$6:$L$365,0)),"")) -> 임박 | J6: =IF(정비현황!$A6="",FALSE(),OR(정비현황!$M6="교체",정비현황!$M6="임박")) -> TRUE | K6: =IF($J6=FALSE(),"",COUNTIF($J$6:$J6,TRUE())) -> 1 | L6: =IF($K6="","","R"&$K6) -> R1
A7: =IF($B7="","",2) | B7: =IFERROR(INDEX(정비현황!$A$6:$A$365,MATCH("R"&2,교체대상!$L$6:$L$365,0)),"") | C7: =IF($B7="","",IFERROR(INDEX(정비현황!$B$6:$B$365,MATCH("R"&2,교체대상!$L$6:$L$365,0)),"")) | D7: =IF($B7="","",IFERROR(INDEX(정비현황!$C$6:$C$365,MATCH("R"&2,교체대상!$L$6:$L$365,0)),"")) | E7: =IF($B7="","",IFERROR(INDEX(정비현황!$J$6:$J$365,MATCH("R"&2,교체대상!$L$6:$L$365,0)),"")) | F7: =IF($B7="","",IFERROR(INDEX(정비현황!$K$6:$K$365,MATCH("R"&2,교체대상!$L$6:$L$365,0)),"")) | G7: =IF($B7="","",IFERROR(INDEX(정비현황!$L$6:$L$365,MATCH("R"&2,교체대상!$L$6:$L$365,0)),"")) | H7: =IF($B7="","",IFERROR(INDEX(정비현황!$M$6:$M$365,MATCH("R"&2,교체대상!$L$6:$L$365,0)),"")) | J7: =IF(정비현황!$A7="",FALSE(),OR(정비현황!$M7="교체",정비현황!$M7="임박")) -> FALSE | K7: =IF($J7=FALSE(),"",COUNTIF($J$6:$J7,TRUE())) | L7: =IF($K7="","","R"&$K7)
A8: =IF($B8="","",3) | B8: =IFERROR(INDEX(정비현황!$A$6:$A$365,MATCH("R"&3,교체대상!$L$6:$L$365,0)),"") | C8: =IF($B8="","",IFERROR(INDEX(정비현황!$B$6:$B$365,MATCH("R"&3,교체대상!$L$6:$L$365,0)),"")) | D8: =IF($B8="","",IFERROR(INDEX(정비현황!$C$6:$C$365,MATCH("R"&3,교체대상!$L$6:$L$365,0)),"")) | E8: =IF($B8="","",IFERROR(INDEX(정비현황!$J$6:$J$365,MATCH("R"&3,교체대상!$L$6:$L$365,0)),"")) | F8: =IF($B8="","",IFERROR(INDEX(정비현황!$K$6:$K$365,MATCH("R"&3,교체대상!$L$6:$L$365,0)),"")) | G8: =IF($B8="","",IFERROR(INDEX(정비현황!$L$6:$L$365,MATCH("R"&3,교체대상!$L$6:$L$365,0)),"")) | H8: =IF($B8="","",IFERROR(INDEX(정비현황!$M$6:$M$365,MATCH("R"&3,교체대상!$L$6:$L$365,0)),"")) | J8: =IF(정비현황!$A8="",FALSE(),OR(정비현황!$M8="교체",정비현황!$M8="임박")) -> FALSE | K8: =IF($J8=FALSE(),"",COUNTIF($J$6:$J8,TRUE())) | L8: =IF($K8="","","R"&$K8)
A9: =IF($B9="","",4) | B9: =IFERROR(INDEX(정비현황!$A$6:$A$365,MATCH("R"&4,교체대상!$L$6:$L$365,0)),"") | C9: =IF($B9="","",IFERROR(INDEX(정비현황!$B$6:$B$365,MATCH("R"&4,교체대상!$L$6:$L$365,0)),"")) | D9: =IF($B9="","",IFERROR(INDEX(정비현황!$C$6:$C$365,MATCH("R"&4,교체대상!$L$6:$L$365,0)),"")) | E9: =IF($B9="","",IFERROR(INDEX(정비현황!$J$6:$J$365,MATCH("R"&4,교체대상!$L$6:$L$365,0)),"")) | F9: =IF($B9="","",IFERROR(INDEX(정비현황!$K$6:$K$365,MATCH("R"&4,교체대상!$L$6:$L$365,0)),"")) | G9: =IF($B9="","",IFERROR(INDEX(정비현황!$L$6:$L$365,MATCH("R"&4,교체대상!$L$6:$L$365,0)),"")) | H9: =IF($B9="","",IFERROR(INDEX(정비현황!$M$6:$M$365,MATCH("R"&4,교체대상!$L$6:$L$365,0)),"")) | J9: =IF(정비현황!$A9="",FALSE(),OR(정비현황!$M9="교체",정비현황!$M9="임박")) -> FALSE | K9: =IF($J9=FALSE(),"",COUNTIF($J$6:$J9,TRUE())) | L9: =IF($K9="","","R"&$K9)
A10: =IF($B10="","",5) | B10: =IFERROR(INDEX(정비현황!$A$6:$A$365,MATCH("R"&5,교체대상!$L$6:$L$365,0)),"") | C10: =IF($B10="","",IFERROR(INDEX(정비현황!$B$6:$B$365,MATCH("R"&5,교체대상!$L$6:$L$365,0)),"")) | D10: =IF($B10="","",IFERROR(INDEX(정비현황!$C$6:$C$365,MATCH("R"&5,교체대상!$L$6:$L$365,0)),"")) | E10: =IF($B10="","",IFERROR(INDEX(정비현황!$J$6:$J$365,MATCH("R"&5,교체대상!$L$6:$L$365,0)),"")) | F10: =IF($B10="","",IFERROR(INDEX(정비현황!$K$6:$K$365,MATCH("R"&5,교체대상!$L$6:$L$365,0)),"")) | G10: =IF($B10="","",IFERROR(INDEX(정비현황!$L$6:$L$365,MATCH("R"&5,교체대상!$L$6:$L$365,0)),"")) | H10: =IF($B10="","",IFERROR(INDEX(정비현황!$M$6:$M$365,MATCH("R"&5,교체대상!$L$6:$L$365,0)),"")) | J10: =IF(정비현황!$A10="",FALSE(),OR(정비현황!$M10="교체",정비현황!$M10="임박")) -> FALSE | K10: =IF($J10=FALSE(),"",COUNTIF($J$6:$J10,TRUE())) | L10: =IF($K10="","","R"&$K10)
A11: =IF($B11="","",6) | B11: =IFERROR(INDEX(정비현황!$A$6:$A$365,MATCH("R"&6,교체대상!$L$6:$L$365,0)),"") | C11: =IF($B11="","",IFERROR(INDEX(정비현황!$B$6:$B$365,MATCH("R"&6,교체대상!$L$6:$L$365,0)),"")) | D11: =IF($B11="","",IFERROR(INDEX(정비현황!$C$6:$C$365,MATCH("R"&6,교체대상!$L$6:$L$365,0)),"")) | E11: =IF($B11="","",IFERROR(INDEX(정비현황!$J$6:$J$365,MATCH("R"&6,교체대상!$L$6:$L$365,0)),"")) | F11: =IF($B11="","",IFERROR(INDEX(정비현황!$K$6:$K$365,MATCH("R"&6,교체대상!$L$6:$L$365,0)),"")) | G11: =IF($B11="","",IFERROR(INDEX(정비현황!$L$6:$L$365,MATCH("R"&6,교체대상!$L$6:$L$365,0)),"")) | H11: =IF($B11="","",IFERROR(INDEX(정비현황!$M$6:$M$365,MATCH("R"&6,교체대상!$L$6:$L$365,0)),"")) | J11: =IF(정비현황!$A11="",FALSE(),OR(정비현황!$M11="교체",정비현황!$M11="임박")) -> FALSE | K11: =IF($J11=FALSE(),"",COUNTIF($J$6:$J11,TRUE())) | L11: =IF($K11="","","R"&$K11)
A12: =IF($B12="","",7) | B12: =IFERROR(INDEX(정비현황!$A$6:$A$365,MATCH("R"&7,교체대상!$L$6:$L$365,0)),"") | C12: =IF($B12="","",IFERROR(INDEX(정비현황!$B$6:$B$365,MATCH("R"&7,교체대상!$L$6:$L$365,0)),"")) | D12: =IF($B12="","",IFERROR(INDEX(정비현황!$C$6:$C$365,MATCH("R"&7,교체대상!$L$6:$L$365,0)),"")) | E12: =IF($B12="","",IFERROR(INDEX(정비현황!$J$6:$J$365,MATCH("R"&7,교체대상!$L$6:$L$365,0)),"")) | F12: =IF($B12="","",IFERROR(INDEX(정비현황!$K$6:$K$365,MATCH("R"&7,교체대상!$L$6:$L$365,0)),"")) | G12: =IF($B12="","",IFERROR(INDEX(정비현황!$L$6:$L$365,MATCH("R"&7,교체대상!$L$6:$L$365,0)),"")) | H12: =IF($B12="","",IFERROR(INDEX(정비현황!$M$6:$M$365,MATCH("R"&7,교체대상!$L$6:$L$365,0)),"")) | J12: =IF(정비현황!$A12="",FALSE(),OR(정비현황!$M12="교체",정비현황!$M12="임박")) -> FALSE | K12: =IF($J12=FALSE(),"",COUNTIF($J$6:$J12,TRUE())) | L12: =IF($K12="","","R"&$K12)
A13: =IF($B13="","",8) | B13: =IFERROR(INDEX(정비현황!$A$6:$A$365,MATCH("R"&8,교체대상!$L$6:$L$365,0)),"") | C13: =IF($B13="","",IFERROR(INDEX(정비현황!$B$6:$B$365,MATCH("R"&8,교체대상!$L$6:$L$365,0)),"")) | D13: =IF($B13="","",IFERROR(INDEX(정비현황!$C$6:$C$365,MATCH("R"&8,교체대상!$L$6:$L$365,0)),"")) | E13: =IF($B13="","",IFERROR(INDEX(정비현황!$J$6:$J$365,MATCH("R"&8,교체대상!$L$6:$L$365,0)),"")) | F13: =IF($B13="","",IFERROR(INDEX(정비현황!$K$6:$K$365,MATCH("R"&8,교체대상!$L$6:$L$365,0)),"")) | G13: =IF($B13="","",IFERROR(INDEX(정비현황!$L$6:$L$365,MATCH("R"&8,교체대상!$L$6:$L$365,0)),"")) | H13: =IF($B13="","",IFERROR(INDEX(정비현황!$M$6:$M$365,MATCH("R"&8,교체대상!$L$6:$L$365,0)),"")) | J13: =IF(정비현황!$A13="",FALSE(),OR(정비현황!$M13="교체",정비현황!$M13="임박")) -> FALSE | K13: =IF($J13=FALSE(),"",COUNTIF($J$6:$J13,TRUE())) | L13: =IF($K13="","","R"&$K13)
A14: =IF($B14="","",9) | B14: =IFERROR(INDEX(정비현황!$A$6:$A$365,MATCH("R"&9,교체대상!$L$6:$L$365,0)),"") | C14: =IF($B14="","",IFERROR(INDEX(정비현황!$B$6:$B$365,MATCH("R"&9,교체대상!$L$6:$L$365,0)),"")) | D14: =IF($B14="","",IFERROR(INDEX(정비현황!$C$6:$C$365,MATCH("R"&9,교체대상!$L$6:$L$365,0)),"")) | E14: =IF($B14="","",IFERROR(INDEX(정비현황!$J$6:$J$365,MATCH("R"&9,교체대상!$L$6:$L$365,0)),"")) | F14: =IF($B14="","",IFERROR(INDEX(정비현황!$K$6:$K$365,MATCH("R"&9,교체대상!$L$6:$L$365,0)),"")) | G14: =IF($B14="","",IFERROR(INDEX(정비현황!$L$6:$L$365,MATCH("R"&9,교체대상!$L$6:$L$365,0)),"")) | H14: =IF($B14="","",IFERROR(INDEX(정비현황!$M$6:$M$365,MATCH("R"&9,교체대상!$L$6:$L$365,0)),"")) | J14: =IF(정비현황!$A14="",FALSE(),OR(정비현황!$M14="교체",정비현황!$M14="임박")) -> FALSE | K14: =IF($J14=FALSE(),"",COUNTIF($J$6:$J14,TRUE())) | L14: =IF($K14="","","R"&$K14)
A15: =IF($B15="","",10) | B15: =IFERROR(INDEX(정비현황!$A$6:$A$365,MATCH("R"&10,교체대상!$L$6:$L$365,0)),"") | C15: =IF($B15="","",IFERROR(INDEX(정비현황!$B$6:$B$365,MATCH("R"&10,교체대상!$L$6:$L$365,0)),"")) | D15: =IF($B15="","",IFERROR(INDEX(정비현황!$C$6:$C$365,MATCH("R"&10,교체대상!$L$6:$L$365,0)),"")) | E15: =IF($B15="","",IFERROR(INDEX(정비현황!$J$6:$J$365,MATCH("R"&10,교체대상!$L$6:$L$365,0)),"")) | F15: =IF($B15="","",IFERROR(INDEX(정비현황!$K$6:$K$365,MATCH("R"&10,교체대상!$L$6:$L$365,0)),"")) | G15: =IF($B15="","",IFERROR(INDEX(정비현황!$L$6:$L$365,MATCH("R"&10,교체대상!$L$6:$L$365,0)),"")) | H15: =IF($B15="","",IFERROR(INDEX(정비현황!$M$6:$M$365,MATCH("R"&10,교체대상!$L$6:$L$365,0)),"")) | J15: =IF(정비현황!$A15="",FALSE(),OR(정비현황!$M15="교체",정비현황!$M15="임박")) -> FALSE | K15: =IF($J15=FALSE(),"",COUNTIF($J$6:$J15,TRUE())) | L15: =IF($K15="","","R"&$K15)
A16: =IF($B16="","",11) | B16: =IFERROR(INDEX(정비현황!$A$6:$A$365,MATCH("R"&11,교체대상!$L$6:$L$365,0)),"") | C16: =IF($B16="","",IFERROR(INDEX(정비현황!$B$6:$B$365,MATCH("R"&11,교체대상!$L$6:$L$365,0)),"")) | D16: =IF($B16="","",IFERROR(INDEX(정비현황!$C$6:$C$365,MATCH("R"&11,교체대상!$L$6:$L$365,0)),"")) | E16: =IF($B16="","",IFERROR(INDEX(정비현황!$J$6:$J$365,MATCH("R"&11,교체대상!$L$6:$L$365,0)),"")) | F16: =IF($B16="","",IFERROR(INDEX(정비현황!$K$6:$K$365,MATCH("R"&11,교체대상!$L$6:$L$365,0)),"")) | G16: =IF($B16="","",IFERROR(INDEX(정비현황!$L$6:$L$365,MATCH("R"&11,교체대상!$L$6:$L$365,0)),"")) | H16: =IF($B16="","",IFERROR(INDEX(정비현황!$M$6:$M$365,MATCH("R"&11,교체대상!$L$6:$L$365,0)),"")) | J16: =IF(정비현황!$A16="",FALSE(),OR(정비현황!$M16="교체",정비현황!$M16="임박")) -> FALSE | K16: =IF($J16=FALSE(),"",COUNTIF($J$6:$J16,TRUE())) | L16: =IF($K16="","","R"&$K16)
A17: =IF($B17="","",12) | B17: =IFERROR(INDEX(정비현황!$A$6:$A$365,MATCH("R"&12,교체대상!$L$6:$L$365,0)),"") | C17: =IF($B17="","",IFERROR(INDEX(정비현황!$B$6:$B$365,MATCH("R"&12,교체대상!$L$6:$L$365,0)),"")) | D17: =IF($B17="","",IFERROR(INDEX(정비현황!$C$6:$C$365,MATCH("R"&12,교체대상!$L$6:$L$365,0)),"")) | E17: =IF($B17="","",IFERROR(INDEX(정비현황!$J$6:$J$365,MATCH("R"&12,교체대상!$L$6:$L$365,0)),"")) | F17: =IF($B17="","",IFERROR(INDEX(정비현황!$K$6:$K$365,MATCH("R"&12,교체대상!$L$6:$L$365,0)),"")) | G17: =IF($B17="","",IFERROR(INDEX(정비현황!$L$6:$L$365,MATCH("R"&12,교체대상!$L$6:$L$365,0)),"")) | H17: =IF($B17="","",IFERROR(INDEX(정비현황!$M$6:$M$365,MATCH("R"&12,교체대상!$L$6:$L$365,0)),"")) | J17: =IF(정비현황!$A17="",FALSE(),OR(정비현황!$M17="교체",정비현황!$M17="임박")) -> FALSE | K17: =IF($J17=FALSE(),"",COUNTIF($J$6:$J17,TRUE())) | L17: =IF($K17="","","R"&$K17)
A18: =IF($B18="","",13) | B18: =IFERROR(INDEX(정비현황!$A$6:$A$365,MATCH("R"&13,교체대상!$L$6:$L$365,0)),"") | C18: =IF($B18="","",IFERROR(INDEX(정비현황!$B$6:$B$365,MATCH("R"&13,교체대상!$L$6:$L$365,0)),"")) | D18: =IF($B18="","",IFERROR(INDEX(정비현황!$C$6:$C$365,MATCH("R"&13,교체대상!$L$6:$L$365,0)),"")) | E18: =IF($B18="","",IFERROR(INDEX(정비현황!$J$6:$J$365,MATCH("R"&13,교체대상!$L$6:$L$365,0)),"")) | F18: =IF($B18="","",IFERROR(INDEX(정비현황!$K$6:$K$365,MATCH("R"&13,교체대상!$L$6:$L$365,0)),"")) | G18: =IF($B18="","",IFERROR(INDEX(정비현황!$L$6:$L$365,MATCH("R"&13,교체대상!$L$6:$L$365,0)),"")) | H18: =IF($B18="","",IFERROR(INDEX(정비현황!$M$6:$M$365,MATCH("R"&13,교체대상!$L$6:$L$365,0)),"")) | J18: =IF(정비현황!$A18="",FALSE(),OR(정비현황!$M18="교체",정비현황!$M18="임박")) -> FALSE | K18: =IF($J18=FALSE(),"",COUNTIF($J$6:$J18,TRUE())) | L18: =IF($K18="","","R"&$K18)
A19: =IF($B19="","",14) | B19: =IFERROR(INDEX(정비현황!$A$6:$A$365,MATCH("R"&14,교체대상!$L$6:$L$365,0)),"") | C19: =IF($B19="","",IFERROR(INDEX(정비현황!$B$6:$B$365,MATCH("R"&14,교체대상!$L$6:$L$365,0)),"")) | D19: =IF($B19="","",IFERROR(INDEX(정비현황!$C$6:$C$365,MATCH("R"&14,교체대상!$L$6:$L$365,0)),"")) | E19: =IF($B19="","",IFERROR(INDEX(정비현황!$J$6:$J$365,MATCH("R"&14,교체대상!$L$6:$L$365,0)),"")) | F19: =IF($B19="","",IFERROR(INDEX(정비현황!$K$6:$K$365,MATCH("R"&14,교체대상!$L$6:$L$365,0)),"")) | G19: =IF($B19="","",IFERROR(INDEX(정비현황!$L$6:$L$365,MATCH("R"&14,교체대상!$L$6:$L$365,0)),"")) | H19: =IF($B19="","",IFERROR(INDEX(정비현황!$M$6:$M$365,MATCH("R"&14,교체대상!$L$6:$L$365,0)),"")) | J19: =IF(정비현황!$A19="",FALSE(),OR(정비현황!$M19="교체",정비현황!$M19="임박")) -> FALSE | K19: =IF($J19=FALSE(),"",COUNTIF($J$6:$J19,TRUE())) | L19: =IF($K19="","","R"&$K19)
A20: =IF($B20="","",15) | B20: =IFERROR(INDEX(정비현황!$A$6:$A$365,MATCH("R"&15,교체대상!$L$6:$L$365,0)),"") | C20: =IF($B20="","",IFERROR(INDEX(정비현황!$B$6:$B$365,MATCH("R"&15,교체대상!$L$6:$L$365,0)),"")) | D20: =IF($B20="","",IFERROR(INDEX(정비현황!$C$6:$C$365,MATCH("R"&15,교체대상!$L$6:$L$365,0)),"")) | E20: =IF($B20="","",IFERROR(INDEX(정비현황!$J$6:$J$365,MATCH("R"&15,교체대상!$L$6:$L$365,0)),"")) | F20: =IF($B20="","",IFERROR(INDEX(정비현황!$K$6:$K$365,MATCH("R"&15,교체대상!$L$6:$L$365,0)),"")) | G20: =IF($B20="","",IFERROR(INDEX(정비현황!$L$6:$L$365,MATCH("R"&15,교체대상!$L$6:$L$365,0)),"")) | H20: =IF($B20="","",IFERROR(INDEX(정비현황!$M$6:$M$365,MATCH("R"&15,교체대상!$L$6:$L$365,0)),"")) | J20: =IF(정비현황!$A20="",FALSE(),OR(정비현황!$M20="교체",정비현황!$M20="임박")) -> FALSE | K20: =IF($J20=FALSE(),"",COUNTIF($J$6:$J20,TRUE())) | L20: =IF($K20="","","R"&$K20)
A21: =IF($B21="","",16) | B21: =IFERROR(INDEX(정비현황!$A$6:$A$365,MATCH("R"&16,교체대상!$L$6:$L$365,0)),"") | C21: =IF($B21="","",IFERROR(INDEX(정비현황!$B$6:$B$365,MATCH("R"&16,교체대상!$L$6:$L$365,0)),"")) | D21: =IF($B21="","",IFERROR(INDEX(정비현황!$C$6:$C$365,MATCH("R"&16,교체대상!$L$6:$L$365,0)),"")) | E21: =IF($B21="","",IFERROR(INDEX(정비현황!$J$6:$J$365,MATCH("R"&16,교체대상!$L$6:$L$365,0)),"")) | F21: =IF($B21="","",IFERROR(INDEX(정비현황!$K$6:$K$365,MATCH("R"&16,교체대상!$L$6:$L$365,0)),"")) | G21: =IF($B21="","",IFERROR(INDEX(정비현황!$L$6:$L$365,MATCH("R"&16,교체대상!$L$6:$L$365,0)),"")) | H21: =IF($B21="","",IFERROR(INDEX(정비현황!$M$6:$M$365,MATCH("R"&16,교체대상!$L$6:$L$365,0)),"")) | J21: =IF(정비현황!$A21="",FALSE(),OR(정비현황!$M21="교체",정비현황!$M21="임박")) -> FALSE | K21: =IF($J21=FALSE(),"",COUNTIF($J$6:$J21,TRUE())) | L21: =IF($K21="","","R"&$K21)
A22: =IF($B22="","",17) | B22: =IFERROR(INDEX(정비현황!$A$6:$A$365,MATCH("R"&17,교체대상!$L$6:$L$365,0)),"") | C22: =IF($B22="","",IFERROR(INDEX(정비현황!$B$6:$B$365,MATCH("R"&17,교체대상!$L$6:$L$365,0)),"")) | D22: =IF($B22="","",IFERROR(INDEX(정비현황!$C$6:$C$365,MATCH("R"&17,교체대상!$L$6:$L$365,0)),"")) | E22: =IF($B22="","",IFERROR(INDEX(정비현황!$J$6:$J$365,MATCH("R"&17,교체대상!$L$6:$L$365,0)),"")) | F22: =IF($B22="","",IFERROR(INDEX(정비현황!$K$6:$K$365,MATCH("R"&17,교체대상!$L$6:$L$365,0)),"")) | G22: =IF($B22="","",IFERROR(INDEX(정비현황!$L$6:$L$365,MATCH("R"&17,교체대상!$L$6:$L$365,0)),"")) | H22: =IF($B22="","",IFERROR(INDEX(정비현황!$M$6:$M$365,MATCH("R"&17,교체대상!$L$6:$L$365,0)),"")) | J22: =IF(정비현황!$A22="",FALSE(),OR(정비현황!$M22="교체",정비현황!$M22="임박")) -> FALSE | K22: =IF($J22=FALSE(),"",COUNTIF($J$6:$J22,TRUE())) | L22: =IF($K22="","","R"&$K22)
A23: =IF($B23="","",18) | B23: =IFERROR(INDEX(정비현황!$A$6:$A$365,MATCH("R"&18,교체대상!$L$6:$L$365,0)),"") | C23: =IF($B23="","",IFERROR(INDEX(정비현황!$B$6:$B$365,MATCH("R"&18,교체대상!$L$6:$L$365,0)),"")) | D23: =IF($B23="","",IFERROR(INDEX(정비현황!$C$6:$C$365,MATCH("R"&18,교체대상!$L$6:$L$365,0)),"")) | E23: =IF($B23="","",IFERROR(INDEX(정비현황!$J$6:$J$365,MATCH("R"&18,교체대상!$L$6:$L$365,0)),"")) | F23: =IF($B23="","",IFERROR(INDEX(정비현황!$K$6:$K$365,MATCH("R"&18,교체대상!$L$6:$L$365,0)),"")) | G23: =IF($B23="","",IFERROR(INDEX(정비현황!$L$6:$L$365,MATCH("R"&18,교체대상!$L$6:$L$365,0)),"")) | H23: =IF($B23="","",IFERROR(INDEX(정비현황!$M$6:$M$365,MATCH("R"&18,교체대상!$L$6:$L$365,0)),"")) | J23: =IF(정비현황!$A23="",FALSE(),OR(정비현황!$M23="교체",정비현황!$M23="임박")) -> FALSE | K23: =IF($J23=FALSE(),"",COUNTIF($J$6:$J23,TRUE())) | L23: =IF($K23="","","R"&$K23)
A24: =IF($B24="","",19) | B24: =IFERROR(INDEX(정비현황!$A$6:$A$365,MATCH("R"&19,교체대상!$L$6:$L$365,0)),"") | C24: =IF($B24="","",IFERROR(INDEX(정비현황!$B$6:$B$365,MATCH("R"&19,교체대상!$L$6:$L$365,0)),"")) | D24: =IF($B24="","",IFERROR(INDEX(정비현황!$C$6:$C$365,MATCH("R"&19,교체대상!$L$6:$L$365,0)),"")) | E24: =IF($B24="","",IFERROR(INDEX(정비현황!$J$6:$J$365,MATCH("R"&19,교체대상!$L$6:$L$365,0)),"")) | F24: =IF($B24="","",IFERROR(INDEX(정비현황!$K$6:$K$365,MATCH("R"&19,교체대상!$L$6:$L$365,0)),"")) | G24: =IF($B24="","",IFERROR(INDEX(정비현황!$L$6:$L$365,MATCH("R"&19,교체대상!$L$6:$L$365,0)),"")) | H24: =IF($B24="","",IFERROR(INDEX(정비현황!$M$6:$M$365,MATCH("R"&19,교체대상!$L$6:$L$365,0)),"")) | J24: =IF(정비현황!$A24="",FALSE(),OR(정비현황!$M24="교체",정비현황!$M24="임박")) -> FALSE | K24: =IF($J24=FALSE(),"",COUNTIF($J$6:$J24,TRUE())) | L24: =IF($K24="","","R"&$K24)
A25: =IF($B25="","",20) | B25: =IFERROR(INDEX(정비현황!$A$6:$A$365,MATCH("R"&20,교체대상!$L$6:$L$365,0)),"") | C25: =IF($B25="","",IFERROR(INDEX(정비현황!$B$6:$B$365,MATCH("R"&20,교체대상!$L$6:$L$365,0)),"")) | D25: =IF($B25="","",IFERROR(INDEX(정비현황!$C$6:$C$365,MATCH("R"&20,교체대상!$L$6:$L$365,0)),"")) | E25: =IF($B25="","",IFERROR(INDEX(정비현황!$J$6:$J$365,MATCH("R"&20,교체대상!$L$6:$L$365,0)),"")) | F25: =IF($B25="","",IFERROR(INDEX(정비현황!$K$6:$K$365,MATCH("R"&20,교체대상!$L$6:$L$365,0)),"")) | G25: =IF($B25="","",IFERROR(INDEX(정비현황!$L$6:$L$365,MATCH("R"&20,교체대상!$L$6:$L$365,0)),"")) | H25: =IF($B25="","",IFERROR(INDEX(정비현황!$M$6:$M$365,MATCH("R"&20,교체대상!$L$6:$L$365,0)),"")) | J25: =IF(정비현황!$A25="",FALSE(),OR(정비현황!$M25="교체",정비현황!$M25="임박")) -> FALSE | K25: =IF($J25=FALSE(),"",COUNTIF($J$6:$J25,TRUE())) | L25: =IF($K25="","","R"&$K25)
