Workbook

Sheet 사용안내
B2: 발주서 세트 전개
B4: 핵심 | C4: 세트 상품으로 들어온 주문을 낱개 품목으로 자동으로 풀어줍니다. 손으로 다시 칠 필요가 없습니다.
B5: 입력 규칙 | C5: 파란색 글씨 칸만 입력하세요. 검은색은 자동 계산입니다.
B6: ① 품목목록 | C6: 낱개 품목을 등록합니다. 세트를 구성하는 최소 단위입니다.
B7: ② 세트구성 | C7: 세트 하나에 무엇이 몇 개 들어가는지 등록합니다. 여기가 핵심입니다.
C8: 예: 선물세트A = 즙 5개 + 정 1개 → 두 줄로 등록
B9: ③ 발주접수 | C9: 받은 발주서를 그대로 넣습니다. 세트든 낱개든 상관없습니다.
B10: ④ 전개결과 | C10: 세트가 낱개로 풀린 결과입니다. 이걸 복사해서 ERP에 넣으면 됩니다.
B11: ⑤ 품목별 소요량 | C11: 낱개 품목별로 총 몇 개가 필요한지 합산됩니다.
B12: ⑥ 거래처별집계 | C12: 거래처별 발주 건수와 금액입니다.
B13: 전개 방식 | C13: 세트 수량 × 구성 수량 = 낱개 소요량
B15: ※ 세트 안에 세트가 들어가는 2단 구성은 지원하지 않습니다.
B16: ※ 발주 120건 × 세트 구성 최대 10품목까지 전개됩니다.

Sheet 품목목록
A1: 품목목록 (낱개 품목)
A2: 품번 | B2: 품명 | C2: 규격 | D2: 단위 | E2: 단가 | F2: 구분
A3: P001 | B3: 홍삼즙 30포 | C3: 3g×30 | D3: 박스 | E3: 28000 | F3: 낱개
A4: P002 | B4: 홍삼정 240g | C4: 240g | D4: EA | E4: 45000 | F4: 낱개
A5: P003 | B5: 쇼핑백 | C5: 대 | D5: EA | E5: 500 | F5: 낱개
A6: K001 | B6: 선물세트 A | C6: 즙5+정1 | D6: 세트 | E6: 0 | F6: 세트
A7: K002 | B7: 선물세트 B | C7: 즙3+정2 | D7: 세트 | E7: 0 | F7: 세트

Sheet 세트구성
A1: 세트구성 (세트 하나에 무엇이 몇 개 들어가는지)
A2: 세트품번 | B2: 세트명(자동) | C2: 구성품번 | D2: 구성품명(자동) | E2: 구성수량 | F2: 순번(자동) | G2: 조회키(자동)
A3: K001 | B3: =IF($A3="","",IFERROR(INDEX(품목목록!$B$3:$B$302,MATCH($A3,품목목록!$A$3:$A$302,0)),"미등록")) -> 선물세트 A | C3: P001 | D3: =IF($C3="","",IFERROR(INDEX(품목목록!$B$3:$B$302,MATCH($C3,품목목록!$A$3:$A$302,0)),"미등록")) -> 홍삼즙 30포 | E3: 5 | F3: =IF($A3="","",COUNTIFS($A$3:$A3,$A3)) -> 1 | G3: =IF($A3="","",$A3&"|"&$F3) -> K001|1
A4: K001 | B4: =IF($A4="","",IFERROR(INDEX(품목목록!$B$3:$B$302,MATCH($A4,품목목록!$A$3:$A$302,0)),"미등록")) -> 선물세트 A | C4: P002 | D4: =IF($C4="","",IFERROR(INDEX(품목목록!$B$3:$B$302,MATCH($C4,품목목록!$A$3:$A$302,0)),"미등록")) -> 홍삼정 240g | E4: 1 | F4: =IF($A4="","",COUNTIFS($A$3:$A4,$A4)) -> 2 | G4: =IF($A4="","",$A4&"|"&$F4) -> K001|2
A5: K001 | B5: =IF($A5="","",IFERROR(INDEX(품목목록!$B$3:$B$302,MATCH($A5,품목목록!$A$3:$A$302,0)),"미등록")) -> 선물세트 A | C5: P003 | D5: =IF($C5="","",IFERROR(INDEX(품목목록!$B$3:$B$302,MATCH($C5,품목목록!$A$3:$A$302,0)),"미등록")) -> 쇼핑백 | E5: 1 | F5: =IF($A5="","",COUNTIFS($A$3:$A5,$A5)) -> 3 | G5: =IF($A5="","",$A5&"|"&$F5) -> K001|3
A6: K002 | B6: =IF($A6="","",IFERROR(INDEX(품목목록!$B$3:$B$302,MATCH($A6,품목목록!$A$3:$A$302,0)),"미등록")) -> 선물세트 B | C6: P001 | D6: =IF($C6="","",IFERROR(INDEX(품목목록!$B$3:$B$302,MATCH($C6,품목목록!$A$3:$A$302,0)),"미등록")) -> 홍삼즙 30포 | E6: 3 | F6: =IF($A6="","",COUNTIFS($A$3:$A6,$A6)) -> 1 | G6: =IF($A6="","",$A6&"|"&$F6) -> K002|1
A7: K002 | B7: =IF($A7="","",IFERROR(INDEX(품목목록!$B$3:$B$302,MATCH($A7,품목목록!$A$3:$A$302,0)),"미등록")) -> 선물세트 B | C7: P002 | D7: =IF($C7="","",IFERROR(INDEX(품목목록!$B$3:$B$302,MATCH($C7,품목목록!$A$3:$A$302,0)),"미등록")) -> 홍삼정 240g | E7: 2 | F7: =IF($A7="","",COUNTIFS($A$3:$A7,$A7)) -> 2 | G7: =IF($A7="","",$A7&"|"&$F7) -> K002|2
A8: K002 | B8: =IF($A8="","",IFERROR(INDEX(품목목록!$B$3:$B$302,MATCH($A8,품목목록!$A$3:$A$302,0)),"미등록")) -> 선물세트 B | C8: P003 | D8: =IF($C8="","",IFERROR(INDEX(품목목록!$B$3:$B$302,MATCH($C8,품목목록!$A$3:$A$302,0)),"미등록")) -> 쇼핑백 | E8: 1 | F8: =IF($A8="","",COUNTIFS($A$3:$A8,$A8)) -> 3 | G8: =IF($A8="","",$A8&"|"&$F8) -> K002|3
B9: =IF($A9="","",IFERROR(INDEX(품목목록!$B$3:$B$302,MATCH($A9,품목목록!$A$3:$A$302,0)),"미등록")) | D9: =IF($C9="","",IFERROR(INDEX(품목목록!$B$3:$B$302,MATCH($C9,품목목록!$A$3:$A$302,0)),"미등록")) | F9: =IF($A9="","",COUNTIFS($A$3:$A9,$A9)) | G9: =IF($A9="","",$A9&"|"&$F9)
B10: =IF($A10="","",IFERROR(INDEX(품목목록!$B$3:$B$302,MATCH($A10,품목목록!$A$3:$A$302,0)),"미등록")) | D10: =IF($C10="","",IFERROR(INDEX(품목목록!$B$3:$B$302,MATCH($C10,품목목록!$A$3:$A$302,0)),"미등록")) | F10: =IF($A10="","",COUNTIFS($A$3:$A10,$A10)) | G10: =IF($A10="","",$A10&"|"&$F10)
B11: =IF($A11="","",IFERROR(INDEX(품목목록!$B$3:$B$302,MATCH($A11,품목목록!$A$3:$A$302,0)),"미등록")) | D11: =IF($C11="","",IFERROR(INDEX(품목목록!$B$3:$B$302,MATCH($C11,품목목록!$A$3:$A$302,0)),"미등록")) | F11: =IF($A11="","",COUNTIFS($A$3:$A11,$A11)) | G11: =IF($A11="","",$A11&"|"&$F11)
B12: =IF($A12="","",IFERROR(INDEX(품목목록!$B$3:$B$302,MATCH($A12,품목목록!$A$3:$A$302,0)),"미등록")) | D12: =IF($C12="","",IFERROR(INDEX(품목목록!$B$3:$B$302,MATCH($C12,품목목록!$A$3:$A$302,0)),"미등록")) | F12: =IF($A12="","",COUNTIFS($A$3:$A12,$A12)) | G12: =IF($A12="","",$A12&"|"&$F12)
B13: =IF($A13="","",IFERROR(INDEX(품목목록!$B$3:$B$302,MATCH($A13,품목목록!$A$3:$A$302,0)),"미등록")) | D13: =IF($C13="","",IFERROR(INDEX(품목목록!$B$3:$B$302,MATCH($C13,품목목록!$A$3:$A$302,0)),"미등록")) | F13: =IF($A13="","",COUNTIFS($A$3:$A13,$A13)) | G13: =IF($A13="","",$A13&"|"&$F13)
B14: =IF($A14="","",IFERROR(INDEX(품목목록!$B$3:$B$302,MATCH($A14,품목목록!$A$3:$A$302,0)),"미등록")) | D14: =IF($C14="","",IFERROR(INDEX(품목목록!$B$3:$B$302,MATCH($C14,품목목록!$A$3:$A$302,0)),"미등록")) | F14: =IF($A14="","",COUNTIFS($A$3:$A14,$A14)) | G14: =IF($A14="","",$A14&"|"&$F14)
B15: =IF($A15="","",IFERROR(INDEX(품목목록!$B$3:$B$302,MATCH($A15,품목목록!$A$3:$A$302,0)),"미등록")) | D15: =IF($C15="","",IFERROR(INDEX(품목목록!$B$3:$B$302,MATCH($C15,품목목록!$A$3:$A$302,0)),"미등록")) | F15: =IF($A15="","",COUNTIFS($A$3:$A15,$A15)) | G15: =IF($A15="","",$A15&"|"&$F15)
B16: =IF($A16="","",IFERROR(INDEX(품목목록!$B$3:$B$302,MATCH($A16,품목목록!$A$3:$A$302,0)),"미등록")) | D16: =IF($C16="","",IFERROR(INDEX(품목목록!$B$3:$B$302,MATCH($C16,품목목록!$A$3:$A$302,0)),"미등록")) | F16: =IF($A16="","",COUNTIFS($A$3:$A16,$A16)) | G16: =IF($A16="","",$A16&"|"&$F16)
B17: =IF($A17="","",IFERROR(INDEX(품목목록!$B$3:$B$302,MATCH($A17,품목목록!$A$3:$A$302,0)),"미등록")) | D17: =IF($C17="","",IFERROR(INDEX(품목목록!$B$3:$B$302,MATCH($C17,품목목록!$A$3:$A$302,0)),"미등록")) | F17: =IF($A17="","",COUNTIFS($A$3:$A17,$A17)) | G17: =IF($A17="","",$A17&"|"&$F17)
B18: =IF($A18="","",IFERROR(INDEX(품목목록!$B$3:$B$302,MATCH($A18,품목목록!$A$3:$A$302,0)),"미등록")) | D18: =IF($C18="","",IFERROR(INDEX(품목목록!$B$3:$B$302,MATCH($C18,품목목록!$A$3:$A$302,0)),"미등록")) | F18: =IF($A18="","",COUNTIFS($A$3:$A18,$A18)) | G18: =IF($A18="","",$A18&"|"&$F18)
B19: =IF($A19="","",IFERROR(INDEX(품목목록!$B$3:$B$302,MATCH($A19,품목목록!$A$3:$A$302,0)),"미등록")) | D19: =IF($C19="","",IFERROR(INDEX(품목목록!$B$3:$B$302,MATCH($C19,품목목록!$A$3:$A$302,0)),"미등록")) | F19: =IF($A19="","",COUNTIFS($A$3:$A19,$A19)) | G19: =IF($A19="","",$A19&"|"&$F19)
B20: =IF($A20="","",IFERROR(INDEX(품목목록!$B$3:$B$302,MATCH($A20,품목목록!$A$3:$A$302,0)),"미등록")) | D20: =IF($C20="","",IFERROR(INDEX(품목목록!$B$3:$B$302,MATCH($C20,품목목록!$A$3:$A$302,0)),"미등록")) | F20: =IF($A20="","",COUNTIFS($A$3:$A20,$A20)) | G20: =IF($A20="","",$A20&"|"&$F20)
... B302: =IF($A302="","",IFERROR(INDEX(품목목록!$B$3:$B$302,MATCH($A302,품목목록!$A$3:$A$302,0)),"미등록")) | D302: =IF($C302="","",IFERROR(INDEX(품목목록!$B$3:$B$302,MATCH($C302,품목목록!$A$3:$A$302,0)),"미등록")) | F302: =IF($A302="","",COUNTIFS($A$3:$A302,$A302)) | G302: =IF($A302="","",$A302&"|"&$F302)

Sheet 발주접수
A1: 발주접수 (받은 발주서 그대로)
A2: No(자동) | B2: 발주일 | C2: 거래처 | D2: 품번 | E2: 품명(자동) | F2: 구분(자동) | G2: 수량 | H2: 단가(자동) | I2: 금액(자동) | J2: 비고
A3: =IF($D3="","",ROW()-2) -> 1 | B3: 46275 | C3: ○○마트 | D3: K001 | E3: =IF($D3="","",IFERROR(INDEX(품목목록!$B$3:$B$302,MATCH($D3,품목목록!$A$3:$A$302,0)),"미등록품번")) -> 선물세트 A | F3: =IF($D3="","",IFERROR(INDEX(품목목록!$F$3:$F$302,MATCH($D3,품목목록!$A$3:$A$302,0)),"")) -> 세트 | G3: 3 | H3: =IF($D3="","",IFERROR(INDEX(품목목록!$E$3:$E$302,MATCH($D3,품목목록!$A$3:$A$302,0)),0)) -> 0 | I3: =IF(OR($G3="",$H3=""),"",ROUND($G3*$H3,0)) -> 0
A4: =IF($D4="","",ROW()-2) -> 2 | B4: 46275 | C4: ○○마트 | D4: P001 | E4: =IF($D4="","",IFERROR(INDEX(품목목록!$B$3:$B$302,MATCH($D4,품목목록!$A$3:$A$302,0)),"미등록품번")) -> 홍삼즙 30포 | F4: =IF($D4="","",IFERROR(INDEX(품목목록!$F$3:$F$302,MATCH($D4,품목목록!$A$3:$A$302,0)),"")) -> 낱개 | G4: 10 | H4: =IF($D4="","",IFERROR(INDEX(품목목록!$E$3:$E$302,MATCH($D4,품목목록!$A$3:$A$302,0)),0)) -> 28000 | I4: =IF(OR($G4="",$H4=""),"",ROUND($G4*$H4,0)) -> 280000
A5: =IF($D5="","",ROW()-2) -> 3 | B5: 46276 | C5: △△백화점 | D5: K002 | E5: =IF($D5="","",IFERROR(INDEX(품목목록!$B$3:$B$302,MATCH($D5,품목목록!$A$3:$A$302,0)),"미등록품번")) -> 선물세트 B | F5: =IF($D5="","",IFERROR(INDEX(품목목록!$F$3:$F$302,MATCH($D5,품목목록!$A$3:$A$302,0)),"")) -> 세트 | G5: 5 | H5: =IF($D5="","",IFERROR(INDEX(품목목록!$E$3:$E$302,MATCH($D5,품목목록!$A$3:$A$302,0)),0)) -> 0 | I5: =IF(OR($G5="",$H5=""),"",ROUND($G5*$H5,0)) -> 0
A6: =IF($D6="","",ROW()-2) | E6: =IF($D6="","",IFERROR(INDEX(품목목록!$B$3:$B$302,MATCH($D6,품목목록!$A$3:$A$302,0)),"미등록품번")) | F6: =IF($D6="","",IFERROR(INDEX(품목목록!$F$3:$F$302,MATCH($D6,품목목록!$A$3:$A$302,0)),"")) | H6: =IF($D6="","",IFERROR(INDEX(품목목록!$E$3:$E$302,MATCH($D6,품목목록!$A$3:$A$302,0)),0)) | I6: =IF(OR($G6="",$H6=""),"",ROUND($G6*$H6,0))
A7: =IF($D7="","",ROW()-2) | E7: =IF($D7="","",IFERROR(INDEX(품목목록!$B$3:$B$302,MATCH($D7,품목목록!$A$3:$A$302,0)),"미등록품번")) | F7: =IF($D7="","",IFERROR(INDEX(품목목록!$F$3:$F$302,MATCH($D7,품목목록!$A$3:$A$302,0)),"")) | H7: =IF($D7="","",IFERROR(INDEX(품목목록!$E$3:$E$302,MATCH($D7,품목목록!$A$3:$A$302,0)),0)) | I7: =IF(OR($G7="",$H7=""),"",ROUND($G7*$H7,0))
A8: =IF($D8="","",ROW()-2) | E8: =IF($D8="","",IFERROR(INDEX(품목목록!$B$3:$B$302,MATCH($D8,품목목록!$A$3:$A$302,0)),"미등록품번")) | F8: =IF($D8="","",IFERROR(INDEX(품목목록!$F$3:$F$302,MATCH($D8,품목목록!$A$3:$A$302,0)),"")) | H8: =IF($D8="","",IFERROR(INDEX(품목목록!$E$3:$E$302,MATCH($D8,품목목록!$A$3:$A$302,0)),0)) | I8: =IF(OR($G8="",$H8=""),"",ROUND($G8*$H8,0))
A9: =IF($D9="","",ROW()-2) | E9: =IF($D9="","",IFERROR(INDEX(품목목록!$B$3:$B$302,MATCH($D9,품목목록!$A$3:$A$302,0)),"미등록품번")) | F9: =IF($D9="","",IFERROR(INDEX(품목목록!$F$3:$F$302,MATCH($D9,품목목록!$A$3:$A$302,0)),"")) | H9: =IF($D9="","",IFERROR(INDEX(품목목록!$E$3:$E$302,MATCH($D9,품목목록!$A$3:$A$302,0)),0)) | I9: =IF(OR($G9="",$H9=""),"",ROUND($G9*$H9,0))
A10: =IF($D10="","",ROW()-2) | E10: =IF($D10="","",IFERROR(INDEX(품목목록!$B$3:$B$302,MATCH($D10,품목목록!$A$3:$A$302,0)),"미등록품번")) | F10: =IF($D10="","",IFERROR(INDEX(품목목록!$F$3:$F$302,MATCH($D10,품목목록!$A$3:$A$302,0)),"")) | H10: =IF($D10="","",IFERROR(INDEX(품목목록!$E$3:$E$302,MATCH($D10,품목목록!$A$3:$A$302,0)),0)) | I10: =IF(OR($G10="",$H10=""),"",ROUND($G10*$H10,0))
A11: =IF($D11="","",ROW()-2) | E11: =IF($D11="","",IFERROR(INDEX(품목목록!$B$3:$B$302,MATCH($D11,품목목록!$A$3:$A$302,0)),"미등록품번")) | F11: =IF($D11="","",IFERROR(INDEX(품목목록!$F$3:$F$302,MATCH($D11,품목목록!$A$3:$A$302,0)),"")) | H11: =IF($D11="","",IFERROR(INDEX(품목목록!$E$3:$E$302,MATCH($D11,품목목록!$A$3:$A$302,0)),0)) | I11: =IF(OR($G11="",$H11=""),"",ROUND($G11*$H11,0))
A12: =IF($D12="","",ROW()-2) | E12: =IF($D12="","",IFERROR(INDEX(품목목록!$B$3:$B$302,MATCH($D12,품목목록!$A$3:$A$302,0)),"미등록품번")) | F12: =IF($D12="","",IFERROR(INDEX(품목목록!$F$3:$F$302,MATCH($D12,품목목록!$A$3:$A$302,0)),"")) | H12: =IF($D12="","",IFERROR(INDEX(품목목록!$E$3:$E$302,MATCH($D12,품목목록!$A$3:$A$302,0)),0)) | I12: =IF(OR($G12="",$H12=""),"",ROUND($G12*$H12,0))
A13: =IF($D13="","",ROW()-2) | E13: =IF($D13="","",IFERROR(INDEX(품목목록!$B$3:$B$302,MATCH($D13,품목목록!$A$3:$A$302,0)),"미등록품번")) | F13: =IF($D13="","",IFERROR(INDEX(품목목록!$F$3:$F$302,MATCH($D13,품목목록!$A$3:$A$302,0)),"")) | H13: =IF($D13="","",IFERROR(INDEX(품목목록!$E$3:$E$302,MATCH($D13,품목목록!$A$3:$A$302,0)),0)) | I13: =IF(OR($G13="",$H13=""),"",ROUND($G13*$H13,0))
A14: =IF($D14="","",ROW()-2) | E14: =IF($D14="","",IFERROR(INDEX(품목목록!$B$3:$B$302,MATCH($D14,품목목록!$A$3:$A$302,0)),"미등록품번")) | F14: =IF($D14="","",IFERROR(INDEX(품목목록!$F$3:$F$302,MATCH($D14,품목목록!$A$3:$A$302,0)),"")) | H14: =IF($D14="","",IFERROR(INDEX(품목목록!$E$3:$E$302,MATCH($D14,품목목록!$A$3:$A$302,0)),0)) | I14: =IF(OR($G14="",$H14=""),"",ROUND($G14*$H14,0))
A15: =IF($D15="","",ROW()-2) | E15: =IF($D15="","",IFERROR(INDEX(품목목록!$B$3:$B$302,MATCH($D15,품목목록!$A$3:$A$302,0)),"미등록품번")) | F15: =IF($D15="","",IFERROR(INDEX(품목목록!$F$3:$F$302,MATCH($D15,품목목록!$A$3:$A$302,0)),"")) | H15: =IF($D15="","",IFERROR(INDEX(품목목록!$E$3:$E$302,MATCH($D15,품목목록!$A$3:$A$302,0)),0)) | I15: =IF(OR($G15="",$H15=""),"",ROUND($G15*$H15,0))
A16: =IF($D16="","",ROW()-2) | E16: =IF($D16="","",IFERROR(INDEX(품목목록!$B$3:$B$302,MATCH($D16,품목목록!$A$3:$A$302,0)),"미등록품번")) | F16: =IF($D16="","",IFERROR(INDEX(품목목록!$F$3:$F$302,MATCH($D16,품목목록!$A$3:$A$302,0)),"")) | H16: =IF($D16="","",IFERROR(INDEX(품목목록!$E$3:$E$302,MATCH($D16,품목목록!$A$3:$A$302,0)),0)) | I16: =IF(OR($G16="",$H16=""),"",ROUND($G16*$H16,0))
A17: =IF($D17="","",ROW()-2) | E17: =IF($D17="","",IFERROR(INDEX(품목목록!$B$3:$B$302,MATCH($D17,품목목록!$A$3:$A$302,0)),"미등록품번")) | F17: =IF($D17="","",IFERROR(INDEX(품목목록!$F$3:$F$302,MATCH($D17,품목목록!$A$3:$A$302,0)),"")) | H17: =IF($D17="","",IFERROR(INDEX(품목목록!$E$3:$E$302,MATCH($D17,품목목록!$A$3:$A$302,0)),0)) | I17: =IF(OR($G17="",$H17=""),"",ROUND($G17*$H17,0))
... A122: =IF($D122="","",ROW()-2) | E122: =IF($D122="","",IFERROR(INDEX(품목목록!$B$3:$B$302,MATCH($D122,품목목록!$A$3:$A$302,0)),"미등록품번")) | F122: =IF($D122="","",IFERROR(INDEX(품목목록!$F$3:$F$302,MATCH($D122,품목목록!$A$3:$A$302,0)),"")) | H122: =IF($D122="","",IFERROR(INDEX(품목목록!$E$3:$E$302,MATCH($D122,품목목록!$A$3:$A$302,0)),0)) | I122: =IF(OR($G122="",$H122=""),"",ROUND($G122*$H122,0))

Sheet 전개결과
A1: 전개결과 (세트가 낱개로 풀린 결과 · 이걸 복사해서 쓰세요)
A3: 전개 줄 수 | B3: =COUNTIF($J$6:$J$1205,TRUE()) -> 7
A5: 순번 | B5: 발주일 | C5: 거래처 | D5: 품번 | E5: 품명 | F5: 단위 | G5: 소요수량 | H5: 출처 | J5: 대상(자동) | K5: 순번(자동) | L5: 키(자동) | M5: 품번(자동) | N5: 수량(자동) | O5: 발주일(자동) | P5: 거래처(자동) | Q5: 출처(자동)
A6: =IF($D6="","",1) -> 1 | B6: =IFERROR(INDEX(전개결과!$O$6:$O$1205,MATCH("R"&1,전개결과!$L$6:$L$1205,0)),"") -> 46275 | C6: =IF($D6="","",IFERROR(INDEX(전개결과!$P$6:$P$1205,MATCH("R"&1,전개결과!$L$6:$L$1205,0)),"")) -> ○○마트 | D6: =IFERROR(INDEX(전개결과!$M$6:$M$1205,MATCH("R"&1,전개결과!$L$6:$L$1205,0)),"") -> P001 | E6: =IF($D6="","",IFERROR(INDEX(품목목록!$B$3:$B$302,MATCH($D6,품목목록!$A$3:$A$302,0)),"")) -> 홍삼즙 30포 | F6: =IF($D6="","",IFERROR(INDEX(품목목록!$D$3:$D$302,MATCH($D6,품목목록!$A$3:$A$302,0)),"")) -> 박스 | G6: =IFERROR(INDEX(전개결과!$N$6:$N$1205,MATCH("R"&1,전개결과!$L$6:$L$1205,0)),"") -> 15 | H6: =IF($D6="","",IFERROR(INDEX(전개결과!$Q$6:$Q$1205,MATCH("R"&1,전개결과!$L$6:$L$1205,0)),"")) -> 선물세트 A 전개 | J6: =IF(발주접수!$D3="",FALSE(),IF(발주접수!$F3="세트",COUNTIF(세트구성!$G$3:$G$302,발주접수!$D3&"|"&1)>0,0=0)) -> TRUE | K6: =IF($J6=FALSE(),"",COUNTIF($J$6:$J6,TRUE())) -> 1 | L6: =IF($K6="","","R"&$K6) -> R1 | M6: =IF($J6=FALSE(),"",IF(발주접수!$F3="세트",IFERROR(INDEX(세트구성!$C$3:$C$302,MATCH(발주접수!$D3&"|"&1,세트구성!$G$3:$G$302,0)),""),발주접수!$D3)) -> P001 | N6: =IF($J6=FALSE(),"",IF(발주접수!$F3="세트",발주접수!$G3*IFERROR(INDEX(세트구성!$E$3:$E$302,MATCH(발주접수!$D3&"|"&1,세트구성!$G$3:$G$302,0)),0),발주접수!$G3)) -> 15 | O6: =IF($J6=FALSE(),"",발주접수!$B3) -> 46275 | P6: =IF($J6=FALSE(),"",발주접수!$C3) -> ○○마트 | Q6: =IF($J6=FALSE(),"",IF(발주접수!$F3="세트",발주접수!$E3&" 전개","직접 발주")) -> 선물세트 A 전개
A7: =IF($D7="","",2) -> 2 | B7: =IFERROR(INDEX(전개결과!$O$6:$O$1205,MATCH("R"&2,전개결과!$L$6:$L$1205,0)),"") -> 46275 | C7: =IF($D7="","",IFERROR(INDEX(전개결과!$P$6:$P$1205,MATCH("R"&2,전개결과!$L$6:$L$1205,0)),"")) -> ○○마트 | D7: =IFERROR(INDEX(전개결과!$M$6:$M$1205,MATCH("R"&2,전개결과!$L$6:$L$1205,0)),"") -> P002 | E7: =IF($D7="","",IFERROR(INDEX(품목목록!$B$3:$B$302,MATCH($D7,품목목록!$A$3:$A$302,0)),"")) -> 홍삼정 240g | F7: =IF($D7="","",IFERROR(INDEX(품목목록!$D$3:$D$302,MATCH($D7,품목목록!$A$3:$A$302,0)),"")) -> EA | G7: =IFERROR(INDEX(전개결과!$N$6:$N$1205,MATCH("R"&2,전개결과!$L$6:$L$1205,0)),"") -> 3 | H7: =IF($D7="","",IFERROR(INDEX(전개결과!$Q$6:$Q$1205,MATCH("R"&2,전개결과!$L$6:$L$1205,0)),"")) -> 선물세트 A 전개 | J7: =IF(발주접수!$D3="",FALSE(),IF(발주접수!$F3="세트",COUNTIF(세트구성!$G$3:$G$302,발주접수!$D3&"|"&2)>0,1=0)) -> TRUE | K7: =IF($J7=FALSE(),"",COUNTIF($J$6:$J7,TRUE())) -> 2 | L7: =IF($K7="","","R"&$K7) -> R2 | M7: =IF($J7=FALSE(),"",IF(발주접수!$F3="세트",IFERROR(INDEX(세트구성!$C$3:$C$302,MATCH(발주접수!$D3&"|"&2,세트구성!$G$3:$G$302,0)),""),발주접수!$D3)) -> P002 | N7: =IF($J7=FALSE(),"",IF(발주접수!$F3="세트",발주접수!$G3*IFERROR(INDEX(세트구성!$E$3:$E$302,MATCH(발주접수!$D3&"|"&2,세트구성!$G$3:$G$302,0)),0),발주접수!$G3)) -> 3 | O7: =IF($J7=FALSE(),"",발주접수!$B3) -> 46275 | P7: =IF($J7=FALSE(),"",발주접수!$C3) -> ○○마트 | Q7: =IF($J7=FALSE(),"",IF(발주접수!$F3="세트",발주접수!$E3&" 전개","직접 발주")) -> 선물세트 A 전개
A8: =IF($D8="","",3) -> 3 | B8: =IFERROR(INDEX(전개결과!$O$6:$O$1205,MATCH("R"&3,전개결과!$L$6:$L$1205,0)),"") -> 46275 | C8: =IF($D8="","",IFERROR(INDEX(전개결과!$P$6:$P$1205,MATCH("R"&3,전개결과!$L$6:$L$1205,0)),"")) -> ○○마트 | D8: =IFERROR(INDEX(전개결과!$M$6:$M$1205,MATCH("R"&3,전개결과!$L$6:$L$1205,0)),"") -> P003 | E8: =IF($D8="","",IFERROR(INDEX(품목목록!$B$3:$B$302,MATCH($D8,품목목록!$A$3:$A$302,0)),"")) -> 쇼핑백 | F8: =IF($D8="","",IFERROR(INDEX(품목목록!$D$3:$D$302,MATCH($D8,품목목록!$A$3:$A$302,0)),"")) -> EA | G8: =IFERROR(INDEX(전개결과!$N$6:$N$1205,MATCH("R"&3,전개결과!$L$6:$L$1205,0)),"") -> 3 | H8: =IF($D8="","",IFERROR(INDEX(전개결과!$Q$6:$Q$1205,MATCH("R"&3,전개결과!$L$6:$L$1205,0)),"")) -> 선물세트 A 전개 | J8: =IF(발주접수!$D3="",FALSE(),IF(발주접수!$F3="세트",COUNTIF(세트구성!$G$3:$G$302,발주접수!$D3&"|"&3)>0,2=0)) -> TRUE | K8: =IF($J8=FALSE(),"",COUNTIF($J$6:$J8,TRUE())) -> 3 | L8: =IF($K8="","","R"&$K8) -> R3 | M8: =IF($J8=FALSE(),"",IF(발주접수!$F3="세트",IFERROR(INDEX(세트구성!$C$3:$C$302,MATCH(발주접수!$D3&"|"&3,세트구성!$G$3:$G$302,0)),""),발주접수!$D3)) -> P003 | N8: =IF($J8=FALSE(),"",IF(발주접수!$F3="세트",발주접수!$G3*IFERROR(INDEX(세트구성!$E$3:$E$302,MATCH(발주접수!$D3&"|"&3,세트구성!$G$3:$G$302,0)),0),발주접수!$G3)) -> 3 | O8: =IF($J8=FALSE(),"",발주접수!$B3) -> 46275 | P8: =IF($J8=FALSE(),"",발주접수!$C3) -> ○○마트 | Q8: =IF($J8=FALSE(),"",IF(발주접수!$F3="세트",발주접수!$E3&" 전개","직접 발주")) -> 선물세트 A 전개
A9: =IF($D9="","",4) -> 4 | B9: =IFERROR(INDEX(전개결과!$O$6:$O$1205,MATCH("R"&4,전개결과!$L$6:$L$1205,0)),"") -> 46275 | C9: =IF($D9="","",IFERROR(INDEX(전개결과!$P$6:$P$1205,MATCH("R"&4,전개결과!$L$6:$L$1205,0)),"")) -> ○○마트 | D9: =IFERROR(INDEX(전개결과!$M$6:$M$1205,MATCH("R"&4,전개결과!$L$6:$L$1205,0)),"") -> P001 | E9: =IF($D9="","",IFERROR(INDEX(품목목록!$B$3:$B$302,MATCH($D9,품목목록!$A$3:$A$302,0)),"")) -> 홍삼즙 30포 | F9: =IF($D9="","",IFERROR(INDEX(품목목록!$D$3:$D$302,MATCH($D9,품목목록!$A$3:$A$302,0)),"")) -> 박스 | G9: =IFERROR(INDEX(전개결과!$N$6:$N$1205,MATCH("R"&4,전개결과!$L$6:$L$1205,0)),"") -> 10 | H9: =IF($D9="","",IFERROR(INDEX(전개결과!$Q$6:$Q$1205,MATCH("R"&4,전개결과!$L$6:$L$1205,0)),"")) -> 직접 발주 | J9: =IF(발주접수!$D3="",FALSE(),IF(발주접수!$F3="세트",COUNTIF(세트구성!$G$3:$G$302,발주접수!$D3&"|"&4)>0,3=0)) -> FALSE | K9: =IF($J9=FALSE(),"",COUNTIF($J$6:$J9,TRUE())) | L9: =IF($K9="","","R"&$K9) | M9: =IF($J9=FALSE(),"",IF(발주접수!$F3="세트",IFERROR(INDEX(세트구성!$C$3:$C$302,MATCH(발주접수!$D3&"|"&4,세트구성!$G$3:$G$302,0)),""),발주접수!$D3)) | N9: =IF($J9=FALSE(),"",IF(발주접수!$F3="세트",발주접수!$G3*IFERROR(INDEX(세트구성!$E$3:$E$302,MATCH(발주접수!$D3&"|"&4,세트구성!$G$3:$G$302,0)),0),발주접수!$G3)) | O9: =IF($J9=FALSE(),"",발주접수!$B3) | P9: =IF($J9=FALSE(),"",발주접수!$C3) | Q9: =IF($J9=FALSE(),"",IF(발주접수!$F3="세트",발주접수!$E3&" 전개","직접 발주"))
A10: =IF($D10="","",5) -> 5 | B10: =IFERROR(INDEX(전개결과!$O$6:$O$1205,MATCH("R"&5,전개결과!$L$6:$L$1205,0)),"") -> 46276 | C10: =IF($D10="","",IFERROR(INDEX(전개결과!$P$6:$P$1205,MATCH("R"&5,전개결과!$L$6:$L$1205,0)),"")) -> △△백화점 | D10: =IFERROR(INDEX(전개결과!$M$6:$M$1205,MATCH("R"&5,전개결과!$L$6:$L$1205,0)),"") -> P001 | E10: =IF($D10="","",IFERROR(INDEX(품목목록!$B$3:$B$302,MATCH($D10,품목목록!$A$3:$A$302,0)),"")) -> 홍삼즙 30포 | F10: =IF($D10="","",IFERROR(INDEX(품목목록!$D$3:$D$302,MATCH($D10,품목목록!$A$3:$A$302,0)),"")) -> 박스 | G10: =IFERROR(INDEX(전개결과!$N$6:$N$1205,MATCH("R"&5,전개결과!$L$6:$L$1205,0)),"") -> 15 | H10: =IF($D10="","",IFERROR(INDEX(전개결과!$Q$6:$Q$1205,MATCH("R"&5,전개결과!$L$6:$L$1205,0)),"")) -> 선물세트 B 전개 | J10: =IF(발주접수!$D3="",FALSE(),IF(발주접수!$F3="세트",COUNTIF(세트구성!$G$3:$G$302,발주접수!$D3&"|"&5)>0,4=0)) -> FALSE | K10: =IF($J10=FALSE(),"",COUNTIF($J$6:$J10,TRUE())) | L10: =IF($K10="","","R"&$K10) | M10: =IF($J10=FALSE(),"",IF(발주접수!$F3="세트",IFERROR(INDEX(세트구성!$C$3:$C$302,MATCH(발주접수!$D3&"|"&5,세트구성!$G$3:$G$302,0)),""),발주접수!$D3)) | N10: =IF($J10=FALSE(),"",IF(발주접수!$F3="세트",발주접수!$G3*IFERROR(INDEX(세트구성!$E$3:$E$302,MATCH(발주접수!$D3&"|"&5,세트구성!$G$3:$G$302,0)),0),발주접수!$G3)) | O10: =IF($J10=FALSE(),"",발주접수!$B3) | P10: =IF($J10=FALSE(),"",발주접수!$C3) | Q10: =IF($J10=FALSE(),"",IF(발주접수!$F3="세트",발주접수!$E3&" 전개","직접 발주"))
A11: =IF($D11="","",6) -> 6 | B11: =IFERROR(INDEX(전개결과!$O$6:$O$1205,MATCH("R"&6,전개결과!$L$6:$L$1205,0)),"") -> 46276 | C11: =IF($D11="","",IFERROR(INDEX(전개결과!$P$6:$P$1205,MATCH("R"&6,전개결과!$L$6:$L$1205,0)),"")) -> △△백화점 | D11: =IFERROR(INDEX(전개결과!$M$6:$M$1205,MATCH("R"&6,전개결과!$L$6:$L$1205,0)),"") -> P002 | E11: =IF($D11="","",IFERROR(INDEX(품목목록!$B$3:$B$302,MATCH($D11,품목목록!$A$3:$A$302,0)),"")) -> 홍삼정 240g | F11: =IF($D11="","",IFERROR(INDEX(품목목록!$D$3:$D$302,MATCH($D11,품목목록!$A$3:$A$302,0)),"")) -> EA | G11: =IFERROR(INDEX(전개결과!$N$6:$N$1205,MATCH("R"&6,전개결과!$L$6:$L$1205,0)),"") -> 10 | H11: =IF($D11="","",IFERROR(INDEX(전개결과!$Q$6:$Q$1205,MATCH("R"&6,전개결과!$L$6:$L$1205,0)),"")) -> 선물세트 B 전개 | J11: =IF(발주접수!$D3="",FALSE(),IF(발주접수!$F3="세트",COUNTIF(세트구성!$G$3:$G$302,발주접수!$D3&"|"&6)>0,5=0)) -> FALSE | K11: =IF($J11=FALSE(),"",COUNTIF($J$6:$J11,TRUE())) | L11: =IF($K11="","","R"&$K11) | M11: =IF($J11=FALSE(),"",IF(발주접수!$F3="세트",IFERROR(INDEX(세트구성!$C$3:$C$302,MATCH(발주접수!$D3&"|"&6,세트구성!$G$3:$G$302,0)),""),발주접수!$D3)) | N11: =IF($J11=FALSE(),"",IF(발주접수!$F3="세트",발주접수!$G3*IFERROR(INDEX(세트구성!$E$3:$E$302,MATCH(발주접수!$D3&"|"&6,세트구성!$G$3:$G$302,0)),0),발주접수!$G3)) | O11: =IF($J11=FALSE(),"",발주접수!$B3) | P11: =IF($J11=FALSE(),"",발주접수!$C3) | Q11: =IF($J11=FALSE(),"",IF(발주접수!$F3="세트",발주접수!$E3&" 전개","직접 발주"))
A12: =IF($D12="","",7) -> 7 | B12: =IFERROR(INDEX(전개결과!$O$6:$O$1205,MATCH("R"&7,전개결과!$L$6:$L$1205,0)),"") -> 46276 | C12: =IF($D12="","",IFERROR(INDEX(전개결과!$P$6:$P$1205,MATCH("R"&7,전개결과!$L$6:$L$1205,0)),"")) -> △△백화점 | D12: =IFERROR(INDEX(전개결과!$M$6:$M$1205,MATCH("R"&7,전개결과!$L$6:$L$1205,0)),"") -> P003 | E12: =IF($D12="","",IFERROR(INDEX(품목목록!$B$3:$B$302,MATCH($D12,품목목록!$A$3:$A$302,0)),"")) -> 쇼핑백 | F12: =IF($D12="","",IFERROR(INDEX(품목목록!$D$3:$D$302,MATCH($D12,품목목록!$A$3:$A$302,0)),"")) -> EA | G12: =IFERROR(INDEX(전개결과!$N$6:$N$1205,MATCH("R"&7,전개결과!$L$6:$L$1205,0)),"") -> 5 | H12: =IF($D12="","",IFERROR(INDEX(전개결과!$Q$6:$Q$1205,MATCH("R"&7,전개결과!$L$6:$L$1205,0)),"")) -> 선물세트 B 전개 | J12: =IF(발주접수!$D3="",FALSE(),IF(발주접수!$F3="세트",COUNTIF(세트구성!$G$3:$G$302,발주접수!$D3&"|"&7)>0,6=0)) -> FALSE | K12: =IF($J12=FALSE(),"",COUNTIF($J$6:$J12,TRUE())) | L12: =IF($K12="","","R"&$K12) | M12: =IF($J12=FALSE(),"",IF(발주접수!$F3="세트",IFERROR(INDEX(세트구성!$C$3:$C$302,MATCH(발주접수!$D3&"|"&7,세트구성!$G$3:$G$302,0)),""),발주접수!$D3)) | N12: =IF($J12=FALSE(),"",IF(발주접수!$F3="세트",발주접수!$G3*IFERROR(INDEX(세트구성!$E$3:$E$302,MATCH(발주접수!$D3&"|"&7,세트구성!$G$3:$G$302,0)),0),발주접수!$G3)) | O12: =IF($J12=FALSE(),"",발주접수!$B3) | P12: =IF($J12=FALSE(),"",발주접수!$C3) | Q12: =IF($J12=FALSE(),"",IF(발주접수!$F3="세트",발주접수!$E3&" 전개","직접 발주"))
A13: =IF($D13="","",8) | B13: =IFERROR(INDEX(전개결과!$O$6:$O$1205,MATCH("R"&8,전개결과!$L$6:$L$1205,0)),"") | C13: =IF($D13="","",IFERROR(INDEX(전개결과!$P$6:$P$1205,MATCH("R"&8,전개결과!$L$6:$L$1205,0)),"")) | D13: =IFERROR(INDEX(전개결과!$M$6:$M$1205,MATCH("R"&8,전개결과!$L$6:$L$1205,0)),"") | E13: =IF($D13="","",IFERROR(INDEX(품목목록!$B$3:$B$302,MATCH($D13,품목목록!$A$3:$A$302,0)),"")) | F13: =IF($D13="","",IFERROR(INDEX(품목목록!$D$3:$D$302,MATCH($D13,품목목록!$A$3:$A$302,0)),"")) | G13: =IFERROR(INDEX(전개결과!$N$6:$N$1205,MATCH("R"&8,전개결과!$L$6:$L$1205,0)),"") | H13: =IF($D13="","",IFERROR(INDEX(전개결과!$Q$6:$Q$1205,MATCH("R"&8,전개결과!$L$6:$L$1205,0)),"")) | J13: =IF(발주접수!$D3="",FALSE(),IF(발주접수!$F3="세트",COUNTIF(세트구성!$G$3:$G$302,발주접수!$D3&"|"&8)>0,7=0)) -> FALSE | K13: =IF($J13=FALSE(),"",COUNTIF($J$6:$J13,TRUE())) | L13: =IF($K13="","","R"&$K13) | M13: =IF($J13=FALSE(),"",IF(발주접수!$F3="세트",IFERROR(INDEX(세트구성!$C$3:$C$302,MATCH(발주접수!$D3&"|"&8,세트구성!$G$3:$G$302,0)),""),발주접수!$D3)) | N13: =IF($J13=FALSE(),"",IF(발주접수!$F3="세트",발주접수!$G3*IFERROR(INDEX(세트구성!$E$3:$E$302,MATCH(발주접수!$D3&"|"&8,세트구성!$G$3:$G$302,0)),0),발주접수!$G3)) | O13: =IF($J13=FALSE(),"",발주접수!$B3) | P13: =IF($J13=FALSE(),"",발주접수!$C3) | Q13: =IF($J13=FALSE(),"",IF(발주접수!$F3="세트",발주접수!$E3&" 전개","직접 발주"))
A14: =IF($D14="","",9) | B14: =IFERROR(INDEX(전개결과!$O$6:$O$1205,MATCH("R"&9,전개결과!$L$6:$L$1205,0)),"") | C14: =IF($D14="","",IFERROR(INDEX(전개결과!$P$6:$P$1205,MATCH("R"&9,전개결과!$L$6:$L$1205,0)),"")) | D14: =IFERROR(INDEX(전개결과!$M$6:$M$1205,MATCH("R"&9,전개결과!$L$6:$L$1205,0)),"") | E14: =IF($D14="","",IFERROR(INDEX(품목목록!$B$3:$B$302,MATCH($D14,품목목록!$A$3:$A$302,0)),"")) | F14: =IF($D14="","",IFERROR(INDEX(품목목록!$D$3:$D$302,MATCH($D14,품목목록!$A$3:$A$302,0)),"")) | G14: =IFERROR(INDEX(전개결과!$N$6:$N$1205,MATCH("R"&9,전개결과!$L$6:$L$1205,0)),"") | H14: =IF($D14="","",IFERROR(INDEX(전개결과!$Q$6:$Q$1205,MATCH("R"&9,전개결과!$L$6:$L$1205,0)),"")) | J14: =IF(발주접수!$D3="",FALSE(),IF(발주접수!$F3="세트",COUNTIF(세트구성!$G$3:$G$302,발주접수!$D3&"|"&9)>0,8=0)) -> FALSE | K14: =IF($J14=FALSE(),"",COUNTIF($J$6:$J14,TRUE())) | L14: =IF($K14="","","R"&$K14) | M14: =IF($J14=FALSE(),"",IF(발주접수!$F3="세트",IFERROR(INDEX(세트구성!$C$3:$C$302,MATCH(발주접수!$D3&"|"&9,세트구성!$G$3:$G$302,0)),""),발주접수!$D3)) | N14: =IF($J14=FALSE(),"",IF(발주접수!$F3="세트",발주접수!$G3*IFERROR(INDEX(세트구성!$E$3:$E$302,MATCH(발주접수!$D3&"|"&9,세트구성!$G$3:$G$302,0)),0),발주접수!$G3)) | O14: =IF($J14=FALSE(),"",발주접수!$B3) | P14: =IF($J14=FALSE(),"",발주접수!$C3) | Q14: =IF($J14=FALSE(),"",IF(발주접수!$F3="세트",발주접수!$E3&" 전개","직접 발주"))
A15: =IF($D15="","",10) | B15: =IFERROR(INDEX(전개결과!$O$6:$O$1205,MATCH("R"&10,전개결과!$L$6:$L$1205,0)),"") | C15: =IF($D15="","",IFERROR(INDEX(전개결과!$P$6:$P$1205,MATCH("R"&10,전개결과!$L$6:$L$1205,0)),"")) | D15: =IFERROR(INDEX(전개결과!$M$6:$M$1205,MATCH("R"&10,전개결과!$L$6:$L$1205,0)),"") | E15: =IF($D15="","",IFERROR(INDEX(품목목록!$B$3:$B$302,MATCH($D15,품목목록!$A$3:$A$302,0)),"")) | F15: =IF($D15="","",IFERROR(INDEX(품목목록!$D$3:$D$302,MATCH($D15,품목목록!$A$3:$A$302,0)),"")) | G15: =IFERROR(INDEX(전개결과!$N$6:$N$1205,MATCH("R"&10,전개결과!$L$6:$L$1205,0)),"") | H15: =IF($D15="","",IFERROR(INDEX(전개결과!$Q$6:$Q$1205,MATCH("R"&10,전개결과!$L$6:$L$1205,0)),"")) | J15: =IF(발주접수!$D3="",FALSE(),IF(발주접수!$F3="세트",COUNTIF(세트구성!$G$3:$G$302,발주접수!$D3&"|"&10)>0,9=0)) -> FALSE | K15: =IF($J15=FALSE(),"",COUNTIF($J$6:$J15,TRUE())) | L15: =IF($K15="","","R"&$K15) | M15: =IF($J15=FALSE(),"",IF(발주접수!$F3="세트",IFERROR(INDEX(세트구성!$C$3:$C$302,MATCH(발주접수!$D3&"|"&10,세트구성!$G$3:$G$302,0)),""),발주접수!$D3)) | N15: =IF($J15=FALSE(),"",IF(발주접수!$F3="세트",발주접수!$G3*IFERROR(INDEX(세트구성!$E$3:$E$302,MATCH(발주접수!$D3&"|"&10,세트구성!$G$3:$G$302,0)),0),발주접수!$G3)) | O15: =IF($J15=FALSE(),"",발주접수!$B3) | P15: =IF($J15=FALSE(),"",발주접수!$C3) | Q15: =IF($J15=FALSE(),"",IF(발주접수!$F3="세트",발주접수!$E3&" 전개","직접 발주"))
A16: =IF($D16="","",11) | B16: =IFERROR(INDEX(전개결과!$O$6:$O$1205,MATCH("R"&11,전개결과!$L$6:$L$1205,0)),"") | C16: =IF($D16="","",IFERROR(INDEX(전개결과!$P$6:$P$1205,MATCH("R"&11,전개결과!$L$6:$L$1205,0)),"")) | D16: =IFERROR(INDEX(전개결과!$M$6:$M$1205,MATCH("R"&11,전개결과!$L$6:$L$1205,0)),"") | E16: =IF($D16="","",IFERROR(INDEX(품목목록!$B$3:$B$302,MATCH($D16,품목목록!$A$3:$A$302,0)),"")) | F16: =IF($D16="","",IFERROR(INDEX(품목목록!$D$3:$D$302,MATCH($D16,품목목록!$A$3:$A$302,0)),"")) | G16: =IFERROR(INDEX(전개결과!$N$6:$N$1205,MATCH("R"&11,전개결과!$L$6:$L$1205,0)),"") | H16: =IF($D16="","",IFERROR(INDEX(전개결과!$Q$6:$Q$1205,MATCH("R"&11,전개결과!$L$6:$L$1205,0)),"")) | J16: =IF(발주접수!$D4="",FALSE(),IF(발주접수!$F4="세트",COUNTIF(세트구성!$G$3:$G$302,발주접수!$D4&"|"&1)>0,0=0)) -> TRUE | K16: =IF($J16=FALSE(),"",COUNTIF($J$6:$J16,TRUE())) -> 4 | L16: =IF($K16="","","R"&$K16) -> R4 | M16: =IF($J16=FALSE(),"",IF(발주접수!$F4="세트",IFERROR(INDEX(세트구성!$C$3:$C$302,MATCH(발주접수!$D4&"|"&1,세트구성!$G$3:$G$302,0)),""),발주접수!$D4)) -> P001 | N16: =IF($J16=FALSE(),"",IF(발주접수!$F4="세트",발주접수!$G4*IFERROR(INDEX(세트구성!$E$3:$E$302,MATCH(발주접수!$D4&"|"&1,세트구성!$G$3:$G$302,0)),0),발주접수!$G4)) -> 10 | O16: =IF($J16=FALSE(),"",발주접수!$B4) -> 46275 | P16: =IF($J16=FALSE(),"",발주접수!$C4) -> ○○마트 | Q16: =IF($J16=FALSE(),"",IF(발주접수!$F4="세트",발주접수!$E4&" 전개","직접 발주")) -> 직접 발주
A17: =IF($D17="","",12) | B17: =IFERROR(INDEX(전개결과!$O$6:$O$1205,MATCH("R"&12,전개결과!$L$6:$L$1205,0)),"") | C17: =IF($D17="","",IFERROR(INDEX(전개결과!$P$6:$P$1205,MATCH("R"&12,전개결과!$L$6:$L$1205,0)),"")) | D17: =IFERROR(INDEX(전개결과!$M$6:$M$1205,MATCH("R"&12,전개결과!$L$6:$L$1205,0)),"") | E17: =IF($D17="","",IFERROR(INDEX(품목목록!$B$3:$B$302,MATCH($D17,품목목록!$A$3:$A$302,0)),"")) | F17: =IF($D17="","",IFERROR(INDEX(품목목록!$D$3:$D$302,MATCH($D17,품목목록!$A$3:$A$302,0)),"")) | G17: =IFERROR(INDEX(전개결과!$N$6:$N$1205,MATCH("R"&12,전개결과!$L$6:$L$1205,0)),"") | H17: =IF($D17="","",IFERROR(INDEX(전개결과!$Q$6:$Q$1205,MATCH("R"&12,전개결과!$L$6:$L$1205,0)),"")) | J17: =IF(발주접수!$D4="",FALSE(),IF(발주접수!$F4="세트",COUNTIF(세트구성!$G$3:$G$302,발주접수!$D4&"|"&2)>0,1=0)) -> FALSE | K17: =IF($J17=FALSE(),"",COUNTIF($J$6:$J17,TRUE())) | L17: =IF($K17="","","R"&$K17) | M17: =IF($J17=FALSE(),"",IF(발주접수!$F4="세트",IFERROR(INDEX(세트구성!$C$3:$C$302,MATCH(발주접수!$D4&"|"&2,세트구성!$G$3:$G$302,0)),""),발주접수!$D4)) | N17: =IF($J17=FALSE(),"",IF(발주접수!$F4="세트",발주접수!$G4*IFERROR(INDEX(세트구성!$E$3:$E$302,MATCH(발주접수!$D4&"|"&2,세트구성!$G$3:$G$302,0)),0),발주접수!$G4)) | O17: =IF($J17=FALSE(),"",발주접수!$B4) | P17: =IF($J17=FALSE(),"",발주접수!$C4) | Q17: =IF($J17=FALSE(),"",IF(발주접수!$F4="세트",발주접수!$E4&" 전개","직접 발주"))
A18: =IF($D18="","",13) | B18: =IFERROR(INDEX(전개결과!$O$6:$O$1205,MATCH("R"&13,전개결과!$L$6:$L$1205,0)),"") | C18: =IF($D18="","",IFERROR(INDEX(전개결과!$P$6:$P$1205,MATCH("R"&13,전개결과!$L$6:$L$1205,0)),"")) | D18: =IFERROR(INDEX(전개결과!$M$6:$M$1205,MATCH("R"&13,전개결과!$L$6:$L$1205,0)),"") | E18: =IF($D18="","",IFERROR(INDEX(품목목록!$B$3:$B$302,MATCH($D18,품목목록!$A$3:$A$302,0)),"")) | F18: =IF($D18="","",IFERROR(INDEX(품목목록!$D$3:$D$302,MATCH($D18,품목목록!$A$3:$A$302,0)),"")) | G18: =IFERROR(INDEX(전개결과!$N$6:$N$1205,MATCH("R"&13,전개결과!$L$6:$L$1205,0)),"") | H18: =IF($D18="","",IFERROR(INDEX(전개결과!$Q$6:$Q$1205,MATCH("R"&13,전개결과!$L$6:$L$1205,0)),"")) | J18: =IF(발주접수!$D4="",FALSE(),IF(발주접수!$F4="세트",COUNTIF(세트구성!$G$3:$G$302,발주접수!$D4&"|"&3)>0,2=0)) -> FALSE | K18: =IF($J18=FALSE(),"",COUNTIF($J$6:$J18,TRUE())) | L18: =IF($K18="","","R"&$K18) | M18: =IF($J18=FALSE(),"",IF(발주접수!$F4="세트",IFERROR(INDEX(세트구성!$C$3:$C$302,MATCH(발주접수!$D4&"|"&3,세트구성!$G$3:$G$302,0)),""),발주접수!$D4)) | N18: =IF($J18=FALSE(),"",IF(발주접수!$F4="세트",발주접수!$G4*IFERROR(INDEX(세트구성!$E$3:$E$302,MATCH(발주접수!$D4&"|"&3,세트구성!$G$3:$G$302,0)),0),발주접수!$G4)) | O18: =IF($J18=FALSE(),"",발주접수!$B4) | P18: =IF($J18=FALSE(),"",발주접수!$C4) | Q18: =IF($J18=FALSE(),"",IF(발주접수!$F4="세트",발주접수!$E4&" 전개","직접 발주"))
A19: =IF($D19="","",14) | B19: =IFERROR(INDEX(전개결과!$O$6:$O$1205,MATCH("R"&14,전개결과!$L$6:$L$1205,0)),"") | C19: =IF($D19="","",IFERROR(INDEX(전개결과!$P$6:$P$1205,MATCH("R"&14,전개결과!$L$6:$L$1205,0)),"")) | D19: =IFERROR(INDEX(전개결과!$M$6:$M$1205,MATCH("R"&14,전개결과!$L$6:$L$1205,0)),"") | E19: =IF($D19="","",IFERROR(INDEX(품목목록!$B$3:$B$302,MATCH($D19,품목목록!$A$3:$A$302,0)),"")) | F19: =IF($D19="","",IFERROR(INDEX(품목목록!$D$3:$D$302,MATCH($D19,품목목록!$A$3:$A$302,0)),"")) | G19: =IFERROR(INDEX(전개결과!$N$6:$N$1205,MATCH("R"&14,전개결과!$L$6:$L$1205,0)),"") | H19: =IF($D19="","",IFERROR(INDEX(전개결과!$Q$6:$Q$1205,MATCH("R"&14,전개결과!$L$6:$L$1205,0)),"")) | J19: =IF(발주접수!$D4="",FALSE(),IF(발주접수!$F4="세트",COUNTIF(세트구성!$G$3:$G$302,발주접수!$D4&"|"&4)>0,3=0)) -> FALSE | K19: =IF($J19=FALSE(),"",COUNTIF($J$6:$J19,TRUE())) | L19: =IF($K19="","","R"&$K19) | M19: =IF($J19=FALSE(),"",IF(발주접수!$F4="세트",IFERROR(INDEX(세트구성!$C$3:$C$302,MATCH(발주접수!$D4&"|"&4,세트구성!$G$3:$G$302,0)),""),발주접수!$D4)) | N19: =IF($J19=FALSE(),"",IF(발주접수!$F4="세트",발주접수!$G4*IFERROR(INDEX(세트구성!$E$3:$E$302,MATCH(발주접수!$D4&"|"&4,세트구성!$G$3:$G$302,0)),0),발주접수!$G4)) | O19: =IF($J19=FALSE(),"",발주접수!$B4) | P19: =IF($J19=FALSE(),"",발주접수!$C4) | Q19: =IF($J19=FALSE(),"",IF(발주접수!$F4="세트",발주접수!$E4&" 전개","직접 발주"))
A20: =IF($D20="","",15) | B20: =IFERROR(INDEX(전개결과!$O$6:$O$1205,MATCH("R"&15,전개결과!$L$6:$L$1205,0)),"") | C20: =IF($D20="","",IFERROR(INDEX(전개결과!$P$6:$P$1205,MATCH("R"&15,전개결과!$L$6:$L$1205,0)),"")) | D20: =IFERROR(INDEX(전개결과!$M$6:$M$1205,MATCH("R"&15,전개결과!$L$6:$L$1205,0)),"") | E20: =IF($D20="","",IFERROR(INDEX(품목목록!$B$3:$B$302,MATCH($D20,품목목록!$A$3:$A$302,0)),"")) | F20: =IF($D20="","",IFERROR(INDEX(품목목록!$D$3:$D$302,MATCH($D20,품목목록!$A$3:$A$302,0)),"")) | G20: =IFERROR(INDEX(전개결과!$N$6:$N$1205,MATCH("R"&15,전개결과!$L$6:$L$1205,0)),"") | H20: =IF($D20="","",IFERROR(INDEX(전개결과!$Q$6:$Q$1205,MATCH("R"&15,전개결과!$L$6:$L$1205,0)),"")) | J20: =IF(발주접수!$D4="",FALSE(),IF(발주접수!$F4="세트",COUNTIF(세트구성!$G$3:$G$302,발주접수!$D4&"|"&5)>0,4=0)) -> FALSE | K20: =IF($J20=FALSE(),"",COUNTIF($J$6:$J20,TRUE())) | L20: =IF($K20="","","R"&$K20) | M20: =IF($J20=FALSE(),"",IF(발주접수!$F4="세트",IFERROR(INDEX(세트구성!$C$3:$C$302,MATCH(발주접수!$D4&"|"&5,세트구성!$G$3:$G$302,0)),""),발주접수!$D4)) | N20: =IF($J20=FALSE(),"",IF(발주접수!$F4="세트",발주접수!$G4*IFERROR(INDEX(세트구성!$E$3:$E$302,MATCH(발주접수!$D4&"|"&5,세트구성!$G$3:$G$302,0)),0),발주접수!$G4)) | O20: =IF($J20=FALSE(),"",발주접수!$B4) | P20: =IF($J20=FALSE(),"",발주접수!$C4) | Q20: =IF($J20=FALSE(),"",IF(발주접수!$F4="세트",발주접수!$E4&" 전개","직접 발주"))
A21: =IF($D21="","",16) | B21: =IFERROR(INDEX(전개결과!$O$6:$O$1205,MATCH("R"&16,전개결과!$L$6:$L$1205,0)),"") | C21: =IF($D21="","",IFERROR(INDEX(전개결과!$P$6:$P$1205,MATCH("R"&16,전개결과!$L$6:$L$1205,0)),"")) | D21: =IFERROR(INDEX(전개결과!$M$6:$M$1205,MATCH("R"&16,전개결과!$L$6:$L$1205,0)),"") | E21: =IF($D21="","",IFERROR(INDEX(품목목록!$B$3:$B$302,MATCH($D21,품목목록!$A$3:$A$302,0)),"")) | F21: =IF($D21="","",IFERROR(INDEX(품목목록!$D$3:$D$302,MATCH($D21,품목목록!$A$3:$A$302,0)),"")) | G21: =IFERROR(INDEX(전개결과!$N$6:$N$1205,MATCH("R"&16,전개결과!$L$6:$L$1205,0)),"") | H21: =IF($D21="","",IFERROR(INDEX(전개결과!$Q$6:$Q$1205,MATCH("R"&16,전개결과!$L$6:$L$1205,0)),"")) | J21: =IF(발주접수!$D4="",FALSE(),IF(발주접수!$F4="세트",COUNTIF(세트구성!$G$3:$G$302,발주접수!$D4&"|"&6)>0,5=0)) -> FALSE | K21: =IF($J21=FALSE(),"",COUNTIF($J$6:$J21,TRUE())) | L21: =IF($K21="","","R"&$K21) | M21: =IF($J21=FALSE(),"",IF(발주접수!$F4="세트",IFERROR(INDEX(세트구성!$C$3:$C$302,MATCH(발주접수!$D4&"|"&6,세트구성!$G$3:$G$302,0)),""),발주접수!$D4)) | N21: =IF($J21=FALSE(),"",IF(발주접수!$F4="세트",발주접수!$G4*IFERROR(INDEX(세트구성!$E$3:$E$302,MATCH(발주접수!$D4&"|"&6,세트구성!$G$3:$G$302,0)),0),발주접수!$G4)) | O21: =IF($J21=FALSE(),"",발주접수!$B4) | P21: =IF($J21=FALSE(),"",발주접수!$C4) | Q21: =IF($J21=FALSE(),"",IF(발주접수!$F4="세트",발주접수!$E4&" 전개","직접 발주"))
A22: =IF($D22="","",17) | B22: =IFERROR(INDEX(전개결과!$O$6:$O$1205,MATCH("R"&17,전개결과!$L$6:$L$1205,0)),"") | C22: =IF($D22="","",IFERROR(INDEX(전개결과!$P$6:$P$1205,MATCH("R"&17,전개결과!$L$6:$L$1205,0)),"")) | D22: =IFERROR(INDEX(전개결과!$M$6:$M$1205,MATCH("R"&17,전개결과!$L$6:$L$1205,0)),"") | E22: =IF($D22="","",IFERROR(INDEX(품목목록!$B$3:$B$302,MATCH($D22,품목목록!$A$3:$A$302,0)),"")) | F22: =IF($D22="","",IFERROR(INDEX(품목목록!$D$3:$D$302,MATCH($D22,품목목록!$A$3:$A$302,0)),"")) | G22: =IFERROR(INDEX(전개결과!$N$6:$N$1205,MATCH("R"&17,전개결과!$L$6:$L$1205,0)),"") | H22: =IF($D22="","",IFERROR(INDEX(전개결과!$Q$6:$Q$1205,MATCH("R"&17,전개결과!$L$6:$L$1205,0)),"")) | J22: =IF(발주접수!$D4="",FALSE(),IF(발주접수!$F4="세트",COUNTIF(세트구성!$G$3:$G$302,발주접수!$D4&"|"&7)>0,6=0)) -> FALSE | K22: =IF($J22=FALSE(),"",COUNTIF($J$6:$J22,TRUE())) | L22: =IF($K22="","","R"&$K22) | M22: =IF($J22=FALSE(),"",IF(발주접수!$F4="세트",IFERROR(INDEX(세트구성!$C$3:$C$302,MATCH(발주접수!$D4&"|"&7,세트구성!$G$3:$G$302,0)),""),발주접수!$D4)) | N22: =IF($J22=FALSE(),"",IF(발주접수!$F4="세트",발주접수!$G4*IFERROR(INDEX(세트구성!$E$3:$E$302,MATCH(발주접수!$D4&"|"&7,세트구성!$G$3:$G$302,0)),0),발주접수!$G4)) | O22: =IF($J22=FALSE(),"",발주접수!$B4) | P22: =IF($J22=FALSE(),"",발주접수!$C4) | Q22: =IF($J22=FALSE(),"",IF(발주접수!$F4="세트",발주접수!$E4&" 전개","직접 발주"))
A23: =IF($D23="","",18) | B23: =IFERROR(INDEX(전개결과!$O$6:$O$1205,MATCH("R"&18,전개결과!$L$6:$L$1205,0)),"") | C23: =IF($D23="","",IFERROR(INDEX(전개결과!$P$6:$P$1205,MATCH("R"&18,전개결과!$L$6:$L$1205,0)),"")) | D23: =IFERROR(INDEX(전개결과!$M$6:$M$1205,MATCH("R"&18,전개결과!$L$6:$L$1205,0)),"") | E23: =IF($D23="","",IFERROR(INDEX(품목목록!$B$3:$B$302,MATCH($D23,품목목록!$A$3:$A$302,0)),"")) | F23: =IF($D23="","",IFERROR(INDEX(품목목록!$D$3:$D$302,MATCH($D23,품목목록!$A$3:$A$302,0)),"")) | G23: =IFERROR(INDEX(전개결과!$N$6:$N$1205,MATCH("R"&18,전개결과!$L$6:$L$1205,0)),"") | H23: =IF($D23="","",IFERROR(INDEX(전개결과!$Q$6:$Q$1205,MATCH("R"&18,전개결과!$L$6:$L$1205,0)),"")) | J23: =IF(발주접수!$D4="",FALSE(),IF(발주접수!$F4="세트",COUNTIF(세트구성!$G$3:$G$302,발주접수!$D4&"|"&8)>0,7=0)) -> FALSE | K23: =IF($J23=FALSE(),"",COUNTIF($J$6:$J23,TRUE())) | L23: =IF($K23="","","R"&$K23) | M23: =IF($J23=FALSE(),"",IF(발주접수!$F4="세트",IFERROR(INDEX(세트구성!$C$3:$C$302,MATCH(발주접수!$D4&"|"&8,세트구성!$G$3:$G$302,0)),""),발주접수!$D4)) | N23: =IF($J23=FALSE(),"",IF(발주접수!$F4="세트",발주접수!$G4*IFERROR(INDEX(세트구성!$E$3:$E$302,MATCH(발주접수!$D4&"|"&8,세트구성!$G$3:$G$302,0)),0),발주접수!$G4)) | O23: =IF($J23=FALSE(),"",발주접수!$B4) | P23: =IF($J23=FALSE(),"",발주접수!$C4) | Q23: =IF($J23=FALSE(),"",IF(발주접수!$F4="세트",발주접수!$E4&" 전개","직접 발주"))
A24: =IF($D24="","",19) | B24: =IFERROR(INDEX(전개결과!$O$6:$O$1205,MATCH("R"&19,전개결과!$L$6:$L$1205,0)),"") | C24: =IF($D24="","",IFERROR(INDEX(전개결과!$P$6:$P$1205,MATCH("R"&19,전개결과!$L$6:$L$1205,0)),"")) | D24: =IFERROR(INDEX(전개결과!$M$6:$M$1205,MATCH("R"&19,전개결과!$L$6:$L$1205,0)),"") | E24: =IF($D24="","",IFERROR(INDEX(품목목록!$B$3:$B$302,MATCH($D24,품목목록!$A$3:$A$302,0)),"")) | F24: =IF($D24="","",IFERROR(INDEX(품목목록!$D$3:$D$302,MATCH($D24,품목목록!$A$3:$A$302,0)),"")) | G24: =IFERROR(INDEX(전개결과!$N$6:$N$1205,MATCH("R"&19,전개결과!$L$6:$L$1205,0)),"") | H24: =IF($D24="","",IFERROR(INDEX(전개결과!$Q$6:$Q$1205,MATCH("R"&19,전개결과!$L$6:$L$1205,0)),"")) | J24: =IF(발주접수!$D4="",FALSE(),IF(발주접수!$F4="세트",COUNTIF(세트구성!$G$3:$G$302,발주접수!$D4&"|"&9)>0,8=0)) -> FALSE | K24: =IF($J24=FALSE(),"",COUNTIF($J$6:$J24,TRUE())) | L24: =IF($K24="","","R"&$K24) | M24: =IF($J24=FALSE(),"",IF(발주접수!$F4="세트",IFERROR(INDEX(세트구성!$C$3:$C$302,MATCH(발주접수!$D4&"|"&9,세트구성!$G$3:$G$302,0)),""),발주접수!$D4)) | N24: =IF($J24=FALSE(),"",IF(발주접수!$F4="세트",발주접수!$G4*IFERROR(INDEX(세트구성!$E$3:$E$302,MATCH(발주접수!$D4&"|"&9,세트구성!$G$3:$G$302,0)),0),발주접수!$G4)) | O24: =IF($J24=FALSE(),"",발주접수!$B4) | P24: =IF($J24=FALSE(),"",발주접수!$C4) | Q24: =IF($J24=FALSE(),"",IF(발주접수!$F4="세트",발주접수!$E4&" 전개","직접 발주"))
A25: =IF($D25="","",20) | B25: =IFERROR(INDEX(전개결과!$O$6:$O$1205,MATCH("R"&20,전개결과!$L$6:$L$1205,0)),"") | C25: =IF($D25="","",IFERROR(INDEX(전개결과!$P$6:$P$1205,MATCH("R"&20,전개결과!$L$6:$L$1205,0)),"")) | D25: =IFERROR(INDEX(전개결과!$M$6:$M$1205,MATCH("R"&20,전개결과!$L$6:$L$1205,0)),"") | E25: =IF($D25="","",IFERROR(INDEX(품목목록!$B$3:$B$302,MATCH($D25,품목목록!$A$3:$A$302,0)),"")) | F25: =IF($D25="","",IFERROR(INDEX(품목목록!$D$3:$D$302,MATCH($D25,품목목록!$A$3:$A$302,0)),"")) | G25: =IFERROR(INDEX(전개결과!$N$6:$N$1205,MATCH("R"&20,전개결과!$L$6:$L$1205,0)),"") | H25: =IF($D25="","",IFERROR(INDEX(전개결과!$Q$6:$Q$1205,MATCH("R"&20,전개결과!$L$6:$L$1205,0)),"")) | J25: =IF(발주접수!$D4="",FALSE(),IF(발주접수!$F4="세트",COUNTIF(세트구성!$G$3:$G$302,발주접수!$D4&"|"&10)>0,9=0)) -> FALSE | K25: =IF($J25=FALSE(),"",COUNTIF($J$6:$J25,TRUE())) | L25: =IF($K25="","","R"&$K25) | M25: =IF($J25=FALSE(),"",IF(발주접수!$F4="세트",IFERROR(INDEX(세트구성!$C$3:$C$302,MATCH(발주접수!$D4&"|"&10,세트구성!$G$3:$G$302,0)),""),발주접수!$D4)) | N25: =IF($J25=FALSE(),"",IF(발주접수!$F4="세트",발주접수!$G4*IFERROR(INDEX(세트구성!$E$3:$E$302,MATCH(발주접수!$D4&"|"&10,세트구성!$G$3:$G$302,0)),0),발주접수!$G4)) | O25: =IF($J25=FALSE(),"",발주접수!$B4) | P25: =IF($J25=FALSE(),"",발주접수!$C4) | Q25: =IF($J25=FALSE(),"",IF(발주접수!$F4="세트",발주접수!$E4&" 전개","직접 발주"))
A26: =IF($D26="","",21) | B26: =IFERROR(INDEX(전개결과!$O$6:$O$1205,MATCH("R"&21,전개결과!$L$6:$L$1205,0)),"") | C26: =IF($D26="","",IFERROR(INDEX(전개결과!$P$6:$P$1205,MATCH("R"&21,전개결과!$L$6:$L$1205,0)),"")) | D26: =IFERROR(INDEX(전개결과!$M$6:$M$1205,MATCH("R"&21,전개결과!$L$6:$L$1205,0)),"") | E26: =IF($D26="","",IFERROR(INDEX(품목목록!$B$3:$B$302,MATCH($D26,품목목록!$A$3:$A$302,0)),"")) | F26: =IF($D26="","",IFERROR(INDEX(품목목록!$D$3:$D$302,MATCH($D26,품목목록!$A$3:$A$302,0)),"")) | G26: =IFERROR(INDEX(전개결과!$N$6:$N$1205,MATCH("R"&21,전개결과!$L$6:$L$1205,0)),"") | H26: =IF($D26="","",IFERROR(INDEX(전개결과!$Q$6:$Q$1205,MATCH("R"&21,전개결과!$L$6:$L$1205,0)),"")) | J26: =IF(발주접수!$D5="",FALSE(),IF(발주접수!$F5="세트",COUNTIF(세트구성!$G$3:$G$302,발주접수!$D5&"|"&1)>0,0=0)) -> TRUE | K26: =IF($J26=FALSE(),"",COUNTIF($J$6:$J26,TRUE())) -> 5 | L26: =IF($K26="","","R"&$K26) -> R5 | M26: =IF($J26=FALSE(),"",IF(발주접수!$F5="세트",IFERROR(INDEX(세트구성!$C$3:$C$302,MATCH(발주접수!$D5&"|"&1,세트구성!$G$3:$G$302,0)),""),발주접수!$D5)) -> P001 | N26: =IF($J26=FALSE(),"",IF(발주접수!$F5="세트",발주접수!$G5*IFERROR(INDEX(세트구성!$E$3:$E$302,MATCH(발주접수!$D5&"|"&1,세트구성!$G$3:$G$302,0)),0),발주접수!$G5)) -> 15 | O26: =IF($J26=FALSE(),"",발주접수!$B5) -> 46276 | P26: =IF($J26=FALSE(),"",발주접수!$C5) -> △△백화점 | Q26: =IF($J26=FALSE(),"",IF(발주접수!$F5="세트",발주접수!$E5&" 전개","직접 발주")) -> 선물세트 B 전개
A27: =IF($D27="","",22) | B27: =IFERROR(INDEX(전개결과!$O$6:$O$1205,MATCH("R"&22,전개결과!$L$6:$L$1205,0)),"") | C27: =IF($D27="","",IFERROR(INDEX(전개결과!$P$6:$P$1205,MATCH("R"&22,전개결과!$L$6:$L$1205,0)),"")) | D27: =IFERROR(INDEX(전개결과!$M$6:$M$1205,MATCH("R"&22,전개결과!$L$6:$L$1205,0)),"") | E27: =IF($D27="","",IFERROR(INDEX(품목목록!$B$3:$B$302,MATCH($D27,품목목록!$A$3:$A$302,0)),"")) | F27: =IF($D27="","",IFERROR(INDEX(품목목록!$D$3:$D$302,MATCH($D27,품목목록!$A$3:$A$302,0)),"")) | G27: =IFERROR(INDEX(전개결과!$N$6:$N$1205,MATCH("R"&22,전개결과!$L$6:$L$1205,0)),"") | H27: =IF($D27="","",IFERROR(INDEX(전개결과!$Q$6:$Q$1205,MATCH("R"&22,전개결과!$L$6:$L$1205,0)),"")) | J27: =IF(발주접수!$D5="",FALSE(),IF(발주접수!$F5="세트",COUNTIF(세트구성!$G$3:$G$302,발주접수!$D5&"|"&2)>0,1=0)) -> TRUE | K27: =IF($J27=FALSE(),"",COUNTIF($J$6:$J27,TRUE())) -> 6 | L27: =IF($K27="","","R"&$K27) -> R6 | M27: =IF($J27=FALSE(),"",IF(발주접수!$F5="세트",IFERROR(INDEX(세트구성!$C$3:$C$302,MATCH(발주접수!$D5&"|"&2,세트구성!$G$3:$G$302,0)),""),발주접수!$D5)) -> P002 | N27: =IF($J27=FALSE(),"",IF(발주접수!$F5="세트",발주접수!$G5*IFERROR(INDEX(세트구성!$E$3:$E$302,MATCH(발주접수!$D5&"|"&2,세트구성!$G$3:$G$302,0)),0),발주접수!$G5)) -> 10 | O27: =IF($J27=FALSE(),"",발주접수!$B5) -> 46276 | P27: =IF($J27=FALSE(),"",발주접수!$C5) -> △△백화점 | Q27: =IF($J27=FALSE(),"",IF(발주접수!$F5="세트",발주접수!$E5&" 전개","직접 발주")) -> 선물세트 B 전개
A28: =IF($D28="","",23) | B28: =IFERROR(INDEX(전개결과!$O$6:$O$1205,MATCH("R"&23,전개결과!$L$6:$L$1205,0)),"") | C28: =IF($D28="","",IFERROR(INDEX(전개결과!$P$6:$P$1205,MATCH("R"&23,전개결과!$L$6:$L$1205,0)),"")) | D28: =IFERROR(INDEX(전개결과!$M$6:$M$1205,MATCH("R"&23,전개결과!$L$6:$L$1205,0)),"") | E28: =IF($D28="","",IFERROR(INDEX(품목목록!$B$3:$B$302,MATCH($D28,품목목록!$A$3:$A$302,0)),"")) | F28: =IF($D28="","",IFERROR(INDEX(품목목록!$D$3:$D$302,MATCH($D28,품목목록!$A$3:$A$302,0)),"")) | G28: =IFERROR(INDEX(전개결과!$N$6:$N$1205,MATCH("R"&23,전개결과!$L$6:$L$1205,0)),"") | H28: =IF($D28="","",IFERROR(INDEX(전개결과!$Q$6:$Q$1205,MATCH("R"&23,전개결과!$L$6:$L$1205,0)),"")) | J28: =IF(발주접수!$D5="",FALSE(),IF(발주접수!$F5="세트",COUNTIF(세트구성!$G$3:$G$302,발주접수!$D5&"|"&3)>0,2=0)) -> TRUE | K28: =IF($J28=FALSE(),"",COUNTIF($J$6:$J28,TRUE())) -> 7 | L28: =IF($K28="","","R"&$K28) -> R7 | M28: =IF($J28=FALSE(),"",IF(발주접수!$F5="세트",IFERROR(INDEX(세트구성!$C$3:$C$302,MATCH(발주접수!$D5&"|"&3,세트구성!$G$3:$G$302,0)),""),발주접수!$D5)) -> P003 | N28: =IF($J28=FALSE(),"",IF(발주접수!$F5="세트",발주접수!$G5*IFERROR(INDEX(세트구성!$E$3:$E$302,MATCH(발주접수!$D5&"|"&3,세트구성!$G$3:$G$302,0)),0),발주접수!$G5)) -> 5 | O28: =IF($J28=FALSE(),"",발주접수!$B5) -> 46276 | P28: =IF($J28=FALSE(),"",발주접수!$C5) -> △△백화점 | Q28: =IF($J28=FALSE(),"",IF(발주접수!$F5="세트",발주접수!$E5&" 전개","직접 발주")) -> 선물세트 B 전개
A29: =IF($D29="","",24) | B29: =IFERROR(INDEX(전개결과!$O$6:$O$1205,MATCH("R"&24,전개결과!$L$6:$L$1205,0)),"") | C29: =IF($D29="","",IFERROR(INDEX(전개결과!$P$6:$P$1205,MATCH("R"&24,전개결과!$L$6:$L$1205,0)),"")) | D29: =IFERROR(INDEX(전개결과!$M$6:$M$1205,MATCH("R"&24,전개결과!$L$6:$L$1205,0)),"") | E29: =IF($D29="","",IFERROR(INDEX(품목목록!$B$3:$B$302,MATCH($D29,품목목록!$A$3:$A$302,0)),"")) | F29: =IF($D29="","",IFERROR(INDEX(품목목록!$D$3:$D$302,MATCH($D29,품목목록!$A$3:$A$302,0)),"")) | G29: =IFERROR(INDEX(전개결과!$N$6:$N$1205,MATCH("R"&24,전개결과!$L$6:$L$1205,0)),"") | H29: =IF($D29="","",IFERROR(INDEX(전개결과!$Q$6:$Q$1205,MATCH("R"&24,전개결과!$L$6:$L$1205,0)),"")) | J29: =IF(발주접수!$D5="",FALSE(),IF(발주접수!$F5="세트",COUNTIF(세트구성!$G$3:$G$302,발주접수!$D5&"|"&4)>0,3=0)) -> FALSE | K29: =IF($J29=FALSE(),"",COUNTIF($J$6:$J29,TRUE())) | L29: =IF($K29="","","R"&$K29) | M29: =IF($J29=FALSE(),"",IF(발주접수!$F5="세트",IFERROR(INDEX(세트구성!$C$3:$C$302,MATCH(발주접수!$D5&"|"&4,세트구성!$G$3:$G$302,0)),""),발주접수!$D5)) | N29: =IF($J29=FALSE(),"",IF(발주접수!$F5="세트",발주접수!$G5*IFERROR(INDEX(세트구성!$E$3:$E$302,MATCH(발주접수!$D5&"|"&4,세트구성!$G$3:$G$302,0)),0),발주접수!$G5)) | O29: =IF($J29=FALSE(),"",발주접수!$B5) | P29: =IF($J29=FALSE(),"",발주접수!$C5) | Q29: =IF($J29=FALSE(),"",IF(발주접수!$F5="세트",발주접수!$E5&" 전개","직접 발주"))
A30: =IF($D30="","",25) | B30: =IFERROR(INDEX(전개결과!$O$6:$O$1205,MATCH("R"&25,전개결과!$L$6:$L$1205,0)),"") | C30: =IF($D30="","",IFERROR(INDEX(전개결과!$P$6:$P$1205,MATCH("R"&25,전개결과!$L$6:$L$1205,0)),"")) | D30: =IFERROR(INDEX(전개결과!$M$6:$M$1205,MATCH("R"&25,전개결과!$L$6:$L$1205,0)),"") | E30: =IF($D30="","",IFERROR(INDEX(품목목록!$B$3:$B$302,MATCH($D30,품목목록!$A$3:$A$302,0)),"")) | F30: =IF($D30="","",IFERROR(INDEX(품목목록!$D$3:$D$302,MATCH($D30,품목목록!$A$3:$A$302,0)),"")) | G30: =IFERROR(INDEX(전개결과!$N$6:$N$1205,MATCH("R"&25,전개결과!$L$6:$L$1205,0)),"") | H30: =IF($D30="","",IFERROR(INDEX(전개결과!$Q$6:$Q$1205,MATCH("R"&25,전개결과!$L$6:$L$1205,0)),"")) | J30: =IF(발주접수!$D5="",FALSE(),IF(발주접수!$F5="세트",COUNTIF(세트구성!$G$3:$G$302,발주접수!$D5&"|"&5)>0,4=0)) -> FALSE | K30: =IF($J30=FALSE(),"",COUNTIF($J$6:$J30,TRUE())) | L30: =IF($K30="","","R"&$K30) | M30: =IF($J30=FALSE(),"",IF(발주접수!$F5="세트",IFERROR(INDEX(세트구성!$C$3:$C$302,MATCH(발주접수!$D5&"|"&5,세트구성!$G$3:$G$302,0)),""),발주접수!$D5)) | N30: =IF($J30=FALSE(),"",IF(발주접수!$F5="세트",발주접수!$G5*IFERROR(INDEX(세트구성!$E$3:$E$302,MATCH(발주접수!$D5&"|"&5,세트구성!$G$3:$G$302,0)),0),발주접수!$G5)) | O30: =IF($J30=FALSE(),"",발주접수!$B5) | P30: =IF($J30=FALSE(),"",발주접수!$C5) | Q30: =IF($J30=FALSE(),"",IF(발주접수!$F5="세트",발주접수!$E5&" 전개","직접 발주"))
A31: =IF($D31="","",26) | B31: =IFERROR(INDEX(전개결과!$O$6:$O$1205,MATCH("R"&26,전개결과!$L$6:$L$1205,0)),"") | C31: =IF($D31="","",IFERROR(INDEX(전개결과!$P$6:$P$1205,MATCH("R"&26,전개결과!$L$6:$L$1205,0)),"")) | D31: =IFERROR(INDEX(전개결과!$M$6:$M$1205,MATCH("R"&26,전개결과!$L$6:$L$1205,0)),"") | E31: =IF($D31="","",IFERROR(INDEX(품목목록!$B$3:$B$302,MATCH($D31,품목목록!$A$3:$A$302,0)),"")) | F31: =IF($D31="","",IFERROR(INDEX(품목목록!$D$3:$D$302,MATCH($D31,품목목록!$A$3:$A$302,0)),"")) | G31: =IFERROR(INDEX(전개결과!$N$6:$N$1205,MATCH("R"&26,전개결과!$L$6:$L$1205,0)),"") | H31: =IF($D31="","",IFERROR(INDEX(전개결과!$Q$6:$Q$1205,MATCH("R"&26,전개결과!$L$6:$L$1205,0)),"")) | J31: =IF(발주접수!$D5="",FALSE(),IF(발주접수!$F5="세트",COUNTIF(세트구성!$G$3:$G$302,발주접수!$D5&"|"&6)>0,5=0)) -> FALSE | K31: =IF($J31=FALSE(),"",COUNTIF($J$6:$J31,TRUE())) | L31: =IF($K31="","","R"&$K31) | M31: =IF($J31=FALSE(),"",IF(발주접수!$F5="세트",IFERROR(INDEX(세트구성!$C$3:$C$302,MATCH(발주접수!$D5&"|"&6,세트구성!$G$3:$G$302,0)),""),발주접수!$D5)) | N31: =IF($J31=FALSE(),"",IF(발주접수!$F5="세트",발주접수!$G5*IFERROR(INDEX(세트구성!$E$3:$E$302,MATCH(발주접수!$D5&"|"&6,세트구성!$G$3:$G$302,0)),0),발주접수!$G5)) | O31: =IF($J31=FALSE(),"",발주접수!$B5) | P31: =IF($J31=FALSE(),"",발주접수!$C5) | Q31: =IF($J31=FALSE(),"",IF(발주접수!$F5="세트",발주접수!$E5&" 전개","직접 발주"))
A32: =IF($D32="","",27) | B32: =IFERROR(INDEX(전개결과!$O$6:$O$1205,MATCH("R"&27,전개결과!$L$6:$L$1205,0)),"") | C32: =IF($D32="","",IFERROR(INDEX(전개결과!$P$6:$P$1205,MATCH("R"&27,전개결과!$L$6:$L$1205,0)),"")) | D32: =IFERROR(INDEX(전개결과!$M$6:$M$1205,MATCH("R"&27,전개결과!$L$6:$L$1205,0)),"") | E32: =IF($D32="","",IFERROR(INDEX(품목목록!$B$3:$B$302,MATCH($D32,품목목록!$A$3:$A$302,0)),"")) | F32: =IF($D32="","",IFERROR(INDEX(품목목록!$D$3:$D$302,MATCH($D32,품목목록!$A$3:$A$302,0)),"")) | G32: =IFERROR(INDEX(전개결과!$N$6:$N$1205,MATCH("R"&27,전개결과!$L$6:$L$1205,0)),"") | H32: =IF($D32="","",IFERROR(INDEX(전개결과!$Q$6:$Q$1205,MATCH("R"&27,전개결과!$L$6:$L$1205,0)),"")) | J32: =IF(발주접수!$D5="",FALSE(),IF(발주접수!$F5="세트",COUNTIF(세트구성!$G$3:$G$302,발주접수!$D5&"|"&7)>0,6=0)) -> FALSE | K32: =IF($J32=FALSE(),"",COUNTIF($J$6:$J32,TRUE())) | L32: =IF($K32="","","R"&$K32) | M32: =IF($J32=FALSE(),"",IF(발주접수!$F5="세트",IFERROR(INDEX(세트구성!$C$3:$C$302,MATCH(발주접수!$D5&"|"&7,세트구성!$G$3:$G$302,0)),""),발주접수!$D5)) | N32: =IF($J32=FALSE(),"",IF(발주접수!$F5="세트",발주접수!$G5*IFERROR(INDEX(세트구성!$E$3:$E$302,MATCH(발주접수!$D5&"|"&7,세트구성!$G$3:$G$302,0)),0),발주접수!$G5)) | O32: =IF($J32=FALSE(),"",발주접수!$B5) | P32: =IF($J32=FALSE(),"",발주접수!$C5) | Q32: =IF($J32=FALSE(),"",IF(발주접수!$F5="세트",발주접수!$E5&" 전개","직접 발주"))
A33: =IF($D33="","",28) | B33: =IFERROR(INDEX(전개결과!$O$6:$O$1205,MATCH("R"&28,전개결과!$L$6:$L$1205,0)),"") | C33: =IF($D33="","",IFERROR(INDEX(전개결과!$P$6:$P$1205,MATCH("R"&28,전개결과!$L$6:$L$1205,0)),"")) | D33: =IFERROR(INDEX(전개결과!$M$6:$M$1205,MATCH("R"&28,전개결과!$L$6:$L$1205,0)),"") | E33: =IF($D33="","",IFERROR(INDEX(품목목록!$B$3:$B$302,MATCH($D33,품목목록!$A$3:$A$302,0)),"")) | F33: =IF($D33="","",IFERROR(INDEX(품목목록!$D$3:$D$302,MATCH($D33,품목목록!$A$3:$A$302,0)),"")) | G33: =IFERROR(INDEX(전개결과!$N$6:$N$1205,MATCH("R"&28,전개결과!$L$6:$L$1205,0)),"") | H33: =IF($D33="","",IFERROR(INDEX(전개결과!$Q$6:$Q$1205,MATCH("R"&28,전개결과!$L$6:$L$1205,0)),"")) | J33: =IF(발주접수!$D5="",FALSE(),IF(발주접수!$F5="세트",COUNTIF(세트구성!$G$3:$G$302,발주접수!$D5&"|"&8)>0,7=0)) -> FALSE | K33: =IF($J33=FALSE(),"",COUNTIF($J$6:$J33,TRUE())) | L33: =IF($K33="","","R"&$K33) | M33: =IF($J33=FALSE(),"",IF(발주접수!$F5="세트",IFERROR(INDEX(세트구성!$C$3:$C$302,MATCH(발주접수!$D5&"|"&8,세트구성!$G$3:$G$302,0)),""),발주접수!$D5)) | N33: =IF($J33=FALSE(),"",IF(발주접수!$F5="세트",발주접수!$G5*IFERROR(INDEX(세트구성!$E$3:$E$302,MATCH(발주접수!$D5&"|"&8,세트구성!$G$3:$G$302,0)),0),발주접수!$G5)) | O33: =IF($J33=FALSE(),"",발주접수!$B5) | P33: =IF($J33=FALSE(),"",발주접수!$C5) | Q33: =IF($J33=FALSE(),"",IF(발주접수!$F5="세트",발주접수!$E5&" 전개","직접 발주"))
A34: =IF($D34="","",29) | B34: =IFERROR(INDEX(전개결과!$O$6:$O$1205,MATCH("R"&29,전개결과!$L$6:$L$1205,0)),"") | C34: =IF($D34="","",IFERROR(INDEX(전개결과!$P$6:$P$1205,MATCH("R"&29,전개결과!$L$6:$L$1205,0)),"")) | D34: =IFERROR(INDEX(전개결과!$M$6:$M$1205,MATCH("R"&29,전개결과!$L$6:$L$1205,0)),"") | E34: =IF($D34="","",IFERROR(INDEX(품목목록!$B$3:$B$302,MATCH($D34,품목목록!$A$3:$A$302,0)),"")) | F34: =IF($D34="","",IFERROR(INDEX(품목목록!$D$3:$D$302,MATCH($D34,품목목록!$A$3:$A$302,0)),"")) | G34: =IFERROR(INDEX(전개결과!$N$6:$N$1205,MATCH("R"&29,전개결과!$L$6:$L$1205,0)),"") | H34: =IF($D34="","",IFERROR(INDEX(전개결과!$Q$6:$Q$1205,MATCH("R"&29,전개결과!$L$6:$L$1205,0)),"")) | J34: =IF(발주접수!$D5="",FALSE(),IF(발주접수!$F5="세트",COUNTIF(세트구성!$G$3:$G$302,발주접수!$D5&"|"&9)>0,8=0)) -> FALSE | K34: =IF($J34=FALSE(),"",COUNTIF($J$6:$J34,TRUE())) | L34: =IF($K34="","","R"&$K34) | M34: =IF($J34=FALSE(),"",IF(발주접수!$F5="세트",IFERROR(INDEX(세트구성!$C$3:$C$302,MATCH(발주접수!$D5&"|"&9,세트구성!$G$3:$G$302,0)),""),발주접수!$D5)) | N34: =IF($J34=FALSE(),"",IF(발주접수!$F5="세트",발주접수!$G5*IFERROR(INDEX(세트구성!$E$3:$E$302,MATCH(발주접수!$D5&"|"&9,세트구성!$G$3:$G$302,0)),0),발주접수!$G5)) | O34: =IF($J34=FALSE(),"",발주접수!$B5) | P34: =IF($J34=FALSE(),"",발주접수!$C5) | Q34: =IF($J34=FALSE(),"",IF(발주접수!$F5="세트",발주접수!$E5&" 전개","직접 발주"))
A35: =IF($D35="","",30) | B35: =IFERROR(INDEX(전개결과!$O$6:$O$1205,MATCH("R"&30,전개결과!$L$6:$L$1205,0)),"") | C35: =IF($D35="","",IFERROR(INDEX(전개결과!$P$6:$P$1205,MATCH("R"&30,전개결과!$L$6:$L$1205,0)),"")) | D35: =IFERROR(INDEX(전개결과!$M$6:$M$1205,MATCH("R"&30,전개결과!$L$6:$L$1205,0)),"") | E35: =IF($D35="","",IFERROR(INDEX(품목목록!$B$3:$B$302,MATCH($D35,품목목록!$A$3:$A$302,0)),"")) | F35: =IF($D35="","",IFERROR(INDEX(품목목록!$D$3:$D$302,MATCH($D35,품목목록!$A$3:$A$302,0)),"")) | G35: =IFERROR(INDEX(전개결과!$N$6:$N$1205,MATCH("R"&30,전개결과!$L$6:$L$1205,0)),"") | H35: =IF($D35="","",IFERROR(INDEX(전개결과!$Q$6:$Q$1205,MATCH("R"&30,전개결과!$L$6:$L$1205,0)),"")) | J35: =IF(발주접수!$D5="",FALSE(),IF(발주접수!$F5="세트",COUNTIF(세트구성!$G$3:$G$302,발주접수!$D5&"|"&10)>0,9=0)) -> FALSE | K35: =IF($J35=FALSE(),"",COUNTIF($J$6:$J35,TRUE())) | L35: =IF($K35="","","R"&$K35) | M35: =IF($J35=FALSE(),"",IF(발주접수!$F5="세트",IFERROR(INDEX(세트구성!$C$3:$C$302,MATCH(발주접수!$D5&"|"&10,세트구성!$G$3:$G$302,0)),""),발주접수!$D5)) | N35: =IF($J35=FALSE(),"",IF(발주접수!$F5="세트",발주접수!$G5*IFERROR(INDEX(세트구성!$E$3:$E$302,MATCH(발주접수!$D5&"|"&10,세트구성!$G$3:$G$302,0)),0),발주접수!$G5)) | O35: =IF($J35=FALSE(),"",발주접수!$B5) | P35: =IF($J35=FALSE(),"",발주접수!$C5) | Q35: =IF($J35=FALSE(),"",IF(발주접수!$F5="세트",발주접수!$E5&" 전개","직접 발주"))
A36: =IF($D36="","",31) | B36: =IFERROR(INDEX(전개결과!$O$6:$O$1205,MATCH("R"&31,전개결과!$L$6:$L$1205,0)),"") | C36: =IF($D36="","",IFERROR(INDEX(전개결과!$P$6:$P$1205,MATCH("R"&31,전개결과!$L$6:$L$1205,0)),"")) | D36: =IFERROR(INDEX(전개결과!$M$6:$M$1205,MATCH("R"&31,전개결과!$L$6:$L$1205,0)),"") | E36: =IF($D36="","",IFERROR(INDEX(품목목록!$B$3:$B$302,MATCH($D36,품목목록!$A$3:$A$302,0)),"")) | F36: =IF($D36="","",IFERROR(INDEX(품목목록!$D$3:$D$302,MATCH($D36,품목목록!$A$3:$A$302,0)),"")) | G36: =IFERROR(INDEX(전개결과!$N$6:$N$1205,MATCH("R"&31,전개결과!$L$6:$L$1205,0)),"") | H36: =IF($D36="","",IFERROR(INDEX(전개결과!$Q$6:$Q$1205,MATCH("R"&31,전개결과!$L$6:$L$1205,0)),"")) | J36: =IF(발주접수!$D6="",FALSE(),IF(발주접수!$F6="세트",COUNTIF(세트구성!$G$3:$G$302,발주접수!$D6&"|"&1)>0,0=0)) -> FALSE | K36: =IF($J36=FALSE(),"",COUNTIF($J$6:$J36,TRUE())) | L36: =IF($K36="","","R"&$K36) | M36: =IF($J36=FALSE(),"",IF(발주접수!$F6="세트",IFERROR(INDEX(세트구성!$C$3:$C$302,MATCH(발주접수!$D6&"|"&1,세트구성!$G$3:$G$302,0)),""),발주접수!$D6)) | N36: =IF($J36=FALSE(),"",IF(발주접수!$F6="세트",발주접수!$G6*IFERROR(INDEX(세트구성!$E$3:$E$302,MATCH(발주접수!$D6&"|"&1,세트구성!$G$3:$G$302,0)),0),발주접수!$G6)) | O36: =IF($J36=FALSE(),"",발주접수!$B6) | P36: =IF($J36=FALSE(),"",발주접수!$C6) | Q36: =IF($J36=FALSE(),"",IF(발주접수!$F6="세트",발주접수!$E6&" 전개","직접 발주"))
A37: =IF($D37="","",32) | B37: =IFERROR(INDEX(전개결과!$O$6:$O$1205,MATCH("R"&32,전개결과!$L$6:$L$1205,0)),"") | C37: =IF($D37="","",IFERROR(INDEX(전개결과!$P$6:$P$1205,MATCH("R"&32,전개결과!$L$6:$L$1205,0)),"")) | D37: =IFERROR(INDEX(전개결과!$M$6:$M$1205,MATCH("R"&32,전개결과!$L$6:$L$1205,0)),"") | E37: =IF($D37="","",IFERROR(INDEX(품목목록!$B$3:$B$302,MATCH($D37,품목목록!$A$3:$A$302,0)),"")) | F37: =IF($D37="","",IFERROR(INDEX(품목목록!$D$3:$D$302,MATCH($D37,품목목록!$A$3:$A$302,0)),"")) | G37: =IFERROR(INDEX(전개결과!$N$6:$N$1205,MATCH("R"&32,전개결과!$L$6:$L$1205,0)),"") | H37: =IF($D37="","",IFERROR(INDEX(전개결과!$Q$6:$Q$1205,MATCH("R"&32,전개결과!$L$6:$L$1205,0)),"")) | J37: =IF(발주접수!$D6="",FALSE(),IF(발주접수!$F6="세트",COUNTIF(세트구성!$G$3:$G$302,발주접수!$D6&"|"&2)>0,1=0)) -> FALSE | K37: =IF($J37=FALSE(),"",COUNTIF($J$6:$J37,TRUE())) | L37: =IF($K37="","","R"&$K37) | M37: =IF($J37=FALSE(),"",IF(발주접수!$F6="세트",IFERROR(INDEX(세트구성!$C$3:$C$302,MATCH(발주접수!$D6&"|"&2,세트구성!$G$3:$G$302,0)),""),발주접수!$D6)) | N37: =IF($J37=FALSE(),"",IF(발주접수!$F6="세트",발주접수!$G6*IFERROR(INDEX(세트구성!$E$3:$E$302,MATCH(발주접수!$D6&"|"&2,세트구성!$G$3:$G$302,0)),0),발주접수!$G6)) | O37: =IF($J37=FALSE(),"",발주접수!$B6) | P37: =IF($J37=FALSE(),"",발주접수!$C6) | Q37: =IF($J37=FALSE(),"",IF(발주접수!$F6="세트",발주접수!$E6&" 전개","직접 발주"))
A38: =IF($D38="","",33) | B38: =IFERROR(INDEX(전개결과!$O$6:$O$1205,MATCH("R"&33,전개결과!$L$6:$L$1205,0)),"") | C38: =IF($D38="","",IFERROR(INDEX(전개결과!$P$6:$P$1205,MATCH("R"&33,전개결과!$L$6:$L$1205,0)),"")) | D38: =IFERROR(INDEX(전개결과!$M$6:$M$1205,MATCH("R"&33,전개결과!$L$6:$L$1205,0)),"") | E38: =IF($D38="","",IFERROR(INDEX(품목목록!$B$3:$B$302,MATCH($D38,품목목록!$A$3:$A$302,0)),"")) | F38: =IF($D38="","",IFERROR(INDEX(품목목록!$D$3:$D$302,MATCH($D38,품목목록!$A$3:$A$302,0)),"")) | G38: =IFERROR(INDEX(전개결과!$N$6:$N$1205,MATCH("R"&33,전개결과!$L$6:$L$1205,0)),"") | H38: =IF($D38="","",IFERROR(INDEX(전개결과!$Q$6:$Q$1205,MATCH("R"&33,전개결과!$L$6:$L$1205,0)),"")) | J38: =IF(발주접수!$D6="",FALSE(),IF(발주접수!$F6="세트",COUNTIF(세트구성!$G$3:$G$302,발주접수!$D6&"|"&3)>0,2=0)) -> FALSE | K38: =IF($J38=FALSE(),"",COUNTIF($J$6:$J38,TRUE())) | L38: =IF($K38="","","R"&$K38) | M38: =IF($J38=FALSE(),"",IF(발주접수!$F6="세트",IFERROR(INDEX(세트구성!$C$3:$C$302,MATCH(발주접수!$D6&"|"&3,세트구성!$G$3:$G$302,0)),""),발주접수!$D6)) | N38: =IF($J38=FALSE(),"",IF(발주접수!$F6="세트",발주접수!$G6*IFERROR(INDEX(세트구성!$E$3:$E$302,MATCH(발주접수!$D6&"|"&3,세트구성!$G$3:$G$302,0)),0),발주접수!$G6)) | O38: =IF($J38=FALSE(),"",발주접수!$B6) | P38: =IF($J38=FALSE(),"",발주접수!$C6) | Q38: =IF($J38=FALSE(),"",IF(발주접수!$F6="세트",발주접수!$E6&" 전개","직접 발주"))
A39: =IF($D39="","",34) | B39: =IFERROR(INDEX(전개결과!$O$6:$O$1205,MATCH("R"&34,전개결과!$L$6:$L$1205,0)),"") | C39: =IF($D39="","",IFERROR(INDEX(전개결과!$P$6:$P$1205,MATCH("R"&34,전개결과!$L$6:$L$1205,0)),"")) | D39: =IFERROR(INDEX(전개결과!$M$6:$M$1205,MATCH("R"&34,전개결과!$L$6:$L$1205,0)),"") | E39: =IF($D39="","",IFERROR(INDEX(품목목록!$B$3:$B$302,MATCH($D39,품목목록!$A$3:$A$302,0)),"")) | F39: =IF($D39="","",IFERROR(INDEX(품목목록!$D$3:$D$302,MATCH($D39,품목목록!$A$3:$A$302,0)),"")) | G39: =IFERROR(INDEX(전개결과!$N$6:$N$1205,MATCH("R"&34,전개결과!$L$6:$L$1205,0)),"") | H39: =IF($D39="","",IFERROR(INDEX(전개결과!$Q$6:$Q$1205,MATCH("R"&34,전개결과!$L$6:$L$1205,0)),"")) | J39: =IF(발주접수!$D6="",FALSE(),IF(발주접수!$F6="세트",COUNTIF(세트구성!$G$3:$G$302,발주접수!$D6&"|"&4)>0,3=0)) -> FALSE | K39: =IF($J39=FALSE(),"",COUNTIF($J$6:$J39,TRUE())) | L39: =IF($K39="","","R"&$K39) | M39: =IF($J39=FALSE(),"",IF(발주접수!$F6="세트",IFERROR(INDEX(세트구성!$C$3:$C$302,MATCH(발주접수!$D6&"|"&4,세트구성!$G$3:$G$302,0)),""),발주접수!$D6)) | N39: =IF($J39=FALSE(),"",IF(발주접수!$F6="세트",발주접수!$G6*IFERROR(INDEX(세트구성!$E$3:$E$302,MATCH(발주접수!$D6&"|"&4,세트구성!$G$3:$G$302,0)),0),발주접수!$G6)) | O39: =IF($J39=FALSE(),"",발주접수!$B6) | P39: =IF($J39=FALSE(),"",발주접수!$C6) | Q39: =IF($J39=FALSE(),"",IF(발주접수!$F6="세트",발주접수!$E6&" 전개","직접 발주"))
A40: =IF($D40="","",35) | B40: =IFERROR(INDEX(전개결과!$O$6:$O$1205,MATCH("R"&35,전개결과!$L$6:$L$1205,0)),"") | C40: =IF($D40="","",IFERROR(INDEX(전개결과!$P$6:$P$1205,MATCH("R"&35,전개결과!$L$6:$L$1205,0)),"")) | D40: =IFERROR(INDEX(전개결과!$M$6:$M$1205,MATCH("R"&35,전개결과!$L$6:$L$1205,0)),"") | E40: =IF($D40="","",IFERROR(INDEX(품목목록!$B$3:$B$302,MATCH($D40,품목목록!$A$3:$A$302,0)),"")) | F40: =IF($D40="","",IFERROR(INDEX(품목목록!$D$3:$D$302,MATCH($D40,품목목록!$A$3:$A$302,0)),"")) | G40: =IFERROR(INDEX(전개결과!$N$6:$N$1205,MATCH("R"&35,전개결과!$L$6:$L$1205,0)),"") | H40: =IF($D40="","",IFERROR(INDEX(전개결과!$Q$6:$Q$1205,MATCH("R"&35,전개결과!$L$6:$L$1205,0)),"")) | J40: =IF(발주접수!$D6="",FALSE(),IF(발주접수!$F6="세트",COUNTIF(세트구성!$G$3:$G$302,발주접수!$D6&"|"&5)>0,4=0)) -> FALSE | K40: =IF($J40=FALSE(),"",COUNTIF($J$6:$J40,TRUE())) | L40: =IF($K40="","","R"&$K40) | M40: =IF($J40=FALSE(),"",IF(발주접수!$F6="세트",IFERROR(INDEX(세트구성!$C$3:$C$302,MATCH(발주접수!$D6&"|"&5,세트구성!$G$3:$G$302,0)),""),발주접수!$D6)) | N40: =IF($J40=FALSE(),"",IF(발주접수!$F6="세트",발주접수!$G6*IFERROR(INDEX(세트구성!$E$3:$E$302,MATCH(발주접수!$D6&"|"&5,세트구성!$G$3:$G$302,0)),0),발주접수!$G6)) | O40: =IF($J40=FALSE(),"",발주접수!$B6) | P40: =IF($J40=FALSE(),"",발주접수!$C6) | Q40: =IF($J40=FALSE(),"",IF(발주접수!$F6="세트",발주접수!$E6&" 전개","직접 발주"))
A41: =IF($D41="","",36) | B41: =IFERROR(INDEX(전개결과!$O$6:$O$1205,MATCH("R"&36,전개결과!$L$6:$L$1205,0)),"") | C41: =IF($D41="","",IFERROR(INDEX(전개결과!$P$6:$P$1205,MATCH("R"&36,전개결과!$L$6:$L$1205,0)),"")) | D41: =IFERROR(INDEX(전개결과!$M$6:$M$1205,MATCH("R"&36,전개결과!$L$6:$L$1205,0)),"") | E41: =IF($D41="","",IFERROR(INDEX(품목목록!$B$3:$B$302,MATCH($D41,품목목록!$A$3:$A$302,0)),"")) | F41: =IF($D41="","",IFERROR(INDEX(품목목록!$D$3:$D$302,MATCH($D41,품목목록!$A$3:$A$302,0)),"")) | G41: =IFERROR(INDEX(전개결과!$N$6:$N$1205,MATCH("R"&36,전개결과!$L$6:$L$1205,0)),"") | H41: =IF($D41="","",IFERROR(INDEX(전개결과!$Q$6:$Q$1205,MATCH("R"&36,전개결과!$L$6:$L$1205,0)),"")) | J41: =IF(발주접수!$D6="",FALSE(),IF(발주접수!$F6="세트",COUNTIF(세트구성!$G$3:$G$302,발주접수!$D6&"|"&6)>0,5=0)) -> FALSE | K41: =IF($J41=FALSE(),"",COUNTIF($J$6:$J41,TRUE())) | L41: =IF($K41="","","R"&$K41) | M41: =IF($J41=FALSE(),"",IF(발주접수!$F6="세트",IFERROR(INDEX(세트구성!$C$3:$C$302,MATCH(발주접수!$D6&"|"&6,세트구성!$G$3:$G$302,0)),""),발주접수!$D6)) | N41: =IF($J41=FALSE(),"",IF(발주접수!$F6="세트",발주접수!$G6*IFERROR(INDEX(세트구성!$E$3:$E$302,MATCH(발주접수!$D6&"|"&6,세트구성!$G$3:$G$302,0)),0),발주접수!$G6)) | O41: =IF($J41=FALSE(),"",발주접수!$B6) | P41: =IF($J41=FALSE(),"",발주접수!$C6) | Q41: =IF($J41=FALSE(),"",IF(발주접수!$F6="세트",발주접수!$E6&" 전개","직접 발주"))
A42: =IF($D42="","",37) | B42: =IFERROR(INDEX(전개결과!$O$6:$O$1205,MATCH("R"&37,전개결과!$L$6:$L$1205,0)),"") | C42: =IF($D42="","",IFERROR(INDEX(전개결과!$P$6:$P$1205,MATCH("R"&37,전개결과!$L$6:$L$1205,0)),"")) | D42: =IFERROR(INDEX(전개결과!$M$6:$M$1205,MATCH("R"&37,전개결과!$L$6:$L$1205,0)),"") | E42: =IF($D42="","",IFERROR(INDEX(품목목록!$B$3:$B$302,MATCH($D42,품목목록!$A$3:$A$302,0)),"")) | F42: =IF($D42="","",IFERROR(INDEX(품목목록!$D$3:$D$302,MATCH($D42,품목목록!$A$3:$A$302,0)),"")) | G42: =IFERROR(INDEX(전개결과!$N$6:$N$1205,MATCH("R"&37,전개결과!$L$6:$L$1205,0)),"") | H42: =IF($D42="","",IFERROR(INDEX(전개결과!$Q$6:$Q$1205,MATCH("R"&37,전개결과!$L$6:$L$1205,0)),"")) | J42: =IF(발주접수!$D6="",FALSE(),IF(발주접수!$F6="세트",COUNTIF(세트구성!$G$3:$G$302,발주접수!$D6&"|"&7)>0,6=0)) -> FALSE | K42: =IF($J42=FALSE(),"",COUNTIF($J$6:$J42,TRUE())) | L42: =IF($K42="","","R"&$K42) | M42: =IF($J42=FALSE(),"",IF(발주접수!$F6="세트",IFERROR(INDEX(세트구성!$C$3:$C$302,MATCH(발주접수!$D6&"|"&7,세트구성!$G$3:$G$302,0)),""),발주접수!$D6)) | N42: =IF($J42=FALSE(),"",IF(발주접수!$F6="세트",발주접수!$G6*IFERROR(INDEX(세트구성!$E$3:$E$302,MATCH(발주접수!$D6&"|"&7,세트구성!$G$3:$G$302,0)),0),발주접수!$G6)) | O42: =IF($J42=FALSE(),"",발주접수!$B6) | P42: =IF($J42=FALSE(),"",발주접수!$C6) | Q42: =IF($J42=FALSE(),"",IF(발주접수!$F6="세트",발주접수!$E6&" 전개","직접 발주"))
...

Sheet 품목별_소요량
A1: 품목별 소요량 (낱개 기준 총 필요 수량)
A3: 대상 발주일 | B3: 전체 | C3: ※ 전개결과 전체를 합산합니다.
A5: 품번 | B5: 품명 | C5: 규격 | D5: 단위 | E5: 총 소요량 | F5: 단가 기준 금액
A6: =IF(품목목록!$A3="","",IF(품목목록!$F3="세트","",품목목록!$A3)) -> P001 | B6: =IF($A6="","",품목목록!$B3) -> 홍삼즙 30포 | C6: =IF($A6="","",품목목록!$C3) -> 3g×30 | D6: =IF($A6="","",품목목록!$D3) -> 박스 | E6: =IF($A6="","",SUMIFS(전개결과!$N$6:$N$1205,전개결과!$M$6:$M$1205,$A6)) -> 40 | F6: =IF($A6="","",ROUND($E6*IF(품목목록!$E3="",0,품목목록!$E3),0)) -> 1120000
