Workbook

Sheet 사용안내
B2: 원자재 규격 목록 · 검색 · 비교
B4: 핵심 | C4: 원자재명 옆에 규격을 따로 두어, 이름이 같아도 규격이 다르면 구분해서 찾을 수 있습니다.
B5: 입력 규칙 | C5: 파란색 글씨 칸만 입력하세요. 검은색은 자동 계산입니다.
B6: ① 원자재마스터 | C6: 품번·품명·규격·재질과 치수를 등록합니다. 품번은 중복되면 안 됩니다.
C7: 치수를 넣으면 규격 표기가 자동으로 만들어집니다. 예: 1000×500×3.2
B8: ② 규격검색 | C8: 품명 일부나 규격 일부만 넣어도 찾아냅니다. 재질로도 걸러집니다.
B9: ③ 규격비교 | C9: 비슷한 자재 최대 6개를 나란히 놓고 치수를 비교합니다.
B10: ④ 거래처별목록 | C10: 거래처를 고르면 그 거래처에서 사는 자재만 나옵니다.
B11: ⑤ 규격라벨 | C11: 선반이나 자재함에 붙일 라벨을 한 장에 12개 인쇄합니다.
B12: 중복 품번 확인 | C12: 마스터에 같은 품번이 두 번 들어가면 빨간색으로 표시됩니다.
B13: 단위중량 | C13: 길이·폭·두께와 비중을 넣으면 장당 중량이 자동 계산됩니다.
B15: ※ 중량은 (길이×폭×두께×비중)으로 계산한 이론값입니다. 실측값과 다를 수 있습니다.
B16: ※ 재고 수량은 관리하지 않습니다. 재고는 별도 파일(재고관리)에서 관리하세요.

Sheet 원자재마스터
A1: 원자재마스터 (품번은 중복되면 안 됩니다)
A2: 품번 | B2: 품명 | C2: 재질 | D2: 길이(mm) | E2: 폭(mm) | F2: 두께(mm) | G2: 규격표기(자동) | H2: 비중 | I2: 장당중량kg(자동) | J2: 단위 | K2: 표준단가 | L2: 주거래처 | M2: 중복(자동) | N2: 비고
A3: R001 | B3: 열연강판 | C3: SS400 | D3: 1000 | E3: 500 | F3: 3.2 | G3: =IF($A3="","",IF(AND($D3="",$E3="",$F3=""),"",IF($D3="","",$D3)&IF($E3="",""," × "&$E3)&IF($F3=""," "," × ")&IF($F3="","",$F3)&"t")) -> 1000 × 500 × 3.2t | H3: 7.85 | I3: =IF($A3="","",IF(OR($D3="",$E3="",$F3="",$H3=""),"",ROUND($D3*$E3*$F3*$H3/1000000,2))) -> 12.56 | J3: EA | K3: 18500 | L3: ○○철강 | M3: =IF($A3="","",IF(COUNTIF($A$3:$A$502,$A3)>1,"중복","-")) -> -
A4: R002 | B4: 열연강판 | C4: SS400 | D4: 1200 | E4: 600 | F4: 4.5 | G4: =IF($A4="","",IF(AND($D4="",$E4="",$F4=""),"",IF($D4="","",$D4)&IF($E4="",""," × "&$E4)&IF($F4=""," "," × ")&IF($F4="","",$F4)&"t")) -> 1200 × 600 × 4.5t | H4: 7.85 | I4: =IF($A4="","",IF(OR($D4="",$E4="",$F4="",$H4=""),"",ROUND($D4*$E4*$F4*$H4/1000000,2))) -> 25.43 | J4: EA | K4: 34200 | L4: ○○철강 | M4: =IF($A4="","",IF(COUNTIF($A$3:$A$502,$A4)>1,"중복","-")) -> -
A5: R003 | B5: 알루미늄판 | C5: A5052 | D5: 1000 | E5: 500 | F5: 2 | G5: =IF($A5="","",IF(AND($D5="",$E5="",$F5=""),"",IF($D5="","",$D5)&IF($E5="",""," × "&$E5)&IF($F5=""," "," × ")&IF($F5="","",$F5)&"t")) -> 1000 × 500 × 2t | H5: 2.7 | I5: =IF($A5="","",IF(OR($D5="",$E5="",$F5="",$H5=""),"",ROUND($D5*$E5*$F5*$H5/1000000,2))) -> 2.7 | J5: EA | K5: 26000 | L5: △△금속 | M5: =IF($A5="","",IF(COUNTIF($A$3:$A$502,$A5)>1,"중복","-")) -> -
A6: R004 | B6: 스테인리스판 | C6: STS304 | D6: 1000 | E6: 500 | F6: 1.5 | G6: =IF($A6="","",IF(AND($D6="",$E6="",$F6=""),"",IF($D6="","",$D6)&IF($E6="",""," × "&$E6)&IF($F6=""," "," × ")&IF($F6="","",$F6)&"t")) -> 1000 × 500 × 1.5t | H6: 7.93 | I6: =IF($A6="","",IF(OR($D6="",$E6="",$F6="",$H6=""),"",ROUND($D6*$E6*$F6*$H6/1000000,2))) -> 5.95 | J6: EA | K6: 41000 | L6: △△금속 | M6: =IF($A6="","",IF(COUNTIF($A$3:$A$502,$A6)>1,"중복","-")) -> -
G7: =IF($A7="","",IF(AND($D7="",$E7="",$F7=""),"",IF($D7="","",$D7)&IF($E7="",""," × "&$E7)&IF($F7=""," "," × ")&IF($F7="","",$F7)&"t")) | I7: =IF($A7="","",IF(OR($D7="",$E7="",$F7="",$H7=""),"",ROUND($D7*$E7*$F7*$H7/1000000,2))) | M7: =IF($A7="","",IF(COUNTIF($A$3:$A$502,$A7)>1,"중복","-"))
G8: =IF($A8="","",IF(AND($D8="",$E8="",$F8=""),"",IF($D8="","",$D8)&IF($E8="",""," × "&$E8)&IF($F8=""," "," × ")&IF($F8="","",$F8)&"t")) | I8: =IF($A8="","",IF(OR($D8="",$E8="",$F8="",$H8=""),"",ROUND($D8*$E8*$F8*$H8/1000000,2))) | M8: =IF($A8="","",IF(COUNTIF($A$3:$A$502,$A8)>1,"중복","-"))
G9: =IF($A9="","",IF(AND($D9="",$E9="",$F9=""),"",IF($D9="","",$D9)&IF($E9="",""," × "&$E9)&IF($F9=""," "," × ")&IF($F9="","",$F9)&"t")) | I9: =IF($A9="","",IF(OR($D9="",$E9="",$F9="",$H9=""),"",ROUND($D9*$E9*$F9*$H9/1000000,2))) | M9: =IF($A9="","",IF(COUNTIF($A$3:$A$502,$A9)>1,"중복","-"))
G10: =IF($A10="","",IF(AND($D10="",$E10="",$F10=""),"",IF($D10="","",$D10)&IF($E10="",""," × "&$E10)&IF($F10=""," "," × ")&IF($F10="","",$F10)&"t")) | I10: =IF($A10="","",IF(OR($D10="",$E10="",$F10="",$H10=""),"",ROUND($D10*$E10*$F10*$H10/1000000,2))) | M10: =IF($A10="","",IF(COUNTIF($A$3:$A$502,$A10)>1,"중복","-"))
G11: =IF($A11="","",IF(AND($D11="",$E11="",$F11=""),"",IF($D11="","",$D11)&IF($E11="",""," × "&$E11)&IF($F11=""," "," × ")&IF($F11="","",$F11)&"t")) | I11: =IF($A11="","",IF(OR($D11="",$E11="",$F11="",$H11=""),"",ROUND($D11*$E11*$F11*$H11/1000000,2))) | M11: =IF($A11="","",IF(COUNTIF($A$3:$A$502,$A11)>1,"중복","-"))
G12: =IF($A12="","",IF(AND($D12="",$E12="",$F12=""),"",IF($D12="","",$D12)&IF($E12="",""," × "&$E12)&IF($F12=""," "," × ")&IF($F12="","",$F12)&"t")) | I12: =IF($A12="","",IF(OR($D12="",$E12="",$F12="",$H12=""),"",ROUND($D12*$E12*$F12*$H12/1000000,2))) | M12: =IF($A12="","",IF(COUNTIF($A$3:$A$502,$A12)>1,"중복","-"))
G13: =IF($A13="","",IF(AND($D13="",$E13="",$F13=""),"",IF($D13="","",$D13)&IF($E13="",""," × "&$E13)&IF($F13=""," "," × ")&IF($F13="","",$F13)&"t")) | I13: =IF($A13="","",IF(OR($D13="",$E13="",$F13="",$H13=""),"",ROUND($D13*$E13*$F13*$H13/1000000,2))) | M13: =IF($A13="","",IF(COUNTIF($A$3:$A$502,$A13)>1,"중복","-"))
G14: =IF($A14="","",IF(AND($D14="",$E14="",$F14=""),"",IF($D14="","",$D14)&IF($E14="",""," × "&$E14)&IF($F14=""," "," × ")&IF($F14="","",$F14)&"t")) | I14: =IF($A14="","",IF(OR($D14="",$E14="",$F14="",$H14=""),"",ROUND($D14*$E14*$F14*$H14/1000000,2))) | M14: =IF($A14="","",IF(COUNTIF($A$3:$A$502,$A14)>1,"중복","-"))
G15: =IF($A15="","",IF(AND($D15="",$E15="",$F15=""),"",IF($D15="","",$D15)&IF($E15="",""," × "&$E15)&IF($F15=""," "," × ")&IF($F15="","",$F15)&"t")) | I15: =IF($A15="","",IF(OR($D15="",$E15="",$F15="",$H15=""),"",ROUND($D15*$E15*$F15*$H15/1000000,2))) | M15: =IF($A15="","",IF(COUNTIF($A$3:$A$502,$A15)>1,"중복","-"))
G16: =IF($A16="","",IF(AND($D16="",$E16="",$F16=""),"",IF($D16="","",$D16)&IF($E16="",""," × "&$E16)&IF($F16=""," "," × ")&IF($F16="","",$F16)&"t")) | I16: =IF($A16="","",IF(OR($D16="",$E16="",$F16="",$H16=""),"",ROUND($D16*$E16*$F16*$H16/1000000,2))) | M16: =IF($A16="","",IF(COUNTIF($A$3:$A$502,$A16)>1,"중복","-"))
G17: =IF($A17="","",IF(AND($D17="",$E17="",$F17=""),"",IF($D17="","",$D17)&IF($E17="",""," × "&$E17)&IF($F17=""," "," × ")&IF($F17="","",$F17)&"t")) | I17: =IF($A17="","",IF(OR($D17="",$E17="",$F17="",$H17=""),"",ROUND($D17*$E17*$F17*$H17/1000000,2))) | M17: =IF($A17="","",IF(COUNTIF($A$3:$A$502,$A17)>1,"중복","-"))
G18: =IF($A18="","",IF(AND($D18="",$E18="",$F18=""),"",IF($D18="","",$D18)&IF($E18="",""," × "&$E18)&IF($F18=""," "," × ")&IF($F18="","",$F18)&"t")) | I18: =IF($A18="","",IF(OR($D18="",$E18="",$F18="",$H18=""),"",ROUND($D18*$E18*$F18*$H18/1000000,2))) | M18: =IF($A18="","",IF(COUNTIF($A$3:$A$502,$A18)>1,"중복","-"))
... G502: =IF($A502="","",IF(AND($D502="",$E502="",$F502=""),"",IF($D502="","",$D502)&IF($E502="",""," × "&$E502)&IF($F502=""," "," × ")&IF($F502="","",$F502)&"t")) | I502: =IF($A502="","",IF(OR($D502="",$E502="",$F502="",$H502=""),"",ROUND($D502*$E502*$F502*$H502/1000000,2))) | M502: =IF($A502="","",IF(COUNTIF($A$3:$A$502,$A502)>1,"중복","-"))
A504: ※ 규격표기는 길이·폭·두께로 자동 조합됩니다. 직접 다르게 쓰고 싶으면 덮어쓰세요.

Sheet 규격검색
A1: 규격검색 (품명·규격·재질 중 아무거나 일부만 넣으세요)
A3: 검색어 | B3: 강판 | D3: 재질 필터 | F3: ← 비우면 전체 | G3: 검색 결과 | H3: =COUNTIF($L$6:$L$505,TRUE())&" 건" -> 2 건
A5: 순번 | B5: 품번 | C5: 품명 | D5: 재질 | E5: 규격 | F5: 장당중량kg | G5: 단위 | H5: 표준단가 | I5: 주거래처 | L5: 대상(자동) | M5: 순번(자동) | N5: 키(자동)
A6: =IF($B6="","",1) -> 1 | B6: =IFERROR(INDEX(원자재마스터!$A$3:$A$502,MATCH("R"&1,규격검색!$N$6:$N$505,0)),"") -> R001 | C6: =IF($B6="","",IFERROR(INDEX(원자재마스터!$B$3:$B$502,MATCH("R"&1,규격검색!$N$6:$N$505,0)),"")) -> 열연강판 | D6: =IF($B6="","",IFERROR(INDEX(원자재마스터!$C$3:$C$502,MATCH("R"&1,규격검색!$N$6:$N$505,0)),"")) -> SS400 | E6: =IF($B6="","",IFERROR(INDEX(원자재마스터!$G$3:$G$502,MATCH("R"&1,규격검색!$N$6:$N$505,0)),"")) -> 1000 × 500 × 3.2t | F6: =IF($B6="","",IFERROR(INDEX(원자재마스터!$I$3:$I$502,MATCH("R"&1,규격검색!$N$6:$N$505,0)),"")) -> 12.56 | G6: =IF($B6="","",IFERROR(INDEX(원자재마스터!$J$3:$J$502,MATCH("R"&1,규격검색!$N$6:$N$505,0)),"")) -> EA | H6: =IF($B6="","",IFERROR(INDEX(원자재마스터!$K$3:$K$502,MATCH("R"&1,규격검색!$N$6:$N$505,0)),"")) -> 18500 | I6: =IF($B6="","",IFERROR(INDEX(원자재마스터!$L$3:$L$502,MATCH("R"&1,규격검색!$N$6:$N$505,0)),"")) -> ○○철강 | L6: =IF(원자재마스터!$A3="",FALSE(),AND(IF($B$3="",TRUE(),ISNUMBER(SEARCH($B$3,원자재마스터!$B3&" "&원자재마스터!$C3&" "&원자재마스터!$G3&" "&원자재마스터!$A3))),IF($E$3="",TRUE(),ISNUMBER(SEARCH($E$3,원자재마스터!$C3))))) -> TRUE | M6: =IF($L6=FALSE(),"",COUNTIF($L$6:$L6,TRUE())) -> 1 | N6: =IF($M6="","","R"&$M6) -> R1
A7: =IF($B7="","",2) -> 2 | B7: =IFERROR(INDEX(원자재마스터!$A$3:$A$502,MATCH("R"&2,규격검색!$N$6:$N$505,0)),"") -> R002 | C7: =IF($B7="","",IFERROR(INDEX(원자재마스터!$B$3:$B$502,MATCH("R"&2,규격검색!$N$6:$N$505,0)),"")) -> 열연강판 | D7: =IF($B7="","",IFERROR(INDEX(원자재마스터!$C$3:$C$502,MATCH("R"&2,규격검색!$N$6:$N$505,0)),"")) -> SS400 | E7: =IF($B7="","",IFERROR(INDEX(원자재마스터!$G$3:$G$502,MATCH("R"&2,규격검색!$N$6:$N$505,0)),"")) -> 1200 × 600 × 4.5t | F7: =IF($B7="","",IFERROR(INDEX(원자재마스터!$I$3:$I$502,MATCH("R"&2,규격검색!$N$6:$N$505,0)),"")) -> 25.43 | G7: =IF($B7="","",IFERROR(INDEX(원자재마스터!$J$3:$J$502,MATCH("R"&2,규격검색!$N$6:$N$505,0)),"")) -> EA | H7: =IF($B7="","",IFERROR(INDEX(원자재마스터!$K$3:$K$502,MATCH("R"&2,규격검색!$N$6:$N$505,0)),"")) -> 34200 | I7: =IF($B7="","",IFERROR(INDEX(원자재마스터!$L$3:$L$502,MATCH("R"&2,규격검색!$N$6:$N$505,0)),"")) -> ○○철강 | L7: =IF(원자재마스터!$A4="",FALSE(),AND(IF($B$3="",TRUE(),ISNUMBER(SEARCH($B$3,원자재마스터!$B4&" "&원자재마스터!$C4&" "&원자재마스터!$G4&" "&원자재마스터!$A4))),IF($E$3="",TRUE(),ISNUMBER(SEARCH($E$3,원자재마스터!$C4))))) -> TRUE | M7: =IF($L7=FALSE(),"",COUNTIF($L$6:$L7,TRUE())) -> 2 | N7: =IF($M7="","","R"&$M7) -> R2
A8: =IF($B8="","",3) | B8: =IFERROR(INDEX(원자재마스터!$A$3:$A$502,MATCH("R"&3,규격검색!$N$6:$N$505,0)),"") | C8: =IF($B8="","",IFERROR(INDEX(원자재마스터!$B$3:$B$502,MATCH("R"&3,규격검색!$N$6:$N$505,0)),"")) | D8: =IF($B8="","",IFERROR(INDEX(원자재마스터!$C$3:$C$502,MATCH("R"&3,규격검색!$N$6:$N$505,0)),"")) | E8: =IF($B8="","",IFERROR(INDEX(원자재마스터!$G$3:$G$502,MATCH("R"&3,규격검색!$N$6:$N$505,0)),"")) | F8: =IF($B8="","",IFERROR(INDEX(원자재마스터!$I$3:$I$502,MATCH("R"&3,규격검색!$N$6:$N$505,0)),"")) | G8: =IF($B8="","",IFERROR(INDEX(원자재마스터!$J$3:$J$502,MATCH("R"&3,규격검색!$N$6:$N$505,0)),"")) | H8: =IF($B8="","",IFERROR(INDEX(원자재마스터!$K$3:$K$502,MATCH("R"&3,규격검색!$N$6:$N$505,0)),"")) | I8: =IF($B8="","",IFERROR(INDEX(원자재마스터!$L$3:$L$502,MATCH("R"&3,규격검색!$N$6:$N$505,0)),"")) | L8: =IF(원자재마스터!$A5="",FALSE(),AND(IF($B$3="",TRUE(),ISNUMBER(SEARCH($B$3,원자재마스터!$B5&" "&원자재마스터!$C5&" "&원자재마스터!$G5&" "&원자재마스터!$A5))),IF($E$3="",TRUE(),ISNUMBER(SEARCH($E$3,원자재마스터!$C5))))) -> FALSE | M8: =IF($L8=FALSE(),"",COUNTIF($L$6:$L8,TRUE())) | N8: =IF($M8="","","R"&$M8)
A9: =IF($B9="","",4) | B9: =IFERROR(INDEX(원자재마스터!$A$3:$A$502,MATCH("R"&4,규격검색!$N$6:$N$505,0)),"") | C9: =IF($B9="","",IFERROR(INDEX(원자재마스터!$B$3:$B$502,MATCH("R"&4,규격검색!$N$6:$N$505,0)),"")) | D9: =IF($B9="","",IFERROR(INDEX(원자재마스터!$C$3:$C$502,MATCH("R"&4,규격검색!$N$6:$N$505,0)),"")) | E9: =IF($B9="","",IFERROR(INDEX(원자재마스터!$G$3:$G$502,MATCH("R"&4,규격검색!$N$6:$N$505,0)),"")) | F9: =IF($B9="","",IFERROR(INDEX(원자재마스터!$I$3:$I$502,MATCH("R"&4,규격검색!$N$6:$N$505,0)),"")) | G9: =IF($B9="","",IFERROR(INDEX(원자재마스터!$J$3:$J$502,MATCH("R"&4,규격검색!$N$6:$N$505,0)),"")) | H9: =IF($B9="","",IFERROR(INDEX(원자재마스터!$K$3:$K$502,MATCH("R"&4,규격검색!$N$6:$N$505,0)),"")) | I9: =IF($B9="","",IFERROR(INDEX(원자재마스터!$L$3:$L$502,MATCH("R"&4,규격검색!$N$6:$N$505,0)),"")) | L9: =IF(원자재마스터!$A6="",FALSE(),AND(IF($B$3="",TRUE(),ISNUMBER(SEARCH($B$3,원자재마스터!$B6&" "&원자재마스터!$C6&" "&원자재마스터!$G6&" "&원자재마스터!$A6))),IF($E$3="",TRUE(),ISNUMBER(SEARCH($E$3,원자재마스터!$C6))))) -> FALSE | M9: =IF($L9=FALSE(),"",COUNTIF($L$6:$L9,TRUE())) | N9: =IF($M9="","","R"&$M9)
A10: =IF($B10="","",5) | B10: =IFERROR(INDEX(원자재마스터!$A$3:$A$502,MATCH("R"&5,규격검색!$N$6:$N$505,0)),"") | C10: =IF($B10="","",IFERROR(INDEX(원자재마스터!$B$3:$B$502,MATCH("R"&5,규격검색!$N$6:$N$505,0)),"")) | D10: =IF($B10="","",IFERROR(INDEX(원자재마스터!$C$3:$C$502,MATCH("R"&5,규격검색!$N$6:$N$505,0)),"")) | E10: =IF($B10="","",IFERROR(INDEX(원자재마스터!$G$3:$G$502,MATCH("R"&5,규격검색!$N$6:$N$505,0)),"")) | F10: =IF($B10="","",IFERROR(INDEX(원자재마스터!$I$3:$I$502,MATCH("R"&5,규격검색!$N$6:$N$505,0)),"")) | G10: =IF($B10="","",IFERROR(INDEX(원자재마스터!$J$3:$J$502,MATCH("R"&5,규격검색!$N$6:$N$505,0)),"")) | H10: =IF($B10="","",IFERROR(INDEX(원자재마스터!$K$3:$K$502,MATCH("R"&5,규격검색!$N$6:$N$505,0)),"")) | I10: =IF($B10="","",IFERROR(INDEX(원자재마스터!$L$3:$L$502,MATCH("R"&5,규격검색!$N$6:$N$505,0)),"")) | L10: =IF(원자재마스터!$A7="",FALSE(),AND(IF($B$3="",TRUE(),ISNUMBER(SEARCH($B$3,원자재마스터!$B7&" "&원자재마스터!$C7&" "&원자재마스터!$G7&" "&원자재마스터!$A7))),IF($E$3="",TRUE(),ISNUMBER(SEARCH($E$3,원자재마스터!$C7))))) -> FALSE | M10: =IF($L10=FALSE(),"",COUNTIF($L$6:$L10,TRUE())) | N10: =IF($M10="","","R"&$M10)
A11: =IF($B11="","",6) | B11: =IFERROR(INDEX(원자재마스터!$A$3:$A$502,MATCH("R"&6,규격검색!$N$6:$N$505,0)),"") | C11: =IF($B11="","",IFERROR(INDEX(원자재마스터!$B$3:$B$502,MATCH("R"&6,규격검색!$N$6:$N$505,0)),"")) | D11: =IF($B11="","",IFERROR(INDEX(원자재마스터!$C$3:$C$502,MATCH("R"&6,규격검색!$N$6:$N$505,0)),"")) | E11: =IF($B11="","",IFERROR(INDEX(원자재마스터!$G$3:$G$502,MATCH("R"&6,규격검색!$N$6:$N$505,0)),"")) | F11: =IF($B11="","",IFERROR(INDEX(원자재마스터!$I$3:$I$502,MATCH("R"&6,규격검색!$N$6:$N$505,0)),"")) | G11: =IF($B11="","",IFERROR(INDEX(원자재마스터!$J$3:$J$502,MATCH("R"&6,규격검색!$N$6:$N$505,0)),"")) | H11: =IF($B11="","",IFERROR(INDEX(원자재마스터!$K$3:$K$502,MATCH("R"&6,규격검색!$N$6:$N$505,0)),"")) | I11: =IF($B11="","",IFERROR(INDEX(원자재마스터!$L$3:$L$502,MATCH("R"&6,규격검색!$N$6:$N$505,0)),"")) | L11: =IF(원자재마스터!$A8="",FALSE(),AND(IF($B$3="",TRUE(),ISNUMBER(SEARCH($B$3,원자재마스터!$B8&" "&원자재마스터!$C8&" "&원자재마스터!$G8&" "&원자재마스터!$A8))),IF($E$3="",TRUE(),ISNUMBER(SEARCH($E$3,원자재마스터!$C8))))) -> FALSE | M11: =IF($L11=FALSE(),"",COUNTIF($L$6:$L11,TRUE())) | N11: =IF($M11="","","R"&$M11)
A12: =IF($B12="","",7) | B12: =IFERROR(INDEX(원자재마스터!$A$3:$A$502,MATCH("R"&7,규격검색!$N$6:$N$505,0)),"") | C12: =IF($B12="","",IFERROR(INDEX(원자재마스터!$B$3:$B$502,MATCH("R"&7,규격검색!$N$6:$N$505,0)),"")) | D12: =IF($B12="","",IFERROR(INDEX(원자재마스터!$C$3:$C$502,MATCH("R"&7,규격검색!$N$6:$N$505,0)),"")) | E12: =IF($B12="","",IFERROR(INDEX(원자재마스터!$G$3:$G$502,MATCH("R"&7,규격검색!$N$6:$N$505,0)),"")) | F12: =IF($B12="","",IFERROR(INDEX(원자재마스터!$I$3:$I$502,MATCH("R"&7,규격검색!$N$6:$N$505,0)),"")) | G12: =IF($B12="","",IFERROR(INDEX(원자재마스터!$J$3:$J$502,MATCH("R"&7,규격검색!$N$6:$N$505,0)),"")) | H12: =IF($B12="","",IFERROR(INDEX(원자재마스터!$K$3:$K$502,MATCH("R"&7,규격검색!$N$6:$N$505,0)),"")) | I12: =IF($B12="","",IFERROR(INDEX(원자재마스터!$L$3:$L$502,MATCH("R"&7,규격검색!$N$6:$N$505,0)),"")) | L12: =IF(원자재마스터!$A9="",FALSE(),AND(IF($B$3="",TRUE(),ISNUMBER(SEARCH($B$3,원자재마스터!$B9&" "&원자재마스터!$C9&" "&원자재마스터!$G9&" "&원자재마스터!$A9))),IF($E$3="",TRUE(),ISNUMBER(SEARCH($E$3,원자재마스터!$C9))))) -> FALSE | M12: =IF($L12=FALSE(),"",COUNTIF($L$6:$L12,TRUE())) | N12: =IF($M12="","","R"&$M12)
A13: =IF($B13="","",8) | B13: =IFERROR(INDEX(원자재마스터!$A$3:$A$502,MATCH("R"&8,규격검색!$N$6:$N$505,0)),"") | C13: =IF($B13="","",IFERROR(INDEX(원자재마스터!$B$3:$B$502,MATCH("R"&8,규격검색!$N$6:$N$505,0)),"")) | D13: =IF($B13="","",IFERROR(INDEX(원자재마스터!$C$3:$C$502,MATCH("R"&8,규격검색!$N$6:$N$505,0)),"")) | E13: =IF($B13="","",IFERROR(INDEX(원자재마스터!$G$3:$G$502,MATCH("R"&8,규격검색!$N$6:$N$505,0)),"")) | F13: =IF($B13="","",IFERROR(INDEX(원자재마스터!$I$3:$I$502,MATCH("R"&8,규격검색!$N$6:$N$505,0)),"")) | G13: =IF($B13="","",IFERROR(INDEX(원자재마스터!$J$3:$J$502,MATCH("R"&8,규격검색!$N$6:$N$505,0)),"")) | H13: =IF($B13="","",IFERROR(INDEX(원자재마스터!$K$3:$K$502,MATCH("R"&8,규격검색!$N$6:$N$505,0)),"")) | I13: =IF($B13="","",IFERROR(INDEX(원자재마스터!$L$3:$L$502,MATCH("R"&8,규격검색!$N$6:$N$505,0)),"")) | L13: =IF(원자재마스터!$A10="",FALSE(),AND(IF($B$3="",TRUE(),ISNUMBER(SEARCH($B$3,원자재마스터!$B10&" "&원자재마스터!$C10&" "&원자재마스터!$G10&" "&원자재마스터!$A10))),IF($E$3="",TRUE(),ISNUMBER(SEARCH($E$3,원자재마스터!$C10))))) -> FALSE | M13: =IF($L13=FALSE(),"",COUNTIF($L$6:$L13,TRUE())) | N13: =IF($M13="","","R"&$M13)
A14: =IF($B14="","",9) | B14: =IFERROR(INDEX(원자재마스터!$A$3:$A$502,MATCH("R"&9,규격검색!$N$6:$N$505,0)),"") | C14: =IF($B14="","",IFERROR(INDEX(원자재마스터!$B$3:$B$502,MATCH("R"&9,규격검색!$N$6:$N$505,0)),"")) | D14: =IF($B14="","",IFERROR(INDEX(원자재마스터!$C$3:$C$502,MATCH("R"&9,규격검색!$N$6:$N$505,0)),"")) | E14: =IF($B14="","",IFERROR(INDEX(원자재마스터!$G$3:$G$502,MATCH("R"&9,규격검색!$N$6:$N$505,0)),"")) | F14: =IF($B14="","",IFERROR(INDEX(원자재마스터!$I$3:$I$502,MATCH("R"&9,규격검색!$N$6:$N$505,0)),"")) | G14: =IF($B14="","",IFERROR(INDEX(원자재마스터!$J$3:$J$502,MATCH("R"&9,규격검색!$N$6:$N$505,0)),"")) | H14: =IF($B14="","",IFERROR(INDEX(원자재마스터!$K$3:$K$502,MATCH("R"&9,규격검색!$N$6:$N$505,0)),"")) | I14: =IF($B14="","",IFERROR(INDEX(원자재마스터!$L$3:$L$502,MATCH("R"&9,규격검색!$N$6:$N$505,0)),"")) | L14: =IF(원자재마스터!$A11="",FALSE(),AND(IF($B$3="",TRUE(),ISNUMBER(SEARCH($B$3,원자재마스터!$B11&" "&원자재마스터!$C11&" "&원자재마스터!$G11&" "&원자재마스터!$A11))),IF($E$3="",TRUE(),ISNUMBER(SEARCH($E$3,원자재마스터!$C11))))) -> FALSE | M14: =IF($L14=FALSE(),"",COUNTIF($L$6:$L14,TRUE())) | N14: =IF($M14="","","R"&$M14)
A15: =IF($B15="","",10) | B15: =IFERROR(INDEX(원자재마스터!$A$3:$A$502,MATCH("R"&10,규격검색!$N$6:$N$505,0)),"") | C15: =IF($B15="","",IFERROR(INDEX(원자재마스터!$B$3:$B$502,MATCH("R"&10,규격검색!$N$6:$N$505,0)),"")) | D15: =IF($B15="","",IFERROR(INDEX(원자재마스터!$C$3:$C$502,MATCH("R"&10,규격검색!$N$6:$N$505,0)),"")) | E15: =IF($B15="","",IFERROR(INDEX(원자재마스터!$G$3:$G$502,MATCH("R"&10,규격검색!$N$6:$N$505,0)),"")) | F15: =IF($B15="","",IFERROR(INDEX(원자재마스터!$I$3:$I$502,MATCH("R"&10,규격검색!$N$6:$N$505,0)),"")) | G15: =IF($B15="","",IFERROR(INDEX(원자재마스터!$J$3:$J$502,MATCH("R"&10,규격검색!$N$6:$N$505,0)),"")) | H15: =IF($B15="","",IFERROR(INDEX(원자재마스터!$K$3:$K$502,MATCH("R"&10,규격검색!$N$6:$N$505,0)),"")) | I15: =IF($B15="","",IFERROR(INDEX(원자재마스터!$L$3:$L$502,MATCH("R"&10,규격검색!$N$6:$N$505,0)),"")) | L15: =IF(원자재마스터!$A12="",FALSE(),AND(IF($B$3="",TRUE(),ISNUMBER(SEARCH($B$3,원자재마스터!$B12&" "&원자재마스터!$C12&" "&원자재마스터!$G12&" "&원자재마스터!$A12))),IF($E$3="",TRUE(),ISNUMBER(SEARCH($E$3,원자재마스터!$C12))))) -> FALSE | M15: =IF($L15=FALSE(),"",COUNTIF($L$6:$L15,TRUE())) | N15: =IF($M15="","","R"&$M15)
A16: =IF($B16="","",11) | B16: =IFERROR(INDEX(원자재마스터!$A$3:$A$502,MATCH("R"&11,규격검색!$N$6:$N$505,0)),"") | C16: =IF($B16="","",IFERROR(INDEX(원자재마스터!$B$3:$B$502,MATCH("R"&11,규격검색!$N$6:$N$505,0)),"")) | D16: =IF($B16="","",IFERROR(INDEX(원자재마스터!$C$3:$C$502,MATCH("R"&11,규격검색!$N$6:$N$505,0)),"")) | E16: =IF($B16="","",IFERROR(INDEX(원자재마스터!$G$3:$G$502,MATCH("R"&11,규격검색!$N$6:$N$505,0)),"")) | F16: =IF($B16="","",IFERROR(INDEX(원자재마스터!$I$3:$I$502,MATCH("R"&11,규격검색!$N$6:$N$505,0)),"")) | G16: =IF($B16="","",IFERROR(INDEX(원자재마스터!$J$3:$J$502,MATCH("R"&11,규격검색!$N$6:$N$505,0)),"")) | H16: =IF($B16="","",IFERROR(INDEX(원자재마스터!$K$3:$K$502,MATCH("R"&11,규격검색!$N$6:$N$505,0)),"")) | I16: =IF($B16="","",IFERROR(INDEX(원자재마스터!$L$3:$L$502,MATCH("R"&11,규격검색!$N$6:$N$505,0)),"")) | L16: =IF(원자재마스터!$A13="",FALSE(),AND(IF($B$3="",TRUE(),ISNUMBER(SEARCH($B$3,원자재마스터!$B13&" "&원자재마스터!$C13&" "&원자재마스터!$G13&" "&원자재마스터!$A13))),IF($E$3="",TRUE(),ISNUMBER(SEARCH($E$3,원자재마스터!$C13))))) -> FALSE | M16: =IF($L16=FALSE(),"",COUNTIF($L$6:$L16,TRUE())) | N16: =IF($M16="","","R"&$M16)
A17: =IF($B17="","",12) | B17: =IFERROR(INDEX(원자재마스터!$A$3:$A$502,MATCH("R"&12,규격검색!$N$6:$N$505,0)),"") | C17: =IF($B17="","",IFERROR(INDEX(원자재마스터!$B$3:$B$502,MATCH("R"&12,규격검색!$N$6:$N$505,0)),"")) | D17: =IF($B17="","",IFERROR(INDEX(원자재마스터!$C$3:$C$502,MATCH("R"&12,규격검색!$N$6:$N$505,0)),"")) | E17: =IF($B17="","",IFERROR(INDEX(원자재마스터!$G$3:$G$502,MATCH("R"&12,규격검색!$N$6:$N$505,0)),"")) | F17: =IF($B17="","",IFERROR(INDEX(원자재마스터!$I$3:$I$502,MATCH("R"&12,규격검색!$N$6:$N$505,0)),"")) | G17: =IF($B17="","",IFERROR(INDEX(원자재마스터!$J$3:$J$502,MATCH("R"&12,규격검색!$N$6:$N$505,0)),"")) | H17: =IF($B17="","",IFERROR(INDEX(원자재마스터!$K$3:$K$502,MATCH("R"&12,규격검색!$N$6:$N$505,0)),"")) | I17: =IF($B17="","",IFERROR(INDEX(원자재마스터!$L$3:$L$502,MATCH("R"&12,규격검색!$N$6:$N$505,0)),"")) | L17: =IF(원자재마스터!$A14="",FALSE(),AND(IF($B$3="",TRUE(),ISNUMBER(SEARCH($B$3,원자재마스터!$B14&" "&원자재마스터!$C14&" "&원자재마스터!$G14&" "&원자재마스터!$A14))),IF($E$3="",TRUE(),ISNUMBER(SEARCH($E$3,원자재마스터!$C14))))) -> FALSE | M17: =IF($L17=FALSE(),"",COUNTIF($L$6:$L17,TRUE())) | N17: =IF($M17="","","R"&$M17)
A18: =IF($B18="","",13) | B18: =IFERROR(INDEX(원자재마스터!$A$3:$A$502,MATCH("R"&13,규격검색!$N$6:$N$505,0)),"") | C18: =IF($B18="","",IFERROR(INDEX(원자재마스터!$B$3:$B$502,MATCH("R"&13,규격검색!$N$6:$N$505,0)),"")) | D18: =IF($B18="","",IFERROR(INDEX(원자재마스터!$C$3:$C$502,MATCH("R"&13,규격검색!$N$6:$N$505,0)),"")) | E18: =IF($B18="","",IFERROR(INDEX(원자재마스터!$G$3:$G$502,MATCH("R"&13,규격검색!$N$6:$N$505,0)),"")) | F18: =IF($B18="","",IFERROR(INDEX(원자재마스터!$I$3:$I$502,MATCH("R"&13,규격검색!$N$6:$N$505,0)),"")) | G18: =IF($B18="","",IFERROR(INDEX(원자재마스터!$J$3:$J$502,MATCH("R"&13,규격검색!$N$6:$N$505,0)),"")) | H18: =IF($B18="","",IFERROR(INDEX(원자재마스터!$K$3:$K$502,MATCH("R"&13,규격검색!$N$6:$N$505,0)),"")) | I18: =IF($B18="","",IFERROR(INDEX(원자재마스터!$L$3:$L$502,MATCH("R"&13,규격검색!$N$6:$N$505,0)),"")) | L18: =IF(원자재마스터!$A15="",FALSE(),AND(IF($B$3="",TRUE(),ISNUMBER(SEARCH($B$3,원자재마스터!$B15&" "&원자재마스터!$C15&" "&원자재마스터!$G15&" "&원자재마스터!$A15))),IF($E$3="",TRUE(),ISNUMBER(SEARCH($E$3,원자재마스터!$C15))))) -> FALSE | M18: =IF($L18=FALSE(),"",COUNTIF($L$6:$L18,TRUE())) | N18: =IF($M18="","","R"&$M18)
A19: =IF($B19="","",14) | B19: =IFERROR(INDEX(원자재마스터!$A$3:$A$502,MATCH("R"&14,규격검색!$N$6:$N$505,0)),"") | C19: =IF($B19="","",IFERROR(INDEX(원자재마스터!$B$3:$B$502,MATCH("R"&14,규격검색!$N$6:$N$505,0)),"")) | D19: =IF($B19="","",IFERROR(INDEX(원자재마스터!$C$3:$C$502,MATCH("R"&14,규격검색!$N$6:$N$505,0)),"")) | E19: =IF($B19="","",IFERROR(INDEX(원자재마스터!$G$3:$G$502,MATCH("R"&14,규격검색!$N$6:$N$505,0)),"")) | F19: =IF($B19="","",IFERROR(INDEX(원자재마스터!$I$3:$I$502,MATCH("R"&14,규격검색!$N$6:$N$505,0)),"")) | G19: =IF($B19="","",IFERROR(INDEX(원자재마스터!$J$3:$J$502,MATCH("R"&14,규격검색!$N$6:$N$505,0)),"")) | H19: =IF($B19="","",IFERROR(INDEX(원자재마스터!$K$3:$K$502,MATCH("R"&14,규격검색!$N$6:$N$505,0)),"")) | I19: =IF($B19="","",IFERROR(INDEX(원자재마스터!$L$3:$L$502,MATCH("R"&14,규격검색!$N$6:$N$505,0)),"")) | L19: =IF(원자재마스터!$A16="",FALSE(),AND(IF($B$3="",TRUE(),ISNUMBER(SEARCH($B$3,원자재마스터!$B16&" "&원자재마스터!$C16&" "&원자재마스터!$G16&" "&원자재마스터!$A16))),IF($E$3="",TRUE(),ISNUMBER(SEARCH($E$3,원자재마스터!$C16))))) -> FALSE | M19: =IF($L19=FALSE(),"",COUNTIF($L$6:$L19,TRUE())) | N19: =IF($M19="","","R"&$M19)
A20: =IF($B20="","",15) | B20: =IFERROR(INDEX(원자재마스터!$A$3:$A$502,MATCH("R"&15,규격검색!$N$6:$N$505,0)),"") | C20: =IF($B20="","",IFERROR(INDEX(원자재마스터!$B$3:$B$502,MATCH("R"&15,규격검색!$N$6:$N$505,0)),"")) | D20: =IF($B20="","",IFERROR(INDEX(원자재마스터!$C$3:$C$502,MATCH("R"&15,규격검색!$N$6:$N$505,0)),"")) | E20: =IF($B20="","",IFERROR(INDEX(원자재마스터!$G$3:$G$502,MATCH("R"&15,규격검색!$N$6:$N$505,0)),"")) | F20: =IF($B20="","",IFERROR(INDEX(원자재마스터!$I$3:$I$502,MATCH("R"&15,규격검색!$N$6:$N$505,0)),"")) | G20: =IF($B20="","",IFERROR(INDEX(원자재마스터!$J$3:$J$502,MATCH("R"&15,규격검색!$N$6:$N$505,0)),"")) | H20: =IF($B20="","",IFERROR(INDEX(원자재마스터!$K$3:$K$502,MATCH("R"&15,규격검색!$N$6:$N$505,0)),"")) | I20: =IF($B20="","",IFERROR(INDEX(원자재마스터!$L$3:$L$502,MATCH("R"&15,규격검색!$N$6:$N$505,0)),"")) | L20: =IF(원자재마스터!$A17="",FALSE(),AND(IF($B$3="",TRUE(),ISNUMBER(SEARCH($B$3,원자재마스터!$B17&" "&원자재마스터!$C17&" "&원자재마스터!$G17&" "&원자재마스터!$A17))),IF($E$3="",TRUE(),ISNUMBER(SEARCH($E$3,원자재마스터!$C17))))) -> FALSE | M20: =IF($L20=FALSE(),"",COUNTIF($L$6:$L20,TRUE())) | N20: =IF($M20="","","R"&$M20)
A21: =IF($B21="","",16) | B21: =IFERROR(INDEX(원자재마스터!$A$3:$A$502,MATCH("R"&16,규격검색!$N$6:$N$505,0)),"") | C21: =IF($B21="","",IFERROR(INDEX(원자재마스터!$B$3:$B$502,MATCH("R"&16,규격검색!$N$6:$N$505,0)),"")) | D21: =IF($B21="","",IFERROR(INDEX(원자재마스터!$C$3:$C$502,MATCH("R"&16,규격검색!$N$6:$N$505,0)),"")) | E21: =IF($B21="","",IFERROR(INDEX(원자재마스터!$G$3:$G$502,MATCH("R"&16,규격검색!$N$6:$N$505,0)),"")) | F21: =IF($B21="","",IFERROR(INDEX(원자재마스터!$I$3:$I$502,MATCH("R"&16,규격검색!$N$6:$N$505,0)),"")) | G21: =IF($B21="","",IFERROR(INDEX(원자재마스터!$J$3:$J$502,MATCH("R"&16,규격검색!$N$6:$N$505,0)),"")) | H21: =IF($B21="","",IFERROR(INDEX(원자재마스터!$K$3:$K$502,MATCH("R"&16,규격검색!$N$6:$N$505,0)),"")) | I21: =IF($B21="","",IFERROR(INDEX(원자재마스터!$L$3:$L$502,MATCH("R"&16,규격검색!$N$6:$N$505,0)),"")) | L21: =IF(원자재마스터!$A18="",FALSE(),AND(IF($B$3="",TRUE(),ISNUMBER(SEARCH($B$3,원자재마스터!$B18&" "&원자재마스터!$C18&" "&원자재마스터!$G18&" "&원자재마스터!$A18))),IF($E$3="",TRUE(),ISNUMBER(SEARCH($E$3,원자재마스터!$C18))))) -> FALSE | M21: =IF($L21=FALSE(),"",COUNTIF($L$6:$L21,TRUE())) | N21: =IF($M21="","","R"&$M21)
A22: =IF($B22="","",17) | B22: =IFERROR(INDEX(원자재마스터!$A$3:$A$502,MATCH("R"&17,규격검색!$N$6:$N$505,0)),"") | C22: =IF($B22="","",IFERROR(INDEX(원자재마스터!$B$3:$B$502,MATCH("R"&17,규격검색!$N$6:$N$505,0)),"")) | D22: =IF($B22="","",IFERROR(INDEX(원자재마스터!$C$3:$C$502,MATCH("R"&17,규격검색!$N$6:$N$505,0)),"")) | E22: =IF($B22="","",IFERROR(INDEX(원자재마스터!$G$3:$G$502,MATCH("R"&17,규격검색!$N$6:$N$505,0)),"")) | F22: =IF($B22="","",IFERROR(INDEX(원자재마스터!$I$3:$I$502,MATCH("R"&17,규격검색!$N$6:$N$505,0)),"")) | G22: =IF($B22="","",IFERROR(INDEX(원자재마스터!$J$3:$J$502,MATCH("R"&17,규격검색!$N$6:$N$505,0)),"")) | H22: =IF($B22="","",IFERROR(INDEX(원자재마스터!$K$3:$K$502,MATCH("R"&17,규격검색!$N$6:$N$505,0)),"")) | I22: =IF($B22="","",IFERROR(INDEX(원자재마스터!$L$3:$L$502,MATCH("R"&17,규격검색!$N$6:$N$505,0)),"")) | L22: =IF(원자재마스터!$A19="",FALSE(),AND(IF($B$3="",TRUE(),ISNUMBER(SEARCH($B$3,원자재마스터!$B19&" "&원자재마스터!$C19&" "&원자재마스터!$G19&" "&원자재마스터!$A19))),IF($E$3="",TRUE(),ISNUMBER(SEARCH($E$3,원자재마스터!$C19))))) -> FALSE | M22: =IF($L22=FALSE(),"",COUNTIF($L$6:$L22,TRUE())) | N22: =IF($M22="","","R"&$M22)
A23: =IF($B23="","",18) | B23: =IFERROR(INDEX(원자재마스터!$A$3:$A$502,MATCH("R"&18,규격검색!$N$6:$N$505,0)),"") | C23: =IF($B23="","",IFERROR(INDEX(원자재마스터!$B$3:$B$502,MATCH("R"&18,규격검색!$N$6:$N$505,0)),"")) | D23: =IF($B23="","",IFERROR(INDEX(원자재마스터!$C$3:$C$502,MATCH("R"&18,규격검색!$N$6:$N$505,0)),"")) | E23: =IF($B23="","",IFERROR(INDEX(원자재마스터!$G$3:$G$502,MATCH("R"&18,규격검색!$N$6:$N$505,0)),"")) | F23: =IF($B23="","",IFERROR(INDEX(원자재마스터!$I$3:$I$502,MATCH("R"&18,규격검색!$N$6:$N$505,0)),"")) | G23: =IF($B23="","",IFERROR(INDEX(원자재마스터!$J$3:$J$502,MATCH("R"&18,규격검색!$N$6:$N$505,0)),"")) | H23: =IF($B23="","",IFERROR(INDEX(원자재마스터!$K$3:$K$502,MATCH("R"&18,규격검색!$N$6:$N$505,0)),"")) | I23: =IF($B23="","",IFERROR(INDEX(원자재마스터!$L$3:$L$502,MATCH("R"&18,규격검색!$N$6:$N$505,0)),"")) | L23: =IF(원자재마스터!$A20="",FALSE(),AND(IF($B$3="",TRUE(),ISNUMBER(SEARCH($B$3,원자재마스터!$B20&" "&원자재마스터!$C20&" "&원자재마스터!$G20&" "&원자재마스터!$A20))),IF($E$3="",TRUE(),ISNUMBER(SEARCH($E$3,원자재마스터!$C20))))) -> FALSE | M23: =IF($L23=FALSE(),"",COUNTIF($L$6:$L23,TRUE())) | N23: =IF($M23="","","R"&$M23)
A24: =IF($B24="","",19) | B24: =IFERROR(INDEX(원자재마스터!$A$3:$A$502,MATCH("R"&19,규격검색!$N$6:$N$505,0)),"") | C24: =IF($B24="","",IFERROR(INDEX(원자재마스터!$B$3:$B$502,MATCH("R"&19,규격검색!$N$6:$N$505,0)),"")) | D24: =IF($B24="","",IFERROR(INDEX(원자재마스터!$C$3:$C$502,MATCH("R"&19,규격검색!$N$6:$N$505,0)),"")) | E24: =IF($B24="","",IFERROR(INDEX(원자재마스터!$G$3:$G$502,MATCH("R"&19,규격검색!$N$6:$N$505,0)),"")) | F24: =IF($B24="","",IFERROR(INDEX(원자재마스터!$I$3:$I$502,MATCH("R"&19,규격검색!$N$6:$N$505,0)),"")) | G24: =IF($B24="","",IFERROR(INDEX(원자재마스터!$J$3:$J$502,MATCH("R"&19,규격검색!$N$6:$N$505,0)),"")) | H24: =IF($B24="","",IFERROR(INDEX(원자재마스터!$K$3:$K$502,MATCH("R"&19,규격검색!$N$6:$N$505,0)),"")) | I24: =IF($B24="","",IFERROR(INDEX(원자재마스터!$L$3:$L$502,MATCH("R"&19,규격검색!$N$6:$N$505,0)),"")) | L24: =IF(원자재마스터!$A21="",FALSE(),AND(IF($B$3="",TRUE(),ISNUMBER(SEARCH($B$3,원자재마스터!$B21&" "&원자재마스터!$C21&" "&원자재마스터!$G21&" "&원자재마스터!$A21))),IF($E$3="",TRUE(),ISNUMBER(SEARCH($E$3,원자재마스터!$C21))))) -> FALSE | M24: =IF($L24=FALSE(),"",COUNTIF($L$6:$L24,TRUE())) | N24: =IF($M24="","","R"&$M24)
A25: =IF($B25="","",20) | B25: =IFERROR(INDEX(원자재마스터!$A$3:$A$502,MATCH("R"&20,규격검색!$N$6:$N$505,0)),"") | C25: =IF($B25="","",IFERROR(INDEX(원자재마스터!$B$3:$B$502,MATCH("R"&20,규격검색!$N$6:$N$505,0)),"")) | D25: =IF($B25="","",IFERROR(INDEX(원자재마스터!$C$3:$C$502,MATCH("R"&20,규격검색!$N$6:$N$505,0)),"")) | E25: =IF($B25="","",IFERROR(INDEX(원자재마스터!$G$3:$G$502,MATCH("R"&20,규격검색!$N$6:$N$505,0)),"")) | F25: =IF($B25="","",IFERROR(INDEX(원자재마스터!$I$3:$I$502,MATCH("R"&20,규격검색!$N$6:$N$505,0)),"")) | G25: =IF($B25="","",IFERROR(INDEX(원자재마스터!$J$3:$J$502,MATCH("R"&20,규격검색!$N$6:$N$505,0)),"")) | H25: =IF($B25="","",IFERROR(INDEX(원자재마스터!$K$3:$K$502,MATCH("R"&20,규격검색!$N$6:$N$505,0)),"")) | I25: =IF($B25="","",IFERROR(INDEX(원자재마스터!$L$3:$L$502,MATCH("R"&20,규격검색!$N$6:$N$505,0)),"")) | L25: =IF(원자재마스터!$A22="",FALSE(),AND(IF($B$3="",TRUE(),ISNUMBER(SEARCH($B$3,원자재마스터!$B22&" "&원자재마스터!$C22&" "&원자재마스터!$G22&" "&원자재마스터!$A22))),IF($E$3="",TRUE(),ISNUMBER(SEARCH($E$3,원자재마스터!$C22))))) -> FALSE | M25: =IF($L25=FALSE(),"",COUNTIF($L$6:$L25,TRUE())) | N25: =IF($M25="","","R"&$M25)
A26: =IF($B26="","",21) | B26: =IFERROR(INDEX(원자재마스터!$A$3:$A$502,MATCH("R"&21,규격검색!$N$6:$N$505,0)),"") | C26: =IF($B26="","",IFERROR(INDEX(원자재마스터!$B$3:$B$502,MATCH("R"&21,규격검색!$N$6:$N$505,0)),"")) | D26: =IF($B26="","",IFERROR(INDEX(원자재마스터!$C$3:$C$502,MATCH("R"&21,규격검색!$N$6:$N$505,0)),"")) | E26: =IF($B26="","",IFERROR(INDEX(원자재마스터!$G$3:$G$502,MATCH("R"&21,규격검색!$N$6:$N$505,0)),"")) | F26: =IF($B26="","",IFERROR(INDEX(원자재마스터!$I$3:$I$502,MATCH("R"&21,규격검색!$N$6:$N$505,0)),"")) | G26: =IF($B26="","",IFERROR(INDEX(원자재마스터!$J$3:$J$502,MATCH("R"&21,규격검색!$N$6:$N$505,0)),"")) | H26: =IF($B26="","",IFERROR(INDEX(원자재마스터!$K$3:$K$502,MATCH("R"&21,규격검색!$N$6:$N$505,0)),"")) | I26: =IF($B26="","",IFERROR(INDEX(원자재마스터!$L$3:$L$502,MATCH("R"&21,규격검색!$N$6:$N$505,0)),"")) | L26: =IF(원자재마스터!$A23="",FALSE(),AND(IF($B$3="",TRUE(),ISNUMBER(SEARCH($B$3,원자재마스터!$B23&" "&원자재마스터!$C23&" "&원자재마스터!$G23&" "&원자재마스터!$A23))),IF($E$3="",TRUE(),ISNUMBER(SEARCH($E$3,원자재마스터!$C23))))) -> FALSE | M26: =IF($L26=FALSE(),"",COUNTIF($L$6:$L26,TRUE())) | N26: =IF($M26="","","R"&$M26)
A27: =IF($B27="","",22) | B27: =IFERROR(INDEX(원자재마스터!$A$3:$A$502,MATCH("R"&22,규격검색!$N$6:$N$505,0)),"") | C27: =IF($B27="","",IFERROR(INDEX(원자재마스터!$B$3:$B$502,MATCH("R"&22,규격검색!$N$6:$N$505,0)),"")) | D27: =IF($B27="","",IFERROR(INDEX(원자재마스터!$C$3:$C$502,MATCH("R"&22,규격검색!$N$6:$N$505,0)),"")) | E27: =IF($B27="","",IFERROR(INDEX(원자재마스터!$G$3:$G$502,MATCH("R"&22,규격검색!$N$6:$N$505,0)),"")) | F27: =IF($B27="","",IFERROR(INDEX(원자재마스터!$I$3:$I$502,MATCH("R"&22,규격검색!$N$6:$N$505,0)),"")) | G27: =IF($B27="","",IFERROR(INDEX(원자재마스터!$J$3:$J$502,MATCH("R"&22,규격검색!$N$6:$N$505,0)),"")) | H27: =IF($B27="","",IFERROR(INDEX(원자재마스터!$K$3:$K$502,MATCH("R"&22,규격검색!$N$6:$N$505,0)),"")) | I27: =IF($B27="","",IFERROR(INDEX(원자재마스터!$L$3:$L$502,MATCH("R"&22,규격검색!$N$6:$N$505,0)),"")) | L27: =IF(원자재마스터!$A24="",FALSE(),AND(IF($B$3="",TRUE(),ISNUMBER(SEARCH($B$3,원자재마스터!$B24&" "&원자재마스터!$C24&" "&원자재마스터!$G24&" "&원자재마스터!$A24))),IF($E$3="",TRUE(),ISNUMBER(SEARCH($E$3,원자재마스터!$C24))))) -> FALSE | M27: =IF($L27=FALSE(),"",COUNTIF($L$6:$L27,TRUE())) | N27: =IF($M27="","","R"&$M27)
A28: =IF($B28="","",23) | B28: =IFERROR(INDEX(원자재마스터!$A$3:$A$502,MATCH("R"&23,규격검색!$N$6:$N$505,0)),"") | C28: =IF($B28="","",IFERROR(INDEX(원자재마스터!$B$3:$B$502,MATCH("R"&23,규격검색!$N$6:$N$505,0)),"")) | D28: =IF($B28="","",IFERROR(INDEX(원자재마스터!$C$3:$C$502,MATCH("R"&23,규격검색!$N$6:$N$505,0)),"")) | E28: =IF($B28="","",IFERROR(INDEX(원자재마스터!$G$3:$G$502,MATCH("R"&23,규격검색!$N$6:$N$505,0)),"")) | F28: =IF($B28="","",IFERROR(INDEX(원자재마스터!$I$3:$I$502,MATCH("R"&23,규격검색!$N$6:$N$505,0)),"")) | G28: =IF($B28="","",IFERROR(INDEX(원자재마스터!$J$3:$J$502,MATCH("R"&23,규격검색!$N$6:$N$505,0)),"")) | H28: =IF($B28="","",IFERROR(INDEX(원자재마스터!$K$3:$K$502,MATCH("R"&23,규격검색!$N$6:$N$505,0)),"")) | I28: =IF($B28="","",IFERROR(INDEX(원자재마스터!$L$3:$L$502,MATCH("R"&23,규격검색!$N$6:$N$505,0)),"")) | L28: =IF(원자재마스터!$A25="",FALSE(),AND(IF($B$3="",TRUE(),ISNUMBER(SEARCH($B$3,원자재마스터!$B25&" "&원자재마스터!$C25&" "&원자재마스터!$G25&" "&원자재마스터!$A25))),IF($E$3="",TRUE(),ISNUMBER(SEARCH($E$3,원자재마스터!$C25))))) -> FALSE | M28: =IF($L28=FALSE(),"",COUNTIF($L$6:$L28,TRUE())) | N28: =IF($M28="","","R"&$M28)
A29: =IF($B29="","",24) | B29: =IFERROR(INDEX(원자재마스터!$A$3:$A$502,MATCH("R"&24,규격검색!$N$6:$N$505,0)),"") | C29: =IF($B29="","",IFERROR(INDEX(원자재마스터!$B$3:$B$502,MATCH("R"&24,규격검색!$N$6:$N$505,0)),"")) | D29: =IF($B29="","",IFERROR(INDEX(원자재마스터!$C$3:$C$502,MATCH("R"&24,규격검색!$N$6:$N$505,0)),"")) | E29: =IF($B29="","",IFERROR(INDEX(원자재마스터!$G$3:$G$502,MATCH("R"&24,규격검색!$N$6:$N$505,0)),"")) | F29: =IF($B29="","",IFERROR(INDEX(원자재마스터!$I$3:$I$502,MATCH("R"&24,규격검색!$N$6:$N$505,0)),"")) | G29: =IF($B29="","",IFERROR(INDEX(원자재마스터!$J$3:$J$502,MATCH("R"&24,규격검색!$N$6:$N$505,0)),"")) | H29: =IF($B29="","",IFERROR(INDEX(원자재마스터!$K$3:$K$502,MATCH("R"&24,규격검색!$N$6:$N$505,0)),"")) | I29: =IF($B29="","",IFERROR(INDEX(원자재마스터!$L$3:$L$502,MATCH("R"&24,규격검색!$N$6:$N$505,0)),"")) | L29: =IF(원자재마스터!$A26="",FALSE(),AND(IF($B$3="",TRUE(),ISNUMBER(SEARCH($B$3,원자재마스터!$B26&" "&원자재마스터!$C26&" "&원자재마스터!$G26&" "&원자재마스터!$A26))),IF($E$3="",TRUE(),ISNUMBER(SEARCH($E$3,원자재마스터!$C26))))) -> FALSE | M29: =IF($L29=FALSE(),"",COUNTIF($L$6:$L29,TRUE())) | N29: =IF($M29="","","R"&$M29)
A30: =IF($B30="","",25) | B30: =IFERROR(INDEX(원자재마스터!$A$3:$A$502,MATCH("R"&25,규격검색!$N$6:$N$505,0)),"") | C30: =IF($B30="","",IFERROR(INDEX(원자재마스터!$B$3:$B$502,MATCH("R"&25,규격검색!$N$6:$N$505,0)),"")) | D30: =IF($B30="","",IFERROR(INDEX(원자재마스터!$C$3:$C$502,MATCH("R"&25,규격검색!$N$6:$N$505,0)),"")) | E30: =IF($B30="","",IFERROR(INDEX(원자재마스터!$G$3:$G$502,MATCH("R"&25,규격검색!$N$6:$N$505,0)),"")) | F30: =IF($B30="","",IFERROR(INDEX(원자재마스터!$I$3:$I$502,MATCH("R"&25,규격검색!$N$6:$N$505,0)),"")) | G30: =IF($B30="","",IFERROR(INDEX(원자재마스터!$J$3:$J$502,MATCH("R"&25,규격검색!$N$6:$N$505,0)),"")) | H30: =IF($B30="","",IFERROR(INDEX(원자재마스터!$K$3:$K$502,MATCH("R"&25,규격검색!$N$6:$N$505,0)),"")) | I30: =IF($B30="","",IFERROR(INDEX(원자재마스터!$L$3:$L$502,MATCH("R"&25,규격검색!$N$6:$N$505,0)),"")) | L30: =IF(원자재마스터!$A27="",FALSE(),AND(IF($B$3="",TRUE(),ISNUMBER(SEARCH($B$3,원자재마스터!$B27&" "&원자재마스터!$C27&" "&원자재마스터!$G27&" "&원자재마스터!$A27))),IF($E$3="",TRUE(),ISNUMBER(SEARCH($E$3,원자재마스터!$C27))))) -> FALSE | M30: =IF($L30=FALSE(),"",COUNTIF($L$6:$L30,TRUE())) | N30: =IF($M30="","","R"&$M30)
A31: =IF($B31="","",26) | B31: =IFERROR(INDEX(원자재마스터!$A$3:$A$502,MATCH("R"&26,규격검색!$N$6:$N$505,0)),"") | C31: =IF($B31="","",IFERROR(INDEX(원자재마스터!$B$3:$B$502,MATCH("R"&26,규격검색!$N$6:$N$505,0)),"")) | D31: =IF($B31="","",IFERROR(INDEX(원자재마스터!$C$3:$C$502,MATCH("R"&26,규격검색!$N$6:$N$505,0)),"")) | E31: =IF($B31="","",IFERROR(INDEX(원자재마스터!$G$3:$G$502,MATCH("R"&26,규격검색!$N$6:$N$505,0)),"")) | F31: =IF($B31="","",IFERROR(INDEX(원자재마스터!$I$3:$I$502,MATCH("R"&26,규격검색!$N$6:$N$505,0)),"")) | G31: =IF($B31="","",IFERROR(INDEX(원자재마스터!$J$3:$J$502,MATCH("R"&26,규격검색!$N$6:$N$505,0)),"")) | H31: =IF($B31="","",IFERROR(INDEX(원자재마스터!$K$3:$K$502,MATCH("R"&26,규격검색!$N$6:$N$505,0)),"")) | I31: =IF($B31="","",IFERROR(INDEX(원자재마스터!$L$3:$L$502,MATCH("R"&26,규격검색!$N$6:$N$505,0)),"")) | L31: =IF(원자재마스터!$A28="",FALSE(),AND(IF($B$3="",TRUE(),ISNUMBER(SEARCH($B$3,원자재마스터!$B28&" "&원자재마스터!$C28&" "&원자재마스터!$G28&" "&원자재마스터!$A28))),IF($E$3="",TRUE(),ISNUMBER(SEARCH($E$3,원자재마스터!$C28))))) -> FALSE | M31: =IF($L31=FALSE(),"",COUNTIF($L$6:$L31,TRUE())) | N31: =IF($M31="","","R"&$M31)
A32: =IF($B32="","",27) | B32: =IFERROR(INDEX(원자재마스터!$A$3:$A$502,MATCH("R"&27,규격검색!$N$6:$N$505,0)),"") | C32: =IF($B32="","",IFERROR(INDEX(원자재마스터!$B$3:$B$502,MATCH("R"&27,규격검색!$N$6:$N$505,0)),"")) | D32: =IF($B32="","",IFERROR(INDEX(원자재마스터!$C$3:$C$502,MATCH("R"&27,규격검색!$N$6:$N$505,0)),"")) | E32: =IF($B32="","",IFERROR(INDEX(원자재마스터!$G$3:$G$502,MATCH("R"&27,규격검색!$N$6:$N$505,0)),"")) | F32: =IF($B32="","",IFERROR(INDEX(원자재마스터!$I$3:$I$502,MATCH("R"&27,규격검색!$N$6:$N$505,0)),"")) | G32: =IF($B32="","",IFERROR(INDEX(원자재마스터!$J$3:$J$502,MATCH("R"&27,규격검색!$N$6:$N$505,0)),"")) | H32: =IF($B32="","",IFERROR(INDEX(원자재마스터!$K$3:$K$502,MATCH("R"&27,규격검색!$N$6:$N$505,0)),"")) | I32: =IF($B32="","",IFERROR(INDEX(원자재마스터!$L$3:$L$502,MATCH("R"&27,규격검색!$N$6:$N$505,0)),"")) | L32: =IF(원자재마스터!$A29="",FALSE(),AND(IF($B$3="",TRUE(),ISNUMBER(SEARCH($B$3,원자재마스터!$B29&" "&원자재마스터!$C29&" "&원자재마스터!$G29&" "&원자재마스터!$A29))),IF($E$3="",TRUE(),ISNUMBER(SEARCH($E$3,원자재마스터!$C29))))) -> FALSE | M32: =IF($L32=FALSE(),"",COUNTIF($L$6:$L32,TRUE())) | N32: =IF($M32="","","R"&$M32)
A33: =IF($B33="","",28) | B33: =IFERROR(INDEX(원자재마스터!$A$3:$A$502,MATCH("R"&28,규격검색!$N$6:$N$505,0)),"") | C33: =IF($B33="","",IFERROR(INDEX(원자재마스터!$B$3:$B$502,MATCH("R"&28,규격검색!$N$6:$N$505,0)),"")) | D33: =IF($B33="","",IFERROR(INDEX(원자재마스터!$C$3:$C$502,MATCH("R"&28,규격검색!$N$6:$N$505,0)),"")) | E33: =IF($B33="","",IFERROR(INDEX(원자재마스터!$G$3:$G$502,MATCH("R"&28,규격검색!$N$6:$N$505,0)),"")) | F33: =IF($B33="","",IFERROR(INDEX(원자재마스터!$I$3:$I$502,MATCH("R"&28,규격검색!$N$6:$N$505,0)),"")) | G33: =IF($B33="","",IFERROR(INDEX(원자재마스터!$J$3:$J$502,MATCH("R"&28,규격검색!$N$6:$N$505,0)),"")) | H33: =IF($B33="","",IFERROR(INDEX(원자재마스터!$K$3:$K$502,MATCH("R"&28,규격검색!$N$6:$N$505,0)),"")) | I33: =IF($B33="","",IFERROR(INDEX(원자재마스터!$L$3:$L$502,MATCH("R"&28,규격검색!$N$6:$N$505,0)),"")) | L33: =IF(원자재마스터!$A30="",FALSE(),AND(IF($B$3="",TRUE(),ISNUMBER(SEARCH($B$3,원자재마스터!$B30&" "&원자재마스터!$C30&" "&원자재마스터!$G30&" "&원자재마스터!$A30))),IF($E$3="",TRUE(),ISNUMBER(SEARCH($E$3,원자재마스터!$C30))))) -> FALSE | M33: =IF($L33=FALSE(),"",COUNTIF($L$6:$L33,TRUE())) | N33: =IF($M33="","","R"&$M33)
A34: =IF($B34="","",29) | B34: =IFERROR(INDEX(원자재마스터!$A$3:$A$502,MATCH("R"&29,규격검색!$N$6:$N$505,0)),"") | C34: =IF($B34="","",IFERROR(INDEX(원자재마스터!$B$3:$B$502,MATCH("R"&29,규격검색!$N$6:$N$505,0)),"")) | D34: =IF($B34="","",IFERROR(INDEX(원자재마스터!$C$3:$C$502,MATCH("R"&29,규격검색!$N$6:$N$505,0)),"")) | E34: =IF($B34="","",IFERROR(INDEX(원자재마스터!$G$3:$G$502,MATCH("R"&29,규격검색!$N$6:$N$505,0)),"")) | F34: =IF($B34="","",IFERROR(INDEX(원자재마스터!$I$3:$I$502,MATCH("R"&29,규격검색!$N$6:$N$505,0)),"")) | G34: =IF($B34="","",IFERROR(INDEX(원자재마스터!$J$3:$J$502,MATCH("R"&29,규격검색!$N$6:$N$505,0)),"")) | H34: =IF($B34="","",IFERROR(INDEX(원자재마스터!$K$3:$K$502,MATCH("R"&29,규격검색!$N$6:$N$505,0)),"")) | I34: =IF($B34="","",IFERROR(INDEX(원자재마스터!$L$3:$L$502,MATCH("R"&29,규격검색!$N$6:$N$505,0)),"")) | L34: =IF(원자재마스터!$A31="",FALSE(),AND(IF($B$3="",TRUE(),ISNUMBER(SEARCH($B$3,원자재마스터!$B31&" "&원자재마스터!$C31&" "&원자재마스터!$G31&" "&원자재마스터!$A31))),IF($E$3="",TRUE(),ISNUMBER(SEARCH($E$3,원자재마스터!$C31))))) -> FALSE | M34: =IF($L34=FALSE(),"",COUNTIF($L$6:$L34,TRUE())) | N34: =IF($M34="","","R"&$M34)
A35: =IF($B35="","",30) | B35: =IFERROR(INDEX(원자재마스터!$A$3:$A$502,MATCH("R"&30,규격검색!$N$6:$N$505,0)),"") | C35: =IF($B35="","",IFERROR(INDEX(원자재마스터!$B$3:$B$502,MATCH("R"&30,규격검색!$N$6:$N$505,0)),"")) | D35: =IF($B35="","",IFERROR(INDEX(원자재마스터!$C$3:$C$502,MATCH("R"&30,규격검색!$N$6:$N$505,0)),"")) | E35: =IF($B35="","",IFERROR(INDEX(원자재마스터!$G$3:$G$502,MATCH("R"&30,규격검색!$N$6:$N$505,0)),"")) | F35: =IF($B35="","",IFERROR(INDEX(원자재마스터!$I$3:$I$502,MATCH("R"&30,규격검색!$N$6:$N$505,0)),"")) | G35: =IF($B35="","",IFERROR(INDEX(원자재마스터!$J$3:$J$502,MATCH("R"&30,규격검색!$N$6:$N$505,0)),"")) | H35: =IF($B35="","",IFERROR(INDEX(원자재마스터!$K$3:$K$502,MATCH("R"&30,규격검색!$N$6:$N$505,0)),"")) | I35: =IF($B35="","",IFERROR(INDEX(원자재마스터!$L$3:$L$502,MATCH("R"&30,규격검색!$N$6:$N$505,0)),"")) | L35: =IF(원자재마스터!$A32="",FALSE(),AND(IF($B$3="",TRUE(),ISNUMBER(SEARCH($B$3,원자재마스터!$B32&" "&원자재마스터!$C32&" "&원자재마스터!$G32&" "&원자재마스터!$A32))),IF($E$3="",TRUE(),ISNUMBER(SEARCH($E$3,원자재마스터!$C32))))) -> FALSE | M35: =IF($L35=FALSE(),"",COUNTIF($L$6:$L35,TRUE())) | N35: =IF($M35="","","R"&$M35)
A36: =IF($B36="","",31) | B36: =IFERROR(INDEX(원자재마스터!$A$3:$A$502,MATCH("R"&31,규격검색!$N$6:$N$505,0)),"") | C36: =IF($B36="","",IFERROR(INDEX(원자재마스터!$B$3:$B$502,MATCH("R"&31,규격검색!$N$6:$N$505,0)),"")) | D36: =IF($B36="","",IFERROR(INDEX(원자재마스터!$C$3:$C$502,MATCH("R"&31,규격검색!$N$6:$N$505,0)),"")) | E36: =IF($B36="","",IFERROR(INDEX(원자재마스터!$G$3:$G$502,MATCH("R"&31,규격검색!$N$6:$N$505,0)),"")) | F36: =IF($B36="","",IFERROR(INDEX(원자재마스터!$I$3:$I$502,MATCH("R"&31,규격검색!$N$6:$N$505,0)),"")) | G36: =IF($B36="","",IFERROR(INDEX(원자재마스터!$J$3:$J$502,MATCH("R"&31,규격검색!$N$6:$N$505,0)),"")) | H36: =IF($B36="","",IFERROR(INDEX(원자재마스터!$K$3:$K$502,MATCH("R"&31,규격검색!$N$6:$N$505,0)),"")) | I36: =IF($B36="","",IFERROR(INDEX(원자재마스터!$L$3:$L$502,MATCH("R"&31,규격검색!$N$6:$N$505,0)),"")) | L36: =IF(원자재마스터!$A33="",FALSE(),AND(IF($B$3="",TRUE(),ISNUMBER(SEARCH($B$3,원자재마스터!$B33&" "&원자재마스터!$C33&" "&원자재마스터!$G33&" "&원자재마스터!$A33))),IF($E$3="",TRUE(),ISNUMBER(SEARCH($E$3,원자재마스터!$C33))))) -> FALSE | M36: =IF($L36=FALSE(),"",COUNTIF($L$6:$L36,TRUE())) | N36: =IF($M36="","","R"&$M36)
A37: =IF($B37="","",32) | B37: =IFERROR(INDEX(원자재마스터!$A$3:$A$502,MATCH("R"&32,규격검색!$N$6:$N$505,0)),"") | C37: =IF($B37="","",IFERROR(INDEX(원자재마스터!$B$3:$B$502,MATCH("R"&32,규격검색!$N$6:$N$505,0)),"")) | D37: =IF($B37="","",IFERROR(INDEX(원자재마스터!$C$3:$C$502,MATCH("R"&32,규격검색!$N$6:$N$505,0)),"")) | E37: =IF($B37="","",IFERROR(INDEX(원자재마스터!$G$3:$G$502,MATCH("R"&32,규격검색!$N$6:$N$505,0)),"")) | F37: =IF($B37="","",IFERROR(INDEX(원자재마스터!$I$3:$I$502,MATCH("R"&32,규격검색!$N$6:$N$505,0)),"")) | G37: =IF($B37="","",IFERROR(INDEX(원자재마스터!$J$3:$J$502,MATCH("R"&32,규격검색!$N$6:$N$505,0)),"")) | H37: =IF($B37="","",IFERROR(INDEX(원자재마스터!$K$3:$K$502,MATCH("R"&32,규격검색!$N$6:$N$505,0)),"")) | I37: =IF($B37="","",IFERROR(INDEX(원자재마스터!$L$3:$L$502,MATCH("R"&32,규격검색!$N$6:$N$505,0)),"")) | L37: =IF(원자재마스터!$A34="",FALSE(),AND(IF($B$3="",TRUE(),ISNUMBER(SEARCH($B$3,원자재마스터!$B34&" "&원자재마스터!$C34&" "&원자재마스터!$G34&" "&원자재마스터!$A34))),IF($E$3="",TRUE(),ISNUMBER(SEARCH($E$3,원자재마스터!$C34))))) -> FALSE | M37: =IF($L37=FALSE(),"",COUNTIF($L$6:$L37,TRUE())) | N37: =IF($M37="","","R"&$M37)
A38: =IF($B38="","",33) | B38: =IFERROR(INDEX(원자재마스터!$A$3:$A$502,MATCH("R"&33,규격검색!$N$6:$N$505,0)),"") | C38: =IF($B38="","",IFERROR(INDEX(원자재마스터!$B$3:$B$502,MATCH("R"&33,규격검색!$N$6:$N$505,0)),"")) | D38: =IF($B38="","",IFERROR(INDEX(원자재마스터!$C$3:$C$502,MATCH("R"&33,규격검색!$N$6:$N$505,0)),"")) | E38: =IF($B38="","",IFERROR(INDEX(원자재마스터!$G$3:$G$502,MATCH("R"&33,규격검색!$N$6:$N$505,0)),"")) | F38: =IF($B38="","",IFERROR(INDEX(원자재마스터!$I$3:$I$502,MATCH("R"&33,규격검색!$N$6:$N$505,0)),"")) | G38: =IF($B38="","",IFERROR(INDEX(원자재마스터!$J$3:$J$502,MATCH("R"&33,규격검색!$N$6:$N$505,0)),"")) | H38: =IF($B38="","",IFERROR(INDEX(원자재마스터!$K$3:$K$502,MATCH("R"&33,규격검색!$N$6:$N$505,0)),"")) | I38: =IF($B38="","",IFERROR(INDEX(원자재마스터!$L$3:$L$502,MATCH("R"&33,규격검색!$N$6:$N$505,0)),"")) | L38: =IF(원자재마스터!$A35="",FALSE(),AND(IF($B$3="",TRUE(),ISNUMBER(SEARCH($B$3,원자재마스터!$B35&" "&원자재마스터!$C35&" "&원자재마스터!$G35&" "&원자재마스터!$A35))),IF($E$3="",TRUE(),ISNUMBER(SEARCH($E$3,원자재마스터!$C35))))) -> FALSE | M38: =IF($L38=FALSE(),"",COUNTIF($L$6:$L38,TRUE())) | N38: =IF($M38="","","R"&$M38)
A39: =IF($B39="","",34) | B39: =IFERROR(INDEX(원자재마스터!$A$3:$A$502,MATCH("R"&34,규격검색!$N$6:$N$505,0)),"") | C39: =IF($B39="","",IFERROR(INDEX(원자재마스터!$B$3:$B$502,MATCH("R"&34,규격검색!$N$6:$N$505,0)),"")) | D39: =IF($B39="","",IFERROR(INDEX(원자재마스터!$C$3:$C$502,MATCH("R"&34,규격검색!$N$6:$N$505,0)),"")) | E39: =IF($B39="","",IFERROR(INDEX(원자재마스터!$G$3:$G$502,MATCH("R"&34,규격검색!$N$6:$N$505,0)),"")) | F39: =IF($B39="","",IFERROR(INDEX(원자재마스터!$I$3:$I$502,MATCH("R"&34,규격검색!$N$6:$N$505,0)),"")) | G39: =IF($B39="","",IFERROR(INDEX(원자재마스터!$J$3:$J$502,MATCH("R"&34,규격검색!$N$6:$N$505,0)),"")) | H39: =IF($B39="","",IFERROR(INDEX(원자재마스터!$K$3:$K$502,MATCH("R"&34,규격검색!$N$6:$N$505,0)),"")) | I39: =IF($B39="","",IFERROR(INDEX(원자재마스터!$L$3:$L$502,MATCH("R"&34,규격검색!$N$6:$N$505,0)),"")) | L39: =IF(원자재마스터!$A36="",FALSE(),AND(IF($B$3="",TRUE(),ISNUMBER(SEARCH($B$3,원자재마스터!$B36&" "&원자재마스터!$C36&" "&원자재마스터!$G36&" "&원자재마스터!$A36))),IF($E$3="",TRUE(),ISNUMBER(SEARCH($E$3,원자재마스터!$C36))))) -> FALSE | M39: =IF($L39=FALSE(),"",COUNTIF($L$6:$L39,TRUE())) | N39: =IF($M39="","","R"&$M39)
A40: =IF($B40="","",35) | B40: =IFERROR(INDEX(원자재마스터!$A$3:$A$502,MATCH("R"&35,규격검색!$N$6:$N$505,0)),"") | C40: =IF($B40="","",IFERROR(INDEX(원자재마스터!$B$3:$B$502,MATCH("R"&35,규격검색!$N$6:$N$505,0)),"")) | D40: =IF($B40="","",IFERROR(INDEX(원자재마스터!$C$3:$C$502,MATCH("R"&35,규격검색!$N$6:$N$505,0)),"")) | E40: =IF($B40="","",IFERROR(INDEX(원자재마스터!$G$3:$G$502,MATCH("R"&35,규격검색!$N$6:$N$505,0)),"")) | F40: =IF($B40="","",IFERROR(INDEX(원자재마스터!$I$3:$I$502,MATCH("R"&35,규격검색!$N$6:$N$505,0)),"")) | G40: =IF($B40="","",IFERROR(INDEX(원자재마스터!$J$3:$J$502,MATCH("R"&35,규격검색!$N$6:$N$505,0)),"")) | H40: =IF($B40="","",IFERROR(INDEX(원자재마스터!$K$3:$K$502,MATCH("R"&35,규격검색!$N$6:$N$505,0)),"")) | I40: =IF($B40="","",IFERROR(INDEX(원자재마스터!$L$3:$L$502,MATCH("R"&35,규격검색!$N$6:$N$505,0)),"")) | L40: =IF(원자재마스터!$A37="",FALSE(),AND(IF($B$3="",TRUE(),ISNUMBER(SEARCH($B$3,원자재마스터!$B37&" "&원자재마스터!$C37&" "&원자재마스터!$G37&" "&원자재마스터!$A37))),IF($E$3="",TRUE(),ISNUMBER(SEARCH($E$3,원자재마스터!$C37))))) -> FALSE | M40: =IF($L40=FALSE(),"",COUNTIF($L$6:$L40,TRUE())) | N40: =IF($M40="","","R"&$M40)
A41: =IF($B41="","",36) | B41: =IFERROR(INDEX(원자재마스터!$A$3:$A$502,MATCH("R"&36,규격검색!$N$6:$N$505,0)),"") | C41: =IF($B41="","",IFERROR(INDEX(원자재마스터!$B$3:$B$502,MATCH("R"&36,규격검색!$N$6:$N$505,0)),"")) | D41: =IF($B41="","",IFERROR(INDEX(원자재마스터!$C$3:$C$502,MATCH("R"&36,규격검색!$N$6:$N$505,0)),"")) | E41: =IF($B41="","",IFERROR(INDEX(원자재마스터!$G$3:$G$502,MATCH("R"&36,규격검색!$N$6:$N$505,0)),"")) | F41: =IF($B41="","",IFERROR(INDEX(원자재마스터!$I$3:$I$502,MATCH("R"&36,규격검색!$N$6:$N$505,0)),"")) | G41: =IF($B41="","",IFERROR(INDEX(원자재마스터!$J$3:$J$502,MATCH("R"&36,규격검색!$N$6:$N$505,0)),"")) | H41: =IF($B41="","",IFERROR(INDEX(원자재마스터!$K$3:$K$502,MATCH("R"&36,규격검색!$N$6:$N$505,0)),"")) | I41: =IF($B41="","",IFERROR(INDEX(원자재마스터!$L$3:$L$502,MATCH("R"&36,규격검색!$N$6:$N$505,0)),"")) | L41: =IF(원자재마스터!$A38="",FALSE(),AND(IF($B$3="",TRUE(),ISNUMBER(SEARCH($B$3,원자재마스터!$B38&" "&원자재마스터!$C38&" "&원자재마스터!$G38&" "&원자재마스터!$A38))),IF($E$3="",TRUE(),ISNUMBER(SEARCH($E$3,원자재마스터!$C38))))) -> FALSE | M41: =IF($L41=FALSE(),"",COUNTIF($L$6:$L41,TRUE())) | N41: =IF($M41="","","R"&$M41)
A42: =IF($B42="","",37) | B42: =IFERROR(INDEX(원자재마스터!$A$3:$A$502,MATCH("R"&37,규격검색!$N$6:$N$505,0)),"") | C42: =IF($B42="","",IFERROR(INDEX(원자재마스터!$B$3:$B$502,MATCH("R"&37,규격검색!$N$6:$N$505,0)),"")) | D42: =IF($B42="","",IFERROR(INDEX(원자재마스터!$C$3:$C$502,MATCH("R"&37,규격검색!$N$6:$N$505,0)),"")) | E42: =IF($B42="","",IFERROR(INDEX(원자재마스터!$G$3:$G$502,MATCH("R"&37,규격검색!$N$6:$N$505,0)),"")) | F42: =IF($B42="","",IFERROR(INDEX(원자재마스터!$I$3:$I$502,MATCH("R"&37,규격검색!$N$6:$N$505,0)),"")) | G42: =IF($B42="","",IFERROR(INDEX(원자재마스터!$J$3:$J$502,MATCH("R"&37,규격검색!$N$6:$N$505,0)),"")) | H42: =IF($B42="","",IFERROR(INDEX(원자재마스터!$K$3:$K$502,MATCH("R"&37,규격검색!$N$6:$N$505,0)),"")) | I42: =IF($B42="","",IFERROR(INDEX(원자재마스터!$L$3:$L$502,MATCH("R"&37,규격검색!$N$6:$N$505,0)),"")) | L42: =IF(원자재마스터!$A39="",FALSE(),AND(IF($B$3="",TRUE(),ISNUMBER(SEARCH($B$3,원자재마스터!$B39&" "&원자재마스터!$C39&" "&원자재마스터!$G39&" "&원자재마스터!$A39))),IF($E$3="",TRUE(),ISNUMBER(SEARCH($E$3,원자재마스터!$C39))))) -> FALSE | M42: =IF($L42=FALSE(),"",COUNTIF($L$6:$L42,TRUE())) | N42: =IF($M42="","","R"&$M42)
...

Sheet 규격비교
A1: 규격비교 (최대 6개를 나란히 비교)
A3: 품번 선택 → | B3: R001 | C3: R002 | D3: R003
A5: 품명 | B5: =IF($B$3="","",IFERROR(INDEX(원자재마스터!$B$3:$B$502,MATCH($B$3,원자재마스터!$A$3:$A$502,0)),"")) -> 열연강판 | C5: =IF($C$3="","",IFERROR(INDEX(원자재마스터!$B$3:$B$502,MATCH($C$3,원자재마스터!$A$3:$A$502,0)),"")) -> 열연강판 | D5: =IF($D$3="","",IFERROR(INDEX(원자재마스터!$B$3:$B$502,MATCH($D$3,원자재마스터!$A$3:$A$502,0)),"")) -> 알루미늄판 | E5: =IF($E$3="","",IFERROR(INDEX(원자재마스터!$B$3:$B$502,MATCH($E$3,원자재마스터!$A$3:$A$502,0)),"")) | F5: =IF($F$3="","",IFERROR(INDEX(원자재마스터!$B$3:$B$502,MATCH($F$3,원자재마스터!$A$3:$A$502,0)),"")) | G5: =IF($G$3="","",IFERROR(INDEX(원자재마스터!$B$3:$B$502,MATCH($G$3,원자재마스터!$A$3:$A$502,0)),""))
A6: 재질 | B6: =IF($B$3="","",IFERROR(INDEX(원자재마스터!$C$3:$C$502,MATCH($B$3,원자재마스터!$A$3:$A$502,0)),"")) -> SS400 | C6: =IF($C$3="","",IFERROR(INDEX(원자재마스터!$C$3:$C$502,MATCH($C$3,원자재마스터!$A$3:$A$502,0)),"")) -> SS400 | D6: =IF($D$3="","",IFERROR(INDEX(원자재마스터!$C$3:$C$502,MATCH($D$3,원자재마스터!$A$3:$A$502,0)),"")) -> A5052 | E6: =IF($E$3="","",IFERROR(INDEX(원자재마스터!$C$3:$C$502,MATCH($E$3,원자재마스터!$A$3:$A$502,0)),"")) | F6: =IF($F$3="","",IFERROR(INDEX(원자재마스터!$C$3:$C$502,MATCH($F$3,원자재마스터!$A$3:$A$502,0)),"")) | G6: =IF($G$3="","",IFERROR(INDEX(원자재마스터!$C$3:$C$502,MATCH($G$3,원자재마스터!$A$3:$A$502,0)),""))
A7: 규격 | B7: =IF($B$3="","",IFERROR(INDEX(원자재마스터!$G$3:$G$502,MATCH($B$3,원자재마스터!$A$3:$A$502,0)),"")) -> 1000 × 500 × 3.2t | C7: =IF($C$3="","",IFERROR(INDEX(원자재마스터!$G$3:$G$502,MATCH($C$3,원자재마스터!$A$3:$A$502,0)),"")) -> 1200 × 600 × 4.5t | D7: =IF($D$3="","",IFERROR(INDEX(원자재마스터!$G$3:$G$502,MATCH($D$3,원자재마스터!$A$3:$A$502,0)),"")) -> 1000 × 500 × 2t | E7: =IF($E$3="","",IFERROR(INDEX(원자재마스터!$G$3:$G$502,MATCH($E$3,원자재마스터!$A$3:$A$502,0)),"")) | F7: =IF($F$3="","",IFERROR(INDEX(원자재마스터!$G$3:$G$502,MATCH($F$3,원자재마스터!$A$3:$A$502,0)),"")) | G7: =IF($G$3="","",IFERROR(INDEX(원자재마스터!$G$3:$G$502,MATCH($G$3,원자재마스터!$A$3:$A$502,0)),""))
A8: 길이(mm) | B8: =IF($B$3="","",IFERROR(INDEX(원자재마스터!$D$3:$D$502,MATCH($B$3,원자재마스터!$A$3:$A$502,0)),"")) -> 1000 | C8: =IF($C$3="","",IFERROR(INDEX(원자재마스터!$D$3:$D$502,MATCH($C$3,원자재마스터!$A$3:$A$502,0)),"")) -> 1200 | D8: =IF($D$3="","",IFERROR(INDEX(원자재마스터!$D$3:$D$502,MATCH($D$3,원자재마스터!$A$3:$A$502,0)),"")) -> 1000 | E8: =IF($E$3="","",IFERROR(INDEX(원자재마스터!$D$3:$D$502,MATCH($E$3,원자재마스터!$A$3:$A$502,0)),"")) | F8: =IF($F$3="","",IFERROR(INDEX(원자재마스터!$D$3:$D$502,MATCH($F$3,원자재마스터!$A$3:$A$502,0)),"")) | G8: =IF($G$3="","",IFERROR(INDEX(원자재마스터!$D$3:$D$502,MATCH($G$3,원자재마스터!$A$3:$A$502,0)),""))
A9: 폭(mm) | B9: =IF($B$3="","",IFERROR(INDEX(원자재마스터!$E$3:$E$502,MATCH($B$3,원자재마스터!$A$3:$A$502,0)),"")) -> 500 | C9: =IF($C$3="","",IFERROR(INDEX(원자재마스터!$E$3:$E$502,MATCH($C$3,원자재마스터!$A$3:$A$502,0)),"")) -> 600 | D9: =IF($D$3="","",IFERROR(INDEX(원자재마스터!$E$3:$E$502,MATCH($D$3,원자재마스터!$A$3:$A$502,0)),"")) -> 500 | E9: =IF($E$3="","",IFERROR(INDEX(원자재마스터!$E$3:$E$502,MATCH($E$3,원자재마스터!$A$3:$A$502,0)),"")) | F9: =IF($F$3="","",IFERROR(INDEX(원자재마스터!$E$3:$E$502,MATCH($F$3,원자재마스터!$A$3:$A$502,0)),"")) | G9: =IF($G$3="","",IFERROR(INDEX(원자재마스터!$E$3:$E$502,MATCH($G$3,원자재마스터!$A$3:$A$502,0)),""))
A10: 두께(mm) | B10: =IF($B$3="","",IFERROR(INDEX(원자재마스터!$F$3:$F$502,MATCH($B$3,원자재마스터!$A$3:$A$502,0)),"")) -> 3.2 | C10: =IF($C$3="","",IFERROR(INDEX(원자재마스터!$F$3:$F$502,MATCH($C$3,원자재마스터!$A$3:$A$502,0)),"")) -> 4.5 | D10: =IF($D$3="","",IFERROR(INDEX(원자재마스터!$F$3:$F$502,MATCH($D$3,원자재마스터!$A$3:$A$502,0)),"")) -> 2 | E10: =IF($E$3="","",IFERROR(INDEX(원자재마스터!$F$3:$F$502,MATCH($E$3,원자재마스터!$A$3:$A$502,0)),"")) | F10: =IF($F$3="","",IFERROR(INDEX(원자재마스터!$F$3:$F$502,MATCH($F$3,원자재마스터!$A$3:$A$502,0)),"")) | G10: =IF($G$3="","",IFERROR(INDEX(원자재마스터!$F$3:$F$502,MATCH($G$3,원자재마스터!$A$3:$A$502,0)),""))
A11: 장당중량kg | B11: =IF($B$3="","",IFERROR(INDEX(원자재마스터!$I$3:$I$502,MATCH($B$3,원자재마스터!$A$3:$A$502,0)),"")) -> 12.56 | C11: =IF($C$3="","",IFERROR(INDEX(원자재마스터!$I$3:$I$502,MATCH($C$3,원자재마스터!$A$3:$A$502,0)),"")) -> 25.43 | D11: =IF($D$3="","",IFERROR(INDEX(원자재마스터!$I$3:$I$502,MATCH($D$3,원자재마스터!$A$3:$A$502,0)),"")) -> 2.7 | E11: =IF($E$3="","",IFERROR(INDEX(원자재마스터!$I$3:$I$502,MATCH($E$3,원자재마스터!$A$3:$A$502,0)),"")) | F11: =IF($F$3="","",IFERROR(INDEX(원자재마스터!$I$3:$I$502,MATCH($F$3,원자재마스터!$A$3:$A$502,0)),"")) | G11: =IF($G$3="","",IFERROR(INDEX(원자재마스터!$I$3:$I$502,MATCH($G$3,원자재마스터!$A$3:$A$502,0)),""))
A12: 단위 | B12: =IF($B$3="","",IFERROR(INDEX(원자재마스터!$J$3:$J$502,MATCH($B$3,원자재마스터!$A$3:$A$502,0)),"")) -> EA | C12: =IF($C$3="","",IFERROR(INDEX(원자재마스터!$J$3:$J$502,MATCH($C$3,원자재마스터!$A$3:$A$502,0)),"")) -> EA | D12: =IF($D$3="","",IFERROR(INDEX(원자재마스터!$J$3:$J$502,MATCH($D$3,원자재마스터!$A$3:$A$502,0)),"")) -> EA | E12: =IF($E$3="","",IFERROR(INDEX(원자재마스터!$J$3:$J$502,MATCH($E$3,원자재마스터!$A$3:$A$502,0)),"")) | F12: =IF($F$3="","",IFERROR(INDEX(원자재마스터!$J$3:$J$502,MATCH($F$3,원자재마스터!$A$3:$A$502,0)),"")) | G12: =IF($G$3="","",IFERROR(INDEX(원자재마스터!$J$3:$J$502,MATCH($G$3,원자재마스터!$A$3:$A$502,0)),""))
A13: 표준단가 | B13: =IF($B$3="","",IFERROR(INDEX(원자재마스터!$K$3:$K$502,MATCH($B$3,원자재마스터!$A$3:$A$502,0)),"")) -> 18500 | C13: =IF($C$3="","",IFERROR(INDEX(원자재마스터!$K$3:$K$502,MATCH($C$3,원자재마스터!$A$3:$A$502,0)),"")) -> 34200 | D13: =IF($D$3="","",IFERROR(INDEX(원자재마스터!$K$3:$K$502,MATCH($D$3,원자재마스터!$A$3:$A$502,0)),"")) -> 26000 | E13: =IF($E$3="","",IFERROR(INDEX(원자재마스터!$K$3:$K$502,MATCH($E$3,원자재마스터!$A$3:$A$502,0)),"")) | F13: =IF($F$3="","",IFERROR(INDEX(원자재마스터!$K$3:$K$502,MATCH($F$3,원자재마스터!$A$3:$A$502,0)),"")) | G13: =IF($G$3="","",IFERROR(INDEX(원자재마스터!$K$3:$K$502,MATCH($G$3,원자재마스터!$A$3:$A$502,0)),""))
A14: 주거래처 | B14: =IF($B$3="","",IFERROR(INDEX(원자재마스터!$L$3:$L$502,MATCH($B$3,원자재마스터!$A$3:$A$502,0)),"")) -> ○○철강 | C14: =IF($C$3="","",IFERROR(INDEX(원자재마스터!$L$3:$L$502,MATCH($C$3,원자재마스터!$A$3:$A$502,0)),"")) -> ○○철강 | D14: =IF($D$3="","",IFERROR(INDEX(원자재마스터!$L$3:$L$502,MATCH($D$3,원자재마스터!$A$3:$A$502,0)),"")) -> △△금속 | E14: =IF($E$3="","",IFERROR(INDEX(원자재마스터!$L$3:$L$502,MATCH($E$3,원자재마스터!$A$3:$A$502,0)),"")) | F14: =IF($F$3="","",IFERROR(INDEX(원자재마스터!$L$3:$L$502,MATCH($F$3,원자재마스터!$A$3:$A$502,0)),"")) | G14: =IF($G$3="","",IFERROR(INDEX(원자재마스터!$L$3:$L$502,MATCH($G$3,원자재마스터!$A$3:$A$502,0)),""))
A16: kg당 단가 | B16: =IF(OR($B$3="",B11="",B11=0),"",ROUND(B13/B11,0)) -> 1473 | C16: =IF(OR($C$3="",C11="",C11=0),"",ROUND(C13/C11,0)) -> 1345 | D16: =IF(OR($D$3="",D11="",D11=0),"",ROUND(D13/D11,0)) -> 9630 | E16: =IF(OR($E$3="",E11="",E11=0),"",ROUND(E13/E11,0)) | F16: =IF(OR($F$3="",F11="",F11=0),"",ROUND(F13/F11,0)) | G16: =IF(OR($G$3="",G11="",G11=0),"",ROUND(G13/G11,0))
A18: ※ kg당 단가 = 표준단가 ÷ 장당중량. 어느 쪽이 싼지 비교할 때 씁니다.

Sheet 거래처별목록
A1: 거래처별목록
A3: 거래처 | B3: ○○철강 | D3: 품목 수 | E3: =COUNTIF($J$6:$J$505,TRUE()) -> 2 | F3: ← 거래처명을 정확히 넣으세요
A5: 순번 | B5: 품번 | C5: 품명 | D5: 재질 | E5: 규격 | F5: 단위 | G5: 표준단가
A6: =IF($B6="","",1) -> 1 | B6: =IFERROR(INDEX(원자재마스터!$A$3:$A$502,MATCH("R"&1,거래처별목록!$L$6:$L$505,0)),"") -> R001 | C6: =IF($B6="","",IFERROR(INDEX(원자재마스터!$B$3:$B$502,MATCH("R"&1,거래처별목록!$L$6:$L$505,0)),"")) -> 열연강판 | D6: =IF($B6="","",IFERROR(INDEX(원자재마스터!$C$3:$C$502,MATCH("R"&1,거래처별목록!$L$6:$L$505,0)),"")) -> SS400 | E6: =IF($B6="","",IFERROR(INDEX(원자재마스터!$G$3:$G$502,MATCH("R"&1,거래처별목록!$L$6:$L$505,0)),"")) -> 1000 × 500 × 3.2t | F6: =IF($B6="","",IFERROR(INDEX(원자재마스터!$J$3:$J$502,MATCH("R"&1,거래처별목록!$L$6:$L$505,0)),"")) -> EA | G6: =IF($B6="","",IFERROR(INDEX(원자재마스터!$K$3:$K$502,MATCH("R"&1,거래처별목록!$L$6:$L$505,0)),"")) -> 18500 | J6: =IF(원자재마스터!$A3="",FALSE(),원자재마스터!$L3=$B$3) -> TRUE | K6: =IF($J6=FALSE(),"",COUNTIF($J$6:$J6,TRUE())) -> 1 | L6: =IF($K6="","","R"&$K6) -> R1
A7: =IF($B7="","",2) -> 2 | B7: =IFERROR(INDEX(원자재마스터!$A$3:$A$502,MATCH("R"&2,거래처별목록!$L$6:$L$505,0)),"") -> R002 | C7: =IF($B7="","",IFERROR(INDEX(원자재마스터!$B$3:$B$502,MATCH("R"&2,거래처별목록!$L$6:$L$505,0)),"")) -> 열연강판 | D7: =IF($B7="","",IFERROR(INDEX(원자재마스터!$C$3:$C$502,MATCH("R"&2,거래처별목록!$L$6:$L$505,0)),"")) -> SS400 | E7: =IF($B7="","",IFERROR(INDEX(원자재마스터!$G$3:$G$502,MATCH("R"&2,거래처별목록!$L$6:$L$505,0)),"")) -> 1200 × 600 × 4.5t | F7: =IF($B7="","",IFERROR(INDEX(원자재마스터!$J$3:$J$502,MATCH("R"&2,거래처별목록!$L$6:$L$505,0)),"")) -> EA | G7: =IF($B7="","",IFERROR(INDEX(원자재마스터!$K$3:$K$502,MATCH("R"&2,거래처별목록!$L$6:$L$505,0)),"")) -> 34200 | J7: =IF(원자재마스터!$A4="",FALSE(),원자재마스터!$L4=$B$3) -> TRUE | K7: =IF($J7=FALSE(),"",COUNTIF($J$6:$J7,TRUE())) -> 2 | L7: =IF($K7="","","R"&$K7) -> R2
A8: =IF($B8="","",3) | B8: =IFERROR(INDEX(원자재마스터!$A$3:$A$502,MATCH("R"&3,거래처별목록!$L$6:$L$505,0)),"") | C8: =IF($B8="","",IFERROR(INDEX(원자재마스터!$B$3:$B$502,MATCH("R"&3,거래처별목록!$L$6:$L$505,0)),"")) | D8: =IF($B8="","",IFERROR(INDEX(원자재마스터!$C$3:$C$502,MATCH("R"&3,거래처별목록!$L$6:$L$505,0)),"")) | E8: =IF($B8="","",IFERROR(INDEX(원자재마스터!$G$3:$G$502,MATCH("R"&3,거래처별목록!$L$6:$L$505,0)),"")) | F8: =IF($B8="","",IFERROR(INDEX(원자재마스터!$J$3:$J$502,MATCH("R"&3,거래처별목록!$L$6:$L$505,0)),"")) | G8: =IF($B8="","",IFERROR(INDEX(원자재마스터!$K$3:$K$502,MATCH("R"&3,거래처별목록!$L$6:$L$505,0)),"")) | J8: =IF(원자재마스터!$A5="",FALSE(),원자재마스터!$L5=$B$3) -> FALSE | K8: =IF($J8=FALSE(),"",COUNTIF($J$6:$J8,TRUE())) | L8: =IF($K8="","","R"&$K8)
A9: =IF($B9="","",4) | B9: =IFERROR(INDEX(원자재마스터!$A$3:$A$502,MATCH("R"&4,거래처별목록!$L$6:$L$505,0)),"") | C9: =IF($B9="","",IFERROR(INDEX(원자재마스터!$B$3:$B$502,MATCH("R"&4,거래처별목록!$L$6:$L$505,0)),"")) | D9: =IF($B9="","",IFERROR(INDEX(원자재마스터!$C$3:$C$502,MATCH("R"&4,거래처별목록!$L$6:$L$505,0)),"")) | E9: =IF($B9="","",IFERROR(INDEX(원자재마스터!$G$3:$G$502,MATCH("R"&4,거래처별목록!$L$6:$L$505,0)),"")) | F9: =IF($B9="","",IFERROR(INDEX(원자재마스터!$J$3:$J$502,MATCH("R"&4,거래처별목록!$L$6:$L$505,0)),"")) | G9: =IF($B9="","",IFERROR(INDEX(원자재마스터!$K$3:$K$502,MATCH("R"&4,거래처별목록!$L$6:$L$505,0)),"")) | J9: =IF(원자재마스터!$A6="",FALSE(),원자재마스터!$L6=$B$3) -> FALSE | K9: =IF($J9=FALSE(),"",COUNTIF($J$6:$J9,TRUE())) | L9: =IF($K9="","","R"&$K9)
A10: =IF($B10="","",5) | B10: =IFERROR(INDEX(원자재마스터!$A$3:$A$502,MATCH("R"&5,거래처별목록!$L$6:$L$505,0)),"") | C10: =IF($B10="","",IFERROR(INDEX(원자재마스터!$B$3:$B$502,MATCH("R"&5,거래처별목록!$L$6:$L$505,0)),"")) | D10: =IF($B10="","",IFERROR(INDEX(원자재마스터!$C$3:$C$502,MATCH("R"&5,거래처별목록!$L$6:$L$505,0)),"")) | E10: =IF($B10="","",IFERROR(INDEX(원자재마스터!$G$3:$G$502,MATCH("R"&5,거래처별목록!$L$6:$L$505,0)),"")) | F10: =IF($B10="","",IFERROR(INDEX(원자재마스터!$J$3:$J$502,MATCH("R"&5,거래처별목록!$L$6:$L$505,0)),"")) | G10: =IF($B10="","",IFERROR(INDEX(원자재마스터!$K$3:$K$502,MATCH("R"&5,거래처별목록!$L$6:$L$505,0)),"")) | J10: =IF(원자재마스터!$A7="",FALSE(),원자재마스터!$L7=$B$3) -> FALSE | K10: =IF($J10=FALSE(),"",COUNTIF($J$6:$J10,TRUE())) | L10: =IF($K10="","","R"&$K10)
A11: =IF($B11="","",6) | B11: =IFERROR(INDEX(원자재마스터!$A$3:$A$502,MATCH("R"&6,거래처별목록!$L$6:$L$505,0)),"") | C11: =IF($B11="","",IFERROR(INDEX(원자재마스터!$B$3:$B$502,MATCH("R"&6,거래처별목록!$L$6:$L$505,0)),"")) | D11: =IF($B11="","",IFERROR(INDEX(원자재마스터!$C$3:$C$502,MATCH("R"&6,거래처별목록!$L$6:$L$505,0)),"")) | E11: =IF($B11="","",IFERROR(INDEX(원자재마스터!$G$3:$G$502,MATCH("R"&6,거래처별목록!$L$6:$L$505,0)),"")) | F11: =IF($B11="","",IFERROR(INDEX(원자재마스터!$J$3:$J$502,MATCH("R"&6,거래처별목록!$L$6:$L$505,0)),"")) | G11: =IF($B11="","",IFERROR(INDEX(원자재마스터!$K$3:$K$502,MATCH("R"&6,거래처별목록!$L$6:$L$505,0)),"")) | J11: =IF(원자재마스터!$A8="",FALSE(),원자재마스터!$L8=$B$3) -> FALSE | K11: =IF($J11=FALSE(),"",COUNTIF($J$6:$J11,TRUE())) | L11: =IF($K11="","","R"&$K11)
A12: =IF($B12="","",7) | B12: =IFERROR(INDEX(원자재마스터!$A$3:$A$502,MATCH("R"&7,거래처별목록!$L$6:$L$505,0)),"") | C12: =IF($B12="","",IFERROR(INDEX(원자재마스터!$B$3:$B$502,MATCH("R"&7,거래처별목록!$L$6:$L$505,0)),"")) | D12: =IF($B12="","",IFERROR(INDEX(원자재마스터!$C$3:$C$502,MATCH("R"&7,거래처별목록!$L$6:$L$505,0)),"")) | E12: =IF($B12="","",IFERROR(INDEX(원자재마스터!$G$3:$G$502,MATCH("R"&7,거래처별목록!$L$6:$L$505,0)),"")) | F12: =IF($B12="","",IFERROR(INDEX(원자재마스터!$J$3:$J$502,MATCH("R"&7,거래처별목록!$L$6:$L$505,0)),"")) | G12: =IF($B12="","",IFERROR(INDEX(원자재마스터!$K$3:$K$502,MATCH("R"&7,거래처별목록!$L$6:$L$505,0)),"")) | J12: =IF(원자재마스터!$A9="",FALSE(),원자재마스터!$L9=$B$3) -> FALSE | K12: =IF($J12=FALSE(),"",COUNTIF($J$6:$J12,TRUE())) | L12: =IF($K12="","","R"&$K12)
A13: =IF($B13="","",8) | B13: =IFERROR(INDEX(원자재마스터!$A$3:$A$502,MATCH("R"&8,거래처별목록!$L$6:$L$505,0)),"") | C13: =IF($B13="","",IFERROR(INDEX(원자재마스터!$B$3:$B$502,MATCH("R"&8,거래처별목록!$L$6:$L$505,0)),"")) | D13: =IF($B13="","",IFERROR(INDEX(원자재마스터!$C$3:$C$502,MATCH("R"&8,거래처별목록!$L$6:$L$505,0)),"")) | E13: =IF($B13="","",IFERROR(INDEX(원자재마스터!$G$3:$G$502,MATCH("R"&8,거래처별목록!$L$6:$L$505,0)),"")) | F13: =IF($B13="","",IFERROR(INDEX(원자재마스터!$J$3:$J$502,MATCH("R"&8,거래처별목록!$L$6:$L$505,0)),"")) | G13: =IF($B13="","",IFERROR(INDEX(원자재마스터!$K$3:$K$502,MATCH("R"&8,거래처별목록!$L$6:$L$505,0)),"")) | J13: =IF(원자재마스터!$A10="",FALSE(),원자재마스터!$L10=$B$3) -> FALSE | K13: =IF($J13=FALSE(),"",COUNTIF($J$6:$J13,TRUE())) | L13: =IF($K13="","","R"&$K13)
A14: =IF($B14="","",9) | B14: =IFERROR(INDEX(원자재마스터!$A$3:$A$502,MATCH("R"&9,거래처별목록!$L$6:$L$505,0)),"") | C14: =IF($B14="","",IFERROR(INDEX(원자재마스터!$B$3:$B$502,MATCH("R"&9,거래처별목록!$L$6:$L$505,0)),"")) | D14: =IF($B14="","",IFERROR(INDEX(원자재마스터!$C$3:$C$502,MATCH("R"&9,거래처별목록!$L$6:$L$505,0)),"")) | E14: =IF($B14="","",IFERROR(INDEX(원자재마스터!$G$3:$G$502,MATCH("R"&9,거래처별목록!$L$6:$L$505,0)),"")) | F14: =IF($B14="","",IFERROR(INDEX(원자재마스터!$J$3:$J$502,MATCH("R"&9,거래처별목록!$L$6:$L$505,0)),"")) | G14: =IF($B14="","",IFERROR(INDEX(원자재마스터!$K$3:$K$502,MATCH("R"&9,거래처별목록!$L$6:$L$505,0)),"")) | J14: =IF(원자재마스터!$A11="",FALSE(),원자재마스터!$L11=$B$3) -> FALSE | K14: =IF($J14=FALSE(),"",COUNTIF($J$6:$J14,TRUE())) | L14: =IF($K14="","","R"&$K14)
A15: =IF($B15="","",10) | B15: =IFERROR(INDEX(원자재마스터!$A$3:$A$502,MATCH("R"&10,거래처별목록!$L$6:$L$505,0)),"") | C15: =IF($B15="","",IFERROR(INDEX(원자재마스터!$B$3:$B$502,MATCH("R"&10,거래처별목록!$L$6:$L$505,0)),"")) | D15: =IF($B15="","",IFERROR(INDEX(원자재마스터!$C$3:$C$502,MATCH("R"&10,거래처별목록!$L$6:$L$505,0)),"")) | E15: =IF($B15="","",IFERROR(INDEX(원자재마스터!$G$3:$G$502,MATCH("R"&10,거래처별목록!$L$6:$L$505,0)),"")) | F15: =IF($B15="","",IFERROR(INDEX(원자재마스터!$J$3:$J$502,MATCH("R"&10,거래처별목록!$L$6:$L$505,0)),"")) | G15: =IF($B15="","",IFERROR(INDEX(원자재마스터!$K$3:$K$502,MATCH("R"&10,거래처별목록!$L$6:$L$505,0)),"")) | J15: =IF(원자재마스터!$A12="",FALSE(),원자재마스터!$L12=$B$3) -> FALSE | K15: =IF($J15=FALSE(),"",COUNTIF($J$6:$J15,TRUE())) | L15: =IF($K15="","","R"&$K15)
