Workbook

Sheet 사용안내
B2: 직원 교육 · 자격 이수 관리
B4: 핵심 | C4: 이수일과 주기만 넣으면 다음 이수 기한이 자동으로 계산되고, 기한이 다가오면 알려줍니다.
B5: 입력 규칙 | C5: 파란색 글씨 칸만 입력하세요. 검은색은 자동 계산입니다.
B6: ① 직원목록 | C6: 사번·이름·부서·입사일을 등록합니다.
B7: ② 교육과정 | C7: 과정명과 이수 주기(개월)를 등록합니다. 주기는 회사가 정한 값을 넣으세요.
B8: ③ 이수내역 | C8: 교육을 받을 때마다 한 줄. 사번·과정명·이수일만 넣으면 됩니다.
B9: ④ 이수현황 | C9: 직원 × 과정별로 최근 이수일과 다음 기한이 나옵니다.
B10: ⑤ 미이수현황 | C10: 기한이 지났거나 임박한 것만 모아서 보여줍니다.
B11: ⑥ 과정별집계 | C11: 과정별 이수 인원과 이수율입니다.
B12: 다음 기한 계산 | C12: 최근 이수일 + 주기(개월). 한 번도 안 받았으면 입사일 기준입니다.
B13: 주의 | C13: 법정 의무교육의 주기와 대상은 법으로 정해져 있습니다. 이 파일은 주기를 검증하지 않습니다.
B15: 설정 | C15: 값을 바꾸면 모든 계산에 반영됩니다
B16: 기한 임박 기준(일) | C16: 30
B18: ※ 산업안전보건교육·성희롱예방교육 등의 법정 주기는 고용노동부 기준을 직접 확인하고 입력하세요.

Sheet 직원목록
A1: 직원목록
A2: 사번 | B2: 이름 | C2: 부서 | D2: 직위 | E2: 입사일 | F2: 재직상태
A3: E001 | B3: 김직원 | C3: 생산1팀 | D3: 사원 | E3: 45353 | F3: 재직
A4: E002 | B4: 이직원 | C4: 생산1팀 | D4: 주임 | E4: 45061 | F4: 재직
A5: E003 | B5: 박직원 | C5: 관리팀 | D5: 대리 | E5: 44571 | F5: 재직

Sheet 교육과정
A1: 교육과정 (주기는 회사·법령 기준을 확인하고 넣으세요)
A2: 과정코드 | B2: 과정명 | C2: 주기(개월) | D2: 이수시간 | E2: 구분 | F2: 비고
A3: C01 | B3: 산업안전보건교육 | C3: 3 | D3: 6 | E3: 법정
A4: C02 | B4: 성희롱 예방교육 | C4: 12 | D4: 1 | E4: 법정
A5: C03 | B5: 개인정보보호 교육 | C5: 12 | D5: 2 | E5: 법정
A6: C04 | B6: 지게차 운전 자격 | C6: 24 | D6: 0 | E6: 자격

Sheet 이수내역
A1: 이수내역 (교육 받을 때마다 한 줄)
A2: 이수일 | B2: 사번 | C2: 이름(자동) | D2: 과정코드 | E2: 과정명(자동) | F2: 이수시간 | G2: 교육기관 | H2: 비고
A3: 46213 | B3: E001 | C3: =IF($B3="","",IFERROR(INDEX(직원목록!$B$3:$B$302,MATCH($B3,직원목록!$A$3:$A$302,0)),"미등록사번")) -> 김직원 | D3: C01 | E3: =IF($D3="","",IFERROR(INDEX(교육과정!$B$3:$B$102,MATCH($D3,교육과정!$A$3:$A$102,0)),"미등록과정")) -> 산업안전보건교육 | F3: 6 | G3: ○○안전교육원
A4: 46086 | B4: E001 | C4: =IF($B4="","",IFERROR(INDEX(직원목록!$B$3:$B$302,MATCH($B4,직원목록!$A$3:$A$302,0)),"미등록사번")) -> 김직원 | D4: C02 | E4: =IF($D4="","",IFERROR(INDEX(교육과정!$B$3:$B$102,MATCH($D4,교육과정!$A$3:$A$102,0)),"미등록과정")) -> 성희롱 예방교육 | F4: 1 | G4: 사내
A5: 46254 | B5: E002 | C5: =IF($B5="","",IFERROR(INDEX(직원목록!$B$3:$B$302,MATCH($B5,직원목록!$A$3:$A$302,0)),"미등록사번")) -> 이직원 | D5: C01 | E5: =IF($D5="","",IFERROR(INDEX(교육과정!$B$3:$B$102,MATCH($D5,교육과정!$A$3:$A$102,0)),"미등록과정")) -> 산업안전보건교육 | F5: 6 | G5: ○○안전교육원
A6: 45809 | B6: E003 | C6: =IF($B6="","",IFERROR(INDEX(직원목록!$B$3:$B$302,MATCH($B6,직원목록!$A$3:$A$302,0)),"미등록사번")) -> 박직원 | D6: C02 | E6: =IF($D6="","",IFERROR(INDEX(교육과정!$B$3:$B$102,MATCH($D6,교육과정!$A$3:$A$102,0)),"미등록과정")) -> 성희롱 예방교육 | F6: 1 | G6: 사내
C7: =IF($B7="","",IFERROR(INDEX(직원목록!$B$3:$B$302,MATCH($B7,직원목록!$A$3:$A$302,0)),"미등록사번")) | E7: =IF($D7="","",IFERROR(INDEX(교육과정!$B$3:$B$102,MATCH($D7,교육과정!$A$3:$A$102,0)),"미등록과정"))
C8: =IF($B8="","",IFERROR(INDEX(직원목록!$B$3:$B$302,MATCH($B8,직원목록!$A$3:$A$302,0)),"미등록사번")) | E8: =IF($D8="","",IFERROR(INDEX(교육과정!$B$3:$B$102,MATCH($D8,교육과정!$A$3:$A$102,0)),"미등록과정"))
C9: =IF($B9="","",IFERROR(INDEX(직원목록!$B$3:$B$302,MATCH($B9,직원목록!$A$3:$A$302,0)),"미등록사번")) | E9: =IF($D9="","",IFERROR(INDEX(교육과정!$B$3:$B$102,MATCH($D9,교육과정!$A$3:$A$102,0)),"미등록과정"))
C10: =IF($B10="","",IFERROR(INDEX(직원목록!$B$3:$B$302,MATCH($B10,직원목록!$A$3:$A$302,0)),"미등록사번")) | E10: =IF($D10="","",IFERROR(INDEX(교육과정!$B$3:$B$102,MATCH($D10,교육과정!$A$3:$A$102,0)),"미등록과정"))
C11: =IF($B11="","",IFERROR(INDEX(직원목록!$B$3:$B$302,MATCH($B11,직원목록!$A$3:$A$302,0)),"미등록사번")) | E11: =IF($D11="","",IFERROR(INDEX(교육과정!$B$3:$B$102,MATCH($D11,교육과정!$A$3:$A$102,0)),"미등록과정"))
C12: =IF($B12="","",IFERROR(INDEX(직원목록!$B$3:$B$302,MATCH($B12,직원목록!$A$3:$A$302,0)),"미등록사번")) | E12: =IF($D12="","",IFERROR(INDEX(교육과정!$B$3:$B$102,MATCH($D12,교육과정!$A$3:$A$102,0)),"미등록과정"))
C13: =IF($B13="","",IFERROR(INDEX(직원목록!$B$3:$B$302,MATCH($B13,직원목록!$A$3:$A$302,0)),"미등록사번")) | E13: =IF($D13="","",IFERROR(INDEX(교육과정!$B$3:$B$102,MATCH($D13,교육과정!$A$3:$A$102,0)),"미등록과정"))
C14: =IF($B14="","",IFERROR(INDEX(직원목록!$B$3:$B$302,MATCH($B14,직원목록!$A$3:$A$302,0)),"미등록사번")) | E14: =IF($D14="","",IFERROR(INDEX(교육과정!$B$3:$B$102,MATCH($D14,교육과정!$A$3:$A$102,0)),"미등록과정"))
C15: =IF($B15="","",IFERROR(INDEX(직원목록!$B$3:$B$302,MATCH($B15,직원목록!$A$3:$A$302,0)),"미등록사번")) | E15: =IF($D15="","",IFERROR(INDEX(교육과정!$B$3:$B$102,MATCH($D15,교육과정!$A$3:$A$102,0)),"미등록과정"))
C16: =IF($B16="","",IFERROR(INDEX(직원목록!$B$3:$B$302,MATCH($B16,직원목록!$A$3:$A$302,0)),"미등록사번")) | E16: =IF($D16="","",IFERROR(INDEX(교육과정!$B$3:$B$102,MATCH($D16,교육과정!$A$3:$A$102,0)),"미등록과정"))
C17: =IF($B17="","",IFERROR(INDEX(직원목록!$B$3:$B$302,MATCH($B17,직원목록!$A$3:$A$302,0)),"미등록사번")) | E17: =IF($D17="","",IFERROR(INDEX(교육과정!$B$3:$B$102,MATCH($D17,교육과정!$A$3:$A$102,0)),"미등록과정"))
C18: =IF($B18="","",IFERROR(INDEX(직원목록!$B$3:$B$302,MATCH($B18,직원목록!$A$3:$A$302,0)),"미등록사번")) | E18: =IF($D18="","",IFERROR(INDEX(교육과정!$B$3:$B$102,MATCH($D18,교육과정!$A$3:$A$102,0)),"미등록과정"))
... C2002: =IF($B2002="","",IFERROR(INDEX(직원목록!$B$3:$B$302,MATCH($B2002,직원목록!$A$3:$A$302,0)),"미등록사번")) | E2002: =IF($D2002="","",IFERROR(INDEX(교육과정!$B$3:$B$102,MATCH($D2002,교육과정!$A$3:$A$102,0)),"미등록과정"))

Sheet 이수현황
A1: 이수현황 (직원 × 과정)
A3: 오늘 | B3: =TODAY() -> 46279 | D3: 기한초과 | E3: =COUNTIF($J$6:$J$485,"기한초과") -> 9 | G3: 임박 | H3: =COUNTIF($J$6:$J$485,"임박") -> 1
A5: 사번 | B5: 이름 | C5: 부서 | D5: 과정코드 | E5: 과정명 | F5: 주기(개월) | G5: 최근 이수일 | H5: 다음 기한 | I5: D-Day | J5: 상태
A6: =IF(OR(직원목록!$A3="",교육과정!$A3="",직원목록!$F3="퇴사"),"",직원목록!$A3) -> E001 | B6: =IF($A6="","",직원목록!$B3) -> 김직원 | C6: =IF($A6="","",직원목록!$C3) -> 생산1팀 | D6: =IF($A6="","",교육과정!$A3) -> C01 | E6: =IF($A6="","",교육과정!$B3) -> 산업안전보건교육 | F6: =IF($A6="","",교육과정!$C3) -> 3 | G6: =IF($A6="","",IF(COUNTIFS(이수내역!$B$3:$B$2002,$A6,이수내역!$D$3:$D$2002,$D6)=0,"",SUMPRODUCT(MAX((이수내역!$B$3:$B$2002=$A6)*(이수내역!$D$3:$D$2002=$D6)*이수내역!$A$3:$A$2002)))) -> 46213 | H6: =IF($A6="","",IF($F6="","",IF($G6="",EDATE(직원목록!$E3,$F6),EDATE($G6,$F6)))) -> 46305 | I6: =IF($H6="","",$H6-TODAY()) -> 26 | J6: =IF($A6="","",IF($H6="","-",IF($I6<0,"기한초과",IF($I6<=사용안내!$C$16,"임박","정상")))) -> 임박
A7: =IF(OR(직원목록!$A3="",교육과정!$A4="",직원목록!$F3="퇴사"),"",직원목록!$A3) -> E001 | B7: =IF($A7="","",직원목록!$B3) -> 김직원 | C7: =IF($A7="","",직원목록!$C3) -> 생산1팀 | D7: =IF($A7="","",교육과정!$A4) -> C02 | E7: =IF($A7="","",교육과정!$B4) -> 성희롱 예방교육 | F7: =IF($A7="","",교육과정!$C4) -> 12 | G7: =IF($A7="","",IF(COUNTIFS(이수내역!$B$3:$B$2002,$A7,이수내역!$D$3:$D$2002,$D7)=0,"",SUMPRODUCT(MAX((이수내역!$B$3:$B$2002=$A7)*(이수내역!$D$3:$D$2002=$D7)*이수내역!$A$3:$A$2002)))) -> 46086 | H7: =IF($A7="","",IF($F7="","",IF($G7="",EDATE(직원목록!$E3,$F7),EDATE($G7,$F7)))) -> 46451 | I7: =IF($H7="","",$H7-TODAY()) -> 172 | J7: =IF($A7="","",IF($H7="","-",IF($I7<0,"기한초과",IF($I7<=사용안내!$C$16,"임박","정상")))) -> 정상
A8: =IF(OR(직원목록!$A3="",교육과정!$A5="",직원목록!$F3="퇴사"),"",직원목록!$A3) -> E001 | B8: =IF($A8="","",직원목록!$B3) -> 김직원 | C8: =IF($A8="","",직원목록!$C3) -> 생산1팀 | D8: =IF($A8="","",교육과정!$A5) -> C03 | E8: =IF($A8="","",교육과정!$B5) -> 개인정보보호 교육 | F8: =IF($A8="","",교육과정!$C5) -> 12 | G8: =IF($A8="","",IF(COUNTIFS(이수내역!$B$3:$B$2002,$A8,이수내역!$D$3:$D$2002,$D8)=0,"",SUMPRODUCT(MAX((이수내역!$B$3:$B$2002=$A8)*(이수내역!$D$3:$D$2002=$D8)*이수내역!$A$3:$A$2002)))) | H8: =IF($A8="","",IF($F8="","",IF($G8="",EDATE(직원목록!$E3,$F8),EDATE($G8,$F8)))) -> 45718 | I8: =IF($H8="","",$H8-TODAY()) -> -561 | J8: =IF($A8="","",IF($H8="","-",IF($I8<0,"기한초과",IF($I8<=사용안내!$C$16,"임박","정상")))) -> 기한초과
A9: =IF(OR(직원목록!$A3="",교육과정!$A6="",직원목록!$F3="퇴사"),"",직원목록!$A3) -> E001 | B9: =IF($A9="","",직원목록!$B3) -> 김직원 | C9: =IF($A9="","",직원목록!$C3) -> 생산1팀 | D9: =IF($A9="","",교육과정!$A6) -> C04 | E9: =IF($A9="","",교육과정!$B6) -> 지게차 운전 자격 | F9: =IF($A9="","",교육과정!$C6) -> 24 | G9: =IF($A9="","",IF(COUNTIFS(이수내역!$B$3:$B$2002,$A9,이수내역!$D$3:$D$2002,$D9)=0,"",SUMPRODUCT(MAX((이수내역!$B$3:$B$2002=$A9)*(이수내역!$D$3:$D$2002=$D9)*이수내역!$A$3:$A$2002)))) | H9: =IF($A9="","",IF($F9="","",IF($G9="",EDATE(직원목록!$E3,$F9),EDATE($G9,$F9)))) -> 46083 | I9: =IF($H9="","",$H9-TODAY()) -> -196 | J9: =IF($A9="","",IF($H9="","-",IF($I9<0,"기한초과",IF($I9<=사용안내!$C$16,"임박","정상")))) -> 기한초과
A10: =IF(OR(직원목록!$A3="",교육과정!$A7="",직원목록!$F3="퇴사"),"",직원목록!$A3) | B10: =IF($A10="","",직원목록!$B3) | C10: =IF($A10="","",직원목록!$C3) | D10: =IF($A10="","",교육과정!$A7) | E10: =IF($A10="","",교육과정!$B7) | F10: =IF($A10="","",교육과정!$C7) | G10: =IF($A10="","",IF(COUNTIFS(이수내역!$B$3:$B$2002,$A10,이수내역!$D$3:$D$2002,$D10)=0,"",SUMPRODUCT(MAX((이수내역!$B$3:$B$2002=$A10)*(이수내역!$D$3:$D$2002=$D10)*이수내역!$A$3:$A$2002)))) | H10: =IF($A10="","",IF($F10="","",IF($G10="",EDATE(직원목록!$E3,$F10),EDATE($G10,$F10)))) | I10: =IF($H10="","",$H10-TODAY()) | J10: =IF($A10="","",IF($H10="","-",IF($I10<0,"기한초과",IF($I10<=사용안내!$C$16,"임박","정상"))))
A11: =IF(OR(직원목록!$A3="",교육과정!$A8="",직원목록!$F3="퇴사"),"",직원목록!$A3) | B11: =IF($A11="","",직원목록!$B3) | C11: =IF($A11="","",직원목록!$C3) | D11: =IF($A11="","",교육과정!$A8) | E11: =IF($A11="","",교육과정!$B8) | F11: =IF($A11="","",교육과정!$C8) | G11: =IF($A11="","",IF(COUNTIFS(이수내역!$B$3:$B$2002,$A11,이수내역!$D$3:$D$2002,$D11)=0,"",SUMPRODUCT(MAX((이수내역!$B$3:$B$2002=$A11)*(이수내역!$D$3:$D$2002=$D11)*이수내역!$A$3:$A$2002)))) | H11: =IF($A11="","",IF($F11="","",IF($G11="",EDATE(직원목록!$E3,$F11),EDATE($G11,$F11)))) | I11: =IF($H11="","",$H11-TODAY()) | J11: =IF($A11="","",IF($H11="","-",IF($I11<0,"기한초과",IF($I11<=사용안내!$C$16,"임박","정상"))))
A12: =IF(OR(직원목록!$A3="",교육과정!$A9="",직원목록!$F3="퇴사"),"",직원목록!$A3) | B12: =IF($A12="","",직원목록!$B3) | C12: =IF($A12="","",직원목록!$C3) | D12: =IF($A12="","",교육과정!$A9) | E12: =IF($A12="","",교육과정!$B9) | F12: =IF($A12="","",교육과정!$C9) | G12: =IF($A12="","",IF(COUNTIFS(이수내역!$B$3:$B$2002,$A12,이수내역!$D$3:$D$2002,$D12)=0,"",SUMPRODUCT(MAX((이수내역!$B$3:$B$2002=$A12)*(이수내역!$D$3:$D$2002=$D12)*이수내역!$A$3:$A$2002)))) | H12: =IF($A12="","",IF($F12="","",IF($G12="",EDATE(직원목록!$E3,$F12),EDATE($G12,$F12)))) | I12: =IF($H12="","",$H12-TODAY()) | J12: =IF($A12="","",IF($H12="","-",IF($I12<0,"기한초과",IF($I12<=사용안내!$C$16,"임박","정상"))))
A13: =IF(OR(직원목록!$A3="",교육과정!$A10="",직원목록!$F3="퇴사"),"",직원목록!$A3) | B13: =IF($A13="","",직원목록!$B3) | C13: =IF($A13="","",직원목록!$C3) | D13: =IF($A13="","",교육과정!$A10) | E13: =IF($A13="","",교육과정!$B10) | F13: =IF($A13="","",교육과정!$C10) | G13: =IF($A13="","",IF(COUNTIFS(이수내역!$B$3:$B$2002,$A13,이수내역!$D$3:$D$2002,$D13)=0,"",SUMPRODUCT(MAX((이수내역!$B$3:$B$2002=$A13)*(이수내역!$D$3:$D$2002=$D13)*이수내역!$A$3:$A$2002)))) | H13: =IF($A13="","",IF($F13="","",IF($G13="",EDATE(직원목록!$E3,$F13),EDATE($G13,$F13)))) | I13: =IF($H13="","",$H13-TODAY()) | J13: =IF($A13="","",IF($H13="","-",IF($I13<0,"기한초과",IF($I13<=사용안내!$C$16,"임박","정상"))))
A14: =IF(OR(직원목록!$A3="",교육과정!$A11="",직원목록!$F3="퇴사"),"",직원목록!$A3) | B14: =IF($A14="","",직원목록!$B3) | C14: =IF($A14="","",직원목록!$C3) | D14: =IF($A14="","",교육과정!$A11) | E14: =IF($A14="","",교육과정!$B11) | F14: =IF($A14="","",교육과정!$C11) | G14: =IF($A14="","",IF(COUNTIFS(이수내역!$B$3:$B$2002,$A14,이수내역!$D$3:$D$2002,$D14)=0,"",SUMPRODUCT(MAX((이수내역!$B$3:$B$2002=$A14)*(이수내역!$D$3:$D$2002=$D14)*이수내역!$A$3:$A$2002)))) | H14: =IF($A14="","",IF($F14="","",IF($G14="",EDATE(직원목록!$E3,$F14),EDATE($G14,$F14)))) | I14: =IF($H14="","",$H14-TODAY()) | J14: =IF($A14="","",IF($H14="","-",IF($I14<0,"기한초과",IF($I14<=사용안내!$C$16,"임박","정상"))))
A15: =IF(OR(직원목록!$A3="",교육과정!$A12="",직원목록!$F3="퇴사"),"",직원목록!$A3) | B15: =IF($A15="","",직원목록!$B3) | C15: =IF($A15="","",직원목록!$C3) | D15: =IF($A15="","",교육과정!$A12) | E15: =IF($A15="","",교육과정!$B12) | F15: =IF($A15="","",교육과정!$C12) | G15: =IF($A15="","",IF(COUNTIFS(이수내역!$B$3:$B$2002,$A15,이수내역!$D$3:$D$2002,$D15)=0,"",SUMPRODUCT(MAX((이수내역!$B$3:$B$2002=$A15)*(이수내역!$D$3:$D$2002=$D15)*이수내역!$A$3:$A$2002)))) | H15: =IF($A15="","",IF($F15="","",IF($G15="",EDATE(직원목록!$E3,$F15),EDATE($G15,$F15)))) | I15: =IF($H15="","",$H15-TODAY()) | J15: =IF($A15="","",IF($H15="","-",IF($I15<0,"기한초과",IF($I15<=사용안내!$C$16,"임박","정상"))))
A16: =IF(OR(직원목록!$A3="",교육과정!$A13="",직원목록!$F3="퇴사"),"",직원목록!$A3) | B16: =IF($A16="","",직원목록!$B3) | C16: =IF($A16="","",직원목록!$C3) | D16: =IF($A16="","",교육과정!$A13) | E16: =IF($A16="","",교육과정!$B13) | F16: =IF($A16="","",교육과정!$C13) | G16: =IF($A16="","",IF(COUNTIFS(이수내역!$B$3:$B$2002,$A16,이수내역!$D$3:$D$2002,$D16)=0,"",SUMPRODUCT(MAX((이수내역!$B$3:$B$2002=$A16)*(이수내역!$D$3:$D$2002=$D16)*이수내역!$A$3:$A$2002)))) | H16: =IF($A16="","",IF($F16="","",IF($G16="",EDATE(직원목록!$E3,$F16),EDATE($G16,$F16)))) | I16: =IF($H16="","",$H16-TODAY()) | J16: =IF($A16="","",IF($H16="","-",IF($I16<0,"기한초과",IF($I16<=사용안내!$C$16,"임박","정상"))))
A17: =IF(OR(직원목록!$A3="",교육과정!$A14="",직원목록!$F3="퇴사"),"",직원목록!$A3) | B17: =IF($A17="","",직원목록!$B3) | C17: =IF($A17="","",직원목록!$C3) | D17: =IF($A17="","",교육과정!$A14) | E17: =IF($A17="","",교육과정!$B14) | F17: =IF($A17="","",교육과정!$C14) | G17: =IF($A17="","",IF(COUNTIFS(이수내역!$B$3:$B$2002,$A17,이수내역!$D$3:$D$2002,$D17)=0,"",SUMPRODUCT(MAX((이수내역!$B$3:$B$2002=$A17)*(이수내역!$D$3:$D$2002=$D17)*이수내역!$A$3:$A$2002)))) | H17: =IF($A17="","",IF($F17="","",IF($G17="",EDATE(직원목록!$E3,$F17),EDATE($G17,$F17)))) | I17: =IF($H17="","",$H17-TODAY()) | J17: =IF($A17="","",IF($H17="","-",IF($I17<0,"기한초과",IF($I17<=사용안내!$C$16,"임박","정상"))))
A18: =IF(OR(직원목록!$A4="",교육과정!$A3="",직원목록!$F4="퇴사"),"",직원목록!$A4) -> E002 | B18: =IF($A18="","",직원목록!$B4) -> 이직원 | C18: =IF($A18="","",직원목록!$C4) -> 생산1팀 | D18: =IF($A18="","",교육과정!$A3) -> C01 | E18: =IF($A18="","",교육과정!$B3) -> 산업안전보건교육 | F18: =IF($A18="","",교육과정!$C3) -> 3 | G18: =IF($A18="","",IF(COUNTIFS(이수내역!$B$3:$B$2002,$A18,이수내역!$D$3:$D$2002,$D18)=0,"",SUMPRODUCT(MAX((이수내역!$B$3:$B$2002=$A18)*(이수내역!$D$3:$D$2002=$D18)*이수내역!$A$3:$A$2002)))) -> 46254 | H18: =IF($A18="","",IF($F18="","",IF($G18="",EDATE(직원목록!$E4,$F18),EDATE($G18,$F18)))) -> 46346 | I18: =IF($H18="","",$H18-TODAY()) -> 67 | J18: =IF($A18="","",IF($H18="","-",IF($I18<0,"기한초과",IF($I18<=사용안내!$C$16,"임박","정상")))) -> 정상
A19: =IF(OR(직원목록!$A4="",교육과정!$A4="",직원목록!$F4="퇴사"),"",직원목록!$A4) -> E002 | B19: =IF($A19="","",직원목록!$B4) -> 이직원 | C19: =IF($A19="","",직원목록!$C4) -> 생산1팀 | D19: =IF($A19="","",교육과정!$A4) -> C02 | E19: =IF($A19="","",교육과정!$B4) -> 성희롱 예방교육 | F19: =IF($A19="","",교육과정!$C4) -> 12 | G19: =IF($A19="","",IF(COUNTIFS(이수내역!$B$3:$B$2002,$A19,이수내역!$D$3:$D$2002,$D19)=0,"",SUMPRODUCT(MAX((이수내역!$B$3:$B$2002=$A19)*(이수내역!$D$3:$D$2002=$D19)*이수내역!$A$3:$A$2002)))) | H19: =IF($A19="","",IF($F19="","",IF($G19="",EDATE(직원목록!$E4,$F19),EDATE($G19,$F19)))) -> 45427 | I19: =IF($H19="","",$H19-TODAY()) -> -852 | J19: =IF($A19="","",IF($H19="","-",IF($I19<0,"기한초과",IF($I19<=사용안내!$C$16,"임박","정상")))) -> 기한초과
A20: =IF(OR(직원목록!$A4="",교육과정!$A5="",직원목록!$F4="퇴사"),"",직원목록!$A4) -> E002 | B20: =IF($A20="","",직원목록!$B4) -> 이직원 | C20: =IF($A20="","",직원목록!$C4) -> 생산1팀 | D20: =IF($A20="","",교육과정!$A5) -> C03 | E20: =IF($A20="","",교육과정!$B5) -> 개인정보보호 교육 | F20: =IF($A20="","",교육과정!$C5) -> 12 | G20: =IF($A20="","",IF(COUNTIFS(이수내역!$B$3:$B$2002,$A20,이수내역!$D$3:$D$2002,$D20)=0,"",SUMPRODUCT(MAX((이수내역!$B$3:$B$2002=$A20)*(이수내역!$D$3:$D$2002=$D20)*이수내역!$A$3:$A$2002)))) | H20: =IF($A20="","",IF($F20="","",IF($G20="",EDATE(직원목록!$E4,$F20),EDATE($G20,$F20)))) -> 45427 | I20: =IF($H20="","",$H20-TODAY()) -> -852 | J20: =IF($A20="","",IF($H20="","-",IF($I20<0,"기한초과",IF($I20<=사용안내!$C$16,"임박","정상")))) -> 기한초과
A21: =IF(OR(직원목록!$A4="",교육과정!$A6="",직원목록!$F4="퇴사"),"",직원목록!$A4) -> E002 | B21: =IF($A21="","",직원목록!$B4) -> 이직원 | C21: =IF($A21="","",직원목록!$C4) -> 생산1팀 | D21: =IF($A21="","",교육과정!$A6) -> C04 | E21: =IF($A21="","",교육과정!$B6) -> 지게차 운전 자격 | F21: =IF($A21="","",교육과정!$C6) -> 24 | G21: =IF($A21="","",IF(COUNTIFS(이수내역!$B$3:$B$2002,$A21,이수내역!$D$3:$D$2002,$D21)=0,"",SUMPRODUCT(MAX((이수내역!$B$3:$B$2002=$A21)*(이수내역!$D$3:$D$2002=$D21)*이수내역!$A$3:$A$2002)))) | H21: =IF($A21="","",IF($F21="","",IF($G21="",EDATE(직원목록!$E4,$F21),EDATE($G21,$F21)))) -> 45792 | I21: =IF($H21="","",$H21-TODAY()) -> -487 | J21: =IF($A21="","",IF($H21="","-",IF($I21<0,"기한초과",IF($I21<=사용안내!$C$16,"임박","정상")))) -> 기한초과
A22: =IF(OR(직원목록!$A4="",교육과정!$A7="",직원목록!$F4="퇴사"),"",직원목록!$A4) | B22: =IF($A22="","",직원목록!$B4) | C22: =IF($A22="","",직원목록!$C4) | D22: =IF($A22="","",교육과정!$A7) | E22: =IF($A22="","",교육과정!$B7) | F22: =IF($A22="","",교육과정!$C7) | G22: =IF($A22="","",IF(COUNTIFS(이수내역!$B$3:$B$2002,$A22,이수내역!$D$3:$D$2002,$D22)=0,"",SUMPRODUCT(MAX((이수내역!$B$3:$B$2002=$A22)*(이수내역!$D$3:$D$2002=$D22)*이수내역!$A$3:$A$2002)))) | H22: =IF($A22="","",IF($F22="","",IF($G22="",EDATE(직원목록!$E4,$F22),EDATE($G22,$F22)))) | I22: =IF($H22="","",$H22-TODAY()) | J22: =IF($A22="","",IF($H22="","-",IF($I22<0,"기한초과",IF($I22<=사용안내!$C$16,"임박","정상"))))
A23: =IF(OR(직원목록!$A4="",교육과정!$A8="",직원목록!$F4="퇴사"),"",직원목록!$A4) | B23: =IF($A23="","",직원목록!$B4) | C23: =IF($A23="","",직원목록!$C4) | D23: =IF($A23="","",교육과정!$A8) | E23: =IF($A23="","",교육과정!$B8) | F23: =IF($A23="","",교육과정!$C8) | G23: =IF($A23="","",IF(COUNTIFS(이수내역!$B$3:$B$2002,$A23,이수내역!$D$3:$D$2002,$D23)=0,"",SUMPRODUCT(MAX((이수내역!$B$3:$B$2002=$A23)*(이수내역!$D$3:$D$2002=$D23)*이수내역!$A$3:$A$2002)))) | H23: =IF($A23="","",IF($F23="","",IF($G23="",EDATE(직원목록!$E4,$F23),EDATE($G23,$F23)))) | I23: =IF($H23="","",$H23-TODAY()) | J23: =IF($A23="","",IF($H23="","-",IF($I23<0,"기한초과",IF($I23<=사용안내!$C$16,"임박","정상"))))
A24: =IF(OR(직원목록!$A4="",교육과정!$A9="",직원목록!$F4="퇴사"),"",직원목록!$A4) | B24: =IF($A24="","",직원목록!$B4) | C24: =IF($A24="","",직원목록!$C4) | D24: =IF($A24="","",교육과정!$A9) | E24: =IF($A24="","",교육과정!$B9) | F24: =IF($A24="","",교육과정!$C9) | G24: =IF($A24="","",IF(COUNTIFS(이수내역!$B$3:$B$2002,$A24,이수내역!$D$3:$D$2002,$D24)=0,"",SUMPRODUCT(MAX((이수내역!$B$3:$B$2002=$A24)*(이수내역!$D$3:$D$2002=$D24)*이수내역!$A$3:$A$2002)))) | H24: =IF($A24="","",IF($F24="","",IF($G24="",EDATE(직원목록!$E4,$F24),EDATE($G24,$F24)))) | I24: =IF($H24="","",$H24-TODAY()) | J24: =IF($A24="","",IF($H24="","-",IF($I24<0,"기한초과",IF($I24<=사용안내!$C$16,"임박","정상"))))
A25: =IF(OR(직원목록!$A4="",교육과정!$A10="",직원목록!$F4="퇴사"),"",직원목록!$A4) | B25: =IF($A25="","",직원목록!$B4) | C25: =IF($A25="","",직원목록!$C4) | D25: =IF($A25="","",교육과정!$A10) | E25: =IF($A25="","",교육과정!$B10) | F25: =IF($A25="","",교육과정!$C10) | G25: =IF($A25="","",IF(COUNTIFS(이수내역!$B$3:$B$2002,$A25,이수내역!$D$3:$D$2002,$D25)=0,"",SUMPRODUCT(MAX((이수내역!$B$3:$B$2002=$A25)*(이수내역!$D$3:$D$2002=$D25)*이수내역!$A$3:$A$2002)))) | H25: =IF($A25="","",IF($F25="","",IF($G25="",EDATE(직원목록!$E4,$F25),EDATE($G25,$F25)))) | I25: =IF($H25="","",$H25-TODAY()) | J25: =IF($A25="","",IF($H25="","-",IF($I25<0,"기한초과",IF($I25<=사용안내!$C$16,"임박","정상"))))
A26: =IF(OR(직원목록!$A4="",교육과정!$A11="",직원목록!$F4="퇴사"),"",직원목록!$A4) | B26: =IF($A26="","",직원목록!$B4) | C26: =IF($A26="","",직원목록!$C4) | D26: =IF($A26="","",교육과정!$A11) | E26: =IF($A26="","",교육과정!$B11) | F26: =IF($A26="","",교육과정!$C11) | G26: =IF($A26="","",IF(COUNTIFS(이수내역!$B$3:$B$2002,$A26,이수내역!$D$3:$D$2002,$D26)=0,"",SUMPRODUCT(MAX((이수내역!$B$3:$B$2002=$A26)*(이수내역!$D$3:$D$2002=$D26)*이수내역!$A$3:$A$2002)))) | H26: =IF($A26="","",IF($F26="","",IF($G26="",EDATE(직원목록!$E4,$F26),EDATE($G26,$F26)))) | I26: =IF($H26="","",$H26-TODAY()) | J26: =IF($A26="","",IF($H26="","-",IF($I26<0,"기한초과",IF($I26<=사용안내!$C$16,"임박","정상"))))
A27: =IF(OR(직원목록!$A4="",교육과정!$A12="",직원목록!$F4="퇴사"),"",직원목록!$A4) | B27: =IF($A27="","",직원목록!$B4) | C27: =IF($A27="","",직원목록!$C4) | D27: =IF($A27="","",교육과정!$A12) | E27: =IF($A27="","",교육과정!$B12) | F27: =IF($A27="","",교육과정!$C12) | G27: =IF($A27="","",IF(COUNTIFS(이수내역!$B$3:$B$2002,$A27,이수내역!$D$3:$D$2002,$D27)=0,"",SUMPRODUCT(MAX((이수내역!$B$3:$B$2002=$A27)*(이수내역!$D$3:$D$2002=$D27)*이수내역!$A$3:$A$2002)))) | H27: =IF($A27="","",IF($F27="","",IF($G27="",EDATE(직원목록!$E4,$F27),EDATE($G27,$F27)))) | I27: =IF($H27="","",$H27-TODAY()) | J27: =IF($A27="","",IF($H27="","-",IF($I27<0,"기한초과",IF($I27<=사용안내!$C$16,"임박","정상"))))
A28: =IF(OR(직원목록!$A4="",교육과정!$A13="",직원목록!$F4="퇴사"),"",직원목록!$A4) | B28: =IF($A28="","",직원목록!$B4) | C28: =IF($A28="","",직원목록!$C4) | D28: =IF($A28="","",교육과정!$A13) | E28: =IF($A28="","",교육과정!$B13) | F28: =IF($A28="","",교육과정!$C13) | G28: =IF($A28="","",IF(COUNTIFS(이수내역!$B$3:$B$2002,$A28,이수내역!$D$3:$D$2002,$D28)=0,"",SUMPRODUCT(MAX((이수내역!$B$3:$B$2002=$A28)*(이수내역!$D$3:$D$2002=$D28)*이수내역!$A$3:$A$2002)))) | H28: =IF($A28="","",IF($F28="","",IF($G28="",EDATE(직원목록!$E4,$F28),EDATE($G28,$F28)))) | I28: =IF($H28="","",$H28-TODAY()) | J28: =IF($A28="","",IF($H28="","-",IF($I28<0,"기한초과",IF($I28<=사용안내!$C$16,"임박","정상"))))
A29: =IF(OR(직원목록!$A4="",교육과정!$A14="",직원목록!$F4="퇴사"),"",직원목록!$A4) | B29: =IF($A29="","",직원목록!$B4) | C29: =IF($A29="","",직원목록!$C4) | D29: =IF($A29="","",교육과정!$A14) | E29: =IF($A29="","",교육과정!$B14) | F29: =IF($A29="","",교육과정!$C14) | G29: =IF($A29="","",IF(COUNTIFS(이수내역!$B$3:$B$2002,$A29,이수내역!$D$3:$D$2002,$D29)=0,"",SUMPRODUCT(MAX((이수내역!$B$3:$B$2002=$A29)*(이수내역!$D$3:$D$2002=$D29)*이수내역!$A$3:$A$2002)))) | H29: =IF($A29="","",IF($F29="","",IF($G29="",EDATE(직원목록!$E4,$F29),EDATE($G29,$F29)))) | I29: =IF($H29="","",$H29-TODAY()) | J29: =IF($A29="","",IF($H29="","-",IF($I29<0,"기한초과",IF($I29<=사용안내!$C$16,"임박","정상"))))
A30: =IF(OR(직원목록!$A5="",교육과정!$A3="",직원목록!$F5="퇴사"),"",직원목록!$A5) -> E003 | B30: =IF($A30="","",직원목록!$B5) -> 박직원 | C30: =IF($A30="","",직원목록!$C5) -> 관리팀 | D30: =IF($A30="","",교육과정!$A3) -> C01 | E30: =IF($A30="","",교육과정!$B3) -> 산업안전보건교육 | F30: =IF($A30="","",교육과정!$C3) -> 3 | G30: =IF($A30="","",IF(COUNTIFS(이수내역!$B$3:$B$2002,$A30,이수내역!$D$3:$D$2002,$D30)=0,"",SUMPRODUCT(MAX((이수내역!$B$3:$B$2002=$A30)*(이수내역!$D$3:$D$2002=$D30)*이수내역!$A$3:$A$2002)))) | H30: =IF($A30="","",IF($F30="","",IF($G30="",EDATE(직원목록!$E5,$F30),EDATE($G30,$F30)))) -> 44661 | I30: =IF($H30="","",$H30-TODAY()) -> -1618 | J30: =IF($A30="","",IF($H30="","-",IF($I30<0,"기한초과",IF($I30<=사용안내!$C$16,"임박","정상")))) -> 기한초과
A31: =IF(OR(직원목록!$A5="",교육과정!$A4="",직원목록!$F5="퇴사"),"",직원목록!$A5) -> E003 | B31: =IF($A31="","",직원목록!$B5) -> 박직원 | C31: =IF($A31="","",직원목록!$C5) -> 관리팀 | D31: =IF($A31="","",교육과정!$A4) -> C02 | E31: =IF($A31="","",교육과정!$B4) -> 성희롱 예방교육 | F31: =IF($A31="","",교육과정!$C4) -> 12 | G31: =IF($A31="","",IF(COUNTIFS(이수내역!$B$3:$B$2002,$A31,이수내역!$D$3:$D$2002,$D31)=0,"",SUMPRODUCT(MAX((이수내역!$B$3:$B$2002=$A31)*(이수내역!$D$3:$D$2002=$D31)*이수내역!$A$3:$A$2002)))) -> 45809 | H31: =IF($A31="","",IF($F31="","",IF($G31="",EDATE(직원목록!$E5,$F31),EDATE($G31,$F31)))) -> 46174 | I31: =IF($H31="","",$H31-TODAY()) -> -105 | J31: =IF($A31="","",IF($H31="","-",IF($I31<0,"기한초과",IF($I31<=사용안내!$C$16,"임박","정상")))) -> 기한초과
A32: =IF(OR(직원목록!$A5="",교육과정!$A5="",직원목록!$F5="퇴사"),"",직원목록!$A5) -> E003 | B32: =IF($A32="","",직원목록!$B5) -> 박직원 | C32: =IF($A32="","",직원목록!$C5) -> 관리팀 | D32: =IF($A32="","",교육과정!$A5) -> C03 | E32: =IF($A32="","",교육과정!$B5) -> 개인정보보호 교육 | F32: =IF($A32="","",교육과정!$C5) -> 12 | G32: =IF($A32="","",IF(COUNTIFS(이수내역!$B$3:$B$2002,$A32,이수내역!$D$3:$D$2002,$D32)=0,"",SUMPRODUCT(MAX((이수내역!$B$3:$B$2002=$A32)*(이수내역!$D$3:$D$2002=$D32)*이수내역!$A$3:$A$2002)))) | H32: =IF($A32="","",IF($F32="","",IF($G32="",EDATE(직원목록!$E5,$F32),EDATE($G32,$F32)))) -> 44936 | I32: =IF($H32="","",$H32-TODAY()) -> -1343 | J32: =IF($A32="","",IF($H32="","-",IF($I32<0,"기한초과",IF($I32<=사용안내!$C$16,"임박","정상")))) -> 기한초과
A33: =IF(OR(직원목록!$A5="",교육과정!$A6="",직원목록!$F5="퇴사"),"",직원목록!$A5) -> E003 | B33: =IF($A33="","",직원목록!$B5) -> 박직원 | C33: =IF($A33="","",직원목록!$C5) -> 관리팀 | D33: =IF($A33="","",교육과정!$A6) -> C04 | E33: =IF($A33="","",교육과정!$B6) -> 지게차 운전 자격 | F33: =IF($A33="","",교육과정!$C6) -> 24 | G33: =IF($A33="","",IF(COUNTIFS(이수내역!$B$3:$B$2002,$A33,이수내역!$D$3:$D$2002,$D33)=0,"",SUMPRODUCT(MAX((이수내역!$B$3:$B$2002=$A33)*(이수내역!$D$3:$D$2002=$D33)*이수내역!$A$3:$A$2002)))) | H33: =IF($A33="","",IF($F33="","",IF($G33="",EDATE(직원목록!$E5,$F33),EDATE($G33,$F33)))) -> 45301 | I33: =IF($H33="","",$H33-TODAY()) -> -978 | J33: =IF($A33="","",IF($H33="","-",IF($I33<0,"기한초과",IF($I33<=사용안내!$C$16,"임박","정상")))) -> 기한초과
A34: =IF(OR(직원목록!$A5="",교육과정!$A7="",직원목록!$F5="퇴사"),"",직원목록!$A5) | B34: =IF($A34="","",직원목록!$B5) | C34: =IF($A34="","",직원목록!$C5) | D34: =IF($A34="","",교육과정!$A7) | E34: =IF($A34="","",교육과정!$B7) | F34: =IF($A34="","",교육과정!$C7) | G34: =IF($A34="","",IF(COUNTIFS(이수내역!$B$3:$B$2002,$A34,이수내역!$D$3:$D$2002,$D34)=0,"",SUMPRODUCT(MAX((이수내역!$B$3:$B$2002=$A34)*(이수내역!$D$3:$D$2002=$D34)*이수내역!$A$3:$A$2002)))) | H34: =IF($A34="","",IF($F34="","",IF($G34="",EDATE(직원목록!$E5,$F34),EDATE($G34,$F34)))) | I34: =IF($H34="","",$H34-TODAY()) | J34: =IF($A34="","",IF($H34="","-",IF($I34<0,"기한초과",IF($I34<=사용안내!$C$16,"임박","정상"))))
A35: =IF(OR(직원목록!$A5="",교육과정!$A8="",직원목록!$F5="퇴사"),"",직원목록!$A5) | B35: =IF($A35="","",직원목록!$B5) | C35: =IF($A35="","",직원목록!$C5) | D35: =IF($A35="","",교육과정!$A8) | E35: =IF($A35="","",교육과정!$B8) | F35: =IF($A35="","",교육과정!$C8) | G35: =IF($A35="","",IF(COUNTIFS(이수내역!$B$3:$B$2002,$A35,이수내역!$D$3:$D$2002,$D35)=0,"",SUMPRODUCT(MAX((이수내역!$B$3:$B$2002=$A35)*(이수내역!$D$3:$D$2002=$D35)*이수내역!$A$3:$A$2002)))) | H35: =IF($A35="","",IF($F35="","",IF($G35="",EDATE(직원목록!$E5,$F35),EDATE($G35,$F35)))) | I35: =IF($H35="","",$H35-TODAY()) | J35: =IF($A35="","",IF($H35="","-",IF($I35<0,"기한초과",IF($I35<=사용안내!$C$16,"임박","정상"))))
A36: =IF(OR(직원목록!$A5="",교육과정!$A9="",직원목록!$F5="퇴사"),"",직원목록!$A5) | B36: =IF($A36="","",직원목록!$B5) | C36: =IF($A36="","",직원목록!$C5) | D36: =IF($A36="","",교육과정!$A9) | E36: =IF($A36="","",교육과정!$B9) | F36: =IF($A36="","",교육과정!$C9) | G36: =IF($A36="","",IF(COUNTIFS(이수내역!$B$3:$B$2002,$A36,이수내역!$D$3:$D$2002,$D36)=0,"",SUMPRODUCT(MAX((이수내역!$B$3:$B$2002=$A36)*(이수내역!$D$3:$D$2002=$D36)*이수내역!$A$3:$A$2002)))) | H36: =IF($A36="","",IF($F36="","",IF($G36="",EDATE(직원목록!$E5,$F36),EDATE($G36,$F36)))) | I36: =IF($H36="","",$H36-TODAY()) | J36: =IF($A36="","",IF($H36="","-",IF($I36<0,"기한초과",IF($I36<=사용안내!$C$16,"임박","정상"))))
A37: =IF(OR(직원목록!$A5="",교육과정!$A10="",직원목록!$F5="퇴사"),"",직원목록!$A5) | B37: =IF($A37="","",직원목록!$B5) | C37: =IF($A37="","",직원목록!$C5) | D37: =IF($A37="","",교육과정!$A10) | E37: =IF($A37="","",교육과정!$B10) | F37: =IF($A37="","",교육과정!$C10) | G37: =IF($A37="","",IF(COUNTIFS(이수내역!$B$3:$B$2002,$A37,이수내역!$D$3:$D$2002,$D37)=0,"",SUMPRODUCT(MAX((이수내역!$B$3:$B$2002=$A37)*(이수내역!$D$3:$D$2002=$D37)*이수내역!$A$3:$A$2002)))) | H37: =IF($A37="","",IF($F37="","",IF($G37="",EDATE(직원목록!$E5,$F37),EDATE($G37,$F37)))) | I37: =IF($H37="","",$H37-TODAY()) | J37: =IF($A37="","",IF($H37="","-",IF($I37<0,"기한초과",IF($I37<=사용안내!$C$16,"임박","정상"))))
A38: =IF(OR(직원목록!$A5="",교육과정!$A11="",직원목록!$F5="퇴사"),"",직원목록!$A5) | B38: =IF($A38="","",직원목록!$B5) | C38: =IF($A38="","",직원목록!$C5) | D38: =IF($A38="","",교육과정!$A11) | E38: =IF($A38="","",교육과정!$B11) | F38: =IF($A38="","",교육과정!$C11) | G38: =IF($A38="","",IF(COUNTIFS(이수내역!$B$3:$B$2002,$A38,이수내역!$D$3:$D$2002,$D38)=0,"",SUMPRODUCT(MAX((이수내역!$B$3:$B$2002=$A38)*(이수내역!$D$3:$D$2002=$D38)*이수내역!$A$3:$A$2002)))) | H38: =IF($A38="","",IF($F38="","",IF($G38="",EDATE(직원목록!$E5,$F38),EDATE($G38,$F38)))) | I38: =IF($H38="","",$H38-TODAY()) | J38: =IF($A38="","",IF($H38="","-",IF($I38<0,"기한초과",IF($I38<=사용안내!$C$16,"임박","정상"))))
A39: =IF(OR(직원목록!$A5="",교육과정!$A12="",직원목록!$F5="퇴사"),"",직원목록!$A5) | B39: =IF($A39="","",직원목록!$B5) | C39: =IF($A39="","",직원목록!$C5) | D39: =IF($A39="","",교육과정!$A12) | E39: =IF($A39="","",교육과정!$B12) | F39: =IF($A39="","",교육과정!$C12) | G39: =IF($A39="","",IF(COUNTIFS(이수내역!$B$3:$B$2002,$A39,이수내역!$D$3:$D$2002,$D39)=0,"",SUMPRODUCT(MAX((이수내역!$B$3:$B$2002=$A39)*(이수내역!$D$3:$D$2002=$D39)*이수내역!$A$3:$A$2002)))) | H39: =IF($A39="","",IF($F39="","",IF($G39="",EDATE(직원목록!$E5,$F39),EDATE($G39,$F39)))) | I39: =IF($H39="","",$H39-TODAY()) | J39: =IF($A39="","",IF($H39="","-",IF($I39<0,"기한초과",IF($I39<=사용안내!$C$16,"임박","정상"))))
A40: =IF(OR(직원목록!$A5="",교육과정!$A13="",직원목록!$F5="퇴사"),"",직원목록!$A5) | B40: =IF($A40="","",직원목록!$B5) | C40: =IF($A40="","",직원목록!$C5) | D40: =IF($A40="","",교육과정!$A13) | E40: =IF($A40="","",교육과정!$B13) | F40: =IF($A40="","",교육과정!$C13) | G40: =IF($A40="","",IF(COUNTIFS(이수내역!$B$3:$B$2002,$A40,이수내역!$D$3:$D$2002,$D40)=0,"",SUMPRODUCT(MAX((이수내역!$B$3:$B$2002=$A40)*(이수내역!$D$3:$D$2002=$D40)*이수내역!$A$3:$A$2002)))) | H40: =IF($A40="","",IF($F40="","",IF($G40="",EDATE(직원목록!$E5,$F40),EDATE($G40,$F40)))) | I40: =IF($H40="","",$H40-TODAY()) | J40: =IF($A40="","",IF($H40="","-",IF($I40<0,"기한초과",IF($I40<=사용안내!$C$16,"임박","정상"))))
A41: =IF(OR(직원목록!$A5="",교육과정!$A14="",직원목록!$F5="퇴사"),"",직원목록!$A5) | B41: =IF($A41="","",직원목록!$B5) | C41: =IF($A41="","",직원목록!$C5) | D41: =IF($A41="","",교육과정!$A14) | E41: =IF($A41="","",교육과정!$B14) | F41: =IF($A41="","",교육과정!$C14) | G41: =IF($A41="","",IF(COUNTIFS(이수내역!$B$3:$B$2002,$A41,이수내역!$D$3:$D$2002,$D41)=0,"",SUMPRODUCT(MAX((이수내역!$B$3:$B$2002=$A41)*(이수내역!$D$3:$D$2002=$D41)*이수내역!$A$3:$A$2002)))) | H41: =IF($A41="","",IF($F41="","",IF($G41="",EDATE(직원목록!$E5,$F41),EDATE($G41,$F41)))) | I41: =IF($H41="","",$H41-TODAY()) | J41: =IF($A41="","",IF($H41="","-",IF($I41<0,"기한초과",IF($I41<=사용안내!$C$16,"임박","정상"))))
A42: =IF(OR(직원목록!$A6="",교육과정!$A3="",직원목록!$F6="퇴사"),"",직원목록!$A6) | B42: =IF($A42="","",직원목록!$B6) | C42: =IF($A42="","",직원목록!$C6) | D42: =IF($A42="","",교육과정!$A3) | E42: =IF($A42="","",교육과정!$B3) | F42: =IF($A42="","",교육과정!$C3) | G42: =IF($A42="","",IF(COUNTIFS(이수내역!$B$3:$B$2002,$A42,이수내역!$D$3:$D$2002,$D42)=0,"",SUMPRODUCT(MAX((이수내역!$B$3:$B$2002=$A42)*(이수내역!$D$3:$D$2002=$D42)*이수내역!$A$3:$A$2002)))) | H42: =IF($A42="","",IF($F42="","",IF($G42="",EDATE(직원목록!$E6,$F42),EDATE($G42,$F42)))) | I42: =IF($H42="","",$H42-TODAY()) | J42: =IF($A42="","",IF($H42="","-",IF($I42<0,"기한초과",IF($I42<=사용안내!$C$16,"임박","정상"))))
...

Sheet 미이수현황
A1: 미이수현황 (기한 초과 · 임박)
A3: 해당 건수 | B3: =COUNTIF($J$6:$J$485,TRUE()) -> 10
A5: 순번 | B5: 사번 | C5: 이름 | D5: 부서 | E5: 과정명 | F5: 최근 이수일 | G5: 다음 기한 | H5: D-Day
A6: =IF($B6="","",1) -> 1 | B6: =IFERROR(INDEX(이수현황!$A$6:$A$485,MATCH("R"&1,미이수현황!$L$6:$L$485,0)),"") -> E001 | C6: =IF($B6="","",IFERROR(INDEX(이수현황!$B$6:$B$485,MATCH("R"&1,미이수현황!$L$6:$L$485,0)),"")) -> 김직원 | D6: =IF($B6="","",IFERROR(INDEX(이수현황!$C$6:$C$485,MATCH("R"&1,미이수현황!$L$6:$L$485,0)),"")) -> 생산1팀 | E6: =IF($B6="","",IFERROR(INDEX(이수현황!$E$6:$E$485,MATCH("R"&1,미이수현황!$L$6:$L$485,0)),"")) -> 산업안전보건교육 | F6: =IF($B6="","",IFERROR(INDEX(이수현황!$G$6:$G$485,MATCH("R"&1,미이수현황!$L$6:$L$485,0)),"")) -> 46213 | G6: =IF($B6="","",IFERROR(INDEX(이수현황!$H$6:$H$485,MATCH("R"&1,미이수현황!$L$6:$L$485,0)),"")) -> 46305 | H6: =IF($B6="","",IFERROR(INDEX(이수현황!$I$6:$I$485,MATCH("R"&1,미이수현황!$L$6:$L$485,0)),"")) -> 26 | J6: =IF(이수현황!$A6="",FALSE(),OR(이수현황!$J6="기한초과",이수현황!$J6="임박")) -> TRUE | K6: =IF($J6=FALSE(),"",COUNTIF($J$6:$J6,TRUE())) -> 1 | L6: =IF($K6="","","R"&$K6) -> R1
A7: =IF($B7="","",2) -> 2 | B7: =IFERROR(INDEX(이수현황!$A$6:$A$485,MATCH("R"&2,미이수현황!$L$6:$L$485,0)),"") -> E001 | C7: =IF($B7="","",IFERROR(INDEX(이수현황!$B$6:$B$485,MATCH("R"&2,미이수현황!$L$6:$L$485,0)),"")) -> 김직원 | D7: =IF($B7="","",IFERROR(INDEX(이수현황!$C$6:$C$485,MATCH("R"&2,미이수현황!$L$6:$L$485,0)),"")) -> 생산1팀 | E7: =IF($B7="","",IFERROR(INDEX(이수현황!$E$6:$E$485,MATCH("R"&2,미이수현황!$L$6:$L$485,0)),"")) -> 개인정보보호 교육 | F7: =IF($B7="","",IFERROR(INDEX(이수현황!$G$6:$G$485,MATCH("R"&2,미이수현황!$L$6:$L$485,0)),"")) | G7: =IF($B7="","",IFERROR(INDEX(이수현황!$H$6:$H$485,MATCH("R"&2,미이수현황!$L$6:$L$485,0)),"")) -> 45718 | H7: =IF($B7="","",IFERROR(INDEX(이수현황!$I$6:$I$485,MATCH("R"&2,미이수현황!$L$6:$L$485,0)),"")) -> -561 | J7: =IF(이수현황!$A7="",FALSE(),OR(이수현황!$J7="기한초과",이수현황!$J7="임박")) -> FALSE | K7: =IF($J7=FALSE(),"",COUNTIF($J$6:$J7,TRUE())) | L7: =IF($K7="","","R"&$K7)
A8: =IF($B8="","",3) -> 3 | B8: =IFERROR(INDEX(이수현황!$A$6:$A$485,MATCH("R"&3,미이수현황!$L$6:$L$485,0)),"") -> E001 | C8: =IF($B8="","",IFERROR(INDEX(이수현황!$B$6:$B$485,MATCH("R"&3,미이수현황!$L$6:$L$485,0)),"")) -> 김직원 | D8: =IF($B8="","",IFERROR(INDEX(이수현황!$C$6:$C$485,MATCH("R"&3,미이수현황!$L$6:$L$485,0)),"")) -> 생산1팀 | E8: =IF($B8="","",IFERROR(INDEX(이수현황!$E$6:$E$485,MATCH("R"&3,미이수현황!$L$6:$L$485,0)),"")) -> 지게차 운전 자격 | F8: =IF($B8="","",IFERROR(INDEX(이수현황!$G$6:$G$485,MATCH("R"&3,미이수현황!$L$6:$L$485,0)),"")) | G8: =IF($B8="","",IFERROR(INDEX(이수현황!$H$6:$H$485,MATCH("R"&3,미이수현황!$L$6:$L$485,0)),"")) -> 46083 | H8: =IF($B8="","",IFERROR(INDEX(이수현황!$I$6:$I$485,MATCH("R"&3,미이수현황!$L$6:$L$485,0)),"")) -> -196 | J8: =IF(이수현황!$A8="",FALSE(),OR(이수현황!$J8="기한초과",이수현황!$J8="임박")) -> TRUE | K8: =IF($J8=FALSE(),"",COUNTIF($J$6:$J8,TRUE())) -> 2 | L8: =IF($K8="","","R"&$K8) -> R2
A9: =IF($B9="","",4) -> 4 | B9: =IFERROR(INDEX(이수현황!$A$6:$A$485,MATCH("R"&4,미이수현황!$L$6:$L$485,0)),"") -> E002 | C9: =IF($B9="","",IFERROR(INDEX(이수현황!$B$6:$B$485,MATCH("R"&4,미이수현황!$L$6:$L$485,0)),"")) -> 이직원 | D9: =IF($B9="","",IFERROR(INDEX(이수현황!$C$6:$C$485,MATCH("R"&4,미이수현황!$L$6:$L$485,0)),"")) -> 생산1팀 | E9: =IF($B9="","",IFERROR(INDEX(이수현황!$E$6:$E$485,MATCH("R"&4,미이수현황!$L$6:$L$485,0)),"")) -> 성희롱 예방교육 | F9: =IF($B9="","",IFERROR(INDEX(이수현황!$G$6:$G$485,MATCH("R"&4,미이수현황!$L$6:$L$485,0)),"")) | G9: =IF($B9="","",IFERROR(INDEX(이수현황!$H$6:$H$485,MATCH("R"&4,미이수현황!$L$6:$L$485,0)),"")) -> 45427 | H9: =IF($B9="","",IFERROR(INDEX(이수현황!$I$6:$I$485,MATCH("R"&4,미이수현황!$L$6:$L$485,0)),"")) -> -852 | J9: =IF(이수현황!$A9="",FALSE(),OR(이수현황!$J9="기한초과",이수현황!$J9="임박")) -> TRUE | K9: =IF($J9=FALSE(),"",COUNTIF($J$6:$J9,TRUE())) -> 3 | L9: =IF($K9="","","R"&$K9) -> R3
A10: =IF($B10="","",5) -> 5 | B10: =IFERROR(INDEX(이수현황!$A$6:$A$485,MATCH("R"&5,미이수현황!$L$6:$L$485,0)),"") -> E002 | C10: =IF($B10="","",IFERROR(INDEX(이수현황!$B$6:$B$485,MATCH("R"&5,미이수현황!$L$6:$L$485,0)),"")) -> 이직원 | D10: =IF($B10="","",IFERROR(INDEX(이수현황!$C$6:$C$485,MATCH("R"&5,미이수현황!$L$6:$L$485,0)),"")) -> 생산1팀 | E10: =IF($B10="","",IFERROR(INDEX(이수현황!$E$6:$E$485,MATCH("R"&5,미이수현황!$L$6:$L$485,0)),"")) -> 개인정보보호 교육 | F10: =IF($B10="","",IFERROR(INDEX(이수현황!$G$6:$G$485,MATCH("R"&5,미이수현황!$L$6:$L$485,0)),"")) | G10: =IF($B10="","",IFERROR(INDEX(이수현황!$H$6:$H$485,MATCH("R"&5,미이수현황!$L$6:$L$485,0)),"")) -> 45427 | H10: =IF($B10="","",IFERROR(INDEX(이수현황!$I$6:$I$485,MATCH("R"&5,미이수현황!$L$6:$L$485,0)),"")) -> -852 | J10: =IF(이수현황!$A10="",FALSE(),OR(이수현황!$J10="기한초과",이수현황!$J10="임박")) -> FALSE | K10: =IF($J10=FALSE(),"",COUNTIF($J$6:$J10,TRUE())) | L10: =IF($K10="","","R"&$K10)
A11: =IF($B11="","",6) -> 6 | B11: =IFERROR(INDEX(이수현황!$A$6:$A$485,MATCH("R"&6,미이수현황!$L$6:$L$485,0)),"") -> E002 | C11: =IF($B11="","",IFERROR(INDEX(이수현황!$B$6:$B$485,MATCH("R"&6,미이수현황!$L$6:$L$485,0)),"")) -> 이직원 | D11: =IF($B11="","",IFERROR(INDEX(이수현황!$C$6:$C$485,MATCH("R"&6,미이수현황!$L$6:$L$485,0)),"")) -> 생산1팀 | E11: =IF($B11="","",IFERROR(INDEX(이수현황!$E$6:$E$485,MATCH("R"&6,미이수현황!$L$6:$L$485,0)),"")) -> 지게차 운전 자격 | F11: =IF($B11="","",IFERROR(INDEX(이수현황!$G$6:$G$485,MATCH("R"&6,미이수현황!$L$6:$L$485,0)),"")) | G11: =IF($B11="","",IFERROR(INDEX(이수현황!$H$6:$H$485,MATCH("R"&6,미이수현황!$L$6:$L$485,0)),"")) -> 45792 | H11: =IF($B11="","",IFERROR(INDEX(이수현황!$I$6:$I$485,MATCH("R"&6,미이수현황!$L$6:$L$485,0)),"")) -> -487 | J11: =IF(이수현황!$A11="",FALSE(),OR(이수현황!$J11="기한초과",이수현황!$J11="임박")) -> FALSE | K11: =IF($J11=FALSE(),"",COUNTIF($J$6:$J11,TRUE())) | L11: =IF($K11="","","R"&$K11)
A12: =IF($B12="","",7) -> 7 | B12: =IFERROR(INDEX(이수현황!$A$6:$A$485,MATCH("R"&7,미이수현황!$L$6:$L$485,0)),"") -> E003 | C12: =IF($B12="","",IFERROR(INDEX(이수현황!$B$6:$B$485,MATCH("R"&7,미이수현황!$L$6:$L$485,0)),"")) -> 박직원 | D12: =IF($B12="","",IFERROR(INDEX(이수현황!$C$6:$C$485,MATCH("R"&7,미이수현황!$L$6:$L$485,0)),"")) -> 관리팀 | E12: =IF($B12="","",IFERROR(INDEX(이수현황!$E$6:$E$485,MATCH("R"&7,미이수현황!$L$6:$L$485,0)),"")) -> 산업안전보건교육 | F12: =IF($B12="","",IFERROR(INDEX(이수현황!$G$6:$G$485,MATCH("R"&7,미이수현황!$L$6:$L$485,0)),"")) | G12: =IF($B12="","",IFERROR(INDEX(이수현황!$H$6:$H$485,MATCH("R"&7,미이수현황!$L$6:$L$485,0)),"")) -> 44661 | H12: =IF($B12="","",IFERROR(INDEX(이수현황!$I$6:$I$485,MATCH("R"&7,미이수현황!$L$6:$L$485,0)),"")) -> -1618 | J12: =IF(이수현황!$A12="",FALSE(),OR(이수현황!$J12="기한초과",이수현황!$J12="임박")) -> FALSE | K12: =IF($J12=FALSE(),"",COUNTIF($J$6:$J12,TRUE())) | L12: =IF($K12="","","R"&$K12)
A13: =IF($B13="","",8) -> 8 | B13: =IFERROR(INDEX(이수현황!$A$6:$A$485,MATCH("R"&8,미이수현황!$L$6:$L$485,0)),"") -> E003 | C13: =IF($B13="","",IFERROR(INDEX(이수현황!$B$6:$B$485,MATCH("R"&8,미이수현황!$L$6:$L$485,0)),"")) -> 박직원 | D13: =IF($B13="","",IFERROR(INDEX(이수현황!$C$6:$C$485,MATCH("R"&8,미이수현황!$L$6:$L$485,0)),"")) -> 관리팀 | E13: =IF($B13="","",IFERROR(INDEX(이수현황!$E$6:$E$485,MATCH("R"&8,미이수현황!$L$6:$L$485,0)),"")) -> 성희롱 예방교육 | F13: =IF($B13="","",IFERROR(INDEX(이수현황!$G$6:$G$485,MATCH("R"&8,미이수현황!$L$6:$L$485,0)),"")) -> 45809 | G13: =IF($B13="","",IFERROR(INDEX(이수현황!$H$6:$H$485,MATCH("R"&8,미이수현황!$L$6:$L$485,0)),"")) -> 46174 | H13: =IF($B13="","",IFERROR(INDEX(이수현황!$I$6:$I$485,MATCH("R"&8,미이수현황!$L$6:$L$485,0)),"")) -> -105 | J13: =IF(이수현황!$A13="",FALSE(),OR(이수현황!$J13="기한초과",이수현황!$J13="임박")) -> FALSE | K13: =IF($J13=FALSE(),"",COUNTIF($J$6:$J13,TRUE())) | L13: =IF($K13="","","R"&$K13)
A14: =IF($B14="","",9) -> 9 | B14: =IFERROR(INDEX(이수현황!$A$6:$A$485,MATCH("R"&9,미이수현황!$L$6:$L$485,0)),"") -> E003 | C14: =IF($B14="","",IFERROR(INDEX(이수현황!$B$6:$B$485,MATCH("R"&9,미이수현황!$L$6:$L$485,0)),"")) -> 박직원 | D14: =IF($B14="","",IFERROR(INDEX(이수현황!$C$6:$C$485,MATCH("R"&9,미이수현황!$L$6:$L$485,0)),"")) -> 관리팀 | E14: =IF($B14="","",IFERROR(INDEX(이수현황!$E$6:$E$485,MATCH("R"&9,미이수현황!$L$6:$L$485,0)),"")) -> 개인정보보호 교육 | F14: =IF($B14="","",IFERROR(INDEX(이수현황!$G$6:$G$485,MATCH("R"&9,미이수현황!$L$6:$L$485,0)),"")) | G14: =IF($B14="","",IFERROR(INDEX(이수현황!$H$6:$H$485,MATCH("R"&9,미이수현황!$L$6:$L$485,0)),"")) -> 44936 | H14: =IF($B14="","",IFERROR(INDEX(이수현황!$I$6:$I$485,MATCH("R"&9,미이수현황!$L$6:$L$485,0)),"")) -> -1343 | J14: =IF(이수현황!$A14="",FALSE(),OR(이수현황!$J14="기한초과",이수현황!$J14="임박")) -> FALSE | K14: =IF($J14=FALSE(),"",COUNTIF($J$6:$J14,TRUE())) | L14: =IF($K14="","","R"&$K14)
A15: =IF($B15="","",10) -> 10 | B15: =IFERROR(INDEX(이수현황!$A$6:$A$485,MATCH("R"&10,미이수현황!$L$6:$L$485,0)),"") -> E003 | C15: =IF($B15="","",IFERROR(INDEX(이수현황!$B$6:$B$485,MATCH("R"&10,미이수현황!$L$6:$L$485,0)),"")) -> 박직원 | D15: =IF($B15="","",IFERROR(INDEX(이수현황!$C$6:$C$485,MATCH("R"&10,미이수현황!$L$6:$L$485,0)),"")) -> 관리팀 | E15: =IF($B15="","",IFERROR(INDEX(이수현황!$E$6:$E$485,MATCH("R"&10,미이수현황!$L$6:$L$485,0)),"")) -> 지게차 운전 자격 | F15: =IF($B15="","",IFERROR(INDEX(이수현황!$G$6:$G$485,MATCH("R"&10,미이수현황!$L$6:$L$485,0)),"")) | G15: =IF($B15="","",IFERROR(INDEX(이수현황!$H$6:$H$485,MATCH("R"&10,미이수현황!$L$6:$L$485,0)),"")) -> 45301 | H15: =IF($B15="","",IFERROR(INDEX(이수현황!$I$6:$I$485,MATCH("R"&10,미이수현황!$L$6:$L$485,0)),"")) -> -978 | J15: =IF(이수현황!$A15="",FALSE(),OR(이수현황!$J15="기한초과",이수현황!$J15="임박")) -> FALSE | K15: =IF($J15=FALSE(),"",COUNTIF($J$6:$J15,TRUE())) | L15: =IF($K15="","","R"&$K15)
A16: =IF($B16="","",11) | B16: =IFERROR(INDEX(이수현황!$A$6:$A$485,MATCH("R"&11,미이수현황!$L$6:$L$485,0)),"") | C16: =IF($B16="","",IFERROR(INDEX(이수현황!$B$6:$B$485,MATCH("R"&11,미이수현황!$L$6:$L$485,0)),"")) | D16: =IF($B16="","",IFERROR(INDEX(이수현황!$C$6:$C$485,MATCH("R"&11,미이수현황!$L$6:$L$485,0)),"")) | E16: =IF($B16="","",IFERROR(INDEX(이수현황!$E$6:$E$485,MATCH("R"&11,미이수현황!$L$6:$L$485,0)),"")) | F16: =IF($B16="","",IFERROR(INDEX(이수현황!$G$6:$G$485,MATCH("R"&11,미이수현황!$L$6:$L$485,0)),"")) | G16: =IF($B16="","",IFERROR(INDEX(이수현황!$H$6:$H$485,MATCH("R"&11,미이수현황!$L$6:$L$485,0)),"")) | H16: =IF($B16="","",IFERROR(INDEX(이수현황!$I$6:$I$485,MATCH("R"&11,미이수현황!$L$6:$L$485,0)),"")) | J16: =IF(이수현황!$A16="",FALSE(),OR(이수현황!$J16="기한초과",이수현황!$J16="임박")) -> FALSE | K16: =IF($J16=FALSE(),"",COUNTIF($J$6:$J16,TRUE())) | L16: =IF($K16="","","R"&$K16)
A17: =IF($B17="","",12) | B17: =IFERROR(INDEX(이수현황!$A$6:$A$485,MATCH("R"&12,미이수현황!$L$6:$L$485,0)),"") | C17: =IF($B17="","",IFERROR(INDEX(이수현황!$B$6:$B$485,MATCH("R"&12,미이수현황!$L$6:$L$485,0)),"")) | D17: =IF($B17="","",IFERROR(INDEX(이수현황!$C$6:$C$485,MATCH("R"&12,미이수현황!$L$6:$L$485,0)),"")) | E17: =IF($B17="","",IFERROR(INDEX(이수현황!$E$6:$E$485,MATCH("R"&12,미이수현황!$L$6:$L$485,0)),"")) | F17: =IF($B17="","",IFERROR(INDEX(이수현황!$G$6:$G$485,MATCH("R"&12,미이수현황!$L$6:$L$485,0)),"")) | G17: =IF($B17="","",IFERROR(INDEX(이수현황!$H$6:$H$485,MATCH("R"&12,미이수현황!$L$6:$L$485,0)),"")) | H17: =IF($B17="","",IFERROR(INDEX(이수현황!$I$6:$I$485,MATCH("R"&12,미이수현황!$L$6:$L$485,0)),"")) | J17: =IF(이수현황!$A17="",FALSE(),OR(이수현황!$J17="기한초과",이수현황!$J17="임박")) -> FALSE | K17: =IF($J17=FALSE(),"",COUNTIF($J$6:$J17,TRUE())) | L17: =IF($K17="","","R"&$K17)
A18: =IF($B18="","",13) | B18: =IFERROR(INDEX(이수현황!$A$6:$A$485,MATCH("R"&13,미이수현황!$L$6:$L$485,0)),"") | C18: =IF($B18="","",IFERROR(INDEX(이수현황!$B$6:$B$485,MATCH("R"&13,미이수현황!$L$6:$L$485,0)),"")) | D18: =IF($B18="","",IFERROR(INDEX(이수현황!$C$6:$C$485,MATCH("R"&13,미이수현황!$L$6:$L$485,0)),"")) | E18: =IF($B18="","",IFERROR(INDEX(이수현황!$E$6:$E$485,MATCH("R"&13,미이수현황!$L$6:$L$485,0)),"")) | F18: =IF($B18="","",IFERROR(INDEX(이수현황!$G$6:$G$485,MATCH("R"&13,미이수현황!$L$6:$L$485,0)),"")) | G18: =IF($B18="","",IFERROR(INDEX(이수현황!$H$6:$H$485,MATCH("R"&13,미이수현황!$L$6:$L$485,0)),"")) | H18: =IF($B18="","",IFERROR(INDEX(이수현황!$I$6:$I$485,MATCH("R"&13,미이수현황!$L$6:$L$485,0)),"")) | J18: =IF(이수현황!$A18="",FALSE(),OR(이수현황!$J18="기한초과",이수현황!$J18="임박")) -> FALSE | K18: =IF($J18=FALSE(),"",COUNTIF($J$6:$J18,TRUE())) | L18: =IF($K18="","","R"&$K18)
A19: =IF($B19="","",14) | B19: =IFERROR(INDEX(이수현황!$A$6:$A$485,MATCH("R"&14,미이수현황!$L$6:$L$485,0)),"") | C19: =IF($B19="","",IFERROR(INDEX(이수현황!$B$6:$B$485,MATCH("R"&14,미이수현황!$L$6:$L$485,0)),"")) | D19: =IF($B19="","",IFERROR(INDEX(이수현황!$C$6:$C$485,MATCH("R"&14,미이수현황!$L$6:$L$485,0)),"")) | E19: =IF($B19="","",IFERROR(INDEX(이수현황!$E$6:$E$485,MATCH("R"&14,미이수현황!$L$6:$L$485,0)),"")) | F19: =IF($B19="","",IFERROR(INDEX(이수현황!$G$6:$G$485,MATCH("R"&14,미이수현황!$L$6:$L$485,0)),"")) | G19: =IF($B19="","",IFERROR(INDEX(이수현황!$H$6:$H$485,MATCH("R"&14,미이수현황!$L$6:$L$485,0)),"")) | H19: =IF($B19="","",IFERROR(INDEX(이수현황!$I$6:$I$485,MATCH("R"&14,미이수현황!$L$6:$L$485,0)),"")) | J19: =IF(이수현황!$A19="",FALSE(),OR(이수현황!$J19="기한초과",이수현황!$J19="임박")) -> TRUE | K19: =IF($J19=FALSE(),"",COUNTIF($J$6:$J19,TRUE())) -> 4 | L19: =IF($K19="","","R"&$K19) -> R4
A20: =IF($B20="","",15) | B20: =IFERROR(INDEX(이수현황!$A$6:$A$485,MATCH("R"&15,미이수현황!$L$6:$L$485,0)),"") | C20: =IF($B20="","",IFERROR(INDEX(이수현황!$B$6:$B$485,MATCH("R"&15,미이수현황!$L$6:$L$485,0)),"")) | D20: =IF($B20="","",IFERROR(INDEX(이수현황!$C$6:$C$485,MATCH("R"&15,미이수현황!$L$6:$L$485,0)),"")) | E20: =IF($B20="","",IFERROR(INDEX(이수현황!$E$6:$E$485,MATCH("R"&15,미이수현황!$L$6:$L$485,0)),"")) | F20: =IF($B20="","",IFERROR(INDEX(이수현황!$G$6:$G$485,MATCH("R"&15,미이수현황!$L$6:$L$485,0)),"")) | G20: =IF($B20="","",IFERROR(INDEX(이수현황!$H$6:$H$485,MATCH("R"&15,미이수현황!$L$6:$L$485,0)),"")) | H20: =IF($B20="","",IFERROR(INDEX(이수현황!$I$6:$I$485,MATCH("R"&15,미이수현황!$L$6:$L$485,0)),"")) | J20: =IF(이수현황!$A20="",FALSE(),OR(이수현황!$J20="기한초과",이수현황!$J20="임박")) -> TRUE | K20: =IF($J20=FALSE(),"",COUNTIF($J$6:$J20,TRUE())) -> 5 | L20: =IF($K20="","","R"&$K20) -> R5
A21: =IF($B21="","",16) | B21: =IFERROR(INDEX(이수현황!$A$6:$A$485,MATCH("R"&16,미이수현황!$L$6:$L$485,0)),"") | C21: =IF($B21="","",IFERROR(INDEX(이수현황!$B$6:$B$485,MATCH("R"&16,미이수현황!$L$6:$L$485,0)),"")) | D21: =IF($B21="","",IFERROR(INDEX(이수현황!$C$6:$C$485,MATCH("R"&16,미이수현황!$L$6:$L$485,0)),"")) | E21: =IF($B21="","",IFERROR(INDEX(이수현황!$E$6:$E$485,MATCH("R"&16,미이수현황!$L$6:$L$485,0)),"")) | F21: =IF($B21="","",IFERROR(INDEX(이수현황!$G$6:$G$485,MATCH("R"&16,미이수현황!$L$6:$L$485,0)),"")) | G21: =IF($B21="","",IFERROR(INDEX(이수현황!$H$6:$H$485,MATCH("R"&16,미이수현황!$L$6:$L$485,0)),"")) | H21: =IF($B21="","",IFERROR(INDEX(이수현황!$I$6:$I$485,MATCH("R"&16,미이수현황!$L$6:$L$485,0)),"")) | J21: =IF(이수현황!$A21="",FALSE(),OR(이수현황!$J21="기한초과",이수현황!$J21="임박")) -> TRUE | K21: =IF($J21=FALSE(),"",COUNTIF($J$6:$J21,TRUE())) -> 6 | L21: =IF($K21="","","R"&$K21) -> R6
A22: =IF($B22="","",17) | B22: =IFERROR(INDEX(이수현황!$A$6:$A$485,MATCH("R"&17,미이수현황!$L$6:$L$485,0)),"") | C22: =IF($B22="","",IFERROR(INDEX(이수현황!$B$6:$B$485,MATCH("R"&17,미이수현황!$L$6:$L$485,0)),"")) | D22: =IF($B22="","",IFERROR(INDEX(이수현황!$C$6:$C$485,MATCH("R"&17,미이수현황!$L$6:$L$485,0)),"")) | E22: =IF($B22="","",IFERROR(INDEX(이수현황!$E$6:$E$485,MATCH("R"&17,미이수현황!$L$6:$L$485,0)),"")) | F22: =IF($B22="","",IFERROR(INDEX(이수현황!$G$6:$G$485,MATCH("R"&17,미이수현황!$L$6:$L$485,0)),"")) | G22: =IF($B22="","",IFERROR(INDEX(이수현황!$H$6:$H$485,MATCH("R"&17,미이수현황!$L$6:$L$485,0)),"")) | H22: =IF($B22="","",IFERROR(INDEX(이수현황!$I$6:$I$485,MATCH("R"&17,미이수현황!$L$6:$L$485,0)),"")) | J22: =IF(이수현황!$A22="",FALSE(),OR(이수현황!$J22="기한초과",이수현황!$J22="임박")) -> FALSE | K22: =IF($J22=FALSE(),"",COUNTIF($J$6:$J22,TRUE())) | L22: =IF($K22="","","R"&$K22)
A23: =IF($B23="","",18) | B23: =IFERROR(INDEX(이수현황!$A$6:$A$485,MATCH("R"&18,미이수현황!$L$6:$L$485,0)),"") | C23: =IF($B23="","",IFERROR(INDEX(이수현황!$B$6:$B$485,MATCH("R"&18,미이수현황!$L$6:$L$485,0)),"")) | D23: =IF($B23="","",IFERROR(INDEX(이수현황!$C$6:$C$485,MATCH("R"&18,미이수현황!$L$6:$L$485,0)),"")) | E23: =IF($B23="","",IFERROR(INDEX(이수현황!$E$6:$E$485,MATCH("R"&18,미이수현황!$L$6:$L$485,0)),"")) | F23: =IF($B23="","",IFERROR(INDEX(이수현황!$G$6:$G$485,MATCH("R"&18,미이수현황!$L$6:$L$485,0)),"")) | G23: =IF($B23="","",IFERROR(INDEX(이수현황!$H$6:$H$485,MATCH("R"&18,미이수현황!$L$6:$L$485,0)),"")) | H23: =IF($B23="","",IFERROR(INDEX(이수현황!$I$6:$I$485,MATCH("R"&18,미이수현황!$L$6:$L$485,0)),"")) | J23: =IF(이수현황!$A23="",FALSE(),OR(이수현황!$J23="기한초과",이수현황!$J23="임박")) -> FALSE | K23: =IF($J23=FALSE(),"",COUNTIF($J$6:$J23,TRUE())) | L23: =IF($K23="","","R"&$K23)
A24: =IF($B24="","",19) | B24: =IFERROR(INDEX(이수현황!$A$6:$A$485,MATCH("R"&19,미이수현황!$L$6:$L$485,0)),"") | C24: =IF($B24="","",IFERROR(INDEX(이수현황!$B$6:$B$485,MATCH("R"&19,미이수현황!$L$6:$L$485,0)),"")) | D24: =IF($B24="","",IFERROR(INDEX(이수현황!$C$6:$C$485,MATCH("R"&19,미이수현황!$L$6:$L$485,0)),"")) | E24: =IF($B24="","",IFERROR(INDEX(이수현황!$E$6:$E$485,MATCH("R"&19,미이수현황!$L$6:$L$485,0)),"")) | F24: =IF($B24="","",IFERROR(INDEX(이수현황!$G$6:$G$485,MATCH("R"&19,미이수현황!$L$6:$L$485,0)),"")) | G24: =IF($B24="","",IFERROR(INDEX(이수현황!$H$6:$H$485,MATCH("R"&19,미이수현황!$L$6:$L$485,0)),"")) | H24: =IF($B24="","",IFERROR(INDEX(이수현황!$I$6:$I$485,MATCH("R"&19,미이수현황!$L$6:$L$485,0)),"")) | J24: =IF(이수현황!$A24="",FALSE(),OR(이수현황!$J24="기한초과",이수현황!$J24="임박")) -> FALSE | K24: =IF($J24=FALSE(),"",COUNTIF($J$6:$J24,TRUE())) | L24: =IF($K24="","","R"&$K24)
A25: =IF($B25="","",20) | B25: =IFERROR(INDEX(이수현황!$A$6:$A$485,MATCH("R"&20,미이수현황!$L$6:$L$485,0)),"") | C25: =IF($B25="","",IFERROR(INDEX(이수현황!$B$6:$B$485,MATCH("R"&20,미이수현황!$L$6:$L$485,0)),"")) | D25: =IF($B25="","",IFERROR(INDEX(이수현황!$C$6:$C$485,MATCH("R"&20,미이수현황!$L$6:$L$485,0)),"")) | E25: =IF($B25="","",IFERROR(INDEX(이수현황!$E$6:$E$485,MATCH("R"&20,미이수현황!$L$6:$L$485,0)),"")) | F25: =IF($B25="","",IFERROR(INDEX(이수현황!$G$6:$G$485,MATCH("R"&20,미이수현황!$L$6:$L$485,0)),"")) | G25: =IF($B25="","",IFERROR(INDEX(이수현황!$H$6:$H$485,MATCH("R"&20,미이수현황!$L$6:$L$485,0)),"")) | H25: =IF($B25="","",IFERROR(INDEX(이수현황!$I$6:$I$485,MATCH("R"&20,미이수현황!$L$6:$L$485,0)),"")) | J25: =IF(이수현황!$A25="",FALSE(),OR(이수현황!$J25="기한초과",이수현황!$J25="임박")) -> FALSE | K25: =IF($J25=FALSE(),"",COUNTIF($J$6:$J25,TRUE())) | L25: =IF($K25="","","R"&$K25)
A26: =IF($B26="","",21) | B26: =IFERROR(INDEX(이수현황!$A$6:$A$485,MATCH("R"&21,미이수현황!$L$6:$L$485,0)),"") | C26: =IF($B26="","",IFERROR(INDEX(이수현황!$B$6:$B$485,MATCH("R"&21,미이수현황!$L$6:$L$485,0)),"")) | D26: =IF($B26="","",IFERROR(INDEX(이수현황!$C$6:$C$485,MATCH("R"&21,미이수현황!$L$6:$L$485,0)),"")) | E26: =IF($B26="","",IFERROR(INDEX(이수현황!$E$6:$E$485,MATCH("R"&21,미이수현황!$L$6:$L$485,0)),"")) | F26: =IF($B26="","",IFERROR(INDEX(이수현황!$G$6:$G$485,MATCH("R"&21,미이수현황!$L$6:$L$485,0)),"")) | G26: =IF($B26="","",IFERROR(INDEX(이수현황!$H$6:$H$485,MATCH("R"&21,미이수현황!$L$6:$L$485,0)),"")) | H26: =IF($B26="","",IFERROR(INDEX(이수현황!$I$6:$I$485,MATCH("R"&21,미이수현황!$L$6:$L$485,0)),"")) | J26: =IF(이수현황!$A26="",FALSE(),OR(이수현황!$J26="기한초과",이수현황!$J26="임박")) -> FALSE | K26: =IF($J26=FALSE(),"",COUNTIF($J$6:$J26,TRUE())) | L26: =IF($K26="","","R"&$K26)
A27: =IF($B27="","",22) | B27: =IFERROR(INDEX(이수현황!$A$6:$A$485,MATCH("R"&22,미이수현황!$L$6:$L$485,0)),"") | C27: =IF($B27="","",IFERROR(INDEX(이수현황!$B$6:$B$485,MATCH("R"&22,미이수현황!$L$6:$L$485,0)),"")) | D27: =IF($B27="","",IFERROR(INDEX(이수현황!$C$6:$C$485,MATCH("R"&22,미이수현황!$L$6:$L$485,0)),"")) | E27: =IF($B27="","",IFERROR(INDEX(이수현황!$E$6:$E$485,MATCH("R"&22,미이수현황!$L$6:$L$485,0)),"")) | F27: =IF($B27="","",IFERROR(INDEX(이수현황!$G$6:$G$485,MATCH("R"&22,미이수현황!$L$6:$L$485,0)),"")) | G27: =IF($B27="","",IFERROR(INDEX(이수현황!$H$6:$H$485,MATCH("R"&22,미이수현황!$L$6:$L$485,0)),"")) | H27: =IF($B27="","",IFERROR(INDEX(이수현황!$I$6:$I$485,MATCH("R"&22,미이수현황!$L$6:$L$485,0)),"")) | J27: =IF(이수현황!$A27="",FALSE(),OR(이수현황!$J27="기한초과",이수현황!$J27="임박")) -> FALSE | K27: =IF($J27=FALSE(),"",COUNTIF($J$6:$J27,TRUE())) | L27: =IF($K27="","","R"&$K27)
A28: =IF($B28="","",23) | B28: =IFERROR(INDEX(이수현황!$A$6:$A$485,MATCH("R"&23,미이수현황!$L$6:$L$485,0)),"") | C28: =IF($B28="","",IFERROR(INDEX(이수현황!$B$6:$B$485,MATCH("R"&23,미이수현황!$L$6:$L$485,0)),"")) | D28: =IF($B28="","",IFERROR(INDEX(이수현황!$C$6:$C$485,MATCH("R"&23,미이수현황!$L$6:$L$485,0)),"")) | E28: =IF($B28="","",IFERROR(INDEX(이수현황!$E$6:$E$485,MATCH("R"&23,미이수현황!$L$6:$L$485,0)),"")) | F28: =IF($B28="","",IFERROR(INDEX(이수현황!$G$6:$G$485,MATCH("R"&23,미이수현황!$L$6:$L$485,0)),"")) | G28: =IF($B28="","",IFERROR(INDEX(이수현황!$H$6:$H$485,MATCH("R"&23,미이수현황!$L$6:$L$485,0)),"")) | H28: =IF($B28="","",IFERROR(INDEX(이수현황!$I$6:$I$485,MATCH("R"&23,미이수현황!$L$6:$L$485,0)),"")) | J28: =IF(이수현황!$A28="",FALSE(),OR(이수현황!$J28="기한초과",이수현황!$J28="임박")) -> FALSE | K28: =IF($J28=FALSE(),"",COUNTIF($J$6:$J28,TRUE())) | L28: =IF($K28="","","R"&$K28)
A29: =IF($B29="","",24) | B29: =IFERROR(INDEX(이수현황!$A$6:$A$485,MATCH("R"&24,미이수현황!$L$6:$L$485,0)),"") | C29: =IF($B29="","",IFERROR(INDEX(이수현황!$B$6:$B$485,MATCH("R"&24,미이수현황!$L$6:$L$485,0)),"")) | D29: =IF($B29="","",IFERROR(INDEX(이수현황!$C$6:$C$485,MATCH("R"&24,미이수현황!$L$6:$L$485,0)),"")) | E29: =IF($B29="","",IFERROR(INDEX(이수현황!$E$6:$E$485,MATCH("R"&24,미이수현황!$L$6:$L$485,0)),"")) | F29: =IF($B29="","",IFERROR(INDEX(이수현황!$G$6:$G$485,MATCH("R"&24,미이수현황!$L$6:$L$485,0)),"")) | G29: =IF($B29="","",IFERROR(INDEX(이수현황!$H$6:$H$485,MATCH("R"&24,미이수현황!$L$6:$L$485,0)),"")) | H29: =IF($B29="","",IFERROR(INDEX(이수현황!$I$6:$I$485,MATCH("R"&24,미이수현황!$L$6:$L$485,0)),"")) | J29: =IF(이수현황!$A29="",FALSE(),OR(이수현황!$J29="기한초과",이수현황!$J29="임박")) -> FALSE | K29: =IF($J29=FALSE(),"",COUNTIF($J$6:$J29,TRUE())) | L29: =IF($K29="","","R"&$K29)
A30: =IF($B30="","",25) | B30: =IFERROR(INDEX(이수현황!$A$6:$A$485,MATCH("R"&25,미이수현황!$L$6:$L$485,0)),"") | C30: =IF($B30="","",IFERROR(INDEX(이수현황!$B$6:$B$485,MATCH("R"&25,미이수현황!$L$6:$L$485,0)),"")) | D30: =IF($B30="","",IFERROR(INDEX(이수현황!$C$6:$C$485,MATCH("R"&25,미이수현황!$L$6:$L$485,0)),"")) | E30: =IF($B30="","",IFERROR(INDEX(이수현황!$E$6:$E$485,MATCH("R"&25,미이수현황!$L$6:$L$485,0)),"")) | F30: =IF($B30="","",IFERROR(INDEX(이수현황!$G$6:$G$485,MATCH("R"&25,미이수현황!$L$6:$L$485,0)),"")) | G30: =IF($B30="","",IFERROR(INDEX(이수현황!$H$6:$H$485,MATCH("R"&25,미이수현황!$L$6:$L$485,0)),"")) | H30: =IF($B30="","",IFERROR(INDEX(이수현황!$I$6:$I$485,MATCH("R"&25,미이수현황!$L$6:$L$485,0)),"")) | J30: =IF(이수현황!$A30="",FALSE(),OR(이수현황!$J30="기한초과",이수현황!$J30="임박")) -> TRUE | K30: =IF($J30=FALSE(),"",COUNTIF($J$6:$J30,TRUE())) -> 7 | L30: =IF($K30="","","R"&$K30) -> R7
A31: =IF($B31="","",26) | B31: =IFERROR(INDEX(이수현황!$A$6:$A$485,MATCH("R"&26,미이수현황!$L$6:$L$485,0)),"") | C31: =IF($B31="","",IFERROR(INDEX(이수현황!$B$6:$B$485,MATCH("R"&26,미이수현황!$L$6:$L$485,0)),"")) | D31: =IF($B31="","",IFERROR(INDEX(이수현황!$C$6:$C$485,MATCH("R"&26,미이수현황!$L$6:$L$485,0)),"")) | E31: =IF($B31="","",IFERROR(INDEX(이수현황!$E$6:$E$485,MATCH("R"&26,미이수현황!$L$6:$L$485,0)),"")) | F31: =IF($B31="","",IFERROR(INDEX(이수현황!$G$6:$G$485,MATCH("R"&26,미이수현황!$L$6:$L$485,0)),"")) | G31: =IF($B31="","",IFERROR(INDEX(이수현황!$H$6:$H$485,MATCH("R"&26,미이수현황!$L$6:$L$485,0)),"")) | H31: =IF($B31="","",IFERROR(INDEX(이수현황!$I$6:$I$485,MATCH("R"&26,미이수현황!$L$6:$L$485,0)),"")) | J31: =IF(이수현황!$A31="",FALSE(),OR(이수현황!$J31="기한초과",이수현황!$J31="임박")) -> TRUE | K31: =IF($J31=FALSE(),"",COUNTIF($J$6:$J31,TRUE())) -> 8 | L31: =IF($K31="","","R"&$K31) -> R8
A32: =IF($B32="","",27) | B32: =IFERROR(INDEX(이수현황!$A$6:$A$485,MATCH("R"&27,미이수현황!$L$6:$L$485,0)),"") | C32: =IF($B32="","",IFERROR(INDEX(이수현황!$B$6:$B$485,MATCH("R"&27,미이수현황!$L$6:$L$485,0)),"")) | D32: =IF($B32="","",IFERROR(INDEX(이수현황!$C$6:$C$485,MATCH("R"&27,미이수현황!$L$6:$L$485,0)),"")) | E32: =IF($B32="","",IFERROR(INDEX(이수현황!$E$6:$E$485,MATCH("R"&27,미이수현황!$L$6:$L$485,0)),"")) | F32: =IF($B32="","",IFERROR(INDEX(이수현황!$G$6:$G$485,MATCH("R"&27,미이수현황!$L$6:$L$485,0)),"")) | G32: =IF($B32="","",IFERROR(INDEX(이수현황!$H$6:$H$485,MATCH("R"&27,미이수현황!$L$6:$L$485,0)),"")) | H32: =IF($B32="","",IFERROR(INDEX(이수현황!$I$6:$I$485,MATCH("R"&27,미이수현황!$L$6:$L$485,0)),"")) | J32: =IF(이수현황!$A32="",FALSE(),OR(이수현황!$J32="기한초과",이수현황!$J32="임박")) -> TRUE | K32: =IF($J32=FALSE(),"",COUNTIF($J$6:$J32,TRUE())) -> 9 | L32: =IF($K32="","","R"&$K32) -> R9
A33: =IF($B33="","",28) | B33: =IFERROR(INDEX(이수현황!$A$6:$A$485,MATCH("R"&28,미이수현황!$L$6:$L$485,0)),"") | C33: =IF($B33="","",IFERROR(INDEX(이수현황!$B$6:$B$485,MATCH("R"&28,미이수현황!$L$6:$L$485,0)),"")) | D33: =IF($B33="","",IFERROR(INDEX(이수현황!$C$6:$C$485,MATCH("R"&28,미이수현황!$L$6:$L$485,0)),"")) | E33: =IF($B33="","",IFERROR(INDEX(이수현황!$E$6:$E$485,MATCH("R"&28,미이수현황!$L$6:$L$485,0)),"")) | F33: =IF($B33="","",IFERROR(INDEX(이수현황!$G$6:$G$485,MATCH("R"&28,미이수현황!$L$6:$L$485,0)),"")) | G33: =IF($B33="","",IFERROR(INDEX(이수현황!$H$6:$H$485,MATCH("R"&28,미이수현황!$L$6:$L$485,0)),"")) | H33: =IF($B33="","",IFERROR(INDEX(이수현황!$I$6:$I$485,MATCH("R"&28,미이수현황!$L$6:$L$485,0)),"")) | J33: =IF(이수현황!$A33="",FALSE(),OR(이수현황!$J33="기한초과",이수현황!$J33="임박")) -> TRUE | K33: =IF($J33=FALSE(),"",COUNTIF($J$6:$J33,TRUE())) -> 10 | L33: =IF($K33="","","R"&$K33) -> R10
A34: =IF($B34="","",29) | B34: =IFERROR(INDEX(이수현황!$A$6:$A$485,MATCH("R"&29,미이수현황!$L$6:$L$485,0)),"") | C34: =IF($B34="","",IFERROR(INDEX(이수현황!$B$6:$B$485,MATCH("R"&29,미이수현황!$L$6:$L$485,0)),"")) | D34: =IF($B34="","",IFERROR(INDEX(이수현황!$C$6:$C$485,MATCH("R"&29,미이수현황!$L$6:$L$485,0)),"")) | E34: =IF($B34="","",IFERROR(INDEX(이수현황!$E$6:$E$485,MATCH("R"&29,미이수현황!$L$6:$L$485,0)),"")) | F34: =IF($B34="","",IFERROR(INDEX(이수현황!$G$6:$G$485,MATCH("R"&29,미이수현황!$L$6:$L$485,0)),"")) | G34: =IF($B34="","",IFERROR(INDEX(이수현황!$H$6:$H$485,MATCH("R"&29,미이수현황!$L$6:$L$485,0)),"")) | H34: =IF($B34="","",IFERROR(INDEX(이수현황!$I$6:$I$485,MATCH("R"&29,미이수현황!$L$6:$L$485,0)),"")) | J34: =IF(이수현황!$A34="",FALSE(),OR(이수현황!$J34="기한초과",이수현황!$J34="임박")) -> FALSE | K34: =IF($J34=FALSE(),"",COUNTIF($J$6:$J34,TRUE())) | L34: =IF($K34="","","R"&$K34)
A35: =IF($B35="","",30) | B35: =IFERROR(INDEX(이수현황!$A$6:$A$485,MATCH("R"&30,미이수현황!$L$6:$L$485,0)),"") | C35: =IF($B35="","",IFERROR(INDEX(이수현황!$B$6:$B$485,MATCH("R"&30,미이수현황!$L$6:$L$485,0)),"")) | D35: =IF($B35="","",IFERROR(INDEX(이수현황!$C$6:$C$485,MATCH("R"&30,미이수현황!$L$6:$L$485,0)),"")) | E35: =IF($B35="","",IFERROR(INDEX(이수현황!$E$6:$E$485,MATCH("R"&30,미이수현황!$L$6:$L$485,0)),"")) | F35: =IF($B35="","",IFERROR(INDEX(이수현황!$G$6:$G$485,MATCH("R"&30,미이수현황!$L$6:$L$485,0)),"")) | G35: =IF($B35="","",IFERROR(INDEX(이수현황!$H$6:$H$485,MATCH("R"&30,미이수현황!$L$6:$L$485,0)),"")) | H35: =IF($B35="","",IFERROR(INDEX(이수현황!$I$6:$I$485,MATCH("R"&30,미이수현황!$L$6:$L$485,0)),"")) | J35: =IF(이수현황!$A35="",FALSE(),OR(이수현황!$J35="기한초과",이수현황!$J35="임박")) -> FALSE | K35: =IF($J35=FALSE(),"",COUNTIF($J$6:$J35,TRUE())) | L35: =IF($K35="","","R"&$K35)
A36: =IF($B36="","",31) | B36: =IFERROR(INDEX(이수현황!$A$6:$A$485,MATCH("R"&31,미이수현황!$L$6:$L$485,0)),"") | C36: =IF($B36="","",IFERROR(INDEX(이수현황!$B$6:$B$485,MATCH("R"&31,미이수현황!$L$6:$L$485,0)),"")) | D36: =IF($B36="","",IFERROR(INDEX(이수현황!$C$6:$C$485,MATCH("R"&31,미이수현황!$L$6:$L$485,0)),"")) | E36: =IF($B36="","",IFERROR(INDEX(이수현황!$E$6:$E$485,MATCH("R"&31,미이수현황!$L$6:$L$485,0)),"")) | F36: =IF($B36="","",IFERROR(INDEX(이수현황!$G$6:$G$485,MATCH("R"&31,미이수현황!$L$6:$L$485,0)),"")) | G36: =IF($B36="","",IFERROR(INDEX(이수현황!$H$6:$H$485,MATCH("R"&31,미이수현황!$L$6:$L$485,0)),"")) | H36: =IF($B36="","",IFERROR(INDEX(이수현황!$I$6:$I$485,MATCH("R"&31,미이수현황!$L$6:$L$485,0)),"")) | J36: =IF(이수현황!$A36="",FALSE(),OR(이수현황!$J36="기한초과",이수현황!$J36="임박")) -> FALSE | K36: =IF($J36=FALSE(),"",COUNTIF($J$6:$J36,TRUE())) | L36: =IF($K36="","","R"&$K36)
A37: =IF($B37="","",32) | B37: =IFERROR(INDEX(이수현황!$A$6:$A$485,MATCH("R"&32,미이수현황!$L$6:$L$485,0)),"") | C37: =IF($B37="","",IFERROR(INDEX(이수현황!$B$6:$B$485,MATCH("R"&32,미이수현황!$L$6:$L$485,0)),"")) | D37: =IF($B37="","",IFERROR(INDEX(이수현황!$C$6:$C$485,MATCH("R"&32,미이수현황!$L$6:$L$485,0)),"")) | E37: =IF($B37="","",IFERROR(INDEX(이수현황!$E$6:$E$485,MATCH("R"&32,미이수현황!$L$6:$L$485,0)),"")) | F37: =IF($B37="","",IFERROR(INDEX(이수현황!$G$6:$G$485,MATCH("R"&32,미이수현황!$L$6:$L$485,0)),"")) | G37: =IF($B37="","",IFERROR(INDEX(이수현황!$H$6:$H$485,MATCH("R"&32,미이수현황!$L$6:$L$485,0)),"")) | H37: =IF($B37="","",IFERROR(INDEX(이수현황!$I$6:$I$485,MATCH("R"&32,미이수현황!$L$6:$L$485,0)),"")) | J37: =IF(이수현황!$A37="",FALSE(),OR(이수현황!$J37="기한초과",이수현황!$J37="임박")) -> FALSE | K37: =IF($J37=FALSE(),"",COUNTIF($J$6:$J37,TRUE())) | L37: =IF($K37="","","R"&$K37)
A38: =IF($B38="","",33) | B38: =IFERROR(INDEX(이수현황!$A$6:$A$485,MATCH("R"&33,미이수현황!$L$6:$L$485,0)),"") | C38: =IF($B38="","",IFERROR(INDEX(이수현황!$B$6:$B$485,MATCH("R"&33,미이수현황!$L$6:$L$485,0)),"")) | D38: =IF($B38="","",IFERROR(INDEX(이수현황!$C$6:$C$485,MATCH("R"&33,미이수현황!$L$6:$L$485,0)),"")) | E38: =IF($B38="","",IFERROR(INDEX(이수현황!$E$6:$E$485,MATCH("R"&33,미이수현황!$L$6:$L$485,0)),"")) | F38: =IF($B38="","",IFERROR(INDEX(이수현황!$G$6:$G$485,MATCH("R"&33,미이수현황!$L$6:$L$485,0)),"")) | G38: =IF($B38="","",IFERROR(INDEX(이수현황!$H$6:$H$485,MATCH("R"&33,미이수현황!$L$6:$L$485,0)),"")) | H38: =IF($B38="","",IFERROR(INDEX(이수현황!$I$6:$I$485,MATCH("R"&33,미이수현황!$L$6:$L$485,0)),"")) | J38: =IF(이수현황!$A38="",FALSE(),OR(이수현황!$J38="기한초과",이수현황!$J38="임박")) -> FALSE | K38: =IF($J38=FALSE(),"",COUNTIF($J$6:$J38,TRUE())) | L38: =IF($K38="","","R"&$K38)
A39: =IF($B39="","",34) | B39: =IFERROR(INDEX(이수현황!$A$6:$A$485,MATCH("R"&34,미이수현황!$L$6:$L$485,0)),"") | C39: =IF($B39="","",IFERROR(INDEX(이수현황!$B$6:$B$485,MATCH("R"&34,미이수현황!$L$6:$L$485,0)),"")) | D39: =IF($B39="","",IFERROR(INDEX(이수현황!$C$6:$C$485,MATCH("R"&34,미이수현황!$L$6:$L$485,0)),"")) | E39: =IF($B39="","",IFERROR(INDEX(이수현황!$E$6:$E$485,MATCH("R"&34,미이수현황!$L$6:$L$485,0)),"")) | F39: =IF($B39="","",IFERROR(INDEX(이수현황!$G$6:$G$485,MATCH("R"&34,미이수현황!$L$6:$L$485,0)),"")) | G39: =IF($B39="","",IFERROR(INDEX(이수현황!$H$6:$H$485,MATCH("R"&34,미이수현황!$L$6:$L$485,0)),"")) | H39: =IF($B39="","",IFERROR(INDEX(이수현황!$I$6:$I$485,MATCH("R"&34,미이수현황!$L$6:$L$485,0)),"")) | J39: =IF(이수현황!$A39="",FALSE(),OR(이수현황!$J39="기한초과",이수현황!$J39="임박")) -> FALSE | K39: =IF($J39=FALSE(),"",COUNTIF($J$6:$J39,TRUE())) | L39: =IF($K39="","","R"&$K39)
A40: =IF($B40="","",35) | B40: =IFERROR(INDEX(이수현황!$A$6:$A$485,MATCH("R"&35,미이수현황!$L$6:$L$485,0)),"") | C40: =IF($B40="","",IFERROR(INDEX(이수현황!$B$6:$B$485,MATCH("R"&35,미이수현황!$L$6:$L$485,0)),"")) | D40: =IF($B40="","",IFERROR(INDEX(이수현황!$C$6:$C$485,MATCH("R"&35,미이수현황!$L$6:$L$485,0)),"")) | E40: =IF($B40="","",IFERROR(INDEX(이수현황!$E$6:$E$485,MATCH("R"&35,미이수현황!$L$6:$L$485,0)),"")) | F40: =IF($B40="","",IFERROR(INDEX(이수현황!$G$6:$G$485,MATCH("R"&35,미이수현황!$L$6:$L$485,0)),"")) | G40: =IF($B40="","",IFERROR(INDEX(이수현황!$H$6:$H$485,MATCH("R"&35,미이수현황!$L$6:$L$485,0)),"")) | H40: =IF($B40="","",IFERROR(INDEX(이수현황!$I$6:$I$485,MATCH("R"&35,미이수현황!$L$6:$L$485,0)),"")) | J40: =IF(이수현황!$A40="",FALSE(),OR(이수현황!$J40="기한초과",이수현황!$J40="임박")) -> FALSE | K40: =IF($J40=FALSE(),"",COUNTIF($J$6:$J40,TRUE())) | L40: =IF($K40="","","R"&$K40)
A41: =IF($B41="","",36) | B41: =IFERROR(INDEX(이수현황!$A$6:$A$485,MATCH("R"&36,미이수현황!$L$6:$L$485,0)),"") | C41: =IF($B41="","",IFERROR(INDEX(이수현황!$B$6:$B$485,MATCH("R"&36,미이수현황!$L$6:$L$485,0)),"")) | D41: =IF($B41="","",IFERROR(INDEX(이수현황!$C$6:$C$485,MATCH("R"&36,미이수현황!$L$6:$L$485,0)),"")) | E41: =IF($B41="","",IFERROR(INDEX(이수현황!$E$6:$E$485,MATCH("R"&36,미이수현황!$L$6:$L$485,0)),"")) | F41: =IF($B41="","",IFERROR(INDEX(이수현황!$G$6:$G$485,MATCH("R"&36,미이수현황!$L$6:$L$485,0)),"")) | G41: =IF($B41="","",IFERROR(INDEX(이수현황!$H$6:$H$485,MATCH("R"&36,미이수현황!$L$6:$L$485,0)),"")) | H41: =IF($B41="","",IFERROR(INDEX(이수현황!$I$6:$I$485,MATCH("R"&36,미이수현황!$L$6:$L$485,0)),"")) | J41: =IF(이수현황!$A41="",FALSE(),OR(이수현황!$J41="기한초과",이수현황!$J41="임박")) -> FALSE | K41: =IF($J41=FALSE(),"",COUNTIF($J$6:$J41,TRUE())) | L41: =IF($K41="","","R"&$K41)
A42: =IF($B42="","",37) | B42: =IFERROR(INDEX(이수현황!$A$6:$A$485,MATCH("R"&37,미이수현황!$L$6:$L$485,0)),"") | C42: =IF($B42="","",IFERROR(INDEX(이수현황!$B$6:$B$485,MATCH("R"&37,미이수현황!$L$6:$L$485,0)),"")) | D42: =IF($B42="","",IFERROR(INDEX(이수현황!$C$6:$C$485,MATCH("R"&37,미이수현황!$L$6:$L$485,0)),"")) | E42: =IF($B42="","",IFERROR(INDEX(이수현황!$E$6:$E$485,MATCH("R"&37,미이수현황!$L$6:$L$485,0)),"")) | F42: =IF($B42="","",IFERROR(INDEX(이수현황!$G$6:$G$485,MATCH("R"&37,미이수현황!$L$6:$L$485,0)),"")) | G42: =IF($B42="","",IFERROR(INDEX(이수현황!$H$6:$H$485,MATCH("R"&37,미이수현황!$L$6:$L$485,0)),"")) | H42: =IF($B42="","",IFERROR(INDEX(이수현황!$I$6:$I$485,MATCH("R"&37,미이수현황!$L$6:$L$485,0)),"")) | J42: =IF(이수현황!$A42="",FALSE(),OR(이수현황!$J42="기한초과",이수현황!$J42="임박")) -> FALSE | K42: =IF($J42=FALSE(),"",COUNTIF($J$6:$J42,TRUE())) | L42: =IF($K42="","","R"&$K42)
...

Sheet 과정별집계
A1: 과정별집계
A3: 대상 연도 | B3: 2026
A5: 과정코드 | B5: 과정명 | C5: 구분 | D5: 주기(개월) | E5: 연간 이수 건수 | F5: 이수 인원 | G5: 총 이수시간 | H5: 미이수 인원
