Workbook

Sheet 사용안내
B2: 출퇴근 기록 · 근무시간 집계
B4: 핵심 | C4: 출근·퇴근 시각만 넣으면 근무시간이 자동으로 계산되고 월별로 집계됩니다.
B5: 입력 규칙 | C5: 파란색 글씨 칸만 입력하세요. 검은색은 자동 계산입니다.
B6: ① 직원목록 | C6: 사번·이름·부서와 하루 소정근로시간을 등록합니다.
B7: ② 출퇴근기록 | C7: 날짜·사번·출근·퇴근·휴게시간(분)만 넣으면 됩니다.
C8: 시각은 콜론(:) 없이 숫자 네 자리로 넣으세요. 오전 9시 → 900, 오후 6시 30분 → 1830
B9: ③ 월별집계 | C9: 직원별 근무일수·총 근무시간·소정시간 대비 초과시간이 나옵니다.
B10: ④ 개인별상세 | C10: 직원 한 명을 골라 한 달 기록을 날짜순으로 봅니다.
B11: ⑤ 일별현황 | C11: 날짜별 출근 인원과 총 근무시간입니다.
B12: 근무시간 계산 | C12: (퇴근 − 출근) − 휴게시간
B13: 중요 | C13: 이 파일은 근무시간만 집계합니다. 수당 금액은 계산하지 않습니다.
B15: ※ 연장·야간·휴일 수당은 법정 기준과 회사 규정에 따라 달라집니다.
B16: 이 파일은 시간만 보여주니 금액은 급여 담당자가 별도로 계산하세요.
B17: ※ 자정을 넘기는 근무는 계산되지 않습니다.

Sheet 직원목록
A1: 직원목록
A2: 사번 | B2: 이름 | C2: 부서 | D2: 직위 | E2: 입사일 | F2: 소정근로(시간/일) | G2: 재직상태
A3: E001 | B3: 김직원 | C3: 생산1팀 | D3: 사원 | E3: 45353 | F3: 8 | G3: 재직
A4: E002 | B4: 이직원 | C4: 생산1팀 | D4: 주임 | E4: 45061 | F4: 8 | G4: 재직
A5: E003 | B5: 박직원 | C5: 관리팀 | D5: 대리 | E5: 44571 | F5: 8 | G5: 재직

Sheet 출퇴근기록
A1: 출퇴근기록 (날짜·사번·출근·퇴근·휴게만 입력)
A2: 근무일 | B2: 사번 | C2: 이름(자동) | D2: 부서(자동) | E2: 출근시각 (예: 900) | F2: 퇴근시각 (예: 1830) | G2: 휴게(분) | H2: 근무시간(자동) | I2: 구분 | J2: 비고 | K2: 출근(분,자동) | L2: 퇴근(분,자동)
A3: 46266 | B3: E001 | C3: =IF($B3="","",IFERROR(INDEX(직원목록!$B$3:$B$302,MATCH($B3,직원목록!$A$3:$A$302,0)),"미등록사번")) -> 김직원 | D3: =IF($B3="","",IFERROR(INDEX(직원목록!$C$3:$C$302,MATCH($B3,직원목록!$A$3:$A$302,0)),"")) -> 생산1팀 | E3: 900 | F3: 1800 | G3: 60 | H3: =IF(OR($K3="",$L3=""),"",ROUND(MAX(0,($L3-$K3)-IF($G3="",0,$G3))/60,2)) -> 8 | I3: 평일 | J3: ← 예시 행입니다. 지우고 쓰세요. | K3: =IF($E3="","",IF($E3<1,ROUND($E3*1440,0),INT($E3/100)*60+MOD($E3,100))) -> 540 | L3: =IF($F3="","",IF($F3<1,ROUND($F3*1440,0),INT($F3/100)*60+MOD($F3,100))) -> 1080
A4: 46266 | B4: E002 | C4: =IF($B4="","",IFERROR(INDEX(직원목록!$B$3:$B$302,MATCH($B4,직원목록!$A$3:$A$302,0)),"미등록사번")) -> 이직원 | D4: =IF($B4="","",IFERROR(INDEX(직원목록!$C$3:$C$302,MATCH($B4,직원목록!$A$3:$A$302,0)),"")) -> 생산1팀 | E4: 900 | F4: 1800 | G4: 60 | H4: =IF(OR($K4="",$L4=""),"",ROUND(MAX(0,($L4-$K4)-IF($G4="",0,$G4))/60,2)) -> 8 | I4: 평일 | K4: =IF($E4="","",IF($E4<1,ROUND($E4*1440,0),INT($E4/100)*60+MOD($E4,100))) -> 540 | L4: =IF($F4="","",IF($F4<1,ROUND($F4*1440,0),INT($F4/100)*60+MOD($F4,100))) -> 1080
A5: 46266 | B5: E003 | C5: =IF($B5="","",IFERROR(INDEX(직원목록!$B$3:$B$302,MATCH($B5,직원목록!$A$3:$A$302,0)),"미등록사번")) -> 박직원 | D5: =IF($B5="","",IFERROR(INDEX(직원목록!$C$3:$C$302,MATCH($B5,직원목록!$A$3:$A$302,0)),"")) -> 관리팀 | E5: 850 | F5: 1830 | G5: 60 | H5: =IF(OR($K5="",$L5=""),"",ROUND(MAX(0,($L5-$K5)-IF($G5="",0,$G5))/60,2)) -> 8.67 | I5: 평일 | K5: =IF($E5="","",IF($E5<1,ROUND($E5*1440,0),INT($E5/100)*60+MOD($E5,100))) -> 530 | L5: =IF($F5="","",IF($F5<1,ROUND($F5*1440,0),INT($F5/100)*60+MOD($F5,100))) -> 1110
A6: 46267 | B6: E001 | C6: =IF($B6="","",IFERROR(INDEX(직원목록!$B$3:$B$302,MATCH($B6,직원목록!$A$3:$A$302,0)),"미등록사번")) -> 김직원 | D6: =IF($B6="","",IFERROR(INDEX(직원목록!$C$3:$C$302,MATCH($B6,직원목록!$A$3:$A$302,0)),"")) -> 생산1팀 | E6: 900 | F6: 1930 | G6: 60 | H6: =IF(OR($K6="",$L6=""),"",ROUND(MAX(0,($L6-$K6)-IF($G6="",0,$G6))/60,2)) -> 9.5 | I6: 평일 | K6: =IF($E6="","",IF($E6<1,ROUND($E6*1440,0),INT($E6/100)*60+MOD($E6,100))) -> 540 | L6: =IF($F6="","",IF($F6<1,ROUND($F6*1440,0),INT($F6/100)*60+MOD($F6,100))) -> 1170
A7: 46267 | B7: E002 | C7: =IF($B7="","",IFERROR(INDEX(직원목록!$B$3:$B$302,MATCH($B7,직원목록!$A$3:$A$302,0)),"미등록사번")) -> 이직원 | D7: =IF($B7="","",IFERROR(INDEX(직원목록!$C$3:$C$302,MATCH($B7,직원목록!$A$3:$A$302,0)),"")) -> 생산1팀 | E7: 900 | F7: 1800 | G7: 60 | H7: =IF(OR($K7="",$L7=""),"",ROUND(MAX(0,($L7-$K7)-IF($G7="",0,$G7))/60,2)) -> 8 | I7: 평일 | K7: =IF($E7="","",IF($E7<1,ROUND($E7*1440,0),INT($E7/100)*60+MOD($E7,100))) -> 540 | L7: =IF($F7="","",IF($F7<1,ROUND($F7*1440,0),INT($F7/100)*60+MOD($F7,100))) -> 1080
A8: 46267 | B8: E003 | C8: =IF($B8="","",IFERROR(INDEX(직원목록!$B$3:$B$302,MATCH($B8,직원목록!$A$3:$A$302,0)),"미등록사번")) -> 박직원 | D8: =IF($B8="","",IFERROR(INDEX(직원목록!$C$3:$C$302,MATCH($B8,직원목록!$A$3:$A$302,0)),"")) -> 관리팀 | E8: 900 | F8: 1800 | G8: 60 | H8: =IF(OR($K8="",$L8=""),"",ROUND(MAX(0,($L8-$K8)-IF($G8="",0,$G8))/60,2)) -> 8 | I8: 평일 | K8: =IF($E8="","",IF($E8<1,ROUND($E8*1440,0),INT($E8/100)*60+MOD($E8,100))) -> 540 | L8: =IF($F8="","",IF($F8<1,ROUND($F8*1440,0),INT($F8/100)*60+MOD($F8,100))) -> 1080
A9: 46268 | B9: E001 | C9: =IF($B9="","",IFERROR(INDEX(직원목록!$B$3:$B$302,MATCH($B9,직원목록!$A$3:$A$302,0)),"미등록사번")) -> 김직원 | D9: =IF($B9="","",IFERROR(INDEX(직원목록!$C$3:$C$302,MATCH($B9,직원목록!$A$3:$A$302,0)),"")) -> 생산1팀 | E9: 900 | F9: 2030 | G9: 60 | H9: =IF(OR($K9="",$L9=""),"",ROUND(MAX(0,($L9-$K9)-IF($G9="",0,$G9))/60,2)) -> 10.5 | I9: 평일 | K9: =IF($E9="","",IF($E9<1,ROUND($E9*1440,0),INT($E9/100)*60+MOD($E9,100))) -> 540 | L9: =IF($F9="","",IF($F9<1,ROUND($F9*1440,0),INT($F9/100)*60+MOD($F9,100))) -> 1230
A10: 46268 | B10: E002 | C10: =IF($B10="","",IFERROR(INDEX(직원목록!$B$3:$B$302,MATCH($B10,직원목록!$A$3:$A$302,0)),"미등록사번")) -> 이직원 | D10: =IF($B10="","",IFERROR(INDEX(직원목록!$C$3:$C$302,MATCH($B10,직원목록!$A$3:$A$302,0)),"")) -> 생산1팀 | H10: =IF(OR($K10="",$L10=""),"",ROUND(MAX(0,($L10-$K10)-IF($G10="",0,$G10))/60,2)) | I10: 연차 | K10: =IF($E10="","",IF($E10<1,ROUND($E10*1440,0),INT($E10/100)*60+MOD($E10,100))) | L10: =IF($F10="","",IF($F10<1,ROUND($F10*1440,0),INT($F10/100)*60+MOD($F10,100)))
A11: 46269 | B11: E001 | C11: =IF($B11="","",IFERROR(INDEX(직원목록!$B$3:$B$302,MATCH($B11,직원목록!$A$3:$A$302,0)),"미등록사번")) -> 김직원 | D11: =IF($B11="","",IFERROR(INDEX(직원목록!$C$3:$C$302,MATCH($B11,직원목록!$A$3:$A$302,0)),"")) -> 생산1팀 | E11: 900 | F11: 1800 | G11: 60 | H11: =IF(OR($K11="",$L11=""),"",ROUND(MAX(0,($L11-$K11)-IF($G11="",0,$G11))/60,2)) -> 8 | I11: 평일 | K11: =IF($E11="","",IF($E11<1,ROUND($E11*1440,0),INT($E11/100)*60+MOD($E11,100))) -> 540 | L11: =IF($F11="","",IF($F11<1,ROUND($F11*1440,0),INT($F11/100)*60+MOD($F11,100))) -> 1080
A12: 46272 | B12: E001 | C12: =IF($B12="","",IFERROR(INDEX(직원목록!$B$3:$B$302,MATCH($B12,직원목록!$A$3:$A$302,0)),"미등록사번")) -> 김직원 | D12: =IF($B12="","",IFERROR(INDEX(직원목록!$C$3:$C$302,MATCH($B12,직원목록!$A$3:$A$302,0)),"")) -> 생산1팀 | E12: 900 | F12: 1800 | G12: 60 | H12: =IF(OR($K12="",$L12=""),"",ROUND(MAX(0,($L12-$K12)-IF($G12="",0,$G12))/60,2)) -> 8 | I12: 평일 | K12: =IF($E12="","",IF($E12<1,ROUND($E12*1440,0),INT($E12/100)*60+MOD($E12,100))) -> 540 | L12: =IF($F12="","",IF($F12<1,ROUND($F12*1440,0),INT($F12/100)*60+MOD($F12,100))) -> 1080
A13: 46273 | B13: E001 | C13: =IF($B13="","",IFERROR(INDEX(직원목록!$B$3:$B$302,MATCH($B13,직원목록!$A$3:$A$302,0)),"미등록사번")) -> 김직원 | D13: =IF($B13="","",IFERROR(INDEX(직원목록!$C$3:$C$302,MATCH($B13,직원목록!$A$3:$A$302,0)),"")) -> 생산1팀 | E13: 900 | F13: 1900 | G13: 60 | H13: =IF(OR($K13="",$L13=""),"",ROUND(MAX(0,($L13-$K13)-IF($G13="",0,$G13))/60,2)) -> 9 | I13: 평일 | K13: =IF($E13="","",IF($E13<1,ROUND($E13*1440,0),INT($E13/100)*60+MOD($E13,100))) -> 540 | L13: =IF($F13="","",IF($F13<1,ROUND($F13*1440,0),INT($F13/100)*60+MOD($F13,100))) -> 1140
A14: 46274 | B14: E001 | C14: =IF($B14="","",IFERROR(INDEX(직원목록!$B$3:$B$302,MATCH($B14,직원목록!$A$3:$A$302,0)),"미등록사번")) -> 김직원 | D14: =IF($B14="","",IFERROR(INDEX(직원목록!$C$3:$C$302,MATCH($B14,직원목록!$A$3:$A$302,0)),"")) -> 생산1팀 | E14: 900 | F14: 1800 | G14: 60 | H14: =IF(OR($K14="",$L14=""),"",ROUND(MAX(0,($L14-$K14)-IF($G14="",0,$G14))/60,2)) -> 8 | I14: 평일 | K14: =IF($E14="","",IF($E14<1,ROUND($E14*1440,0),INT($E14/100)*60+MOD($E14,100))) -> 540 | L14: =IF($F14="","",IF($F14<1,ROUND($F14*1440,0),INT($F14/100)*60+MOD($F14,100))) -> 1080
A15: 46275 | B15: E001 | C15: =IF($B15="","",IFERROR(INDEX(직원목록!$B$3:$B$302,MATCH($B15,직원목록!$A$3:$A$302,0)),"미등록사번")) -> 김직원 | D15: =IF($B15="","",IFERROR(INDEX(직원목록!$C$3:$C$302,MATCH($B15,직원목록!$A$3:$A$302,0)),"")) -> 생산1팀 | E15: 900 | F15: 1800 | G15: 60 | H15: =IF(OR($K15="",$L15=""),"",ROUND(MAX(0,($L15-$K15)-IF($G15="",0,$G15))/60,2)) -> 8 | I15: 평일 | K15: =IF($E15="","",IF($E15<1,ROUND($E15*1440,0),INT($E15/100)*60+MOD($E15,100))) -> 540 | L15: =IF($F15="","",IF($F15<1,ROUND($F15*1440,0),INT($F15/100)*60+MOD($F15,100))) -> 1080
A16: 46276 | B16: E001 | C16: =IF($B16="","",IFERROR(INDEX(직원목록!$B$3:$B$302,MATCH($B16,직원목록!$A$3:$A$302,0)),"미등록사번")) -> 김직원 | D16: =IF($B16="","",IFERROR(INDEX(직원목록!$C$3:$C$302,MATCH($B16,직원목록!$A$3:$A$302,0)),"")) -> 생산1팀 | E16: 900 | F16: 1730 | G16: 60 | H16: =IF(OR($K16="",$L16=""),"",ROUND(MAX(0,($L16-$K16)-IF($G16="",0,$G16))/60,2)) -> 7.5 | I16: 평일 | K16: =IF($E16="","",IF($E16<1,ROUND($E16*1440,0),INT($E16/100)*60+MOD($E16,100))) -> 540 | L16: =IF($F16="","",IF($F16<1,ROUND($F16*1440,0),INT($F16/100)*60+MOD($F16,100))) -> 1050
A17: 46277 | B17: E002 | C17: =IF($B17="","",IFERROR(INDEX(직원목록!$B$3:$B$302,MATCH($B17,직원목록!$A$3:$A$302,0)),"미등록사번")) -> 이직원 | D17: =IF($B17="","",IFERROR(INDEX(직원목록!$C$3:$C$302,MATCH($B17,직원목록!$A$3:$A$302,0)),"")) -> 생산1팀 | E17: 900 | F17: 1500 | G17: 0 | H17: =IF(OR($K17="",$L17=""),"",ROUND(MAX(0,($L17-$K17)-IF($G17="",0,$G17))/60,2)) -> 6 | I17: 휴일 | K17: =IF($E17="","",IF($E17<1,ROUND($E17*1440,0),INT($E17/100)*60+MOD($E17,100))) -> 540 | L17: =IF($F17="","",IF($F17<1,ROUND($F17*1440,0),INT($F17/100)*60+MOD($F17,100))) -> 900
C18: =IF($B18="","",IFERROR(INDEX(직원목록!$B$3:$B$302,MATCH($B18,직원목록!$A$3:$A$302,0)),"미등록사번")) | D18: =IF($B18="","",IFERROR(INDEX(직원목록!$C$3:$C$302,MATCH($B18,직원목록!$A$3:$A$302,0)),"")) | H18: =IF(OR($K18="",$L18=""),"",ROUND(MAX(0,($L18-$K18)-IF($G18="",0,$G18))/60,2)) | K18: =IF($E18="","",IF($E18<1,ROUND($E18*1440,0),INT($E18/100)*60+MOD($E18,100))) | L18: =IF($F18="","",IF($F18<1,ROUND($F18*1440,0),INT($F18/100)*60+MOD($F18,100)))
C19: =IF($B19="","",IFERROR(INDEX(직원목록!$B$3:$B$302,MATCH($B19,직원목록!$A$3:$A$302,0)),"미등록사번")) | D19: =IF($B19="","",IFERROR(INDEX(직원목록!$C$3:$C$302,MATCH($B19,직원목록!$A$3:$A$302,0)),"")) | H19: =IF(OR($K19="",$L19=""),"",ROUND(MAX(0,($L19-$K19)-IF($G19="",0,$G19))/60,2)) | K19: =IF($E19="","",IF($E19<1,ROUND($E19*1440,0),INT($E19/100)*60+MOD($E19,100))) | L19: =IF($F19="","",IF($F19<1,ROUND($F19*1440,0),INT($F19/100)*60+MOD($F19,100)))
C20: =IF($B20="","",IFERROR(INDEX(직원목록!$B$3:$B$302,MATCH($B20,직원목록!$A$3:$A$302,0)),"미등록사번")) | D20: =IF($B20="","",IFERROR(INDEX(직원목록!$C$3:$C$302,MATCH($B20,직원목록!$A$3:$A$302,0)),"")) | H20: =IF(OR($K20="",$L20=""),"",ROUND(MAX(0,($L20-$K20)-IF($G20="",0,$G20))/60,2)) | K20: =IF($E20="","",IF($E20<1,ROUND($E20*1440,0),INT($E20/100)*60+MOD($E20,100))) | L20: =IF($F20="","",IF($F20<1,ROUND($F20*1440,0),INT($F20/100)*60+MOD($F20,100)))
C21: =IF($B21="","",IFERROR(INDEX(직원목록!$B$3:$B$302,MATCH($B21,직원목록!$A$3:$A$302,0)),"미등록사번")) | D21: =IF($B21="","",IFERROR(INDEX(직원목록!$C$3:$C$302,MATCH($B21,직원목록!$A$3:$A$302,0)),"")) | H21: =IF(OR($K21="",$L21=""),"",ROUND(MAX(0,($L21-$K21)-IF($G21="",0,$G21))/60,2)) | K21: =IF($E21="","",IF($E21<1,ROUND($E21*1440,0),INT($E21/100)*60+MOD($E21,100))) | L21: =IF($F21="","",IF($F21<1,ROUND($F21*1440,0),INT($F21/100)*60+MOD($F21,100)))
C22: =IF($B22="","",IFERROR(INDEX(직원목록!$B$3:$B$302,MATCH($B22,직원목록!$A$3:$A$302,0)),"미등록사번")) | D22: =IF($B22="","",IFERROR(INDEX(직원목록!$C$3:$C$302,MATCH($B22,직원목록!$A$3:$A$302,0)),"")) | H22: =IF(OR($K22="",$L22=""),"",ROUND(MAX(0,($L22-$K22)-IF($G22="",0,$G22))/60,2)) | K22: =IF($E22="","",IF($E22<1,ROUND($E22*1440,0),INT($E22/100)*60+MOD($E22,100))) | L22: =IF($F22="","",IF($F22<1,ROUND($F22*1440,0),INT($F22/100)*60+MOD($F22,100)))
C23: =IF($B23="","",IFERROR(INDEX(직원목록!$B$3:$B$302,MATCH($B23,직원목록!$A$3:$A$302,0)),"미등록사번")) | D23: =IF($B23="","",IFERROR(INDEX(직원목록!$C$3:$C$302,MATCH($B23,직원목록!$A$3:$A$302,0)),"")) | H23: =IF(OR($K23="",$L23=""),"",ROUND(MAX(0,($L23-$K23)-IF($G23="",0,$G23))/60,2)) | K23: =IF($E23="","",IF($E23<1,ROUND($E23*1440,0),INT($E23/100)*60+MOD($E23,100))) | L23: =IF($F23="","",IF($F23<1,ROUND($F23*1440,0),INT($F23/100)*60+MOD($F23,100)))
C24: =IF($B24="","",IFERROR(INDEX(직원목록!$B$3:$B$302,MATCH($B24,직원목록!$A$3:$A$302,0)),"미등록사번")) | D24: =IF($B24="","",IFERROR(INDEX(직원목록!$C$3:$C$302,MATCH($B24,직원목록!$A$3:$A$302,0)),"")) | H24: =IF(OR($K24="",$L24=""),"",ROUND(MAX(0,($L24-$K24)-IF($G24="",0,$G24))/60,2)) | K24: =IF($E24="","",IF($E24<1,ROUND($E24*1440,0),INT($E24/100)*60+MOD($E24,100))) | L24: =IF($F24="","",IF($F24<1,ROUND($F24*1440,0),INT($F24/100)*60+MOD($F24,100)))
C25: =IF($B25="","",IFERROR(INDEX(직원목록!$B$3:$B$302,MATCH($B25,직원목록!$A$3:$A$302,0)),"미등록사번")) | D25: =IF($B25="","",IFERROR(INDEX(직원목록!$C$3:$C$302,MATCH($B25,직원목록!$A$3:$A$302,0)),"")) | H25: =IF(OR($K25="",$L25=""),"",ROUND(MAX(0,($L25-$K25)-IF($G25="",0,$G25))/60,2)) | K25: =IF($E25="","",IF($E25<1,ROUND($E25*1440,0),INT($E25/100)*60+MOD($E25,100))) | L25: =IF($F25="","",IF($F25<1,ROUND($F25*1440,0),INT($F25/100)*60+MOD($F25,100)))
C26: =IF($B26="","",IFERROR(INDEX(직원목록!$B$3:$B$302,MATCH($B26,직원목록!$A$3:$A$302,0)),"미등록사번")) | D26: =IF($B26="","",IFERROR(INDEX(직원목록!$C$3:$C$302,MATCH($B26,직원목록!$A$3:$A$302,0)),"")) | H26: =IF(OR($K26="",$L26=""),"",ROUND(MAX(0,($L26-$K26)-IF($G26="",0,$G26))/60,2)) | K26: =IF($E26="","",IF($E26<1,ROUND($E26*1440,0),INT($E26/100)*60+MOD($E26,100))) | L26: =IF($F26="","",IF($F26<1,ROUND($F26*1440,0),INT($F26/100)*60+MOD($F26,100)))
C27: =IF($B27="","",IFERROR(INDEX(직원목록!$B$3:$B$302,MATCH($B27,직원목록!$A$3:$A$302,0)),"미등록사번")) | D27: =IF($B27="","",IFERROR(INDEX(직원목록!$C$3:$C$302,MATCH($B27,직원목록!$A$3:$A$302,0)),"")) | H27: =IF(OR($K27="",$L27=""),"",ROUND(MAX(0,($L27-$K27)-IF($G27="",0,$G27))/60,2)) | K27: =IF($E27="","",IF($E27<1,ROUND($E27*1440,0),INT($E27/100)*60+MOD($E27,100))) | L27: =IF($F27="","",IF($F27<1,ROUND($F27*1440,0),INT($F27/100)*60+MOD($F27,100)))
C28: =IF($B28="","",IFERROR(INDEX(직원목록!$B$3:$B$302,MATCH($B28,직원목록!$A$3:$A$302,0)),"미등록사번")) | D28: =IF($B28="","",IFERROR(INDEX(직원목록!$C$3:$C$302,MATCH($B28,직원목록!$A$3:$A$302,0)),"")) | H28: =IF(OR($K28="",$L28=""),"",ROUND(MAX(0,($L28-$K28)-IF($G28="",0,$G28))/60,2)) | K28: =IF($E28="","",IF($E28<1,ROUND($E28*1440,0),INT($E28/100)*60+MOD($E28,100))) | L28: =IF($F28="","",IF($F28<1,ROUND($F28*1440,0),INT($F28/100)*60+MOD($F28,100)))
C29: =IF($B29="","",IFERROR(INDEX(직원목록!$B$3:$B$302,MATCH($B29,직원목록!$A$3:$A$302,0)),"미등록사번")) | D29: =IF($B29="","",IFERROR(INDEX(직원목록!$C$3:$C$302,MATCH($B29,직원목록!$A$3:$A$302,0)),"")) | H29: =IF(OR($K29="",$L29=""),"",ROUND(MAX(0,($L29-$K29)-IF($G29="",0,$G29))/60,2)) | K29: =IF($E29="","",IF($E29<1,ROUND($E29*1440,0),INT($E29/100)*60+MOD($E29,100))) | L29: =IF($F29="","",IF($F29<1,ROUND($F29*1440,0),INT($F29/100)*60+MOD($F29,100)))
... C3002: =IF($B3002="","",IFERROR(INDEX(직원목록!$B$3:$B$302,MATCH($B3002,직원목록!$A$3:$A$302,0)),"미등록사번")) | D3002: =IF($B3002="","",IFERROR(INDEX(직원목록!$C$3:$C$302,MATCH($B3002,직원목록!$A$3:$A$302,0)),"")) | H3002: =IF(OR($K3002="",$L3002=""),"",ROUND(MAX(0,($L3002-$K3002)-IF($G3002="",0,$G3002))/60,2)) | K3002: =IF($E3002="","",IF($E3002<1,ROUND($E3002*1440,0),INT($E3002/100)*60+MOD($E3002,100))) | L3002: =IF($F3002="","",IF($F3002<1,ROUND($F3002*1440,0),INT($F3002/100)*60+MOD($F3002,100)))
A3004: ※ 휴게시간은 분 단위로 넣으세요. 점심 1시간이면 60입니다.

Sheet 월별집계
A1: 월별집계 (근무시간만 · 금액 계산 없음)
A3: 대상 연도 | B3: 2026 | C3: 대상 월 | D3: 9 | E3: ← 두 칸만 바꾸세요
A5: 사번 | B5: 이름 | C5: 부서 | D5: 근무일수 | E5: 평일시간 | F5: 휴일시간 | G5: 총 근무시간 | H5: 소정시간 | I5: 초과시간 | J5: 연차 | K5: 결근
A6: =IF(직원목록!$A3="","",직원목록!$A3) -> E001 | B6: =IF($A6="","",직원목록!$B3) -> 김직원 | C6: =IF($A6="","",직원목록!$C3) -> 생산1팀 | D6: =IF($A6="","",COUNTIFS(출퇴근기록!$B$3:$B$3002,$A6,출퇴근기록!$H$3:$H$3002,">0",출퇴근기록!$A$3:$A$3002,">="&DATE($B$3,$D$3,1),출퇴근기록!$A$3:$A$3002,"<="&EOMONTH(DATE($B$3,$D$3,1),0))) -> 9 | E6: =IF($A6="","",ROUND(SUMIFS(출퇴근기록!$H$3:$H$3002,출퇴근기록!$B$3:$B$3002,$A6,출퇴근기록!$I$3:$I$3002,"평일",출퇴근기록!$A$3:$A$3002,">="&DATE($B$3,$D$3,1),출퇴근기록!$A$3:$A$3002,"<="&EOMONTH(DATE($B$3,$D$3,1),0)),2)) -> 76.5 | F6: =IF($A6="","",ROUND(SUMIFS(출퇴근기록!$H$3:$H$3002,출퇴근기록!$B$3:$B$3002,$A6,출퇴근기록!$I$3:$I$3002,"휴일",출퇴근기록!$A$3:$A$3002,">="&DATE($B$3,$D$3,1),출퇴근기록!$A$3:$A$3002,"<="&EOMONTH(DATE($B$3,$D$3,1),0)),2)) -> 0 | G6: =IF($A6="","",ROUND(SUMIFS(출퇴근기록!$H$3:$H$3002,출퇴근기록!$B$3:$B$3002,$A6,출퇴근기록!$A$3:$A$3002,">="&DATE($B$3,$D$3,1),출퇴근기록!$A$3:$A$3002,"<="&EOMONTH(DATE($B$3,$D$3,1),0)),2)) -> 76.5 | H6: =IF($A6="","",ROUND($D6*IF(직원목록!$F3="",8,직원목록!$F3),2)) -> 72 | I6: =IF($A6="","",ROUND($G6-$H6,2)) -> 4.5 | J6: =IF($A6="","",COUNTIFS(출퇴근기록!$B$3:$B$3002,$A6,출퇴근기록!$I$3:$I$3002,"연차",출퇴근기록!$A$3:$A$3002,">="&DATE($B$3,$D$3,1),출퇴근기록!$A$3:$A$3002,"<="&EOMONTH(DATE($B$3,$D$3,1),0))) -> 0 | K6: =IF($A6="","",COUNTIFS(출퇴근기록!$B$3:$B$3002,$A6,출퇴근기록!$I$3:$I$3002,"결근",출퇴근기록!$A$3:$A$3002,">="&DATE($B$3,$D$3,1),출퇴근기록!$A$3:$A$3002,"<="&EOMONTH(DATE($B$3,$D$3,1),0))) -> 0
A7: =IF(직원목록!$A4="","",직원목록!$A4) -> E002 | B7: =IF($A7="","",직원목록!$B4) -> 이직원 | C7: =IF($A7="","",직원목록!$C4) -> 생산1팀 | D7: =IF($A7="","",COUNTIFS(출퇴근기록!$B$3:$B$3002,$A7,출퇴근기록!$H$3:$H$3002,">0",출퇴근기록!$A$3:$A$3002,">="&DATE($B$3,$D$3,1),출퇴근기록!$A$3:$A$3002,"<="&EOMONTH(DATE($B$3,$D$3,1),0))) -> 3 | E7: =IF($A7="","",ROUND(SUMIFS(출퇴근기록!$H$3:$H$3002,출퇴근기록!$B$3:$B$3002,$A7,출퇴근기록!$I$3:$I$3002,"평일",출퇴근기록!$A$3:$A$3002,">="&DATE($B$3,$D$3,1),출퇴근기록!$A$3:$A$3002,"<="&EOMONTH(DATE($B$3,$D$3,1),0)),2)) -> 16 | F7: =IF($A7="","",ROUND(SUMIFS(출퇴근기록!$H$3:$H$3002,출퇴근기록!$B$3:$B$3002,$A7,출퇴근기록!$I$3:$I$3002,"휴일",출퇴근기록!$A$3:$A$3002,">="&DATE($B$3,$D$3,1),출퇴근기록!$A$3:$A$3002,"<="&EOMONTH(DATE($B$3,$D$3,1),0)),2)) -> 6 | G7: =IF($A7="","",ROUND(SUMIFS(출퇴근기록!$H$3:$H$3002,출퇴근기록!$B$3:$B$3002,$A7,출퇴근기록!$A$3:$A$3002,">="&DATE($B$3,$D$3,1),출퇴근기록!$A$3:$A$3002,"<="&EOMONTH(DATE($B$3,$D$3,1),0)),2)) -> 22 | H7: =IF($A7="","",ROUND($D7*IF(직원목록!$F4="",8,직원목록!$F4),2)) -> 24 | I7: =IF($A7="","",ROUND($G7-$H7,2)) -> -2 | J7: =IF($A7="","",COUNTIFS(출퇴근기록!$B$3:$B$3002,$A7,출퇴근기록!$I$3:$I$3002,"연차",출퇴근기록!$A$3:$A$3002,">="&DATE($B$3,$D$3,1),출퇴근기록!$A$3:$A$3002,"<="&EOMONTH(DATE($B$3,$D$3,1),0))) -> 1 | K7: =IF($A7="","",COUNTIFS(출퇴근기록!$B$3:$B$3002,$A7,출퇴근기록!$I$3:$I$3002,"결근",출퇴근기록!$A$3:$A$3002,">="&DATE($B$3,$D$3,1),출퇴근기록!$A$3:$A$3002,"<="&EOMONTH(DATE($B$3,$D$3,1),0))) -> 0
A8: =IF(직원목록!$A5="","",직원목록!$A5) -> E003 | B8: =IF($A8="","",직원목록!$B5) -> 박직원 | C8: =IF($A8="","",직원목록!$C5) -> 관리팀 | D8: =IF($A8="","",COUNTIFS(출퇴근기록!$B$3:$B$3002,$A8,출퇴근기록!$H$3:$H$3002,">0",출퇴근기록!$A$3:$A$3002,">="&DATE($B$3,$D$3,1),출퇴근기록!$A$3:$A$3002,"<="&EOMONTH(DATE($B$3,$D$3,1),0))) -> 2 | E8: =IF($A8="","",ROUND(SUMIFS(출퇴근기록!$H$3:$H$3002,출퇴근기록!$B$3:$B$3002,$A8,출퇴근기록!$I$3:$I$3002,"평일",출퇴근기록!$A$3:$A$3002,">="&DATE($B$3,$D$3,1),출퇴근기록!$A$3:$A$3002,"<="&EOMONTH(DATE($B$3,$D$3,1),0)),2)) -> 16.67 | F8: =IF($A8="","",ROUND(SUMIFS(출퇴근기록!$H$3:$H$3002,출퇴근기록!$B$3:$B$3002,$A8,출퇴근기록!$I$3:$I$3002,"휴일",출퇴근기록!$A$3:$A$3002,">="&DATE($B$3,$D$3,1),출퇴근기록!$A$3:$A$3002,"<="&EOMONTH(DATE($B$3,$D$3,1),0)),2)) -> 0 | G8: =IF($A8="","",ROUND(SUMIFS(출퇴근기록!$H$3:$H$3002,출퇴근기록!$B$3:$B$3002,$A8,출퇴근기록!$A$3:$A$3002,">="&DATE($B$3,$D$3,1),출퇴근기록!$A$3:$A$3002,"<="&EOMONTH(DATE($B$3,$D$3,1),0)),2)) -> 16.67 | H8: =IF($A8="","",ROUND($D8*IF(직원목록!$F5="",8,직원목록!$F5),2)) -> 16 | I8: =IF($A8="","",ROUND($G8-$H8,2)) -> 0.67 | J8: =IF($A8="","",COUNTIFS(출퇴근기록!$B$3:$B$3002,$A8,출퇴근기록!$I$3:$I$3002,"연차",출퇴근기록!$A$3:$A$3002,">="&DATE($B$3,$D$3,1),출퇴근기록!$A$3:$A$3002,"<="&EOMONTH(DATE($B$3,$D$3,1),0))) -> 0 | K8: =IF($A8="","",COUNTIFS(출퇴근기록!$B$3:$B$3002,$A8,출퇴근기록!$I$3:$I$3002,"결근",출퇴근기록!$A$3:$A$3002,">="&DATE($B$3,$D$3,1),출퇴근기록!$A$3:$A$3002,"<="&EOMONTH(DATE($B$3,$D$3,1),0))) -> 0
A9: =IF(직원목록!$A6="","",직원목록!$A6) | B9: =IF($A9="","",직원목록!$B6) | C9: =IF($A9="","",직원목록!$C6) | D9: =IF($A9="","",COUNTIFS(출퇴근기록!$B$3:$B$3002,$A9,출퇴근기록!$H$3:$H$3002,">0",출퇴근기록!$A$3:$A$3002,">="&DATE($B$3,$D$3,1),출퇴근기록!$A$3:$A$3002,"<="&EOMONTH(DATE($B$3,$D$3,1),0))) | E9: =IF($A9="","",ROUND(SUMIFS(출퇴근기록!$H$3:$H$3002,출퇴근기록!$B$3:$B$3002,$A9,출퇴근기록!$I$3:$I$3002,"평일",출퇴근기록!$A$3:$A$3002,">="&DATE($B$3,$D$3,1),출퇴근기록!$A$3:$A$3002,"<="&EOMONTH(DATE($B$3,$D$3,1),0)),2)) | F9: =IF($A9="","",ROUND(SUMIFS(출퇴근기록!$H$3:$H$3002,출퇴근기록!$B$3:$B$3002,$A9,출퇴근기록!$I$3:$I$3002,"휴일",출퇴근기록!$A$3:$A$3002,">="&DATE($B$3,$D$3,1),출퇴근기록!$A$3:$A$3002,"<="&EOMONTH(DATE($B$3,$D$3,1),0)),2)) | G9: =IF($A9="","",ROUND(SUMIFS(출퇴근기록!$H$3:$H$3002,출퇴근기록!$B$3:$B$3002,$A9,출퇴근기록!$A$3:$A$3002,">="&DATE($B$3,$D$3,1),출퇴근기록!$A$3:$A$3002,"<="&EOMONTH(DATE($B$3,$D$3,1),0)),2)) | H9: =IF($A9="","",ROUND($D9*IF(직원목록!$F6="",8,직원목록!$F6),2)) | I9: =IF($A9="","",ROUND($G9-$H9,2)) | J9: =IF($A9="","",COUNTIFS(출퇴근기록!$B$3:$B$3002,$A9,출퇴근기록!$I$3:$I$3002,"연차",출퇴근기록!$A$3:$A$3002,">="&DATE($B$3,$D$3,1),출퇴근기록!$A$3:$A$3002,"<="&EOMONTH(DATE($B$3,$D$3,1),0))) | K9: =IF($A9="","",COUNTIFS(출퇴근기록!$B$3:$B$3002,$A9,출퇴근기록!$I$3:$I$3002,"결근",출퇴근기록!$A$3:$A$3002,">="&DATE($B$3,$D$3,1),출퇴근기록!$A$3:$A$3002,"<="&EOMONTH(DATE($B$3,$D$3,1),0)))
A10: =IF(직원목록!$A7="","",직원목록!$A7) | B10: =IF($A10="","",직원목록!$B7) | C10: =IF($A10="","",직원목록!$C7) | D10: =IF($A10="","",COUNTIFS(출퇴근기록!$B$3:$B$3002,$A10,출퇴근기록!$H$3:$H$3002,">0",출퇴근기록!$A$3:$A$3002,">="&DATE($B$3,$D$3,1),출퇴근기록!$A$3:$A$3002,"<="&EOMONTH(DATE($B$3,$D$3,1),0))) | E10: =IF($A10="","",ROUND(SUMIFS(출퇴근기록!$H$3:$H$3002,출퇴근기록!$B$3:$B$3002,$A10,출퇴근기록!$I$3:$I$3002,"평일",출퇴근기록!$A$3:$A$3002,">="&DATE($B$3,$D$3,1),출퇴근기록!$A$3:$A$3002,"<="&EOMONTH(DATE($B$3,$D$3,1),0)),2)) | F10: =IF($A10="","",ROUND(SUMIFS(출퇴근기록!$H$3:$H$3002,출퇴근기록!$B$3:$B$3002,$A10,출퇴근기록!$I$3:$I$3002,"휴일",출퇴근기록!$A$3:$A$3002,">="&DATE($B$3,$D$3,1),출퇴근기록!$A$3:$A$3002,"<="&EOMONTH(DATE($B$3,$D$3,1),0)),2)) | G10: =IF($A10="","",ROUND(SUMIFS(출퇴근기록!$H$3:$H$3002,출퇴근기록!$B$3:$B$3002,$A10,출퇴근기록!$A$3:$A$3002,">="&DATE($B$3,$D$3,1),출퇴근기록!$A$3:$A$3002,"<="&EOMONTH(DATE($B$3,$D$3,1),0)),2)) | H10: =IF($A10="","",ROUND($D10*IF(직원목록!$F7="",8,직원목록!$F7),2)) | I10: =IF($A10="","",ROUND($G10-$H10,2)) | J10: =IF($A10="","",COUNTIFS(출퇴근기록!$B$3:$B$3002,$A10,출퇴근기록!$I$3:$I$3002,"연차",출퇴근기록!$A$3:$A$3002,">="&DATE($B$3,$D$3,1),출퇴근기록!$A$3:$A$3002,"<="&EOMONTH(DATE($B$3,$D$3,1),0))) | K10: =IF($A10="","",COUNTIFS(출퇴근기록!$B$3:$B$3002,$A10,출퇴근기록!$I$3:$I$3002,"결근",출퇴근기록!$A$3:$A$3002,">="&DATE($B$3,$D$3,1),출퇴근기록!$A$3:$A$3002,"<="&EOMONTH(DATE($B$3,$D$3,1),0)))
A11: =IF(직원목록!$A8="","",직원목록!$A8) | B11: =IF($A11="","",직원목록!$B8) | C11: =IF($A11="","",직원목록!$C8) | D11: =IF($A11="","",COUNTIFS(출퇴근기록!$B$3:$B$3002,$A11,출퇴근기록!$H$3:$H$3002,">0",출퇴근기록!$A$3:$A$3002,">="&DATE($B$3,$D$3,1),출퇴근기록!$A$3:$A$3002,"<="&EOMONTH(DATE($B$3,$D$3,1),0))) | E11: =IF($A11="","",ROUND(SUMIFS(출퇴근기록!$H$3:$H$3002,출퇴근기록!$B$3:$B$3002,$A11,출퇴근기록!$I$3:$I$3002,"평일",출퇴근기록!$A$3:$A$3002,">="&DATE($B$3,$D$3,1),출퇴근기록!$A$3:$A$3002,"<="&EOMONTH(DATE($B$3,$D$3,1),0)),2)) | F11: =IF($A11="","",ROUND(SUMIFS(출퇴근기록!$H$3:$H$3002,출퇴근기록!$B$3:$B$3002,$A11,출퇴근기록!$I$3:$I$3002,"휴일",출퇴근기록!$A$3:$A$3002,">="&DATE($B$3,$D$3,1),출퇴근기록!$A$3:$A$3002,"<="&EOMONTH(DATE($B$3,$D$3,1),0)),2)) | G11: =IF($A11="","",ROUND(SUMIFS(출퇴근기록!$H$3:$H$3002,출퇴근기록!$B$3:$B$3002,$A11,출퇴근기록!$A$3:$A$3002,">="&DATE($B$3,$D$3,1),출퇴근기록!$A$3:$A$3002,"<="&EOMONTH(DATE($B$3,$D$3,1),0)),2)) | H11: =IF($A11="","",ROUND($D11*IF(직원목록!$F8="",8,직원목록!$F8),2)) | I11: =IF($A11="","",ROUND($G11-$H11,2)) | J11: =IF($A11="","",COUNTIFS(출퇴근기록!$B$3:$B$3002,$A11,출퇴근기록!$I$3:$I$3002,"연차",출퇴근기록!$A$3:$A$3002,">="&DATE($B$3,$D$3,1),출퇴근기록!$A$3:$A$3002,"<="&EOMONTH(DATE($B$3,$D$3,1),0))) | K11: =IF($A11="","",COUNTIFS(출퇴근기록!$B$3:$B$3002,$A11,출퇴근기록!$I$3:$I$3002,"결근",출퇴근기록!$A$3:$A$3002,">="&DATE($B$3,$D$3,1),출퇴근기록!$A$3:$A$3002,"<="&EOMONTH(DATE($B$3,$D$3,1),0)))
A12: =IF(직원목록!$A9="","",직원목록!$A9) | B12: =IF($A12="","",직원목록!$B9) | C12: =IF($A12="","",직원목록!$C9) | D12: =IF($A12="","",COUNTIFS(출퇴근기록!$B$3:$B$3002,$A12,출퇴근기록!$H$3:$H$3002,">0",출퇴근기록!$A$3:$A$3002,">="&DATE($B$3,$D$3,1),출퇴근기록!$A$3:$A$3002,"<="&EOMONTH(DATE($B$3,$D$3,1),0))) | E12: =IF($A12="","",ROUND(SUMIFS(출퇴근기록!$H$3:$H$3002,출퇴근기록!$B$3:$B$3002,$A12,출퇴근기록!$I$3:$I$3002,"평일",출퇴근기록!$A$3:$A$3002,">="&DATE($B$3,$D$3,1),출퇴근기록!$A$3:$A$3002,"<="&EOMONTH(DATE($B$3,$D$3,1),0)),2)) | F12: =IF($A12="","",ROUND(SUMIFS(출퇴근기록!$H$3:$H$3002,출퇴근기록!$B$3:$B$3002,$A12,출퇴근기록!$I$3:$I$3002,"휴일",출퇴근기록!$A$3:$A$3002,">="&DATE($B$3,$D$3,1),출퇴근기록!$A$3:$A$3002,"<="&EOMONTH(DATE($B$3,$D$3,1),0)),2)) | G12: =IF($A12="","",ROUND(SUMIFS(출퇴근기록!$H$3:$H$3002,출퇴근기록!$B$3:$B$3002,$A12,출퇴근기록!$A$3:$A$3002,">="&DATE($B$3,$D$3,1),출퇴근기록!$A$3:$A$3002,"<="&EOMONTH(DATE($B$3,$D$3,1),0)),2)) | H12: =IF($A12="","",ROUND($D12*IF(직원목록!$F9="",8,직원목록!$F9),2)) | I12: =IF($A12="","",ROUND($G12-$H12,2)) | J12: =IF($A12="","",COUNTIFS(출퇴근기록!$B$3:$B$3002,$A12,출퇴근기록!$I$3:$I$3002,"연차",출퇴근기록!$A$3:$A$3002,">="&DATE($B$3,$D$3,1),출퇴근기록!$A$3:$A$3002,"<="&EOMONTH(DATE($B$3,$D$3,1),0))) | K12: =IF($A12="","",COUNTIFS(출퇴근기록!$B$3:$B$3002,$A12,출퇴근기록!$I$3:$I$3002,"결근",출퇴근기록!$A$3:$A$3002,">="&DATE($B$3,$D$3,1),출퇴근기록!$A$3:$A$3002,"<="&EOMONTH(DATE($B$3,$D$3,1),0)))
A13: =IF(직원목록!$A10="","",직원목록!$A10) | B13: =IF($A13="","",직원목록!$B10) | C13: =IF($A13="","",직원목록!$C10) | D13: =IF($A13="","",COUNTIFS(출퇴근기록!$B$3:$B$3002,$A13,출퇴근기록!$H$3:$H$3002,">0",출퇴근기록!$A$3:$A$3002,">="&DATE($B$3,$D$3,1),출퇴근기록!$A$3:$A$3002,"<="&EOMONTH(DATE($B$3,$D$3,1),0))) | E13: =IF($A13="","",ROUND(SUMIFS(출퇴근기록!$H$3:$H$3002,출퇴근기록!$B$3:$B$3002,$A13,출퇴근기록!$I$3:$I$3002,"평일",출퇴근기록!$A$3:$A$3002,">="&DATE($B$3,$D$3,1),출퇴근기록!$A$3:$A$3002,"<="&EOMONTH(DATE($B$3,$D$3,1),0)),2)) | F13: =IF($A13="","",ROUND(SUMIFS(출퇴근기록!$H$3:$H$3002,출퇴근기록!$B$3:$B$3002,$A13,출퇴근기록!$I$3:$I$3002,"휴일",출퇴근기록!$A$3:$A$3002,">="&DATE($B$3,$D$3,1),출퇴근기록!$A$3:$A$3002,"<="&EOMONTH(DATE($B$3,$D$3,1),0)),2)) | G13: =IF($A13="","",ROUND(SUMIFS(출퇴근기록!$H$3:$H$3002,출퇴근기록!$B$3:$B$3002,$A13,출퇴근기록!$A$3:$A$3002,">="&DATE($B$3,$D$3,1),출퇴근기록!$A$3:$A$3002,"<="&EOMONTH(DATE($B$3,$D$3,1),0)),2)) | H13: =IF($A13="","",ROUND($D13*IF(직원목록!$F10="",8,직원목록!$F10),2)) | I13: =IF($A13="","",ROUND($G13-$H13,2)) | J13: =IF($A13="","",COUNTIFS(출퇴근기록!$B$3:$B$3002,$A13,출퇴근기록!$I$3:$I$3002,"연차",출퇴근기록!$A$3:$A$3002,">="&DATE($B$3,$D$3,1),출퇴근기록!$A$3:$A$3002,"<="&EOMONTH(DATE($B$3,$D$3,1),0))) | K13: =IF($A13="","",COUNTIFS(출퇴근기록!$B$3:$B$3002,$A13,출퇴근기록!$I$3:$I$3002,"결근",출퇴근기록!$A$3:$A$3002,">="&DATE($B$3,$D$3,1),출퇴근기록!$A$3:$A$3002,"<="&EOMONTH(DATE($B$3,$D$3,1),0)))
A14: =IF(직원목록!$A11="","",직원목록!$A11) | B14: =IF($A14="","",직원목록!$B11) | C14: =IF($A14="","",직원목록!$C11) | D14: =IF($A14="","",COUNTIFS(출퇴근기록!$B$3:$B$3002,$A14,출퇴근기록!$H$3:$H$3002,">0",출퇴근기록!$A$3:$A$3002,">="&DATE($B$3,$D$3,1),출퇴근기록!$A$3:$A$3002,"<="&EOMONTH(DATE($B$3,$D$3,1),0))) | E14: =IF($A14="","",ROUND(SUMIFS(출퇴근기록!$H$3:$H$3002,출퇴근기록!$B$3:$B$3002,$A14,출퇴근기록!$I$3:$I$3002,"평일",출퇴근기록!$A$3:$A$3002,">="&DATE($B$3,$D$3,1),출퇴근기록!$A$3:$A$3002,"<="&EOMONTH(DATE($B$3,$D$3,1),0)),2)) | F14: =IF($A14="","",ROUND(SUMIFS(출퇴근기록!$H$3:$H$3002,출퇴근기록!$B$3:$B$3002,$A14,출퇴근기록!$I$3:$I$3002,"휴일",출퇴근기록!$A$3:$A$3002,">="&DATE($B$3,$D$3,1),출퇴근기록!$A$3:$A$3002,"<="&EOMONTH(DATE($B$3,$D$3,1),0)),2)) | G14: =IF($A14="","",ROUND(SUMIFS(출퇴근기록!$H$3:$H$3002,출퇴근기록!$B$3:$B$3002,$A14,출퇴근기록!$A$3:$A$3002,">="&DATE($B$3,$D$3,1),출퇴근기록!$A$3:$A$3002,"<="&EOMONTH(DATE($B$3,$D$3,1),0)),2)) | H14: =IF($A14="","",ROUND($D14*IF(직원목록!$F11="",8,직원목록!$F11),2)) | I14: =IF($A14="","",ROUND($G14-$H14,2)) | J14: =IF($A14="","",COUNTIFS(출퇴근기록!$B$3:$B$3002,$A14,출퇴근기록!$I$3:$I$3002,"연차",출퇴근기록!$A$3:$A$3002,">="&DATE($B$3,$D$3,1),출퇴근기록!$A$3:$A$3002,"<="&EOMONTH(DATE($B$3,$D$3,1),0))) | K14: =IF($A14="","",COUNTIFS(출퇴근기록!$B$3:$B$3002,$A14,출퇴근기록!$I$3:$I$3002,"결근",출퇴근기록!$A$3:$A$3002,">="&DATE($B$3,$D$3,1),출퇴근기록!$A$3:$A$3002,"<="&EOMONTH(DATE($B$3,$D$3,1),0)))
A15: =IF(직원목록!$A12="","",직원목록!$A12) | B15: =IF($A15="","",직원목록!$B12) | C15: =IF($A15="","",직원목록!$C12) | D15: =IF($A15="","",COUNTIFS(출퇴근기록!$B$3:$B$3002,$A15,출퇴근기록!$H$3:$H$3002,">0",출퇴근기록!$A$3:$A$3002,">="&DATE($B$3,$D$3,1),출퇴근기록!$A$3:$A$3002,"<="&EOMONTH(DATE($B$3,$D$3,1),0))) | E15: =IF($A15="","",ROUND(SUMIFS(출퇴근기록!$H$3:$H$3002,출퇴근기록!$B$3:$B$3002,$A15,출퇴근기록!$I$3:$I$3002,"평일",출퇴근기록!$A$3:$A$3002,">="&DATE($B$3,$D$3,1),출퇴근기록!$A$3:$A$3002,"<="&EOMONTH(DATE($B$3,$D$3,1),0)),2)) | F15: =IF($A15="","",ROUND(SUMIFS(출퇴근기록!$H$3:$H$3002,출퇴근기록!$B$3:$B$3002,$A15,출퇴근기록!$I$3:$I$3002,"휴일",출퇴근기록!$A$3:$A$3002,">="&DATE($B$3,$D$3,1),출퇴근기록!$A$3:$A$3002,"<="&EOMONTH(DATE($B$3,$D$3,1),0)),2)) | G15: =IF($A15="","",ROUND(SUMIFS(출퇴근기록!$H$3:$H$3002,출퇴근기록!$B$3:$B$3002,$A15,출퇴근기록!$A$3:$A$3002,">="&DATE($B$3,$D$3,1),출퇴근기록!$A$3:$A$3002,"<="&EOMONTH(DATE($B$3,$D$3,1),0)),2)) | H15: =IF($A15="","",ROUND($D15*IF(직원목록!$F12="",8,직원목록!$F12),2)) | I15: =IF($A15="","",ROUND($G15-$H15,2)) | J15: =IF($A15="","",COUNTIFS(출퇴근기록!$B$3:$B$3002,$A15,출퇴근기록!$I$3:$I$3002,"연차",출퇴근기록!$A$3:$A$3002,">="&DATE($B$3,$D$3,1),출퇴근기록!$A$3:$A$3002,"<="&EOMONTH(DATE($B$3,$D$3,1),0))) | K15: =IF($A15="","",COUNTIFS(출퇴근기록!$B$3:$B$3002,$A15,출퇴근기록!$I$3:$I$3002,"결근",출퇴근기록!$A$3:$A$3002,">="&DATE($B$3,$D$3,1),출퇴근기록!$A$3:$A$3002,"<="&EOMONTH(DATE($B$3,$D$3,1),0)))
A16: =IF(직원목록!$A13="","",직원목록!$A13) | B16: =IF($A16="","",직원목록!$B13) | C16: =IF($A16="","",직원목록!$C13) | D16: =IF($A16="","",COUNTIFS(출퇴근기록!$B$3:$B$3002,$A16,출퇴근기록!$H$3:$H$3002,">0",출퇴근기록!$A$3:$A$3002,">="&DATE($B$3,$D$3,1),출퇴근기록!$A$3:$A$3002,"<="&EOMONTH(DATE($B$3,$D$3,1),0))) | E16: =IF($A16="","",ROUND(SUMIFS(출퇴근기록!$H$3:$H$3002,출퇴근기록!$B$3:$B$3002,$A16,출퇴근기록!$I$3:$I$3002,"평일",출퇴근기록!$A$3:$A$3002,">="&DATE($B$3,$D$3,1),출퇴근기록!$A$3:$A$3002,"<="&EOMONTH(DATE($B$3,$D$3,1),0)),2)) | F16: =IF($A16="","",ROUND(SUMIFS(출퇴근기록!$H$3:$H$3002,출퇴근기록!$B$3:$B$3002,$A16,출퇴근기록!$I$3:$I$3002,"휴일",출퇴근기록!$A$3:$A$3002,">="&DATE($B$3,$D$3,1),출퇴근기록!$A$3:$A$3002,"<="&EOMONTH(DATE($B$3,$D$3,1),0)),2)) | G16: =IF($A16="","",ROUND(SUMIFS(출퇴근기록!$H$3:$H$3002,출퇴근기록!$B$3:$B$3002,$A16,출퇴근기록!$A$3:$A$3002,">="&DATE($B$3,$D$3,1),출퇴근기록!$A$3:$A$3002,"<="&EOMONTH(DATE($B$3,$D$3,1),0)),2)) | H16: =IF($A16="","",ROUND($D16*IF(직원목록!$F13="",8,직원목록!$F13),2)) | I16: =IF($A16="","",ROUND($G16-$H16,2)) | J16: =IF($A16="","",COUNTIFS(출퇴근기록!$B$3:$B$3002,$A16,출퇴근기록!$I$3:$I$3002,"연차",출퇴근기록!$A$3:$A$3002,">="&DATE($B$3,$D$3,1),출퇴근기록!$A$3:$A$3002,"<="&EOMONTH(DATE($B$3,$D$3,1),0))) | K16: =IF($A16="","",COUNTIFS(출퇴근기록!$B$3:$B$3002,$A16,출퇴근기록!$I$3:$I$3002,"결근",출퇴근기록!$A$3:$A$3002,">="&DATE($B$3,$D$3,1),출퇴근기록!$A$3:$A$3002,"<="&EOMONTH(DATE($B$3,$D$3,1),0)))
A17: =IF(직원목록!$A14="","",직원목록!$A14) | B17: =IF($A17="","",직원목록!$B14) | C17: =IF($A17="","",직원목록!$C14) | D17: =IF($A17="","",COUNTIFS(출퇴근기록!$B$3:$B$3002,$A17,출퇴근기록!$H$3:$H$3002,">0",출퇴근기록!$A$3:$A$3002,">="&DATE($B$3,$D$3,1),출퇴근기록!$A$3:$A$3002,"<="&EOMONTH(DATE($B$3,$D$3,1),0))) | E17: =IF($A17="","",ROUND(SUMIFS(출퇴근기록!$H$3:$H$3002,출퇴근기록!$B$3:$B$3002,$A17,출퇴근기록!$I$3:$I$3002,"평일",출퇴근기록!$A$3:$A$3002,">="&DATE($B$3,$D$3,1),출퇴근기록!$A$3:$A$3002,"<="&EOMONTH(DATE($B$3,$D$3,1),0)),2)) | F17: =IF($A17="","",ROUND(SUMIFS(출퇴근기록!$H$3:$H$3002,출퇴근기록!$B$3:$B$3002,$A17,출퇴근기록!$I$3:$I$3002,"휴일",출퇴근기록!$A$3:$A$3002,">="&DATE($B$3,$D$3,1),출퇴근기록!$A$3:$A$3002,"<="&EOMONTH(DATE($B$3,$D$3,1),0)),2)) | G17: =IF($A17="","",ROUND(SUMIFS(출퇴근기록!$H$3:$H$3002,출퇴근기록!$B$3:$B$3002,$A17,출퇴근기록!$A$3:$A$3002,">="&DATE($B$3,$D$3,1),출퇴근기록!$A$3:$A$3002,"<="&EOMONTH(DATE($B$3,$D$3,1),0)),2)) | H17: =IF($A17="","",ROUND($D17*IF(직원목록!$F14="",8,직원목록!$F14),2)) | I17: =IF($A17="","",ROUND($G17-$H17,2)) | J17: =IF($A17="","",COUNTIFS(출퇴근기록!$B$3:$B$3002,$A17,출퇴근기록!$I$3:$I$3002,"연차",출퇴근기록!$A$3:$A$3002,">="&DATE($B$3,$D$3,1),출퇴근기록!$A$3:$A$3002,"<="&EOMONTH(DATE($B$3,$D$3,1),0))) | K17: =IF($A17="","",COUNTIFS(출퇴근기록!$B$3:$B$3002,$A17,출퇴근기록!$I$3:$I$3002,"결근",출퇴근기록!$A$3:$A$3002,">="&DATE($B$3,$D$3,1),출퇴근기록!$A$3:$A$3002,"<="&EOMONTH(DATE($B$3,$D$3,1),0)))
... A305: =IF(직원목록!$A302="","",직원목록!$A302) | B305: =IF($A305="","",직원목록!$B302) | C305: =IF($A305="","",직원목록!$C302) | D305: =IF($A305="","",COUNTIFS(출퇴근기록!$B$3:$B$3002,$A305,출퇴근기록!$H$3:$H$3002,">0",출퇴근기록!$A$3:$A$3002,">="&DATE($B$3,$D$3,1),출퇴근기록!$A$3:$A$3002,"<="&EOMONTH(DATE($B$3,$D$3,1),0))) | E305: =IF($A305="","",ROUND(SUMIFS(출퇴근기록!$H$3:$H$3002,출퇴근기록!$B$3:$B$3002,$A305,출퇴근기록!$I$3:$I$3002,"평일",출퇴근기록!$A$3:$A$3002,">="&DATE($B$3,$D$3,1),출퇴근기록!$A$3:$A$3002,"<="&EOMONTH(DATE($B$3,$D$3,1),0)),2)) | F305: =IF($A305="","",ROUND(SUMIFS(출퇴근기록!$H$3:$H$3002,출퇴근기록!$B$3:$B$3002,$A305,출퇴근기록!$I$3:$I$3002,"휴일",출퇴근기록!$A$3:$A$3002,">="&DATE($B$3,$D$3,1),출퇴근기록!$A$3:$A$3002,"<="&EOMONTH(DATE($B$3,$D$3,1),0)),2)) | G305: =IF($A305="","",ROUND(SUMIFS(출퇴근기록!$H$3:$H$3002,출퇴근기록!$B$3:$B$3002,$A305,출퇴근기록!$A$3:$A$3002,">="&DATE($B$3,$D$3,1),출퇴근기록!$A$3:$A$3002,"<="&EOMONTH(DATE($B$3,$D$3,1),0)),2)) | H305: =IF($A305="","",ROUND($D305*IF(직원목록!$F302="",8,직원목록!$F302),2)) | I305: =IF($A305="","",ROUND($G305-$H305,2)) | J305: =IF($A305="","",COUNTIFS(출퇴근기록!$B$3:$B$3002,$A305,출퇴근기록!$I$3:$I$3002,"연차",출퇴근기록!$A$3:$A$3002,">="&DATE($B$3,$D$3,1),출퇴근기록!$A$3:$A$3002,"<="&EOMONTH(DATE($B$3,$D$3,1),0))) | K305: =IF($A305="","",COUNTIFS(출퇴근기록!$B$3:$B$3002,$A305,출퇴근기록!$I$3:$I$3002,"결근",출퇴근기록!$A$3:$A$3002,">="&DATE($B$3,$D$3,1),출퇴근기록!$A$3:$A$3002,"<="&EOMONTH(DATE($B$3,$D$3,1),0)))
C307: 합계 | D307: =SUM(D6:D305) -> 14 | E307: =SUM(E6:E305) -> 109.17 | F307: =SUM(F6:F305) -> 6 | G307: =SUM(G6:G305) -> 115.17 | H307: =SUM(H6:H305) -> 112 | I307: =SUM(I6:I305) -> 3.17 | J307: =SUM(J6:J305) -> 1 | K307: =SUM(K6:K305) -> 0
A309: ※ 초과시간 = 총 근무시간 − (근무일수 × 소정근로시간). 수당 금액은 계산하지 않습니다.

Sheet 개인별상세
A1: 개인별상세
A3: 사번 | B3: E001 | C3: =IFERROR(INDEX(직원목록!$B$3:$B$302,MATCH($B$3,직원목록!$A$3:$A$302,0)),"") -> 김직원 | E3: 연도 | F3: 2026 | G3: 월 | H3: 9
A5: 일 | B5: 요일 | C5: 출근 | D5: 퇴근 | E5: 휴게(분) | F5: 근무시간 | G5: 구분 | H5: 비고
A6: =IF(MONTH(DATE($F$3,$H$3,1))<>$H$3,"",1) -> 1 | B6: =IF($A6="","",CHOOSE(WEEKDAY(DATE($F$3,$H$3,1)),"일","월","화","수","목","금","토")) -> 화 | C6: =IF($A6="","",IFERROR(IF(INDEX(출퇴근기록!$E$3:$E$3002,MATCH(1,INDEX((출퇴근기록!$A$3:$A$3002=DATE($F$3,$H$3,1))*(출퇴근기록!$B$3:$B$3002=$B$3),0),0))="","",INDEX(출퇴근기록!$E$3:$E$3002,MATCH(1,INDEX((출퇴근기록!$A$3:$A$3002=DATE($F$3,$H$3,1))*(출퇴근기록!$B$3:$B$3002=$B$3),0),0))),"")) -> 900 | D6: =IF($A6="","",IFERROR(IF(INDEX(출퇴근기록!$F$3:$F$3002,MATCH(1,INDEX((출퇴근기록!$A$3:$A$3002=DATE($F$3,$H$3,1))*(출퇴근기록!$B$3:$B$3002=$B$3),0),0))="","",INDEX(출퇴근기록!$F$3:$F$3002,MATCH(1,INDEX((출퇴근기록!$A$3:$A$3002=DATE($F$3,$H$3,1))*(출퇴근기록!$B$3:$B$3002=$B$3),0),0))),"")) -> 1800 | E6: =IF($A6="","",IFERROR(IF(INDEX(출퇴근기록!$G$3:$G$3002,MATCH(1,INDEX((출퇴근기록!$A$3:$A$3002=DATE($F$3,$H$3,1))*(출퇴근기록!$B$3:$B$3002=$B$3),0),0))="","",INDEX(출퇴근기록!$G$3:$G$3002,MATCH(1,INDEX((출퇴근기록!$A$3:$A$3002=DATE($F$3,$H$3,1))*(출퇴근기록!$B$3:$B$3002=$B$3),0),0))),"")) -> 60 | F6: =IF($A6="","",IFERROR(IF(INDEX(출퇴근기록!$H$3:$H$3002,MATCH(1,INDEX((출퇴근기록!$A$3:$A$3002=DATE($F$3,$H$3,1))*(출퇴근기록!$B$3:$B$3002=$B$3),0),0))="","",INDEX(출퇴근기록!$H$3:$H$3002,MATCH(1,INDEX((출퇴근기록!$A$3:$A$3002=DATE($F$3,$H$3,1))*(출퇴근기록!$B$3:$B$3002=$B$3),0),0))),"")) -> 8 | G6: =IF($A6="","",IFERROR(IF(INDEX(출퇴근기록!$I$3:$I$3002,MATCH(1,INDEX((출퇴근기록!$A$3:$A$3002=DATE($F$3,$H$3,1))*(출퇴근기록!$B$3:$B$3002=$B$3),0),0))="","",INDEX(출퇴근기록!$I$3:$I$3002,MATCH(1,INDEX((출퇴근기록!$A$3:$A$3002=DATE($F$3,$H$3,1))*(출퇴근기록!$B$3:$B$3002=$B$3),0),0))),"")) -> 평일 | H6: =IF($A6="","",IFERROR(IF(INDEX(출퇴근기록!$J$3:$J$3002,MATCH(1,INDEX((출퇴근기록!$A$3:$A$3002=DATE($F$3,$H$3,1))*(출퇴근기록!$B$3:$B$3002=$B$3),0),0))="","",INDEX(출퇴근기록!$J$3:$J$3002,MATCH(1,INDEX((출퇴근기록!$A$3:$A$3002=DATE($F$3,$H$3,1))*(출퇴근기록!$B$3:$B$3002=$B$3),0),0))),"")) -> ← 예시 행입니다. 지우고 쓰세요.
A7: =IF(MONTH(DATE($F$3,$H$3,2))<>$H$3,"",2) -> 2 | B7: =IF($A7="","",CHOOSE(WEEKDAY(DATE($F$3,$H$3,2)),"일","월","화","수","목","금","토")) -> 수 | C7: =IF($A7="","",IFERROR(IF(INDEX(출퇴근기록!$E$3:$E$3002,MATCH(1,INDEX((출퇴근기록!$A$3:$A$3002=DATE($F$3,$H$3,2))*(출퇴근기록!$B$3:$B$3002=$B$3),0),0))="","",INDEX(출퇴근기록!$E$3:$E$3002,MATCH(1,INDEX((출퇴근기록!$A$3:$A$3002=DATE($F$3,$H$3,2))*(출퇴근기록!$B$3:$B$3002=$B$3),0),0))),"")) -> 900 | D7: =IF($A7="","",IFERROR(IF(INDEX(출퇴근기록!$F$3:$F$3002,MATCH(1,INDEX((출퇴근기록!$A$3:$A$3002=DATE($F$3,$H$3,2))*(출퇴근기록!$B$3:$B$3002=$B$3),0),0))="","",INDEX(출퇴근기록!$F$3:$F$3002,MATCH(1,INDEX((출퇴근기록!$A$3:$A$3002=DATE($F$3,$H$3,2))*(출퇴근기록!$B$3:$B$3002=$B$3),0),0))),"")) -> 1930 | E7: =IF($A7="","",IFERROR(IF(INDEX(출퇴근기록!$G$3:$G$3002,MATCH(1,INDEX((출퇴근기록!$A$3:$A$3002=DATE($F$3,$H$3,2))*(출퇴근기록!$B$3:$B$3002=$B$3),0),0))="","",INDEX(출퇴근기록!$G$3:$G$3002,MATCH(1,INDEX((출퇴근기록!$A$3:$A$3002=DATE($F$3,$H$3,2))*(출퇴근기록!$B$3:$B$3002=$B$3),0),0))),"")) -> 60 | F7: =IF($A7="","",IFERROR(IF(INDEX(출퇴근기록!$H$3:$H$3002,MATCH(1,INDEX((출퇴근기록!$A$3:$A$3002=DATE($F$3,$H$3,2))*(출퇴근기록!$B$3:$B$3002=$B$3),0),0))="","",INDEX(출퇴근기록!$H$3:$H$3002,MATCH(1,INDEX((출퇴근기록!$A$3:$A$3002=DATE($F$3,$H$3,2))*(출퇴근기록!$B$3:$B$3002=$B$3),0),0))),"")) -> 9.5 | G7: =IF($A7="","",IFERROR(IF(INDEX(출퇴근기록!$I$3:$I$3002,MATCH(1,INDEX((출퇴근기록!$A$3:$A$3002=DATE($F$3,$H$3,2))*(출퇴근기록!$B$3:$B$3002=$B$3),0),0))="","",INDEX(출퇴근기록!$I$3:$I$3002,MATCH(1,INDEX((출퇴근기록!$A$3:$A$3002=DATE($F$3,$H$3,2))*(출퇴근기록!$B$3:$B$3002=$B$3),0),0))),"")) -> 평일 | H7: =IF($A7="","",IFERROR(IF(INDEX(출퇴근기록!$J$3:$J$3002,MATCH(1,INDEX((출퇴근기록!$A$3:$A$3002=DATE($F$3,$H$3,2))*(출퇴근기록!$B$3:$B$3002=$B$3),0),0))="","",INDEX(출퇴근기록!$J$3:$J$3002,MATCH(1,INDEX((출퇴근기록!$A$3:$A$3002=DATE($F$3,$H$3,2))*(출퇴근기록!$B$3:$B$3002=$B$3),0),0))),""))
A8: =IF(MONTH(DATE($F$3,$H$3,3))<>$H$3,"",3) -> 3 | B8: =IF($A8="","",CHOOSE(WEEKDAY(DATE($F$3,$H$3,3)),"일","월","화","수","목","금","토")) -> 목 | C8: =IF($A8="","",IFERROR(IF(INDEX(출퇴근기록!$E$3:$E$3002,MATCH(1,INDEX((출퇴근기록!$A$3:$A$3002=DATE($F$3,$H$3,3))*(출퇴근기록!$B$3:$B$3002=$B$3),0),0))="","",INDEX(출퇴근기록!$E$3:$E$3002,MATCH(1,INDEX((출퇴근기록!$A$3:$A$3002=DATE($F$3,$H$3,3))*(출퇴근기록!$B$3:$B$3002=$B$3),0),0))),"")) -> 900 | D8: =IF($A8="","",IFERROR(IF(INDEX(출퇴근기록!$F$3:$F$3002,MATCH(1,INDEX((출퇴근기록!$A$3:$A$3002=DATE($F$3,$H$3,3))*(출퇴근기록!$B$3:$B$3002=$B$3),0),0))="","",INDEX(출퇴근기록!$F$3:$F$3002,MATCH(1,INDEX((출퇴근기록!$A$3:$A$3002=DATE($F$3,$H$3,3))*(출퇴근기록!$B$3:$B$3002=$B$3),0),0))),"")) -> 2030 | E8: =IF($A8="","",IFERROR(IF(INDEX(출퇴근기록!$G$3:$G$3002,MATCH(1,INDEX((출퇴근기록!$A$3:$A$3002=DATE($F$3,$H$3,3))*(출퇴근기록!$B$3:$B$3002=$B$3),0),0))="","",INDEX(출퇴근기록!$G$3:$G$3002,MATCH(1,INDEX((출퇴근기록!$A$3:$A$3002=DATE($F$3,$H$3,3))*(출퇴근기록!$B$3:$B$3002=$B$3),0),0))),"")) -> 60 | F8: =IF($A8="","",IFERROR(IF(INDEX(출퇴근기록!$H$3:$H$3002,MATCH(1,INDEX((출퇴근기록!$A$3:$A$3002=DATE($F$3,$H$3,3))*(출퇴근기록!$B$3:$B$3002=$B$3),0),0))="","",INDEX(출퇴근기록!$H$3:$H$3002,MATCH(1,INDEX((출퇴근기록!$A$3:$A$3002=DATE($F$3,$H$3,3))*(출퇴근기록!$B$3:$B$3002=$B$3),0),0))),"")) -> 10.5 | G8: =IF($A8="","",IFERROR(IF(INDEX(출퇴근기록!$I$3:$I$3002,MATCH(1,INDEX((출퇴근기록!$A$3:$A$3002=DATE($F$3,$H$3,3))*(출퇴근기록!$B$3:$B$3002=$B$3),0),0))="","",INDEX(출퇴근기록!$I$3:$I$3002,MATCH(1,INDEX((출퇴근기록!$A$3:$A$3002=DATE($F$3,$H$3,3))*(출퇴근기록!$B$3:$B$3002=$B$3),0),0))),"")) -> 평일 | H8: =IF($A8="","",IFERROR(IF(INDEX(출퇴근기록!$J$3:$J$3002,MATCH(1,INDEX((출퇴근기록!$A$3:$A$3002=DATE($F$3,$H$3,3))*(출퇴근기록!$B$3:$B$3002=$B$3),0),0))="","",INDEX(출퇴근기록!$J$3:$J$3002,MATCH(1,INDEX((출퇴근기록!$A$3:$A$3002=DATE($F$3,$H$3,3))*(출퇴근기록!$B$3:$B$3002=$B$3),0),0))),""))
A9: =IF(MONTH(DATE($F$3,$H$3,4))<>$H$3,"",4) -> 4 | B9: =IF($A9="","",CHOOSE(WEEKDAY(DATE($F$3,$H$3,4)),"일","월","화","수","목","금","토")) -> 금 | C9: =IF($A9="","",IFERROR(IF(INDEX(출퇴근기록!$E$3:$E$3002,MATCH(1,INDEX((출퇴근기록!$A$3:$A$3002=DATE($F$3,$H$3,4))*(출퇴근기록!$B$3:$B$3002=$B$3),0),0))="","",INDEX(출퇴근기록!$E$3:$E$3002,MATCH(1,INDEX((출퇴근기록!$A$3:$A$3002=DATE($F$3,$H$3,4))*(출퇴근기록!$B$3:$B$3002=$B$3),0),0))),"")) -> 900 | D9: =IF($A9="","",IFERROR(IF(INDEX(출퇴근기록!$F$3:$F$3002,MATCH(1,INDEX((출퇴근기록!$A$3:$A$3002=DATE($F$3,$H$3,4))*(출퇴근기록!$B$3:$B$3002=$B$3),0),0))="","",INDEX(출퇴근기록!$F$3:$F$3002,MATCH(1,INDEX((출퇴근기록!$A$3:$A$3002=DATE($F$3,$H$3,4))*(출퇴근기록!$B$3:$B$3002=$B$3),0),0))),"")) -> 1800 | E9: =IF($A9="","",IFERROR(IF(INDEX(출퇴근기록!$G$3:$G$3002,MATCH(1,INDEX((출퇴근기록!$A$3:$A$3002=DATE($F$3,$H$3,4))*(출퇴근기록!$B$3:$B$3002=$B$3),0),0))="","",INDEX(출퇴근기록!$G$3:$G$3002,MATCH(1,INDEX((출퇴근기록!$A$3:$A$3002=DATE($F$3,$H$3,4))*(출퇴근기록!$B$3:$B$3002=$B$3),0),0))),"")) -> 60 | F9: =IF($A9="","",IFERROR(IF(INDEX(출퇴근기록!$H$3:$H$3002,MATCH(1,INDEX((출퇴근기록!$A$3:$A$3002=DATE($F$3,$H$3,4))*(출퇴근기록!$B$3:$B$3002=$B$3),0),0))="","",INDEX(출퇴근기록!$H$3:$H$3002,MATCH(1,INDEX((출퇴근기록!$A$3:$A$3002=DATE($F$3,$H$3,4))*(출퇴근기록!$B$3:$B$3002=$B$3),0),0))),"")) -> 8 | G9: =IF($A9="","",IFERROR(IF(INDEX(출퇴근기록!$I$3:$I$3002,MATCH(1,INDEX((출퇴근기록!$A$3:$A$3002=DATE($F$3,$H$3,4))*(출퇴근기록!$B$3:$B$3002=$B$3),0),0))="","",INDEX(출퇴근기록!$I$3:$I$3002,MATCH(1,INDEX((출퇴근기록!$A$3:$A$3002=DATE($F$3,$H$3,4))*(출퇴근기록!$B$3:$B$3002=$B$3),0),0))),"")) -> 평일 | H9: =IF($A9="","",IFERROR(IF(INDEX(출퇴근기록!$J$3:$J$3002,MATCH(1,INDEX((출퇴근기록!$A$3:$A$3002=DATE($F$3,$H$3,4))*(출퇴근기록!$B$3:$B$3002=$B$3),0),0))="","",INDEX(출퇴근기록!$J$3:$J$3002,MATCH(1,INDEX((출퇴근기록!$A$3:$A$3002=DATE($F$3,$H$3,4))*(출퇴근기록!$B$3:$B$3002=$B$3),0),0))),""))
A10: =IF(MONTH(DATE($F$3,$H$3,5))<>$H$3,"",5) -> 5 | B10: =IF($A10="","",CHOOSE(WEEKDAY(DATE($F$3,$H$3,5)),"일","월","화","수","목","금","토")) -> 토 | C10: =IF($A10="","",IFERROR(IF(INDEX(출퇴근기록!$E$3:$E$3002,MATCH(1,INDEX((출퇴근기록!$A$3:$A$3002=DATE($F$3,$H$3,5))*(출퇴근기록!$B$3:$B$3002=$B$3),0),0))="","",INDEX(출퇴근기록!$E$3:$E$3002,MATCH(1,INDEX((출퇴근기록!$A$3:$A$3002=DATE($F$3,$H$3,5))*(출퇴근기록!$B$3:$B$3002=$B$3),0),0))),"")) | D10: =IF($A10="","",IFERROR(IF(INDEX(출퇴근기록!$F$3:$F$3002,MATCH(1,INDEX((출퇴근기록!$A$3:$A$3002=DATE($F$3,$H$3,5))*(출퇴근기록!$B$3:$B$3002=$B$3),0),0))="","",INDEX(출퇴근기록!$F$3:$F$3002,MATCH(1,INDEX((출퇴근기록!$A$3:$A$3002=DATE($F$3,$H$3,5))*(출퇴근기록!$B$3:$B$3002=$B$3),0),0))),"")) | E10: =IF($A10="","",IFERROR(IF(INDEX(출퇴근기록!$G$3:$G$3002,MATCH(1,INDEX((출퇴근기록!$A$3:$A$3002=DATE($F$3,$H$3,5))*(출퇴근기록!$B$3:$B$3002=$B$3),0),0))="","",INDEX(출퇴근기록!$G$3:$G$3002,MATCH(1,INDEX((출퇴근기록!$A$3:$A$3002=DATE($F$3,$H$3,5))*(출퇴근기록!$B$3:$B$3002=$B$3),0),0))),"")) | F10: =IF($A10="","",IFERROR(IF(INDEX(출퇴근기록!$H$3:$H$3002,MATCH(1,INDEX((출퇴근기록!$A$3:$A$3002=DATE($F$3,$H$3,5))*(출퇴근기록!$B$3:$B$3002=$B$3),0),0))="","",INDEX(출퇴근기록!$H$3:$H$3002,MATCH(1,INDEX((출퇴근기록!$A$3:$A$3002=DATE($F$3,$H$3,5))*(출퇴근기록!$B$3:$B$3002=$B$3),0),0))),"")) | G10: =IF($A10="","",IFERROR(IF(INDEX(출퇴근기록!$I$3:$I$3002,MATCH(1,INDEX((출퇴근기록!$A$3:$A$3002=DATE($F$3,$H$3,5))*(출퇴근기록!$B$3:$B$3002=$B$3),0),0))="","",INDEX(출퇴근기록!$I$3:$I$3002,MATCH(1,INDEX((출퇴근기록!$A$3:$A$3002=DATE($F$3,$H$3,5))*(출퇴근기록!$B$3:$B$3002=$B$3),0),0))),"")) | H10: =IF($A10="","",IFERROR(IF(INDEX(출퇴근기록!$J$3:$J$3002,MATCH(1,INDEX((출퇴근기록!$A$3:$A$3002=DATE($F$3,$H$3,5))*(출퇴근기록!$B$3:$B$3002=$B$3),0),0))="","",INDEX(출퇴근기록!$J$3:$J$3002,MATCH(1,INDEX((출퇴근기록!$A$3:$A$3002=DATE($F$3,$H$3,5))*(출퇴근기록!$B$3:$B$3002=$B$3),0),0))),""))
A11: =IF(MONTH(DATE($F$3,$H$3,6))<>$H$3,"",6) -> 6 | B11: =IF($A11="","",CHOOSE(WEEKDAY(DATE($F$3,$H$3,6)),"일","월","화","수","목","금","토")) -> 일 | C11: =IF($A11="","",IFERROR(IF(INDEX(출퇴근기록!$E$3:$E$3002,MATCH(1,INDEX((출퇴근기록!$A$3:$A$3002=DATE($F$3,$H$3,6))*(출퇴근기록!$B$3:$B$3002=$B$3),0),0))="","",INDEX(출퇴근기록!$E$3:$E$3002,MATCH(1,INDEX((출퇴근기록!$A$3:$A$3002=DATE($F$3,$H$3,6))*(출퇴근기록!$B$3:$B$3002=$B$3),0),0))),"")) | D11: =IF($A11="","",IFERROR(IF(INDEX(출퇴근기록!$F$3:$F$3002,MATCH(1,INDEX((출퇴근기록!$A$3:$A$3002=DATE($F$3,$H$3,6))*(출퇴근기록!$B$3:$B$3002=$B$3),0),0))="","",INDEX(출퇴근기록!$F$3:$F$3002,MATCH(1,INDEX((출퇴근기록!$A$3:$A$3002=DATE($F$3,$H$3,6))*(출퇴근기록!$B$3:$B$3002=$B$3),0),0))),"")) | E11: =IF($A11="","",IFERROR(IF(INDEX(출퇴근기록!$G$3:$G$3002,MATCH(1,INDEX((출퇴근기록!$A$3:$A$3002=DATE($F$3,$H$3,6))*(출퇴근기록!$B$3:$B$3002=$B$3),0),0))="","",INDEX(출퇴근기록!$G$3:$G$3002,MATCH(1,INDEX((출퇴근기록!$A$3:$A$3002=DATE($F$3,$H$3,6))*(출퇴근기록!$B$3:$B$3002=$B$3),0),0))),"")) | F11: =IF($A11="","",IFERROR(IF(INDEX(출퇴근기록!$H$3:$H$3002,MATCH(1,INDEX((출퇴근기록!$A$3:$A$3002=DATE($F$3,$H$3,6))*(출퇴근기록!$B$3:$B$3002=$B$3),0),0))="","",INDEX(출퇴근기록!$H$3:$H$3002,MATCH(1,INDEX((출퇴근기록!$A$3:$A$3002=DATE($F$3,$H$3,6))*(출퇴근기록!$B$3:$B$3002=$B$3),0),0))),"")) | G11: =IF($A11="","",IFERROR(IF(INDEX(출퇴근기록!$I$3:$I$3002,MATCH(1,INDEX((출퇴근기록!$A$3:$A$3002=DATE($F$3,$H$3,6))*(출퇴근기록!$B$3:$B$3002=$B$3),0),0))="","",INDEX(출퇴근기록!$I$3:$I$3002,MATCH(1,INDEX((출퇴근기록!$A$3:$A$3002=DATE($F$3,$H$3,6))*(출퇴근기록!$B$3:$B$3002=$B$3),0),0))),"")) | H11: =IF($A11="","",IFERROR(IF(INDEX(출퇴근기록!$J$3:$J$3002,MATCH(1,INDEX((출퇴근기록!$A$3:$A$3002=DATE($F$3,$H$3,6))*(출퇴근기록!$B$3:$B$3002=$B$3),0),0))="","",INDEX(출퇴근기록!$J$3:$J$3002,MATCH(1,INDEX((출퇴근기록!$A$3:$A$3002=DATE($F$3,$H$3,6))*(출퇴근기록!$B$3:$B$3002=$B$3),0),0))),""))
A12: =IF(MONTH(DATE($F$3,$H$3,7))<>$H$3,"",7) -> 7 | B12: =IF($A12="","",CHOOSE(WEEKDAY(DATE($F$3,$H$3,7)),"일","월","화","수","목","금","토")) -> 월 | C12: =IF($A12="","",IFERROR(IF(INDEX(출퇴근기록!$E$3:$E$3002,MATCH(1,INDEX((출퇴근기록!$A$3:$A$3002=DATE($F$3,$H$3,7))*(출퇴근기록!$B$3:$B$3002=$B$3),0),0))="","",INDEX(출퇴근기록!$E$3:$E$3002,MATCH(1,INDEX((출퇴근기록!$A$3:$A$3002=DATE($F$3,$H$3,7))*(출퇴근기록!$B$3:$B$3002=$B$3),0),0))),"")) -> 900 | D12: =IF($A12="","",IFERROR(IF(INDEX(출퇴근기록!$F$3:$F$3002,MATCH(1,INDEX((출퇴근기록!$A$3:$A$3002=DATE($F$3,$H$3,7))*(출퇴근기록!$B$3:$B$3002=$B$3),0),0))="","",INDEX(출퇴근기록!$F$3:$F$3002,MATCH(1,INDEX((출퇴근기록!$A$3:$A$3002=DATE($F$3,$H$3,7))*(출퇴근기록!$B$3:$B$3002=$B$3),0),0))),"")) -> 1800 | E12: =IF($A12="","",IFERROR(IF(INDEX(출퇴근기록!$G$3:$G$3002,MATCH(1,INDEX((출퇴근기록!$A$3:$A$3002=DATE($F$3,$H$3,7))*(출퇴근기록!$B$3:$B$3002=$B$3),0),0))="","",INDEX(출퇴근기록!$G$3:$G$3002,MATCH(1,INDEX((출퇴근기록!$A$3:$A$3002=DATE($F$3,$H$3,7))*(출퇴근기록!$B$3:$B$3002=$B$3),0),0))),"")) -> 60 | F12: =IF($A12="","",IFERROR(IF(INDEX(출퇴근기록!$H$3:$H$3002,MATCH(1,INDEX((출퇴근기록!$A$3:$A$3002=DATE($F$3,$H$3,7))*(출퇴근기록!$B$3:$B$3002=$B$3),0),0))="","",INDEX(출퇴근기록!$H$3:$H$3002,MATCH(1,INDEX((출퇴근기록!$A$3:$A$3002=DATE($F$3,$H$3,7))*(출퇴근기록!$B$3:$B$3002=$B$3),0),0))),"")) -> 8 | G12: =IF($A12="","",IFERROR(IF(INDEX(출퇴근기록!$I$3:$I$3002,MATCH(1,INDEX((출퇴근기록!$A$3:$A$3002=DATE($F$3,$H$3,7))*(출퇴근기록!$B$3:$B$3002=$B$3),0),0))="","",INDEX(출퇴근기록!$I$3:$I$3002,MATCH(1,INDEX((출퇴근기록!$A$3:$A$3002=DATE($F$3,$H$3,7))*(출퇴근기록!$B$3:$B$3002=$B$3),0),0))),"")) -> 평일 | H12: =IF($A12="","",IFERROR(IF(INDEX(출퇴근기록!$J$3:$J$3002,MATCH(1,INDEX((출퇴근기록!$A$3:$A$3002=DATE($F$3,$H$3,7))*(출퇴근기록!$B$3:$B$3002=$B$3),0),0))="","",INDEX(출퇴근기록!$J$3:$J$3002,MATCH(1,INDEX((출퇴근기록!$A$3:$A$3002=DATE($F$3,$H$3,7))*(출퇴근기록!$B$3:$B$3002=$B$3),0),0))),""))
A13: =IF(MONTH(DATE($F$3,$H$3,8))<>$H$3,"",8) -> 8 | B13: =IF($A13="","",CHOOSE(WEEKDAY(DATE($F$3,$H$3,8)),"일","월","화","수","목","금","토")) -> 화 | C13: =IF($A13="","",IFERROR(IF(INDEX(출퇴근기록!$E$3:$E$3002,MATCH(1,INDEX((출퇴근기록!$A$3:$A$3002=DATE($F$3,$H$3,8))*(출퇴근기록!$B$3:$B$3002=$B$3),0),0))="","",INDEX(출퇴근기록!$E$3:$E$3002,MATCH(1,INDEX((출퇴근기록!$A$3:$A$3002=DATE($F$3,$H$3,8))*(출퇴근기록!$B$3:$B$3002=$B$3),0),0))),"")) -> 900 | D13: =IF($A13="","",IFERROR(IF(INDEX(출퇴근기록!$F$3:$F$3002,MATCH(1,INDEX((출퇴근기록!$A$3:$A$3002=DATE($F$3,$H$3,8))*(출퇴근기록!$B$3:$B$3002=$B$3),0),0))="","",INDEX(출퇴근기록!$F$3:$F$3002,MATCH(1,INDEX((출퇴근기록!$A$3:$A$3002=DATE($F$3,$H$3,8))*(출퇴근기록!$B$3:$B$3002=$B$3),0),0))),"")) -> 1900 | E13: =IF($A13="","",IFERROR(IF(INDEX(출퇴근기록!$G$3:$G$3002,MATCH(1,INDEX((출퇴근기록!$A$3:$A$3002=DATE($F$3,$H$3,8))*(출퇴근기록!$B$3:$B$3002=$B$3),0),0))="","",INDEX(출퇴근기록!$G$3:$G$3002,MATCH(1,INDEX((출퇴근기록!$A$3:$A$3002=DATE($F$3,$H$3,8))*(출퇴근기록!$B$3:$B$3002=$B$3),0),0))),"")) -> 60 | F13: =IF($A13="","",IFERROR(IF(INDEX(출퇴근기록!$H$3:$H$3002,MATCH(1,INDEX((출퇴근기록!$A$3:$A$3002=DATE($F$3,$H$3,8))*(출퇴근기록!$B$3:$B$3002=$B$3),0),0))="","",INDEX(출퇴근기록!$H$3:$H$3002,MATCH(1,INDEX((출퇴근기록!$A$3:$A$3002=DATE($F$3,$H$3,8))*(출퇴근기록!$B$3:$B$3002=$B$3),0),0))),"")) -> 9 | G13: =IF($A13="","",IFERROR(IF(INDEX(출퇴근기록!$I$3:$I$3002,MATCH(1,INDEX((출퇴근기록!$A$3:$A$3002=DATE($F$3,$H$3,8))*(출퇴근기록!$B$3:$B$3002=$B$3),0),0))="","",INDEX(출퇴근기록!$I$3:$I$3002,MATCH(1,INDEX((출퇴근기록!$A$3:$A$3002=DATE($F$3,$H$3,8))*(출퇴근기록!$B$3:$B$3002=$B$3),0),0))),"")) -> 평일 | H13: =IF($A13="","",IFERROR(IF(INDEX(출퇴근기록!$J$3:$J$3002,MATCH(1,INDEX((출퇴근기록!$A$3:$A$3002=DATE($F$3,$H$3,8))*(출퇴근기록!$B$3:$B$3002=$B$3),0),0))="","",INDEX(출퇴근기록!$J$3:$J$3002,MATCH(1,INDEX((출퇴근기록!$A$3:$A$3002=DATE($F$3,$H$3,8))*(출퇴근기록!$B$3:$B$3002=$B$3),0),0))),""))
A14: =IF(MONTH(DATE($F$3,$H$3,9))<>$H$3,"",9) -> 9 | B14: =IF($A14="","",CHOOSE(WEEKDAY(DATE($F$3,$H$3,9)),"일","월","화","수","목","금","토")) -> 수 | C14: =IF($A14="","",IFERROR(IF(INDEX(출퇴근기록!$E$3:$E$3002,MATCH(1,INDEX((출퇴근기록!$A$3:$A$3002=DATE($F$3,$H$3,9))*(출퇴근기록!$B$3:$B$3002=$B$3),0),0))="","",INDEX(출퇴근기록!$E$3:$E$3002,MATCH(1,INDEX((출퇴근기록!$A$3:$A$3002=DATE($F$3,$H$3,9))*(출퇴근기록!$B$3:$B$3002=$B$3),0),0))),"")) -> 900 | D14: =IF($A14="","",IFERROR(IF(INDEX(출퇴근기록!$F$3:$F$3002,MATCH(1,INDEX((출퇴근기록!$A$3:$A$3002=DATE($F$3,$H$3,9))*(출퇴근기록!$B$3:$B$3002=$B$3),0),0))="","",INDEX(출퇴근기록!$F$3:$F$3002,MATCH(1,INDEX((출퇴근기록!$A$3:$A$3002=DATE($F$3,$H$3,9))*(출퇴근기록!$B$3:$B$3002=$B$3),0),0))),"")) -> 1800 | E14: =IF($A14="","",IFERROR(IF(INDEX(출퇴근기록!$G$3:$G$3002,MATCH(1,INDEX((출퇴근기록!$A$3:$A$3002=DATE($F$3,$H$3,9))*(출퇴근기록!$B$3:$B$3002=$B$3),0),0))="","",INDEX(출퇴근기록!$G$3:$G$3002,MATCH(1,INDEX((출퇴근기록!$A$3:$A$3002=DATE($F$3,$H$3,9))*(출퇴근기록!$B$3:$B$3002=$B$3),0),0))),"")) -> 60 | F14: =IF($A14="","",IFERROR(IF(INDEX(출퇴근기록!$H$3:$H$3002,MATCH(1,INDEX((출퇴근기록!$A$3:$A$3002=DATE($F$3,$H$3,9))*(출퇴근기록!$B$3:$B$3002=$B$3),0),0))="","",INDEX(출퇴근기록!$H$3:$H$3002,MATCH(1,INDEX((출퇴근기록!$A$3:$A$3002=DATE($F$3,$H$3,9))*(출퇴근기록!$B$3:$B$3002=$B$3),0),0))),"")) -> 8 | G14: =IF($A14="","",IFERROR(IF(INDEX(출퇴근기록!$I$3:$I$3002,MATCH(1,INDEX((출퇴근기록!$A$3:$A$3002=DATE($F$3,$H$3,9))*(출퇴근기록!$B$3:$B$3002=$B$3),0),0))="","",INDEX(출퇴근기록!$I$3:$I$3002,MATCH(1,INDEX((출퇴근기록!$A$3:$A$3002=DATE($F$3,$H$3,9))*(출퇴근기록!$B$3:$B$3002=$B$3),0),0))),"")) -> 평일 | H14: =IF($A14="","",IFERROR(IF(INDEX(출퇴근기록!$J$3:$J$3002,MATCH(1,INDEX((출퇴근기록!$A$3:$A$3002=DATE($F$3,$H$3,9))*(출퇴근기록!$B$3:$B$3002=$B$3),0),0))="","",INDEX(출퇴근기록!$J$3:$J$3002,MATCH(1,INDEX((출퇴근기록!$A$3:$A$3002=DATE($F$3,$H$3,9))*(출퇴근기록!$B$3:$B$3002=$B$3),0),0))),""))
A15: =IF(MONTH(DATE($F$3,$H$3,10))<>$H$3,"",10) -> 10 | B15: =IF($A15="","",CHOOSE(WEEKDAY(DATE($F$3,$H$3,10)),"일","월","화","수","목","금","토")) -> 목 | C15: =IF($A15="","",IFERROR(IF(INDEX(출퇴근기록!$E$3:$E$3002,MATCH(1,INDEX((출퇴근기록!$A$3:$A$3002=DATE($F$3,$H$3,10))*(출퇴근기록!$B$3:$B$3002=$B$3),0),0))="","",INDEX(출퇴근기록!$E$3:$E$3002,MATCH(1,INDEX((출퇴근기록!$A$3:$A$3002=DATE($F$3,$H$3,10))*(출퇴근기록!$B$3:$B$3002=$B$3),0),0))),"")) -> 900 | D15: =IF($A15="","",IFERROR(IF(INDEX(출퇴근기록!$F$3:$F$3002,MATCH(1,INDEX((출퇴근기록!$A$3:$A$3002=DATE($F$3,$H$3,10))*(출퇴근기록!$B$3:$B$3002=$B$3),0),0))="","",INDEX(출퇴근기록!$F$3:$F$3002,MATCH(1,INDEX((출퇴근기록!$A$3:$A$3002=DATE($F$3,$H$3,10))*(출퇴근기록!$B$3:$B$3002=$B$3),0),0))),"")) -> 1800 | E15: =IF($A15="","",IFERROR(IF(INDEX(출퇴근기록!$G$3:$G$3002,MATCH(1,INDEX((출퇴근기록!$A$3:$A$3002=DATE($F$3,$H$3,10))*(출퇴근기록!$B$3:$B$3002=$B$3),0),0))="","",INDEX(출퇴근기록!$G$3:$G$3002,MATCH(1,INDEX((출퇴근기록!$A$3:$A$3002=DATE($F$3,$H$3,10))*(출퇴근기록!$B$3:$B$3002=$B$3),0),0))),"")) -> 60 | F15: =IF($A15="","",IFERROR(IF(INDEX(출퇴근기록!$H$3:$H$3002,MATCH(1,INDEX((출퇴근기록!$A$3:$A$3002=DATE($F$3,$H$3,10))*(출퇴근기록!$B$3:$B$3002=$B$3),0),0))="","",INDEX(출퇴근기록!$H$3:$H$3002,MATCH(1,INDEX((출퇴근기록!$A$3:$A$3002=DATE($F$3,$H$3,10))*(출퇴근기록!$B$3:$B$3002=$B$3),0),0))),"")) -> 8 | G15: =IF($A15="","",IFERROR(IF(INDEX(출퇴근기록!$I$3:$I$3002,MATCH(1,INDEX((출퇴근기록!$A$3:$A$3002=DATE($F$3,$H$3,10))*(출퇴근기록!$B$3:$B$3002=$B$3),0),0))="","",INDEX(출퇴근기록!$I$3:$I$3002,MATCH(1,INDEX((출퇴근기록!$A$3:$A$3002=DATE($F$3,$H$3,10))*(출퇴근기록!$B$3:$B$3002=$B$3),0),0))),"")) -> 평일 | H15: =IF($A15="","",IFERROR(IF(INDEX(출퇴근기록!$J$3:$J$3002,MATCH(1,INDEX((출퇴근기록!$A$3:$A$3002=DATE($F$3,$H$3,10))*(출퇴근기록!$B$3:$B$3002=$B$3),0),0))="","",INDEX(출퇴근기록!$J$3:$J$3002,MATCH(1,INDEX((출퇴근기록!$A$3:$A$3002=DATE($F$3,$H$3,10))*(출퇴근기록!$B$3:$B$3002=$B$3),0),0))),""))
A16: =IF(MONTH(DATE($F$3,$H$3,11))<>$H$3,"",11) -> 11 | B16: =IF($A16="","",CHOOSE(WEEKDAY(DATE($F$3,$H$3,11)),"일","월","화","수","목","금","토")) -> 금 | C16: =IF($A16="","",IFERROR(IF(INDEX(출퇴근기록!$E$3:$E$3002,MATCH(1,INDEX((출퇴근기록!$A$3:$A$3002=DATE($F$3,$H$3,11))*(출퇴근기록!$B$3:$B$3002=$B$3),0),0))="","",INDEX(출퇴근기록!$E$3:$E$3002,MATCH(1,INDEX((출퇴근기록!$A$3:$A$3002=DATE($F$3,$H$3,11))*(출퇴근기록!$B$3:$B$3002=$B$3),0),0))),"")) -> 900 | D16: =IF($A16="","",IFERROR(IF(INDEX(출퇴근기록!$F$3:$F$3002,MATCH(1,INDEX((출퇴근기록!$A$3:$A$3002=DATE($F$3,$H$3,11))*(출퇴근기록!$B$3:$B$3002=$B$3),0),0))="","",INDEX(출퇴근기록!$F$3:$F$3002,MATCH(1,INDEX((출퇴근기록!$A$3:$A$3002=DATE($F$3,$H$3,11))*(출퇴근기록!$B$3:$B$3002=$B$3),0),0))),"")) -> 1730 | E16: =IF($A16="","",IFERROR(IF(INDEX(출퇴근기록!$G$3:$G$3002,MATCH(1,INDEX((출퇴근기록!$A$3:$A$3002=DATE($F$3,$H$3,11))*(출퇴근기록!$B$3:$B$3002=$B$3),0),0))="","",INDEX(출퇴근기록!$G$3:$G$3002,MATCH(1,INDEX((출퇴근기록!$A$3:$A$3002=DATE($F$3,$H$3,11))*(출퇴근기록!$B$3:$B$3002=$B$3),0),0))),"")) -> 60 | F16: =IF($A16="","",IFERROR(IF(INDEX(출퇴근기록!$H$3:$H$3002,MATCH(1,INDEX((출퇴근기록!$A$3:$A$3002=DATE($F$3,$H$3,11))*(출퇴근기록!$B$3:$B$3002=$B$3),0),0))="","",INDEX(출퇴근기록!$H$3:$H$3002,MATCH(1,INDEX((출퇴근기록!$A$3:$A$3002=DATE($F$3,$H$3,11))*(출퇴근기록!$B$3:$B$3002=$B$3),0),0))),"")) -> 7.5 | G16: =IF($A16="","",IFERROR(IF(INDEX(출퇴근기록!$I$3:$I$3002,MATCH(1,INDEX((출퇴근기록!$A$3:$A$3002=DATE($F$3,$H$3,11))*(출퇴근기록!$B$3:$B$3002=$B$3),0),0))="","",INDEX(출퇴근기록!$I$3:$I$3002,MATCH(1,INDEX((출퇴근기록!$A$3:$A$3002=DATE($F$3,$H$3,11))*(출퇴근기록!$B$3:$B$3002=$B$3),0),0))),"")) -> 평일 | H16: =IF($A16="","",IFERROR(IF(INDEX(출퇴근기록!$J$3:$J$3002,MATCH(1,INDEX((출퇴근기록!$A$3:$A$3002=DATE($F$3,$H$3,11))*(출퇴근기록!$B$3:$B$3002=$B$3),0),0))="","",INDEX(출퇴근기록!$J$3:$J$3002,MATCH(1,INDEX((출퇴근기록!$A$3:$A$3002=DATE($F$3,$H$3,11))*(출퇴근기록!$B$3:$B$3002=$B$3),0),0))),""))
A17: =IF(MONTH(DATE($F$3,$H$3,12))<>$H$3,"",12) -> 12 | B17: =IF($A17="","",CHOOSE(WEEKDAY(DATE($F$3,$H$3,12)),"일","월","화","수","목","금","토")) -> 토 | C17: =IF($A17="","",IFERROR(IF(INDEX(출퇴근기록!$E$3:$E$3002,MATCH(1,INDEX((출퇴근기록!$A$3:$A$3002=DATE($F$3,$H$3,12))*(출퇴근기록!$B$3:$B$3002=$B$3),0),0))="","",INDEX(출퇴근기록!$E$3:$E$3002,MATCH(1,INDEX((출퇴근기록!$A$3:$A$3002=DATE($F$3,$H$3,12))*(출퇴근기록!$B$3:$B$3002=$B$3),0),0))),"")) | D17: =IF($A17="","",IFERROR(IF(INDEX(출퇴근기록!$F$3:$F$3002,MATCH(1,INDEX((출퇴근기록!$A$3:$A$3002=DATE($F$3,$H$3,12))*(출퇴근기록!$B$3:$B$3002=$B$3),0),0))="","",INDEX(출퇴근기록!$F$3:$F$3002,MATCH(1,INDEX((출퇴근기록!$A$3:$A$3002=DATE($F$3,$H$3,12))*(출퇴근기록!$B$3:$B$3002=$B$3),0),0))),"")) | E17: =IF($A17="","",IFERROR(IF(INDEX(출퇴근기록!$G$3:$G$3002,MATCH(1,INDEX((출퇴근기록!$A$3:$A$3002=DATE($F$3,$H$3,12))*(출퇴근기록!$B$3:$B$3002=$B$3),0),0))="","",INDEX(출퇴근기록!$G$3:$G$3002,MATCH(1,INDEX((출퇴근기록!$A$3:$A$3002=DATE($F$3,$H$3,12))*(출퇴근기록!$B$3:$B$3002=$B$3),0),0))),"")) | F17: =IF($A17="","",IFERROR(IF(INDEX(출퇴근기록!$H$3:$H$3002,MATCH(1,INDEX((출퇴근기록!$A$3:$A$3002=DATE($F$3,$H$3,12))*(출퇴근기록!$B$3:$B$3002=$B$3),0),0))="","",INDEX(출퇴근기록!$H$3:$H$3002,MATCH(1,INDEX((출퇴근기록!$A$3:$A$3002=DATE($F$3,$H$3,12))*(출퇴근기록!$B$3:$B$3002=$B$3),0),0))),"")) | G17: =IF($A17="","",IFERROR(IF(INDEX(출퇴근기록!$I$3:$I$3002,MATCH(1,INDEX((출퇴근기록!$A$3:$A$3002=DATE($F$3,$H$3,12))*(출퇴근기록!$B$3:$B$3002=$B$3),0),0))="","",INDEX(출퇴근기록!$I$3:$I$3002,MATCH(1,INDEX((출퇴근기록!$A$3:$A$3002=DATE($F$3,$H$3,12))*(출퇴근기록!$B$3:$B$3002=$B$3),0),0))),"")) | H17: =IF($A17="","",IFERROR(IF(INDEX(출퇴근기록!$J$3:$J$3002,MATCH(1,INDEX((출퇴근기록!$A$3:$A$3002=DATE($F$3,$H$3,12))*(출퇴근기록!$B$3:$B$3002=$B$3),0),0))="","",INDEX(출퇴근기록!$J$3:$J$3002,MATCH(1,INDEX((출퇴근기록!$A$3:$A$3002=DATE($F$3,$H$3,12))*(출퇴근기록!$B$3:$B$3002=$B$3),0),0))),""))
A18: =IF(MONTH(DATE($F$3,$H$3,13))<>$H$3,"",13) -> 13 | B18: =IF($A18="","",CHOOSE(WEEKDAY(DATE($F$3,$H$3,13)),"일","월","화","수","목","금","토")) -> 일 | C18: =IF($A18="","",IFERROR(IF(INDEX(출퇴근기록!$E$3:$E$3002,MATCH(1,INDEX((출퇴근기록!$A$3:$A$3002=DATE($F$3,$H$3,13))*(출퇴근기록!$B$3:$B$3002=$B$3),0),0))="","",INDEX(출퇴근기록!$E$3:$E$3002,MATCH(1,INDEX((출퇴근기록!$A$3:$A$3002=DATE($F$3,$H$3,13))*(출퇴근기록!$B$3:$B$3002=$B$3),0),0))),"")) | D18: =IF($A18="","",IFERROR(IF(INDEX(출퇴근기록!$F$3:$F$3002,MATCH(1,INDEX((출퇴근기록!$A$3:$A$3002=DATE($F$3,$H$3,13))*(출퇴근기록!$B$3:$B$3002=$B$3),0),0))="","",INDEX(출퇴근기록!$F$3:$F$3002,MATCH(1,INDEX((출퇴근기록!$A$3:$A$3002=DATE($F$3,$H$3,13))*(출퇴근기록!$B$3:$B$3002=$B$3),0),0))),"")) | E18: =IF($A18="","",IFERROR(IF(INDEX(출퇴근기록!$G$3:$G$3002,MATCH(1,INDEX((출퇴근기록!$A$3:$A$3002=DATE($F$3,$H$3,13))*(출퇴근기록!$B$3:$B$3002=$B$3),0),0))="","",INDEX(출퇴근기록!$G$3:$G$3002,MATCH(1,INDEX((출퇴근기록!$A$3:$A$3002=DATE($F$3,$H$3,13))*(출퇴근기록!$B$3:$B$3002=$B$3),0),0))),"")) | F18: =IF($A18="","",IFERROR(IF(INDEX(출퇴근기록!$H$3:$H$3002,MATCH(1,INDEX((출퇴근기록!$A$3:$A$3002=DATE($F$3,$H$3,13))*(출퇴근기록!$B$3:$B$3002=$B$3),0),0))="","",INDEX(출퇴근기록!$H$3:$H$3002,MATCH(1,INDEX((출퇴근기록!$A$3:$A$3002=DATE($F$3,$H$3,13))*(출퇴근기록!$B$3:$B$3002=$B$3),0),0))),"")) | G18: =IF($A18="","",IFERROR(IF(INDEX(출퇴근기록!$I$3:$I$3002,MATCH(1,INDEX((출퇴근기록!$A$3:$A$3002=DATE($F$3,$H$3,13))*(출퇴근기록!$B$3:$B$3002=$B$3),0),0))="","",INDEX(출퇴근기록!$I$3:$I$3002,MATCH(1,INDEX((출퇴근기록!$A$3:$A$3002=DATE($F$3,$H$3,13))*(출퇴근기록!$B$3:$B$3002=$B$3),0),0))),"")) | H18: =IF($A18="","",IFERROR(IF(INDEX(출퇴근기록!$J$3:$J$3002,MATCH(1,INDEX((출퇴근기록!$A$3:$A$3002=DATE($F$3,$H$3,13))*(출퇴근기록!$B$3:$B$3002=$B$3),0),0))="","",INDEX(출퇴근기록!$J$3:$J$3002,MATCH(1,INDEX((출퇴근기록!$A$3:$A$3002=DATE($F$3,$H$3,13))*(출퇴근기록!$B$3:$B$3002=$B$3),0),0))),""))
A19: =IF(MONTH(DATE($F$3,$H$3,14))<>$H$3,"",14) -> 14 | B19: =IF($A19="","",CHOOSE(WEEKDAY(DATE($F$3,$H$3,14)),"일","월","화","수","목","금","토")) -> 월 | C19: =IF($A19="","",IFERROR(IF(INDEX(출퇴근기록!$E$3:$E$3002,MATCH(1,INDEX((출퇴근기록!$A$3:$A$3002=DATE($F$3,$H$3,14))*(출퇴근기록!$B$3:$B$3002=$B$3),0),0))="","",INDEX(출퇴근기록!$E$3:$E$3002,MATCH(1,INDEX((출퇴근기록!$A$3:$A$3002=DATE($F$3,$H$3,14))*(출퇴근기록!$B$3:$B$3002=$B$3),0),0))),"")) | D19: =IF($A19="","",IFERROR(IF(INDEX(출퇴근기록!$F$3:$F$3002,MATCH(1,INDEX((출퇴근기록!$A$3:$A$3002=DATE($F$3,$H$3,14))*(출퇴근기록!$B$3:$B$3002=$B$3),0),0))="","",INDEX(출퇴근기록!$F$3:$F$3002,MATCH(1,INDEX((출퇴근기록!$A$3:$A$3002=DATE($F$3,$H$3,14))*(출퇴근기록!$B$3:$B$3002=$B$3),0),0))),"")) | E19: =IF($A19="","",IFERROR(IF(INDEX(출퇴근기록!$G$3:$G$3002,MATCH(1,INDEX((출퇴근기록!$A$3:$A$3002=DATE($F$3,$H$3,14))*(출퇴근기록!$B$3:$B$3002=$B$3),0),0))="","",INDEX(출퇴근기록!$G$3:$G$3002,MATCH(1,INDEX((출퇴근기록!$A$3:$A$3002=DATE($F$3,$H$3,14))*(출퇴근기록!$B$3:$B$3002=$B$3),0),0))),"")) | F19: =IF($A19="","",IFERROR(IF(INDEX(출퇴근기록!$H$3:$H$3002,MATCH(1,INDEX((출퇴근기록!$A$3:$A$3002=DATE($F$3,$H$3,14))*(출퇴근기록!$B$3:$B$3002=$B$3),0),0))="","",INDEX(출퇴근기록!$H$3:$H$3002,MATCH(1,INDEX((출퇴근기록!$A$3:$A$3002=DATE($F$3,$H$3,14))*(출퇴근기록!$B$3:$B$3002=$B$3),0),0))),"")) | G19: =IF($A19="","",IFERROR(IF(INDEX(출퇴근기록!$I$3:$I$3002,MATCH(1,INDEX((출퇴근기록!$A$3:$A$3002=DATE($F$3,$H$3,14))*(출퇴근기록!$B$3:$B$3002=$B$3),0),0))="","",INDEX(출퇴근기록!$I$3:$I$3002,MATCH(1,INDEX((출퇴근기록!$A$3:$A$3002=DATE($F$3,$H$3,14))*(출퇴근기록!$B$3:$B$3002=$B$3),0),0))),"")) | H19: =IF($A19="","",IFERROR(IF(INDEX(출퇴근기록!$J$3:$J$3002,MATCH(1,INDEX((출퇴근기록!$A$3:$A$3002=DATE($F$3,$H$3,14))*(출퇴근기록!$B$3:$B$3002=$B$3),0),0))="","",INDEX(출퇴근기록!$J$3:$J$3002,MATCH(1,INDEX((출퇴근기록!$A$3:$A$3002=DATE($F$3,$H$3,14))*(출퇴근기록!$B$3:$B$3002=$B$3),0),0))),""))
A20: =IF(MONTH(DATE($F$3,$H$3,15))<>$H$3,"",15) -> 15 | B20: =IF($A20="","",CHOOSE(WEEKDAY(DATE($F$3,$H$3,15)),"일","월","화","수","목","금","토")) -> 화 | C20: =IF($A20="","",IFERROR(IF(INDEX(출퇴근기록!$E$3:$E$3002,MATCH(1,INDEX((출퇴근기록!$A$3:$A$3002=DATE($F$3,$H$3,15))*(출퇴근기록!$B$3:$B$3002=$B$3),0),0))="","",INDEX(출퇴근기록!$E$3:$E$3002,MATCH(1,INDEX((출퇴근기록!$A$3:$A$3002=DATE($F$3,$H$3,15))*(출퇴근기록!$B$3:$B$3002=$B$3),0),0))),"")) | D20: =IF($A20="","",IFERROR(IF(INDEX(출퇴근기록!$F$3:$F$3002,MATCH(1,INDEX((출퇴근기록!$A$3:$A$3002=DATE($F$3,$H$3,15))*(출퇴근기록!$B$3:$B$3002=$B$3),0),0))="","",INDEX(출퇴근기록!$F$3:$F$3002,MATCH(1,INDEX((출퇴근기록!$A$3:$A$3002=DATE($F$3,$H$3,15))*(출퇴근기록!$B$3:$B$3002=$B$3),0),0))),"")) | E20: =IF($A20="","",IFERROR(IF(INDEX(출퇴근기록!$G$3:$G$3002,MATCH(1,INDEX((출퇴근기록!$A$3:$A$3002=DATE($F$3,$H$3,15))*(출퇴근기록!$B$3:$B$3002=$B$3),0),0))="","",INDEX(출퇴근기록!$G$3:$G$3002,MATCH(1,INDEX((출퇴근기록!$A$3:$A$3002=DATE($F$3,$H$3,15))*(출퇴근기록!$B$3:$B$3002=$B$3),0),0))),"")) | F20: =IF($A20="","",IFERROR(IF(INDEX(출퇴근기록!$H$3:$H$3002,MATCH(1,INDEX((출퇴근기록!$A$3:$A$3002=DATE($F$3,$H$3,15))*(출퇴근기록!$B$3:$B$3002=$B$3),0),0))="","",INDEX(출퇴근기록!$H$3:$H$3002,MATCH(1,INDEX((출퇴근기록!$A$3:$A$3002=DATE($F$3,$H$3,15))*(출퇴근기록!$B$3:$B$3002=$B$3),0),0))),"")) | G20: =IF($A20="","",IFERROR(IF(INDEX(출퇴근기록!$I$3:$I$3002,MATCH(1,INDEX((출퇴근기록!$A$3:$A$3002=DATE($F$3,$H$3,15))*(출퇴근기록!$B$3:$B$3002=$B$3),0),0))="","",INDEX(출퇴근기록!$I$3:$I$3002,MATCH(1,INDEX((출퇴근기록!$A$3:$A$3002=DATE($F$3,$H$3,15))*(출퇴근기록!$B$3:$B$3002=$B$3),0),0))),"")) | H20: =IF($A20="","",IFERROR(IF(INDEX(출퇴근기록!$J$3:$J$3002,MATCH(1,INDEX((출퇴근기록!$A$3:$A$3002=DATE($F$3,$H$3,15))*(출퇴근기록!$B$3:$B$3002=$B$3),0),0))="","",INDEX(출퇴근기록!$J$3:$J$3002,MATCH(1,INDEX((출퇴근기록!$A$3:$A$3002=DATE($F$3,$H$3,15))*(출퇴근기록!$B$3:$B$3002=$B$3),0),0))),""))
