Workbook

Sheet 사용안내
B2: 회원 횟수권 차감관리
B4: 핵심 | C4: 횟수권을 팔고 쓸 때마다 기록하면 남은 횟수와 만료일이 자동으로 계산됩니다.
B5: 입력 규칙 | C5: 파란색 글씨 칸만 입력하세요. 검은색은 자동 계산입니다.
B6: ① 회원명부 | C6: 회원번호·이름·연락처를 등록합니다. 회원번호는 중복되면 안 됩니다.
B7: ② 상품목록 | C7: 판매하는 횟수권을 등록합니다. 예: 10회권 30일, 20회권 90일
B8: ③ 결제내역 | C8: 회원이 횟수권을 살 때마다 한 줄. 만료일이 자동으로 계산됩니다.
B9: ④ 사용내역 | C9: 회원이 이용할 때마다 한 줄. 1회 이용이면 수량 1을 넣으세요.
B10: ⑤ 회원현황 | C10: 회원별 총 충전·사용·잔여 횟수와 만료일이 나옵니다.
B11: ⑥ 만료임박 | C11: 만료가 가까운 회원만 모아서 보여줍니다. 재결제 안내용입니다.
B12: ⑦ 월별집계 | C12: 월별 결제액과 이용 건수가 나옵니다.
B13: 잔여 횟수 계산 | C13: 총 충전 횟수 − 총 사용 횟수
B14: 어디에 쓰나 | C14: PT·필라테스·학원·세차·네일·스터디카페·장비대여 등 횟수권을 파는 모든 업종
B16: 설정 | C16: 값을 바꾸면 모든 계산에 반영됩니다
B17: 만료 경고 기준(일) | C17: 7
B18: 잔여 경고 기준(회) | C18: 2
B20: ※ 이 파일은 회원 500명, 결제 1,000건, 사용 3,000건까지 처리하도록 만들어졌습니다.

Sheet 회원명부
A1: 회원명부 (회원번호는 중복되면 안 됩니다)
A2: 회원번호 | B2: 이름 | C2: 연락처 | D2: 가입일 | E2: 구분 | F2: 비고
A3: 1001 | B3: 김회원 | C3: 010-0000-0001 | D3: 46027 | E3: 일반 | F3: ← 예시 행입니다. 지우고 쓰세요.
A4: 1002 | B4: 이회원 | C4: 010-0000-0002 | D4: 46063 | E4: 일반
A5: 1003 | B5: 박회원 | C5: 010-0000-0003 | D5: 46083 | E5: VIP

Sheet 상품목록
A1: 상품목록 (판매하는 횟수권)
A2: 상품명 | B2: 횟수 | C2: 유효기간(일) | D2: 판매가 | E2: 비고
A3: 10회권 | B3: 10 | C3: 60 | D3: 300000
A4: 20회권 | B4: 20 | C4: 120 | D4: 560000
A5: 30회권 | B5: 30 | C5: 180 | D5: 780000
A6: 1회 이용권 | B6: 1 | C6: 30 | D6: 35000

Sheet 결제내역
A1: 결제내역 (횟수권을 팔 때마다 한 줄)
A2: 결제일 | B2: 회원번호 | C2: 이름(자동) | D2: 상품명 | E2: 충전횟수(자동) | F2: 유효기간(자동) | G2: 만료일(자동) | H2: 결제금액(자동) | I2: 결제수단 | J2: 환불 | K2: 비고
A3: 46209 | B3: 1001 | C3: =IF($B3="","",IFERROR(INDEX(회원명부!$B$3:$B$502,MATCH($B3,회원명부!$A$3:$A$502,0)),"미등록회원")) -> 김회원 | D3: 20회권 | E3: =IF($D3="","",IF($J3="환불",0,IFERROR(INDEX(상품목록!$B$3:$B$102,MATCH($D3,상품목록!$A$3:$A$102,0)),0))) -> 20 | F3: =IF($D3="","",IFERROR(INDEX(상품목록!$C$3:$C$102,MATCH($D3,상품목록!$A$3:$A$102,0)),0)) -> 120 | G3: =IF(OR($A3="",$F3=""),"",$A3+$F3) -> 46329 | H3: =IF($D3="","",IF($J3="환불",0,IFERROR(INDEX(상품목록!$D$3:$D$102,MATCH($D3,상품목록!$A$3:$A$102,0)),0))) -> 560000 | I3: 카드 | K3: ← 예시 행입니다. 지우고 쓰세요.
A4: 46237 | B4: 1002 | C4: =IF($B4="","",IFERROR(INDEX(회원명부!$B$3:$B$502,MATCH($B4,회원명부!$A$3:$A$502,0)),"미등록회원")) -> 이회원 | D4: 10회권 | E4: =IF($D4="","",IF($J4="환불",0,IFERROR(INDEX(상품목록!$B$3:$B$102,MATCH($D4,상품목록!$A$3:$A$102,0)),0))) -> 10 | F4: =IF($D4="","",IFERROR(INDEX(상품목록!$C$3:$C$102,MATCH($D4,상품목록!$A$3:$A$102,0)),0)) -> 60 | G4: =IF(OR($A4="",$F4=""),"",$A4+$F4) -> 46297 | H4: =IF($D4="","",IF($J4="환불",0,IFERROR(INDEX(상품목록!$D$3:$D$102,MATCH($D4,상품목록!$A$3:$A$102,0)),0))) -> 300000 | I4: 계좌이체
A5: 46254 | B5: 1003 | C5: =IF($B5="","",IFERROR(INDEX(회원명부!$B$3:$B$502,MATCH($B5,회원명부!$A$3:$A$502,0)),"미등록회원")) -> 박회원 | D5: 30회권 | E5: =IF($D5="","",IF($J5="환불",0,IFERROR(INDEX(상품목록!$B$3:$B$102,MATCH($D5,상품목록!$A$3:$A$102,0)),0))) -> 30 | F5: =IF($D5="","",IFERROR(INDEX(상품목록!$C$3:$C$102,MATCH($D5,상품목록!$A$3:$A$102,0)),0)) -> 180 | G5: =IF(OR($A5="",$F5=""),"",$A5+$F5) -> 46434 | H5: =IF($D5="","",IF($J5="환불",0,IFERROR(INDEX(상품목록!$D$3:$D$102,MATCH($D5,상품목록!$A$3:$A$102,0)),0))) -> 780000 | I5: 카드
A6: 46266 | B6: 1001 | C6: =IF($B6="","",IFERROR(INDEX(회원명부!$B$3:$B$502,MATCH($B6,회원명부!$A$3:$A$502,0)),"미등록회원")) -> 김회원 | D6: 1회 이용권 | E6: =IF($D6="","",IF($J6="환불",0,IFERROR(INDEX(상품목록!$B$3:$B$102,MATCH($D6,상품목록!$A$3:$A$102,0)),0))) -> 1 | F6: =IF($D6="","",IFERROR(INDEX(상품목록!$C$3:$C$102,MATCH($D6,상품목록!$A$3:$A$102,0)),0)) -> 30 | G6: =IF(OR($A6="",$F6=""),"",$A6+$F6) -> 46296 | H6: =IF($D6="","",IF($J6="환불",0,IFERROR(INDEX(상품목록!$D$3:$D$102,MATCH($D6,상품목록!$A$3:$A$102,0)),0))) -> 35000 | I6: 현금
C7: =IF($B7="","",IFERROR(INDEX(회원명부!$B$3:$B$502,MATCH($B7,회원명부!$A$3:$A$502,0)),"미등록회원")) | E7: =IF($D7="","",IF($J7="환불",0,IFERROR(INDEX(상품목록!$B$3:$B$102,MATCH($D7,상품목록!$A$3:$A$102,0)),0))) | F7: =IF($D7="","",IFERROR(INDEX(상품목록!$C$3:$C$102,MATCH($D7,상품목록!$A$3:$A$102,0)),0)) | G7: =IF(OR($A7="",$F7=""),"",$A7+$F7) | H7: =IF($D7="","",IF($J7="환불",0,IFERROR(INDEX(상품목록!$D$3:$D$102,MATCH($D7,상품목록!$A$3:$A$102,0)),0)))
C8: =IF($B8="","",IFERROR(INDEX(회원명부!$B$3:$B$502,MATCH($B8,회원명부!$A$3:$A$502,0)),"미등록회원")) | E8: =IF($D8="","",IF($J8="환불",0,IFERROR(INDEX(상품목록!$B$3:$B$102,MATCH($D8,상품목록!$A$3:$A$102,0)),0))) | F8: =IF($D8="","",IFERROR(INDEX(상품목록!$C$3:$C$102,MATCH($D8,상품목록!$A$3:$A$102,0)),0)) | G8: =IF(OR($A8="",$F8=""),"",$A8+$F8) | H8: =IF($D8="","",IF($J8="환불",0,IFERROR(INDEX(상품목록!$D$3:$D$102,MATCH($D8,상품목록!$A$3:$A$102,0)),0)))
C9: =IF($B9="","",IFERROR(INDEX(회원명부!$B$3:$B$502,MATCH($B9,회원명부!$A$3:$A$502,0)),"미등록회원")) | E9: =IF($D9="","",IF($J9="환불",0,IFERROR(INDEX(상품목록!$B$3:$B$102,MATCH($D9,상품목록!$A$3:$A$102,0)),0))) | F9: =IF($D9="","",IFERROR(INDEX(상품목록!$C$3:$C$102,MATCH($D9,상품목록!$A$3:$A$102,0)),0)) | G9: =IF(OR($A9="",$F9=""),"",$A9+$F9) | H9: =IF($D9="","",IF($J9="환불",0,IFERROR(INDEX(상품목록!$D$3:$D$102,MATCH($D9,상품목록!$A$3:$A$102,0)),0)))
C10: =IF($B10="","",IFERROR(INDEX(회원명부!$B$3:$B$502,MATCH($B10,회원명부!$A$3:$A$502,0)),"미등록회원")) | E10: =IF($D10="","",IF($J10="환불",0,IFERROR(INDEX(상품목록!$B$3:$B$102,MATCH($D10,상품목록!$A$3:$A$102,0)),0))) | F10: =IF($D10="","",IFERROR(INDEX(상품목록!$C$3:$C$102,MATCH($D10,상품목록!$A$3:$A$102,0)),0)) | G10: =IF(OR($A10="",$F10=""),"",$A10+$F10) | H10: =IF($D10="","",IF($J10="환불",0,IFERROR(INDEX(상품목록!$D$3:$D$102,MATCH($D10,상품목록!$A$3:$A$102,0)),0)))
C11: =IF($B11="","",IFERROR(INDEX(회원명부!$B$3:$B$502,MATCH($B11,회원명부!$A$3:$A$502,0)),"미등록회원")) | E11: =IF($D11="","",IF($J11="환불",0,IFERROR(INDEX(상품목록!$B$3:$B$102,MATCH($D11,상품목록!$A$3:$A$102,0)),0))) | F11: =IF($D11="","",IFERROR(INDEX(상품목록!$C$3:$C$102,MATCH($D11,상품목록!$A$3:$A$102,0)),0)) | G11: =IF(OR($A11="",$F11=""),"",$A11+$F11) | H11: =IF($D11="","",IF($J11="환불",0,IFERROR(INDEX(상품목록!$D$3:$D$102,MATCH($D11,상품목록!$A$3:$A$102,0)),0)))
C12: =IF($B12="","",IFERROR(INDEX(회원명부!$B$3:$B$502,MATCH($B12,회원명부!$A$3:$A$502,0)),"미등록회원")) | E12: =IF($D12="","",IF($J12="환불",0,IFERROR(INDEX(상품목록!$B$3:$B$102,MATCH($D12,상품목록!$A$3:$A$102,0)),0))) | F12: =IF($D12="","",IFERROR(INDEX(상품목록!$C$3:$C$102,MATCH($D12,상품목록!$A$3:$A$102,0)),0)) | G12: =IF(OR($A12="",$F12=""),"",$A12+$F12) | H12: =IF($D12="","",IF($J12="환불",0,IFERROR(INDEX(상품목록!$D$3:$D$102,MATCH($D12,상품목록!$A$3:$A$102,0)),0)))
C13: =IF($B13="","",IFERROR(INDEX(회원명부!$B$3:$B$502,MATCH($B13,회원명부!$A$3:$A$502,0)),"미등록회원")) | E13: =IF($D13="","",IF($J13="환불",0,IFERROR(INDEX(상품목록!$B$3:$B$102,MATCH($D13,상품목록!$A$3:$A$102,0)),0))) | F13: =IF($D13="","",IFERROR(INDEX(상품목록!$C$3:$C$102,MATCH($D13,상품목록!$A$3:$A$102,0)),0)) | G13: =IF(OR($A13="",$F13=""),"",$A13+$F13) | H13: =IF($D13="","",IF($J13="환불",0,IFERROR(INDEX(상품목록!$D$3:$D$102,MATCH($D13,상품목록!$A$3:$A$102,0)),0)))
C14: =IF($B14="","",IFERROR(INDEX(회원명부!$B$3:$B$502,MATCH($B14,회원명부!$A$3:$A$502,0)),"미등록회원")) | E14: =IF($D14="","",IF($J14="환불",0,IFERROR(INDEX(상품목록!$B$3:$B$102,MATCH($D14,상품목록!$A$3:$A$102,0)),0))) | F14: =IF($D14="","",IFERROR(INDEX(상품목록!$C$3:$C$102,MATCH($D14,상품목록!$A$3:$A$102,0)),0)) | G14: =IF(OR($A14="",$F14=""),"",$A14+$F14) | H14: =IF($D14="","",IF($J14="환불",0,IFERROR(INDEX(상품목록!$D$3:$D$102,MATCH($D14,상품목록!$A$3:$A$102,0)),0)))
C15: =IF($B15="","",IFERROR(INDEX(회원명부!$B$3:$B$502,MATCH($B15,회원명부!$A$3:$A$502,0)),"미등록회원")) | E15: =IF($D15="","",IF($J15="환불",0,IFERROR(INDEX(상품목록!$B$3:$B$102,MATCH($D15,상품목록!$A$3:$A$102,0)),0))) | F15: =IF($D15="","",IFERROR(INDEX(상품목록!$C$3:$C$102,MATCH($D15,상품목록!$A$3:$A$102,0)),0)) | G15: =IF(OR($A15="",$F15=""),"",$A15+$F15) | H15: =IF($D15="","",IF($J15="환불",0,IFERROR(INDEX(상품목록!$D$3:$D$102,MATCH($D15,상품목록!$A$3:$A$102,0)),0)))
C16: =IF($B16="","",IFERROR(INDEX(회원명부!$B$3:$B$502,MATCH($B16,회원명부!$A$3:$A$502,0)),"미등록회원")) | E16: =IF($D16="","",IF($J16="환불",0,IFERROR(INDEX(상품목록!$B$3:$B$102,MATCH($D16,상품목록!$A$3:$A$102,0)),0))) | F16: =IF($D16="","",IFERROR(INDEX(상품목록!$C$3:$C$102,MATCH($D16,상품목록!$A$3:$A$102,0)),0)) | G16: =IF(OR($A16="",$F16=""),"",$A16+$F16) | H16: =IF($D16="","",IF($J16="환불",0,IFERROR(INDEX(상품목록!$D$3:$D$102,MATCH($D16,상품목록!$A$3:$A$102,0)),0)))
C17: =IF($B17="","",IFERROR(INDEX(회원명부!$B$3:$B$502,MATCH($B17,회원명부!$A$3:$A$502,0)),"미등록회원")) | E17: =IF($D17="","",IF($J17="환불",0,IFERROR(INDEX(상품목록!$B$3:$B$102,MATCH($D17,상품목록!$A$3:$A$102,0)),0))) | F17: =IF($D17="","",IFERROR(INDEX(상품목록!$C$3:$C$102,MATCH($D17,상품목록!$A$3:$A$102,0)),0)) | G17: =IF(OR($A17="",$F17=""),"",$A17+$F17) | H17: =IF($D17="","",IF($J17="환불",0,IFERROR(INDEX(상품목록!$D$3:$D$102,MATCH($D17,상품목록!$A$3:$A$102,0)),0)))
C18: =IF($B18="","",IFERROR(INDEX(회원명부!$B$3:$B$502,MATCH($B18,회원명부!$A$3:$A$502,0)),"미등록회원")) | E18: =IF($D18="","",IF($J18="환불",0,IFERROR(INDEX(상품목록!$B$3:$B$102,MATCH($D18,상품목록!$A$3:$A$102,0)),0))) | F18: =IF($D18="","",IFERROR(INDEX(상품목록!$C$3:$C$102,MATCH($D18,상품목록!$A$3:$A$102,0)),0)) | G18: =IF(OR($A18="",$F18=""),"",$A18+$F18) | H18: =IF($D18="","",IF($J18="환불",0,IFERROR(INDEX(상품목록!$D$3:$D$102,MATCH($D18,상품목록!$A$3:$A$102,0)),0)))
... C1002: =IF($B1002="","",IFERROR(INDEX(회원명부!$B$3:$B$502,MATCH($B1002,회원명부!$A$3:$A$502,0)),"미등록회원")) | E1002: =IF($D1002="","",IF($J1002="환불",0,IFERROR(INDEX(상품목록!$B$3:$B$102,MATCH($D1002,상품목록!$A$3:$A$102,0)),0))) | F1002: =IF($D1002="","",IFERROR(INDEX(상품목록!$C$3:$C$102,MATCH($D1002,상품목록!$A$3:$A$102,0)),0)) | G1002: =IF(OR($A1002="",$F1002=""),"",$A1002+$F1002) | H1002: =IF($D1002="","",IF($J1002="환불",0,IFERROR(INDEX(상품목록!$D$3:$D$102,MATCH($D1002,상품목록!$A$3:$A$102,0)),0)))
A1004: ※ 환불한 건은 [환불] 칸에 '환불'을 넣으세요. 충전횟수와 결제금액이 0으로 처리됩니다.

Sheet 사용내역
A1: 사용내역 (회원이 이용할 때마다 한 줄)
A2: 이용일 | B2: 회원번호 | C2: 이름(자동) | D2: 차감횟수 | E2: 담당자 | F2: 이용내용 | G2: 비고
A3: 46213 | B3: 1001 | C3: =IF($B3="","",IFERROR(INDEX(회원명부!$B$3:$B$502,MATCH($B3,회원명부!$A$3:$A$502,0)),"미등록회원")) -> 김회원 | D3: 1 | E3: 김실장 | F3: PT 1회 | G3: ← 예시 행입니다. 지우고 쓰세요.
A4: 46220 | B4: 1001 | C4: =IF($B4="","",IFERROR(INDEX(회원명부!$B$3:$B$502,MATCH($B4,회원명부!$A$3:$A$502,0)),"미등록회원")) -> 김회원 | D4: 1 | E4: 김실장 | F4: PT 1회
A5: 46239 | B5: 1002 | C5: =IF($B5="","",IFERROR(INDEX(회원명부!$B$3:$B$502,MATCH($B5,회원명부!$A$3:$A$502,0)),"미등록회원")) -> 이회원 | D5: 1 | E5: 이실장 | F5: 필라테스
A6: 46246 | B6: 1002 | C6: =IF($B6="","",IFERROR(INDEX(회원명부!$B$3:$B$502,MATCH($B6,회원명부!$A$3:$A$502,0)),"미등록회원")) -> 이회원 | D6: 1 | E6: 이실장 | F6: 필라테스
A7: 46259 | B7: 1003 | C7: =IF($B7="","",IFERROR(INDEX(회원명부!$B$3:$B$502,MATCH($B7,회원명부!$A$3:$A$502,0)),"미등록회원")) -> 박회원 | D7: 2 | E7: 김실장 | F7: 개인 레슨 2회
A8: 46267 | B8: 1001 | C8: =IF($B8="","",IFERROR(INDEX(회원명부!$B$3:$B$502,MATCH($B8,회원명부!$A$3:$A$502,0)),"미등록회원")) -> 김회원 | D8: 1 | E8: 김실장 | F8: PT 1회
A9: 46272 | B9: 1002 | C9: =IF($B9="","",IFERROR(INDEX(회원명부!$B$3:$B$502,MATCH($B9,회원명부!$A$3:$A$502,0)),"미등록회원")) -> 이회원 | D9: 1 | E9: 이실장 | F9: 필라테스
A10: 46273 | B10: 1002 | C10: =IF($B10="","",IFERROR(INDEX(회원명부!$B$3:$B$502,MATCH($B10,회원명부!$A$3:$A$502,0)),"미등록회원")) -> 이회원 | D10: 1 | E10: 이실장 | F10: 필라테스
A11: 46274 | B11: 1002 | C11: =IF($B11="","",IFERROR(INDEX(회원명부!$B$3:$B$502,MATCH($B11,회원명부!$A$3:$A$502,0)),"미등록회원")) -> 이회원 | D11: 1 | E11: 이실장 | F11: 필라테스
A12: 46275 | B12: 1002 | C12: =IF($B12="","",IFERROR(INDEX(회원명부!$B$3:$B$502,MATCH($B12,회원명부!$A$3:$A$502,0)),"미등록회원")) -> 이회원 | D12: 1 | E12: 이실장 | F12: 필라테스
A13: 46276 | B13: 1002 | C13: =IF($B13="","",IFERROR(INDEX(회원명부!$B$3:$B$502,MATCH($B13,회원명부!$A$3:$A$502,0)),"미등록회원")) -> 이회원 | D13: 1 | E13: 이실장 | F13: 필라테스
A14: 46277 | B14: 1002 | C14: =IF($B14="","",IFERROR(INDEX(회원명부!$B$3:$B$502,MATCH($B14,회원명부!$A$3:$A$502,0)),"미등록회원")) -> 이회원 | D14: 1 | E14: 이실장 | F14: 필라테스
C15: =IF($B15="","",IFERROR(INDEX(회원명부!$B$3:$B$502,MATCH($B15,회원명부!$A$3:$A$502,0)),"미등록회원"))
C16: =IF($B16="","",IFERROR(INDEX(회원명부!$B$3:$B$502,MATCH($B16,회원명부!$A$3:$A$502,0)),"미등록회원"))
C17: =IF($B17="","",IFERROR(INDEX(회원명부!$B$3:$B$502,MATCH($B17,회원명부!$A$3:$A$502,0)),"미등록회원"))
C18: =IF($B18="","",IFERROR(INDEX(회원명부!$B$3:$B$502,MATCH($B18,회원명부!$A$3:$A$502,0)),"미등록회원"))
C19: =IF($B19="","",IFERROR(INDEX(회원명부!$B$3:$B$502,MATCH($B19,회원명부!$A$3:$A$502,0)),"미등록회원"))
C20: =IF($B20="","",IFERROR(INDEX(회원명부!$B$3:$B$502,MATCH($B20,회원명부!$A$3:$A$502,0)),"미등록회원"))
C21: =IF($B21="","",IFERROR(INDEX(회원명부!$B$3:$B$502,MATCH($B21,회원명부!$A$3:$A$502,0)),"미등록회원"))
C22: =IF($B22="","",IFERROR(INDEX(회원명부!$B$3:$B$502,MATCH($B22,회원명부!$A$3:$A$502,0)),"미등록회원"))
C23: =IF($B23="","",IFERROR(INDEX(회원명부!$B$3:$B$502,MATCH($B23,회원명부!$A$3:$A$502,0)),"미등록회원"))
C24: =IF($B24="","",IFERROR(INDEX(회원명부!$B$3:$B$502,MATCH($B24,회원명부!$A$3:$A$502,0)),"미등록회원"))
C25: =IF($B25="","",IFERROR(INDEX(회원명부!$B$3:$B$502,MATCH($B25,회원명부!$A$3:$A$502,0)),"미등록회원"))
C26: =IF($B26="","",IFERROR(INDEX(회원명부!$B$3:$B$502,MATCH($B26,회원명부!$A$3:$A$502,0)),"미등록회원"))
... C3002: =IF($B3002="","",IFERROR(INDEX(회원명부!$B$3:$B$502,MATCH($B3002,회원명부!$A$3:$A$502,0)),"미등록회원"))
A3004: ※ 1회 이용이면 차감횟수에 1을 넣으세요. 2회분을 한 번에 쓰면 2를 넣습니다.

Sheet 회원현황
A1: 회원현황 (전부 자동)
A3: 오늘 | B3: =TODAY() -> 46279 | D3: 잔여 부족 회원 | E3: =SUMPRODUCT(($A$6:$A$505<>"")*($F$6:$F$505>0)*($F$6:$F$505<=사용안내!$C$18)) -> 1 | G3: 만료 임박 회원 | H3: =SUMPRODUCT(($A$6:$A$505<>"")*($H$6:$H$505<>"")*($H$6:$H$505>=0)*($H$6:$H$505<=사용안내!$C$17)) -> 0
A5: 회원번호 | B5: 이름 | C5: 연락처 | D5: 총 충전 | E5: 총 사용 | F5: 잔여 횟수 | G5: 최종 만료일 | H5: D-Day | I5: 총 결제금액 | J5: 상태
A6: =IF(회원명부!$A3="","",회원명부!$A3) -> 1001 | B6: =IF($A6="","",회원명부!$B3) -> 김회원 | C6: =IF($A6="","",회원명부!$C3) -> 010-0000-0001 | D6: =IF($A6="","",SUMIFS(결제내역!$E$3:$E$1002,결제내역!$B$3:$B$1002,$A6)) -> 21 | E6: =IF($A6="","",SUMIFS(사용내역!$D$3:$D$3002,사용내역!$B$3:$B$3002,$A6)) -> 3 | F6: =IF($A6="","",$D6-$E6) -> 18 | G6: =IF($A6="","",IF(COUNTIFS(결제내역!$B$3:$B$1002,$A6)=0,"",_xlfn.MAXIFS(결제내역!$G$3:$G$1002,결제내역!$B$3:$B$1002,$A6))) -> 46329 | H6: =IF(OR($A6="",$G6=""),"",$G6-TODAY()) -> 50 | I6: =IF($A6="","",SUMIFS(결제내역!$H$3:$H$1002,결제내역!$B$3:$B$1002,$A6)) -> 595000 | J6: =IF($A6="","",IF($D6=0,"미결제",IF($F6<=0,"횟수소진",IF($H6="","",IF($H6<0,"기간만료",IF(OR($F6<=사용안내!$C$18,$H6<=사용안내!$C$17),"재결제 안내","정상")))))) -> 정상
A7: =IF(회원명부!$A4="","",회원명부!$A4) -> 1002 | B7: =IF($A7="","",회원명부!$B4) -> 이회원 | C7: =IF($A7="","",회원명부!$C4) -> 010-0000-0002 | D7: =IF($A7="","",SUMIFS(결제내역!$E$3:$E$1002,결제내역!$B$3:$B$1002,$A7)) -> 10 | E7: =IF($A7="","",SUMIFS(사용내역!$D$3:$D$3002,사용내역!$B$3:$B$3002,$A7)) -> 8 | F7: =IF($A7="","",$D7-$E7) -> 2 | G7: =IF($A7="","",IF(COUNTIFS(결제내역!$B$3:$B$1002,$A7)=0,"",_xlfn.MAXIFS(결제내역!$G$3:$G$1002,결제내역!$B$3:$B$1002,$A7))) -> 46297 | H7: =IF(OR($A7="",$G7=""),"",$G7-TODAY()) -> 18 | I7: =IF($A7="","",SUMIFS(결제내역!$H$3:$H$1002,결제내역!$B$3:$B$1002,$A7)) -> 300000 | J7: =IF($A7="","",IF($D7=0,"미결제",IF($F7<=0,"횟수소진",IF($H7="","",IF($H7<0,"기간만료",IF(OR($F7<=사용안내!$C$18,$H7<=사용안내!$C$17),"재결제 안내","정상")))))) -> 재결제 안내
A8: =IF(회원명부!$A5="","",회원명부!$A5) -> 1003 | B8: =IF($A8="","",회원명부!$B5) -> 박회원 | C8: =IF($A8="","",회원명부!$C5) -> 010-0000-0003 | D8: =IF($A8="","",SUMIFS(결제내역!$E$3:$E$1002,결제내역!$B$3:$B$1002,$A8)) -> 30 | E8: =IF($A8="","",SUMIFS(사용내역!$D$3:$D$3002,사용내역!$B$3:$B$3002,$A8)) -> 2 | F8: =IF($A8="","",$D8-$E8) -> 28 | G8: =IF($A8="","",IF(COUNTIFS(결제내역!$B$3:$B$1002,$A8)=0,"",_xlfn.MAXIFS(결제내역!$G$3:$G$1002,결제내역!$B$3:$B$1002,$A8))) -> 46434 | H8: =IF(OR($A8="",$G8=""),"",$G8-TODAY()) -> 155 | I8: =IF($A8="","",SUMIFS(결제내역!$H$3:$H$1002,결제내역!$B$3:$B$1002,$A8)) -> 780000 | J8: =IF($A8="","",IF($D8=0,"미결제",IF($F8<=0,"횟수소진",IF($H8="","",IF($H8<0,"기간만료",IF(OR($F8<=사용안내!$C$18,$H8<=사용안내!$C$17),"재결제 안내","정상")))))) -> 정상
A9: =IF(회원명부!$A6="","",회원명부!$A6) | B9: =IF($A9="","",회원명부!$B6) | C9: =IF($A9="","",회원명부!$C6) | D9: =IF($A9="","",SUMIFS(결제내역!$E$3:$E$1002,결제내역!$B$3:$B$1002,$A9)) | E9: =IF($A9="","",SUMIFS(사용내역!$D$3:$D$3002,사용내역!$B$3:$B$3002,$A9)) | F9: =IF($A9="","",$D9-$E9) | G9: =IF($A9="","",IF(COUNTIFS(결제내역!$B$3:$B$1002,$A9)=0,"",_xlfn.MAXIFS(결제내역!$G$3:$G$1002,결제내역!$B$3:$B$1002,$A9))) | H9: =IF(OR($A9="",$G9=""),"",$G9-TODAY()) | I9: =IF($A9="","",SUMIFS(결제내역!$H$3:$H$1002,결제내역!$B$3:$B$1002,$A9)) | J9: =IF($A9="","",IF($D9=0,"미결제",IF($F9<=0,"횟수소진",IF($H9="","",IF($H9<0,"기간만료",IF(OR($F9<=사용안내!$C$18,$H9<=사용안내!$C$17),"재결제 안내","정상"))))))
A10: =IF(회원명부!$A7="","",회원명부!$A7) | B10: =IF($A10="","",회원명부!$B7) | C10: =IF($A10="","",회원명부!$C7) | D10: =IF($A10="","",SUMIFS(결제내역!$E$3:$E$1002,결제내역!$B$3:$B$1002,$A10)) | E10: =IF($A10="","",SUMIFS(사용내역!$D$3:$D$3002,사용내역!$B$3:$B$3002,$A10)) | F10: =IF($A10="","",$D10-$E10) | G10: =IF($A10="","",IF(COUNTIFS(결제내역!$B$3:$B$1002,$A10)=0,"",_xlfn.MAXIFS(결제내역!$G$3:$G$1002,결제내역!$B$3:$B$1002,$A10))) | H10: =IF(OR($A10="",$G10=""),"",$G10-TODAY()) | I10: =IF($A10="","",SUMIFS(결제내역!$H$3:$H$1002,결제내역!$B$3:$B$1002,$A10)) | J10: =IF($A10="","",IF($D10=0,"미결제",IF($F10<=0,"횟수소진",IF($H10="","",IF($H10<0,"기간만료",IF(OR($F10<=사용안내!$C$18,$H10<=사용안내!$C$17),"재결제 안내","정상"))))))
A11: =IF(회원명부!$A8="","",회원명부!$A8) | B11: =IF($A11="","",회원명부!$B8) | C11: =IF($A11="","",회원명부!$C8) | D11: =IF($A11="","",SUMIFS(결제내역!$E$3:$E$1002,결제내역!$B$3:$B$1002,$A11)) | E11: =IF($A11="","",SUMIFS(사용내역!$D$3:$D$3002,사용내역!$B$3:$B$3002,$A11)) | F11: =IF($A11="","",$D11-$E11) | G11: =IF($A11="","",IF(COUNTIFS(결제내역!$B$3:$B$1002,$A11)=0,"",_xlfn.MAXIFS(결제내역!$G$3:$G$1002,결제내역!$B$3:$B$1002,$A11))) | H11: =IF(OR($A11="",$G11=""),"",$G11-TODAY()) | I11: =IF($A11="","",SUMIFS(결제내역!$H$3:$H$1002,결제내역!$B$3:$B$1002,$A11)) | J11: =IF($A11="","",IF($D11=0,"미결제",IF($F11<=0,"횟수소진",IF($H11="","",IF($H11<0,"기간만료",IF(OR($F11<=사용안내!$C$18,$H11<=사용안내!$C$17),"재결제 안내","정상"))))))
A12: =IF(회원명부!$A9="","",회원명부!$A9) | B12: =IF($A12="","",회원명부!$B9) | C12: =IF($A12="","",회원명부!$C9) | D12: =IF($A12="","",SUMIFS(결제내역!$E$3:$E$1002,결제내역!$B$3:$B$1002,$A12)) | E12: =IF($A12="","",SUMIFS(사용내역!$D$3:$D$3002,사용내역!$B$3:$B$3002,$A12)) | F12: =IF($A12="","",$D12-$E12) | G12: =IF($A12="","",IF(COUNTIFS(결제내역!$B$3:$B$1002,$A12)=0,"",_xlfn.MAXIFS(결제내역!$G$3:$G$1002,결제내역!$B$3:$B$1002,$A12))) | H12: =IF(OR($A12="",$G12=""),"",$G12-TODAY()) | I12: =IF($A12="","",SUMIFS(결제내역!$H$3:$H$1002,결제내역!$B$3:$B$1002,$A12)) | J12: =IF($A12="","",IF($D12=0,"미결제",IF($F12<=0,"횟수소진",IF($H12="","",IF($H12<0,"기간만료",IF(OR($F12<=사용안내!$C$18,$H12<=사용안내!$C$17),"재결제 안내","정상"))))))
A13: =IF(회원명부!$A10="","",회원명부!$A10) | B13: =IF($A13="","",회원명부!$B10) | C13: =IF($A13="","",회원명부!$C10) | D13: =IF($A13="","",SUMIFS(결제내역!$E$3:$E$1002,결제내역!$B$3:$B$1002,$A13)) | E13: =IF($A13="","",SUMIFS(사용내역!$D$3:$D$3002,사용내역!$B$3:$B$3002,$A13)) | F13: =IF($A13="","",$D13-$E13) | G13: =IF($A13="","",IF(COUNTIFS(결제내역!$B$3:$B$1002,$A13)=0,"",_xlfn.MAXIFS(결제내역!$G$3:$G$1002,결제내역!$B$3:$B$1002,$A13))) | H13: =IF(OR($A13="",$G13=""),"",$G13-TODAY()) | I13: =IF($A13="","",SUMIFS(결제내역!$H$3:$H$1002,결제내역!$B$3:$B$1002,$A13)) | J13: =IF($A13="","",IF($D13=0,"미결제",IF($F13<=0,"횟수소진",IF($H13="","",IF($H13<0,"기간만료",IF(OR($F13<=사용안내!$C$18,$H13<=사용안내!$C$17),"재결제 안내","정상"))))))
A14: =IF(회원명부!$A11="","",회원명부!$A11) | B14: =IF($A14="","",회원명부!$B11) | C14: =IF($A14="","",회원명부!$C11) | D14: =IF($A14="","",SUMIFS(결제내역!$E$3:$E$1002,결제내역!$B$3:$B$1002,$A14)) | E14: =IF($A14="","",SUMIFS(사용내역!$D$3:$D$3002,사용내역!$B$3:$B$3002,$A14)) | F14: =IF($A14="","",$D14-$E14) | G14: =IF($A14="","",IF(COUNTIFS(결제내역!$B$3:$B$1002,$A14)=0,"",_xlfn.MAXIFS(결제내역!$G$3:$G$1002,결제내역!$B$3:$B$1002,$A14))) | H14: =IF(OR($A14="",$G14=""),"",$G14-TODAY()) | I14: =IF($A14="","",SUMIFS(결제내역!$H$3:$H$1002,결제내역!$B$3:$B$1002,$A14)) | J14: =IF($A14="","",IF($D14=0,"미결제",IF($F14<=0,"횟수소진",IF($H14="","",IF($H14<0,"기간만료",IF(OR($F14<=사용안내!$C$18,$H14<=사용안내!$C$17),"재결제 안내","정상"))))))
A15: =IF(회원명부!$A12="","",회원명부!$A12) | B15: =IF($A15="","",회원명부!$B12) | C15: =IF($A15="","",회원명부!$C12) | D15: =IF($A15="","",SUMIFS(결제내역!$E$3:$E$1002,결제내역!$B$3:$B$1002,$A15)) | E15: =IF($A15="","",SUMIFS(사용내역!$D$3:$D$3002,사용내역!$B$3:$B$3002,$A15)) | F15: =IF($A15="","",$D15-$E15) | G15: =IF($A15="","",IF(COUNTIFS(결제내역!$B$3:$B$1002,$A15)=0,"",_xlfn.MAXIFS(결제내역!$G$3:$G$1002,결제내역!$B$3:$B$1002,$A15))) | H15: =IF(OR($A15="",$G15=""),"",$G15-TODAY()) | I15: =IF($A15="","",SUMIFS(결제내역!$H$3:$H$1002,결제내역!$B$3:$B$1002,$A15)) | J15: =IF($A15="","",IF($D15=0,"미결제",IF($F15<=0,"횟수소진",IF($H15="","",IF($H15<0,"기간만료",IF(OR($F15<=사용안내!$C$18,$H15<=사용안내!$C$17),"재결제 안내","정상"))))))
A16: =IF(회원명부!$A13="","",회원명부!$A13) | B16: =IF($A16="","",회원명부!$B13) | C16: =IF($A16="","",회원명부!$C13) | D16: =IF($A16="","",SUMIFS(결제내역!$E$3:$E$1002,결제내역!$B$3:$B$1002,$A16)) | E16: =IF($A16="","",SUMIFS(사용내역!$D$3:$D$3002,사용내역!$B$3:$B$3002,$A16)) | F16: =IF($A16="","",$D16-$E16) | G16: =IF($A16="","",IF(COUNTIFS(결제내역!$B$3:$B$1002,$A16)=0,"",_xlfn.MAXIFS(결제내역!$G$3:$G$1002,결제내역!$B$3:$B$1002,$A16))) | H16: =IF(OR($A16="",$G16=""),"",$G16-TODAY()) | I16: =IF($A16="","",SUMIFS(결제내역!$H$3:$H$1002,결제내역!$B$3:$B$1002,$A16)) | J16: =IF($A16="","",IF($D16=0,"미결제",IF($F16<=0,"횟수소진",IF($H16="","",IF($H16<0,"기간만료",IF(OR($F16<=사용안내!$C$18,$H16<=사용안내!$C$17),"재결제 안내","정상"))))))
A17: =IF(회원명부!$A14="","",회원명부!$A14) | B17: =IF($A17="","",회원명부!$B14) | C17: =IF($A17="","",회원명부!$C14) | D17: =IF($A17="","",SUMIFS(결제내역!$E$3:$E$1002,결제내역!$B$3:$B$1002,$A17)) | E17: =IF($A17="","",SUMIFS(사용내역!$D$3:$D$3002,사용내역!$B$3:$B$3002,$A17)) | F17: =IF($A17="","",$D17-$E17) | G17: =IF($A17="","",IF(COUNTIFS(결제내역!$B$3:$B$1002,$A17)=0,"",_xlfn.MAXIFS(결제내역!$G$3:$G$1002,결제내역!$B$3:$B$1002,$A17))) | H17: =IF(OR($A17="",$G17=""),"",$G17-TODAY()) | I17: =IF($A17="","",SUMIFS(결제내역!$H$3:$H$1002,결제내역!$B$3:$B$1002,$A17)) | J17: =IF($A17="","",IF($D17=0,"미결제",IF($F17<=0,"횟수소진",IF($H17="","",IF($H17<0,"기간만료",IF(OR($F17<=사용안내!$C$18,$H17<=사용안내!$C$17),"재결제 안내","정상"))))))
... A505: =IF(회원명부!$A502="","",회원명부!$A502) | B505: =IF($A505="","",회원명부!$B502) | C505: =IF($A505="","",회원명부!$C502) | D505: =IF($A505="","",SUMIFS(결제내역!$E$3:$E$1002,결제내역!$B$3:$B$1002,$A505)) | E505: =IF($A505="","",SUMIFS(사용내역!$D$3:$D$3002,사용내역!$B$3:$B$3002,$A505)) | F505: =IF($A505="","",$D505-$E505) | G505: =IF($A505="","",IF(COUNTIFS(결제내역!$B$3:$B$1002,$A505)=0,"",_xlfn.MAXIFS(결제내역!$G$3:$G$1002,결제내역!$B$3:$B$1002,$A505))) | H505: =IF(OR($A505="",$G505=""),"",$G505-TODAY()) | I505: =IF($A505="","",SUMIFS(결제내역!$H$3:$H$1002,결제내역!$B$3:$B$1002,$A505)) | J505: =IF($A505="","",IF($D505=0,"미결제",IF($F505<=0,"횟수소진",IF($H505="","",IF($H505<0,"기간만료",IF(OR($F505<=사용안내!$C$18,$H505<=사용안내!$C$17),"재결제 안내","정상"))))))
B507: 합계 | D507: =SUM(D6:D505) -> 61 | E507: =SUM(E6:E505) -> 13 | F507: =SUM(F6:F505) -> 48 | I507: =SUM(I6:I505) -> 1675000
A509: ※ 상태: 횟수소진·기간만료는 분홍, 재결제 안내는 노랑으로 표시됩니다.

Sheet 만료임박
A1: 만료임박 (재결제 안내용 명단)
A3: 표시 기준 | B3: ="잔여 "&사용안내!$C$18&"회 이하 또는 만료 "&사용안내!$C$17&"일 이내" -> 잔여 2회 이하 또는 만료 7일 이내 | E3: 해당 인원 | F3: =COUNTIF($H$6:$H$505,TRUE()) -> 1
A5: 순번 | B5: 회원번호 | C5: 이름 | D5: 연락처 | E5: 잔여 횟수 | F5: 만료일 | G5: D-Day | H5: 대상(자동) | I5: 순번(자동) | J5: 키(자동)
A6: 1 | B6: =IFERROR(INDEX(회원현황!$A$6:$A$505,MATCH("R"&1,만료임박!$J$6:$J$505,0)),"") -> 1002 | C6: =IF($B6="","",IFERROR(INDEX(회원현황!$B$6:$B$505,MATCH("R"&1,만료임박!$J$6:$J$505,0)),"")) -> 이회원 | D6: =IF($B6="","",IFERROR(INDEX(회원현황!$C$6:$C$505,MATCH("R"&1,만료임박!$J$6:$J$505,0)),"")) -> 010-0000-0002 | E6: =IF($B6="","",IFERROR(INDEX(회원현황!$F$6:$F$505,MATCH("R"&1,만료임박!$J$6:$J$505,0)),"")) -> 2 | F6: =IF($B6="","",IFERROR(INDEX(회원현황!$G$6:$G$505,MATCH("R"&1,만료임박!$J$6:$J$505,0)),"")) -> 46297 | G6: =IF($B6="","",IFERROR(INDEX(회원현황!$H$6:$H$505,MATCH("R"&1,만료임박!$J$6:$J$505,0)),"")) -> 18 | H6: =IF(회원현황!$A6="",FALSE(),OR(AND(회원현황!$F6>0,회원현황!$F6<=사용안내!$C$18),AND(회원현황!$H6<>"",회원현황!$H6>=0,회원현황!$H6<=사용안내!$C$17))) -> FALSE | I6: =IF($H6=FALSE(),"",COUNTIF($H$6:$H6,TRUE())) | J6: =IF($I6="","","R"&$I6)
A7: 2 | B7: =IFERROR(INDEX(회원현황!$A$6:$A$505,MATCH("R"&2,만료임박!$J$6:$J$505,0)),"") | C7: =IF($B7="","",IFERROR(INDEX(회원현황!$B$6:$B$505,MATCH("R"&2,만료임박!$J$6:$J$505,0)),"")) | D7: =IF($B7="","",IFERROR(INDEX(회원현황!$C$6:$C$505,MATCH("R"&2,만료임박!$J$6:$J$505,0)),"")) | E7: =IF($B7="","",IFERROR(INDEX(회원현황!$F$6:$F$505,MATCH("R"&2,만료임박!$J$6:$J$505,0)),"")) | F7: =IF($B7="","",IFERROR(INDEX(회원현황!$G$6:$G$505,MATCH("R"&2,만료임박!$J$6:$J$505,0)),"")) | G7: =IF($B7="","",IFERROR(INDEX(회원현황!$H$6:$H$505,MATCH("R"&2,만료임박!$J$6:$J$505,0)),"")) | H7: =IF(회원현황!$A7="",FALSE(),OR(AND(회원현황!$F7>0,회원현황!$F7<=사용안내!$C$18),AND(회원현황!$H7<>"",회원현황!$H7>=0,회원현황!$H7<=사용안내!$C$17))) -> TRUE | I7: =IF($H7=FALSE(),"",COUNTIF($H$6:$H7,TRUE())) -> 1 | J7: =IF($I7="","","R"&$I7) -> R1
A8: 3 | B8: =IFERROR(INDEX(회원현황!$A$6:$A$505,MATCH("R"&3,만료임박!$J$6:$J$505,0)),"") | C8: =IF($B8="","",IFERROR(INDEX(회원현황!$B$6:$B$505,MATCH("R"&3,만료임박!$J$6:$J$505,0)),"")) | D8: =IF($B8="","",IFERROR(INDEX(회원현황!$C$6:$C$505,MATCH("R"&3,만료임박!$J$6:$J$505,0)),"")) | E8: =IF($B8="","",IFERROR(INDEX(회원현황!$F$6:$F$505,MATCH("R"&3,만료임박!$J$6:$J$505,0)),"")) | F8: =IF($B8="","",IFERROR(INDEX(회원현황!$G$6:$G$505,MATCH("R"&3,만료임박!$J$6:$J$505,0)),"")) | G8: =IF($B8="","",IFERROR(INDEX(회원현황!$H$6:$H$505,MATCH("R"&3,만료임박!$J$6:$J$505,0)),"")) | H8: =IF(회원현황!$A8="",FALSE(),OR(AND(회원현황!$F8>0,회원현황!$F8<=사용안내!$C$18),AND(회원현황!$H8<>"",회원현황!$H8>=0,회원현황!$H8<=사용안내!$C$17))) -> FALSE | I8: =IF($H8=FALSE(),"",COUNTIF($H$6:$H8,TRUE())) | J8: =IF($I8="","","R"&$I8)
A9: 4 | B9: =IFERROR(INDEX(회원현황!$A$6:$A$505,MATCH("R"&4,만료임박!$J$6:$J$505,0)),"") | C9: =IF($B9="","",IFERROR(INDEX(회원현황!$B$6:$B$505,MATCH("R"&4,만료임박!$J$6:$J$505,0)),"")) | D9: =IF($B9="","",IFERROR(INDEX(회원현황!$C$6:$C$505,MATCH("R"&4,만료임박!$J$6:$J$505,0)),"")) | E9: =IF($B9="","",IFERROR(INDEX(회원현황!$F$6:$F$505,MATCH("R"&4,만료임박!$J$6:$J$505,0)),"")) | F9: =IF($B9="","",IFERROR(INDEX(회원현황!$G$6:$G$505,MATCH("R"&4,만료임박!$J$6:$J$505,0)),"")) | G9: =IF($B9="","",IFERROR(INDEX(회원현황!$H$6:$H$505,MATCH("R"&4,만료임박!$J$6:$J$505,0)),"")) | H9: =IF(회원현황!$A9="",FALSE(),OR(AND(회원현황!$F9>0,회원현황!$F9<=사용안내!$C$18),AND(회원현황!$H9<>"",회원현황!$H9>=0,회원현황!$H9<=사용안내!$C$17))) -> FALSE | I9: =IF($H9=FALSE(),"",COUNTIF($H$6:$H9,TRUE())) | J9: =IF($I9="","","R"&$I9)
A10: 5 | B10: =IFERROR(INDEX(회원현황!$A$6:$A$505,MATCH("R"&5,만료임박!$J$6:$J$505,0)),"") | C10: =IF($B10="","",IFERROR(INDEX(회원현황!$B$6:$B$505,MATCH("R"&5,만료임박!$J$6:$J$505,0)),"")) | D10: =IF($B10="","",IFERROR(INDEX(회원현황!$C$6:$C$505,MATCH("R"&5,만료임박!$J$6:$J$505,0)),"")) | E10: =IF($B10="","",IFERROR(INDEX(회원현황!$F$6:$F$505,MATCH("R"&5,만료임박!$J$6:$J$505,0)),"")) | F10: =IF($B10="","",IFERROR(INDEX(회원현황!$G$6:$G$505,MATCH("R"&5,만료임박!$J$6:$J$505,0)),"")) | G10: =IF($B10="","",IFERROR(INDEX(회원현황!$H$6:$H$505,MATCH("R"&5,만료임박!$J$6:$J$505,0)),"")) | H10: =IF(회원현황!$A10="",FALSE(),OR(AND(회원현황!$F10>0,회원현황!$F10<=사용안내!$C$18),AND(회원현황!$H10<>"",회원현황!$H10>=0,회원현황!$H10<=사용안내!$C$17))) -> FALSE | I10: =IF($H10=FALSE(),"",COUNTIF($H$6:$H10,TRUE())) | J10: =IF($I10="","","R"&$I10)
A11: 6 | B11: =IFERROR(INDEX(회원현황!$A$6:$A$505,MATCH("R"&6,만료임박!$J$6:$J$505,0)),"") | C11: =IF($B11="","",IFERROR(INDEX(회원현황!$B$6:$B$505,MATCH("R"&6,만료임박!$J$6:$J$505,0)),"")) | D11: =IF($B11="","",IFERROR(INDEX(회원현황!$C$6:$C$505,MATCH("R"&6,만료임박!$J$6:$J$505,0)),"")) | E11: =IF($B11="","",IFERROR(INDEX(회원현황!$F$6:$F$505,MATCH("R"&6,만료임박!$J$6:$J$505,0)),"")) | F11: =IF($B11="","",IFERROR(INDEX(회원현황!$G$6:$G$505,MATCH("R"&6,만료임박!$J$6:$J$505,0)),"")) | G11: =IF($B11="","",IFERROR(INDEX(회원현황!$H$6:$H$505,MATCH("R"&6,만료임박!$J$6:$J$505,0)),"")) | H11: =IF(회원현황!$A11="",FALSE(),OR(AND(회원현황!$F11>0,회원현황!$F11<=사용안내!$C$18),AND(회원현황!$H11<>"",회원현황!$H11>=0,회원현황!$H11<=사용안내!$C$17))) -> FALSE | I11: =IF($H11=FALSE(),"",COUNTIF($H$6:$H11,TRUE())) | J11: =IF($I11="","","R"&$I11)
A12: 7 | B12: =IFERROR(INDEX(회원현황!$A$6:$A$505,MATCH("R"&7,만료임박!$J$6:$J$505,0)),"") | C12: =IF($B12="","",IFERROR(INDEX(회원현황!$B$6:$B$505,MATCH("R"&7,만료임박!$J$6:$J$505,0)),"")) | D12: =IF($B12="","",IFERROR(INDEX(회원현황!$C$6:$C$505,MATCH("R"&7,만료임박!$J$6:$J$505,0)),"")) | E12: =IF($B12="","",IFERROR(INDEX(회원현황!$F$6:$F$505,MATCH("R"&7,만료임박!$J$6:$J$505,0)),"")) | F12: =IF($B12="","",IFERROR(INDEX(회원현황!$G$6:$G$505,MATCH("R"&7,만료임박!$J$6:$J$505,0)),"")) | G12: =IF($B12="","",IFERROR(INDEX(회원현황!$H$6:$H$505,MATCH("R"&7,만료임박!$J$6:$J$505,0)),"")) | H12: =IF(회원현황!$A12="",FALSE(),OR(AND(회원현황!$F12>0,회원현황!$F12<=사용안내!$C$18),AND(회원현황!$H12<>"",회원현황!$H12>=0,회원현황!$H12<=사용안내!$C$17))) -> FALSE | I12: =IF($H12=FALSE(),"",COUNTIF($H$6:$H12,TRUE())) | J12: =IF($I12="","","R"&$I12)
A13: 8 | B13: =IFERROR(INDEX(회원현황!$A$6:$A$505,MATCH("R"&8,만료임박!$J$6:$J$505,0)),"") | C13: =IF($B13="","",IFERROR(INDEX(회원현황!$B$6:$B$505,MATCH("R"&8,만료임박!$J$6:$J$505,0)),"")) | D13: =IF($B13="","",IFERROR(INDEX(회원현황!$C$6:$C$505,MATCH("R"&8,만료임박!$J$6:$J$505,0)),"")) | E13: =IF($B13="","",IFERROR(INDEX(회원현황!$F$6:$F$505,MATCH("R"&8,만료임박!$J$6:$J$505,0)),"")) | F13: =IF($B13="","",IFERROR(INDEX(회원현황!$G$6:$G$505,MATCH("R"&8,만료임박!$J$6:$J$505,0)),"")) | G13: =IF($B13="","",IFERROR(INDEX(회원현황!$H$6:$H$505,MATCH("R"&8,만료임박!$J$6:$J$505,0)),"")) | H13: =IF(회원현황!$A13="",FALSE(),OR(AND(회원현황!$F13>0,회원현황!$F13<=사용안내!$C$18),AND(회원현황!$H13<>"",회원현황!$H13>=0,회원현황!$H13<=사용안내!$C$17))) -> FALSE | I13: =IF($H13=FALSE(),"",COUNTIF($H$6:$H13,TRUE())) | J13: =IF($I13="","","R"&$I13)
A14: 9 | B14: =IFERROR(INDEX(회원현황!$A$6:$A$505,MATCH("R"&9,만료임박!$J$6:$J$505,0)),"") | C14: =IF($B14="","",IFERROR(INDEX(회원현황!$B$6:$B$505,MATCH("R"&9,만료임박!$J$6:$J$505,0)),"")) | D14: =IF($B14="","",IFERROR(INDEX(회원현황!$C$6:$C$505,MATCH("R"&9,만료임박!$J$6:$J$505,0)),"")) | E14: =IF($B14="","",IFERROR(INDEX(회원현황!$F$6:$F$505,MATCH("R"&9,만료임박!$J$6:$J$505,0)),"")) | F14: =IF($B14="","",IFERROR(INDEX(회원현황!$G$6:$G$505,MATCH("R"&9,만료임박!$J$6:$J$505,0)),"")) | G14: =IF($B14="","",IFERROR(INDEX(회원현황!$H$6:$H$505,MATCH("R"&9,만료임박!$J$6:$J$505,0)),"")) | H14: =IF(회원현황!$A14="",FALSE(),OR(AND(회원현황!$F14>0,회원현황!$F14<=사용안내!$C$18),AND(회원현황!$H14<>"",회원현황!$H14>=0,회원현황!$H14<=사용안내!$C$17))) -> FALSE | I14: =IF($H14=FALSE(),"",COUNTIF($H$6:$H14,TRUE())) | J14: =IF($I14="","","R"&$I14)
A15: 10 | B15: =IFERROR(INDEX(회원현황!$A$6:$A$505,MATCH("R"&10,만료임박!$J$6:$J$505,0)),"") | C15: =IF($B15="","",IFERROR(INDEX(회원현황!$B$6:$B$505,MATCH("R"&10,만료임박!$J$6:$J$505,0)),"")) | D15: =IF($B15="","",IFERROR(INDEX(회원현황!$C$6:$C$505,MATCH("R"&10,만료임박!$J$6:$J$505,0)),"")) | E15: =IF($B15="","",IFERROR(INDEX(회원현황!$F$6:$F$505,MATCH("R"&10,만료임박!$J$6:$J$505,0)),"")) | F15: =IF($B15="","",IFERROR(INDEX(회원현황!$G$6:$G$505,MATCH("R"&10,만료임박!$J$6:$J$505,0)),"")) | G15: =IF($B15="","",IFERROR(INDEX(회원현황!$H$6:$H$505,MATCH("R"&10,만료임박!$J$6:$J$505,0)),"")) | H15: =IF(회원현황!$A15="",FALSE(),OR(AND(회원현황!$F15>0,회원현황!$F15<=사용안내!$C$18),AND(회원현황!$H15<>"",회원현황!$H15>=0,회원현황!$H15<=사용안내!$C$17))) -> FALSE | I15: =IF($H15=FALSE(),"",COUNTIF($H$6:$H15,TRUE())) | J15: =IF($I15="","","R"&$I15)
A16: 11 | B16: =IFERROR(INDEX(회원현황!$A$6:$A$505,MATCH("R"&11,만료임박!$J$6:$J$505,0)),"") | C16: =IF($B16="","",IFERROR(INDEX(회원현황!$B$6:$B$505,MATCH("R"&11,만료임박!$J$6:$J$505,0)),"")) | D16: =IF($B16="","",IFERROR(INDEX(회원현황!$C$6:$C$505,MATCH("R"&11,만료임박!$J$6:$J$505,0)),"")) | E16: =IF($B16="","",IFERROR(INDEX(회원현황!$F$6:$F$505,MATCH("R"&11,만료임박!$J$6:$J$505,0)),"")) | F16: =IF($B16="","",IFERROR(INDEX(회원현황!$G$6:$G$505,MATCH("R"&11,만료임박!$J$6:$J$505,0)),"")) | G16: =IF($B16="","",IFERROR(INDEX(회원현황!$H$6:$H$505,MATCH("R"&11,만료임박!$J$6:$J$505,0)),"")) | H16: =IF(회원현황!$A16="",FALSE(),OR(AND(회원현황!$F16>0,회원현황!$F16<=사용안내!$C$18),AND(회원현황!$H16<>"",회원현황!$H16>=0,회원현황!$H16<=사용안내!$C$17))) -> FALSE | I16: =IF($H16=FALSE(),"",COUNTIF($H$6:$H16,TRUE())) | J16: =IF($I16="","","R"&$I16)
A17: 12 | B17: =IFERROR(INDEX(회원현황!$A$6:$A$505,MATCH("R"&12,만료임박!$J$6:$J$505,0)),"") | C17: =IF($B17="","",IFERROR(INDEX(회원현황!$B$6:$B$505,MATCH("R"&12,만료임박!$J$6:$J$505,0)),"")) | D17: =IF($B17="","",IFERROR(INDEX(회원현황!$C$6:$C$505,MATCH("R"&12,만료임박!$J$6:$J$505,0)),"")) | E17: =IF($B17="","",IFERROR(INDEX(회원현황!$F$6:$F$505,MATCH("R"&12,만료임박!$J$6:$J$505,0)),"")) | F17: =IF($B17="","",IFERROR(INDEX(회원현황!$G$6:$G$505,MATCH("R"&12,만료임박!$J$6:$J$505,0)),"")) | G17: =IF($B17="","",IFERROR(INDEX(회원현황!$H$6:$H$505,MATCH("R"&12,만료임박!$J$6:$J$505,0)),"")) | H17: =IF(회원현황!$A17="",FALSE(),OR(AND(회원현황!$F17>0,회원현황!$F17<=사용안내!$C$18),AND(회원현황!$H17<>"",회원현황!$H17>=0,회원현황!$H17<=사용안내!$C$17))) -> FALSE | I17: =IF($H17=FALSE(),"",COUNTIF($H$6:$H17,TRUE())) | J17: =IF($I17="","","R"&$I17)
A18: 13 | B18: =IFERROR(INDEX(회원현황!$A$6:$A$505,MATCH("R"&13,만료임박!$J$6:$J$505,0)),"") | C18: =IF($B18="","",IFERROR(INDEX(회원현황!$B$6:$B$505,MATCH("R"&13,만료임박!$J$6:$J$505,0)),"")) | D18: =IF($B18="","",IFERROR(INDEX(회원현황!$C$6:$C$505,MATCH("R"&13,만료임박!$J$6:$J$505,0)),"")) | E18: =IF($B18="","",IFERROR(INDEX(회원현황!$F$6:$F$505,MATCH("R"&13,만료임박!$J$6:$J$505,0)),"")) | F18: =IF($B18="","",IFERROR(INDEX(회원현황!$G$6:$G$505,MATCH("R"&13,만료임박!$J$6:$J$505,0)),"")) | G18: =IF($B18="","",IFERROR(INDEX(회원현황!$H$6:$H$505,MATCH("R"&13,만료임박!$J$6:$J$505,0)),"")) | H18: =IF(회원현황!$A18="",FALSE(),OR(AND(회원현황!$F18>0,회원현황!$F18<=사용안내!$C$18),AND(회원현황!$H18<>"",회원현황!$H18>=0,회원현황!$H18<=사용안내!$C$17))) -> FALSE | I18: =IF($H18=FALSE(),"",COUNTIF($H$6:$H18,TRUE())) | J18: =IF($I18="","","R"&$I18)
A19: 14 | B19: =IFERROR(INDEX(회원현황!$A$6:$A$505,MATCH("R"&14,만료임박!$J$6:$J$505,0)),"") | C19: =IF($B19="","",IFERROR(INDEX(회원현황!$B$6:$B$505,MATCH("R"&14,만료임박!$J$6:$J$505,0)),"")) | D19: =IF($B19="","",IFERROR(INDEX(회원현황!$C$6:$C$505,MATCH("R"&14,만료임박!$J$6:$J$505,0)),"")) | E19: =IF($B19="","",IFERROR(INDEX(회원현황!$F$6:$F$505,MATCH("R"&14,만료임박!$J$6:$J$505,0)),"")) | F19: =IF($B19="","",IFERROR(INDEX(회원현황!$G$6:$G$505,MATCH("R"&14,만료임박!$J$6:$J$505,0)),"")) | G19: =IF($B19="","",IFERROR(INDEX(회원현황!$H$6:$H$505,MATCH("R"&14,만료임박!$J$6:$J$505,0)),"")) | H19: =IF(회원현황!$A19="",FALSE(),OR(AND(회원현황!$F19>0,회원현황!$F19<=사용안내!$C$18),AND(회원현황!$H19<>"",회원현황!$H19>=0,회원현황!$H19<=사용안내!$C$17))) -> FALSE | I19: =IF($H19=FALSE(),"",COUNTIF($H$6:$H19,TRUE())) | J19: =IF($I19="","","R"&$I19)
A20: 15 | B20: =IFERROR(INDEX(회원현황!$A$6:$A$505,MATCH("R"&15,만료임박!$J$6:$J$505,0)),"") | C20: =IF($B20="","",IFERROR(INDEX(회원현황!$B$6:$B$505,MATCH("R"&15,만료임박!$J$6:$J$505,0)),"")) | D20: =IF($B20="","",IFERROR(INDEX(회원현황!$C$6:$C$505,MATCH("R"&15,만료임박!$J$6:$J$505,0)),"")) | E20: =IF($B20="","",IFERROR(INDEX(회원현황!$F$6:$F$505,MATCH("R"&15,만료임박!$J$6:$J$505,0)),"")) | F20: =IF($B20="","",IFERROR(INDEX(회원현황!$G$6:$G$505,MATCH("R"&15,만료임박!$J$6:$J$505,0)),"")) | G20: =IF($B20="","",IFERROR(INDEX(회원현황!$H$6:$H$505,MATCH("R"&15,만료임박!$J$6:$J$505,0)),"")) | H20: =IF(회원현황!$A20="",FALSE(),OR(AND(회원현황!$F20>0,회원현황!$F20<=사용안내!$C$18),AND(회원현황!$H20<>"",회원현황!$H20>=0,회원현황!$H20<=사용안내!$C$17))) -> FALSE | I20: =IF($H20=FALSE(),"",COUNTIF($H$6:$H20,TRUE())) | J20: =IF($I20="","","R"&$I20)
A21: 16 | B21: =IFERROR(INDEX(회원현황!$A$6:$A$505,MATCH("R"&16,만료임박!$J$6:$J$505,0)),"") | C21: =IF($B21="","",IFERROR(INDEX(회원현황!$B$6:$B$505,MATCH("R"&16,만료임박!$J$6:$J$505,0)),"")) | D21: =IF($B21="","",IFERROR(INDEX(회원현황!$C$6:$C$505,MATCH("R"&16,만료임박!$J$6:$J$505,0)),"")) | E21: =IF($B21="","",IFERROR(INDEX(회원현황!$F$6:$F$505,MATCH("R"&16,만료임박!$J$6:$J$505,0)),"")) | F21: =IF($B21="","",IFERROR(INDEX(회원현황!$G$6:$G$505,MATCH("R"&16,만료임박!$J$6:$J$505,0)),"")) | G21: =IF($B21="","",IFERROR(INDEX(회원현황!$H$6:$H$505,MATCH("R"&16,만료임박!$J$6:$J$505,0)),"")) | H21: =IF(회원현황!$A21="",FALSE(),OR(AND(회원현황!$F21>0,회원현황!$F21<=사용안내!$C$18),AND(회원현황!$H21<>"",회원현황!$H21>=0,회원현황!$H21<=사용안내!$C$17))) -> FALSE | I21: =IF($H21=FALSE(),"",COUNTIF($H$6:$H21,TRUE())) | J21: =IF($I21="","","R"&$I21)
A22: 17 | B22: =IFERROR(INDEX(회원현황!$A$6:$A$505,MATCH("R"&17,만료임박!$J$6:$J$505,0)),"") | C22: =IF($B22="","",IFERROR(INDEX(회원현황!$B$6:$B$505,MATCH("R"&17,만료임박!$J$6:$J$505,0)),"")) | D22: =IF($B22="","",IFERROR(INDEX(회원현황!$C$6:$C$505,MATCH("R"&17,만료임박!$J$6:$J$505,0)),"")) | E22: =IF($B22="","",IFERROR(INDEX(회원현황!$F$6:$F$505,MATCH("R"&17,만료임박!$J$6:$J$505,0)),"")) | F22: =IF($B22="","",IFERROR(INDEX(회원현황!$G$6:$G$505,MATCH("R"&17,만료임박!$J$6:$J$505,0)),"")) | G22: =IF($B22="","",IFERROR(INDEX(회원현황!$H$6:$H$505,MATCH("R"&17,만료임박!$J$6:$J$505,0)),"")) | H22: =IF(회원현황!$A22="",FALSE(),OR(AND(회원현황!$F22>0,회원현황!$F22<=사용안내!$C$18),AND(회원현황!$H22<>"",회원현황!$H22>=0,회원현황!$H22<=사용안내!$C$17))) -> FALSE | I22: =IF($H22=FALSE(),"",COUNTIF($H$6:$H22,TRUE())) | J22: =IF($I22="","","R"&$I22)
A23: 18 | B23: =IFERROR(INDEX(회원현황!$A$6:$A$505,MATCH("R"&18,만료임박!$J$6:$J$505,0)),"") | C23: =IF($B23="","",IFERROR(INDEX(회원현황!$B$6:$B$505,MATCH("R"&18,만료임박!$J$6:$J$505,0)),"")) | D23: =IF($B23="","",IFERROR(INDEX(회원현황!$C$6:$C$505,MATCH("R"&18,만료임박!$J$6:$J$505,0)),"")) | E23: =IF($B23="","",IFERROR(INDEX(회원현황!$F$6:$F$505,MATCH("R"&18,만료임박!$J$6:$J$505,0)),"")) | F23: =IF($B23="","",IFERROR(INDEX(회원현황!$G$6:$G$505,MATCH("R"&18,만료임박!$J$6:$J$505,0)),"")) | G23: =IF($B23="","",IFERROR(INDEX(회원현황!$H$6:$H$505,MATCH("R"&18,만료임박!$J$6:$J$505,0)),"")) | H23: =IF(회원현황!$A23="",FALSE(),OR(AND(회원현황!$F23>0,회원현황!$F23<=사용안내!$C$18),AND(회원현황!$H23<>"",회원현황!$H23>=0,회원현황!$H23<=사용안내!$C$17))) -> FALSE | I23: =IF($H23=FALSE(),"",COUNTIF($H$6:$H23,TRUE())) | J23: =IF($I23="","","R"&$I23)
A24: 19 | B24: =IFERROR(INDEX(회원현황!$A$6:$A$505,MATCH("R"&19,만료임박!$J$6:$J$505,0)),"") | C24: =IF($B24="","",IFERROR(INDEX(회원현황!$B$6:$B$505,MATCH("R"&19,만료임박!$J$6:$J$505,0)),"")) | D24: =IF($B24="","",IFERROR(INDEX(회원현황!$C$6:$C$505,MATCH("R"&19,만료임박!$J$6:$J$505,0)),"")) | E24: =IF($B24="","",IFERROR(INDEX(회원현황!$F$6:$F$505,MATCH("R"&19,만료임박!$J$6:$J$505,0)),"")) | F24: =IF($B24="","",IFERROR(INDEX(회원현황!$G$6:$G$505,MATCH("R"&19,만료임박!$J$6:$J$505,0)),"")) | G24: =IF($B24="","",IFERROR(INDEX(회원현황!$H$6:$H$505,MATCH("R"&19,만료임박!$J$6:$J$505,0)),"")) | H24: =IF(회원현황!$A24="",FALSE(),OR(AND(회원현황!$F24>0,회원현황!$F24<=사용안내!$C$18),AND(회원현황!$H24<>"",회원현황!$H24>=0,회원현황!$H24<=사용안내!$C$17))) -> FALSE | I24: =IF($H24=FALSE(),"",COUNTIF($H$6:$H24,TRUE())) | J24: =IF($I24="","","R"&$I24)
A25: 20 | B25: =IFERROR(INDEX(회원현황!$A$6:$A$505,MATCH("R"&20,만료임박!$J$6:$J$505,0)),"") | C25: =IF($B25="","",IFERROR(INDEX(회원현황!$B$6:$B$505,MATCH("R"&20,만료임박!$J$6:$J$505,0)),"")) | D25: =IF($B25="","",IFERROR(INDEX(회원현황!$C$6:$C$505,MATCH("R"&20,만료임박!$J$6:$J$505,0)),"")) | E25: =IF($B25="","",IFERROR(INDEX(회원현황!$F$6:$F$505,MATCH("R"&20,만료임박!$J$6:$J$505,0)),"")) | F25: =IF($B25="","",IFERROR(INDEX(회원현황!$G$6:$G$505,MATCH("R"&20,만료임박!$J$6:$J$505,0)),"")) | G25: =IF($B25="","",IFERROR(INDEX(회원현황!$H$6:$H$505,MATCH("R"&20,만료임박!$J$6:$J$505,0)),"")) | H25: =IF(회원현황!$A25="",FALSE(),OR(AND(회원현황!$F25>0,회원현황!$F25<=사용안내!$C$18),AND(회원현황!$H25<>"",회원현황!$H25>=0,회원현황!$H25<=사용안내!$C$17))) -> FALSE | I25: =IF($H25=FALSE(),"",COUNTIF($H$6:$H25,TRUE())) | J25: =IF($I25="","","R"&$I25)
A26: 21 | B26: =IFERROR(INDEX(회원현황!$A$6:$A$505,MATCH("R"&21,만료임박!$J$6:$J$505,0)),"") | C26: =IF($B26="","",IFERROR(INDEX(회원현황!$B$6:$B$505,MATCH("R"&21,만료임박!$J$6:$J$505,0)),"")) | D26: =IF($B26="","",IFERROR(INDEX(회원현황!$C$6:$C$505,MATCH("R"&21,만료임박!$J$6:$J$505,0)),"")) | E26: =IF($B26="","",IFERROR(INDEX(회원현황!$F$6:$F$505,MATCH("R"&21,만료임박!$J$6:$J$505,0)),"")) | F26: =IF($B26="","",IFERROR(INDEX(회원현황!$G$6:$G$505,MATCH("R"&21,만료임박!$J$6:$J$505,0)),"")) | G26: =IF($B26="","",IFERROR(INDEX(회원현황!$H$6:$H$505,MATCH("R"&21,만료임박!$J$6:$J$505,0)),"")) | H26: =IF(회원현황!$A26="",FALSE(),OR(AND(회원현황!$F26>0,회원현황!$F26<=사용안내!$C$18),AND(회원현황!$H26<>"",회원현황!$H26>=0,회원현황!$H26<=사용안내!$C$17))) -> FALSE | I26: =IF($H26=FALSE(),"",COUNTIF($H$6:$H26,TRUE())) | J26: =IF($I26="","","R"&$I26)
A27: 22 | B27: =IFERROR(INDEX(회원현황!$A$6:$A$505,MATCH("R"&22,만료임박!$J$6:$J$505,0)),"") | C27: =IF($B27="","",IFERROR(INDEX(회원현황!$B$6:$B$505,MATCH("R"&22,만료임박!$J$6:$J$505,0)),"")) | D27: =IF($B27="","",IFERROR(INDEX(회원현황!$C$6:$C$505,MATCH("R"&22,만료임박!$J$6:$J$505,0)),"")) | E27: =IF($B27="","",IFERROR(INDEX(회원현황!$F$6:$F$505,MATCH("R"&22,만료임박!$J$6:$J$505,0)),"")) | F27: =IF($B27="","",IFERROR(INDEX(회원현황!$G$6:$G$505,MATCH("R"&22,만료임박!$J$6:$J$505,0)),"")) | G27: =IF($B27="","",IFERROR(INDEX(회원현황!$H$6:$H$505,MATCH("R"&22,만료임박!$J$6:$J$505,0)),"")) | H27: =IF(회원현황!$A27="",FALSE(),OR(AND(회원현황!$F27>0,회원현황!$F27<=사용안내!$C$18),AND(회원현황!$H27<>"",회원현황!$H27>=0,회원현황!$H27<=사용안내!$C$17))) -> FALSE | I27: =IF($H27=FALSE(),"",COUNTIF($H$6:$H27,TRUE())) | J27: =IF($I27="","","R"&$I27)
A28: 23 | B28: =IFERROR(INDEX(회원현황!$A$6:$A$505,MATCH("R"&23,만료임박!$J$6:$J$505,0)),"") | C28: =IF($B28="","",IFERROR(INDEX(회원현황!$B$6:$B$505,MATCH("R"&23,만료임박!$J$6:$J$505,0)),"")) | D28: =IF($B28="","",IFERROR(INDEX(회원현황!$C$6:$C$505,MATCH("R"&23,만료임박!$J$6:$J$505,0)),"")) | E28: =IF($B28="","",IFERROR(INDEX(회원현황!$F$6:$F$505,MATCH("R"&23,만료임박!$J$6:$J$505,0)),"")) | F28: =IF($B28="","",IFERROR(INDEX(회원현황!$G$6:$G$505,MATCH("R"&23,만료임박!$J$6:$J$505,0)),"")) | G28: =IF($B28="","",IFERROR(INDEX(회원현황!$H$6:$H$505,MATCH("R"&23,만료임박!$J$6:$J$505,0)),"")) | H28: =IF(회원현황!$A28="",FALSE(),OR(AND(회원현황!$F28>0,회원현황!$F28<=사용안내!$C$18),AND(회원현황!$H28<>"",회원현황!$H28>=0,회원현황!$H28<=사용안내!$C$17))) -> FALSE | I28: =IF($H28=FALSE(),"",COUNTIF($H$6:$H28,TRUE())) | J28: =IF($I28="","","R"&$I28)
A29: 24 | B29: =IFERROR(INDEX(회원현황!$A$6:$A$505,MATCH("R"&24,만료임박!$J$6:$J$505,0)),"") | C29: =IF($B29="","",IFERROR(INDEX(회원현황!$B$6:$B$505,MATCH("R"&24,만료임박!$J$6:$J$505,0)),"")) | D29: =IF($B29="","",IFERROR(INDEX(회원현황!$C$6:$C$505,MATCH("R"&24,만료임박!$J$6:$J$505,0)),"")) | E29: =IF($B29="","",IFERROR(INDEX(회원현황!$F$6:$F$505,MATCH("R"&24,만료임박!$J$6:$J$505,0)),"")) | F29: =IF($B29="","",IFERROR(INDEX(회원현황!$G$6:$G$505,MATCH("R"&24,만료임박!$J$6:$J$505,0)),"")) | G29: =IF($B29="","",IFERROR(INDEX(회원현황!$H$6:$H$505,MATCH("R"&24,만료임박!$J$6:$J$505,0)),"")) | H29: =IF(회원현황!$A29="",FALSE(),OR(AND(회원현황!$F29>0,회원현황!$F29<=사용안내!$C$18),AND(회원현황!$H29<>"",회원현황!$H29>=0,회원현황!$H29<=사용안내!$C$17))) -> FALSE | I29: =IF($H29=FALSE(),"",COUNTIF($H$6:$H29,TRUE())) | J29: =IF($I29="","","R"&$I29)
A30: 25 | B30: =IFERROR(INDEX(회원현황!$A$6:$A$505,MATCH("R"&25,만료임박!$J$6:$J$505,0)),"") | C30: =IF($B30="","",IFERROR(INDEX(회원현황!$B$6:$B$505,MATCH("R"&25,만료임박!$J$6:$J$505,0)),"")) | D30: =IF($B30="","",IFERROR(INDEX(회원현황!$C$6:$C$505,MATCH("R"&25,만료임박!$J$6:$J$505,0)),"")) | E30: =IF($B30="","",IFERROR(INDEX(회원현황!$F$6:$F$505,MATCH("R"&25,만료임박!$J$6:$J$505,0)),"")) | F30: =IF($B30="","",IFERROR(INDEX(회원현황!$G$6:$G$505,MATCH("R"&25,만료임박!$J$6:$J$505,0)),"")) | G30: =IF($B30="","",IFERROR(INDEX(회원현황!$H$6:$H$505,MATCH("R"&25,만료임박!$J$6:$J$505,0)),"")) | H30: =IF(회원현황!$A30="",FALSE(),OR(AND(회원현황!$F30>0,회원현황!$F30<=사용안내!$C$18),AND(회원현황!$H30<>"",회원현황!$H30>=0,회원현황!$H30<=사용안내!$C$17))) -> FALSE | I30: =IF($H30=FALSE(),"",COUNTIF($H$6:$H30,TRUE())) | J30: =IF($I30="","","R"&$I30)
A31: 26 | B31: =IFERROR(INDEX(회원현황!$A$6:$A$505,MATCH("R"&26,만료임박!$J$6:$J$505,0)),"") | C31: =IF($B31="","",IFERROR(INDEX(회원현황!$B$6:$B$505,MATCH("R"&26,만료임박!$J$6:$J$505,0)),"")) | D31: =IF($B31="","",IFERROR(INDEX(회원현황!$C$6:$C$505,MATCH("R"&26,만료임박!$J$6:$J$505,0)),"")) | E31: =IF($B31="","",IFERROR(INDEX(회원현황!$F$6:$F$505,MATCH("R"&26,만료임박!$J$6:$J$505,0)),"")) | F31: =IF($B31="","",IFERROR(INDEX(회원현황!$G$6:$G$505,MATCH("R"&26,만료임박!$J$6:$J$505,0)),"")) | G31: =IF($B31="","",IFERROR(INDEX(회원현황!$H$6:$H$505,MATCH("R"&26,만료임박!$J$6:$J$505,0)),"")) | H31: =IF(회원현황!$A31="",FALSE(),OR(AND(회원현황!$F31>0,회원현황!$F31<=사용안내!$C$18),AND(회원현황!$H31<>"",회원현황!$H31>=0,회원현황!$H31<=사용안내!$C$17))) -> FALSE | I31: =IF($H31=FALSE(),"",COUNTIF($H$6:$H31,TRUE())) | J31: =IF($I31="","","R"&$I31)
A32: 27 | B32: =IFERROR(INDEX(회원현황!$A$6:$A$505,MATCH("R"&27,만료임박!$J$6:$J$505,0)),"") | C32: =IF($B32="","",IFERROR(INDEX(회원현황!$B$6:$B$505,MATCH("R"&27,만료임박!$J$6:$J$505,0)),"")) | D32: =IF($B32="","",IFERROR(INDEX(회원현황!$C$6:$C$505,MATCH("R"&27,만료임박!$J$6:$J$505,0)),"")) | E32: =IF($B32="","",IFERROR(INDEX(회원현황!$F$6:$F$505,MATCH("R"&27,만료임박!$J$6:$J$505,0)),"")) | F32: =IF($B32="","",IFERROR(INDEX(회원현황!$G$6:$G$505,MATCH("R"&27,만료임박!$J$6:$J$505,0)),"")) | G32: =IF($B32="","",IFERROR(INDEX(회원현황!$H$6:$H$505,MATCH("R"&27,만료임박!$J$6:$J$505,0)),"")) | H32: =IF(회원현황!$A32="",FALSE(),OR(AND(회원현황!$F32>0,회원현황!$F32<=사용안내!$C$18),AND(회원현황!$H32<>"",회원현황!$H32>=0,회원현황!$H32<=사용안내!$C$17))) -> FALSE | I32: =IF($H32=FALSE(),"",COUNTIF($H$6:$H32,TRUE())) | J32: =IF($I32="","","R"&$I32)
A33: 28 | B33: =IFERROR(INDEX(회원현황!$A$6:$A$505,MATCH("R"&28,만료임박!$J$6:$J$505,0)),"") | C33: =IF($B33="","",IFERROR(INDEX(회원현황!$B$6:$B$505,MATCH("R"&28,만료임박!$J$6:$J$505,0)),"")) | D33: =IF($B33="","",IFERROR(INDEX(회원현황!$C$6:$C$505,MATCH("R"&28,만료임박!$J$6:$J$505,0)),"")) | E33: =IF($B33="","",IFERROR(INDEX(회원현황!$F$6:$F$505,MATCH("R"&28,만료임박!$J$6:$J$505,0)),"")) | F33: =IF($B33="","",IFERROR(INDEX(회원현황!$G$6:$G$505,MATCH("R"&28,만료임박!$J$6:$J$505,0)),"")) | G33: =IF($B33="","",IFERROR(INDEX(회원현황!$H$6:$H$505,MATCH("R"&28,만료임박!$J$6:$J$505,0)),"")) | H33: =IF(회원현황!$A33="",FALSE(),OR(AND(회원현황!$F33>0,회원현황!$F33<=사용안내!$C$18),AND(회원현황!$H33<>"",회원현황!$H33>=0,회원현황!$H33<=사용안내!$C$17))) -> FALSE | I33: =IF($H33=FALSE(),"",COUNTIF($H$6:$H33,TRUE())) | J33: =IF($I33="","","R"&$I33)
A34: 29 | B34: =IFERROR(INDEX(회원현황!$A$6:$A$505,MATCH("R"&29,만료임박!$J$6:$J$505,0)),"") | C34: =IF($B34="","",IFERROR(INDEX(회원현황!$B$6:$B$505,MATCH("R"&29,만료임박!$J$6:$J$505,0)),"")) | D34: =IF($B34="","",IFERROR(INDEX(회원현황!$C$6:$C$505,MATCH("R"&29,만료임박!$J$6:$J$505,0)),"")) | E34: =IF($B34="","",IFERROR(INDEX(회원현황!$F$6:$F$505,MATCH("R"&29,만료임박!$J$6:$J$505,0)),"")) | F34: =IF($B34="","",IFERROR(INDEX(회원현황!$G$6:$G$505,MATCH("R"&29,만료임박!$J$6:$J$505,0)),"")) | G34: =IF($B34="","",IFERROR(INDEX(회원현황!$H$6:$H$505,MATCH("R"&29,만료임박!$J$6:$J$505,0)),"")) | H34: =IF(회원현황!$A34="",FALSE(),OR(AND(회원현황!$F34>0,회원현황!$F34<=사용안내!$C$18),AND(회원현황!$H34<>"",회원현황!$H34>=0,회원현황!$H34<=사용안내!$C$17))) -> FALSE | I34: =IF($H34=FALSE(),"",COUNTIF($H$6:$H34,TRUE())) | J34: =IF($I34="","","R"&$I34)
A35: 30 | B35: =IFERROR(INDEX(회원현황!$A$6:$A$505,MATCH("R"&30,만료임박!$J$6:$J$505,0)),"") | C35: =IF($B35="","",IFERROR(INDEX(회원현황!$B$6:$B$505,MATCH("R"&30,만료임박!$J$6:$J$505,0)),"")) | D35: =IF($B35="","",IFERROR(INDEX(회원현황!$C$6:$C$505,MATCH("R"&30,만료임박!$J$6:$J$505,0)),"")) | E35: =IF($B35="","",IFERROR(INDEX(회원현황!$F$6:$F$505,MATCH("R"&30,만료임박!$J$6:$J$505,0)),"")) | F35: =IF($B35="","",IFERROR(INDEX(회원현황!$G$6:$G$505,MATCH("R"&30,만료임박!$J$6:$J$505,0)),"")) | G35: =IF($B35="","",IFERROR(INDEX(회원현황!$H$6:$H$505,MATCH("R"&30,만료임박!$J$6:$J$505,0)),"")) | H35: =IF(회원현황!$A35="",FALSE(),OR(AND(회원현황!$F35>0,회원현황!$F35<=사용안내!$C$18),AND(회원현황!$H35<>"",회원현황!$H35>=0,회원현황!$H35<=사용안내!$C$17))) -> FALSE | I35: =IF($H35=FALSE(),"",COUNTIF($H$6:$H35,TRUE())) | J35: =IF($I35="","","R"&$I35)
A36: 31 | B36: =IFERROR(INDEX(회원현황!$A$6:$A$505,MATCH("R"&31,만료임박!$J$6:$J$505,0)),"") | C36: =IF($B36="","",IFERROR(INDEX(회원현황!$B$6:$B$505,MATCH("R"&31,만료임박!$J$6:$J$505,0)),"")) | D36: =IF($B36="","",IFERROR(INDEX(회원현황!$C$6:$C$505,MATCH("R"&31,만료임박!$J$6:$J$505,0)),"")) | E36: =IF($B36="","",IFERROR(INDEX(회원현황!$F$6:$F$505,MATCH("R"&31,만료임박!$J$6:$J$505,0)),"")) | F36: =IF($B36="","",IFERROR(INDEX(회원현황!$G$6:$G$505,MATCH("R"&31,만료임박!$J$6:$J$505,0)),"")) | G36: =IF($B36="","",IFERROR(INDEX(회원현황!$H$6:$H$505,MATCH("R"&31,만료임박!$J$6:$J$505,0)),"")) | H36: =IF(회원현황!$A36="",FALSE(),OR(AND(회원현황!$F36>0,회원현황!$F36<=사용안내!$C$18),AND(회원현황!$H36<>"",회원현황!$H36>=0,회원현황!$H36<=사용안내!$C$17))) -> FALSE | I36: =IF($H36=FALSE(),"",COUNTIF($H$6:$H36,TRUE())) | J36: =IF($I36="","","R"&$I36)
A37: 32 | B37: =IFERROR(INDEX(회원현황!$A$6:$A$505,MATCH("R"&32,만료임박!$J$6:$J$505,0)),"") | C37: =IF($B37="","",IFERROR(INDEX(회원현황!$B$6:$B$505,MATCH("R"&32,만료임박!$J$6:$J$505,0)),"")) | D37: =IF($B37="","",IFERROR(INDEX(회원현황!$C$6:$C$505,MATCH("R"&32,만료임박!$J$6:$J$505,0)),"")) | E37: =IF($B37="","",IFERROR(INDEX(회원현황!$F$6:$F$505,MATCH("R"&32,만료임박!$J$6:$J$505,0)),"")) | F37: =IF($B37="","",IFERROR(INDEX(회원현황!$G$6:$G$505,MATCH("R"&32,만료임박!$J$6:$J$505,0)),"")) | G37: =IF($B37="","",IFERROR(INDEX(회원현황!$H$6:$H$505,MATCH("R"&32,만료임박!$J$6:$J$505,0)),"")) | H37: =IF(회원현황!$A37="",FALSE(),OR(AND(회원현황!$F37>0,회원현황!$F37<=사용안내!$C$18),AND(회원현황!$H37<>"",회원현황!$H37>=0,회원현황!$H37<=사용안내!$C$17))) -> FALSE | I37: =IF($H37=FALSE(),"",COUNTIF($H$6:$H37,TRUE())) | J37: =IF($I37="","","R"&$I37)
A38: 33 | B38: =IFERROR(INDEX(회원현황!$A$6:$A$505,MATCH("R"&33,만료임박!$J$6:$J$505,0)),"") | C38: =IF($B38="","",IFERROR(INDEX(회원현황!$B$6:$B$505,MATCH("R"&33,만료임박!$J$6:$J$505,0)),"")) | D38: =IF($B38="","",IFERROR(INDEX(회원현황!$C$6:$C$505,MATCH("R"&33,만료임박!$J$6:$J$505,0)),"")) | E38: =IF($B38="","",IFERROR(INDEX(회원현황!$F$6:$F$505,MATCH("R"&33,만료임박!$J$6:$J$505,0)),"")) | F38: =IF($B38="","",IFERROR(INDEX(회원현황!$G$6:$G$505,MATCH("R"&33,만료임박!$J$6:$J$505,0)),"")) | G38: =IF($B38="","",IFERROR(INDEX(회원현황!$H$6:$H$505,MATCH("R"&33,만료임박!$J$6:$J$505,0)),"")) | H38: =IF(회원현황!$A38="",FALSE(),OR(AND(회원현황!$F38>0,회원현황!$F38<=사용안내!$C$18),AND(회원현황!$H38<>"",회원현황!$H38>=0,회원현황!$H38<=사용안내!$C$17))) -> FALSE | I38: =IF($H38=FALSE(),"",COUNTIF($H$6:$H38,TRUE())) | J38: =IF($I38="","","R"&$I38)
A39: 34 | B39: =IFERROR(INDEX(회원현황!$A$6:$A$505,MATCH("R"&34,만료임박!$J$6:$J$505,0)),"") | C39: =IF($B39="","",IFERROR(INDEX(회원현황!$B$6:$B$505,MATCH("R"&34,만료임박!$J$6:$J$505,0)),"")) | D39: =IF($B39="","",IFERROR(INDEX(회원현황!$C$6:$C$505,MATCH("R"&34,만료임박!$J$6:$J$505,0)),"")) | E39: =IF($B39="","",IFERROR(INDEX(회원현황!$F$6:$F$505,MATCH("R"&34,만료임박!$J$6:$J$505,0)),"")) | F39: =IF($B39="","",IFERROR(INDEX(회원현황!$G$6:$G$505,MATCH("R"&34,만료임박!$J$6:$J$505,0)),"")) | G39: =IF($B39="","",IFERROR(INDEX(회원현황!$H$6:$H$505,MATCH("R"&34,만료임박!$J$6:$J$505,0)),"")) | H39: =IF(회원현황!$A39="",FALSE(),OR(AND(회원현황!$F39>0,회원현황!$F39<=사용안내!$C$18),AND(회원현황!$H39<>"",회원현황!$H39>=0,회원현황!$H39<=사용안내!$C$17))) -> FALSE | I39: =IF($H39=FALSE(),"",COUNTIF($H$6:$H39,TRUE())) | J39: =IF($I39="","","R"&$I39)
A40: 35 | B40: =IFERROR(INDEX(회원현황!$A$6:$A$505,MATCH("R"&35,만료임박!$J$6:$J$505,0)),"") | C40: =IF($B40="","",IFERROR(INDEX(회원현황!$B$6:$B$505,MATCH("R"&35,만료임박!$J$6:$J$505,0)),"")) | D40: =IF($B40="","",IFERROR(INDEX(회원현황!$C$6:$C$505,MATCH("R"&35,만료임박!$J$6:$J$505,0)),"")) | E40: =IF($B40="","",IFERROR(INDEX(회원현황!$F$6:$F$505,MATCH("R"&35,만료임박!$J$6:$J$505,0)),"")) | F40: =IF($B40="","",IFERROR(INDEX(회원현황!$G$6:$G$505,MATCH("R"&35,만료임박!$J$6:$J$505,0)),"")) | G40: =IF($B40="","",IFERROR(INDEX(회원현황!$H$6:$H$505,MATCH("R"&35,만료임박!$J$6:$J$505,0)),"")) | H40: =IF(회원현황!$A40="",FALSE(),OR(AND(회원현황!$F40>0,회원현황!$F40<=사용안내!$C$18),AND(회원현황!$H40<>"",회원현황!$H40>=0,회원현황!$H40<=사용안내!$C$17))) -> FALSE | I40: =IF($H40=FALSE(),"",COUNTIF($H$6:$H40,TRUE())) | J40: =IF($I40="","","R"&$I40)
A41: 36 | B41: =IFERROR(INDEX(회원현황!$A$6:$A$505,MATCH("R"&36,만료임박!$J$6:$J$505,0)),"") | C41: =IF($B41="","",IFERROR(INDEX(회원현황!$B$6:$B$505,MATCH("R"&36,만료임박!$J$6:$J$505,0)),"")) | D41: =IF($B41="","",IFERROR(INDEX(회원현황!$C$6:$C$505,MATCH("R"&36,만료임박!$J$6:$J$505,0)),"")) | E41: =IF($B41="","",IFERROR(INDEX(회원현황!$F$6:$F$505,MATCH("R"&36,만료임박!$J$6:$J$505,0)),"")) | F41: =IF($B41="","",IFERROR(INDEX(회원현황!$G$6:$G$505,MATCH("R"&36,만료임박!$J$6:$J$505,0)),"")) | G41: =IF($B41="","",IFERROR(INDEX(회원현황!$H$6:$H$505,MATCH("R"&36,만료임박!$J$6:$J$505,0)),"")) | H41: =IF(회원현황!$A41="",FALSE(),OR(AND(회원현황!$F41>0,회원현황!$F41<=사용안내!$C$18),AND(회원현황!$H41<>"",회원현황!$H41>=0,회원현황!$H41<=사용안내!$C$17))) -> FALSE | I41: =IF($H41=FALSE(),"",COUNTIF($H$6:$H41,TRUE())) | J41: =IF($I41="","","R"&$I41)
A42: 37 | B42: =IFERROR(INDEX(회원현황!$A$6:$A$505,MATCH("R"&37,만료임박!$J$6:$J$505,0)),"") | C42: =IF($B42="","",IFERROR(INDEX(회원현황!$B$6:$B$505,MATCH("R"&37,만료임박!$J$6:$J$505,0)),"")) | D42: =IF($B42="","",IFERROR(INDEX(회원현황!$C$6:$C$505,MATCH("R"&37,만료임박!$J$6:$J$505,0)),"")) | E42: =IF($B42="","",IFERROR(INDEX(회원현황!$F$6:$F$505,MATCH("R"&37,만료임박!$J$6:$J$505,0)),"")) | F42: =IF($B42="","",IFERROR(INDEX(회원현황!$G$6:$G$505,MATCH("R"&37,만료임박!$J$6:$J$505,0)),"")) | G42: =IF($B42="","",IFERROR(INDEX(회원현황!$H$6:$H$505,MATCH("R"&37,만료임박!$J$6:$J$505,0)),"")) | H42: =IF(회원현황!$A42="",FALSE(),OR(AND(회원현황!$F42>0,회원현황!$F42<=사용안내!$C$18),AND(회원현황!$H42<>"",회원현황!$H42>=0,회원현황!$H42<=사용안내!$C$17))) -> FALSE | I42: =IF($H42=FALSE(),"",COUNTIF($H$6:$H42,TRUE())) | J42: =IF($I42="","","R"&$I42)
...

Sheet 월별집계
A1: 월별집계
A3: 대상 연도 | B3: 2026 | C3: ← 이 칸만 바꾸세요
A5: 월 | B5: 결제 건수 | C5: 결제 금액 | D5: 충전 횟수 | E5: 이용 건수 | F5: 차감 횟수
A6: 1 | B6: =COUNTIFS(결제내역!$A$3:$A$1002,">="&DATE($B$3,1,1),결제내역!$A$3:$A$1002,"<="&EOMONTH(DATE($B$3,1,1),0)) -> 0 | C6: =SUMIFS(결제내역!$H$3:$H$1002,결제내역!$A$3:$A$1002,">="&DATE($B$3,1,1),결제내역!$A$3:$A$1002,"<="&EOMONTH(DATE($B$3,1,1),0)) -> 0 | D6: =SUMIFS(결제내역!$E$3:$E$1002,결제내역!$A$3:$A$1002,">="&DATE($B$3,1,1),결제내역!$A$3:$A$1002,"<="&EOMONTH(DATE($B$3,1,1),0)) -> 0 | E6: =COUNTIFS(사용내역!$A$3:$A$3002,">="&DATE($B$3,1,1),사용내역!$A$3:$A$3002,"<="&EOMONTH(DATE($B$3,1,1),0)) -> 0 | F6: =SUMIFS(사용내역!$D$3:$D$3002,사용내역!$A$3:$A$3002,">="&DATE($B$3,1,1),사용내역!$A$3:$A$3002,"<="&EOMONTH(DATE($B$3,1,1),0)) -> 0
A7: 2 | B7: =COUNTIFS(결제내역!$A$3:$A$1002,">="&DATE($B$3,2,1),결제내역!$A$3:$A$1002,"<="&EOMONTH(DATE($B$3,2,1),0)) -> 0 | C7: =SUMIFS(결제내역!$H$3:$H$1002,결제내역!$A$3:$A$1002,">="&DATE($B$3,2,1),결제내역!$A$3:$A$1002,"<="&EOMONTH(DATE($B$3,2,1),0)) -> 0 | D7: =SUMIFS(결제내역!$E$3:$E$1002,결제내역!$A$3:$A$1002,">="&DATE($B$3,2,1),결제내역!$A$3:$A$1002,"<="&EOMONTH(DATE($B$3,2,1),0)) -> 0 | E7: =COUNTIFS(사용내역!$A$3:$A$3002,">="&DATE($B$3,2,1),사용내역!$A$3:$A$3002,"<="&EOMONTH(DATE($B$3,2,1),0)) -> 0 | F7: =SUMIFS(사용내역!$D$3:$D$3002,사용내역!$A$3:$A$3002,">="&DATE($B$3,2,1),사용내역!$A$3:$A$3002,"<="&EOMONTH(DATE($B$3,2,1),0)) -> 0
A8: 3 | B8: =COUNTIFS(결제내역!$A$3:$A$1002,">="&DATE($B$3,3,1),결제내역!$A$3:$A$1002,"<="&EOMONTH(DATE($B$3,3,1),0)) -> 0 | C8: =SUMIFS(결제내역!$H$3:$H$1002,결제내역!$A$3:$A$1002,">="&DATE($B$3,3,1),결제내역!$A$3:$A$1002,"<="&EOMONTH(DATE($B$3,3,1),0)) -> 0 | D8: =SUMIFS(결제내역!$E$3:$E$1002,결제내역!$A$3:$A$1002,">="&DATE($B$3,3,1),결제내역!$A$3:$A$1002,"<="&EOMONTH(DATE($B$3,3,1),0)) -> 0 | E8: =COUNTIFS(사용내역!$A$3:$A$3002,">="&DATE($B$3,3,1),사용내역!$A$3:$A$3002,"<="&EOMONTH(DATE($B$3,3,1),0)) -> 0 | F8: =SUMIFS(사용내역!$D$3:$D$3002,사용내역!$A$3:$A$3002,">="&DATE($B$3,3,1),사용내역!$A$3:$A$3002,"<="&EOMONTH(DATE($B$3,3,1),0)) -> 0
A9: 4 | B9: =COUNTIFS(결제내역!$A$3:$A$1002,">="&DATE($B$3,4,1),결제내역!$A$3:$A$1002,"<="&EOMONTH(DATE($B$3,4,1),0)) -> 0 | C9: =SUMIFS(결제내역!$H$3:$H$1002,결제내역!$A$3:$A$1002,">="&DATE($B$3,4,1),결제내역!$A$3:$A$1002,"<="&EOMONTH(DATE($B$3,4,1),0)) -> 0 | D9: =SUMIFS(결제내역!$E$3:$E$1002,결제내역!$A$3:$A$1002,">="&DATE($B$3,4,1),결제내역!$A$3:$A$1002,"<="&EOMONTH(DATE($B$3,4,1),0)) -> 0 | E9: =COUNTIFS(사용내역!$A$3:$A$3002,">="&DATE($B$3,4,1),사용내역!$A$3:$A$3002,"<="&EOMONTH(DATE($B$3,4,1),0)) -> 0 | F9: =SUMIFS(사용내역!$D$3:$D$3002,사용내역!$A$3:$A$3002,">="&DATE($B$3,4,1),사용내역!$A$3:$A$3002,"<="&EOMONTH(DATE($B$3,4,1),0)) -> 0
A10: 5 | B10: =COUNTIFS(결제내역!$A$3:$A$1002,">="&DATE($B$3,5,1),결제내역!$A$3:$A$1002,"<="&EOMONTH(DATE($B$3,5,1),0)) -> 0 | C10: =SUMIFS(결제내역!$H$3:$H$1002,결제내역!$A$3:$A$1002,">="&DATE($B$3,5,1),결제내역!$A$3:$A$1002,"<="&EOMONTH(DATE($B$3,5,1),0)) -> 0 | D10: =SUMIFS(결제내역!$E$3:$E$1002,결제내역!$A$3:$A$1002,">="&DATE($B$3,5,1),결제내역!$A$3:$A$1002,"<="&EOMONTH(DATE($B$3,5,1),0)) -> 0 | E10: =COUNTIFS(사용내역!$A$3:$A$3002,">="&DATE($B$3,5,1),사용내역!$A$3:$A$3002,"<="&EOMONTH(DATE($B$3,5,1),0)) -> 0 | F10: =SUMIFS(사용내역!$D$3:$D$3002,사용내역!$A$3:$A$3002,">="&DATE($B$3,5,1),사용내역!$A$3:$A$3002,"<="&EOMONTH(DATE($B$3,5,1),0)) -> 0
A11: 6 | B11: =COUNTIFS(결제내역!$A$3:$A$1002,">="&DATE($B$3,6,1),결제내역!$A$3:$A$1002,"<="&EOMONTH(DATE($B$3,6,1),0)) -> 0 | C11: =SUMIFS(결제내역!$H$3:$H$1002,결제내역!$A$3:$A$1002,">="&DATE($B$3,6,1),결제내역!$A$3:$A$1002,"<="&EOMONTH(DATE($B$3,6,1),0)) -> 0 | D11: =SUMIFS(결제내역!$E$3:$E$1002,결제내역!$A$3:$A$1002,">="&DATE($B$3,6,1),결제내역!$A$3:$A$1002,"<="&EOMONTH(DATE($B$3,6,1),0)) -> 0 | E11: =COUNTIFS(사용내역!$A$3:$A$3002,">="&DATE($B$3,6,1),사용내역!$A$3:$A$3002,"<="&EOMONTH(DATE($B$3,6,1),0)) -> 0 | F11: =SUMIFS(사용내역!$D$3:$D$3002,사용내역!$A$3:$A$3002,">="&DATE($B$3,6,1),사용내역!$A$3:$A$3002,"<="&EOMONTH(DATE($B$3,6,1),0)) -> 0
A12: 7 | B12: =COUNTIFS(결제내역!$A$3:$A$1002,">="&DATE($B$3,7,1),결제내역!$A$3:$A$1002,"<="&EOMONTH(DATE($B$3,7,1),0)) -> 1 | C12: =SUMIFS(결제내역!$H$3:$H$1002,결제내역!$A$3:$A$1002,">="&DATE($B$3,7,1),결제내역!$A$3:$A$1002,"<="&EOMONTH(DATE($B$3,7,1),0)) -> 560000 | D12: =SUMIFS(결제내역!$E$3:$E$1002,결제내역!$A$3:$A$1002,">="&DATE($B$3,7,1),결제내역!$A$3:$A$1002,"<="&EOMONTH(DATE($B$3,7,1),0)) -> 20 | E12: =COUNTIFS(사용내역!$A$3:$A$3002,">="&DATE($B$3,7,1),사용내역!$A$3:$A$3002,"<="&EOMONTH(DATE($B$3,7,1),0)) -> 2 | F12: =SUMIFS(사용내역!$D$3:$D$3002,사용내역!$A$3:$A$3002,">="&DATE($B$3,7,1),사용내역!$A$3:$A$3002,"<="&EOMONTH(DATE($B$3,7,1),0)) -> 2
A13: 8 | B13: =COUNTIFS(결제내역!$A$3:$A$1002,">="&DATE($B$3,8,1),결제내역!$A$3:$A$1002,"<="&EOMONTH(DATE($B$3,8,1),0)) -> 2 | C13: =SUMIFS(결제내역!$H$3:$H$1002,결제내역!$A$3:$A$1002,">="&DATE($B$3,8,1),결제내역!$A$3:$A$1002,"<="&EOMONTH(DATE($B$3,8,1),0)) -> 1080000 | D13: =SUMIFS(결제내역!$E$3:$E$1002,결제내역!$A$3:$A$1002,">="&DATE($B$3,8,1),결제내역!$A$3:$A$1002,"<="&EOMONTH(DATE($B$3,8,1),0)) -> 40 | E13: =COUNTIFS(사용내역!$A$3:$A$3002,">="&DATE($B$3,8,1),사용내역!$A$3:$A$3002,"<="&EOMONTH(DATE($B$3,8,1),0)) -> 3 | F13: =SUMIFS(사용내역!$D$3:$D$3002,사용내역!$A$3:$A$3002,">="&DATE($B$3,8,1),사용내역!$A$3:$A$3002,"<="&EOMONTH(DATE($B$3,8,1),0)) -> 4
A14: 9 | B14: =COUNTIFS(결제내역!$A$3:$A$1002,">="&DATE($B$3,9,1),결제내역!$A$3:$A$1002,"<="&EOMONTH(DATE($B$3,9,1),0)) -> 1 | C14: =SUMIFS(결제내역!$H$3:$H$1002,결제내역!$A$3:$A$1002,">="&DATE($B$3,9,1),결제내역!$A$3:$A$1002,"<="&EOMONTH(DATE($B$3,9,1),0)) -> 35000 | D14: =SUMIFS(결제내역!$E$3:$E$1002,결제내역!$A$3:$A$1002,">="&DATE($B$3,9,1),결제내역!$A$3:$A$1002,"<="&EOMONTH(DATE($B$3,9,1),0)) -> 1 | E14: =COUNTIFS(사용내역!$A$3:$A$3002,">="&DATE($B$3,9,1),사용내역!$A$3:$A$3002,"<="&EOMONTH(DATE($B$3,9,1),0)) -> 7 | F14: =SUMIFS(사용내역!$D$3:$D$3002,사용내역!$A$3:$A$3002,">="&DATE($B$3,9,1),사용내역!$A$3:$A$3002,"<="&EOMONTH(DATE($B$3,9,1),0)) -> 7
A15: 10 | B15: =COUNTIFS(결제내역!$A$3:$A$1002,">="&DATE($B$3,10,1),결제내역!$A$3:$A$1002,"<="&EOMONTH(DATE($B$3,10,1),0)) -> 0 | C15: =SUMIFS(결제내역!$H$3:$H$1002,결제내역!$A$3:$A$1002,">="&DATE($B$3,10,1),결제내역!$A$3:$A$1002,"<="&EOMONTH(DATE($B$3,10,1),0)) -> 0 | D15: =SUMIFS(결제내역!$E$3:$E$1002,결제내역!$A$3:$A$1002,">="&DATE($B$3,10,1),결제내역!$A$3:$A$1002,"<="&EOMONTH(DATE($B$3,10,1),0)) -> 0 | E15: =COUNTIFS(사용내역!$A$3:$A$3002,">="&DATE($B$3,10,1),사용내역!$A$3:$A$3002,"<="&EOMONTH(DATE($B$3,10,1),0)) -> 0 | F15: =SUMIFS(사용내역!$D$3:$D$3002,사용내역!$A$3:$A$3002,">="&DATE($B$3,10,1),사용내역!$A$3:$A$3002,"<="&EOMONTH(DATE($B$3,10,1),0)) -> 0
A16: 11 | B16: =COUNTIFS(결제내역!$A$3:$A$1002,">="&DATE($B$3,11,1),결제내역!$A$3:$A$1002,"<="&EOMONTH(DATE($B$3,11,1),0)) -> 0 | C16: =SUMIFS(결제내역!$H$3:$H$1002,결제내역!$A$3:$A$1002,">="&DATE($B$3,11,1),결제내역!$A$3:$A$1002,"<="&EOMONTH(DATE($B$3,11,1),0)) -> 0 | D16: =SUMIFS(결제내역!$E$3:$E$1002,결제내역!$A$3:$A$1002,">="&DATE($B$3,11,1),결제내역!$A$3:$A$1002,"<="&EOMONTH(DATE($B$3,11,1),0)) -> 0 | E16: =COUNTIFS(사용내역!$A$3:$A$3002,">="&DATE($B$3,11,1),사용내역!$A$3:$A$3002,"<="&EOMONTH(DATE($B$3,11,1),0)) -> 0 | F16: =SUMIFS(사용내역!$D$3:$D$3002,사용내역!$A$3:$A$3002,">="&DATE($B$3,11,1),사용내역!$A$3:$A$3002,"<="&EOMONTH(DATE($B$3,11,1),0)) -> 0
A17: 12 | B17: =COUNTIFS(결제내역!$A$3:$A$1002,">="&DATE($B$3,12,1),결제내역!$A$3:$A$1002,"<="&EOMONTH(DATE($B$3,12,1),0)) -> 0 | C17: =SUMIFS(결제내역!$H$3:$H$1002,결제내역!$A$3:$A$1002,">="&DATE($B$3,12,1),결제내역!$A$3:$A$1002,"<="&EOMONTH(DATE($B$3,12,1),0)) -> 0 | D17: =SUMIFS(결제내역!$E$3:$E$1002,결제내역!$A$3:$A$1002,">="&DATE($B$3,12,1),결제내역!$A$3:$A$1002,"<="&EOMONTH(DATE($B$3,12,1),0)) -> 0 | E17: =COUNTIFS(사용내역!$A$3:$A$3002,">="&DATE($B$3,12,1),사용내역!$A$3:$A$3002,"<="&EOMONTH(DATE($B$3,12,1),0)) -> 0 | F17: =SUMIFS(사용내역!$D$3:$D$3002,사용내역!$A$3:$A$3002,">="&DATE($B$3,12,1),사용내역!$A$3:$A$3002,"<="&EOMONTH(DATE($B$3,12,1),0)) -> 0
A18: 합계 | B18: =SUM(B6:B17) -> 4 | C18: =SUM(C6:C17) -> 1675000 | D18: =SUM(D6:D17) -> 61 | E18: =SUM(E6:E17) -> 12 | F18: =SUM(F6:F17) -> 13
