Workbook

Sheet 사용안내
B2: 예약관리 (중복 방지)
B4: 핵심 | C4: 예약을 넣으면 같은 자리·같은 시간에 이미 예약이 있는지 즉시 알려줍니다.
B5: 입력 규칙 | C5: 파란색 글씨 칸만 입력하세요. 검은색은 자동 계산입니다.
B6: ① 자원목록 | C6: 예약을 받는 대상을 등록합니다. 방·좌석·장비·강사·시술대 등 무엇이든 됩니다.
B7: ② 고객목록 | C7: 단골은 등록해두면 다음 예약부터 연락처가 자동으로 붙습니다.
B8: ③ 예약내역 | C8: 예약마다 한 줄. 날짜·자원·시작·종료만 넣으면 중복 여부가 바로 나옵니다.
C9: 시각은 콜론(:) 없이 숫자 네 자리로 넣으세요. 오후 2시 30분 → 1430
B10: ④ 일별현황 | C10: 날짜 하나를 고르면 그날 예약이 시간 순서로 나옵니다.
B11: ⑤ 자원별현황 | C11: 자원별 예약 건수와 총 이용 시간이 나옵니다.
B12: ⑥ 월별집계 | C12: 월별 예약·취소·노쇼 건수입니다.
B13: 중복 판정 방식 | C13: 같은 날짜·같은 자원에서 시간이 조금이라도 겹치면 중복으로 표시합니다.
B14: 취소한 예약 | C14: 지우지 말고 상태를 '취소'로 바꾸세요. 중복 판정에서 빠집니다.
B16: ※ 이 파일은 예약 2,000건까지 처리하도록 만들어졌습니다.
B17: ※ 자정을 넘기는 예약은 계산되지 않습니다. 같은 날 안에서 끝나는 예약만 지원합니다.

Sheet 자원목록
A1: 자원목록 (방·좌석·장비·강사 등 예약 받는 대상)
A2: 자원코드 | B2: 자원명 | C2: 구분 | D2: 수용 인원 | E2: 비고
A3: R01 | B3: 1번 방 | C3: 룸 | D3: 4
A4: R02 | B4: 2번 방 | C4: 룸 | D4: 6
A5: R03 | B5: 세미나실 | C5: 룸 | D5: 20
A6: E01 | B6: 빔프로젝터 | C6: 장비 | D6: 1

Sheet 고객목록
A1: 고객목록
A2: 고객명 | B2: 연락처 | C2: 구분 | D2: 비고
A3: 김고객 | B3: 010-0000-0001 | C3: 일반
A4: 이고객 | B4: 010-0000-0002 | C4: 단골

Sheet 예약내역
A1: 예약내역 (날짜·자원·시작·종료만 넣으면 중복 여부가 바로 나옵니다)
A2: 예약일 | B2: 자원코드 | C2: 자원명(자동) | D2: 고객명 | E2: 연락처(자동) | F2: 시작시각 (예: 1400) | G2: 종료시각 (예: 1600) | H2: 이용시간(자동) | I2: 인원 | J2: 상태 | K2: 메모 | L2: 시작(분,자동) | M2: 종료(분,자동) | N2: 중복(자동)
A3: 46279 | B3: R01 | C3: =IF($B3="","",IFERROR(INDEX(자원목록!$B$3:$B$102,MATCH($B3,자원목록!$A$3:$A$102,0)),"미등록자원")) -> 1번 방 | D3: 김고객 | E3: =IF($D3="","",IFERROR(INDEX(고객목록!$B$3:$B$502,MATCH($D3,고객목록!$A$3:$A$502,0)),"")) -> 010-0000-0001 | F3: 1000 | G3: 1200 | H3: =IF(OR($L3="",$M3=""),"",ROUND(($M3-$L3)/60,2)) -> 2 | I3: 4 | J3: 완료 | K3: ← 예시 행입니다. 지우고 쓰세요. | L3: =IF($F3="","",IF($F3<1,ROUND($F3*1440,0),INT($F3/100)*60+MOD($F3,100))) -> 600 | M3: =IF($G3="","",IF($G3<1,ROUND($G3*1440,0),INT($G3/100)*60+MOD($G3,100))) -> 720 | N3: =IF(OR($A3="",$B3="",$L3="",$M3="",$J3="취소"),"",IF(SUMPRODUCT(($A$3:$A$2002=$A3)*($B$3:$B$2002=$B3)*($J$3:$J$2002<>"취소")*($L$3:$L$2002<>"")*($M$3:$M$2002<>"")*($L$3:$L$2002<$M3)*($M$3:$M$2002>$L3))>1,"중복","-")) -> 중복
A4: 46279 | B4: R02 | C4: =IF($B4="","",IFERROR(INDEX(자원목록!$B$3:$B$102,MATCH($B4,자원목록!$A$3:$A$102,0)),"미등록자원")) -> 2번 방 | D4: 이고객 | E4: =IF($D4="","",IFERROR(INDEX(고객목록!$B$3:$B$502,MATCH($D4,고객목록!$A$3:$A$502,0)),"")) -> 010-0000-0002 | F4: 1300 | G4: 1500 | H4: =IF(OR($L4="",$M4=""),"",ROUND(($M4-$L4)/60,2)) -> 2 | I4: 6 | J4: 예약 | L4: =IF($F4="","",IF($F4<1,ROUND($F4*1440,0),INT($F4/100)*60+MOD($F4,100))) -> 780 | M4: =IF($G4="","",IF($G4<1,ROUND($G4*1440,0),INT($G4/100)*60+MOD($G4,100))) -> 900 | N4: =IF(OR($A4="",$B4="",$L4="",$M4="",$J4="취소"),"",IF(SUMPRODUCT(($A$3:$A$2002=$A4)*($B$3:$B$2002=$B4)*($J$3:$J$2002<>"취소")*($L$3:$L$2002<>"")*($M$3:$M$2002<>"")*($L$3:$L$2002<$M4)*($M$3:$M$2002>$L4))>1,"중복","-")) -> -
A5: 46279 | B5: R03 | C5: =IF($B5="","",IFERROR(INDEX(자원목록!$B$3:$B$102,MATCH($B5,자원목록!$A$3:$A$102,0)),"미등록자원")) -> 세미나실 | D5: 김고객 | E5: =IF($D5="","",IFERROR(INDEX(고객목록!$B$3:$B$502,MATCH($D5,고객목록!$A$3:$A$502,0)),"")) -> 010-0000-0001 | F5: 1400 | G5: 1700 | H5: =IF(OR($L5="",$M5=""),"",ROUND(($M5-$L5)/60,2)) -> 3 | I5: 15 | J5: 예약 | L5: =IF($F5="","",IF($F5<1,ROUND($F5*1440,0),INT($F5/100)*60+MOD($F5,100))) -> 840 | M5: =IF($G5="","",IF($G5<1,ROUND($G5*1440,0),INT($G5/100)*60+MOD($G5,100))) -> 1020 | N5: =IF(OR($A5="",$B5="",$L5="",$M5="",$J5="취소"),"",IF(SUMPRODUCT(($A$3:$A$2002=$A5)*($B$3:$B$2002=$B5)*($J$3:$J$2002<>"취소")*($L$3:$L$2002<>"")*($M$3:$M$2002<>"")*($L$3:$L$2002<$M5)*($M$3:$M$2002>$L5))>1,"중복","-")) -> -
A6: 46279 | B6: R01 | C6: =IF($B6="","",IFERROR(INDEX(자원목록!$B$3:$B$102,MATCH($B6,자원목록!$A$3:$A$102,0)),"미등록자원")) -> 1번 방 | D6: 이고객 | E6: =IF($D6="","",IFERROR(INDEX(고객목록!$B$3:$B$502,MATCH($D6,고객목록!$A$3:$A$502,0)),"")) -> 010-0000-0002 | F6: 1130 | G6: 1300 | H6: =IF(OR($L6="",$M6=""),"",ROUND(($M6-$L6)/60,2)) -> 1.5 | I6: 3 | J6: 예약 | K6: 시간이 겹칩니다 | L6: =IF($F6="","",IF($F6<1,ROUND($F6*1440,0),INT($F6/100)*60+MOD($F6,100))) -> 690 | M6: =IF($G6="","",IF($G6<1,ROUND($G6*1440,0),INT($G6/100)*60+MOD($G6,100))) -> 780 | N6: =IF(OR($A6="",$B6="",$L6="",$M6="",$J6="취소"),"",IF(SUMPRODUCT(($A$3:$A$2002=$A6)*($B$3:$B$2002=$B6)*($J$3:$J$2002<>"취소")*($L$3:$L$2002<>"")*($M$3:$M$2002<>"")*($L$3:$L$2002<$M6)*($M$3:$M$2002>$L6))>1,"중복","-")) -> 중복
A7: 46280 | B7: R01 | C7: =IF($B7="","",IFERROR(INDEX(자원목록!$B$3:$B$102,MATCH($B7,자원목록!$A$3:$A$102,0)),"미등록자원")) -> 1번 방 | D7: 김고객 | E7: =IF($D7="","",IFERROR(INDEX(고객목록!$B$3:$B$502,MATCH($D7,고객목록!$A$3:$A$502,0)),"")) -> 010-0000-0001 | F7: 900 | G7: 1100 | H7: =IF(OR($L7="",$M7=""),"",ROUND(($M7-$L7)/60,2)) -> 2 | I7: 4 | J7: 예약 | L7: =IF($F7="","",IF($F7<1,ROUND($F7*1440,0),INT($F7/100)*60+MOD($F7,100))) -> 540 | M7: =IF($G7="","",IF($G7<1,ROUND($G7*1440,0),INT($G7/100)*60+MOD($G7,100))) -> 660 | N7: =IF(OR($A7="",$B7="",$L7="",$M7="",$J7="취소"),"",IF(SUMPRODUCT(($A$3:$A$2002=$A7)*($B$3:$B$2002=$B7)*($J$3:$J$2002<>"취소")*($L$3:$L$2002<>"")*($M$3:$M$2002<>"")*($L$3:$L$2002<$M7)*($M$3:$M$2002>$L7))>1,"중복","-")) -> -
A8: 46280 | B8: E01 | C8: =IF($B8="","",IFERROR(INDEX(자원목록!$B$3:$B$102,MATCH($B8,자원목록!$A$3:$A$102,0)),"미등록자원")) -> 빔프로젝터 | D8: 이고객 | E8: =IF($D8="","",IFERROR(INDEX(고객목록!$B$3:$B$502,MATCH($D8,고객목록!$A$3:$A$502,0)),"")) -> 010-0000-0002 | F8: 1400 | G8: 1600 | H8: =IF(OR($L8="",$M8=""),"",ROUND(($M8-$L8)/60,2)) -> 2 | I8: 1 | J8: 예약 | L8: =IF($F8="","",IF($F8<1,ROUND($F8*1440,0),INT($F8/100)*60+MOD($F8,100))) -> 840 | M8: =IF($G8="","",IF($G8<1,ROUND($G8*1440,0),INT($G8/100)*60+MOD($G8,100))) -> 960 | N8: =IF(OR($A8="",$B8="",$L8="",$M8="",$J8="취소"),"",IF(SUMPRODUCT(($A$3:$A$2002=$A8)*($B$3:$B$2002=$B8)*($J$3:$J$2002<>"취소")*($L$3:$L$2002<>"")*($M$3:$M$2002<>"")*($L$3:$L$2002<$M8)*($M$3:$M$2002>$L8))>1,"중복","-")) -> -
A9: 46275 | B9: R02 | C9: =IF($B9="","",IFERROR(INDEX(자원목록!$B$3:$B$102,MATCH($B9,자원목록!$A$3:$A$102,0)),"미등록자원")) -> 2번 방 | D9: 김고객 | E9: =IF($D9="","",IFERROR(INDEX(고객목록!$B$3:$B$502,MATCH($D9,고객목록!$A$3:$A$502,0)),"")) -> 010-0000-0001 | F9: 1000 | G9: 1200 | H9: =IF(OR($L9="",$M9=""),"",ROUND(($M9-$L9)/60,2)) -> 2 | I9: 5 | J9: 취소 | L9: =IF($F9="","",IF($F9<1,ROUND($F9*1440,0),INT($F9/100)*60+MOD($F9,100))) -> 600 | M9: =IF($G9="","",IF($G9<1,ROUND($G9*1440,0),INT($G9/100)*60+MOD($G9,100))) -> 720 | N9: =IF(OR($A9="",$B9="",$L9="",$M9="",$J9="취소"),"",IF(SUMPRODUCT(($A$3:$A$2002=$A9)*($B$3:$B$2002=$B9)*($J$3:$J$2002<>"취소")*($L$3:$L$2002<>"")*($M$3:$M$2002<>"")*($L$3:$L$2002<$M9)*($M$3:$M$2002>$L9))>1,"중복","-"))
A10: 46277 | B10: R03 | C10: =IF($B10="","",IFERROR(INDEX(자원목록!$B$3:$B$102,MATCH($B10,자원목록!$A$3:$A$102,0)),"미등록자원")) -> 세미나실 | D10: 이고객 | E10: =IF($D10="","",IFERROR(INDEX(고객목록!$B$3:$B$502,MATCH($D10,고객목록!$A$3:$A$502,0)),"")) -> 010-0000-0002 | F10: 1300 | G10: 1600 | H10: =IF(OR($L10="",$M10=""),"",ROUND(($M10-$L10)/60,2)) -> 3 | I10: 12 | J10: 노쇼 | L10: =IF($F10="","",IF($F10<1,ROUND($F10*1440,0),INT($F10/100)*60+MOD($F10,100))) -> 780 | M10: =IF($G10="","",IF($G10<1,ROUND($G10*1440,0),INT($G10/100)*60+MOD($G10,100))) -> 960 | N10: =IF(OR($A10="",$B10="",$L10="",$M10="",$J10="취소"),"",IF(SUMPRODUCT(($A$3:$A$2002=$A10)*($B$3:$B$2002=$B10)*($J$3:$J$2002<>"취소")*($L$3:$L$2002<>"")*($M$3:$M$2002<>"")*($L$3:$L$2002<$M10)*($M$3:$M$2002>$L10))>1,"중복","-")) -> -
C11: =IF($B11="","",IFERROR(INDEX(자원목록!$B$3:$B$102,MATCH($B11,자원목록!$A$3:$A$102,0)),"미등록자원")) | E11: =IF($D11="","",IFERROR(INDEX(고객목록!$B$3:$B$502,MATCH($D11,고객목록!$A$3:$A$502,0)),"")) | H11: =IF(OR($L11="",$M11=""),"",ROUND(($M11-$L11)/60,2)) | L11: =IF($F11="","",IF($F11<1,ROUND($F11*1440,0),INT($F11/100)*60+MOD($F11,100))) | M11: =IF($G11="","",IF($G11<1,ROUND($G11*1440,0),INT($G11/100)*60+MOD($G11,100))) | N11: =IF(OR($A11="",$B11="",$L11="",$M11="",$J11="취소"),"",IF(SUMPRODUCT(($A$3:$A$2002=$A11)*($B$3:$B$2002=$B11)*($J$3:$J$2002<>"취소")*($L$3:$L$2002<>"")*($M$3:$M$2002<>"")*($L$3:$L$2002<$M11)*($M$3:$M$2002>$L11))>1,"중복","-"))
C12: =IF($B12="","",IFERROR(INDEX(자원목록!$B$3:$B$102,MATCH($B12,자원목록!$A$3:$A$102,0)),"미등록자원")) | E12: =IF($D12="","",IFERROR(INDEX(고객목록!$B$3:$B$502,MATCH($D12,고객목록!$A$3:$A$502,0)),"")) | H12: =IF(OR($L12="",$M12=""),"",ROUND(($M12-$L12)/60,2)) | L12: =IF($F12="","",IF($F12<1,ROUND($F12*1440,0),INT($F12/100)*60+MOD($F12,100))) | M12: =IF($G12="","",IF($G12<1,ROUND($G12*1440,0),INT($G12/100)*60+MOD($G12,100))) | N12: =IF(OR($A12="",$B12="",$L12="",$M12="",$J12="취소"),"",IF(SUMPRODUCT(($A$3:$A$2002=$A12)*($B$3:$B$2002=$B12)*($J$3:$J$2002<>"취소")*($L$3:$L$2002<>"")*($M$3:$M$2002<>"")*($L$3:$L$2002<$M12)*($M$3:$M$2002>$L12))>1,"중복","-"))
C13: =IF($B13="","",IFERROR(INDEX(자원목록!$B$3:$B$102,MATCH($B13,자원목록!$A$3:$A$102,0)),"미등록자원")) | E13: =IF($D13="","",IFERROR(INDEX(고객목록!$B$3:$B$502,MATCH($D13,고객목록!$A$3:$A$502,0)),"")) | H13: =IF(OR($L13="",$M13=""),"",ROUND(($M13-$L13)/60,2)) | L13: =IF($F13="","",IF($F13<1,ROUND($F13*1440,0),INT($F13/100)*60+MOD($F13,100))) | M13: =IF($G13="","",IF($G13<1,ROUND($G13*1440,0),INT($G13/100)*60+MOD($G13,100))) | N13: =IF(OR($A13="",$B13="",$L13="",$M13="",$J13="취소"),"",IF(SUMPRODUCT(($A$3:$A$2002=$A13)*($B$3:$B$2002=$B13)*($J$3:$J$2002<>"취소")*($L$3:$L$2002<>"")*($M$3:$M$2002<>"")*($L$3:$L$2002<$M13)*($M$3:$M$2002>$L13))>1,"중복","-"))
C14: =IF($B14="","",IFERROR(INDEX(자원목록!$B$3:$B$102,MATCH($B14,자원목록!$A$3:$A$102,0)),"미등록자원")) | E14: =IF($D14="","",IFERROR(INDEX(고객목록!$B$3:$B$502,MATCH($D14,고객목록!$A$3:$A$502,0)),"")) | H14: =IF(OR($L14="",$M14=""),"",ROUND(($M14-$L14)/60,2)) | L14: =IF($F14="","",IF($F14<1,ROUND($F14*1440,0),INT($F14/100)*60+MOD($F14,100))) | M14: =IF($G14="","",IF($G14<1,ROUND($G14*1440,0),INT($G14/100)*60+MOD($G14,100))) | N14: =IF(OR($A14="",$B14="",$L14="",$M14="",$J14="취소"),"",IF(SUMPRODUCT(($A$3:$A$2002=$A14)*($B$3:$B$2002=$B14)*($J$3:$J$2002<>"취소")*($L$3:$L$2002<>"")*($M$3:$M$2002<>"")*($L$3:$L$2002<$M14)*($M$3:$M$2002>$L14))>1,"중복","-"))
C15: =IF($B15="","",IFERROR(INDEX(자원목록!$B$3:$B$102,MATCH($B15,자원목록!$A$3:$A$102,0)),"미등록자원")) | E15: =IF($D15="","",IFERROR(INDEX(고객목록!$B$3:$B$502,MATCH($D15,고객목록!$A$3:$A$502,0)),"")) | H15: =IF(OR($L15="",$M15=""),"",ROUND(($M15-$L15)/60,2)) | L15: =IF($F15="","",IF($F15<1,ROUND($F15*1440,0),INT($F15/100)*60+MOD($F15,100))) | M15: =IF($G15="","",IF($G15<1,ROUND($G15*1440,0),INT($G15/100)*60+MOD($G15,100))) | N15: =IF(OR($A15="",$B15="",$L15="",$M15="",$J15="취소"),"",IF(SUMPRODUCT(($A$3:$A$2002=$A15)*($B$3:$B$2002=$B15)*($J$3:$J$2002<>"취소")*($L$3:$L$2002<>"")*($M$3:$M$2002<>"")*($L$3:$L$2002<$M15)*($M$3:$M$2002>$L15))>1,"중복","-"))
C16: =IF($B16="","",IFERROR(INDEX(자원목록!$B$3:$B$102,MATCH($B16,자원목록!$A$3:$A$102,0)),"미등록자원")) | E16: =IF($D16="","",IFERROR(INDEX(고객목록!$B$3:$B$502,MATCH($D16,고객목록!$A$3:$A$502,0)),"")) | H16: =IF(OR($L16="",$M16=""),"",ROUND(($M16-$L16)/60,2)) | L16: =IF($F16="","",IF($F16<1,ROUND($F16*1440,0),INT($F16/100)*60+MOD($F16,100))) | M16: =IF($G16="","",IF($G16<1,ROUND($G16*1440,0),INT($G16/100)*60+MOD($G16,100))) | N16: =IF(OR($A16="",$B16="",$L16="",$M16="",$J16="취소"),"",IF(SUMPRODUCT(($A$3:$A$2002=$A16)*($B$3:$B$2002=$B16)*($J$3:$J$2002<>"취소")*($L$3:$L$2002<>"")*($M$3:$M$2002<>"")*($L$3:$L$2002<$M16)*($M$3:$M$2002>$L16))>1,"중복","-"))
C17: =IF($B17="","",IFERROR(INDEX(자원목록!$B$3:$B$102,MATCH($B17,자원목록!$A$3:$A$102,0)),"미등록자원")) | E17: =IF($D17="","",IFERROR(INDEX(고객목록!$B$3:$B$502,MATCH($D17,고객목록!$A$3:$A$502,0)),"")) | H17: =IF(OR($L17="",$M17=""),"",ROUND(($M17-$L17)/60,2)) | L17: =IF($F17="","",IF($F17<1,ROUND($F17*1440,0),INT($F17/100)*60+MOD($F17,100))) | M17: =IF($G17="","",IF($G17<1,ROUND($G17*1440,0),INT($G17/100)*60+MOD($G17,100))) | N17: =IF(OR($A17="",$B17="",$L17="",$M17="",$J17="취소"),"",IF(SUMPRODUCT(($A$3:$A$2002=$A17)*($B$3:$B$2002=$B17)*($J$3:$J$2002<>"취소")*($L$3:$L$2002<>"")*($M$3:$M$2002<>"")*($L$3:$L$2002<$M17)*($M$3:$M$2002>$L17))>1,"중복","-"))
C18: =IF($B18="","",IFERROR(INDEX(자원목록!$B$3:$B$102,MATCH($B18,자원목록!$A$3:$A$102,0)),"미등록자원")) | E18: =IF($D18="","",IFERROR(INDEX(고객목록!$B$3:$B$502,MATCH($D18,고객목록!$A$3:$A$502,0)),"")) | H18: =IF(OR($L18="",$M18=""),"",ROUND(($M18-$L18)/60,2)) | L18: =IF($F18="","",IF($F18<1,ROUND($F18*1440,0),INT($F18/100)*60+MOD($F18,100))) | M18: =IF($G18="","",IF($G18<1,ROUND($G18*1440,0),INT($G18/100)*60+MOD($G18,100))) | N18: =IF(OR($A18="",$B18="",$L18="",$M18="",$J18="취소"),"",IF(SUMPRODUCT(($A$3:$A$2002=$A18)*($B$3:$B$2002=$B18)*($J$3:$J$2002<>"취소")*($L$3:$L$2002<>"")*($M$3:$M$2002<>"")*($L$3:$L$2002<$M18)*($M$3:$M$2002>$L18))>1,"중복","-"))
C19: =IF($B19="","",IFERROR(INDEX(자원목록!$B$3:$B$102,MATCH($B19,자원목록!$A$3:$A$102,0)),"미등록자원")) | E19: =IF($D19="","",IFERROR(INDEX(고객목록!$B$3:$B$502,MATCH($D19,고객목록!$A$3:$A$502,0)),"")) | H19: =IF(OR($L19="",$M19=""),"",ROUND(($M19-$L19)/60,2)) | L19: =IF($F19="","",IF($F19<1,ROUND($F19*1440,0),INT($F19/100)*60+MOD($F19,100))) | M19: =IF($G19="","",IF($G19<1,ROUND($G19*1440,0),INT($G19/100)*60+MOD($G19,100))) | N19: =IF(OR($A19="",$B19="",$L19="",$M19="",$J19="취소"),"",IF(SUMPRODUCT(($A$3:$A$2002=$A19)*($B$3:$B$2002=$B19)*($J$3:$J$2002<>"취소")*($L$3:$L$2002<>"")*($M$3:$M$2002<>"")*($L$3:$L$2002<$M19)*($M$3:$M$2002>$L19))>1,"중복","-"))
C20: =IF($B20="","",IFERROR(INDEX(자원목록!$B$3:$B$102,MATCH($B20,자원목록!$A$3:$A$102,0)),"미등록자원")) | E20: =IF($D20="","",IFERROR(INDEX(고객목록!$B$3:$B$502,MATCH($D20,고객목록!$A$3:$A$502,0)),"")) | H20: =IF(OR($L20="",$M20=""),"",ROUND(($M20-$L20)/60,2)) | L20: =IF($F20="","",IF($F20<1,ROUND($F20*1440,0),INT($F20/100)*60+MOD($F20,100))) | M20: =IF($G20="","",IF($G20<1,ROUND($G20*1440,0),INT($G20/100)*60+MOD($G20,100))) | N20: =IF(OR($A20="",$B20="",$L20="",$M20="",$J20="취소"),"",IF(SUMPRODUCT(($A$3:$A$2002=$A20)*($B$3:$B$2002=$B20)*($J$3:$J$2002<>"취소")*($L$3:$L$2002<>"")*($M$3:$M$2002<>"")*($L$3:$L$2002<$M20)*($M$3:$M$2002>$L20))>1,"중복","-"))
C21: =IF($B21="","",IFERROR(INDEX(자원목록!$B$3:$B$102,MATCH($B21,자원목록!$A$3:$A$102,0)),"미등록자원")) | E21: =IF($D21="","",IFERROR(INDEX(고객목록!$B$3:$B$502,MATCH($D21,고객목록!$A$3:$A$502,0)),"")) | H21: =IF(OR($L21="",$M21=""),"",ROUND(($M21-$L21)/60,2)) | L21: =IF($F21="","",IF($F21<1,ROUND($F21*1440,0),INT($F21/100)*60+MOD($F21,100))) | M21: =IF($G21="","",IF($G21<1,ROUND($G21*1440,0),INT($G21/100)*60+MOD($G21,100))) | N21: =IF(OR($A21="",$B21="",$L21="",$M21="",$J21="취소"),"",IF(SUMPRODUCT(($A$3:$A$2002=$A21)*($B$3:$B$2002=$B21)*($J$3:$J$2002<>"취소")*($L$3:$L$2002<>"")*($M$3:$M$2002<>"")*($L$3:$L$2002<$M21)*($M$3:$M$2002>$L21))>1,"중복","-"))
C22: =IF($B22="","",IFERROR(INDEX(자원목록!$B$3:$B$102,MATCH($B22,자원목록!$A$3:$A$102,0)),"미등록자원")) | E22: =IF($D22="","",IFERROR(INDEX(고객목록!$B$3:$B$502,MATCH($D22,고객목록!$A$3:$A$502,0)),"")) | H22: =IF(OR($L22="",$M22=""),"",ROUND(($M22-$L22)/60,2)) | L22: =IF($F22="","",IF($F22<1,ROUND($F22*1440,0),INT($F22/100)*60+MOD($F22,100))) | M22: =IF($G22="","",IF($G22<1,ROUND($G22*1440,0),INT($G22/100)*60+MOD($G22,100))) | N22: =IF(OR($A22="",$B22="",$L22="",$M22="",$J22="취소"),"",IF(SUMPRODUCT(($A$3:$A$2002=$A22)*($B$3:$B$2002=$B22)*($J$3:$J$2002<>"취소")*($L$3:$L$2002<>"")*($M$3:$M$2002<>"")*($L$3:$L$2002<$M22)*($M$3:$M$2002>$L22))>1,"중복","-"))
... C2002: =IF($B2002="","",IFERROR(INDEX(자원목록!$B$3:$B$102,MATCH($B2002,자원목록!$A$3:$A$102,0)),"미등록자원")) | E2002: =IF($D2002="","",IFERROR(INDEX(고객목록!$B$3:$B$502,MATCH($D2002,고객목록!$A$3:$A$502,0)),"")) | H2002: =IF(OR($L2002="",$M2002=""),"",ROUND(($M2002-$L2002)/60,2)) | L2002: =IF($F2002="","",IF($F2002<1,ROUND($F2002*1440,0),INT($F2002/100)*60+MOD($F2002,100))) | M2002: =IF($G2002="","",IF($G2002<1,ROUND($G2002*1440,0),INT($G2002/100)*60+MOD($G2002,100))) | N2002: =IF(OR($A2002="",$B2002="",$L2002="",$M2002="",$J2002="취소"),"",IF(SUMPRODUCT(($A$3:$A$2002=$A2002)*($B$3:$B$2002=$B2002)*($J$3:$J$2002<>"취소")*($L$3:$L$2002<>"")*($M$3:$M$2002<>"")*($L$3:$L$2002<$M2002)*($M$3:$M$2002>$L2002))>1,"중복","-"))
A2004: ※ 중복이 뜨면 겹치는 두 줄이 모두 빨간색이 됩니다. 어느 쪽을 고칠지 정하세요.
A2005: ※ 시작·종료 시각이 같은 예약(0분짜리)은 중복으로 잡히지 않습니다.

Sheet 일별현황
A1: 일별현황
A3: 기준일 | B3: 46280 | C3: =CHOOSE(WEEKDAY($B$3),"일","월","화","수","목","금","토")&"요일" -> 화요일 | E3: 예약 건수 | F3: =COUNTIFS(예약내역!$A$3:$A$2002,$B$3,예약내역!$J$3:$J$2002,"<>취소") -> 2 | G3: 중복 건수 | H3: =COUNTIFS(예약내역!$A$3:$A$2002,$B$3,예약내역!$N$3:$N$2002,"중복") -> 0
A5: 순번 | B5: 시작 | C5: 종료 | D5: 자원명 | E5: 고객명 | F5: 연락처 | G5: 인원 | H5: 상태 | J5: 대상(자동) | K5: 정렬키(자동) | L5: 순위키(자동)
A6: =IF($D6="","",1) -> 1 | B6: =IFERROR(INDEX(예약내역!$F$3:$F$2002,MATCH(1,일별현황!$L$6:$L$2005,0)),"") -> 900 | C6: =IF($B6="","",IFERROR(INDEX(예약내역!$G$3:$G$2002,MATCH(1,일별현황!$L$6:$L$2005,0)),"")) -> 1100 | D6: =IFERROR(INDEX(예약내역!$C$3:$C$2002,MATCH(1,일별현황!$L$6:$L$2005,0)),"") -> 1번 방 | E6: =IF($D6="","",IFERROR(INDEX(예약내역!$D$3:$D$2002,MATCH(1,일별현황!$L$6:$L$2005,0)),"")) -> 김고객 | F6: =IF($D6="","",IFERROR(INDEX(예약내역!$E$3:$E$2002,MATCH(1,일별현황!$L$6:$L$2005,0)),"")) -> 010-0000-0001 | G6: =IF($D6="","",IFERROR(INDEX(예약내역!$I$3:$I$2002,MATCH(1,일별현황!$L$6:$L$2005,0)),"")) -> 4 | H6: =IF($D6="","",IFERROR(INDEX(예약내역!$J$3:$J$2002,MATCH(1,일별현황!$L$6:$L$2005,0)),"")) -> 예약 | J6: =IF(예약내역!$A3="",FALSE(),AND(예약내역!$A3=$B$3,예약내역!$J3<>"취소")) -> FALSE | K6: =IF($J6=FALSE(),"",예약내역!$L3*10000+ROW()) | L6: =IF($K6="","",RANK($K6,$K$6:$K$2005,1))
A7: =IF($D7="","",2) -> 2 | B7: =IFERROR(INDEX(예약내역!$F$3:$F$2002,MATCH(2,일별현황!$L$6:$L$2005,0)),"") -> 1400 | C7: =IF($B7="","",IFERROR(INDEX(예약내역!$G$3:$G$2002,MATCH(2,일별현황!$L$6:$L$2005,0)),"")) -> 1600 | D7: =IFERROR(INDEX(예약내역!$C$3:$C$2002,MATCH(2,일별현황!$L$6:$L$2005,0)),"") -> 빔프로젝터 | E7: =IF($D7="","",IFERROR(INDEX(예약내역!$D$3:$D$2002,MATCH(2,일별현황!$L$6:$L$2005,0)),"")) -> 이고객 | F7: =IF($D7="","",IFERROR(INDEX(예약내역!$E$3:$E$2002,MATCH(2,일별현황!$L$6:$L$2005,0)),"")) -> 010-0000-0002 | G7: =IF($D7="","",IFERROR(INDEX(예약내역!$I$3:$I$2002,MATCH(2,일별현황!$L$6:$L$2005,0)),"")) -> 1 | H7: =IF($D7="","",IFERROR(INDEX(예약내역!$J$3:$J$2002,MATCH(2,일별현황!$L$6:$L$2005,0)),"")) -> 예약 | J7: =IF(예약내역!$A4="",FALSE(),AND(예약내역!$A4=$B$3,예약내역!$J4<>"취소")) -> FALSE | K7: =IF($J7=FALSE(),"",예약내역!$L4*10000+ROW()) | L7: =IF($K7="","",RANK($K7,$K$6:$K$2005,1))
A8: =IF($D8="","",3) | B8: =IFERROR(INDEX(예약내역!$F$3:$F$2002,MATCH(3,일별현황!$L$6:$L$2005,0)),"") | C8: =IF($B8="","",IFERROR(INDEX(예약내역!$G$3:$G$2002,MATCH(3,일별현황!$L$6:$L$2005,0)),"")) | D8: =IFERROR(INDEX(예약내역!$C$3:$C$2002,MATCH(3,일별현황!$L$6:$L$2005,0)),"") | E8: =IF($D8="","",IFERROR(INDEX(예약내역!$D$3:$D$2002,MATCH(3,일별현황!$L$6:$L$2005,0)),"")) | F8: =IF($D8="","",IFERROR(INDEX(예약내역!$E$3:$E$2002,MATCH(3,일별현황!$L$6:$L$2005,0)),"")) | G8: =IF($D8="","",IFERROR(INDEX(예약내역!$I$3:$I$2002,MATCH(3,일별현황!$L$6:$L$2005,0)),"")) | H8: =IF($D8="","",IFERROR(INDEX(예약내역!$J$3:$J$2002,MATCH(3,일별현황!$L$6:$L$2005,0)),"")) | J8: =IF(예약내역!$A5="",FALSE(),AND(예약내역!$A5=$B$3,예약내역!$J5<>"취소")) -> FALSE | K8: =IF($J8=FALSE(),"",예약내역!$L5*10000+ROW()) | L8: =IF($K8="","",RANK($K8,$K$6:$K$2005,1))
A9: =IF($D9="","",4) | B9: =IFERROR(INDEX(예약내역!$F$3:$F$2002,MATCH(4,일별현황!$L$6:$L$2005,0)),"") | C9: =IF($B9="","",IFERROR(INDEX(예약내역!$G$3:$G$2002,MATCH(4,일별현황!$L$6:$L$2005,0)),"")) | D9: =IFERROR(INDEX(예약내역!$C$3:$C$2002,MATCH(4,일별현황!$L$6:$L$2005,0)),"") | E9: =IF($D9="","",IFERROR(INDEX(예약내역!$D$3:$D$2002,MATCH(4,일별현황!$L$6:$L$2005,0)),"")) | F9: =IF($D9="","",IFERROR(INDEX(예약내역!$E$3:$E$2002,MATCH(4,일별현황!$L$6:$L$2005,0)),"")) | G9: =IF($D9="","",IFERROR(INDEX(예약내역!$I$3:$I$2002,MATCH(4,일별현황!$L$6:$L$2005,0)),"")) | H9: =IF($D9="","",IFERROR(INDEX(예약내역!$J$3:$J$2002,MATCH(4,일별현황!$L$6:$L$2005,0)),"")) | J9: =IF(예약내역!$A6="",FALSE(),AND(예약내역!$A6=$B$3,예약내역!$J6<>"취소")) -> FALSE | K9: =IF($J9=FALSE(),"",예약내역!$L6*10000+ROW()) | L9: =IF($K9="","",RANK($K9,$K$6:$K$2005,1))
A10: =IF($D10="","",5) | B10: =IFERROR(INDEX(예약내역!$F$3:$F$2002,MATCH(5,일별현황!$L$6:$L$2005,0)),"") | C10: =IF($B10="","",IFERROR(INDEX(예약내역!$G$3:$G$2002,MATCH(5,일별현황!$L$6:$L$2005,0)),"")) | D10: =IFERROR(INDEX(예약내역!$C$3:$C$2002,MATCH(5,일별현황!$L$6:$L$2005,0)),"") | E10: =IF($D10="","",IFERROR(INDEX(예약내역!$D$3:$D$2002,MATCH(5,일별현황!$L$6:$L$2005,0)),"")) | F10: =IF($D10="","",IFERROR(INDEX(예약내역!$E$3:$E$2002,MATCH(5,일별현황!$L$6:$L$2005,0)),"")) | G10: =IF($D10="","",IFERROR(INDEX(예약내역!$I$3:$I$2002,MATCH(5,일별현황!$L$6:$L$2005,0)),"")) | H10: =IF($D10="","",IFERROR(INDEX(예약내역!$J$3:$J$2002,MATCH(5,일별현황!$L$6:$L$2005,0)),"")) | J10: =IF(예약내역!$A7="",FALSE(),AND(예약내역!$A7=$B$3,예약내역!$J7<>"취소")) -> TRUE | K10: =IF($J10=FALSE(),"",예약내역!$L7*10000+ROW()) -> 5400010 | L10: =IF($K10="","",RANK($K10,$K$6:$K$2005,1)) -> 1
A11: =IF($D11="","",6) | B11: =IFERROR(INDEX(예약내역!$F$3:$F$2002,MATCH(6,일별현황!$L$6:$L$2005,0)),"") | C11: =IF($B11="","",IFERROR(INDEX(예약내역!$G$3:$G$2002,MATCH(6,일별현황!$L$6:$L$2005,0)),"")) | D11: =IFERROR(INDEX(예약내역!$C$3:$C$2002,MATCH(6,일별현황!$L$6:$L$2005,0)),"") | E11: =IF($D11="","",IFERROR(INDEX(예약내역!$D$3:$D$2002,MATCH(6,일별현황!$L$6:$L$2005,0)),"")) | F11: =IF($D11="","",IFERROR(INDEX(예약내역!$E$3:$E$2002,MATCH(6,일별현황!$L$6:$L$2005,0)),"")) | G11: =IF($D11="","",IFERROR(INDEX(예약내역!$I$3:$I$2002,MATCH(6,일별현황!$L$6:$L$2005,0)),"")) | H11: =IF($D11="","",IFERROR(INDEX(예약내역!$J$3:$J$2002,MATCH(6,일별현황!$L$6:$L$2005,0)),"")) | J11: =IF(예약내역!$A8="",FALSE(),AND(예약내역!$A8=$B$3,예약내역!$J8<>"취소")) -> TRUE | K11: =IF($J11=FALSE(),"",예약내역!$L8*10000+ROW()) -> 8400011 | L11: =IF($K11="","",RANK($K11,$K$6:$K$2005,1)) -> 2
A12: =IF($D12="","",7) | B12: =IFERROR(INDEX(예약내역!$F$3:$F$2002,MATCH(7,일별현황!$L$6:$L$2005,0)),"") | C12: =IF($B12="","",IFERROR(INDEX(예약내역!$G$3:$G$2002,MATCH(7,일별현황!$L$6:$L$2005,0)),"")) | D12: =IFERROR(INDEX(예약내역!$C$3:$C$2002,MATCH(7,일별현황!$L$6:$L$2005,0)),"") | E12: =IF($D12="","",IFERROR(INDEX(예약내역!$D$3:$D$2002,MATCH(7,일별현황!$L$6:$L$2005,0)),"")) | F12: =IF($D12="","",IFERROR(INDEX(예약내역!$E$3:$E$2002,MATCH(7,일별현황!$L$6:$L$2005,0)),"")) | G12: =IF($D12="","",IFERROR(INDEX(예약내역!$I$3:$I$2002,MATCH(7,일별현황!$L$6:$L$2005,0)),"")) | H12: =IF($D12="","",IFERROR(INDEX(예약내역!$J$3:$J$2002,MATCH(7,일별현황!$L$6:$L$2005,0)),"")) | J12: =IF(예약내역!$A9="",FALSE(),AND(예약내역!$A9=$B$3,예약내역!$J9<>"취소")) -> FALSE | K12: =IF($J12=FALSE(),"",예약내역!$L9*10000+ROW()) | L12: =IF($K12="","",RANK($K12,$K$6:$K$2005,1))
A13: =IF($D13="","",8) | B13: =IFERROR(INDEX(예약내역!$F$3:$F$2002,MATCH(8,일별현황!$L$6:$L$2005,0)),"") | C13: =IF($B13="","",IFERROR(INDEX(예약내역!$G$3:$G$2002,MATCH(8,일별현황!$L$6:$L$2005,0)),"")) | D13: =IFERROR(INDEX(예약내역!$C$3:$C$2002,MATCH(8,일별현황!$L$6:$L$2005,0)),"") | E13: =IF($D13="","",IFERROR(INDEX(예약내역!$D$3:$D$2002,MATCH(8,일별현황!$L$6:$L$2005,0)),"")) | F13: =IF($D13="","",IFERROR(INDEX(예약내역!$E$3:$E$2002,MATCH(8,일별현황!$L$6:$L$2005,0)),"")) | G13: =IF($D13="","",IFERROR(INDEX(예약내역!$I$3:$I$2002,MATCH(8,일별현황!$L$6:$L$2005,0)),"")) | H13: =IF($D13="","",IFERROR(INDEX(예약내역!$J$3:$J$2002,MATCH(8,일별현황!$L$6:$L$2005,0)),"")) | J13: =IF(예약내역!$A10="",FALSE(),AND(예약내역!$A10=$B$3,예약내역!$J10<>"취소")) -> FALSE | K13: =IF($J13=FALSE(),"",예약내역!$L10*10000+ROW()) | L13: =IF($K13="","",RANK($K13,$K$6:$K$2005,1))
A14: =IF($D14="","",9) | B14: =IFERROR(INDEX(예약내역!$F$3:$F$2002,MATCH(9,일별현황!$L$6:$L$2005,0)),"") | C14: =IF($B14="","",IFERROR(INDEX(예약내역!$G$3:$G$2002,MATCH(9,일별현황!$L$6:$L$2005,0)),"")) | D14: =IFERROR(INDEX(예약내역!$C$3:$C$2002,MATCH(9,일별현황!$L$6:$L$2005,0)),"") | E14: =IF($D14="","",IFERROR(INDEX(예약내역!$D$3:$D$2002,MATCH(9,일별현황!$L$6:$L$2005,0)),"")) | F14: =IF($D14="","",IFERROR(INDEX(예약내역!$E$3:$E$2002,MATCH(9,일별현황!$L$6:$L$2005,0)),"")) | G14: =IF($D14="","",IFERROR(INDEX(예약내역!$I$3:$I$2002,MATCH(9,일별현황!$L$6:$L$2005,0)),"")) | H14: =IF($D14="","",IFERROR(INDEX(예약내역!$J$3:$J$2002,MATCH(9,일별현황!$L$6:$L$2005,0)),"")) | J14: =IF(예약내역!$A11="",FALSE(),AND(예약내역!$A11=$B$3,예약내역!$J11<>"취소")) -> FALSE | K14: =IF($J14=FALSE(),"",예약내역!$L11*10000+ROW()) | L14: =IF($K14="","",RANK($K14,$K$6:$K$2005,1))
A15: =IF($D15="","",10) | B15: =IFERROR(INDEX(예약내역!$F$3:$F$2002,MATCH(10,일별현황!$L$6:$L$2005,0)),"") | C15: =IF($B15="","",IFERROR(INDEX(예약내역!$G$3:$G$2002,MATCH(10,일별현황!$L$6:$L$2005,0)),"")) | D15: =IFERROR(INDEX(예약내역!$C$3:$C$2002,MATCH(10,일별현황!$L$6:$L$2005,0)),"") | E15: =IF($D15="","",IFERROR(INDEX(예약내역!$D$3:$D$2002,MATCH(10,일별현황!$L$6:$L$2005,0)),"")) | F15: =IF($D15="","",IFERROR(INDEX(예약내역!$E$3:$E$2002,MATCH(10,일별현황!$L$6:$L$2005,0)),"")) | G15: =IF($D15="","",IFERROR(INDEX(예약내역!$I$3:$I$2002,MATCH(10,일별현황!$L$6:$L$2005,0)),"")) | H15: =IF($D15="","",IFERROR(INDEX(예약내역!$J$3:$J$2002,MATCH(10,일별현황!$L$6:$L$2005,0)),"")) | J15: =IF(예약내역!$A12="",FALSE(),AND(예약내역!$A12=$B$3,예약내역!$J12<>"취소")) -> FALSE | K15: =IF($J15=FALSE(),"",예약내역!$L12*10000+ROW()) | L15: =IF($K15="","",RANK($K15,$K$6:$K$2005,1))
A16: =IF($D16="","",11) | B16: =IFERROR(INDEX(예약내역!$F$3:$F$2002,MATCH(11,일별현황!$L$6:$L$2005,0)),"") | C16: =IF($B16="","",IFERROR(INDEX(예약내역!$G$3:$G$2002,MATCH(11,일별현황!$L$6:$L$2005,0)),"")) | D16: =IFERROR(INDEX(예약내역!$C$3:$C$2002,MATCH(11,일별현황!$L$6:$L$2005,0)),"") | E16: =IF($D16="","",IFERROR(INDEX(예약내역!$D$3:$D$2002,MATCH(11,일별현황!$L$6:$L$2005,0)),"")) | F16: =IF($D16="","",IFERROR(INDEX(예약내역!$E$3:$E$2002,MATCH(11,일별현황!$L$6:$L$2005,0)),"")) | G16: =IF($D16="","",IFERROR(INDEX(예약내역!$I$3:$I$2002,MATCH(11,일별현황!$L$6:$L$2005,0)),"")) | H16: =IF($D16="","",IFERROR(INDEX(예약내역!$J$3:$J$2002,MATCH(11,일별현황!$L$6:$L$2005,0)),"")) | J16: =IF(예약내역!$A13="",FALSE(),AND(예약내역!$A13=$B$3,예약내역!$J13<>"취소")) -> FALSE | K16: =IF($J16=FALSE(),"",예약내역!$L13*10000+ROW()) | L16: =IF($K16="","",RANK($K16,$K$6:$K$2005,1))
A17: =IF($D17="","",12) | B17: =IFERROR(INDEX(예약내역!$F$3:$F$2002,MATCH(12,일별현황!$L$6:$L$2005,0)),"") | C17: =IF($B17="","",IFERROR(INDEX(예약내역!$G$3:$G$2002,MATCH(12,일별현황!$L$6:$L$2005,0)),"")) | D17: =IFERROR(INDEX(예약내역!$C$3:$C$2002,MATCH(12,일별현황!$L$6:$L$2005,0)),"") | E17: =IF($D17="","",IFERROR(INDEX(예약내역!$D$3:$D$2002,MATCH(12,일별현황!$L$6:$L$2005,0)),"")) | F17: =IF($D17="","",IFERROR(INDEX(예약내역!$E$3:$E$2002,MATCH(12,일별현황!$L$6:$L$2005,0)),"")) | G17: =IF($D17="","",IFERROR(INDEX(예약내역!$I$3:$I$2002,MATCH(12,일별현황!$L$6:$L$2005,0)),"")) | H17: =IF($D17="","",IFERROR(INDEX(예약내역!$J$3:$J$2002,MATCH(12,일별현황!$L$6:$L$2005,0)),"")) | J17: =IF(예약내역!$A14="",FALSE(),AND(예약내역!$A14=$B$3,예약내역!$J14<>"취소")) -> FALSE | K17: =IF($J17=FALSE(),"",예약내역!$L14*10000+ROW()) | L17: =IF($K17="","",RANK($K17,$K$6:$K$2005,1))
A18: =IF($D18="","",13) | B18: =IFERROR(INDEX(예약내역!$F$3:$F$2002,MATCH(13,일별현황!$L$6:$L$2005,0)),"") | C18: =IF($B18="","",IFERROR(INDEX(예약내역!$G$3:$G$2002,MATCH(13,일별현황!$L$6:$L$2005,0)),"")) | D18: =IFERROR(INDEX(예약내역!$C$3:$C$2002,MATCH(13,일별현황!$L$6:$L$2005,0)),"") | E18: =IF($D18="","",IFERROR(INDEX(예약내역!$D$3:$D$2002,MATCH(13,일별현황!$L$6:$L$2005,0)),"")) | F18: =IF($D18="","",IFERROR(INDEX(예약내역!$E$3:$E$2002,MATCH(13,일별현황!$L$6:$L$2005,0)),"")) | G18: =IF($D18="","",IFERROR(INDEX(예약내역!$I$3:$I$2002,MATCH(13,일별현황!$L$6:$L$2005,0)),"")) | H18: =IF($D18="","",IFERROR(INDEX(예약내역!$J$3:$J$2002,MATCH(13,일별현황!$L$6:$L$2005,0)),"")) | J18: =IF(예약내역!$A15="",FALSE(),AND(예약내역!$A15=$B$3,예약내역!$J15<>"취소")) -> FALSE | K18: =IF($J18=FALSE(),"",예약내역!$L15*10000+ROW()) | L18: =IF($K18="","",RANK($K18,$K$6:$K$2005,1))
A19: =IF($D19="","",14) | B19: =IFERROR(INDEX(예약내역!$F$3:$F$2002,MATCH(14,일별현황!$L$6:$L$2005,0)),"") | C19: =IF($B19="","",IFERROR(INDEX(예약내역!$G$3:$G$2002,MATCH(14,일별현황!$L$6:$L$2005,0)),"")) | D19: =IFERROR(INDEX(예약내역!$C$3:$C$2002,MATCH(14,일별현황!$L$6:$L$2005,0)),"") | E19: =IF($D19="","",IFERROR(INDEX(예약내역!$D$3:$D$2002,MATCH(14,일별현황!$L$6:$L$2005,0)),"")) | F19: =IF($D19="","",IFERROR(INDEX(예약내역!$E$3:$E$2002,MATCH(14,일별현황!$L$6:$L$2005,0)),"")) | G19: =IF($D19="","",IFERROR(INDEX(예약내역!$I$3:$I$2002,MATCH(14,일별현황!$L$6:$L$2005,0)),"")) | H19: =IF($D19="","",IFERROR(INDEX(예약내역!$J$3:$J$2002,MATCH(14,일별현황!$L$6:$L$2005,0)),"")) | J19: =IF(예약내역!$A16="",FALSE(),AND(예약내역!$A16=$B$3,예약내역!$J16<>"취소")) -> FALSE | K19: =IF($J19=FALSE(),"",예약내역!$L16*10000+ROW()) | L19: =IF($K19="","",RANK($K19,$K$6:$K$2005,1))
A20: =IF($D20="","",15) | B20: =IFERROR(INDEX(예약내역!$F$3:$F$2002,MATCH(15,일별현황!$L$6:$L$2005,0)),"") | C20: =IF($B20="","",IFERROR(INDEX(예약내역!$G$3:$G$2002,MATCH(15,일별현황!$L$6:$L$2005,0)),"")) | D20: =IFERROR(INDEX(예약내역!$C$3:$C$2002,MATCH(15,일별현황!$L$6:$L$2005,0)),"") | E20: =IF($D20="","",IFERROR(INDEX(예약내역!$D$3:$D$2002,MATCH(15,일별현황!$L$6:$L$2005,0)),"")) | F20: =IF($D20="","",IFERROR(INDEX(예약내역!$E$3:$E$2002,MATCH(15,일별현황!$L$6:$L$2005,0)),"")) | G20: =IF($D20="","",IFERROR(INDEX(예약내역!$I$3:$I$2002,MATCH(15,일별현황!$L$6:$L$2005,0)),"")) | H20: =IF($D20="","",IFERROR(INDEX(예약내역!$J$3:$J$2002,MATCH(15,일별현황!$L$6:$L$2005,0)),"")) | J20: =IF(예약내역!$A17="",FALSE(),AND(예약내역!$A17=$B$3,예약내역!$J17<>"취소")) -> FALSE | K20: =IF($J20=FALSE(),"",예약내역!$L17*10000+ROW()) | L20: =IF($K20="","",RANK($K20,$K$6:$K$2005,1))
A21: =IF($D21="","",16) | B21: =IFERROR(INDEX(예약내역!$F$3:$F$2002,MATCH(16,일별현황!$L$6:$L$2005,0)),"") | C21: =IF($B21="","",IFERROR(INDEX(예약내역!$G$3:$G$2002,MATCH(16,일별현황!$L$6:$L$2005,0)),"")) | D21: =IFERROR(INDEX(예약내역!$C$3:$C$2002,MATCH(16,일별현황!$L$6:$L$2005,0)),"") | E21: =IF($D21="","",IFERROR(INDEX(예약내역!$D$3:$D$2002,MATCH(16,일별현황!$L$6:$L$2005,0)),"")) | F21: =IF($D21="","",IFERROR(INDEX(예약내역!$E$3:$E$2002,MATCH(16,일별현황!$L$6:$L$2005,0)),"")) | G21: =IF($D21="","",IFERROR(INDEX(예약내역!$I$3:$I$2002,MATCH(16,일별현황!$L$6:$L$2005,0)),"")) | H21: =IF($D21="","",IFERROR(INDEX(예약내역!$J$3:$J$2002,MATCH(16,일별현황!$L$6:$L$2005,0)),"")) | J21: =IF(예약내역!$A18="",FALSE(),AND(예약내역!$A18=$B$3,예약내역!$J18<>"취소")) -> FALSE | K21: =IF($J21=FALSE(),"",예약내역!$L18*10000+ROW()) | L21: =IF($K21="","",RANK($K21,$K$6:$K$2005,1))
A22: =IF($D22="","",17) | B22: =IFERROR(INDEX(예약내역!$F$3:$F$2002,MATCH(17,일별현황!$L$6:$L$2005,0)),"") | C22: =IF($B22="","",IFERROR(INDEX(예약내역!$G$3:$G$2002,MATCH(17,일별현황!$L$6:$L$2005,0)),"")) | D22: =IFERROR(INDEX(예약내역!$C$3:$C$2002,MATCH(17,일별현황!$L$6:$L$2005,0)),"") | E22: =IF($D22="","",IFERROR(INDEX(예약내역!$D$3:$D$2002,MATCH(17,일별현황!$L$6:$L$2005,0)),"")) | F22: =IF($D22="","",IFERROR(INDEX(예약내역!$E$3:$E$2002,MATCH(17,일별현황!$L$6:$L$2005,0)),"")) | G22: =IF($D22="","",IFERROR(INDEX(예약내역!$I$3:$I$2002,MATCH(17,일별현황!$L$6:$L$2005,0)),"")) | H22: =IF($D22="","",IFERROR(INDEX(예약내역!$J$3:$J$2002,MATCH(17,일별현황!$L$6:$L$2005,0)),"")) | J22: =IF(예약내역!$A19="",FALSE(),AND(예약내역!$A19=$B$3,예약내역!$J19<>"취소")) -> FALSE | K22: =IF($J22=FALSE(),"",예약내역!$L19*10000+ROW()) | L22: =IF($K22="","",RANK($K22,$K$6:$K$2005,1))
A23: =IF($D23="","",18) | B23: =IFERROR(INDEX(예약내역!$F$3:$F$2002,MATCH(18,일별현황!$L$6:$L$2005,0)),"") | C23: =IF($B23="","",IFERROR(INDEX(예약내역!$G$3:$G$2002,MATCH(18,일별현황!$L$6:$L$2005,0)),"")) | D23: =IFERROR(INDEX(예약내역!$C$3:$C$2002,MATCH(18,일별현황!$L$6:$L$2005,0)),"") | E23: =IF($D23="","",IFERROR(INDEX(예약내역!$D$3:$D$2002,MATCH(18,일별현황!$L$6:$L$2005,0)),"")) | F23: =IF($D23="","",IFERROR(INDEX(예약내역!$E$3:$E$2002,MATCH(18,일별현황!$L$6:$L$2005,0)),"")) | G23: =IF($D23="","",IFERROR(INDEX(예약내역!$I$3:$I$2002,MATCH(18,일별현황!$L$6:$L$2005,0)),"")) | H23: =IF($D23="","",IFERROR(INDEX(예약내역!$J$3:$J$2002,MATCH(18,일별현황!$L$6:$L$2005,0)),"")) | J23: =IF(예약내역!$A20="",FALSE(),AND(예약내역!$A20=$B$3,예약내역!$J20<>"취소")) -> FALSE | K23: =IF($J23=FALSE(),"",예약내역!$L20*10000+ROW()) | L23: =IF($K23="","",RANK($K23,$K$6:$K$2005,1))
A24: =IF($D24="","",19) | B24: =IFERROR(INDEX(예약내역!$F$3:$F$2002,MATCH(19,일별현황!$L$6:$L$2005,0)),"") | C24: =IF($B24="","",IFERROR(INDEX(예약내역!$G$3:$G$2002,MATCH(19,일별현황!$L$6:$L$2005,0)),"")) | D24: =IFERROR(INDEX(예약내역!$C$3:$C$2002,MATCH(19,일별현황!$L$6:$L$2005,0)),"") | E24: =IF($D24="","",IFERROR(INDEX(예약내역!$D$3:$D$2002,MATCH(19,일별현황!$L$6:$L$2005,0)),"")) | F24: =IF($D24="","",IFERROR(INDEX(예약내역!$E$3:$E$2002,MATCH(19,일별현황!$L$6:$L$2005,0)),"")) | G24: =IF($D24="","",IFERROR(INDEX(예약내역!$I$3:$I$2002,MATCH(19,일별현황!$L$6:$L$2005,0)),"")) | H24: =IF($D24="","",IFERROR(INDEX(예약내역!$J$3:$J$2002,MATCH(19,일별현황!$L$6:$L$2005,0)),"")) | J24: =IF(예약내역!$A21="",FALSE(),AND(예약내역!$A21=$B$3,예약내역!$J21<>"취소")) -> FALSE | K24: =IF($J24=FALSE(),"",예약내역!$L21*10000+ROW()) | L24: =IF($K24="","",RANK($K24,$K$6:$K$2005,1))
A25: =IF($D25="","",20) | B25: =IFERROR(INDEX(예약내역!$F$3:$F$2002,MATCH(20,일별현황!$L$6:$L$2005,0)),"") | C25: =IF($B25="","",IFERROR(INDEX(예약내역!$G$3:$G$2002,MATCH(20,일별현황!$L$6:$L$2005,0)),"")) | D25: =IFERROR(INDEX(예약내역!$C$3:$C$2002,MATCH(20,일별현황!$L$6:$L$2005,0)),"") | E25: =IF($D25="","",IFERROR(INDEX(예약내역!$D$3:$D$2002,MATCH(20,일별현황!$L$6:$L$2005,0)),"")) | F25: =IF($D25="","",IFERROR(INDEX(예약내역!$E$3:$E$2002,MATCH(20,일별현황!$L$6:$L$2005,0)),"")) | G25: =IF($D25="","",IFERROR(INDEX(예약내역!$I$3:$I$2002,MATCH(20,일별현황!$L$6:$L$2005,0)),"")) | H25: =IF($D25="","",IFERROR(INDEX(예약내역!$J$3:$J$2002,MATCH(20,일별현황!$L$6:$L$2005,0)),"")) | J25: =IF(예약내역!$A22="",FALSE(),AND(예약내역!$A22=$B$3,예약내역!$J22<>"취소")) -> FALSE | K25: =IF($J25=FALSE(),"",예약내역!$L22*10000+ROW()) | L25: =IF($K25="","",RANK($K25,$K$6:$K$2005,1))
A26: =IF($D26="","",21) | B26: =IFERROR(INDEX(예약내역!$F$3:$F$2002,MATCH(21,일별현황!$L$6:$L$2005,0)),"") | C26: =IF($B26="","",IFERROR(INDEX(예약내역!$G$3:$G$2002,MATCH(21,일별현황!$L$6:$L$2005,0)),"")) | D26: =IFERROR(INDEX(예약내역!$C$3:$C$2002,MATCH(21,일별현황!$L$6:$L$2005,0)),"") | E26: =IF($D26="","",IFERROR(INDEX(예약내역!$D$3:$D$2002,MATCH(21,일별현황!$L$6:$L$2005,0)),"")) | F26: =IF($D26="","",IFERROR(INDEX(예약내역!$E$3:$E$2002,MATCH(21,일별현황!$L$6:$L$2005,0)),"")) | G26: =IF($D26="","",IFERROR(INDEX(예약내역!$I$3:$I$2002,MATCH(21,일별현황!$L$6:$L$2005,0)),"")) | H26: =IF($D26="","",IFERROR(INDEX(예약내역!$J$3:$J$2002,MATCH(21,일별현황!$L$6:$L$2005,0)),"")) | J26: =IF(예약내역!$A23="",FALSE(),AND(예약내역!$A23=$B$3,예약내역!$J23<>"취소")) -> FALSE | K26: =IF($J26=FALSE(),"",예약내역!$L23*10000+ROW()) | L26: =IF($K26="","",RANK($K26,$K$6:$K$2005,1))
A27: =IF($D27="","",22) | B27: =IFERROR(INDEX(예약내역!$F$3:$F$2002,MATCH(22,일별현황!$L$6:$L$2005,0)),"") | C27: =IF($B27="","",IFERROR(INDEX(예약내역!$G$3:$G$2002,MATCH(22,일별현황!$L$6:$L$2005,0)),"")) | D27: =IFERROR(INDEX(예약내역!$C$3:$C$2002,MATCH(22,일별현황!$L$6:$L$2005,0)),"") | E27: =IF($D27="","",IFERROR(INDEX(예약내역!$D$3:$D$2002,MATCH(22,일별현황!$L$6:$L$2005,0)),"")) | F27: =IF($D27="","",IFERROR(INDEX(예약내역!$E$3:$E$2002,MATCH(22,일별현황!$L$6:$L$2005,0)),"")) | G27: =IF($D27="","",IFERROR(INDEX(예약내역!$I$3:$I$2002,MATCH(22,일별현황!$L$6:$L$2005,0)),"")) | H27: =IF($D27="","",IFERROR(INDEX(예약내역!$J$3:$J$2002,MATCH(22,일별현황!$L$6:$L$2005,0)),"")) | J27: =IF(예약내역!$A24="",FALSE(),AND(예약내역!$A24=$B$3,예약내역!$J24<>"취소")) -> FALSE | K27: =IF($J27=FALSE(),"",예약내역!$L24*10000+ROW()) | L27: =IF($K27="","",RANK($K27,$K$6:$K$2005,1))
A28: =IF($D28="","",23) | B28: =IFERROR(INDEX(예약내역!$F$3:$F$2002,MATCH(23,일별현황!$L$6:$L$2005,0)),"") | C28: =IF($B28="","",IFERROR(INDEX(예약내역!$G$3:$G$2002,MATCH(23,일별현황!$L$6:$L$2005,0)),"")) | D28: =IFERROR(INDEX(예약내역!$C$3:$C$2002,MATCH(23,일별현황!$L$6:$L$2005,0)),"") | E28: =IF($D28="","",IFERROR(INDEX(예약내역!$D$3:$D$2002,MATCH(23,일별현황!$L$6:$L$2005,0)),"")) | F28: =IF($D28="","",IFERROR(INDEX(예약내역!$E$3:$E$2002,MATCH(23,일별현황!$L$6:$L$2005,0)),"")) | G28: =IF($D28="","",IFERROR(INDEX(예약내역!$I$3:$I$2002,MATCH(23,일별현황!$L$6:$L$2005,0)),"")) | H28: =IF($D28="","",IFERROR(INDEX(예약내역!$J$3:$J$2002,MATCH(23,일별현황!$L$6:$L$2005,0)),"")) | J28: =IF(예약내역!$A25="",FALSE(),AND(예약내역!$A25=$B$3,예약내역!$J25<>"취소")) -> FALSE | K28: =IF($J28=FALSE(),"",예약내역!$L25*10000+ROW()) | L28: =IF($K28="","",RANK($K28,$K$6:$K$2005,1))
A29: =IF($D29="","",24) | B29: =IFERROR(INDEX(예약내역!$F$3:$F$2002,MATCH(24,일별현황!$L$6:$L$2005,0)),"") | C29: =IF($B29="","",IFERROR(INDEX(예약내역!$G$3:$G$2002,MATCH(24,일별현황!$L$6:$L$2005,0)),"")) | D29: =IFERROR(INDEX(예약내역!$C$3:$C$2002,MATCH(24,일별현황!$L$6:$L$2005,0)),"") | E29: =IF($D29="","",IFERROR(INDEX(예약내역!$D$3:$D$2002,MATCH(24,일별현황!$L$6:$L$2005,0)),"")) | F29: =IF($D29="","",IFERROR(INDEX(예약내역!$E$3:$E$2002,MATCH(24,일별현황!$L$6:$L$2005,0)),"")) | G29: =IF($D29="","",IFERROR(INDEX(예약내역!$I$3:$I$2002,MATCH(24,일별현황!$L$6:$L$2005,0)),"")) | H29: =IF($D29="","",IFERROR(INDEX(예약내역!$J$3:$J$2002,MATCH(24,일별현황!$L$6:$L$2005,0)),"")) | J29: =IF(예약내역!$A26="",FALSE(),AND(예약내역!$A26=$B$3,예약내역!$J26<>"취소")) -> FALSE | K29: =IF($J29=FALSE(),"",예약내역!$L26*10000+ROW()) | L29: =IF($K29="","",RANK($K29,$K$6:$K$2005,1))
A30: =IF($D30="","",25) | B30: =IFERROR(INDEX(예약내역!$F$3:$F$2002,MATCH(25,일별현황!$L$6:$L$2005,0)),"") | C30: =IF($B30="","",IFERROR(INDEX(예약내역!$G$3:$G$2002,MATCH(25,일별현황!$L$6:$L$2005,0)),"")) | D30: =IFERROR(INDEX(예약내역!$C$3:$C$2002,MATCH(25,일별현황!$L$6:$L$2005,0)),"") | E30: =IF($D30="","",IFERROR(INDEX(예약내역!$D$3:$D$2002,MATCH(25,일별현황!$L$6:$L$2005,0)),"")) | F30: =IF($D30="","",IFERROR(INDEX(예약내역!$E$3:$E$2002,MATCH(25,일별현황!$L$6:$L$2005,0)),"")) | G30: =IF($D30="","",IFERROR(INDEX(예약내역!$I$3:$I$2002,MATCH(25,일별현황!$L$6:$L$2005,0)),"")) | H30: =IF($D30="","",IFERROR(INDEX(예약내역!$J$3:$J$2002,MATCH(25,일별현황!$L$6:$L$2005,0)),"")) | J30: =IF(예약내역!$A27="",FALSE(),AND(예약내역!$A27=$B$3,예약내역!$J27<>"취소")) -> FALSE | K30: =IF($J30=FALSE(),"",예약내역!$L27*10000+ROW()) | L30: =IF($K30="","",RANK($K30,$K$6:$K$2005,1))
A31: =IF($D31="","",26) | B31: =IFERROR(INDEX(예약내역!$F$3:$F$2002,MATCH(26,일별현황!$L$6:$L$2005,0)),"") | C31: =IF($B31="","",IFERROR(INDEX(예약내역!$G$3:$G$2002,MATCH(26,일별현황!$L$6:$L$2005,0)),"")) | D31: =IFERROR(INDEX(예약내역!$C$3:$C$2002,MATCH(26,일별현황!$L$6:$L$2005,0)),"") | E31: =IF($D31="","",IFERROR(INDEX(예약내역!$D$3:$D$2002,MATCH(26,일별현황!$L$6:$L$2005,0)),"")) | F31: =IF($D31="","",IFERROR(INDEX(예약내역!$E$3:$E$2002,MATCH(26,일별현황!$L$6:$L$2005,0)),"")) | G31: =IF($D31="","",IFERROR(INDEX(예약내역!$I$3:$I$2002,MATCH(26,일별현황!$L$6:$L$2005,0)),"")) | H31: =IF($D31="","",IFERROR(INDEX(예약내역!$J$3:$J$2002,MATCH(26,일별현황!$L$6:$L$2005,0)),"")) | J31: =IF(예약내역!$A28="",FALSE(),AND(예약내역!$A28=$B$3,예약내역!$J28<>"취소")) -> FALSE | K31: =IF($J31=FALSE(),"",예약내역!$L28*10000+ROW()) | L31: =IF($K31="","",RANK($K31,$K$6:$K$2005,1))
A32: =IF($D32="","",27) | B32: =IFERROR(INDEX(예약내역!$F$3:$F$2002,MATCH(27,일별현황!$L$6:$L$2005,0)),"") | C32: =IF($B32="","",IFERROR(INDEX(예약내역!$G$3:$G$2002,MATCH(27,일별현황!$L$6:$L$2005,0)),"")) | D32: =IFERROR(INDEX(예약내역!$C$3:$C$2002,MATCH(27,일별현황!$L$6:$L$2005,0)),"") | E32: =IF($D32="","",IFERROR(INDEX(예약내역!$D$3:$D$2002,MATCH(27,일별현황!$L$6:$L$2005,0)),"")) | F32: =IF($D32="","",IFERROR(INDEX(예약내역!$E$3:$E$2002,MATCH(27,일별현황!$L$6:$L$2005,0)),"")) | G32: =IF($D32="","",IFERROR(INDEX(예약내역!$I$3:$I$2002,MATCH(27,일별현황!$L$6:$L$2005,0)),"")) | H32: =IF($D32="","",IFERROR(INDEX(예약내역!$J$3:$J$2002,MATCH(27,일별현황!$L$6:$L$2005,0)),"")) | J32: =IF(예약내역!$A29="",FALSE(),AND(예약내역!$A29=$B$3,예약내역!$J29<>"취소")) -> FALSE | K32: =IF($J32=FALSE(),"",예약내역!$L29*10000+ROW()) | L32: =IF($K32="","",RANK($K32,$K$6:$K$2005,1))
A33: =IF($D33="","",28) | B33: =IFERROR(INDEX(예약내역!$F$3:$F$2002,MATCH(28,일별현황!$L$6:$L$2005,0)),"") | C33: =IF($B33="","",IFERROR(INDEX(예약내역!$G$3:$G$2002,MATCH(28,일별현황!$L$6:$L$2005,0)),"")) | D33: =IFERROR(INDEX(예약내역!$C$3:$C$2002,MATCH(28,일별현황!$L$6:$L$2005,0)),"") | E33: =IF($D33="","",IFERROR(INDEX(예약내역!$D$3:$D$2002,MATCH(28,일별현황!$L$6:$L$2005,0)),"")) | F33: =IF($D33="","",IFERROR(INDEX(예약내역!$E$3:$E$2002,MATCH(28,일별현황!$L$6:$L$2005,0)),"")) | G33: =IF($D33="","",IFERROR(INDEX(예약내역!$I$3:$I$2002,MATCH(28,일별현황!$L$6:$L$2005,0)),"")) | H33: =IF($D33="","",IFERROR(INDEX(예약내역!$J$3:$J$2002,MATCH(28,일별현황!$L$6:$L$2005,0)),"")) | J33: =IF(예약내역!$A30="",FALSE(),AND(예약내역!$A30=$B$3,예약내역!$J30<>"취소")) -> FALSE | K33: =IF($J33=FALSE(),"",예약내역!$L30*10000+ROW()) | L33: =IF($K33="","",RANK($K33,$K$6:$K$2005,1))
A34: =IF($D34="","",29) | B34: =IFERROR(INDEX(예약내역!$F$3:$F$2002,MATCH(29,일별현황!$L$6:$L$2005,0)),"") | C34: =IF($B34="","",IFERROR(INDEX(예약내역!$G$3:$G$2002,MATCH(29,일별현황!$L$6:$L$2005,0)),"")) | D34: =IFERROR(INDEX(예약내역!$C$3:$C$2002,MATCH(29,일별현황!$L$6:$L$2005,0)),"") | E34: =IF($D34="","",IFERROR(INDEX(예약내역!$D$3:$D$2002,MATCH(29,일별현황!$L$6:$L$2005,0)),"")) | F34: =IF($D34="","",IFERROR(INDEX(예약내역!$E$3:$E$2002,MATCH(29,일별현황!$L$6:$L$2005,0)),"")) | G34: =IF($D34="","",IFERROR(INDEX(예약내역!$I$3:$I$2002,MATCH(29,일별현황!$L$6:$L$2005,0)),"")) | H34: =IF($D34="","",IFERROR(INDEX(예약내역!$J$3:$J$2002,MATCH(29,일별현황!$L$6:$L$2005,0)),"")) | J34: =IF(예약내역!$A31="",FALSE(),AND(예약내역!$A31=$B$3,예약내역!$J31<>"취소")) -> FALSE | K34: =IF($J34=FALSE(),"",예약내역!$L31*10000+ROW()) | L34: =IF($K34="","",RANK($K34,$K$6:$K$2005,1))
A35: =IF($D35="","",30) | B35: =IFERROR(INDEX(예약내역!$F$3:$F$2002,MATCH(30,일별현황!$L$6:$L$2005,0)),"") | C35: =IF($B35="","",IFERROR(INDEX(예약내역!$G$3:$G$2002,MATCH(30,일별현황!$L$6:$L$2005,0)),"")) | D35: =IFERROR(INDEX(예약내역!$C$3:$C$2002,MATCH(30,일별현황!$L$6:$L$2005,0)),"") | E35: =IF($D35="","",IFERROR(INDEX(예약내역!$D$3:$D$2002,MATCH(30,일별현황!$L$6:$L$2005,0)),"")) | F35: =IF($D35="","",IFERROR(INDEX(예약내역!$E$3:$E$2002,MATCH(30,일별현황!$L$6:$L$2005,0)),"")) | G35: =IF($D35="","",IFERROR(INDEX(예약내역!$I$3:$I$2002,MATCH(30,일별현황!$L$6:$L$2005,0)),"")) | H35: =IF($D35="","",IFERROR(INDEX(예약내역!$J$3:$J$2002,MATCH(30,일별현황!$L$6:$L$2005,0)),"")) | J35: =IF(예약내역!$A32="",FALSE(),AND(예약내역!$A32=$B$3,예약내역!$J32<>"취소")) -> FALSE | K35: =IF($J35=FALSE(),"",예약내역!$L32*10000+ROW()) | L35: =IF($K35="","",RANK($K35,$K$6:$K$2005,1))
A36: =IF($D36="","",31) | B36: =IFERROR(INDEX(예약내역!$F$3:$F$2002,MATCH(31,일별현황!$L$6:$L$2005,0)),"") | C36: =IF($B36="","",IFERROR(INDEX(예약내역!$G$3:$G$2002,MATCH(31,일별현황!$L$6:$L$2005,0)),"")) | D36: =IFERROR(INDEX(예약내역!$C$3:$C$2002,MATCH(31,일별현황!$L$6:$L$2005,0)),"") | E36: =IF($D36="","",IFERROR(INDEX(예약내역!$D$3:$D$2002,MATCH(31,일별현황!$L$6:$L$2005,0)),"")) | F36: =IF($D36="","",IFERROR(INDEX(예약내역!$E$3:$E$2002,MATCH(31,일별현황!$L$6:$L$2005,0)),"")) | G36: =IF($D36="","",IFERROR(INDEX(예약내역!$I$3:$I$2002,MATCH(31,일별현황!$L$6:$L$2005,0)),"")) | H36: =IF($D36="","",IFERROR(INDEX(예약내역!$J$3:$J$2002,MATCH(31,일별현황!$L$6:$L$2005,0)),"")) | J36: =IF(예약내역!$A33="",FALSE(),AND(예약내역!$A33=$B$3,예약내역!$J33<>"취소")) -> FALSE | K36: =IF($J36=FALSE(),"",예약내역!$L33*10000+ROW()) | L36: =IF($K36="","",RANK($K36,$K$6:$K$2005,1))
A37: =IF($D37="","",32) | B37: =IFERROR(INDEX(예약내역!$F$3:$F$2002,MATCH(32,일별현황!$L$6:$L$2005,0)),"") | C37: =IF($B37="","",IFERROR(INDEX(예약내역!$G$3:$G$2002,MATCH(32,일별현황!$L$6:$L$2005,0)),"")) | D37: =IFERROR(INDEX(예약내역!$C$3:$C$2002,MATCH(32,일별현황!$L$6:$L$2005,0)),"") | E37: =IF($D37="","",IFERROR(INDEX(예약내역!$D$3:$D$2002,MATCH(32,일별현황!$L$6:$L$2005,0)),"")) | F37: =IF($D37="","",IFERROR(INDEX(예약내역!$E$3:$E$2002,MATCH(32,일별현황!$L$6:$L$2005,0)),"")) | G37: =IF($D37="","",IFERROR(INDEX(예약내역!$I$3:$I$2002,MATCH(32,일별현황!$L$6:$L$2005,0)),"")) | H37: =IF($D37="","",IFERROR(INDEX(예약내역!$J$3:$J$2002,MATCH(32,일별현황!$L$6:$L$2005,0)),"")) | J37: =IF(예약내역!$A34="",FALSE(),AND(예약내역!$A34=$B$3,예약내역!$J34<>"취소")) -> FALSE | K37: =IF($J37=FALSE(),"",예약내역!$L34*10000+ROW()) | L37: =IF($K37="","",RANK($K37,$K$6:$K$2005,1))
A38: =IF($D38="","",33) | B38: =IFERROR(INDEX(예약내역!$F$3:$F$2002,MATCH(33,일별현황!$L$6:$L$2005,0)),"") | C38: =IF($B38="","",IFERROR(INDEX(예약내역!$G$3:$G$2002,MATCH(33,일별현황!$L$6:$L$2005,0)),"")) | D38: =IFERROR(INDEX(예약내역!$C$3:$C$2002,MATCH(33,일별현황!$L$6:$L$2005,0)),"") | E38: =IF($D38="","",IFERROR(INDEX(예약내역!$D$3:$D$2002,MATCH(33,일별현황!$L$6:$L$2005,0)),"")) | F38: =IF($D38="","",IFERROR(INDEX(예약내역!$E$3:$E$2002,MATCH(33,일별현황!$L$6:$L$2005,0)),"")) | G38: =IF($D38="","",IFERROR(INDEX(예약내역!$I$3:$I$2002,MATCH(33,일별현황!$L$6:$L$2005,0)),"")) | H38: =IF($D38="","",IFERROR(INDEX(예약내역!$J$3:$J$2002,MATCH(33,일별현황!$L$6:$L$2005,0)),"")) | J38: =IF(예약내역!$A35="",FALSE(),AND(예약내역!$A35=$B$3,예약내역!$J35<>"취소")) -> FALSE | K38: =IF($J38=FALSE(),"",예약내역!$L35*10000+ROW()) | L38: =IF($K38="","",RANK($K38,$K$6:$K$2005,1))
A39: =IF($D39="","",34) | B39: =IFERROR(INDEX(예약내역!$F$3:$F$2002,MATCH(34,일별현황!$L$6:$L$2005,0)),"") | C39: =IF($B39="","",IFERROR(INDEX(예약내역!$G$3:$G$2002,MATCH(34,일별현황!$L$6:$L$2005,0)),"")) | D39: =IFERROR(INDEX(예약내역!$C$3:$C$2002,MATCH(34,일별현황!$L$6:$L$2005,0)),"") | E39: =IF($D39="","",IFERROR(INDEX(예약내역!$D$3:$D$2002,MATCH(34,일별현황!$L$6:$L$2005,0)),"")) | F39: =IF($D39="","",IFERROR(INDEX(예약내역!$E$3:$E$2002,MATCH(34,일별현황!$L$6:$L$2005,0)),"")) | G39: =IF($D39="","",IFERROR(INDEX(예약내역!$I$3:$I$2002,MATCH(34,일별현황!$L$6:$L$2005,0)),"")) | H39: =IF($D39="","",IFERROR(INDEX(예약내역!$J$3:$J$2002,MATCH(34,일별현황!$L$6:$L$2005,0)),"")) | J39: =IF(예약내역!$A36="",FALSE(),AND(예약내역!$A36=$B$3,예약내역!$J36<>"취소")) -> FALSE | K39: =IF($J39=FALSE(),"",예약내역!$L36*10000+ROW()) | L39: =IF($K39="","",RANK($K39,$K$6:$K$2005,1))
A40: =IF($D40="","",35) | B40: =IFERROR(INDEX(예약내역!$F$3:$F$2002,MATCH(35,일별현황!$L$6:$L$2005,0)),"") | C40: =IF($B40="","",IFERROR(INDEX(예약내역!$G$3:$G$2002,MATCH(35,일별현황!$L$6:$L$2005,0)),"")) | D40: =IFERROR(INDEX(예약내역!$C$3:$C$2002,MATCH(35,일별현황!$L$6:$L$2005,0)),"") | E40: =IF($D40="","",IFERROR(INDEX(예약내역!$D$3:$D$2002,MATCH(35,일별현황!$L$6:$L$2005,0)),"")) | F40: =IF($D40="","",IFERROR(INDEX(예약내역!$E$3:$E$2002,MATCH(35,일별현황!$L$6:$L$2005,0)),"")) | G40: =IF($D40="","",IFERROR(INDEX(예약내역!$I$3:$I$2002,MATCH(35,일별현황!$L$6:$L$2005,0)),"")) | H40: =IF($D40="","",IFERROR(INDEX(예약내역!$J$3:$J$2002,MATCH(35,일별현황!$L$6:$L$2005,0)),"")) | J40: =IF(예약내역!$A37="",FALSE(),AND(예약내역!$A37=$B$3,예약내역!$J37<>"취소")) -> FALSE | K40: =IF($J40=FALSE(),"",예약내역!$L37*10000+ROW()) | L40: =IF($K40="","",RANK($K40,$K$6:$K$2005,1))
A41: =IF($D41="","",36) | B41: =IFERROR(INDEX(예약내역!$F$3:$F$2002,MATCH(36,일별현황!$L$6:$L$2005,0)),"") | C41: =IF($B41="","",IFERROR(INDEX(예약내역!$G$3:$G$2002,MATCH(36,일별현황!$L$6:$L$2005,0)),"")) | D41: =IFERROR(INDEX(예약내역!$C$3:$C$2002,MATCH(36,일별현황!$L$6:$L$2005,0)),"") | E41: =IF($D41="","",IFERROR(INDEX(예약내역!$D$3:$D$2002,MATCH(36,일별현황!$L$6:$L$2005,0)),"")) | F41: =IF($D41="","",IFERROR(INDEX(예약내역!$E$3:$E$2002,MATCH(36,일별현황!$L$6:$L$2005,0)),"")) | G41: =IF($D41="","",IFERROR(INDEX(예약내역!$I$3:$I$2002,MATCH(36,일별현황!$L$6:$L$2005,0)),"")) | H41: =IF($D41="","",IFERROR(INDEX(예약내역!$J$3:$J$2002,MATCH(36,일별현황!$L$6:$L$2005,0)),"")) | J41: =IF(예약내역!$A38="",FALSE(),AND(예약내역!$A38=$B$3,예약내역!$J38<>"취소")) -> FALSE | K41: =IF($J41=FALSE(),"",예약내역!$L38*10000+ROW()) | L41: =IF($K41="","",RANK($K41,$K$6:$K$2005,1))
A42: =IF($D42="","",37) | B42: =IFERROR(INDEX(예약내역!$F$3:$F$2002,MATCH(37,일별현황!$L$6:$L$2005,0)),"") | C42: =IF($B42="","",IFERROR(INDEX(예약내역!$G$3:$G$2002,MATCH(37,일별현황!$L$6:$L$2005,0)),"")) | D42: =IFERROR(INDEX(예약내역!$C$3:$C$2002,MATCH(37,일별현황!$L$6:$L$2005,0)),"") | E42: =IF($D42="","",IFERROR(INDEX(예약내역!$D$3:$D$2002,MATCH(37,일별현황!$L$6:$L$2005,0)),"")) | F42: =IF($D42="","",IFERROR(INDEX(예약내역!$E$3:$E$2002,MATCH(37,일별현황!$L$6:$L$2005,0)),"")) | G42: =IF($D42="","",IFERROR(INDEX(예약내역!$I$3:$I$2002,MATCH(37,일별현황!$L$6:$L$2005,0)),"")) | H42: =IF($D42="","",IFERROR(INDEX(예약내역!$J$3:$J$2002,MATCH(37,일별현황!$L$6:$L$2005,0)),"")) | J42: =IF(예약내역!$A39="",FALSE(),AND(예약내역!$A39=$B$3,예약내역!$J39<>"취소")) -> FALSE | K42: =IF($J42=FALSE(),"",예약내역!$L39*10000+ROW()) | L42: =IF($K42="","",RANK($K42,$K$6:$K$2005,1))
...

Sheet 자원별현황
A1: 자원별현황
A3: 대상 연도 | B3: 2026 | C3: 대상 월 | D3: 9 | E3: ← 두 칸만 바꾸세요
A5: 자원코드 | B5: 자원명 | C5: 예약 건수 | D5: 총 이용시간 | E5: 취소 | F5: 노쇼 | G5: 중복
A6: =IF(자원목록!$A3="","",자원목록!$A3) -> R01 | B6: =IF($A6="","",자원목록!$B3) -> 1번 방 | C6: =IF($A6="","",COUNTIFS(예약내역!$B$3:$B$2002,$A6,예약내역!$J$3:$J$2002,"<>취소",예약내역!$A$3:$A$2002,">="&DATE($B$3,$D$3,1),예약내역!$A$3:$A$2002,"<="&EOMONTH(DATE($B$3,$D$3,1),0))) -> 3 | D6: =IF($A6="","",ROUND(SUMIFS(예약내역!$H$3:$H$2002,예약내역!$B$3:$B$2002,$A6,예약내역!$J$3:$J$2002,"<>취소",예약내역!$A$3:$A$2002,">="&DATE($B$3,$D$3,1),예약내역!$A$3:$A$2002,"<="&EOMONTH(DATE($B$3,$D$3,1),0)),2)) -> 5.5 | E6: =IF($A6="","",COUNTIFS(예약내역!$B$3:$B$2002,$A6,예약내역!$J$3:$J$2002,"취소",예약내역!$A$3:$A$2002,">="&DATE($B$3,$D$3,1),예약내역!$A$3:$A$2002,"<="&EOMONTH(DATE($B$3,$D$3,1),0))) -> 0 | F6: =IF($A6="","",COUNTIFS(예약내역!$B$3:$B$2002,$A6,예약내역!$J$3:$J$2002,"노쇼",예약내역!$A$3:$A$2002,">="&DATE($B$3,$D$3,1),예약내역!$A$3:$A$2002,"<="&EOMONTH(DATE($B$3,$D$3,1),0))) -> 0 | G6: =IF($A6="","",COUNTIFS(예약내역!$B$3:$B$2002,$A6,예약내역!$N$3:$N$2002,"중복",예약내역!$A$3:$A$2002,">="&DATE($B$3,$D$3,1),예약내역!$A$3:$A$2002,"<="&EOMONTH(DATE($B$3,$D$3,1),0))) -> 2
A7: =IF(자원목록!$A4="","",자원목록!$A4) -> R02 | B7: =IF($A7="","",자원목록!$B4) -> 2번 방 | C7: =IF($A7="","",COUNTIFS(예약내역!$B$3:$B$2002,$A7,예약내역!$J$3:$J$2002,"<>취소",예약내역!$A$3:$A$2002,">="&DATE($B$3,$D$3,1),예약내역!$A$3:$A$2002,"<="&EOMONTH(DATE($B$3,$D$3,1),0))) -> 1 | D7: =IF($A7="","",ROUND(SUMIFS(예약내역!$H$3:$H$2002,예약내역!$B$3:$B$2002,$A7,예약내역!$J$3:$J$2002,"<>취소",예약내역!$A$3:$A$2002,">="&DATE($B$3,$D$3,1),예약내역!$A$3:$A$2002,"<="&EOMONTH(DATE($B$3,$D$3,1),0)),2)) -> 2 | E7: =IF($A7="","",COUNTIFS(예약내역!$B$3:$B$2002,$A7,예약내역!$J$3:$J$2002,"취소",예약내역!$A$3:$A$2002,">="&DATE($B$3,$D$3,1),예약내역!$A$3:$A$2002,"<="&EOMONTH(DATE($B$3,$D$3,1),0))) -> 1 | F7: =IF($A7="","",COUNTIFS(예약내역!$B$3:$B$2002,$A7,예약내역!$J$3:$J$2002,"노쇼",예약내역!$A$3:$A$2002,">="&DATE($B$3,$D$3,1),예약내역!$A$3:$A$2002,"<="&EOMONTH(DATE($B$3,$D$3,1),0))) -> 0 | G7: =IF($A7="","",COUNTIFS(예약내역!$B$3:$B$2002,$A7,예약내역!$N$3:$N$2002,"중복",예약내역!$A$3:$A$2002,">="&DATE($B$3,$D$3,1),예약내역!$A$3:$A$2002,"<="&EOMONTH(DATE($B$3,$D$3,1),0))) -> 0
A8: =IF(자원목록!$A5="","",자원목록!$A5) -> R03 | B8: =IF($A8="","",자원목록!$B5) -> 세미나실 | C8: =IF($A8="","",COUNTIFS(예약내역!$B$3:$B$2002,$A8,예약내역!$J$3:$J$2002,"<>취소",예약내역!$A$3:$A$2002,">="&DATE($B$3,$D$3,1),예약내역!$A$3:$A$2002,"<="&EOMONTH(DATE($B$3,$D$3,1),0))) -> 2 | D8: =IF($A8="","",ROUND(SUMIFS(예약내역!$H$3:$H$2002,예약내역!$B$3:$B$2002,$A8,예약내역!$J$3:$J$2002,"<>취소",예약내역!$A$3:$A$2002,">="&DATE($B$3,$D$3,1),예약내역!$A$3:$A$2002,"<="&EOMONTH(DATE($B$3,$D$3,1),0)),2)) -> 6 | E8: =IF($A8="","",COUNTIFS(예약내역!$B$3:$B$2002,$A8,예약내역!$J$3:$J$2002,"취소",예약내역!$A$3:$A$2002,">="&DATE($B$3,$D$3,1),예약내역!$A$3:$A$2002,"<="&EOMONTH(DATE($B$3,$D$3,1),0))) -> 0 | F8: =IF($A8="","",COUNTIFS(예약내역!$B$3:$B$2002,$A8,예약내역!$J$3:$J$2002,"노쇼",예약내역!$A$3:$A$2002,">="&DATE($B$3,$D$3,1),예약내역!$A$3:$A$2002,"<="&EOMONTH(DATE($B$3,$D$3,1),0))) -> 1 | G8: =IF($A8="","",COUNTIFS(예약내역!$B$3:$B$2002,$A8,예약내역!$N$3:$N$2002,"중복",예약내역!$A$3:$A$2002,">="&DATE($B$3,$D$3,1),예약내역!$A$3:$A$2002,"<="&EOMONTH(DATE($B$3,$D$3,1),0))) -> 0
A9: =IF(자원목록!$A6="","",자원목록!$A6) -> E01 | B9: =IF($A9="","",자원목록!$B6) -> 빔프로젝터 | C9: =IF($A9="","",COUNTIFS(예약내역!$B$3:$B$2002,$A9,예약내역!$J$3:$J$2002,"<>취소",예약내역!$A$3:$A$2002,">="&DATE($B$3,$D$3,1),예약내역!$A$3:$A$2002,"<="&EOMONTH(DATE($B$3,$D$3,1),0))) -> 1 | D9: =IF($A9="","",ROUND(SUMIFS(예약내역!$H$3:$H$2002,예약내역!$B$3:$B$2002,$A9,예약내역!$J$3:$J$2002,"<>취소",예약내역!$A$3:$A$2002,">="&DATE($B$3,$D$3,1),예약내역!$A$3:$A$2002,"<="&EOMONTH(DATE($B$3,$D$3,1),0)),2)) -> 2 | E9: =IF($A9="","",COUNTIFS(예약내역!$B$3:$B$2002,$A9,예약내역!$J$3:$J$2002,"취소",예약내역!$A$3:$A$2002,">="&DATE($B$3,$D$3,1),예약내역!$A$3:$A$2002,"<="&EOMONTH(DATE($B$3,$D$3,1),0))) -> 0 | F9: =IF($A9="","",COUNTIFS(예약내역!$B$3:$B$2002,$A9,예약내역!$J$3:$J$2002,"노쇼",예약내역!$A$3:$A$2002,">="&DATE($B$3,$D$3,1),예약내역!$A$3:$A$2002,"<="&EOMONTH(DATE($B$3,$D$3,1),0))) -> 0 | G9: =IF($A9="","",COUNTIFS(예약내역!$B$3:$B$2002,$A9,예약내역!$N$3:$N$2002,"중복",예약내역!$A$3:$A$2002,">="&DATE($B$3,$D$3,1),예약내역!$A$3:$A$2002,"<="&EOMONTH(DATE($B$3,$D$3,1),0))) -> 0
A10: =IF(자원목록!$A7="","",자원목록!$A7) | B10: =IF($A10="","",자원목록!$B7) | C10: =IF($A10="","",COUNTIFS(예약내역!$B$3:$B$2002,$A10,예약내역!$J$3:$J$2002,"<>취소",예약내역!$A$3:$A$2002,">="&DATE($B$3,$D$3,1),예약내역!$A$3:$A$2002,"<="&EOMONTH(DATE($B$3,$D$3,1),0))) | D10: =IF($A10="","",ROUND(SUMIFS(예약내역!$H$3:$H$2002,예약내역!$B$3:$B$2002,$A10,예약내역!$J$3:$J$2002,"<>취소",예약내역!$A$3:$A$2002,">="&DATE($B$3,$D$3,1),예약내역!$A$3:$A$2002,"<="&EOMONTH(DATE($B$3,$D$3,1),0)),2)) | E10: =IF($A10="","",COUNTIFS(예약내역!$B$3:$B$2002,$A10,예약내역!$J$3:$J$2002,"취소",예약내역!$A$3:$A$2002,">="&DATE($B$3,$D$3,1),예약내역!$A$3:$A$2002,"<="&EOMONTH(DATE($B$3,$D$3,1),0))) | F10: =IF($A10="","",COUNTIFS(예약내역!$B$3:$B$2002,$A10,예약내역!$J$3:$J$2002,"노쇼",예약내역!$A$3:$A$2002,">="&DATE($B$3,$D$3,1),예약내역!$A$3:$A$2002,"<="&EOMONTH(DATE($B$3,$D$3,1),0))) | G10: =IF($A10="","",COUNTIFS(예약내역!$B$3:$B$2002,$A10,예약내역!$N$3:$N$2002,"중복",예약내역!$A$3:$A$2002,">="&DATE($B$3,$D$3,1),예약내역!$A$3:$A$2002,"<="&EOMONTH(DATE($B$3,$D$3,1),0)))
A11: =IF(자원목록!$A8="","",자원목록!$A8) | B11: =IF($A11="","",자원목록!$B8) | C11: =IF($A11="","",COUNTIFS(예약내역!$B$3:$B$2002,$A11,예약내역!$J$3:$J$2002,"<>취소",예약내역!$A$3:$A$2002,">="&DATE($B$3,$D$3,1),예약내역!$A$3:$A$2002,"<="&EOMONTH(DATE($B$3,$D$3,1),0))) | D11: =IF($A11="","",ROUND(SUMIFS(예약내역!$H$3:$H$2002,예약내역!$B$3:$B$2002,$A11,예약내역!$J$3:$J$2002,"<>취소",예약내역!$A$3:$A$2002,">="&DATE($B$3,$D$3,1),예약내역!$A$3:$A$2002,"<="&EOMONTH(DATE($B$3,$D$3,1),0)),2)) | E11: =IF($A11="","",COUNTIFS(예약내역!$B$3:$B$2002,$A11,예약내역!$J$3:$J$2002,"취소",예약내역!$A$3:$A$2002,">="&DATE($B$3,$D$3,1),예약내역!$A$3:$A$2002,"<="&EOMONTH(DATE($B$3,$D$3,1),0))) | F11: =IF($A11="","",COUNTIFS(예약내역!$B$3:$B$2002,$A11,예약내역!$J$3:$J$2002,"노쇼",예약내역!$A$3:$A$2002,">="&DATE($B$3,$D$3,1),예약내역!$A$3:$A$2002,"<="&EOMONTH(DATE($B$3,$D$3,1),0))) | G11: =IF($A11="","",COUNTIFS(예약내역!$B$3:$B$2002,$A11,예약내역!$N$3:$N$2002,"중복",예약내역!$A$3:$A$2002,">="&DATE($B$3,$D$3,1),예약내역!$A$3:$A$2002,"<="&EOMONTH(DATE($B$3,$D$3,1),0)))
A12: =IF(자원목록!$A9="","",자원목록!$A9) | B12: =IF($A12="","",자원목록!$B9) | C12: =IF($A12="","",COUNTIFS(예약내역!$B$3:$B$2002,$A12,예약내역!$J$3:$J$2002,"<>취소",예약내역!$A$3:$A$2002,">="&DATE($B$3,$D$3,1),예약내역!$A$3:$A$2002,"<="&EOMONTH(DATE($B$3,$D$3,1),0))) | D12: =IF($A12="","",ROUND(SUMIFS(예약내역!$H$3:$H$2002,예약내역!$B$3:$B$2002,$A12,예약내역!$J$3:$J$2002,"<>취소",예약내역!$A$3:$A$2002,">="&DATE($B$3,$D$3,1),예약내역!$A$3:$A$2002,"<="&EOMONTH(DATE($B$3,$D$3,1),0)),2)) | E12: =IF($A12="","",COUNTIFS(예약내역!$B$3:$B$2002,$A12,예약내역!$J$3:$J$2002,"취소",예약내역!$A$3:$A$2002,">="&DATE($B$3,$D$3,1),예약내역!$A$3:$A$2002,"<="&EOMONTH(DATE($B$3,$D$3,1),0))) | F12: =IF($A12="","",COUNTIFS(예약내역!$B$3:$B$2002,$A12,예약내역!$J$3:$J$2002,"노쇼",예약내역!$A$3:$A$2002,">="&DATE($B$3,$D$3,1),예약내역!$A$3:$A$2002,"<="&EOMONTH(DATE($B$3,$D$3,1),0))) | G12: =IF($A12="","",COUNTIFS(예약내역!$B$3:$B$2002,$A12,예약내역!$N$3:$N$2002,"중복",예약내역!$A$3:$A$2002,">="&DATE($B$3,$D$3,1),예약내역!$A$3:$A$2002,"<="&EOMONTH(DATE($B$3,$D$3,1),0)))
A13: =IF(자원목록!$A10="","",자원목록!$A10) | B13: =IF($A13="","",자원목록!$B10) | C13: =IF($A13="","",COUNTIFS(예약내역!$B$3:$B$2002,$A13,예약내역!$J$3:$J$2002,"<>취소",예약내역!$A$3:$A$2002,">="&DATE($B$3,$D$3,1),예약내역!$A$3:$A$2002,"<="&EOMONTH(DATE($B$3,$D$3,1),0))) | D13: =IF($A13="","",ROUND(SUMIFS(예약내역!$H$3:$H$2002,예약내역!$B$3:$B$2002,$A13,예약내역!$J$3:$J$2002,"<>취소",예약내역!$A$3:$A$2002,">="&DATE($B$3,$D$3,1),예약내역!$A$3:$A$2002,"<="&EOMONTH(DATE($B$3,$D$3,1),0)),2)) | E13: =IF($A13="","",COUNTIFS(예약내역!$B$3:$B$2002,$A13,예약내역!$J$3:$J$2002,"취소",예약내역!$A$3:$A$2002,">="&DATE($B$3,$D$3,1),예약내역!$A$3:$A$2002,"<="&EOMONTH(DATE($B$3,$D$3,1),0))) | F13: =IF($A13="","",COUNTIFS(예약내역!$B$3:$B$2002,$A13,예약내역!$J$3:$J$2002,"노쇼",예약내역!$A$3:$A$2002,">="&DATE($B$3,$D$3,1),예약내역!$A$3:$A$2002,"<="&EOMONTH(DATE($B$3,$D$3,1),0))) | G13: =IF($A13="","",COUNTIFS(예약내역!$B$3:$B$2002,$A13,예약내역!$N$3:$N$2002,"중복",예약내역!$A$3:$A$2002,">="&DATE($B$3,$D$3,1),예약내역!$A$3:$A$2002,"<="&EOMONTH(DATE($B$3,$D$3,1),0)))
A14: =IF(자원목록!$A11="","",자원목록!$A11) | B14: =IF($A14="","",자원목록!$B11) | C14: =IF($A14="","",COUNTIFS(예약내역!$B$3:$B$2002,$A14,예약내역!$J$3:$J$2002,"<>취소",예약내역!$A$3:$A$2002,">="&DATE($B$3,$D$3,1),예약내역!$A$3:$A$2002,"<="&EOMONTH(DATE($B$3,$D$3,1),0))) | D14: =IF($A14="","",ROUND(SUMIFS(예약내역!$H$3:$H$2002,예약내역!$B$3:$B$2002,$A14,예약내역!$J$3:$J$2002,"<>취소",예약내역!$A$3:$A$2002,">="&DATE($B$3,$D$3,1),예약내역!$A$3:$A$2002,"<="&EOMONTH(DATE($B$3,$D$3,1),0)),2)) | E14: =IF($A14="","",COUNTIFS(예약내역!$B$3:$B$2002,$A14,예약내역!$J$3:$J$2002,"취소",예약내역!$A$3:$A$2002,">="&DATE($B$3,$D$3,1),예약내역!$A$3:$A$2002,"<="&EOMONTH(DATE($B$3,$D$3,1),0))) | F14: =IF($A14="","",COUNTIFS(예약내역!$B$3:$B$2002,$A14,예약내역!$J$3:$J$2002,"노쇼",예약내역!$A$3:$A$2002,">="&DATE($B$3,$D$3,1),예약내역!$A$3:$A$2002,"<="&EOMONTH(DATE($B$3,$D$3,1),0))) | G14: =IF($A14="","",COUNTIFS(예약내역!$B$3:$B$2002,$A14,예약내역!$N$3:$N$2002,"중복",예약내역!$A$3:$A$2002,">="&DATE($B$3,$D$3,1),예약내역!$A$3:$A$2002,"<="&EOMONTH(DATE($B$3,$D$3,1),0)))
A15: =IF(자원목록!$A12="","",자원목록!$A12) | B15: =IF($A15="","",자원목록!$B12) | C15: =IF($A15="","",COUNTIFS(예약내역!$B$3:$B$2002,$A15,예약내역!$J$3:$J$2002,"<>취소",예약내역!$A$3:$A$2002,">="&DATE($B$3,$D$3,1),예약내역!$A$3:$A$2002,"<="&EOMONTH(DATE($B$3,$D$3,1),0))) | D15: =IF($A15="","",ROUND(SUMIFS(예약내역!$H$3:$H$2002,예약내역!$B$3:$B$2002,$A15,예약내역!$J$3:$J$2002,"<>취소",예약내역!$A$3:$A$2002,">="&DATE($B$3,$D$3,1),예약내역!$A$3:$A$2002,"<="&EOMONTH(DATE($B$3,$D$3,1),0)),2)) | E15: =IF($A15="","",COUNTIFS(예약내역!$B$3:$B$2002,$A15,예약내역!$J$3:$J$2002,"취소",예약내역!$A$3:$A$2002,">="&DATE($B$3,$D$3,1),예약내역!$A$3:$A$2002,"<="&EOMONTH(DATE($B$3,$D$3,1),0))) | F15: =IF($A15="","",COUNTIFS(예약내역!$B$3:$B$2002,$A15,예약내역!$J$3:$J$2002,"노쇼",예약내역!$A$3:$A$2002,">="&DATE($B$3,$D$3,1),예약내역!$A$3:$A$2002,"<="&EOMONTH(DATE($B$3,$D$3,1),0))) | G15: =IF($A15="","",COUNTIFS(예약내역!$B$3:$B$2002,$A15,예약내역!$N$3:$N$2002,"중복",예약내역!$A$3:$A$2002,">="&DATE($B$3,$D$3,1),예약내역!$A$3:$A$2002,"<="&EOMONTH(DATE($B$3,$D$3,1),0)))
A16: =IF(자원목록!$A13="","",자원목록!$A13) | B16: =IF($A16="","",자원목록!$B13) | C16: =IF($A16="","",COUNTIFS(예약내역!$B$3:$B$2002,$A16,예약내역!$J$3:$J$2002,"<>취소",예약내역!$A$3:$A$2002,">="&DATE($B$3,$D$3,1),예약내역!$A$3:$A$2002,"<="&EOMONTH(DATE($B$3,$D$3,1),0))) | D16: =IF($A16="","",ROUND(SUMIFS(예약내역!$H$3:$H$2002,예약내역!$B$3:$B$2002,$A16,예약내역!$J$3:$J$2002,"<>취소",예약내역!$A$3:$A$2002,">="&DATE($B$3,$D$3,1),예약내역!$A$3:$A$2002,"<="&EOMONTH(DATE($B$3,$D$3,1),0)),2)) | E16: =IF($A16="","",COUNTIFS(예약내역!$B$3:$B$2002,$A16,예약내역!$J$3:$J$2002,"취소",예약내역!$A$3:$A$2002,">="&DATE($B$3,$D$3,1),예약내역!$A$3:$A$2002,"<="&EOMONTH(DATE($B$3,$D$3,1),0))) | F16: =IF($A16="","",COUNTIFS(예약내역!$B$3:$B$2002,$A16,예약내역!$J$3:$J$2002,"노쇼",예약내역!$A$3:$A$2002,">="&DATE($B$3,$D$3,1),예약내역!$A$3:$A$2002,"<="&EOMONTH(DATE($B$3,$D$3,1),0))) | G16: =IF($A16="","",COUNTIFS(예약내역!$B$3:$B$2002,$A16,예약내역!$N$3:$N$2002,"중복",예약내역!$A$3:$A$2002,">="&DATE($B$3,$D$3,1),예약내역!$A$3:$A$2002,"<="&EOMONTH(DATE($B$3,$D$3,1),0)))
A17: =IF(자원목록!$A14="","",자원목록!$A14) | B17: =IF($A17="","",자원목록!$B14) | C17: =IF($A17="","",COUNTIFS(예약내역!$B$3:$B$2002,$A17,예약내역!$J$3:$J$2002,"<>취소",예약내역!$A$3:$A$2002,">="&DATE($B$3,$D$3,1),예약내역!$A$3:$A$2002,"<="&EOMONTH(DATE($B$3,$D$3,1),0))) | D17: =IF($A17="","",ROUND(SUMIFS(예약내역!$H$3:$H$2002,예약내역!$B$3:$B$2002,$A17,예약내역!$J$3:$J$2002,"<>취소",예약내역!$A$3:$A$2002,">="&DATE($B$3,$D$3,1),예약내역!$A$3:$A$2002,"<="&EOMONTH(DATE($B$3,$D$3,1),0)),2)) | E17: =IF($A17="","",COUNTIFS(예약내역!$B$3:$B$2002,$A17,예약내역!$J$3:$J$2002,"취소",예약내역!$A$3:$A$2002,">="&DATE($B$3,$D$3,1),예약내역!$A$3:$A$2002,"<="&EOMONTH(DATE($B$3,$D$3,1),0))) | F17: =IF($A17="","",COUNTIFS(예약내역!$B$3:$B$2002,$A17,예약내역!$J$3:$J$2002,"노쇼",예약내역!$A$3:$A$2002,">="&DATE($B$3,$D$3,1),예약내역!$A$3:$A$2002,"<="&EOMONTH(DATE($B$3,$D$3,1),0))) | G17: =IF($A17="","",COUNTIFS(예약내역!$B$3:$B$2002,$A17,예약내역!$N$3:$N$2002,"중복",예약내역!$A$3:$A$2002,">="&DATE($B$3,$D$3,1),예약내역!$A$3:$A$2002,"<="&EOMONTH(DATE($B$3,$D$3,1),0)))
... A105: =IF(자원목록!$A102="","",자원목록!$A102) | B105: =IF($A105="","",자원목록!$B102) | C105: =IF($A105="","",COUNTIFS(예약내역!$B$3:$B$2002,$A105,예약내역!$J$3:$J$2002,"<>취소",예약내역!$A$3:$A$2002,">="&DATE($B$3,$D$3,1),예약내역!$A$3:$A$2002,"<="&EOMONTH(DATE($B$3,$D$3,1),0))) | D105: =IF($A105="","",ROUND(SUMIFS(예약내역!$H$3:$H$2002,예약내역!$B$3:$B$2002,$A105,예약내역!$J$3:$J$2002,"<>취소",예약내역!$A$3:$A$2002,">="&DATE($B$3,$D$3,1),예약내역!$A$3:$A$2002,"<="&EOMONTH(DATE($B$3,$D$3,1),0)),2)) | E105: =IF($A105="","",COUNTIFS(예약내역!$B$3:$B$2002,$A105,예약내역!$J$3:$J$2002,"취소",예약내역!$A$3:$A$2002,">="&DATE($B$3,$D$3,1),예약내역!$A$3:$A$2002,"<="&EOMONTH(DATE($B$3,$D$3,1),0))) | F105: =IF($A105="","",COUNTIFS(예약내역!$B$3:$B$2002,$A105,예약내역!$J$3:$J$2002,"노쇼",예약내역!$A$3:$A$2002,">="&DATE($B$3,$D$3,1),예약내역!$A$3:$A$2002,"<="&EOMONTH(DATE($B$3,$D$3,1),0))) | G105: =IF($A105="","",COUNTIFS(예약내역!$B$3:$B$2002,$A105,예약내역!$N$3:$N$2002,"중복",예약내역!$A$3:$A$2002,">="&DATE($B$3,$D$3,1),예약내역!$A$3:$A$2002,"<="&EOMONTH(DATE($B$3,$D$3,1),0)))
B107: 합계 | C107: =SUM(C6:C105) -> 7 | D107: =SUM(D6:D105) -> 15.5 | E107: =SUM(E6:E105) -> 1 | F107: =SUM(F6:F105) -> 1 | G107: =SUM(G6:G105) -> 2

Sheet 월별집계
A1: 월별집계
A3: 대상 연도 | B3: 2026
A5: 월 | B5: 예약 | C5: 완료 | D5: 취소 | E5: 노쇼 | F5: 총 이용시간 | G5: 노쇼율
A6: 1 | B6: =COUNTIFS(예약내역!$A$3:$A$2002,">="&DATE($B$3,1,1),예약내역!$A$3:$A$2002,"<="&EOMONTH(DATE($B$3,1,1),0)) -> 0 | C6: =COUNTIFS(예약내역!$J$3:$J$2002,"완료",예약내역!$A$3:$A$2002,">="&DATE($B$3,1,1),예약내역!$A$3:$A$2002,"<="&EOMONTH(DATE($B$3,1,1),0)) -> 0 | D6: =COUNTIFS(예약내역!$J$3:$J$2002,"취소",예약내역!$A$3:$A$2002,">="&DATE($B$3,1,1),예약내역!$A$3:$A$2002,"<="&EOMONTH(DATE($B$3,1,1),0)) -> 0 | E6: =COUNTIFS(예약내역!$J$3:$J$2002,"노쇼",예약내역!$A$3:$A$2002,">="&DATE($B$3,1,1),예약내역!$A$3:$A$2002,"<="&EOMONTH(DATE($B$3,1,1),0)) -> 0 | F6: =ROUND(SUMIFS(예약내역!$H$3:$H$2002,예약내역!$J$3:$J$2002,"<>취소",예약내역!$A$3:$A$2002,">="&DATE($B$3,1,1),예약내역!$A$3:$A$2002,"<="&EOMONTH(DATE($B$3,1,1),0)),2) -> 0 | G6: =IF($B6=0,"",$E6/$B6)
A7: 2 | B7: =COUNTIFS(예약내역!$A$3:$A$2002,">="&DATE($B$3,2,1),예약내역!$A$3:$A$2002,"<="&EOMONTH(DATE($B$3,2,1),0)) -> 0 | C7: =COUNTIFS(예약내역!$J$3:$J$2002,"완료",예약내역!$A$3:$A$2002,">="&DATE($B$3,2,1),예약내역!$A$3:$A$2002,"<="&EOMONTH(DATE($B$3,2,1),0)) -> 0 | D7: =COUNTIFS(예약내역!$J$3:$J$2002,"취소",예약내역!$A$3:$A$2002,">="&DATE($B$3,2,1),예약내역!$A$3:$A$2002,"<="&EOMONTH(DATE($B$3,2,1),0)) -> 0 | E7: =COUNTIFS(예약내역!$J$3:$J$2002,"노쇼",예약내역!$A$3:$A$2002,">="&DATE($B$3,2,1),예약내역!$A$3:$A$2002,"<="&EOMONTH(DATE($B$3,2,1),0)) -> 0 | F7: =ROUND(SUMIFS(예약내역!$H$3:$H$2002,예약내역!$J$3:$J$2002,"<>취소",예약내역!$A$3:$A$2002,">="&DATE($B$3,2,1),예약내역!$A$3:$A$2002,"<="&EOMONTH(DATE($B$3,2,1),0)),2) -> 0 | G7: =IF($B7=0,"",$E7/$B7)
