Workbook

Sheet 사용안내
B2: 농산물 전화주문 · 입금확인 · 택배송장 관리
B4: 핵심 | C4: 고객을 한 번 등록하면 다음 주문부터 이름·연락처·주소가 자동으로 붙습니다.
B5: 입력 규칙 | C5: 파란색 글씨 칸만 입력하세요. 검은색은 자동 계산입니다.
B6: ① 고객명부 | C6: 전화 주문을 받으면 고객번호를 부여해 등록합니다. 단골은 한 번만 등록하면 됩니다.
B7: ② 상품목록 | C7: 판매 상품의 규격·단가를 등록합니다.
B8: ③ 주문접수 | C8: 주문마다 한 줄. 고객번호와 상품만 고르면 주소·단가가 자동으로 채워집니다.
C9: 입금일을 넣으면 '입금완료'로 바뀌고, 송장번호를 넣으면 '발송완료'가 됩니다.
B10: ④ 택배송장 | C10: 주문번호를 고르면 받는사람·주소·상품이 채워집니다. 그대로 인쇄하세요.
B11: ⑤ 고객히스토리 | C11: 고객번호를 고르면 그 고객의 과거 주문이 전부 나옵니다.
B12: ⑥ 일별현황 | C12: 날짜를 고르면 그날 주문·입금·발송 건수와 금액이 나옵니다.
B13: 주문번호 | C13: 비워두면 자동으로 매겨집니다. 직접 넣어도 됩니다.
B15: ※ PC 두 대에서 동시에 쓰려면 이 파일을 공유 폴더(OneDrive 등)에 두세요. 다만 동시에 편집하면 충돌이 날 수 있어 한 번에 한 명만 쓰는 것을 권장합니다.

Sheet 고객명부
A1: 고객명부 (한 번 등록하면 다음 주문부터 자동으로 불러옵니다)
A2: 고객번호 | B2: 고객명 | C2: 연락처 | D2: 우편번호 | E2: 주소 | F2: 상세주소 | G2: 비고
A3: 1001 | B3: 김고객 | C3: 010-0000-0000 | D3: 12345 | E3: 서울시 ○○구 ○○로 10 | F3: 101동 101호 | G3: ← 예시 행
A4: 1002 | B4: 이고객 | C4: 010-0000-0002 | D4: 54321 | E4: 부산시 ○○구 ○○로 20 | F4: 202동 303호

Sheet 상품목록
A1: 상품목록
A2: 상품명 | B2: 규격 | C2: 단가 | D2: 비고
A3: 사과 부사 5kg | B3: 5kg (특) | C3: 35000
A4: 사과 부사 10kg | B4: 10kg (상) | C4: 55000
A5: 배 신고 7.5kg | B5: 7.5kg | C5: 48000

Sheet 주문접수
A1: 주문접수 (고객번호·상품·수량만 고르면 나머지 자동)
A2: 주문번호(자동) | B2: 주문일 | C2: 고객번호 | D2: 고객명(자동) | E2: 연락처(자동) | F2: 우편번호(자동) | G2: 주소(자동) | H2: 상품명 | I2: 규격(자동) | J2: 단가(자동) | K2: 수량 | L2: 주문금액(자동) | M2: 택배비 | N2: 합계(자동) | O2: 입금일 | P2: 송장번호 | Q2: 상태(자동) | R2: 고객순번(자동) | S2: 고객키(자동)
A3: =IF($C3="","",TEXT($B3,"yymmdd")&"-"&TEXT(COUNTIFS($B$3:$B3,$B3),"000")) -> 260903-001 | B3: 46268 | C3: 1001 | D3: =IF($C3="","",IFERROR(INDEX(고객명부!$B$3:$B$502,MATCH($C3,고객명부!$A$3:$A$502,0)),"미등록고객")) -> 김고객 | E3: =IF($C3="","",IFERROR(INDEX(고객명부!$C$3:$C$502,MATCH($C3,고객명부!$A$3:$A$502,0)),"")) -> 010-0000-0000 | F3: =IF($C3="","",IFERROR(INDEX(고객명부!$D$3:$D$502,MATCH($C3,고객명부!$A$3:$A$502,0)),"")) -> 12345 | G3: =IF($C3="","",IFERROR(INDEX(고객명부!$E$3:$E$502,MATCH($C3,고객명부!$A$3:$A$502,0))&" "&INDEX(고객명부!$F$3:$F$502,MATCH($C3,고객명부!$A$3:$A$502,0)),"")) -> 서울시 ○○구 ○○로 10 101동 101호 | H3: 사과 부사 5kg | I3: =IF($H3="","",IFERROR(INDEX(상품목록!$B$3:$B$102,MATCH($H3,상품목록!$A$3:$A$102,0)),"")) -> 5kg (특) | J3: =IF($H3="","",IFERROR(INDEX(상품목록!$C$3:$C$102,MATCH($H3,상품목록!$A$3:$A$102,0)),0)) -> 35000 | K3: 2 | L3: =IF(OR($J3="",$K3=""),"",ROUND($J3*$K3,0)) -> 70000 | M3: 3500 | N3: =IF($L3="","",$L3+IF($M3="",0,$M3)) -> 73500 | O3: 46268 | P3: 1234567890 | Q3: =IF($C3="","",IF($P3<>"","발송완료",IF($O3<>"","입금완료","입금대기"))) -> 발송완료 | R3: =IF($C3="","",COUNTIFS($C$3:$C3,$C3)) -> 1 | S3: =IF($C3="","",$C3&"|"&$R3) -> 1001|1
A4: =IF($C4="","",TEXT($B4,"yymmdd")&"-"&TEXT(COUNTIFS($B$3:$B4,$B4),"000")) -> 260903-002 | B4: 46268 | C4: 1002 | D4: =IF($C4="","",IFERROR(INDEX(고객명부!$B$3:$B$502,MATCH($C4,고객명부!$A$3:$A$502,0)),"미등록고객")) -> 이고객 | E4: =IF($C4="","",IFERROR(INDEX(고객명부!$C$3:$C$502,MATCH($C4,고객명부!$A$3:$A$502,0)),"")) -> 010-0000-0002 | F4: =IF($C4="","",IFERROR(INDEX(고객명부!$D$3:$D$502,MATCH($C4,고객명부!$A$3:$A$502,0)),"")) -> 54321 | G4: =IF($C4="","",IFERROR(INDEX(고객명부!$E$3:$E$502,MATCH($C4,고객명부!$A$3:$A$502,0))&" "&INDEX(고객명부!$F$3:$F$502,MATCH($C4,고객명부!$A$3:$A$502,0)),"")) -> 부산시 ○○구 ○○로 20 202동 303호 | H4: 배 신고 7.5kg | I4: =IF($H4="","",IFERROR(INDEX(상품목록!$B$3:$B$102,MATCH($H4,상품목록!$A$3:$A$102,0)),"")) -> 7.5kg | J4: =IF($H4="","",IFERROR(INDEX(상품목록!$C$3:$C$102,MATCH($H4,상품목록!$A$3:$A$102,0)),0)) -> 48000 | K4: 1 | L4: =IF(OR($J4="",$K4=""),"",ROUND($J4*$K4,0)) -> 48000 | M4: 3500 | N4: =IF($L4="","",$L4+IF($M4="",0,$M4)) -> 51500 | O4: 46269 | P4: 1234567891 | Q4: =IF($C4="","",IF($P4<>"","발송완료",IF($O4<>"","입금완료","입금대기"))) -> 발송완료 | R4: =IF($C4="","",COUNTIFS($C$3:$C4,$C4)) -> 1 | S4: =IF($C4="","",$C4&"|"&$R4) -> 1002|1
A5: =IF($C5="","",TEXT($B5,"yymmdd")&"-"&TEXT(COUNTIFS($B$3:$B5,$B5),"000")) -> 260909-001 | B5: 46274 | C5: 1001 | D5: =IF($C5="","",IFERROR(INDEX(고객명부!$B$3:$B$502,MATCH($C5,고객명부!$A$3:$A$502,0)),"미등록고객")) -> 김고객 | E5: =IF($C5="","",IFERROR(INDEX(고객명부!$C$3:$C$502,MATCH($C5,고객명부!$A$3:$A$502,0)),"")) -> 010-0000-0000 | F5: =IF($C5="","",IFERROR(INDEX(고객명부!$D$3:$D$502,MATCH($C5,고객명부!$A$3:$A$502,0)),"")) -> 12345 | G5: =IF($C5="","",IFERROR(INDEX(고객명부!$E$3:$E$502,MATCH($C5,고객명부!$A$3:$A$502,0))&" "&INDEX(고객명부!$F$3:$F$502,MATCH($C5,고객명부!$A$3:$A$502,0)),"")) -> 서울시 ○○구 ○○로 10 101동 101호 | H5: 사과 부사 10kg | I5: =IF($H5="","",IFERROR(INDEX(상품목록!$B$3:$B$102,MATCH($H5,상품목록!$A$3:$A$102,0)),"")) -> 10kg (상) | J5: =IF($H5="","",IFERROR(INDEX(상품목록!$C$3:$C$102,MATCH($H5,상품목록!$A$3:$A$102,0)),0)) -> 55000 | K5: 1 | L5: =IF(OR($J5="",$K5=""),"",ROUND($J5*$K5,0)) -> 55000 | M5: 3500 | N5: =IF($L5="","",$L5+IF($M5="",0,$M5)) -> 58500 | O5: 46274 | Q5: =IF($C5="","",IF($P5<>"","발송완료",IF($O5<>"","입금완료","입금대기"))) -> 입금완료 | R5: =IF($C5="","",COUNTIFS($C$3:$C5,$C5)) -> 2 | S5: =IF($C5="","",$C5&"|"&$R5) -> 1001|2
A6: =IF($C6="","",TEXT($B6,"yymmdd")&"-"&TEXT(COUNTIFS($B$3:$B6,$B6),"000")) -> 260912-001 | B6: 46277 | C6: 1002 | D6: =IF($C6="","",IFERROR(INDEX(고객명부!$B$3:$B$502,MATCH($C6,고객명부!$A$3:$A$502,0)),"미등록고객")) -> 이고객 | E6: =IF($C6="","",IFERROR(INDEX(고객명부!$C$3:$C$502,MATCH($C6,고객명부!$A$3:$A$502,0)),"")) -> 010-0000-0002 | F6: =IF($C6="","",IFERROR(INDEX(고객명부!$D$3:$D$502,MATCH($C6,고객명부!$A$3:$A$502,0)),"")) -> 54321 | G6: =IF($C6="","",IFERROR(INDEX(고객명부!$E$3:$E$502,MATCH($C6,고객명부!$A$3:$A$502,0))&" "&INDEX(고객명부!$F$3:$F$502,MATCH($C6,고객명부!$A$3:$A$502,0)),"")) -> 부산시 ○○구 ○○로 20 202동 303호 | H6: 사과 부사 5kg | I6: =IF($H6="","",IFERROR(INDEX(상품목록!$B$3:$B$102,MATCH($H6,상품목록!$A$3:$A$102,0)),"")) -> 5kg (특) | J6: =IF($H6="","",IFERROR(INDEX(상품목록!$C$3:$C$102,MATCH($H6,상품목록!$A$3:$A$102,0)),0)) -> 35000 | K6: 3 | L6: =IF(OR($J6="",$K6=""),"",ROUND($J6*$K6,0)) -> 105000 | M6: 0 | N6: =IF($L6="","",$L6+IF($M6="",0,$M6)) -> 105000 | Q6: =IF($C6="","",IF($P6<>"","발송완료",IF($O6<>"","입금완료","입금대기"))) -> 입금대기 | R6: =IF($C6="","",COUNTIFS($C$3:$C6,$C6)) -> 2 | S6: =IF($C6="","",$C6&"|"&$R6) -> 1002|2
A7: =IF($C7="","",TEXT($B7,"yymmdd")&"-"&TEXT(COUNTIFS($B$3:$B7,$B7),"000")) | D7: =IF($C7="","",IFERROR(INDEX(고객명부!$B$3:$B$502,MATCH($C7,고객명부!$A$3:$A$502,0)),"미등록고객")) | E7: =IF($C7="","",IFERROR(INDEX(고객명부!$C$3:$C$502,MATCH($C7,고객명부!$A$3:$A$502,0)),"")) | F7: =IF($C7="","",IFERROR(INDEX(고객명부!$D$3:$D$502,MATCH($C7,고객명부!$A$3:$A$502,0)),"")) | G7: =IF($C7="","",IFERROR(INDEX(고객명부!$E$3:$E$502,MATCH($C7,고객명부!$A$3:$A$502,0))&" "&INDEX(고객명부!$F$3:$F$502,MATCH($C7,고객명부!$A$3:$A$502,0)),"")) | I7: =IF($H7="","",IFERROR(INDEX(상품목록!$B$3:$B$102,MATCH($H7,상품목록!$A$3:$A$102,0)),"")) | J7: =IF($H7="","",IFERROR(INDEX(상품목록!$C$3:$C$102,MATCH($H7,상품목록!$A$3:$A$102,0)),0)) | L7: =IF(OR($J7="",$K7=""),"",ROUND($J7*$K7,0)) | N7: =IF($L7="","",$L7+IF($M7="",0,$M7)) | Q7: =IF($C7="","",IF($P7<>"","발송완료",IF($O7<>"","입금완료","입금대기"))) | R7: =IF($C7="","",COUNTIFS($C$3:$C7,$C7)) | S7: =IF($C7="","",$C7&"|"&$R7)
A8: =IF($C8="","",TEXT($B8,"yymmdd")&"-"&TEXT(COUNTIFS($B$3:$B8,$B8),"000")) | D8: =IF($C8="","",IFERROR(INDEX(고객명부!$B$3:$B$502,MATCH($C8,고객명부!$A$3:$A$502,0)),"미등록고객")) | E8: =IF($C8="","",IFERROR(INDEX(고객명부!$C$3:$C$502,MATCH($C8,고객명부!$A$3:$A$502,0)),"")) | F8: =IF($C8="","",IFERROR(INDEX(고객명부!$D$3:$D$502,MATCH($C8,고객명부!$A$3:$A$502,0)),"")) | G8: =IF($C8="","",IFERROR(INDEX(고객명부!$E$3:$E$502,MATCH($C8,고객명부!$A$3:$A$502,0))&" "&INDEX(고객명부!$F$3:$F$502,MATCH($C8,고객명부!$A$3:$A$502,0)),"")) | I8: =IF($H8="","",IFERROR(INDEX(상품목록!$B$3:$B$102,MATCH($H8,상품목록!$A$3:$A$102,0)),"")) | J8: =IF($H8="","",IFERROR(INDEX(상품목록!$C$3:$C$102,MATCH($H8,상품목록!$A$3:$A$102,0)),0)) | L8: =IF(OR($J8="",$K8=""),"",ROUND($J8*$K8,0)) | N8: =IF($L8="","",$L8+IF($M8="",0,$M8)) | Q8: =IF($C8="","",IF($P8<>"","발송완료",IF($O8<>"","입금완료","입금대기"))) | R8: =IF($C8="","",COUNTIFS($C$3:$C8,$C8)) | S8: =IF($C8="","",$C8&"|"&$R8)
A9: =IF($C9="","",TEXT($B9,"yymmdd")&"-"&TEXT(COUNTIFS($B$3:$B9,$B9),"000")) | D9: =IF($C9="","",IFERROR(INDEX(고객명부!$B$3:$B$502,MATCH($C9,고객명부!$A$3:$A$502,0)),"미등록고객")) | E9: =IF($C9="","",IFERROR(INDEX(고객명부!$C$3:$C$502,MATCH($C9,고객명부!$A$3:$A$502,0)),"")) | F9: =IF($C9="","",IFERROR(INDEX(고객명부!$D$3:$D$502,MATCH($C9,고객명부!$A$3:$A$502,0)),"")) | G9: =IF($C9="","",IFERROR(INDEX(고객명부!$E$3:$E$502,MATCH($C9,고객명부!$A$3:$A$502,0))&" "&INDEX(고객명부!$F$3:$F$502,MATCH($C9,고객명부!$A$3:$A$502,0)),"")) | I9: =IF($H9="","",IFERROR(INDEX(상품목록!$B$3:$B$102,MATCH($H9,상품목록!$A$3:$A$102,0)),"")) | J9: =IF($H9="","",IFERROR(INDEX(상품목록!$C$3:$C$102,MATCH($H9,상품목록!$A$3:$A$102,0)),0)) | L9: =IF(OR($J9="",$K9=""),"",ROUND($J9*$K9,0)) | N9: =IF($L9="","",$L9+IF($M9="",0,$M9)) | Q9: =IF($C9="","",IF($P9<>"","발송완료",IF($O9<>"","입금완료","입금대기"))) | R9: =IF($C9="","",COUNTIFS($C$3:$C9,$C9)) | S9: =IF($C9="","",$C9&"|"&$R9)
A10: =IF($C10="","",TEXT($B10,"yymmdd")&"-"&TEXT(COUNTIFS($B$3:$B10,$B10),"000")) | D10: =IF($C10="","",IFERROR(INDEX(고객명부!$B$3:$B$502,MATCH($C10,고객명부!$A$3:$A$502,0)),"미등록고객")) | E10: =IF($C10="","",IFERROR(INDEX(고객명부!$C$3:$C$502,MATCH($C10,고객명부!$A$3:$A$502,0)),"")) | F10: =IF($C10="","",IFERROR(INDEX(고객명부!$D$3:$D$502,MATCH($C10,고객명부!$A$3:$A$502,0)),"")) | G10: =IF($C10="","",IFERROR(INDEX(고객명부!$E$3:$E$502,MATCH($C10,고객명부!$A$3:$A$502,0))&" "&INDEX(고객명부!$F$3:$F$502,MATCH($C10,고객명부!$A$3:$A$502,0)),"")) | I10: =IF($H10="","",IFERROR(INDEX(상품목록!$B$3:$B$102,MATCH($H10,상품목록!$A$3:$A$102,0)),"")) | J10: =IF($H10="","",IFERROR(INDEX(상품목록!$C$3:$C$102,MATCH($H10,상품목록!$A$3:$A$102,0)),0)) | L10: =IF(OR($J10="",$K10=""),"",ROUND($J10*$K10,0)) | N10: =IF($L10="","",$L10+IF($M10="",0,$M10)) | Q10: =IF($C10="","",IF($P10<>"","발송완료",IF($O10<>"","입금완료","입금대기"))) | R10: =IF($C10="","",COUNTIFS($C$3:$C10,$C10)) | S10: =IF($C10="","",$C10&"|"&$R10)
A11: =IF($C11="","",TEXT($B11,"yymmdd")&"-"&TEXT(COUNTIFS($B$3:$B11,$B11),"000")) | D11: =IF($C11="","",IFERROR(INDEX(고객명부!$B$3:$B$502,MATCH($C11,고객명부!$A$3:$A$502,0)),"미등록고객")) | E11: =IF($C11="","",IFERROR(INDEX(고객명부!$C$3:$C$502,MATCH($C11,고객명부!$A$3:$A$502,0)),"")) | F11: =IF($C11="","",IFERROR(INDEX(고객명부!$D$3:$D$502,MATCH($C11,고객명부!$A$3:$A$502,0)),"")) | G11: =IF($C11="","",IFERROR(INDEX(고객명부!$E$3:$E$502,MATCH($C11,고객명부!$A$3:$A$502,0))&" "&INDEX(고객명부!$F$3:$F$502,MATCH($C11,고객명부!$A$3:$A$502,0)),"")) | I11: =IF($H11="","",IFERROR(INDEX(상품목록!$B$3:$B$102,MATCH($H11,상품목록!$A$3:$A$102,0)),"")) | J11: =IF($H11="","",IFERROR(INDEX(상품목록!$C$3:$C$102,MATCH($H11,상품목록!$A$3:$A$102,0)),0)) | L11: =IF(OR($J11="",$K11=""),"",ROUND($J11*$K11,0)) | N11: =IF($L11="","",$L11+IF($M11="",0,$M11)) | Q11: =IF($C11="","",IF($P11<>"","발송완료",IF($O11<>"","입금완료","입금대기"))) | R11: =IF($C11="","",COUNTIFS($C$3:$C11,$C11)) | S11: =IF($C11="","",$C11&"|"&$R11)
A12: =IF($C12="","",TEXT($B12,"yymmdd")&"-"&TEXT(COUNTIFS($B$3:$B12,$B12),"000")) | D12: =IF($C12="","",IFERROR(INDEX(고객명부!$B$3:$B$502,MATCH($C12,고객명부!$A$3:$A$502,0)),"미등록고객")) | E12: =IF($C12="","",IFERROR(INDEX(고객명부!$C$3:$C$502,MATCH($C12,고객명부!$A$3:$A$502,0)),"")) | F12: =IF($C12="","",IFERROR(INDEX(고객명부!$D$3:$D$502,MATCH($C12,고객명부!$A$3:$A$502,0)),"")) | G12: =IF($C12="","",IFERROR(INDEX(고객명부!$E$3:$E$502,MATCH($C12,고객명부!$A$3:$A$502,0))&" "&INDEX(고객명부!$F$3:$F$502,MATCH($C12,고객명부!$A$3:$A$502,0)),"")) | I12: =IF($H12="","",IFERROR(INDEX(상품목록!$B$3:$B$102,MATCH($H12,상품목록!$A$3:$A$102,0)),"")) | J12: =IF($H12="","",IFERROR(INDEX(상품목록!$C$3:$C$102,MATCH($H12,상품목록!$A$3:$A$102,0)),0)) | L12: =IF(OR($J12="",$K12=""),"",ROUND($J12*$K12,0)) | N12: =IF($L12="","",$L12+IF($M12="",0,$M12)) | Q12: =IF($C12="","",IF($P12<>"","발송완료",IF($O12<>"","입금완료","입금대기"))) | R12: =IF($C12="","",COUNTIFS($C$3:$C12,$C12)) | S12: =IF($C12="","",$C12&"|"&$R12)
A13: =IF($C13="","",TEXT($B13,"yymmdd")&"-"&TEXT(COUNTIFS($B$3:$B13,$B13),"000")) | D13: =IF($C13="","",IFERROR(INDEX(고객명부!$B$3:$B$502,MATCH($C13,고객명부!$A$3:$A$502,0)),"미등록고객")) | E13: =IF($C13="","",IFERROR(INDEX(고객명부!$C$3:$C$502,MATCH($C13,고객명부!$A$3:$A$502,0)),"")) | F13: =IF($C13="","",IFERROR(INDEX(고객명부!$D$3:$D$502,MATCH($C13,고객명부!$A$3:$A$502,0)),"")) | G13: =IF($C13="","",IFERROR(INDEX(고객명부!$E$3:$E$502,MATCH($C13,고객명부!$A$3:$A$502,0))&" "&INDEX(고객명부!$F$3:$F$502,MATCH($C13,고객명부!$A$3:$A$502,0)),"")) | I13: =IF($H13="","",IFERROR(INDEX(상품목록!$B$3:$B$102,MATCH($H13,상품목록!$A$3:$A$102,0)),"")) | J13: =IF($H13="","",IFERROR(INDEX(상품목록!$C$3:$C$102,MATCH($H13,상품목록!$A$3:$A$102,0)),0)) | L13: =IF(OR($J13="",$K13=""),"",ROUND($J13*$K13,0)) | N13: =IF($L13="","",$L13+IF($M13="",0,$M13)) | Q13: =IF($C13="","",IF($P13<>"","발송완료",IF($O13<>"","입금완료","입금대기"))) | R13: =IF($C13="","",COUNTIFS($C$3:$C13,$C13)) | S13: =IF($C13="","",$C13&"|"&$R13)
A14: =IF($C14="","",TEXT($B14,"yymmdd")&"-"&TEXT(COUNTIFS($B$3:$B14,$B14),"000")) | D14: =IF($C14="","",IFERROR(INDEX(고객명부!$B$3:$B$502,MATCH($C14,고객명부!$A$3:$A$502,0)),"미등록고객")) | E14: =IF($C14="","",IFERROR(INDEX(고객명부!$C$3:$C$502,MATCH($C14,고객명부!$A$3:$A$502,0)),"")) | F14: =IF($C14="","",IFERROR(INDEX(고객명부!$D$3:$D$502,MATCH($C14,고객명부!$A$3:$A$502,0)),"")) | G14: =IF($C14="","",IFERROR(INDEX(고객명부!$E$3:$E$502,MATCH($C14,고객명부!$A$3:$A$502,0))&" "&INDEX(고객명부!$F$3:$F$502,MATCH($C14,고객명부!$A$3:$A$502,0)),"")) | I14: =IF($H14="","",IFERROR(INDEX(상품목록!$B$3:$B$102,MATCH($H14,상품목록!$A$3:$A$102,0)),"")) | J14: =IF($H14="","",IFERROR(INDEX(상품목록!$C$3:$C$102,MATCH($H14,상품목록!$A$3:$A$102,0)),0)) | L14: =IF(OR($J14="",$K14=""),"",ROUND($J14*$K14,0)) | N14: =IF($L14="","",$L14+IF($M14="",0,$M14)) | Q14: =IF($C14="","",IF($P14<>"","발송완료",IF($O14<>"","입금완료","입금대기"))) | R14: =IF($C14="","",COUNTIFS($C$3:$C14,$C14)) | S14: =IF($C14="","",$C14&"|"&$R14)
A15: =IF($C15="","",TEXT($B15,"yymmdd")&"-"&TEXT(COUNTIFS($B$3:$B15,$B15),"000")) | D15: =IF($C15="","",IFERROR(INDEX(고객명부!$B$3:$B$502,MATCH($C15,고객명부!$A$3:$A$502,0)),"미등록고객")) | E15: =IF($C15="","",IFERROR(INDEX(고객명부!$C$3:$C$502,MATCH($C15,고객명부!$A$3:$A$502,0)),"")) | F15: =IF($C15="","",IFERROR(INDEX(고객명부!$D$3:$D$502,MATCH($C15,고객명부!$A$3:$A$502,0)),"")) | G15: =IF($C15="","",IFERROR(INDEX(고객명부!$E$3:$E$502,MATCH($C15,고객명부!$A$3:$A$502,0))&" "&INDEX(고객명부!$F$3:$F$502,MATCH($C15,고객명부!$A$3:$A$502,0)),"")) | I15: =IF($H15="","",IFERROR(INDEX(상품목록!$B$3:$B$102,MATCH($H15,상품목록!$A$3:$A$102,0)),"")) | J15: =IF($H15="","",IFERROR(INDEX(상품목록!$C$3:$C$102,MATCH($H15,상품목록!$A$3:$A$102,0)),0)) | L15: =IF(OR($J15="",$K15=""),"",ROUND($J15*$K15,0)) | N15: =IF($L15="","",$L15+IF($M15="",0,$M15)) | Q15: =IF($C15="","",IF($P15<>"","발송완료",IF($O15<>"","입금완료","입금대기"))) | R15: =IF($C15="","",COUNTIFS($C$3:$C15,$C15)) | S15: =IF($C15="","",$C15&"|"&$R15)
A16: =IF($C16="","",TEXT($B16,"yymmdd")&"-"&TEXT(COUNTIFS($B$3:$B16,$B16),"000")) | D16: =IF($C16="","",IFERROR(INDEX(고객명부!$B$3:$B$502,MATCH($C16,고객명부!$A$3:$A$502,0)),"미등록고객")) | E16: =IF($C16="","",IFERROR(INDEX(고객명부!$C$3:$C$502,MATCH($C16,고객명부!$A$3:$A$502,0)),"")) | F16: =IF($C16="","",IFERROR(INDEX(고객명부!$D$3:$D$502,MATCH($C16,고객명부!$A$3:$A$502,0)),"")) | G16: =IF($C16="","",IFERROR(INDEX(고객명부!$E$3:$E$502,MATCH($C16,고객명부!$A$3:$A$502,0))&" "&INDEX(고객명부!$F$3:$F$502,MATCH($C16,고객명부!$A$3:$A$502,0)),"")) | I16: =IF($H16="","",IFERROR(INDEX(상품목록!$B$3:$B$102,MATCH($H16,상품목록!$A$3:$A$102,0)),"")) | J16: =IF($H16="","",IFERROR(INDEX(상품목록!$C$3:$C$102,MATCH($H16,상품목록!$A$3:$A$102,0)),0)) | L16: =IF(OR($J16="",$K16=""),"",ROUND($J16*$K16,0)) | N16: =IF($L16="","",$L16+IF($M16="",0,$M16)) | Q16: =IF($C16="","",IF($P16<>"","발송완료",IF($O16<>"","입금완료","입금대기"))) | R16: =IF($C16="","",COUNTIFS($C$3:$C16,$C16)) | S16: =IF($C16="","",$C16&"|"&$R16)
A17: =IF($C17="","",TEXT($B17,"yymmdd")&"-"&TEXT(COUNTIFS($B$3:$B17,$B17),"000")) | D17: =IF($C17="","",IFERROR(INDEX(고객명부!$B$3:$B$502,MATCH($C17,고객명부!$A$3:$A$502,0)),"미등록고객")) | E17: =IF($C17="","",IFERROR(INDEX(고객명부!$C$3:$C$502,MATCH($C17,고객명부!$A$3:$A$502,0)),"")) | F17: =IF($C17="","",IFERROR(INDEX(고객명부!$D$3:$D$502,MATCH($C17,고객명부!$A$3:$A$502,0)),"")) | G17: =IF($C17="","",IFERROR(INDEX(고객명부!$E$3:$E$502,MATCH($C17,고객명부!$A$3:$A$502,0))&" "&INDEX(고객명부!$F$3:$F$502,MATCH($C17,고객명부!$A$3:$A$502,0)),"")) | I17: =IF($H17="","",IFERROR(INDEX(상품목록!$B$3:$B$102,MATCH($H17,상품목록!$A$3:$A$102,0)),"")) | J17: =IF($H17="","",IFERROR(INDEX(상품목록!$C$3:$C$102,MATCH($H17,상품목록!$A$3:$A$102,0)),0)) | L17: =IF(OR($J17="",$K17=""),"",ROUND($J17*$K17,0)) | N17: =IF($L17="","",$L17+IF($M17="",0,$M17)) | Q17: =IF($C17="","",IF($P17<>"","발송완료",IF($O17<>"","입금완료","입금대기"))) | R17: =IF($C17="","",COUNTIFS($C$3:$C17,$C17)) | S17: =IF($C17="","",$C17&"|"&$R17)
A18: =IF($C18="","",TEXT($B18,"yymmdd")&"-"&TEXT(COUNTIFS($B$3:$B18,$B18),"000")) | D18: =IF($C18="","",IFERROR(INDEX(고객명부!$B$3:$B$502,MATCH($C18,고객명부!$A$3:$A$502,0)),"미등록고객")) | E18: =IF($C18="","",IFERROR(INDEX(고객명부!$C$3:$C$502,MATCH($C18,고객명부!$A$3:$A$502,0)),"")) | F18: =IF($C18="","",IFERROR(INDEX(고객명부!$D$3:$D$502,MATCH($C18,고객명부!$A$3:$A$502,0)),"")) | G18: =IF($C18="","",IFERROR(INDEX(고객명부!$E$3:$E$502,MATCH($C18,고객명부!$A$3:$A$502,0))&" "&INDEX(고객명부!$F$3:$F$502,MATCH($C18,고객명부!$A$3:$A$502,0)),"")) | I18: =IF($H18="","",IFERROR(INDEX(상품목록!$B$3:$B$102,MATCH($H18,상품목록!$A$3:$A$102,0)),"")) | J18: =IF($H18="","",IFERROR(INDEX(상품목록!$C$3:$C$102,MATCH($H18,상품목록!$A$3:$A$102,0)),0)) | L18: =IF(OR($J18="",$K18=""),"",ROUND($J18*$K18,0)) | N18: =IF($L18="","",$L18+IF($M18="",0,$M18)) | Q18: =IF($C18="","",IF($P18<>"","발송완료",IF($O18<>"","입금완료","입금대기"))) | R18: =IF($C18="","",COUNTIFS($C$3:$C18,$C18)) | S18: =IF($C18="","",$C18&"|"&$R18)
... A602: =IF($C602="","",TEXT($B602,"yymmdd")&"-"&TEXT(COUNTIFS($B$3:$B602,$B602),"000")) | D602: =IF($C602="","",IFERROR(INDEX(고객명부!$B$3:$B$502,MATCH($C602,고객명부!$A$3:$A$502,0)),"미등록고객")) | E602: =IF($C602="","",IFERROR(INDEX(고객명부!$C$3:$C$502,MATCH($C602,고객명부!$A$3:$A$502,0)),"")) | F602: =IF($C602="","",IFERROR(INDEX(고객명부!$D$3:$D$502,MATCH($C602,고객명부!$A$3:$A$502,0)),"")) | G602: =IF($C602="","",IFERROR(INDEX(고객명부!$E$3:$E$502,MATCH($C602,고객명부!$A$3:$A$502,0))&" "&INDEX(고객명부!$F$3:$F$502,MATCH($C602,고객명부!$A$3:$A$502,0)),"")) | I602: =IF($H602="","",IFERROR(INDEX(상품목록!$B$3:$B$102,MATCH($H602,상품목록!$A$3:$A$102,0)),"")) | J602: =IF($H602="","",IFERROR(INDEX(상품목록!$C$3:$C$102,MATCH($H602,상품목록!$A$3:$A$102,0)),0)) | L602: =IF(OR($J602="",$K602=""),"",ROUND($J602*$K602,0)) | N602: =IF($L602="","",$L602+IF($M602="",0,$M602)) | Q602: =IF($C602="","",IF($P602<>"","발송완료",IF($O602<>"","입금완료","입금대기"))) | R602: =IF($C602="","",COUNTIFS($C$3:$C602,$C602)) | S602: =IF($C602="","",$C602&"|"&$R602)

Sheet 택배송장
A1: 택 배 송 장
A3: 주문번호 | B3: 260903-001 | C3: ← 이 칸만 바꾸세요
A5: 받는 사람 | B5: =IFERROR(INDEX(주문접수!$D$3:$D$602,MATCH($B$3,주문접수!$A$3:$A$602,0)),"") -> 김고객
A6: 연락처 | B6: =IFERROR(INDEX(주문접수!$E$3:$E$602,MATCH($B$3,주문접수!$A$3:$A$602,0)),"") -> 010-0000-0000
A7: 우편번호 | B7: =IFERROR(INDEX(주문접수!$F$3:$F$602,MATCH($B$3,주문접수!$A$3:$A$602,0)),"") -> 12345
A8: 주소 | B8: =IFERROR(INDEX(주문접수!$G$3:$G$602,MATCH($B$3,주문접수!$A$3:$A$602,0)),"") -> 서울시 ○○구 ○○로 10 101동 101호
A9: 품명 | B9: =IFERROR(INDEX(주문접수!$H$3:$H$602,MATCH($B$3,주문접수!$A$3:$A$602,0))&" / "&INDEX(주문접수!$I$3:$I$602,MATCH($B$3,주문접수!$A$3:$A$602,0)),"") -> 사과 부사 5kg / 5kg (특)
A10: 수량 | B10: =IFERROR(INDEX(주문접수!$K$3:$K$602,MATCH($B$3,주문접수!$A$3:$A$602,0)),"") -> 2
A11: 결제상태 | B11: =IFERROR(INDEX(주문접수!$Q$3:$Q$602,MATCH($B$3,주문접수!$A$3:$A$602,0)),"") -> 발송완료
A13: 보내는 사람 | B13: ○○농원 / 010-0000-0000 / 경북 ○○군 ○○면 ○○리 00
A15: ※ 보내는 사람 칸은 직접 수정하세요. 실제 택배사 송장 양식과 다를 수 있습니다.

Sheet 고객히스토리
A1: 고객히스토리
A3: 고객번호 | B3: 1001 | C3: =IFERROR(INDEX(고객명부!$B$3:$B$502,MATCH($B$3,고객명부!$A$3:$A$502,0)),"") -> 김고객 | D3: ← 고객번호만 바꾸세요
A5: 총 주문건수 | C5: 총 주문금액 | E5: 미입금 건수
A6: =COUNTIFS(주문접수!$C$3:$C$602,$B$3) -> 2 | C6: =SUMIFS(주문접수!$N$3:$N$602,주문접수!$C$3:$C$602,$B$3) -> 132000 | E6: =COUNTIFS(주문접수!$C$3:$C$602,$B$3,주문접수!$Q$3:$Q$602,"입금대기") -> 0
A7: No | B7: 주문일 | C7: 주문번호 | D7: 상품명 | E7: 수량 | F7: 합계금액 | G7: 상태
A8: 1 | B8: =IFERROR(INDEX(주문접수!$B$3:$B$602,MATCH($B$3&"|"&1,주문접수!$S$3:$S$602,0)),"") -> 46268 | C8: =IF($B8="","",IFERROR(INDEX(주문접수!$A$3:$A$602,MATCH($B$3&"|"&1,주문접수!$S$3:$S$602,0)),"")) -> 260903-001 | D8: =IF($B8="","",IFERROR(INDEX(주문접수!$H$3:$H$602,MATCH($B$3&"|"&1,주문접수!$S$3:$S$602,0)),"")) -> 사과 부사 5kg | E8: =IF($B8="","",IFERROR(INDEX(주문접수!$K$3:$K$602,MATCH($B$3&"|"&1,주문접수!$S$3:$S$602,0)),"")) -> 2 | F8: =IF($B8="","",IFERROR(INDEX(주문접수!$N$3:$N$602,MATCH($B$3&"|"&1,주문접수!$S$3:$S$602,0)),"")) -> 73500 | G8: =IF($B8="","",IFERROR(INDEX(주문접수!$Q$3:$Q$602,MATCH($B$3&"|"&1,주문접수!$S$3:$S$602,0)),"")) -> 발송완료
A9: 2 | B9: =IFERROR(INDEX(주문접수!$B$3:$B$602,MATCH($B$3&"|"&2,주문접수!$S$3:$S$602,0)),"") -> 46274 | C9: =IF($B9="","",IFERROR(INDEX(주문접수!$A$3:$A$602,MATCH($B$3&"|"&2,주문접수!$S$3:$S$602,0)),"")) -> 260909-001 | D9: =IF($B9="","",IFERROR(INDEX(주문접수!$H$3:$H$602,MATCH($B$3&"|"&2,주문접수!$S$3:$S$602,0)),"")) -> 사과 부사 10kg | E9: =IF($B9="","",IFERROR(INDEX(주문접수!$K$3:$K$602,MATCH($B$3&"|"&2,주문접수!$S$3:$S$602,0)),"")) -> 1 | F9: =IF($B9="","",IFERROR(INDEX(주문접수!$N$3:$N$602,MATCH($B$3&"|"&2,주문접수!$S$3:$S$602,0)),"")) -> 58500 | G9: =IF($B9="","",IFERROR(INDEX(주문접수!$Q$3:$Q$602,MATCH($B$3&"|"&2,주문접수!$S$3:$S$602,0)),"")) -> 입금완료
A10: 3 | B10: =IFERROR(INDEX(주문접수!$B$3:$B$602,MATCH($B$3&"|"&3,주문접수!$S$3:$S$602,0)),"") | C10: =IF($B10="","",IFERROR(INDEX(주문접수!$A$3:$A$602,MATCH($B$3&"|"&3,주문접수!$S$3:$S$602,0)),"")) | D10: =IF($B10="","",IFERROR(INDEX(주문접수!$H$3:$H$602,MATCH($B$3&"|"&3,주문접수!$S$3:$S$602,0)),"")) | E10: =IF($B10="","",IFERROR(INDEX(주문접수!$K$3:$K$602,MATCH($B$3&"|"&3,주문접수!$S$3:$S$602,0)),"")) | F10: =IF($B10="","",IFERROR(INDEX(주문접수!$N$3:$N$602,MATCH($B$3&"|"&3,주문접수!$S$3:$S$602,0)),"")) | G10: =IF($B10="","",IFERROR(INDEX(주문접수!$Q$3:$Q$602,MATCH($B$3&"|"&3,주문접수!$S$3:$S$602,0)),""))
A11: 4 | B11: =IFERROR(INDEX(주문접수!$B$3:$B$602,MATCH($B$3&"|"&4,주문접수!$S$3:$S$602,0)),"") | C11: =IF($B11="","",IFERROR(INDEX(주문접수!$A$3:$A$602,MATCH($B$3&"|"&4,주문접수!$S$3:$S$602,0)),"")) | D11: =IF($B11="","",IFERROR(INDEX(주문접수!$H$3:$H$602,MATCH($B$3&"|"&4,주문접수!$S$3:$S$602,0)),"")) | E11: =IF($B11="","",IFERROR(INDEX(주문접수!$K$3:$K$602,MATCH($B$3&"|"&4,주문접수!$S$3:$S$602,0)),"")) | F11: =IF($B11="","",IFERROR(INDEX(주문접수!$N$3:$N$602,MATCH($B$3&"|"&4,주문접수!$S$3:$S$602,0)),"")) | G11: =IF($B11="","",IFERROR(INDEX(주문접수!$Q$3:$Q$602,MATCH($B$3&"|"&4,주문접수!$S$3:$S$602,0)),""))
A12: 5 | B12: =IFERROR(INDEX(주문접수!$B$3:$B$602,MATCH($B$3&"|"&5,주문접수!$S$3:$S$602,0)),"") | C12: =IF($B12="","",IFERROR(INDEX(주문접수!$A$3:$A$602,MATCH($B$3&"|"&5,주문접수!$S$3:$S$602,0)),"")) | D12: =IF($B12="","",IFERROR(INDEX(주문접수!$H$3:$H$602,MATCH($B$3&"|"&5,주문접수!$S$3:$S$602,0)),"")) | E12: =IF($B12="","",IFERROR(INDEX(주문접수!$K$3:$K$602,MATCH($B$3&"|"&5,주문접수!$S$3:$S$602,0)),"")) | F12: =IF($B12="","",IFERROR(INDEX(주문접수!$N$3:$N$602,MATCH($B$3&"|"&5,주문접수!$S$3:$S$602,0)),"")) | G12: =IF($B12="","",IFERROR(INDEX(주문접수!$Q$3:$Q$602,MATCH($B$3&"|"&5,주문접수!$S$3:$S$602,0)),""))
A13: 6 | B13: =IFERROR(INDEX(주문접수!$B$3:$B$602,MATCH($B$3&"|"&6,주문접수!$S$3:$S$602,0)),"") | C13: =IF($B13="","",IFERROR(INDEX(주문접수!$A$3:$A$602,MATCH($B$3&"|"&6,주문접수!$S$3:$S$602,0)),"")) | D13: =IF($B13="","",IFERROR(INDEX(주문접수!$H$3:$H$602,MATCH($B$3&"|"&6,주문접수!$S$3:$S$602,0)),"")) | E13: =IF($B13="","",IFERROR(INDEX(주문접수!$K$3:$K$602,MATCH($B$3&"|"&6,주문접수!$S$3:$S$602,0)),"")) | F13: =IF($B13="","",IFERROR(INDEX(주문접수!$N$3:$N$602,MATCH($B$3&"|"&6,주문접수!$S$3:$S$602,0)),"")) | G13: =IF($B13="","",IFERROR(INDEX(주문접수!$Q$3:$Q$602,MATCH($B$3&"|"&6,주문접수!$S$3:$S$602,0)),""))
A14: 7 | B14: =IFERROR(INDEX(주문접수!$B$3:$B$602,MATCH($B$3&"|"&7,주문접수!$S$3:$S$602,0)),"") | C14: =IF($B14="","",IFERROR(INDEX(주문접수!$A$3:$A$602,MATCH($B$3&"|"&7,주문접수!$S$3:$S$602,0)),"")) | D14: =IF($B14="","",IFERROR(INDEX(주문접수!$H$3:$H$602,MATCH($B$3&"|"&7,주문접수!$S$3:$S$602,0)),"")) | E14: =IF($B14="","",IFERROR(INDEX(주문접수!$K$3:$K$602,MATCH($B$3&"|"&7,주문접수!$S$3:$S$602,0)),"")) | F14: =IF($B14="","",IFERROR(INDEX(주문접수!$N$3:$N$602,MATCH($B$3&"|"&7,주문접수!$S$3:$S$602,0)),"")) | G14: =IF($B14="","",IFERROR(INDEX(주문접수!$Q$3:$Q$602,MATCH($B$3&"|"&7,주문접수!$S$3:$S$602,0)),""))
A15: 8 | B15: =IFERROR(INDEX(주문접수!$B$3:$B$602,MATCH($B$3&"|"&8,주문접수!$S$3:$S$602,0)),"") | C15: =IF($B15="","",IFERROR(INDEX(주문접수!$A$3:$A$602,MATCH($B$3&"|"&8,주문접수!$S$3:$S$602,0)),"")) | D15: =IF($B15="","",IFERROR(INDEX(주문접수!$H$3:$H$602,MATCH($B$3&"|"&8,주문접수!$S$3:$S$602,0)),"")) | E15: =IF($B15="","",IFERROR(INDEX(주문접수!$K$3:$K$602,MATCH($B$3&"|"&8,주문접수!$S$3:$S$602,0)),"")) | F15: =IF($B15="","",IFERROR(INDEX(주문접수!$N$3:$N$602,MATCH($B$3&"|"&8,주문접수!$S$3:$S$602,0)),"")) | G15: =IF($B15="","",IFERROR(INDEX(주문접수!$Q$3:$Q$602,MATCH($B$3&"|"&8,주문접수!$S$3:$S$602,0)),""))
A16: 9 | B16: =IFERROR(INDEX(주문접수!$B$3:$B$602,MATCH($B$3&"|"&9,주문접수!$S$3:$S$602,0)),"") | C16: =IF($B16="","",IFERROR(INDEX(주문접수!$A$3:$A$602,MATCH($B$3&"|"&9,주문접수!$S$3:$S$602,0)),"")) | D16: =IF($B16="","",IFERROR(INDEX(주문접수!$H$3:$H$602,MATCH($B$3&"|"&9,주문접수!$S$3:$S$602,0)),"")) | E16: =IF($B16="","",IFERROR(INDEX(주문접수!$K$3:$K$602,MATCH($B$3&"|"&9,주문접수!$S$3:$S$602,0)),"")) | F16: =IF($B16="","",IFERROR(INDEX(주문접수!$N$3:$N$602,MATCH($B$3&"|"&9,주문접수!$S$3:$S$602,0)),"")) | G16: =IF($B16="","",IFERROR(INDEX(주문접수!$Q$3:$Q$602,MATCH($B$3&"|"&9,주문접수!$S$3:$S$602,0)),""))
A17: 10 | B17: =IFERROR(INDEX(주문접수!$B$3:$B$602,MATCH($B$3&"|"&10,주문접수!$S$3:$S$602,0)),"") | C17: =IF($B17="","",IFERROR(INDEX(주문접수!$A$3:$A$602,MATCH($B$3&"|"&10,주문접수!$S$3:$S$602,0)),"")) | D17: =IF($B17="","",IFERROR(INDEX(주문접수!$H$3:$H$602,MATCH($B$3&"|"&10,주문접수!$S$3:$S$602,0)),"")) | E17: =IF($B17="","",IFERROR(INDEX(주문접수!$K$3:$K$602,MATCH($B$3&"|"&10,주문접수!$S$3:$S$602,0)),"")) | F17: =IF($B17="","",IFERROR(INDEX(주문접수!$N$3:$N$602,MATCH($B$3&"|"&10,주문접수!$S$3:$S$602,0)),"")) | G17: =IF($B17="","",IFERROR(INDEX(주문접수!$Q$3:$Q$602,MATCH($B$3&"|"&10,주문접수!$S$3:$S$602,0)),""))
A18: 11 | B18: =IFERROR(INDEX(주문접수!$B$3:$B$602,MATCH($B$3&"|"&11,주문접수!$S$3:$S$602,0)),"") | C18: =IF($B18="","",IFERROR(INDEX(주문접수!$A$3:$A$602,MATCH($B$3&"|"&11,주문접수!$S$3:$S$602,0)),"")) | D18: =IF($B18="","",IFERROR(INDEX(주문접수!$H$3:$H$602,MATCH($B$3&"|"&11,주문접수!$S$3:$S$602,0)),"")) | E18: =IF($B18="","",IFERROR(INDEX(주문접수!$K$3:$K$602,MATCH($B$3&"|"&11,주문접수!$S$3:$S$602,0)),"")) | F18: =IF($B18="","",IFERROR(INDEX(주문접수!$N$3:$N$602,MATCH($B$3&"|"&11,주문접수!$S$3:$S$602,0)),"")) | G18: =IF($B18="","",IFERROR(INDEX(주문접수!$Q$3:$Q$602,MATCH($B$3&"|"&11,주문접수!$S$3:$S$602,0)),""))
A19: 12 | B19: =IFERROR(INDEX(주문접수!$B$3:$B$602,MATCH($B$3&"|"&12,주문접수!$S$3:$S$602,0)),"") | C19: =IF($B19="","",IFERROR(INDEX(주문접수!$A$3:$A$602,MATCH($B$3&"|"&12,주문접수!$S$3:$S$602,0)),"")) | D19: =IF($B19="","",IFERROR(INDEX(주문접수!$H$3:$H$602,MATCH($B$3&"|"&12,주문접수!$S$3:$S$602,0)),"")) | E19: =IF($B19="","",IFERROR(INDEX(주문접수!$K$3:$K$602,MATCH($B$3&"|"&12,주문접수!$S$3:$S$602,0)),"")) | F19: =IF($B19="","",IFERROR(INDEX(주문접수!$N$3:$N$602,MATCH($B$3&"|"&12,주문접수!$S$3:$S$602,0)),"")) | G19: =IF($B19="","",IFERROR(INDEX(주문접수!$Q$3:$Q$602,MATCH($B$3&"|"&12,주문접수!$S$3:$S$602,0)),""))
A20: 13 | B20: =IFERROR(INDEX(주문접수!$B$3:$B$602,MATCH($B$3&"|"&13,주문접수!$S$3:$S$602,0)),"") | C20: =IF($B20="","",IFERROR(INDEX(주문접수!$A$3:$A$602,MATCH($B$3&"|"&13,주문접수!$S$3:$S$602,0)),"")) | D20: =IF($B20="","",IFERROR(INDEX(주문접수!$H$3:$H$602,MATCH($B$3&"|"&13,주문접수!$S$3:$S$602,0)),"")) | E20: =IF($B20="","",IFERROR(INDEX(주문접수!$K$3:$K$602,MATCH($B$3&"|"&13,주문접수!$S$3:$S$602,0)),"")) | F20: =IF($B20="","",IFERROR(INDEX(주문접수!$N$3:$N$602,MATCH($B$3&"|"&13,주문접수!$S$3:$S$602,0)),"")) | G20: =IF($B20="","",IFERROR(INDEX(주문접수!$Q$3:$Q$602,MATCH($B$3&"|"&13,주문접수!$S$3:$S$602,0)),""))
A21: 14 | B21: =IFERROR(INDEX(주문접수!$B$3:$B$602,MATCH($B$3&"|"&14,주문접수!$S$3:$S$602,0)),"") | C21: =IF($B21="","",IFERROR(INDEX(주문접수!$A$3:$A$602,MATCH($B$3&"|"&14,주문접수!$S$3:$S$602,0)),"")) | D21: =IF($B21="","",IFERROR(INDEX(주문접수!$H$3:$H$602,MATCH($B$3&"|"&14,주문접수!$S$3:$S$602,0)),"")) | E21: =IF($B21="","",IFERROR(INDEX(주문접수!$K$3:$K$602,MATCH($B$3&"|"&14,주문접수!$S$3:$S$602,0)),"")) | F21: =IF($B21="","",IFERROR(INDEX(주문접수!$N$3:$N$602,MATCH($B$3&"|"&14,주문접수!$S$3:$S$602,0)),"")) | G21: =IF($B21="","",IFERROR(INDEX(주문접수!$Q$3:$Q$602,MATCH($B$3&"|"&14,주문접수!$S$3:$S$602,0)),""))
A22: 15 | B22: =IFERROR(INDEX(주문접수!$B$3:$B$602,MATCH($B$3&"|"&15,주문접수!$S$3:$S$602,0)),"") | C22: =IF($B22="","",IFERROR(INDEX(주문접수!$A$3:$A$602,MATCH($B$3&"|"&15,주문접수!$S$3:$S$602,0)),"")) | D22: =IF($B22="","",IFERROR(INDEX(주문접수!$H$3:$H$602,MATCH($B$3&"|"&15,주문접수!$S$3:$S$602,0)),"")) | E22: =IF($B22="","",IFERROR(INDEX(주문접수!$K$3:$K$602,MATCH($B$3&"|"&15,주문접수!$S$3:$S$602,0)),"")) | F22: =IF($B22="","",IFERROR(INDEX(주문접수!$N$3:$N$602,MATCH($B$3&"|"&15,주문접수!$S$3:$S$602,0)),"")) | G22: =IF($B22="","",IFERROR(INDEX(주문접수!$Q$3:$Q$602,MATCH($B$3&"|"&15,주문접수!$S$3:$S$602,0)),""))
A23: 16 | B23: =IFERROR(INDEX(주문접수!$B$3:$B$602,MATCH($B$3&"|"&16,주문접수!$S$3:$S$602,0)),"") | C23: =IF($B23="","",IFERROR(INDEX(주문접수!$A$3:$A$602,MATCH($B$3&"|"&16,주문접수!$S$3:$S$602,0)),"")) | D23: =IF($B23="","",IFERROR(INDEX(주문접수!$H$3:$H$602,MATCH($B$3&"|"&16,주문접수!$S$3:$S$602,0)),"")) | E23: =IF($B23="","",IFERROR(INDEX(주문접수!$K$3:$K$602,MATCH($B$3&"|"&16,주문접수!$S$3:$S$602,0)),"")) | F23: =IF($B23="","",IFERROR(INDEX(주문접수!$N$3:$N$602,MATCH($B$3&"|"&16,주문접수!$S$3:$S$602,0)),"")) | G23: =IF($B23="","",IFERROR(INDEX(주문접수!$Q$3:$Q$602,MATCH($B$3&"|"&16,주문접수!$S$3:$S$602,0)),""))
A24: 17 | B24: =IFERROR(INDEX(주문접수!$B$3:$B$602,MATCH($B$3&"|"&17,주문접수!$S$3:$S$602,0)),"") | C24: =IF($B24="","",IFERROR(INDEX(주문접수!$A$3:$A$602,MATCH($B$3&"|"&17,주문접수!$S$3:$S$602,0)),"")) | D24: =IF($B24="","",IFERROR(INDEX(주문접수!$H$3:$H$602,MATCH($B$3&"|"&17,주문접수!$S$3:$S$602,0)),"")) | E24: =IF($B24="","",IFERROR(INDEX(주문접수!$K$3:$K$602,MATCH($B$3&"|"&17,주문접수!$S$3:$S$602,0)),"")) | F24: =IF($B24="","",IFERROR(INDEX(주문접수!$N$3:$N$602,MATCH($B$3&"|"&17,주문접수!$S$3:$S$602,0)),"")) | G24: =IF($B24="","",IFERROR(INDEX(주문접수!$Q$3:$Q$602,MATCH($B$3&"|"&17,주문접수!$S$3:$S$602,0)),""))
A25: 18 | B25: =IFERROR(INDEX(주문접수!$B$3:$B$602,MATCH($B$3&"|"&18,주문접수!$S$3:$S$602,0)),"") | C25: =IF($B25="","",IFERROR(INDEX(주문접수!$A$3:$A$602,MATCH($B$3&"|"&18,주문접수!$S$3:$S$602,0)),"")) | D25: =IF($B25="","",IFERROR(INDEX(주문접수!$H$3:$H$602,MATCH($B$3&"|"&18,주문접수!$S$3:$S$602,0)),"")) | E25: =IF($B25="","",IFERROR(INDEX(주문접수!$K$3:$K$602,MATCH($B$3&"|"&18,주문접수!$S$3:$S$602,0)),"")) | F25: =IF($B25="","",IFERROR(INDEX(주문접수!$N$3:$N$602,MATCH($B$3&"|"&18,주문접수!$S$3:$S$602,0)),"")) | G25: =IF($B25="","",IFERROR(INDEX(주문접수!$Q$3:$Q$602,MATCH($B$3&"|"&18,주문접수!$S$3:$S$602,0)),""))
A26: 19 | B26: =IFERROR(INDEX(주문접수!$B$3:$B$602,MATCH($B$3&"|"&19,주문접수!$S$3:$S$602,0)),"") | C26: =IF($B26="","",IFERROR(INDEX(주문접수!$A$3:$A$602,MATCH($B$3&"|"&19,주문접수!$S$3:$S$602,0)),"")) | D26: =IF($B26="","",IFERROR(INDEX(주문접수!$H$3:$H$602,MATCH($B$3&"|"&19,주문접수!$S$3:$S$602,0)),"")) | E26: =IF($B26="","",IFERROR(INDEX(주문접수!$K$3:$K$602,MATCH($B$3&"|"&19,주문접수!$S$3:$S$602,0)),"")) | F26: =IF($B26="","",IFERROR(INDEX(주문접수!$N$3:$N$602,MATCH($B$3&"|"&19,주문접수!$S$3:$S$602,0)),"")) | G26: =IF($B26="","",IFERROR(INDEX(주문접수!$Q$3:$Q$602,MATCH($B$3&"|"&19,주문접수!$S$3:$S$602,0)),""))
A27: 20 | B27: =IFERROR(INDEX(주문접수!$B$3:$B$602,MATCH($B$3&"|"&20,주문접수!$S$3:$S$602,0)),"") | C27: =IF($B27="","",IFERROR(INDEX(주문접수!$A$3:$A$602,MATCH($B$3&"|"&20,주문접수!$S$3:$S$602,0)),"")) | D27: =IF($B27="","",IFERROR(INDEX(주문접수!$H$3:$H$602,MATCH($B$3&"|"&20,주문접수!$S$3:$S$602,0)),"")) | E27: =IF($B27="","",IFERROR(INDEX(주문접수!$K$3:$K$602,MATCH($B$3&"|"&20,주문접수!$S$3:$S$602,0)),"")) | F27: =IF($B27="","",IFERROR(INDEX(주문접수!$N$3:$N$602,MATCH($B$3&"|"&20,주문접수!$S$3:$S$602,0)),"")) | G27: =IF($B27="","",IFERROR(INDEX(주문접수!$Q$3:$Q$602,MATCH($B$3&"|"&20,주문접수!$S$3:$S$602,0)),""))
A28: 21 | B28: =IFERROR(INDEX(주문접수!$B$3:$B$602,MATCH($B$3&"|"&21,주문접수!$S$3:$S$602,0)),"") | C28: =IF($B28="","",IFERROR(INDEX(주문접수!$A$3:$A$602,MATCH($B$3&"|"&21,주문접수!$S$3:$S$602,0)),"")) | D28: =IF($B28="","",IFERROR(INDEX(주문접수!$H$3:$H$602,MATCH($B$3&"|"&21,주문접수!$S$3:$S$602,0)),"")) | E28: =IF($B28="","",IFERROR(INDEX(주문접수!$K$3:$K$602,MATCH($B$3&"|"&21,주문접수!$S$3:$S$602,0)),"")) | F28: =IF($B28="","",IFERROR(INDEX(주문접수!$N$3:$N$602,MATCH($B$3&"|"&21,주문접수!$S$3:$S$602,0)),"")) | G28: =IF($B28="","",IFERROR(INDEX(주문접수!$Q$3:$Q$602,MATCH($B$3&"|"&21,주문접수!$S$3:$S$602,0)),""))
A29: 22 | B29: =IFERROR(INDEX(주문접수!$B$3:$B$602,MATCH($B$3&"|"&22,주문접수!$S$3:$S$602,0)),"") | C29: =IF($B29="","",IFERROR(INDEX(주문접수!$A$3:$A$602,MATCH($B$3&"|"&22,주문접수!$S$3:$S$602,0)),"")) | D29: =IF($B29="","",IFERROR(INDEX(주문접수!$H$3:$H$602,MATCH($B$3&"|"&22,주문접수!$S$3:$S$602,0)),"")) | E29: =IF($B29="","",IFERROR(INDEX(주문접수!$K$3:$K$602,MATCH($B$3&"|"&22,주문접수!$S$3:$S$602,0)),"")) | F29: =IF($B29="","",IFERROR(INDEX(주문접수!$N$3:$N$602,MATCH($B$3&"|"&22,주문접수!$S$3:$S$602,0)),"")) | G29: =IF($B29="","",IFERROR(INDEX(주문접수!$Q$3:$Q$602,MATCH($B$3&"|"&22,주문접수!$S$3:$S$602,0)),""))
A30: 23 | B30: =IFERROR(INDEX(주문접수!$B$3:$B$602,MATCH($B$3&"|"&23,주문접수!$S$3:$S$602,0)),"") | C30: =IF($B30="","",IFERROR(INDEX(주문접수!$A$3:$A$602,MATCH($B$3&"|"&23,주문접수!$S$3:$S$602,0)),"")) | D30: =IF($B30="","",IFERROR(INDEX(주문접수!$H$3:$H$602,MATCH($B$3&"|"&23,주문접수!$S$3:$S$602,0)),"")) | E30: =IF($B30="","",IFERROR(INDEX(주문접수!$K$3:$K$602,MATCH($B$3&"|"&23,주문접수!$S$3:$S$602,0)),"")) | F30: =IF($B30="","",IFERROR(INDEX(주문접수!$N$3:$N$602,MATCH($B$3&"|"&23,주문접수!$S$3:$S$602,0)),"")) | G30: =IF($B30="","",IFERROR(INDEX(주문접수!$Q$3:$Q$602,MATCH($B$3&"|"&23,주문접수!$S$3:$S$602,0)),""))
A31: 24 | B31: =IFERROR(INDEX(주문접수!$B$3:$B$602,MATCH($B$3&"|"&24,주문접수!$S$3:$S$602,0)),"") | C31: =IF($B31="","",IFERROR(INDEX(주문접수!$A$3:$A$602,MATCH($B$3&"|"&24,주문접수!$S$3:$S$602,0)),"")) | D31: =IF($B31="","",IFERROR(INDEX(주문접수!$H$3:$H$602,MATCH($B$3&"|"&24,주문접수!$S$3:$S$602,0)),"")) | E31: =IF($B31="","",IFERROR(INDEX(주문접수!$K$3:$K$602,MATCH($B$3&"|"&24,주문접수!$S$3:$S$602,0)),"")) | F31: =IF($B31="","",IFERROR(INDEX(주문접수!$N$3:$N$602,MATCH($B$3&"|"&24,주문접수!$S$3:$S$602,0)),"")) | G31: =IF($B31="","",IFERROR(INDEX(주문접수!$Q$3:$Q$602,MATCH($B$3&"|"&24,주문접수!$S$3:$S$602,0)),""))
A32: 25 | B32: =IFERROR(INDEX(주문접수!$B$3:$B$602,MATCH($B$3&"|"&25,주문접수!$S$3:$S$602,0)),"") | C32: =IF($B32="","",IFERROR(INDEX(주문접수!$A$3:$A$602,MATCH($B$3&"|"&25,주문접수!$S$3:$S$602,0)),"")) | D32: =IF($B32="","",IFERROR(INDEX(주문접수!$H$3:$H$602,MATCH($B$3&"|"&25,주문접수!$S$3:$S$602,0)),"")) | E32: =IF($B32="","",IFERROR(INDEX(주문접수!$K$3:$K$602,MATCH($B$3&"|"&25,주문접수!$S$3:$S$602,0)),"")) | F32: =IF($B32="","",IFERROR(INDEX(주문접수!$N$3:$N$602,MATCH($B$3&"|"&25,주문접수!$S$3:$S$602,0)),"")) | G32: =IF($B32="","",IFERROR(INDEX(주문접수!$Q$3:$Q$602,MATCH($B$3&"|"&25,주문접수!$S$3:$S$602,0)),""))
A33: 26 | B33: =IFERROR(INDEX(주문접수!$B$3:$B$602,MATCH($B$3&"|"&26,주문접수!$S$3:$S$602,0)),"") | C33: =IF($B33="","",IFERROR(INDEX(주문접수!$A$3:$A$602,MATCH($B$3&"|"&26,주문접수!$S$3:$S$602,0)),"")) | D33: =IF($B33="","",IFERROR(INDEX(주문접수!$H$3:$H$602,MATCH($B$3&"|"&26,주문접수!$S$3:$S$602,0)),"")) | E33: =IF($B33="","",IFERROR(INDEX(주문접수!$K$3:$K$602,MATCH($B$3&"|"&26,주문접수!$S$3:$S$602,0)),"")) | F33: =IF($B33="","",IFERROR(INDEX(주문접수!$N$3:$N$602,MATCH($B$3&"|"&26,주문접수!$S$3:$S$602,0)),"")) | G33: =IF($B33="","",IFERROR(INDEX(주문접수!$Q$3:$Q$602,MATCH($B$3&"|"&26,주문접수!$S$3:$S$602,0)),""))
A34: 27 | B34: =IFERROR(INDEX(주문접수!$B$3:$B$602,MATCH($B$3&"|"&27,주문접수!$S$3:$S$602,0)),"") | C34: =IF($B34="","",IFERROR(INDEX(주문접수!$A$3:$A$602,MATCH($B$3&"|"&27,주문접수!$S$3:$S$602,0)),"")) | D34: =IF($B34="","",IFERROR(INDEX(주문접수!$H$3:$H$602,MATCH($B$3&"|"&27,주문접수!$S$3:$S$602,0)),"")) | E34: =IF($B34="","",IFERROR(INDEX(주문접수!$K$3:$K$602,MATCH($B$3&"|"&27,주문접수!$S$3:$S$602,0)),"")) | F34: =IF($B34="","",IFERROR(INDEX(주문접수!$N$3:$N$602,MATCH($B$3&"|"&27,주문접수!$S$3:$S$602,0)),"")) | G34: =IF($B34="","",IFERROR(INDEX(주문접수!$Q$3:$Q$602,MATCH($B$3&"|"&27,주문접수!$S$3:$S$602,0)),""))
A35: 28 | B35: =IFERROR(INDEX(주문접수!$B$3:$B$602,MATCH($B$3&"|"&28,주문접수!$S$3:$S$602,0)),"") | C35: =IF($B35="","",IFERROR(INDEX(주문접수!$A$3:$A$602,MATCH($B$3&"|"&28,주문접수!$S$3:$S$602,0)),"")) | D35: =IF($B35="","",IFERROR(INDEX(주문접수!$H$3:$H$602,MATCH($B$3&"|"&28,주문접수!$S$3:$S$602,0)),"")) | E35: =IF($B35="","",IFERROR(INDEX(주문접수!$K$3:$K$602,MATCH($B$3&"|"&28,주문접수!$S$3:$S$602,0)),"")) | F35: =IF($B35="","",IFERROR(INDEX(주문접수!$N$3:$N$602,MATCH($B$3&"|"&28,주문접수!$S$3:$S$602,0)),"")) | G35: =IF($B35="","",IFERROR(INDEX(주문접수!$Q$3:$Q$602,MATCH($B$3&"|"&28,주문접수!$S$3:$S$602,0)),""))
A36: 29 | B36: =IFERROR(INDEX(주문접수!$B$3:$B$602,MATCH($B$3&"|"&29,주문접수!$S$3:$S$602,0)),"") | C36: =IF($B36="","",IFERROR(INDEX(주문접수!$A$3:$A$602,MATCH($B$3&"|"&29,주문접수!$S$3:$S$602,0)),"")) | D36: =IF($B36="","",IFERROR(INDEX(주문접수!$H$3:$H$602,MATCH($B$3&"|"&29,주문접수!$S$3:$S$602,0)),"")) | E36: =IF($B36="","",IFERROR(INDEX(주문접수!$K$3:$K$602,MATCH($B$3&"|"&29,주문접수!$S$3:$S$602,0)),"")) | F36: =IF($B36="","",IFERROR(INDEX(주문접수!$N$3:$N$602,MATCH($B$3&"|"&29,주문접수!$S$3:$S$602,0)),"")) | G36: =IF($B36="","",IFERROR(INDEX(주문접수!$Q$3:$Q$602,MATCH($B$3&"|"&29,주문접수!$S$3:$S$602,0)),""))
A37: 30 | B37: =IFERROR(INDEX(주문접수!$B$3:$B$602,MATCH($B$3&"|"&30,주문접수!$S$3:$S$602,0)),"") | C37: =IF($B37="","",IFERROR(INDEX(주문접수!$A$3:$A$602,MATCH($B$3&"|"&30,주문접수!$S$3:$S$602,0)),"")) | D37: =IF($B37="","",IFERROR(INDEX(주문접수!$H$3:$H$602,MATCH($B$3&"|"&30,주문접수!$S$3:$S$602,0)),"")) | E37: =IF($B37="","",IFERROR(INDEX(주문접수!$K$3:$K$602,MATCH($B$3&"|"&30,주문접수!$S$3:$S$602,0)),"")) | F37: =IF($B37="","",IFERROR(INDEX(주문접수!$N$3:$N$602,MATCH($B$3&"|"&30,주문접수!$S$3:$S$602,0)),"")) | G37: =IF($B37="","",IFERROR(INDEX(주문접수!$Q$3:$Q$602,MATCH($B$3&"|"&30,주문접수!$S$3:$S$602,0)),""))
A38: 31 | B38: =IFERROR(INDEX(주문접수!$B$3:$B$602,MATCH($B$3&"|"&31,주문접수!$S$3:$S$602,0)),"") | C38: =IF($B38="","",IFERROR(INDEX(주문접수!$A$3:$A$602,MATCH($B$3&"|"&31,주문접수!$S$3:$S$602,0)),"")) | D38: =IF($B38="","",IFERROR(INDEX(주문접수!$H$3:$H$602,MATCH($B$3&"|"&31,주문접수!$S$3:$S$602,0)),"")) | E38: =IF($B38="","",IFERROR(INDEX(주문접수!$K$3:$K$602,MATCH($B$3&"|"&31,주문접수!$S$3:$S$602,0)),"")) | F38: =IF($B38="","",IFERROR(INDEX(주문접수!$N$3:$N$602,MATCH($B$3&"|"&31,주문접수!$S$3:$S$602,0)),"")) | G38: =IF($B38="","",IFERROR(INDEX(주문접수!$Q$3:$Q$602,MATCH($B$3&"|"&31,주문접수!$S$3:$S$602,0)),""))
A39: 32 | B39: =IFERROR(INDEX(주문접수!$B$3:$B$602,MATCH($B$3&"|"&32,주문접수!$S$3:$S$602,0)),"") | C39: =IF($B39="","",IFERROR(INDEX(주문접수!$A$3:$A$602,MATCH($B$3&"|"&32,주문접수!$S$3:$S$602,0)),"")) | D39: =IF($B39="","",IFERROR(INDEX(주문접수!$H$3:$H$602,MATCH($B$3&"|"&32,주문접수!$S$3:$S$602,0)),"")) | E39: =IF($B39="","",IFERROR(INDEX(주문접수!$K$3:$K$602,MATCH($B$3&"|"&32,주문접수!$S$3:$S$602,0)),"")) | F39: =IF($B39="","",IFERROR(INDEX(주문접수!$N$3:$N$602,MATCH($B$3&"|"&32,주문접수!$S$3:$S$602,0)),"")) | G39: =IF($B39="","",IFERROR(INDEX(주문접수!$Q$3:$Q$602,MATCH($B$3&"|"&32,주문접수!$S$3:$S$602,0)),""))
A40: 33 | B40: =IFERROR(INDEX(주문접수!$B$3:$B$602,MATCH($B$3&"|"&33,주문접수!$S$3:$S$602,0)),"") | C40: =IF($B40="","",IFERROR(INDEX(주문접수!$A$3:$A$602,MATCH($B$3&"|"&33,주문접수!$S$3:$S$602,0)),"")) | D40: =IF($B40="","",IFERROR(INDEX(주문접수!$H$3:$H$602,MATCH($B$3&"|"&33,주문접수!$S$3:$S$602,0)),"")) | E40: =IF($B40="","",IFERROR(INDEX(주문접수!$K$3:$K$602,MATCH($B$3&"|"&33,주문접수!$S$3:$S$602,0)),"")) | F40: =IF($B40="","",IFERROR(INDEX(주문접수!$N$3:$N$602,MATCH($B$3&"|"&33,주문접수!$S$3:$S$602,0)),"")) | G40: =IF($B40="","",IFERROR(INDEX(주문접수!$Q$3:$Q$602,MATCH($B$3&"|"&33,주문접수!$S$3:$S$602,0)),""))
A41: 34 | B41: =IFERROR(INDEX(주문접수!$B$3:$B$602,MATCH($B$3&"|"&34,주문접수!$S$3:$S$602,0)),"") | C41: =IF($B41="","",IFERROR(INDEX(주문접수!$A$3:$A$602,MATCH($B$3&"|"&34,주문접수!$S$3:$S$602,0)),"")) | D41: =IF($B41="","",IFERROR(INDEX(주문접수!$H$3:$H$602,MATCH($B$3&"|"&34,주문접수!$S$3:$S$602,0)),"")) | E41: =IF($B41="","",IFERROR(INDEX(주문접수!$K$3:$K$602,MATCH($B$3&"|"&34,주문접수!$S$3:$S$602,0)),"")) | F41: =IF($B41="","",IFERROR(INDEX(주문접수!$N$3:$N$602,MATCH($B$3&"|"&34,주문접수!$S$3:$S$602,0)),"")) | G41: =IF($B41="","",IFERROR(INDEX(주문접수!$Q$3:$Q$602,MATCH($B$3&"|"&34,주문접수!$S$3:$S$602,0)),""))
A42: 35 | B42: =IFERROR(INDEX(주문접수!$B$3:$B$602,MATCH($B$3&"|"&35,주문접수!$S$3:$S$602,0)),"") | C42: =IF($B42="","",IFERROR(INDEX(주문접수!$A$3:$A$602,MATCH($B$3&"|"&35,주문접수!$S$3:$S$602,0)),"")) | D42: =IF($B42="","",IFERROR(INDEX(주문접수!$H$3:$H$602,MATCH($B$3&"|"&35,주문접수!$S$3:$S$602,0)),"")) | E42: =IF($B42="","",IFERROR(INDEX(주문접수!$K$3:$K$602,MATCH($B$3&"|"&35,주문접수!$S$3:$S$602,0)),"")) | F42: =IF($B42="","",IFERROR(INDEX(주문접수!$N$3:$N$602,MATCH($B$3&"|"&35,주문접수!$S$3:$S$602,0)),"")) | G42: =IF($B42="","",IFERROR(INDEX(주문접수!$Q$3:$Q$602,MATCH($B$3&"|"&35,주문접수!$S$3:$S$602,0)),""))
...

Sheet 일별현황
A1: 일별현황
A3: 기준일 | B3: 46268 | C3: ← 이 칸만 바꾸세요
A5: 당일 주문 건수 | B5: =COUNTIFS(주문접수!$B$3:$B$602,$B$3) -> 2
A6: 당일 주문 금액 | B6: =SUMIFS(주문접수!$N$3:$N$602,주문접수!$B$3:$B$602,$B$3) -> 125000
A7: 당일 입금 건수 | B7: =COUNTIFS(주문접수!$O$3:$O$602,$B$3) -> 1
A8: 당일 입금 금액 | B8: =SUMIFS(주문접수!$N$3:$N$602,주문접수!$O$3:$O$602,$B$3) -> 73500
A9: 입금대기 건수 (전체) | B9: =COUNTIFS(주문접수!$Q$3:$Q$602,"입금대기") -> 1
A10: 입금대기 금액 (전체) | B10: =SUMIFS(주문접수!$N$3:$N$602,주문접수!$Q$3:$Q$602,"입금대기") -> 105000
A11: 발송대기 건수 (입금완료·미발송) | B11: =COUNTIFS(주문접수!$Q$3:$Q$602,"입금완료") -> 1
A12: 발송완료 건수 (전체) | B12: =COUNTIFS(주문접수!$Q$3:$Q$602,"발송완료") -> 2
