Workbook

Sheet 사용안내
B2: 반품 · 불량 처리 대장
B4: 핵심 | C4: 반품·불량을 접수하고 어떻게 처리했는지 기록하면 미처리 건이 자동으로 남습니다.
B5: 입력 규칙 | C5: 파란색 글씨 칸만 입력하세요. 검은색은 자동 계산입니다.
B6: ① 거래처목록 / 품목목록 | C6: 먼저 등록해두면 접수할 때 골라 쓸 수 있습니다.
B7: ② 반품접수 | C7: 반품·불량이 들어올 때마다 한 줄. 접수번호는 자동으로 매겨집니다.
C8: 원재료와 부자재는 [자재구분]으로 나눠서 따로 집계됩니다.
B9: ③ 처리내역 | C9: 처리할 때마다 한 줄. 한 건을 나눠서 처리해도 됩니다.
C10: 예: 10개 접수 → 6개 재입고, 4개 폐기 로 두 줄을 넣으면 됩니다.
B11: ④ 미처리현황 | C11: 아직 처리 안 된 건만 모아서 보여줍니다. 오래된 순서로 챙기세요.
B12: ⑤ 사유별집계 / 거래처별집계 | C12: 어떤 사유가 많은지, 어느 거래처가 많은지 보여줍니다.
B13: ⑥ 월별집계 | C13: 월별 접수·처리 건수와 수량입니다.
B14: 상태 판정 | C14: 처리 수량 합계가 접수 수량보다 적으면 미처리 또는 부분처리로 표시됩니다.
B16: 설정 | C16: 값을 바꾸면 모든 계산에 반영됩니다
B17: 장기 미처리 기준(일) | C17: 14
B19: ※ 접수 후 이 일수를 넘기도록 처리되지 않으면 빨간색으로 표시됩니다.

Sheet 거래처목록
A1: 거래처목록
A2: 거래처명 | B2: 구분 | C2: 담당자 | D2: 연락처
A3: ○○소재 | B3: 매입처 | C3: 김과장 | D3: 010-0000-0001
A4: △△부품 | B4: 매입처 | C4: 이과장 | D4: 010-0000-0002
A5: □□유통 | B5: 매출처 | C5: 박대리 | D5: 010-0000-0003

Sheet 품목목록
A1: 품목목록
A2: 품번 | B2: 품명 | C2: 규격 | D2: 단위 | E2: 자재구분
A3: A001 | B3: 원단 롤 | C3: 1200mm | D3: 롤 | E3: 원재료
A4: A002 | B4: 접착제 | C4: 20L | D4: 통 | E4: 원재료
A5: B001 | B5: 포장박스 | C5: 300×200 | D5: EA | E5: 부자재
A6: B002 | B6: 라벨 스티커 | C6: 50×30 | D6: EA | E6: 부자재

Sheet 반품접수
A1: 반품접수 (접수번호는 자동)
A2: 접수번호(자동) | B2: 접수일 | C2: 거래처명 | D2: 품번 | E2: 품명(자동) | F2: 규격(자동) | G2: 단위(자동) | H2: 자재구분(자동) | I2: 접수수량 | J2: 구분 | K2: 사유 | L2: 상세내용 | M2: 처리수량(자동) | N2: 잔여수량(자동) | O2: 상태(자동)
A3: =IF($B3="","",TEXT($B3,"yymm")&"-"&TEXT(COUNTIFS($B$3:$B3,">="&DATE(YEAR($B3),MONTH($B3),1),$B$3:$B3,"<="&EOMONTH($B3,0)),"000")) -> 2608-001 | B3: 46262 | C3: ○○소재 | D3: A001 | E3: =IF($D3="","",IFERROR(INDEX(품목목록!$B$3:$B$302,MATCH($D3,품목목록!$A$3:$A$302,0)),"미등록품번")) -> 원단 롤 | F3: =IF($D3="","",IFERROR(INDEX(품목목록!$C$3:$C$302,MATCH($D3,품목목록!$A$3:$A$302,0)),"")) -> 1200mm | G3: =IF($D3="","",IFERROR(INDEX(품목목록!$D$3:$D$302,MATCH($D3,품목목록!$A$3:$A$302,0)),"")) -> 롤 | H3: =IF($D3="","",IFERROR(INDEX(품목목록!$E$3:$E$302,MATCH($D3,품목목록!$A$3:$A$302,0)),"")) -> 원재료 | I3: 3 | J3: 불량 | K3: 오염 | L3: 롤 표면 이물 혼입 | M3: =IF($A3="","",SUMIFS(처리내역!$E$3:$E$1502,처리내역!$B$3:$B$1502,$A3)) -> 2 | N3: =IF($A3="","",IF($I3="","",$I3-$M3)) -> 1 | O3: =IF($A3="","",IF($I3="","",IF($M3=0,"미처리",IF($N3<=0,"완료","부분처리")))) -> 부분처리
A4: =IF($B4="","",TEXT($B4,"yymm")&"-"&TEXT(COUNTIFS($B$3:$B4,">="&DATE(YEAR($B4),MONTH($B4),1),$B$3:$B4,"<="&EOMONTH($B4,0)),"000")) -> 2609-001 | B4: 46267 | C4: △△부품 | D4: A002 | E4: =IF($D4="","",IFERROR(INDEX(품목목록!$B$3:$B$302,MATCH($D4,품목목록!$A$3:$A$302,0)),"미등록품번")) -> 접착제 | F4: =IF($D4="","",IFERROR(INDEX(품목목록!$C$3:$C$302,MATCH($D4,품목목록!$A$3:$A$302,0)),"")) -> 20L | G4: =IF($D4="","",IFERROR(INDEX(품목목록!$D$3:$D$302,MATCH($D4,품목목록!$A$3:$A$302,0)),"")) -> 통 | H4: =IF($D4="","",IFERROR(INDEX(품목목록!$E$3:$E$302,MATCH($D4,품목목록!$A$3:$A$302,0)),"")) -> 원재료 | I4: 2 | J4: 반품 | K4: 규격상이 | L4: 점도 규격 상이 | M4: =IF($A4="","",SUMIFS(처리내역!$E$3:$E$1502,처리내역!$B$3:$B$1502,$A4)) -> 2 | N4: =IF($A4="","",IF($I4="","",$I4-$M4)) -> 0 | O4: =IF($A4="","",IF($I4="","",IF($M4=0,"미처리",IF($N4<=0,"완료","부분처리")))) -> 완료
A5: =IF($B5="","",TEXT($B5,"yymm")&"-"&TEXT(COUNTIFS($B$3:$B5,">="&DATE(YEAR($B5),MONTH($B5),1),$B$3:$B5,"<="&EOMONTH($B5,0)),"000")) -> 2609-002 | B5: 46270 | C5: □□유통 | D5: B001 | E5: =IF($D5="","",IFERROR(INDEX(품목목록!$B$3:$B$302,MATCH($D5,품목목록!$A$3:$A$302,0)),"미등록품번")) -> 포장박스 | F5: =IF($D5="","",IFERROR(INDEX(품목목록!$C$3:$C$302,MATCH($D5,품목목록!$A$3:$A$302,0)),"")) -> 300×200 | G5: =IF($D5="","",IFERROR(INDEX(품목목록!$D$3:$D$302,MATCH($D5,품목목록!$A$3:$A$302,0)),"")) -> EA | H5: =IF($D5="","",IFERROR(INDEX(품목목록!$E$3:$E$302,MATCH($D5,품목목록!$A$3:$A$302,0)),"")) -> 부자재 | I5: 50 | J5: 불량 | K5: 파손 | L5: 모서리 눌림 | M5: =IF($A5="","",SUMIFS(처리내역!$E$3:$E$1502,처리내역!$B$3:$B$1502,$A5)) -> 50 | N5: =IF($A5="","",IF($I5="","",$I5-$M5)) -> 0 | O5: =IF($A5="","",IF($I5="","",IF($M5=0,"미처리",IF($N5<=0,"완료","부분처리")))) -> 완료
A6: =IF($B6="","",TEXT($B6,"yymm")&"-"&TEXT(COUNTIFS($B$3:$B6,">="&DATE(YEAR($B6),MONTH($B6),1),$B$3:$B6,"<="&EOMONTH($B6,0)),"000")) -> 2609-003 | B6: 46274 | C6: □□유통 | D6: B002 | E6: =IF($D6="","",IFERROR(INDEX(품목목록!$B$3:$B$302,MATCH($D6,품목목록!$A$3:$A$302,0)),"미등록품번")) -> 라벨 스티커 | F6: =IF($D6="","",IFERROR(INDEX(품목목록!$C$3:$C$302,MATCH($D6,품목목록!$A$3:$A$302,0)),"")) -> 50×30 | G6: =IF($D6="","",IFERROR(INDEX(품목목록!$D$3:$D$302,MATCH($D6,품목목록!$A$3:$A$302,0)),"")) -> EA | H6: =IF($D6="","",IFERROR(INDEX(품목목록!$E$3:$E$302,MATCH($D6,품목목록!$A$3:$A$302,0)),"")) -> 부자재 | I6: 200 | J6: 반품 | K6: 오배송 | L6: 타 거래처 라벨 혼입 | M6: =IF($A6="","",SUMIFS(처리내역!$E$3:$E$1502,처리내역!$B$3:$B$1502,$A6)) -> 0 | N6: =IF($A6="","",IF($I6="","",$I6-$M6)) -> 200 | O6: =IF($A6="","",IF($I6="","",IF($M6=0,"미처리",IF($N6<=0,"완료","부분처리")))) -> 미처리
A7: =IF($B7="","",TEXT($B7,"yymm")&"-"&TEXT(COUNTIFS($B$3:$B7,">="&DATE(YEAR($B7),MONTH($B7),1),$B$3:$B7,"<="&EOMONTH($B7,0)),"000")) -> 2609-004 | B7: 46277 | C7: ○○소재 | D7: A001 | E7: =IF($D7="","",IFERROR(INDEX(품목목록!$B$3:$B$302,MATCH($D7,품목목록!$A$3:$A$302,0)),"미등록품번")) -> 원단 롤 | F7: =IF($D7="","",IFERROR(INDEX(품목목록!$C$3:$C$302,MATCH($D7,품목목록!$A$3:$A$302,0)),"")) -> 1200mm | G7: =IF($D7="","",IFERROR(INDEX(품목목록!$D$3:$D$302,MATCH($D7,품목목록!$A$3:$A$302,0)),"")) -> 롤 | H7: =IF($D7="","",IFERROR(INDEX(품목목록!$E$3:$E$302,MATCH($D7,품목목록!$A$3:$A$302,0)),"")) -> 원재료 | I7: 1 | J7: 교환 | K7: 유통기한 | L7: 보관기한 초과 | M7: =IF($A7="","",SUMIFS(처리내역!$E$3:$E$1502,처리내역!$B$3:$B$1502,$A7)) -> 0 | N7: =IF($A7="","",IF($I7="","",$I7-$M7)) -> 1 | O7: =IF($A7="","",IF($I7="","",IF($M7=0,"미처리",IF($N7<=0,"완료","부분처리")))) -> 미처리
A8: =IF($B8="","",TEXT($B8,"yymm")&"-"&TEXT(COUNTIFS($B$3:$B8,">="&DATE(YEAR($B8),MONTH($B8),1),$B$3:$B8,"<="&EOMONTH($B8,0)),"000")) | E8: =IF($D8="","",IFERROR(INDEX(품목목록!$B$3:$B$302,MATCH($D8,품목목록!$A$3:$A$302,0)),"미등록품번")) | F8: =IF($D8="","",IFERROR(INDEX(품목목록!$C$3:$C$302,MATCH($D8,품목목록!$A$3:$A$302,0)),"")) | G8: =IF($D8="","",IFERROR(INDEX(품목목록!$D$3:$D$302,MATCH($D8,품목목록!$A$3:$A$302,0)),"")) | H8: =IF($D8="","",IFERROR(INDEX(품목목록!$E$3:$E$302,MATCH($D8,품목목록!$A$3:$A$302,0)),"")) | M8: =IF($A8="","",SUMIFS(처리내역!$E$3:$E$1502,처리내역!$B$3:$B$1502,$A8)) | N8: =IF($A8="","",IF($I8="","",$I8-$M8)) | O8: =IF($A8="","",IF($I8="","",IF($M8=0,"미처리",IF($N8<=0,"완료","부분처리"))))
A9: =IF($B9="","",TEXT($B9,"yymm")&"-"&TEXT(COUNTIFS($B$3:$B9,">="&DATE(YEAR($B9),MONTH($B9),1),$B$3:$B9,"<="&EOMONTH($B9,0)),"000")) | E9: =IF($D9="","",IFERROR(INDEX(품목목록!$B$3:$B$302,MATCH($D9,품목목록!$A$3:$A$302,0)),"미등록품번")) | F9: =IF($D9="","",IFERROR(INDEX(품목목록!$C$3:$C$302,MATCH($D9,품목목록!$A$3:$A$302,0)),"")) | G9: =IF($D9="","",IFERROR(INDEX(품목목록!$D$3:$D$302,MATCH($D9,품목목록!$A$3:$A$302,0)),"")) | H9: =IF($D9="","",IFERROR(INDEX(품목목록!$E$3:$E$302,MATCH($D9,품목목록!$A$3:$A$302,0)),"")) | M9: =IF($A9="","",SUMIFS(처리내역!$E$3:$E$1502,처리내역!$B$3:$B$1502,$A9)) | N9: =IF($A9="","",IF($I9="","",$I9-$M9)) | O9: =IF($A9="","",IF($I9="","",IF($M9=0,"미처리",IF($N9<=0,"완료","부분처리"))))
A10: =IF($B10="","",TEXT($B10,"yymm")&"-"&TEXT(COUNTIFS($B$3:$B10,">="&DATE(YEAR($B10),MONTH($B10),1),$B$3:$B10,"<="&EOMONTH($B10,0)),"000")) | E10: =IF($D10="","",IFERROR(INDEX(품목목록!$B$3:$B$302,MATCH($D10,품목목록!$A$3:$A$302,0)),"미등록품번")) | F10: =IF($D10="","",IFERROR(INDEX(품목목록!$C$3:$C$302,MATCH($D10,품목목록!$A$3:$A$302,0)),"")) | G10: =IF($D10="","",IFERROR(INDEX(품목목록!$D$3:$D$302,MATCH($D10,품목목록!$A$3:$A$302,0)),"")) | H10: =IF($D10="","",IFERROR(INDEX(품목목록!$E$3:$E$302,MATCH($D10,품목목록!$A$3:$A$302,0)),"")) | M10: =IF($A10="","",SUMIFS(처리내역!$E$3:$E$1502,처리내역!$B$3:$B$1502,$A10)) | N10: =IF($A10="","",IF($I10="","",$I10-$M10)) | O10: =IF($A10="","",IF($I10="","",IF($M10=0,"미처리",IF($N10<=0,"완료","부분처리"))))
A11: =IF($B11="","",TEXT($B11,"yymm")&"-"&TEXT(COUNTIFS($B$3:$B11,">="&DATE(YEAR($B11),MONTH($B11),1),$B$3:$B11,"<="&EOMONTH($B11,0)),"000")) | E11: =IF($D11="","",IFERROR(INDEX(품목목록!$B$3:$B$302,MATCH($D11,품목목록!$A$3:$A$302,0)),"미등록품번")) | F11: =IF($D11="","",IFERROR(INDEX(품목목록!$C$3:$C$302,MATCH($D11,품목목록!$A$3:$A$302,0)),"")) | G11: =IF($D11="","",IFERROR(INDEX(품목목록!$D$3:$D$302,MATCH($D11,품목목록!$A$3:$A$302,0)),"")) | H11: =IF($D11="","",IFERROR(INDEX(품목목록!$E$3:$E$302,MATCH($D11,품목목록!$A$3:$A$302,0)),"")) | M11: =IF($A11="","",SUMIFS(처리내역!$E$3:$E$1502,처리내역!$B$3:$B$1502,$A11)) | N11: =IF($A11="","",IF($I11="","",$I11-$M11)) | O11: =IF($A11="","",IF($I11="","",IF($M11=0,"미처리",IF($N11<=0,"완료","부분처리"))))
A12: =IF($B12="","",TEXT($B12,"yymm")&"-"&TEXT(COUNTIFS($B$3:$B12,">="&DATE(YEAR($B12),MONTH($B12),1),$B$3:$B12,"<="&EOMONTH($B12,0)),"000")) | E12: =IF($D12="","",IFERROR(INDEX(품목목록!$B$3:$B$302,MATCH($D12,품목목록!$A$3:$A$302,0)),"미등록품번")) | F12: =IF($D12="","",IFERROR(INDEX(품목목록!$C$3:$C$302,MATCH($D12,품목목록!$A$3:$A$302,0)),"")) | G12: =IF($D12="","",IFERROR(INDEX(품목목록!$D$3:$D$302,MATCH($D12,품목목록!$A$3:$A$302,0)),"")) | H12: =IF($D12="","",IFERROR(INDEX(품목목록!$E$3:$E$302,MATCH($D12,품목목록!$A$3:$A$302,0)),"")) | M12: =IF($A12="","",SUMIFS(처리내역!$E$3:$E$1502,처리내역!$B$3:$B$1502,$A12)) | N12: =IF($A12="","",IF($I12="","",$I12-$M12)) | O12: =IF($A12="","",IF($I12="","",IF($M12=0,"미처리",IF($N12<=0,"완료","부분처리"))))
A13: =IF($B13="","",TEXT($B13,"yymm")&"-"&TEXT(COUNTIFS($B$3:$B13,">="&DATE(YEAR($B13),MONTH($B13),1),$B$3:$B13,"<="&EOMONTH($B13,0)),"000")) | E13: =IF($D13="","",IFERROR(INDEX(품목목록!$B$3:$B$302,MATCH($D13,품목목록!$A$3:$A$302,0)),"미등록품번")) | F13: =IF($D13="","",IFERROR(INDEX(품목목록!$C$3:$C$302,MATCH($D13,품목목록!$A$3:$A$302,0)),"")) | G13: =IF($D13="","",IFERROR(INDEX(품목목록!$D$3:$D$302,MATCH($D13,품목목록!$A$3:$A$302,0)),"")) | H13: =IF($D13="","",IFERROR(INDEX(품목목록!$E$3:$E$302,MATCH($D13,품목목록!$A$3:$A$302,0)),"")) | M13: =IF($A13="","",SUMIFS(처리내역!$E$3:$E$1502,처리내역!$B$3:$B$1502,$A13)) | N13: =IF($A13="","",IF($I13="","",$I13-$M13)) | O13: =IF($A13="","",IF($I13="","",IF($M13=0,"미처리",IF($N13<=0,"완료","부분처리"))))
A14: =IF($B14="","",TEXT($B14,"yymm")&"-"&TEXT(COUNTIFS($B$3:$B14,">="&DATE(YEAR($B14),MONTH($B14),1),$B$3:$B14,"<="&EOMONTH($B14,0)),"000")) | E14: =IF($D14="","",IFERROR(INDEX(품목목록!$B$3:$B$302,MATCH($D14,품목목록!$A$3:$A$302,0)),"미등록품번")) | F14: =IF($D14="","",IFERROR(INDEX(품목목록!$C$3:$C$302,MATCH($D14,품목목록!$A$3:$A$302,0)),"")) | G14: =IF($D14="","",IFERROR(INDEX(품목목록!$D$3:$D$302,MATCH($D14,품목목록!$A$3:$A$302,0)),"")) | H14: =IF($D14="","",IFERROR(INDEX(품목목록!$E$3:$E$302,MATCH($D14,품목목록!$A$3:$A$302,0)),"")) | M14: =IF($A14="","",SUMIFS(처리내역!$E$3:$E$1502,처리내역!$B$3:$B$1502,$A14)) | N14: =IF($A14="","",IF($I14="","",$I14-$M14)) | O14: =IF($A14="","",IF($I14="","",IF($M14=0,"미처리",IF($N14<=0,"완료","부분처리"))))
A15: =IF($B15="","",TEXT($B15,"yymm")&"-"&TEXT(COUNTIFS($B$3:$B15,">="&DATE(YEAR($B15),MONTH($B15),1),$B$3:$B15,"<="&EOMONTH($B15,0)),"000")) | E15: =IF($D15="","",IFERROR(INDEX(품목목록!$B$3:$B$302,MATCH($D15,품목목록!$A$3:$A$302,0)),"미등록품번")) | F15: =IF($D15="","",IFERROR(INDEX(품목목록!$C$3:$C$302,MATCH($D15,품목목록!$A$3:$A$302,0)),"")) | G15: =IF($D15="","",IFERROR(INDEX(품목목록!$D$3:$D$302,MATCH($D15,품목목록!$A$3:$A$302,0)),"")) | H15: =IF($D15="","",IFERROR(INDEX(품목목록!$E$3:$E$302,MATCH($D15,품목목록!$A$3:$A$302,0)),"")) | M15: =IF($A15="","",SUMIFS(처리내역!$E$3:$E$1502,처리내역!$B$3:$B$1502,$A15)) | N15: =IF($A15="","",IF($I15="","",$I15-$M15)) | O15: =IF($A15="","",IF($I15="","",IF($M15=0,"미처리",IF($N15<=0,"완료","부분처리"))))
A16: =IF($B16="","",TEXT($B16,"yymm")&"-"&TEXT(COUNTIFS($B$3:$B16,">="&DATE(YEAR($B16),MONTH($B16),1),$B$3:$B16,"<="&EOMONTH($B16,0)),"000")) | E16: =IF($D16="","",IFERROR(INDEX(품목목록!$B$3:$B$302,MATCH($D16,품목목록!$A$3:$A$302,0)),"미등록품번")) | F16: =IF($D16="","",IFERROR(INDEX(품목목록!$C$3:$C$302,MATCH($D16,품목목록!$A$3:$A$302,0)),"")) | G16: =IF($D16="","",IFERROR(INDEX(품목목록!$D$3:$D$302,MATCH($D16,품목목록!$A$3:$A$302,0)),"")) | H16: =IF($D16="","",IFERROR(INDEX(품목목록!$E$3:$E$302,MATCH($D16,품목목록!$A$3:$A$302,0)),"")) | M16: =IF($A16="","",SUMIFS(처리내역!$E$3:$E$1502,처리내역!$B$3:$B$1502,$A16)) | N16: =IF($A16="","",IF($I16="","",$I16-$M16)) | O16: =IF($A16="","",IF($I16="","",IF($M16=0,"미처리",IF($N16<=0,"완료","부분처리"))))
A17: =IF($B17="","",TEXT($B17,"yymm")&"-"&TEXT(COUNTIFS($B$3:$B17,">="&DATE(YEAR($B17),MONTH($B17),1),$B$3:$B17,"<="&EOMONTH($B17,0)),"000")) | E17: =IF($D17="","",IFERROR(INDEX(품목목록!$B$3:$B$302,MATCH($D17,품목목록!$A$3:$A$302,0)),"미등록품번")) | F17: =IF($D17="","",IFERROR(INDEX(품목목록!$C$3:$C$302,MATCH($D17,품목목록!$A$3:$A$302,0)),"")) | G17: =IF($D17="","",IFERROR(INDEX(품목목록!$D$3:$D$302,MATCH($D17,품목목록!$A$3:$A$302,0)),"")) | H17: =IF($D17="","",IFERROR(INDEX(품목목록!$E$3:$E$302,MATCH($D17,품목목록!$A$3:$A$302,0)),"")) | M17: =IF($A17="","",SUMIFS(처리내역!$E$3:$E$1502,처리내역!$B$3:$B$1502,$A17)) | N17: =IF($A17="","",IF($I17="","",$I17-$M17)) | O17: =IF($A17="","",IF($I17="","",IF($M17=0,"미처리",IF($N17<=0,"완료","부분처리"))))
A18: =IF($B18="","",TEXT($B18,"yymm")&"-"&TEXT(COUNTIFS($B$3:$B18,">="&DATE(YEAR($B18),MONTH($B18),1),$B$3:$B18,"<="&EOMONTH($B18,0)),"000")) | E18: =IF($D18="","",IFERROR(INDEX(품목목록!$B$3:$B$302,MATCH($D18,품목목록!$A$3:$A$302,0)),"미등록품번")) | F18: =IF($D18="","",IFERROR(INDEX(품목목록!$C$3:$C$302,MATCH($D18,품목목록!$A$3:$A$302,0)),"")) | G18: =IF($D18="","",IFERROR(INDEX(품목목록!$D$3:$D$302,MATCH($D18,품목목록!$A$3:$A$302,0)),"")) | H18: =IF($D18="","",IFERROR(INDEX(품목목록!$E$3:$E$302,MATCH($D18,품목목록!$A$3:$A$302,0)),"")) | M18: =IF($A18="","",SUMIFS(처리내역!$E$3:$E$1502,처리내역!$B$3:$B$1502,$A18)) | N18: =IF($A18="","",IF($I18="","",$I18-$M18)) | O18: =IF($A18="","",IF($I18="","",IF($M18=0,"미처리",IF($N18<=0,"완료","부분처리"))))
A19: =IF($B19="","",TEXT($B19,"yymm")&"-"&TEXT(COUNTIFS($B$3:$B19,">="&DATE(YEAR($B19),MONTH($B19),1),$B$3:$B19,"<="&EOMONTH($B19,0)),"000")) | E19: =IF($D19="","",IFERROR(INDEX(품목목록!$B$3:$B$302,MATCH($D19,품목목록!$A$3:$A$302,0)),"미등록품번")) | F19: =IF($D19="","",IFERROR(INDEX(품목목록!$C$3:$C$302,MATCH($D19,품목목록!$A$3:$A$302,0)),"")) | G19: =IF($D19="","",IFERROR(INDEX(품목목록!$D$3:$D$302,MATCH($D19,품목목록!$A$3:$A$302,0)),"")) | H19: =IF($D19="","",IFERROR(INDEX(품목목록!$E$3:$E$302,MATCH($D19,품목목록!$A$3:$A$302,0)),"")) | M19: =IF($A19="","",SUMIFS(처리내역!$E$3:$E$1502,처리내역!$B$3:$B$1502,$A19)) | N19: =IF($A19="","",IF($I19="","",$I19-$M19)) | O19: =IF($A19="","",IF($I19="","",IF($M19=0,"미처리",IF($N19<=0,"완료","부분처리"))))
... A1002: =IF($B1002="","",TEXT($B1002,"yymm")&"-"&TEXT(COUNTIFS($B$3:$B1002,">="&DATE(YEAR($B1002),MONTH($B1002),1),$B$3:$B1002,"<="&EOMONTH($B1002,0)),"000")) | E1002: =IF($D1002="","",IFERROR(INDEX(품목목록!$B$3:$B$302,MATCH($D1002,품목목록!$A$3:$A$302,0)),"미등록품번")) | F1002: =IF($D1002="","",IFERROR(INDEX(품목목록!$C$3:$C$302,MATCH($D1002,품목목록!$A$3:$A$302,0)),"")) | G1002: =IF($D1002="","",IFERROR(INDEX(품목목록!$D$3:$D$302,MATCH($D1002,품목목록!$A$3:$A$302,0)),"")) | H1002: =IF($D1002="","",IFERROR(INDEX(품목목록!$E$3:$E$302,MATCH($D1002,품목목록!$A$3:$A$302,0)),"")) | M1002: =IF($A1002="","",SUMIFS(처리내역!$E$3:$E$1502,처리내역!$B$3:$B$1502,$A1002)) | N1002: =IF($A1002="","",IF($I1002="","",$I1002-$M1002)) | O1002: =IF($A1002="","",IF($I1002="","",IF($M1002=0,"미처리",IF($N1002<=0,"완료","부분처리"))))
A1004: ※ 접수번호는 '연월-순번' 형태로 자동 생성됩니다. 처리내역에서 이 번호를 씁니다.

Sheet 처리내역
A1: 처리내역 (한 건을 나눠서 처리해도 됩니다)
A2: 처리일 | B2: 접수번호 | C2: 품명(자동) | D2: 처리방법 | E2: 처리수량 | F2: 처리자 | G2: 비용 | H2: 비고
A3: 46266 | B3: 2608-001 | C3: =IF($B3="","",IFERROR(INDEX(반품접수!$E$3:$E$1002,MATCH($B3,반품접수!$A$3:$A$1002,0)),"접수번호없음")) -> 원단 롤 | D3: 폐기 | E3: 2 | F3: 김검사 | G3: 60000 | H3: ← 예시 행입니다. 지우고 쓰세요.
A4: 46269 | B4: 2609-001 | C4: =IF($B4="","",IFERROR(INDEX(반품접수!$E$3:$E$1002,MATCH($B4,반품접수!$A$3:$A$1002,0)),"접수번호없음")) -> 접착제 | D4: 반송 | E4: 2 | F4: 김검사 | G4: 30000
A5: 46273 | B5: 2609-002 | C5: =IF($B5="","",IFERROR(INDEX(반품접수!$E$3:$E$1002,MATCH($B5,반품접수!$A$3:$A$1002,0)),"접수번호없음")) -> 포장박스 | D5: 재입고 | E5: 30 | F5: 이검사
A6: 46273 | B6: 2609-002 | C6: =IF($B6="","",IFERROR(INDEX(반품접수!$E$3:$E$1002,MATCH($B6,반품접수!$A$3:$A$1002,0)),"접수번호없음")) -> 포장박스 | D6: 폐기 | E6: 20 | F6: 이검사 | G6: 40000
C7: =IF($B7="","",IFERROR(INDEX(반품접수!$E$3:$E$1002,MATCH($B7,반품접수!$A$3:$A$1002,0)),"접수번호없음"))
C8: =IF($B8="","",IFERROR(INDEX(반품접수!$E$3:$E$1002,MATCH($B8,반품접수!$A$3:$A$1002,0)),"접수번호없음"))
C9: =IF($B9="","",IFERROR(INDEX(반품접수!$E$3:$E$1002,MATCH($B9,반품접수!$A$3:$A$1002,0)),"접수번호없음"))
C10: =IF($B10="","",IFERROR(INDEX(반품접수!$E$3:$E$1002,MATCH($B10,반품접수!$A$3:$A$1002,0)),"접수번호없음"))
C11: =IF($B11="","",IFERROR(INDEX(반품접수!$E$3:$E$1002,MATCH($B11,반품접수!$A$3:$A$1002,0)),"접수번호없음"))
C12: =IF($B12="","",IFERROR(INDEX(반품접수!$E$3:$E$1002,MATCH($B12,반품접수!$A$3:$A$1002,0)),"접수번호없음"))
C13: =IF($B13="","",IFERROR(INDEX(반품접수!$E$3:$E$1002,MATCH($B13,반품접수!$A$3:$A$1002,0)),"접수번호없음"))
C14: =IF($B14="","",IFERROR(INDEX(반품접수!$E$3:$E$1002,MATCH($B14,반품접수!$A$3:$A$1002,0)),"접수번호없음"))
C15: =IF($B15="","",IFERROR(INDEX(반품접수!$E$3:$E$1002,MATCH($B15,반품접수!$A$3:$A$1002,0)),"접수번호없음"))
C16: =IF($B16="","",IFERROR(INDEX(반품접수!$E$3:$E$1002,MATCH($B16,반품접수!$A$3:$A$1002,0)),"접수번호없음"))
C17: =IF($B17="","",IFERROR(INDEX(반품접수!$E$3:$E$1002,MATCH($B17,반품접수!$A$3:$A$1002,0)),"접수번호없음"))
C18: =IF($B18="","",IFERROR(INDEX(반품접수!$E$3:$E$1002,MATCH($B18,반품접수!$A$3:$A$1002,0)),"접수번호없음"))
... C1502: =IF($B1502="","",IFERROR(INDEX(반품접수!$E$3:$E$1002,MATCH($B1502,반품접수!$A$3:$A$1002,0)),"접수번호없음"))

Sheet 미처리현황
A1: 미처리현황 (아직 못 끝낸 건)
A3: 미처리 건수 | B3: =COUNTIF(반품접수!$O$3:$O$1002,"미처리")+COUNTIF(반품접수!$O$3:$O$1002,"부분처리") -> 3 | D3: 장기 미처리 | E3: =SUMPRODUCT((반품접수!$O$3:$O$1002<>"완료")*(반품접수!$O$3:$O$1002<>"")*((TODAY()-반품접수!$B$3:$B$1002)>사용안내!$C$17)) -> 1 | G3: 미처리 수량 | H3: =SUMIFS(반품접수!$N$3:$N$1002,반품접수!$O$3:$O$1002,"미처리")+SUMIFS(반품접수!$N$3:$N$1002,반품접수!$O$3:$O$1002,"부분처리") -> 202
A5: 순번 | B5: 접수번호 | C5: 접수일 | D5: 경과일 | E5: 거래처명 | F5: 품명 | G5: 접수수량 | H5: 잔여수량 | I5: 상태 | K5: 대상(자동) | L5: 순번(자동) | M5: 키(자동)
A6: =IF($B6="","",1) -> 1 | B6: =IFERROR(INDEX(반품접수!$A$3:$A$1002,MATCH("R"&1,미처리현황!$M$6:$M$1005,0)),"") -> 2608-001 | C6: =IF($B6="","",IFERROR(INDEX(반품접수!$B$3:$B$1002,MATCH("R"&1,미처리현황!$M$6:$M$1005,0)),"")) -> 46262 | D6: =IF($C6="","",TODAY()-$C6) -> 17 | E6: =IF($B6="","",IFERROR(INDEX(반품접수!$C$3:$C$1002,MATCH("R"&1,미처리현황!$M$6:$M$1005,0)),"")) -> ○○소재 | F6: =IF($B6="","",IFERROR(INDEX(반품접수!$E$3:$E$1002,MATCH("R"&1,미처리현황!$M$6:$M$1005,0)),"")) -> 원단 롤 | G6: =IF($B6="","",IFERROR(INDEX(반품접수!$I$3:$I$1002,MATCH("R"&1,미처리현황!$M$6:$M$1005,0)),"")) -> 3 | H6: =IF($B6="","",IFERROR(INDEX(반품접수!$N$3:$N$1002,MATCH("R"&1,미처리현황!$M$6:$M$1005,0)),"")) -> 1 | I6: =IF($B6="","",IFERROR(INDEX(반품접수!$O$3:$O$1002,MATCH("R"&1,미처리현황!$M$6:$M$1005,0)),"")) -> 부분처리 | K6: =IF(반품접수!$A3="",FALSE(),OR(반품접수!$O3="미처리",반품접수!$O3="부분처리")) -> TRUE | L6: =IF($K6=FALSE(),"",COUNTIF($K$6:$K6,TRUE())) -> 1 | M6: =IF($L6="","","R"&$L6) -> R1
A7: =IF($B7="","",2) -> 2 | B7: =IFERROR(INDEX(반품접수!$A$3:$A$1002,MATCH("R"&2,미처리현황!$M$6:$M$1005,0)),"") -> 2609-003 | C7: =IF($B7="","",IFERROR(INDEX(반품접수!$B$3:$B$1002,MATCH("R"&2,미처리현황!$M$6:$M$1005,0)),"")) -> 46274 | D7: =IF($C7="","",TODAY()-$C7) -> 5 | E7: =IF($B7="","",IFERROR(INDEX(반품접수!$C$3:$C$1002,MATCH("R"&2,미처리현황!$M$6:$M$1005,0)),"")) -> □□유통 | F7: =IF($B7="","",IFERROR(INDEX(반품접수!$E$3:$E$1002,MATCH("R"&2,미처리현황!$M$6:$M$1005,0)),"")) -> 라벨 스티커 | G7: =IF($B7="","",IFERROR(INDEX(반품접수!$I$3:$I$1002,MATCH("R"&2,미처리현황!$M$6:$M$1005,0)),"")) -> 200 | H7: =IF($B7="","",IFERROR(INDEX(반품접수!$N$3:$N$1002,MATCH("R"&2,미처리현황!$M$6:$M$1005,0)),"")) -> 200 | I7: =IF($B7="","",IFERROR(INDEX(반품접수!$O$3:$O$1002,MATCH("R"&2,미처리현황!$M$6:$M$1005,0)),"")) -> 미처리 | K7: =IF(반품접수!$A4="",FALSE(),OR(반품접수!$O4="미처리",반품접수!$O4="부분처리")) -> FALSE | L7: =IF($K7=FALSE(),"",COUNTIF($K$6:$K7,TRUE())) | M7: =IF($L7="","","R"&$L7)
A8: =IF($B8="","",3) -> 3 | B8: =IFERROR(INDEX(반품접수!$A$3:$A$1002,MATCH("R"&3,미처리현황!$M$6:$M$1005,0)),"") -> 2609-004 | C8: =IF($B8="","",IFERROR(INDEX(반품접수!$B$3:$B$1002,MATCH("R"&3,미처리현황!$M$6:$M$1005,0)),"")) -> 46277 | D8: =IF($C8="","",TODAY()-$C8) -> 2 | E8: =IF($B8="","",IFERROR(INDEX(반품접수!$C$3:$C$1002,MATCH("R"&3,미처리현황!$M$6:$M$1005,0)),"")) -> ○○소재 | F8: =IF($B8="","",IFERROR(INDEX(반품접수!$E$3:$E$1002,MATCH("R"&3,미처리현황!$M$6:$M$1005,0)),"")) -> 원단 롤 | G8: =IF($B8="","",IFERROR(INDEX(반품접수!$I$3:$I$1002,MATCH("R"&3,미처리현황!$M$6:$M$1005,0)),"")) -> 1 | H8: =IF($B8="","",IFERROR(INDEX(반품접수!$N$3:$N$1002,MATCH("R"&3,미처리현황!$M$6:$M$1005,0)),"")) -> 1 | I8: =IF($B8="","",IFERROR(INDEX(반품접수!$O$3:$O$1002,MATCH("R"&3,미처리현황!$M$6:$M$1005,0)),"")) -> 미처리 | K8: =IF(반품접수!$A5="",FALSE(),OR(반품접수!$O5="미처리",반품접수!$O5="부분처리")) -> FALSE | L8: =IF($K8=FALSE(),"",COUNTIF($K$6:$K8,TRUE())) | M8: =IF($L8="","","R"&$L8)
A9: =IF($B9="","",4) | B9: =IFERROR(INDEX(반품접수!$A$3:$A$1002,MATCH("R"&4,미처리현황!$M$6:$M$1005,0)),"") | C9: =IF($B9="","",IFERROR(INDEX(반품접수!$B$3:$B$1002,MATCH("R"&4,미처리현황!$M$6:$M$1005,0)),"")) | D9: =IF($C9="","",TODAY()-$C9) | E9: =IF($B9="","",IFERROR(INDEX(반품접수!$C$3:$C$1002,MATCH("R"&4,미처리현황!$M$6:$M$1005,0)),"")) | F9: =IF($B9="","",IFERROR(INDEX(반품접수!$E$3:$E$1002,MATCH("R"&4,미처리현황!$M$6:$M$1005,0)),"")) | G9: =IF($B9="","",IFERROR(INDEX(반품접수!$I$3:$I$1002,MATCH("R"&4,미처리현황!$M$6:$M$1005,0)),"")) | H9: =IF($B9="","",IFERROR(INDEX(반품접수!$N$3:$N$1002,MATCH("R"&4,미처리현황!$M$6:$M$1005,0)),"")) | I9: =IF($B9="","",IFERROR(INDEX(반품접수!$O$3:$O$1002,MATCH("R"&4,미처리현황!$M$6:$M$1005,0)),"")) | K9: =IF(반품접수!$A6="",FALSE(),OR(반품접수!$O6="미처리",반품접수!$O6="부분처리")) -> TRUE | L9: =IF($K9=FALSE(),"",COUNTIF($K$6:$K9,TRUE())) -> 2 | M9: =IF($L9="","","R"&$L9) -> R2
A10: =IF($B10="","",5) | B10: =IFERROR(INDEX(반품접수!$A$3:$A$1002,MATCH("R"&5,미처리현황!$M$6:$M$1005,0)),"") | C10: =IF($B10="","",IFERROR(INDEX(반품접수!$B$3:$B$1002,MATCH("R"&5,미처리현황!$M$6:$M$1005,0)),"")) | D10: =IF($C10="","",TODAY()-$C10) | E10: =IF($B10="","",IFERROR(INDEX(반품접수!$C$3:$C$1002,MATCH("R"&5,미처리현황!$M$6:$M$1005,0)),"")) | F10: =IF($B10="","",IFERROR(INDEX(반품접수!$E$3:$E$1002,MATCH("R"&5,미처리현황!$M$6:$M$1005,0)),"")) | G10: =IF($B10="","",IFERROR(INDEX(반품접수!$I$3:$I$1002,MATCH("R"&5,미처리현황!$M$6:$M$1005,0)),"")) | H10: =IF($B10="","",IFERROR(INDEX(반품접수!$N$3:$N$1002,MATCH("R"&5,미처리현황!$M$6:$M$1005,0)),"")) | I10: =IF($B10="","",IFERROR(INDEX(반품접수!$O$3:$O$1002,MATCH("R"&5,미처리현황!$M$6:$M$1005,0)),"")) | K10: =IF(반품접수!$A7="",FALSE(),OR(반품접수!$O7="미처리",반품접수!$O7="부분처리")) -> TRUE | L10: =IF($K10=FALSE(),"",COUNTIF($K$6:$K10,TRUE())) -> 3 | M10: =IF($L10="","","R"&$L10) -> R3
A11: =IF($B11="","",6) | B11: =IFERROR(INDEX(반품접수!$A$3:$A$1002,MATCH("R"&6,미처리현황!$M$6:$M$1005,0)),"") | C11: =IF($B11="","",IFERROR(INDEX(반품접수!$B$3:$B$1002,MATCH("R"&6,미처리현황!$M$6:$M$1005,0)),"")) | D11: =IF($C11="","",TODAY()-$C11) | E11: =IF($B11="","",IFERROR(INDEX(반품접수!$C$3:$C$1002,MATCH("R"&6,미처리현황!$M$6:$M$1005,0)),"")) | F11: =IF($B11="","",IFERROR(INDEX(반품접수!$E$3:$E$1002,MATCH("R"&6,미처리현황!$M$6:$M$1005,0)),"")) | G11: =IF($B11="","",IFERROR(INDEX(반품접수!$I$3:$I$1002,MATCH("R"&6,미처리현황!$M$6:$M$1005,0)),"")) | H11: =IF($B11="","",IFERROR(INDEX(반품접수!$N$3:$N$1002,MATCH("R"&6,미처리현황!$M$6:$M$1005,0)),"")) | I11: =IF($B11="","",IFERROR(INDEX(반품접수!$O$3:$O$1002,MATCH("R"&6,미처리현황!$M$6:$M$1005,0)),"")) | K11: =IF(반품접수!$A8="",FALSE(),OR(반품접수!$O8="미처리",반품접수!$O8="부분처리")) -> FALSE | L11: =IF($K11=FALSE(),"",COUNTIF($K$6:$K11,TRUE())) | M11: =IF($L11="","","R"&$L11)
A12: =IF($B12="","",7) | B12: =IFERROR(INDEX(반품접수!$A$3:$A$1002,MATCH("R"&7,미처리현황!$M$6:$M$1005,0)),"") | C12: =IF($B12="","",IFERROR(INDEX(반품접수!$B$3:$B$1002,MATCH("R"&7,미처리현황!$M$6:$M$1005,0)),"")) | D12: =IF($C12="","",TODAY()-$C12) | E12: =IF($B12="","",IFERROR(INDEX(반품접수!$C$3:$C$1002,MATCH("R"&7,미처리현황!$M$6:$M$1005,0)),"")) | F12: =IF($B12="","",IFERROR(INDEX(반품접수!$E$3:$E$1002,MATCH("R"&7,미처리현황!$M$6:$M$1005,0)),"")) | G12: =IF($B12="","",IFERROR(INDEX(반품접수!$I$3:$I$1002,MATCH("R"&7,미처리현황!$M$6:$M$1005,0)),"")) | H12: =IF($B12="","",IFERROR(INDEX(반품접수!$N$3:$N$1002,MATCH("R"&7,미처리현황!$M$6:$M$1005,0)),"")) | I12: =IF($B12="","",IFERROR(INDEX(반품접수!$O$3:$O$1002,MATCH("R"&7,미처리현황!$M$6:$M$1005,0)),"")) | K12: =IF(반품접수!$A9="",FALSE(),OR(반품접수!$O9="미처리",반품접수!$O9="부분처리")) -> FALSE | L12: =IF($K12=FALSE(),"",COUNTIF($K$6:$K12,TRUE())) | M12: =IF($L12="","","R"&$L12)
A13: =IF($B13="","",8) | B13: =IFERROR(INDEX(반품접수!$A$3:$A$1002,MATCH("R"&8,미처리현황!$M$6:$M$1005,0)),"") | C13: =IF($B13="","",IFERROR(INDEX(반품접수!$B$3:$B$1002,MATCH("R"&8,미처리현황!$M$6:$M$1005,0)),"")) | D13: =IF($C13="","",TODAY()-$C13) | E13: =IF($B13="","",IFERROR(INDEX(반품접수!$C$3:$C$1002,MATCH("R"&8,미처리현황!$M$6:$M$1005,0)),"")) | F13: =IF($B13="","",IFERROR(INDEX(반품접수!$E$3:$E$1002,MATCH("R"&8,미처리현황!$M$6:$M$1005,0)),"")) | G13: =IF($B13="","",IFERROR(INDEX(반품접수!$I$3:$I$1002,MATCH("R"&8,미처리현황!$M$6:$M$1005,0)),"")) | H13: =IF($B13="","",IFERROR(INDEX(반품접수!$N$3:$N$1002,MATCH("R"&8,미처리현황!$M$6:$M$1005,0)),"")) | I13: =IF($B13="","",IFERROR(INDEX(반품접수!$O$3:$O$1002,MATCH("R"&8,미처리현황!$M$6:$M$1005,0)),"")) | K13: =IF(반품접수!$A10="",FALSE(),OR(반품접수!$O10="미처리",반품접수!$O10="부분처리")) -> FALSE | L13: =IF($K13=FALSE(),"",COUNTIF($K$6:$K13,TRUE())) | M13: =IF($L13="","","R"&$L13)
A14: =IF($B14="","",9) | B14: =IFERROR(INDEX(반품접수!$A$3:$A$1002,MATCH("R"&9,미처리현황!$M$6:$M$1005,0)),"") | C14: =IF($B14="","",IFERROR(INDEX(반품접수!$B$3:$B$1002,MATCH("R"&9,미처리현황!$M$6:$M$1005,0)),"")) | D14: =IF($C14="","",TODAY()-$C14) | E14: =IF($B14="","",IFERROR(INDEX(반품접수!$C$3:$C$1002,MATCH("R"&9,미처리현황!$M$6:$M$1005,0)),"")) | F14: =IF($B14="","",IFERROR(INDEX(반품접수!$E$3:$E$1002,MATCH("R"&9,미처리현황!$M$6:$M$1005,0)),"")) | G14: =IF($B14="","",IFERROR(INDEX(반품접수!$I$3:$I$1002,MATCH("R"&9,미처리현황!$M$6:$M$1005,0)),"")) | H14: =IF($B14="","",IFERROR(INDEX(반품접수!$N$3:$N$1002,MATCH("R"&9,미처리현황!$M$6:$M$1005,0)),"")) | I14: =IF($B14="","",IFERROR(INDEX(반품접수!$O$3:$O$1002,MATCH("R"&9,미처리현황!$M$6:$M$1005,0)),"")) | K14: =IF(반품접수!$A11="",FALSE(),OR(반품접수!$O11="미처리",반품접수!$O11="부분처리")) -> FALSE | L14: =IF($K14=FALSE(),"",COUNTIF($K$6:$K14,TRUE())) | M14: =IF($L14="","","R"&$L14)
A15: =IF($B15="","",10) | B15: =IFERROR(INDEX(반품접수!$A$3:$A$1002,MATCH("R"&10,미처리현황!$M$6:$M$1005,0)),"") | C15: =IF($B15="","",IFERROR(INDEX(반품접수!$B$3:$B$1002,MATCH("R"&10,미처리현황!$M$6:$M$1005,0)),"")) | D15: =IF($C15="","",TODAY()-$C15) | E15: =IF($B15="","",IFERROR(INDEX(반품접수!$C$3:$C$1002,MATCH("R"&10,미처리현황!$M$6:$M$1005,0)),"")) | F15: =IF($B15="","",IFERROR(INDEX(반품접수!$E$3:$E$1002,MATCH("R"&10,미처리현황!$M$6:$M$1005,0)),"")) | G15: =IF($B15="","",IFERROR(INDEX(반품접수!$I$3:$I$1002,MATCH("R"&10,미처리현황!$M$6:$M$1005,0)),"")) | H15: =IF($B15="","",IFERROR(INDEX(반품접수!$N$3:$N$1002,MATCH("R"&10,미처리현황!$M$6:$M$1005,0)),"")) | I15: =IF($B15="","",IFERROR(INDEX(반품접수!$O$3:$O$1002,MATCH("R"&10,미처리현황!$M$6:$M$1005,0)),"")) | K15: =IF(반품접수!$A12="",FALSE(),OR(반품접수!$O12="미처리",반품접수!$O12="부분처리")) -> FALSE | L15: =IF($K15=FALSE(),"",COUNTIF($K$6:$K15,TRUE())) | M15: =IF($L15="","","R"&$L15)
A16: =IF($B16="","",11) | B16: =IFERROR(INDEX(반품접수!$A$3:$A$1002,MATCH("R"&11,미처리현황!$M$6:$M$1005,0)),"") | C16: =IF($B16="","",IFERROR(INDEX(반품접수!$B$3:$B$1002,MATCH("R"&11,미처리현황!$M$6:$M$1005,0)),"")) | D16: =IF($C16="","",TODAY()-$C16) | E16: =IF($B16="","",IFERROR(INDEX(반품접수!$C$3:$C$1002,MATCH("R"&11,미처리현황!$M$6:$M$1005,0)),"")) | F16: =IF($B16="","",IFERROR(INDEX(반품접수!$E$3:$E$1002,MATCH("R"&11,미처리현황!$M$6:$M$1005,0)),"")) | G16: =IF($B16="","",IFERROR(INDEX(반품접수!$I$3:$I$1002,MATCH("R"&11,미처리현황!$M$6:$M$1005,0)),"")) | H16: =IF($B16="","",IFERROR(INDEX(반품접수!$N$3:$N$1002,MATCH("R"&11,미처리현황!$M$6:$M$1005,0)),"")) | I16: =IF($B16="","",IFERROR(INDEX(반품접수!$O$3:$O$1002,MATCH("R"&11,미처리현황!$M$6:$M$1005,0)),"")) | K16: =IF(반품접수!$A13="",FALSE(),OR(반품접수!$O13="미처리",반품접수!$O13="부분처리")) -> FALSE | L16: =IF($K16=FALSE(),"",COUNTIF($K$6:$K16,TRUE())) | M16: =IF($L16="","","R"&$L16)
A17: =IF($B17="","",12) | B17: =IFERROR(INDEX(반품접수!$A$3:$A$1002,MATCH("R"&12,미처리현황!$M$6:$M$1005,0)),"") | C17: =IF($B17="","",IFERROR(INDEX(반품접수!$B$3:$B$1002,MATCH("R"&12,미처리현황!$M$6:$M$1005,0)),"")) | D17: =IF($C17="","",TODAY()-$C17) | E17: =IF($B17="","",IFERROR(INDEX(반품접수!$C$3:$C$1002,MATCH("R"&12,미처리현황!$M$6:$M$1005,0)),"")) | F17: =IF($B17="","",IFERROR(INDEX(반품접수!$E$3:$E$1002,MATCH("R"&12,미처리현황!$M$6:$M$1005,0)),"")) | G17: =IF($B17="","",IFERROR(INDEX(반품접수!$I$3:$I$1002,MATCH("R"&12,미처리현황!$M$6:$M$1005,0)),"")) | H17: =IF($B17="","",IFERROR(INDEX(반품접수!$N$3:$N$1002,MATCH("R"&12,미처리현황!$M$6:$M$1005,0)),"")) | I17: =IF($B17="","",IFERROR(INDEX(반품접수!$O$3:$O$1002,MATCH("R"&12,미처리현황!$M$6:$M$1005,0)),"")) | K17: =IF(반품접수!$A14="",FALSE(),OR(반품접수!$O14="미처리",반품접수!$O14="부분처리")) -> FALSE | L17: =IF($K17=FALSE(),"",COUNTIF($K$6:$K17,TRUE())) | M17: =IF($L17="","","R"&$L17)
A18: =IF($B18="","",13) | B18: =IFERROR(INDEX(반품접수!$A$3:$A$1002,MATCH("R"&13,미처리현황!$M$6:$M$1005,0)),"") | C18: =IF($B18="","",IFERROR(INDEX(반품접수!$B$3:$B$1002,MATCH("R"&13,미처리현황!$M$6:$M$1005,0)),"")) | D18: =IF($C18="","",TODAY()-$C18) | E18: =IF($B18="","",IFERROR(INDEX(반품접수!$C$3:$C$1002,MATCH("R"&13,미처리현황!$M$6:$M$1005,0)),"")) | F18: =IF($B18="","",IFERROR(INDEX(반품접수!$E$3:$E$1002,MATCH("R"&13,미처리현황!$M$6:$M$1005,0)),"")) | G18: =IF($B18="","",IFERROR(INDEX(반품접수!$I$3:$I$1002,MATCH("R"&13,미처리현황!$M$6:$M$1005,0)),"")) | H18: =IF($B18="","",IFERROR(INDEX(반품접수!$N$3:$N$1002,MATCH("R"&13,미처리현황!$M$6:$M$1005,0)),"")) | I18: =IF($B18="","",IFERROR(INDEX(반품접수!$O$3:$O$1002,MATCH("R"&13,미처리현황!$M$6:$M$1005,0)),"")) | K18: =IF(반품접수!$A15="",FALSE(),OR(반품접수!$O15="미처리",반품접수!$O15="부분처리")) -> FALSE | L18: =IF($K18=FALSE(),"",COUNTIF($K$6:$K18,TRUE())) | M18: =IF($L18="","","R"&$L18)
A19: =IF($B19="","",14) | B19: =IFERROR(INDEX(반품접수!$A$3:$A$1002,MATCH("R"&14,미처리현황!$M$6:$M$1005,0)),"") | C19: =IF($B19="","",IFERROR(INDEX(반품접수!$B$3:$B$1002,MATCH("R"&14,미처리현황!$M$6:$M$1005,0)),"")) | D19: =IF($C19="","",TODAY()-$C19) | E19: =IF($B19="","",IFERROR(INDEX(반품접수!$C$3:$C$1002,MATCH("R"&14,미처리현황!$M$6:$M$1005,0)),"")) | F19: =IF($B19="","",IFERROR(INDEX(반품접수!$E$3:$E$1002,MATCH("R"&14,미처리현황!$M$6:$M$1005,0)),"")) | G19: =IF($B19="","",IFERROR(INDEX(반품접수!$I$3:$I$1002,MATCH("R"&14,미처리현황!$M$6:$M$1005,0)),"")) | H19: =IF($B19="","",IFERROR(INDEX(반품접수!$N$3:$N$1002,MATCH("R"&14,미처리현황!$M$6:$M$1005,0)),"")) | I19: =IF($B19="","",IFERROR(INDEX(반품접수!$O$3:$O$1002,MATCH("R"&14,미처리현황!$M$6:$M$1005,0)),"")) | K19: =IF(반품접수!$A16="",FALSE(),OR(반품접수!$O16="미처리",반품접수!$O16="부분처리")) -> FALSE | L19: =IF($K19=FALSE(),"",COUNTIF($K$6:$K19,TRUE())) | M19: =IF($L19="","","R"&$L19)
A20: =IF($B20="","",15) | B20: =IFERROR(INDEX(반품접수!$A$3:$A$1002,MATCH("R"&15,미처리현황!$M$6:$M$1005,0)),"") | C20: =IF($B20="","",IFERROR(INDEX(반품접수!$B$3:$B$1002,MATCH("R"&15,미처리현황!$M$6:$M$1005,0)),"")) | D20: =IF($C20="","",TODAY()-$C20) | E20: =IF($B20="","",IFERROR(INDEX(반품접수!$C$3:$C$1002,MATCH("R"&15,미처리현황!$M$6:$M$1005,0)),"")) | F20: =IF($B20="","",IFERROR(INDEX(반품접수!$E$3:$E$1002,MATCH("R"&15,미처리현황!$M$6:$M$1005,0)),"")) | G20: =IF($B20="","",IFERROR(INDEX(반품접수!$I$3:$I$1002,MATCH("R"&15,미처리현황!$M$6:$M$1005,0)),"")) | H20: =IF($B20="","",IFERROR(INDEX(반품접수!$N$3:$N$1002,MATCH("R"&15,미처리현황!$M$6:$M$1005,0)),"")) | I20: =IF($B20="","",IFERROR(INDEX(반품접수!$O$3:$O$1002,MATCH("R"&15,미처리현황!$M$6:$M$1005,0)),"")) | K20: =IF(반품접수!$A17="",FALSE(),OR(반품접수!$O17="미처리",반품접수!$O17="부분처리")) -> FALSE | L20: =IF($K20=FALSE(),"",COUNTIF($K$6:$K20,TRUE())) | M20: =IF($L20="","","R"&$L20)
A21: =IF($B21="","",16) | B21: =IFERROR(INDEX(반품접수!$A$3:$A$1002,MATCH("R"&16,미처리현황!$M$6:$M$1005,0)),"") | C21: =IF($B21="","",IFERROR(INDEX(반품접수!$B$3:$B$1002,MATCH("R"&16,미처리현황!$M$6:$M$1005,0)),"")) | D21: =IF($C21="","",TODAY()-$C21) | E21: =IF($B21="","",IFERROR(INDEX(반품접수!$C$3:$C$1002,MATCH("R"&16,미처리현황!$M$6:$M$1005,0)),"")) | F21: =IF($B21="","",IFERROR(INDEX(반품접수!$E$3:$E$1002,MATCH("R"&16,미처리현황!$M$6:$M$1005,0)),"")) | G21: =IF($B21="","",IFERROR(INDEX(반품접수!$I$3:$I$1002,MATCH("R"&16,미처리현황!$M$6:$M$1005,0)),"")) | H21: =IF($B21="","",IFERROR(INDEX(반품접수!$N$3:$N$1002,MATCH("R"&16,미처리현황!$M$6:$M$1005,0)),"")) | I21: =IF($B21="","",IFERROR(INDEX(반품접수!$O$3:$O$1002,MATCH("R"&16,미처리현황!$M$6:$M$1005,0)),"")) | K21: =IF(반품접수!$A18="",FALSE(),OR(반품접수!$O18="미처리",반품접수!$O18="부분처리")) -> FALSE | L21: =IF($K21=FALSE(),"",COUNTIF($K$6:$K21,TRUE())) | M21: =IF($L21="","","R"&$L21)
A22: =IF($B22="","",17) | B22: =IFERROR(INDEX(반품접수!$A$3:$A$1002,MATCH("R"&17,미처리현황!$M$6:$M$1005,0)),"") | C22: =IF($B22="","",IFERROR(INDEX(반품접수!$B$3:$B$1002,MATCH("R"&17,미처리현황!$M$6:$M$1005,0)),"")) | D22: =IF($C22="","",TODAY()-$C22) | E22: =IF($B22="","",IFERROR(INDEX(반품접수!$C$3:$C$1002,MATCH("R"&17,미처리현황!$M$6:$M$1005,0)),"")) | F22: =IF($B22="","",IFERROR(INDEX(반품접수!$E$3:$E$1002,MATCH("R"&17,미처리현황!$M$6:$M$1005,0)),"")) | G22: =IF($B22="","",IFERROR(INDEX(반품접수!$I$3:$I$1002,MATCH("R"&17,미처리현황!$M$6:$M$1005,0)),"")) | H22: =IF($B22="","",IFERROR(INDEX(반품접수!$N$3:$N$1002,MATCH("R"&17,미처리현황!$M$6:$M$1005,0)),"")) | I22: =IF($B22="","",IFERROR(INDEX(반품접수!$O$3:$O$1002,MATCH("R"&17,미처리현황!$M$6:$M$1005,0)),"")) | K22: =IF(반품접수!$A19="",FALSE(),OR(반품접수!$O19="미처리",반품접수!$O19="부분처리")) -> FALSE | L22: =IF($K22=FALSE(),"",COUNTIF($K$6:$K22,TRUE())) | M22: =IF($L22="","","R"&$L22)
A23: =IF($B23="","",18) | B23: =IFERROR(INDEX(반품접수!$A$3:$A$1002,MATCH("R"&18,미처리현황!$M$6:$M$1005,0)),"") | C23: =IF($B23="","",IFERROR(INDEX(반품접수!$B$3:$B$1002,MATCH("R"&18,미처리현황!$M$6:$M$1005,0)),"")) | D23: =IF($C23="","",TODAY()-$C23) | E23: =IF($B23="","",IFERROR(INDEX(반품접수!$C$3:$C$1002,MATCH("R"&18,미처리현황!$M$6:$M$1005,0)),"")) | F23: =IF($B23="","",IFERROR(INDEX(반품접수!$E$3:$E$1002,MATCH("R"&18,미처리현황!$M$6:$M$1005,0)),"")) | G23: =IF($B23="","",IFERROR(INDEX(반품접수!$I$3:$I$1002,MATCH("R"&18,미처리현황!$M$6:$M$1005,0)),"")) | H23: =IF($B23="","",IFERROR(INDEX(반품접수!$N$3:$N$1002,MATCH("R"&18,미처리현황!$M$6:$M$1005,0)),"")) | I23: =IF($B23="","",IFERROR(INDEX(반품접수!$O$3:$O$1002,MATCH("R"&18,미처리현황!$M$6:$M$1005,0)),"")) | K23: =IF(반품접수!$A20="",FALSE(),OR(반품접수!$O20="미처리",반품접수!$O20="부분처리")) -> FALSE | L23: =IF($K23=FALSE(),"",COUNTIF($K$6:$K23,TRUE())) | M23: =IF($L23="","","R"&$L23)
A24: =IF($B24="","",19) | B24: =IFERROR(INDEX(반품접수!$A$3:$A$1002,MATCH("R"&19,미처리현황!$M$6:$M$1005,0)),"") | C24: =IF($B24="","",IFERROR(INDEX(반품접수!$B$3:$B$1002,MATCH("R"&19,미처리현황!$M$6:$M$1005,0)),"")) | D24: =IF($C24="","",TODAY()-$C24) | E24: =IF($B24="","",IFERROR(INDEX(반품접수!$C$3:$C$1002,MATCH("R"&19,미처리현황!$M$6:$M$1005,0)),"")) | F24: =IF($B24="","",IFERROR(INDEX(반품접수!$E$3:$E$1002,MATCH("R"&19,미처리현황!$M$6:$M$1005,0)),"")) | G24: =IF($B24="","",IFERROR(INDEX(반품접수!$I$3:$I$1002,MATCH("R"&19,미처리현황!$M$6:$M$1005,0)),"")) | H24: =IF($B24="","",IFERROR(INDEX(반품접수!$N$3:$N$1002,MATCH("R"&19,미처리현황!$M$6:$M$1005,0)),"")) | I24: =IF($B24="","",IFERROR(INDEX(반품접수!$O$3:$O$1002,MATCH("R"&19,미처리현황!$M$6:$M$1005,0)),"")) | K24: =IF(반품접수!$A21="",FALSE(),OR(반품접수!$O21="미처리",반품접수!$O21="부분처리")) -> FALSE | L24: =IF($K24=FALSE(),"",COUNTIF($K$6:$K24,TRUE())) | M24: =IF($L24="","","R"&$L24)
A25: =IF($B25="","",20) | B25: =IFERROR(INDEX(반품접수!$A$3:$A$1002,MATCH("R"&20,미처리현황!$M$6:$M$1005,0)),"") | C25: =IF($B25="","",IFERROR(INDEX(반품접수!$B$3:$B$1002,MATCH("R"&20,미처리현황!$M$6:$M$1005,0)),"")) | D25: =IF($C25="","",TODAY()-$C25) | E25: =IF($B25="","",IFERROR(INDEX(반품접수!$C$3:$C$1002,MATCH("R"&20,미처리현황!$M$6:$M$1005,0)),"")) | F25: =IF($B25="","",IFERROR(INDEX(반품접수!$E$3:$E$1002,MATCH("R"&20,미처리현황!$M$6:$M$1005,0)),"")) | G25: =IF($B25="","",IFERROR(INDEX(반품접수!$I$3:$I$1002,MATCH("R"&20,미처리현황!$M$6:$M$1005,0)),"")) | H25: =IF($B25="","",IFERROR(INDEX(반품접수!$N$3:$N$1002,MATCH("R"&20,미처리현황!$M$6:$M$1005,0)),"")) | I25: =IF($B25="","",IFERROR(INDEX(반품접수!$O$3:$O$1002,MATCH("R"&20,미처리현황!$M$6:$M$1005,0)),"")) | K25: =IF(반품접수!$A22="",FALSE(),OR(반품접수!$O22="미처리",반품접수!$O22="부분처리")) -> FALSE | L25: =IF($K25=FALSE(),"",COUNTIF($K$6:$K25,TRUE())) | M25: =IF($L25="","","R"&$L25)
A26: =IF($B26="","",21) | B26: =IFERROR(INDEX(반품접수!$A$3:$A$1002,MATCH("R"&21,미처리현황!$M$6:$M$1005,0)),"") | C26: =IF($B26="","",IFERROR(INDEX(반품접수!$B$3:$B$1002,MATCH("R"&21,미처리현황!$M$6:$M$1005,0)),"")) | D26: =IF($C26="","",TODAY()-$C26) | E26: =IF($B26="","",IFERROR(INDEX(반품접수!$C$3:$C$1002,MATCH("R"&21,미처리현황!$M$6:$M$1005,0)),"")) | F26: =IF($B26="","",IFERROR(INDEX(반품접수!$E$3:$E$1002,MATCH("R"&21,미처리현황!$M$6:$M$1005,0)),"")) | G26: =IF($B26="","",IFERROR(INDEX(반품접수!$I$3:$I$1002,MATCH("R"&21,미처리현황!$M$6:$M$1005,0)),"")) | H26: =IF($B26="","",IFERROR(INDEX(반품접수!$N$3:$N$1002,MATCH("R"&21,미처리현황!$M$6:$M$1005,0)),"")) | I26: =IF($B26="","",IFERROR(INDEX(반품접수!$O$3:$O$1002,MATCH("R"&21,미처리현황!$M$6:$M$1005,0)),"")) | K26: =IF(반품접수!$A23="",FALSE(),OR(반품접수!$O23="미처리",반품접수!$O23="부분처리")) -> FALSE | L26: =IF($K26=FALSE(),"",COUNTIF($K$6:$K26,TRUE())) | M26: =IF($L26="","","R"&$L26)
A27: =IF($B27="","",22) | B27: =IFERROR(INDEX(반품접수!$A$3:$A$1002,MATCH("R"&22,미처리현황!$M$6:$M$1005,0)),"") | C27: =IF($B27="","",IFERROR(INDEX(반품접수!$B$3:$B$1002,MATCH("R"&22,미처리현황!$M$6:$M$1005,0)),"")) | D27: =IF($C27="","",TODAY()-$C27) | E27: =IF($B27="","",IFERROR(INDEX(반품접수!$C$3:$C$1002,MATCH("R"&22,미처리현황!$M$6:$M$1005,0)),"")) | F27: =IF($B27="","",IFERROR(INDEX(반품접수!$E$3:$E$1002,MATCH("R"&22,미처리현황!$M$6:$M$1005,0)),"")) | G27: =IF($B27="","",IFERROR(INDEX(반품접수!$I$3:$I$1002,MATCH("R"&22,미처리현황!$M$6:$M$1005,0)),"")) | H27: =IF($B27="","",IFERROR(INDEX(반품접수!$N$3:$N$1002,MATCH("R"&22,미처리현황!$M$6:$M$1005,0)),"")) | I27: =IF($B27="","",IFERROR(INDEX(반품접수!$O$3:$O$1002,MATCH("R"&22,미처리현황!$M$6:$M$1005,0)),"")) | K27: =IF(반품접수!$A24="",FALSE(),OR(반품접수!$O24="미처리",반품접수!$O24="부분처리")) -> FALSE | L27: =IF($K27=FALSE(),"",COUNTIF($K$6:$K27,TRUE())) | M27: =IF($L27="","","R"&$L27)
A28: =IF($B28="","",23) | B28: =IFERROR(INDEX(반품접수!$A$3:$A$1002,MATCH("R"&23,미처리현황!$M$6:$M$1005,0)),"") | C28: =IF($B28="","",IFERROR(INDEX(반품접수!$B$3:$B$1002,MATCH("R"&23,미처리현황!$M$6:$M$1005,0)),"")) | D28: =IF($C28="","",TODAY()-$C28) | E28: =IF($B28="","",IFERROR(INDEX(반품접수!$C$3:$C$1002,MATCH("R"&23,미처리현황!$M$6:$M$1005,0)),"")) | F28: =IF($B28="","",IFERROR(INDEX(반품접수!$E$3:$E$1002,MATCH("R"&23,미처리현황!$M$6:$M$1005,0)),"")) | G28: =IF($B28="","",IFERROR(INDEX(반품접수!$I$3:$I$1002,MATCH("R"&23,미처리현황!$M$6:$M$1005,0)),"")) | H28: =IF($B28="","",IFERROR(INDEX(반품접수!$N$3:$N$1002,MATCH("R"&23,미처리현황!$M$6:$M$1005,0)),"")) | I28: =IF($B28="","",IFERROR(INDEX(반품접수!$O$3:$O$1002,MATCH("R"&23,미처리현황!$M$6:$M$1005,0)),"")) | K28: =IF(반품접수!$A25="",FALSE(),OR(반품접수!$O25="미처리",반품접수!$O25="부분처리")) -> FALSE | L28: =IF($K28=FALSE(),"",COUNTIF($K$6:$K28,TRUE())) | M28: =IF($L28="","","R"&$L28)
A29: =IF($B29="","",24) | B29: =IFERROR(INDEX(반품접수!$A$3:$A$1002,MATCH("R"&24,미처리현황!$M$6:$M$1005,0)),"") | C29: =IF($B29="","",IFERROR(INDEX(반품접수!$B$3:$B$1002,MATCH("R"&24,미처리현황!$M$6:$M$1005,0)),"")) | D29: =IF($C29="","",TODAY()-$C29) | E29: =IF($B29="","",IFERROR(INDEX(반품접수!$C$3:$C$1002,MATCH("R"&24,미처리현황!$M$6:$M$1005,0)),"")) | F29: =IF($B29="","",IFERROR(INDEX(반품접수!$E$3:$E$1002,MATCH("R"&24,미처리현황!$M$6:$M$1005,0)),"")) | G29: =IF($B29="","",IFERROR(INDEX(반품접수!$I$3:$I$1002,MATCH("R"&24,미처리현황!$M$6:$M$1005,0)),"")) | H29: =IF($B29="","",IFERROR(INDEX(반품접수!$N$3:$N$1002,MATCH("R"&24,미처리현황!$M$6:$M$1005,0)),"")) | I29: =IF($B29="","",IFERROR(INDEX(반품접수!$O$3:$O$1002,MATCH("R"&24,미처리현황!$M$6:$M$1005,0)),"")) | K29: =IF(반품접수!$A26="",FALSE(),OR(반품접수!$O26="미처리",반품접수!$O26="부분처리")) -> FALSE | L29: =IF($K29=FALSE(),"",COUNTIF($K$6:$K29,TRUE())) | M29: =IF($L29="","","R"&$L29)
A30: =IF($B30="","",25) | B30: =IFERROR(INDEX(반품접수!$A$3:$A$1002,MATCH("R"&25,미처리현황!$M$6:$M$1005,0)),"") | C30: =IF($B30="","",IFERROR(INDEX(반품접수!$B$3:$B$1002,MATCH("R"&25,미처리현황!$M$6:$M$1005,0)),"")) | D30: =IF($C30="","",TODAY()-$C30) | E30: =IF($B30="","",IFERROR(INDEX(반품접수!$C$3:$C$1002,MATCH("R"&25,미처리현황!$M$6:$M$1005,0)),"")) | F30: =IF($B30="","",IFERROR(INDEX(반품접수!$E$3:$E$1002,MATCH("R"&25,미처리현황!$M$6:$M$1005,0)),"")) | G30: =IF($B30="","",IFERROR(INDEX(반품접수!$I$3:$I$1002,MATCH("R"&25,미처리현황!$M$6:$M$1005,0)),"")) | H30: =IF($B30="","",IFERROR(INDEX(반품접수!$N$3:$N$1002,MATCH("R"&25,미처리현황!$M$6:$M$1005,0)),"")) | I30: =IF($B30="","",IFERROR(INDEX(반품접수!$O$3:$O$1002,MATCH("R"&25,미처리현황!$M$6:$M$1005,0)),"")) | K30: =IF(반품접수!$A27="",FALSE(),OR(반품접수!$O27="미처리",반품접수!$O27="부분처리")) -> FALSE | L30: =IF($K30=FALSE(),"",COUNTIF($K$6:$K30,TRUE())) | M30: =IF($L30="","","R"&$L30)
A31: =IF($B31="","",26) | B31: =IFERROR(INDEX(반품접수!$A$3:$A$1002,MATCH("R"&26,미처리현황!$M$6:$M$1005,0)),"") | C31: =IF($B31="","",IFERROR(INDEX(반품접수!$B$3:$B$1002,MATCH("R"&26,미처리현황!$M$6:$M$1005,0)),"")) | D31: =IF($C31="","",TODAY()-$C31) | E31: =IF($B31="","",IFERROR(INDEX(반품접수!$C$3:$C$1002,MATCH("R"&26,미처리현황!$M$6:$M$1005,0)),"")) | F31: =IF($B31="","",IFERROR(INDEX(반품접수!$E$3:$E$1002,MATCH("R"&26,미처리현황!$M$6:$M$1005,0)),"")) | G31: =IF($B31="","",IFERROR(INDEX(반품접수!$I$3:$I$1002,MATCH("R"&26,미처리현황!$M$6:$M$1005,0)),"")) | H31: =IF($B31="","",IFERROR(INDEX(반품접수!$N$3:$N$1002,MATCH("R"&26,미처리현황!$M$6:$M$1005,0)),"")) | I31: =IF($B31="","",IFERROR(INDEX(반품접수!$O$3:$O$1002,MATCH("R"&26,미처리현황!$M$6:$M$1005,0)),"")) | K31: =IF(반품접수!$A28="",FALSE(),OR(반품접수!$O28="미처리",반품접수!$O28="부분처리")) -> FALSE | L31: =IF($K31=FALSE(),"",COUNTIF($K$6:$K31,TRUE())) | M31: =IF($L31="","","R"&$L31)
A32: =IF($B32="","",27) | B32: =IFERROR(INDEX(반품접수!$A$3:$A$1002,MATCH("R"&27,미처리현황!$M$6:$M$1005,0)),"") | C32: =IF($B32="","",IFERROR(INDEX(반품접수!$B$3:$B$1002,MATCH("R"&27,미처리현황!$M$6:$M$1005,0)),"")) | D32: =IF($C32="","",TODAY()-$C32) | E32: =IF($B32="","",IFERROR(INDEX(반품접수!$C$3:$C$1002,MATCH("R"&27,미처리현황!$M$6:$M$1005,0)),"")) | F32: =IF($B32="","",IFERROR(INDEX(반품접수!$E$3:$E$1002,MATCH("R"&27,미처리현황!$M$6:$M$1005,0)),"")) | G32: =IF($B32="","",IFERROR(INDEX(반품접수!$I$3:$I$1002,MATCH("R"&27,미처리현황!$M$6:$M$1005,0)),"")) | H32: =IF($B32="","",IFERROR(INDEX(반품접수!$N$3:$N$1002,MATCH("R"&27,미처리현황!$M$6:$M$1005,0)),"")) | I32: =IF($B32="","",IFERROR(INDEX(반품접수!$O$3:$O$1002,MATCH("R"&27,미처리현황!$M$6:$M$1005,0)),"")) | K32: =IF(반품접수!$A29="",FALSE(),OR(반품접수!$O29="미처리",반품접수!$O29="부분처리")) -> FALSE | L32: =IF($K32=FALSE(),"",COUNTIF($K$6:$K32,TRUE())) | M32: =IF($L32="","","R"&$L32)
A33: =IF($B33="","",28) | B33: =IFERROR(INDEX(반품접수!$A$3:$A$1002,MATCH("R"&28,미처리현황!$M$6:$M$1005,0)),"") | C33: =IF($B33="","",IFERROR(INDEX(반품접수!$B$3:$B$1002,MATCH("R"&28,미처리현황!$M$6:$M$1005,0)),"")) | D33: =IF($C33="","",TODAY()-$C33) | E33: =IF($B33="","",IFERROR(INDEX(반품접수!$C$3:$C$1002,MATCH("R"&28,미처리현황!$M$6:$M$1005,0)),"")) | F33: =IF($B33="","",IFERROR(INDEX(반품접수!$E$3:$E$1002,MATCH("R"&28,미처리현황!$M$6:$M$1005,0)),"")) | G33: =IF($B33="","",IFERROR(INDEX(반품접수!$I$3:$I$1002,MATCH("R"&28,미처리현황!$M$6:$M$1005,0)),"")) | H33: =IF($B33="","",IFERROR(INDEX(반품접수!$N$3:$N$1002,MATCH("R"&28,미처리현황!$M$6:$M$1005,0)),"")) | I33: =IF($B33="","",IFERROR(INDEX(반품접수!$O$3:$O$1002,MATCH("R"&28,미처리현황!$M$6:$M$1005,0)),"")) | K33: =IF(반품접수!$A30="",FALSE(),OR(반품접수!$O30="미처리",반품접수!$O30="부분처리")) -> FALSE | L33: =IF($K33=FALSE(),"",COUNTIF($K$6:$K33,TRUE())) | M33: =IF($L33="","","R"&$L33)
A34: =IF($B34="","",29) | B34: =IFERROR(INDEX(반품접수!$A$3:$A$1002,MATCH("R"&29,미처리현황!$M$6:$M$1005,0)),"") | C34: =IF($B34="","",IFERROR(INDEX(반품접수!$B$3:$B$1002,MATCH("R"&29,미처리현황!$M$6:$M$1005,0)),"")) | D34: =IF($C34="","",TODAY()-$C34) | E34: =IF($B34="","",IFERROR(INDEX(반품접수!$C$3:$C$1002,MATCH("R"&29,미처리현황!$M$6:$M$1005,0)),"")) | F34: =IF($B34="","",IFERROR(INDEX(반품접수!$E$3:$E$1002,MATCH("R"&29,미처리현황!$M$6:$M$1005,0)),"")) | G34: =IF($B34="","",IFERROR(INDEX(반품접수!$I$3:$I$1002,MATCH("R"&29,미처리현황!$M$6:$M$1005,0)),"")) | H34: =IF($B34="","",IFERROR(INDEX(반품접수!$N$3:$N$1002,MATCH("R"&29,미처리현황!$M$6:$M$1005,0)),"")) | I34: =IF($B34="","",IFERROR(INDEX(반품접수!$O$3:$O$1002,MATCH("R"&29,미처리현황!$M$6:$M$1005,0)),"")) | K34: =IF(반품접수!$A31="",FALSE(),OR(반품접수!$O31="미처리",반품접수!$O31="부분처리")) -> FALSE | L34: =IF($K34=FALSE(),"",COUNTIF($K$6:$K34,TRUE())) | M34: =IF($L34="","","R"&$L34)
A35: =IF($B35="","",30) | B35: =IFERROR(INDEX(반품접수!$A$3:$A$1002,MATCH("R"&30,미처리현황!$M$6:$M$1005,0)),"") | C35: =IF($B35="","",IFERROR(INDEX(반품접수!$B$3:$B$1002,MATCH("R"&30,미처리현황!$M$6:$M$1005,0)),"")) | D35: =IF($C35="","",TODAY()-$C35) | E35: =IF($B35="","",IFERROR(INDEX(반품접수!$C$3:$C$1002,MATCH("R"&30,미처리현황!$M$6:$M$1005,0)),"")) | F35: =IF($B35="","",IFERROR(INDEX(반품접수!$E$3:$E$1002,MATCH("R"&30,미처리현황!$M$6:$M$1005,0)),"")) | G35: =IF($B35="","",IFERROR(INDEX(반품접수!$I$3:$I$1002,MATCH("R"&30,미처리현황!$M$6:$M$1005,0)),"")) | H35: =IF($B35="","",IFERROR(INDEX(반품접수!$N$3:$N$1002,MATCH("R"&30,미처리현황!$M$6:$M$1005,0)),"")) | I35: =IF($B35="","",IFERROR(INDEX(반품접수!$O$3:$O$1002,MATCH("R"&30,미처리현황!$M$6:$M$1005,0)),"")) | K35: =IF(반품접수!$A32="",FALSE(),OR(반품접수!$O32="미처리",반품접수!$O32="부분처리")) -> FALSE | L35: =IF($K35=FALSE(),"",COUNTIF($K$6:$K35,TRUE())) | M35: =IF($L35="","","R"&$L35)
A36: =IF($B36="","",31) | B36: =IFERROR(INDEX(반품접수!$A$3:$A$1002,MATCH("R"&31,미처리현황!$M$6:$M$1005,0)),"") | C36: =IF($B36="","",IFERROR(INDEX(반품접수!$B$3:$B$1002,MATCH("R"&31,미처리현황!$M$6:$M$1005,0)),"")) | D36: =IF($C36="","",TODAY()-$C36) | E36: =IF($B36="","",IFERROR(INDEX(반품접수!$C$3:$C$1002,MATCH("R"&31,미처리현황!$M$6:$M$1005,0)),"")) | F36: =IF($B36="","",IFERROR(INDEX(반품접수!$E$3:$E$1002,MATCH("R"&31,미처리현황!$M$6:$M$1005,0)),"")) | G36: =IF($B36="","",IFERROR(INDEX(반품접수!$I$3:$I$1002,MATCH("R"&31,미처리현황!$M$6:$M$1005,0)),"")) | H36: =IF($B36="","",IFERROR(INDEX(반품접수!$N$3:$N$1002,MATCH("R"&31,미처리현황!$M$6:$M$1005,0)),"")) | I36: =IF($B36="","",IFERROR(INDEX(반품접수!$O$3:$O$1002,MATCH("R"&31,미처리현황!$M$6:$M$1005,0)),"")) | K36: =IF(반품접수!$A33="",FALSE(),OR(반품접수!$O33="미처리",반품접수!$O33="부분처리")) -> FALSE | L36: =IF($K36=FALSE(),"",COUNTIF($K$6:$K36,TRUE())) | M36: =IF($L36="","","R"&$L36)
A37: =IF($B37="","",32) | B37: =IFERROR(INDEX(반품접수!$A$3:$A$1002,MATCH("R"&32,미처리현황!$M$6:$M$1005,0)),"") | C37: =IF($B37="","",IFERROR(INDEX(반품접수!$B$3:$B$1002,MATCH("R"&32,미처리현황!$M$6:$M$1005,0)),"")) | D37: =IF($C37="","",TODAY()-$C37) | E37: =IF($B37="","",IFERROR(INDEX(반품접수!$C$3:$C$1002,MATCH("R"&32,미처리현황!$M$6:$M$1005,0)),"")) | F37: =IF($B37="","",IFERROR(INDEX(반품접수!$E$3:$E$1002,MATCH("R"&32,미처리현황!$M$6:$M$1005,0)),"")) | G37: =IF($B37="","",IFERROR(INDEX(반품접수!$I$3:$I$1002,MATCH("R"&32,미처리현황!$M$6:$M$1005,0)),"")) | H37: =IF($B37="","",IFERROR(INDEX(반품접수!$N$3:$N$1002,MATCH("R"&32,미처리현황!$M$6:$M$1005,0)),"")) | I37: =IF($B37="","",IFERROR(INDEX(반품접수!$O$3:$O$1002,MATCH("R"&32,미처리현황!$M$6:$M$1005,0)),"")) | K37: =IF(반품접수!$A34="",FALSE(),OR(반품접수!$O34="미처리",반품접수!$O34="부분처리")) -> FALSE | L37: =IF($K37=FALSE(),"",COUNTIF($K$6:$K37,TRUE())) | M37: =IF($L37="","","R"&$L37)
A38: =IF($B38="","",33) | B38: =IFERROR(INDEX(반품접수!$A$3:$A$1002,MATCH("R"&33,미처리현황!$M$6:$M$1005,0)),"") | C38: =IF($B38="","",IFERROR(INDEX(반품접수!$B$3:$B$1002,MATCH("R"&33,미처리현황!$M$6:$M$1005,0)),"")) | D38: =IF($C38="","",TODAY()-$C38) | E38: =IF($B38="","",IFERROR(INDEX(반품접수!$C$3:$C$1002,MATCH("R"&33,미처리현황!$M$6:$M$1005,0)),"")) | F38: =IF($B38="","",IFERROR(INDEX(반품접수!$E$3:$E$1002,MATCH("R"&33,미처리현황!$M$6:$M$1005,0)),"")) | G38: =IF($B38="","",IFERROR(INDEX(반품접수!$I$3:$I$1002,MATCH("R"&33,미처리현황!$M$6:$M$1005,0)),"")) | H38: =IF($B38="","",IFERROR(INDEX(반품접수!$N$3:$N$1002,MATCH("R"&33,미처리현황!$M$6:$M$1005,0)),"")) | I38: =IF($B38="","",IFERROR(INDEX(반품접수!$O$3:$O$1002,MATCH("R"&33,미처리현황!$M$6:$M$1005,0)),"")) | K38: =IF(반품접수!$A35="",FALSE(),OR(반품접수!$O35="미처리",반품접수!$O35="부분처리")) -> FALSE | L38: =IF($K38=FALSE(),"",COUNTIF($K$6:$K38,TRUE())) | M38: =IF($L38="","","R"&$L38)
A39: =IF($B39="","",34) | B39: =IFERROR(INDEX(반품접수!$A$3:$A$1002,MATCH("R"&34,미처리현황!$M$6:$M$1005,0)),"") | C39: =IF($B39="","",IFERROR(INDEX(반품접수!$B$3:$B$1002,MATCH("R"&34,미처리현황!$M$6:$M$1005,0)),"")) | D39: =IF($C39="","",TODAY()-$C39) | E39: =IF($B39="","",IFERROR(INDEX(반품접수!$C$3:$C$1002,MATCH("R"&34,미처리현황!$M$6:$M$1005,0)),"")) | F39: =IF($B39="","",IFERROR(INDEX(반품접수!$E$3:$E$1002,MATCH("R"&34,미처리현황!$M$6:$M$1005,0)),"")) | G39: =IF($B39="","",IFERROR(INDEX(반품접수!$I$3:$I$1002,MATCH("R"&34,미처리현황!$M$6:$M$1005,0)),"")) | H39: =IF($B39="","",IFERROR(INDEX(반품접수!$N$3:$N$1002,MATCH("R"&34,미처리현황!$M$6:$M$1005,0)),"")) | I39: =IF($B39="","",IFERROR(INDEX(반품접수!$O$3:$O$1002,MATCH("R"&34,미처리현황!$M$6:$M$1005,0)),"")) | K39: =IF(반품접수!$A36="",FALSE(),OR(반품접수!$O36="미처리",반품접수!$O36="부분처리")) -> FALSE | L39: =IF($K39=FALSE(),"",COUNTIF($K$6:$K39,TRUE())) | M39: =IF($L39="","","R"&$L39)
A40: =IF($B40="","",35) | B40: =IFERROR(INDEX(반품접수!$A$3:$A$1002,MATCH("R"&35,미처리현황!$M$6:$M$1005,0)),"") | C40: =IF($B40="","",IFERROR(INDEX(반품접수!$B$3:$B$1002,MATCH("R"&35,미처리현황!$M$6:$M$1005,0)),"")) | D40: =IF($C40="","",TODAY()-$C40) | E40: =IF($B40="","",IFERROR(INDEX(반품접수!$C$3:$C$1002,MATCH("R"&35,미처리현황!$M$6:$M$1005,0)),"")) | F40: =IF($B40="","",IFERROR(INDEX(반품접수!$E$3:$E$1002,MATCH("R"&35,미처리현황!$M$6:$M$1005,0)),"")) | G40: =IF($B40="","",IFERROR(INDEX(반품접수!$I$3:$I$1002,MATCH("R"&35,미처리현황!$M$6:$M$1005,0)),"")) | H40: =IF($B40="","",IFERROR(INDEX(반품접수!$N$3:$N$1002,MATCH("R"&35,미처리현황!$M$6:$M$1005,0)),"")) | I40: =IF($B40="","",IFERROR(INDEX(반품접수!$O$3:$O$1002,MATCH("R"&35,미처리현황!$M$6:$M$1005,0)),"")) | K40: =IF(반품접수!$A37="",FALSE(),OR(반품접수!$O37="미처리",반품접수!$O37="부분처리")) -> FALSE | L40: =IF($K40=FALSE(),"",COUNTIF($K$6:$K40,TRUE())) | M40: =IF($L40="","","R"&$L40)
A41: =IF($B41="","",36) | B41: =IFERROR(INDEX(반품접수!$A$3:$A$1002,MATCH("R"&36,미처리현황!$M$6:$M$1005,0)),"") | C41: =IF($B41="","",IFERROR(INDEX(반품접수!$B$3:$B$1002,MATCH("R"&36,미처리현황!$M$6:$M$1005,0)),"")) | D41: =IF($C41="","",TODAY()-$C41) | E41: =IF($B41="","",IFERROR(INDEX(반품접수!$C$3:$C$1002,MATCH("R"&36,미처리현황!$M$6:$M$1005,0)),"")) | F41: =IF($B41="","",IFERROR(INDEX(반품접수!$E$3:$E$1002,MATCH("R"&36,미처리현황!$M$6:$M$1005,0)),"")) | G41: =IF($B41="","",IFERROR(INDEX(반품접수!$I$3:$I$1002,MATCH("R"&36,미처리현황!$M$6:$M$1005,0)),"")) | H41: =IF($B41="","",IFERROR(INDEX(반품접수!$N$3:$N$1002,MATCH("R"&36,미처리현황!$M$6:$M$1005,0)),"")) | I41: =IF($B41="","",IFERROR(INDEX(반품접수!$O$3:$O$1002,MATCH("R"&36,미처리현황!$M$6:$M$1005,0)),"")) | K41: =IF(반품접수!$A38="",FALSE(),OR(반품접수!$O38="미처리",반품접수!$O38="부분처리")) -> FALSE | L41: =IF($K41=FALSE(),"",COUNTIF($K$6:$K41,TRUE())) | M41: =IF($L41="","","R"&$L41)
A42: =IF($B42="","",37) | B42: =IFERROR(INDEX(반품접수!$A$3:$A$1002,MATCH("R"&37,미처리현황!$M$6:$M$1005,0)),"") | C42: =IF($B42="","",IFERROR(INDEX(반품접수!$B$3:$B$1002,MATCH("R"&37,미처리현황!$M$6:$M$1005,0)),"")) | D42: =IF($C42="","",TODAY()-$C42) | E42: =IF($B42="","",IFERROR(INDEX(반품접수!$C$3:$C$1002,MATCH("R"&37,미처리현황!$M$6:$M$1005,0)),"")) | F42: =IF($B42="","",IFERROR(INDEX(반품접수!$E$3:$E$1002,MATCH("R"&37,미처리현황!$M$6:$M$1005,0)),"")) | G42: =IF($B42="","",IFERROR(INDEX(반품접수!$I$3:$I$1002,MATCH("R"&37,미처리현황!$M$6:$M$1005,0)),"")) | H42: =IF($B42="","",IFERROR(INDEX(반품접수!$N$3:$N$1002,MATCH("R"&37,미처리현황!$M$6:$M$1005,0)),"")) | I42: =IF($B42="","",IFERROR(INDEX(반품접수!$O$3:$O$1002,MATCH("R"&37,미처리현황!$M$6:$M$1005,0)),"")) | K42: =IF(반품접수!$A39="",FALSE(),OR(반품접수!$O39="미처리",반품접수!$O39="부분처리")) -> FALSE | L42: =IF($K42=FALSE(),"",COUNTIF($K$6:$K42,TRUE())) | M42: =IF($L42="","","R"&$L42)
...

Sheet 사유별집계
A1: 사유별집계
A3: 대상 연도 | B3: 2026
A5: 사유 | B5: 건수 | C5: 수량 | D5: 원재료 수량 | E5: 부자재 수량 | F5: 비중 | G5: 처리비용
A6: 파손 | B6: =COUNTIFS(반품접수!$K$3:$K$1002,$A6,반품접수!$B$3:$B$1002,">="&DATE($B$3,1,1),반품접수!$B$3:$B$1002,"<="&DATE($B$3,12,31)) -> 1 | C6: =SUMIFS(반품접수!$I$3:$I$1002,반품접수!$K$3:$K$1002,$A6,반품접수!$B$3:$B$1002,">="&DATE($B$3,1,1),반품접수!$B$3:$B$1002,"<="&DATE($B$3,12,31)) -> 50 | D6: =SUMIFS(반품접수!$I$3:$I$1002,반품접수!$K$3:$K$1002,$A6,반품접수!$H$3:$H$1002,"원재료",반품접수!$B$3:$B$1002,">="&DATE($B$3,1,1),반품접수!$B$3:$B$1002,"<="&DATE($B$3,12,31)) -> 0 | E6: =SUMIFS(반품접수!$I$3:$I$1002,반품접수!$K$3:$K$1002,$A6,반품접수!$H$3:$H$1002,"부자재",반품접수!$B$3:$B$1002,">="&DATE($B$3,1,1),반품접수!$B$3:$B$1002,"<="&DATE($B$3,12,31)) -> 50 | F6: =IF($C$14=0,"",$C6/$C$14) -> 0.1953125 | G6: =SUMPRODUCT((반품접수!$K$3:$K$1002=$A6)*1,IFERROR(SUMIF(처리내역!$B$3:$B$1502,반품접수!$A$3:$A$1002,처리내역!$G$3:$G$1502),0)) -> 40000
A7: 오염 | B7: =COUNTIFS(반품접수!$K$3:$K$1002,$A7,반품접수!$B$3:$B$1002,">="&DATE($B$3,1,1),반품접수!$B$3:$B$1002,"<="&DATE($B$3,12,31)) -> 1 | C7: =SUMIFS(반품접수!$I$3:$I$1002,반품접수!$K$3:$K$1002,$A7,반품접수!$B$3:$B$1002,">="&DATE($B$3,1,1),반품접수!$B$3:$B$1002,"<="&DATE($B$3,12,31)) -> 3 | D7: =SUMIFS(반품접수!$I$3:$I$1002,반품접수!$K$3:$K$1002,$A7,반품접수!$H$3:$H$1002,"원재료",반품접수!$B$3:$B$1002,">="&DATE($B$3,1,1),반품접수!$B$3:$B$1002,"<="&DATE($B$3,12,31)) -> 3 | E7: =SUMIFS(반품접수!$I$3:$I$1002,반품접수!$K$3:$K$1002,$A7,반품접수!$H$3:$H$1002,"부자재",반품접수!$B$3:$B$1002,">="&DATE($B$3,1,1),반품접수!$B$3:$B$1002,"<="&DATE($B$3,12,31)) -> 0 | F7: =IF($C$14=0,"",$C7/$C$14) -> 0.01171875 | G7: =SUMPRODUCT((반품접수!$K$3:$K$1002=$A7)*1,IFERROR(SUMIF(처리내역!$B$3:$B$1502,반품접수!$A$3:$A$1002,처리내역!$G$3:$G$1502),0)) -> 60000
A8: 수량부족 | B8: =COUNTIFS(반품접수!$K$3:$K$1002,$A8,반품접수!$B$3:$B$1002,">="&DATE($B$3,1,1),반품접수!$B$3:$B$1002,"<="&DATE($B$3,12,31)) -> 0 | C8: =SUMIFS(반품접수!$I$3:$I$1002,반품접수!$K$3:$K$1002,$A8,반품접수!$B$3:$B$1002,">="&DATE($B$3,1,1),반품접수!$B$3:$B$1002,"<="&DATE($B$3,12,31)) -> 0 | D8: =SUMIFS(반품접수!$I$3:$I$1002,반품접수!$K$3:$K$1002,$A8,반품접수!$H$3:$H$1002,"원재료",반품접수!$B$3:$B$1002,">="&DATE($B$3,1,1),반품접수!$B$3:$B$1002,"<="&DATE($B$3,12,31)) -> 0 | E8: =SUMIFS(반품접수!$I$3:$I$1002,반품접수!$K$3:$K$1002,$A8,반품접수!$H$3:$H$1002,"부자재",반품접수!$B$3:$B$1002,">="&DATE($B$3,1,1),반품접수!$B$3:$B$1002,"<="&DATE($B$3,12,31)) -> 0 | F8: =IF($C$14=0,"",$C8/$C$14) -> 0 | G8: =SUMPRODUCT((반품접수!$K$3:$K$1002=$A8)*1,IFERROR(SUMIF(처리내역!$B$3:$B$1502,반품접수!$A$3:$A$1002,처리내역!$G$3:$G$1502),0)) -> 0
A9: 규격상이 | B9: =COUNTIFS(반품접수!$K$3:$K$1002,$A9,반품접수!$B$3:$B$1002,">="&DATE($B$3,1,1),반품접수!$B$3:$B$1002,"<="&DATE($B$3,12,31)) -> 1 | C9: =SUMIFS(반품접수!$I$3:$I$1002,반품접수!$K$3:$K$1002,$A9,반품접수!$B$3:$B$1002,">="&DATE($B$3,1,1),반품접수!$B$3:$B$1002,"<="&DATE($B$3,12,31)) -> 2 | D9: =SUMIFS(반품접수!$I$3:$I$1002,반품접수!$K$3:$K$1002,$A9,반품접수!$H$3:$H$1002,"원재료",반품접수!$B$3:$B$1002,">="&DATE($B$3,1,1),반품접수!$B$3:$B$1002,"<="&DATE($B$3,12,31)) -> 2 | E9: =SUMIFS(반품접수!$I$3:$I$1002,반품접수!$K$3:$K$1002,$A9,반품접수!$H$3:$H$1002,"부자재",반품접수!$B$3:$B$1002,">="&DATE($B$3,1,1),반품접수!$B$3:$B$1002,"<="&DATE($B$3,12,31)) -> 0 | F9: =IF($C$14=0,"",$C9/$C$14) -> 0.0078125 | G9: =SUMPRODUCT((반품접수!$K$3:$K$1002=$A9)*1,IFERROR(SUMIF(처리내역!$B$3:$B$1502,반품접수!$A$3:$A$1002,처리내역!$G$3:$G$1502),0)) -> 30000
A10: 오배송 | B10: =COUNTIFS(반품접수!$K$3:$K$1002,$A10,반품접수!$B$3:$B$1002,">="&DATE($B$3,1,1),반품접수!$B$3:$B$1002,"<="&DATE($B$3,12,31)) -> 1 | C10: =SUMIFS(반품접수!$I$3:$I$1002,반품접수!$K$3:$K$1002,$A10,반품접수!$B$3:$B$1002,">="&DATE($B$3,1,1),반품접수!$B$3:$B$1002,"<="&DATE($B$3,12,31)) -> 200 | D10: =SUMIFS(반품접수!$I$3:$I$1002,반품접수!$K$3:$K$1002,$A10,반품접수!$H$3:$H$1002,"원재료",반품접수!$B$3:$B$1002,">="&DATE($B$3,1,1),반품접수!$B$3:$B$1002,"<="&DATE($B$3,12,31)) -> 0 | E10: =SUMIFS(반품접수!$I$3:$I$1002,반품접수!$K$3:$K$1002,$A10,반품접수!$H$3:$H$1002,"부자재",반품접수!$B$3:$B$1002,">="&DATE($B$3,1,1),반품접수!$B$3:$B$1002,"<="&DATE($B$3,12,31)) -> 200 | F10: =IF($C$14=0,"",$C10/$C$14) -> 0.78125 | G10: =SUMPRODUCT((반품접수!$K$3:$K$1002=$A10)*1,IFERROR(SUMIF(처리내역!$B$3:$B$1502,반품접수!$A$3:$A$1002,처리내역!$G$3:$G$1502),0)) -> 0
A11: 유통기한 | B11: =COUNTIFS(반품접수!$K$3:$K$1002,$A11,반품접수!$B$3:$B$1002,">="&DATE($B$3,1,1),반품접수!$B$3:$B$1002,"<="&DATE($B$3,12,31)) -> 1 | C11: =SUMIFS(반품접수!$I$3:$I$1002,반품접수!$K$3:$K$1002,$A11,반품접수!$B$3:$B$1002,">="&DATE($B$3,1,1),반품접수!$B$3:$B$1002,"<="&DATE($B$3,12,31)) -> 1 | D11: =SUMIFS(반품접수!$I$3:$I$1002,반품접수!$K$3:$K$1002,$A11,반품접수!$H$3:$H$1002,"원재료",반품접수!$B$3:$B$1002,">="&DATE($B$3,1,1),반품접수!$B$3:$B$1002,"<="&DATE($B$3,12,31)) -> 1 | E11: =SUMIFS(반품접수!$I$3:$I$1002,반품접수!$K$3:$K$1002,$A11,반품접수!$H$3:$H$1002,"부자재",반품접수!$B$3:$B$1002,">="&DATE($B$3,1,1),반품접수!$B$3:$B$1002,"<="&DATE($B$3,12,31)) -> 0 | F11: =IF($C$14=0,"",$C11/$C$14) -> 0.00390625 | G11: =SUMPRODUCT((반품접수!$K$3:$K$1002=$A11)*1,IFERROR(SUMIF(처리내역!$B$3:$B$1502,반품접수!$A$3:$A$1002,처리내역!$G$3:$G$1502),0)) -> 0
A12: 고객변심 | B12: =COUNTIFS(반품접수!$K$3:$K$1002,$A12,반품접수!$B$3:$B$1002,">="&DATE($B$3,1,1),반품접수!$B$3:$B$1002,"<="&DATE($B$3,12,31)) -> 0 | C12: =SUMIFS(반품접수!$I$3:$I$1002,반품접수!$K$3:$K$1002,$A12,반품접수!$B$3:$B$1002,">="&DATE($B$3,1,1),반품접수!$B$3:$B$1002,"<="&DATE($B$3,12,31)) -> 0 | D12: =SUMIFS(반품접수!$I$3:$I$1002,반품접수!$K$3:$K$1002,$A12,반품접수!$H$3:$H$1002,"원재료",반품접수!$B$3:$B$1002,">="&DATE($B$3,1,1),반품접수!$B$3:$B$1002,"<="&DATE($B$3,12,31)) -> 0 | E12: =SUMIFS(반품접수!$I$3:$I$1002,반품접수!$K$3:$K$1002,$A12,반품접수!$H$3:$H$1002,"부자재",반품접수!$B$3:$B$1002,">="&DATE($B$3,1,1),반품접수!$B$3:$B$1002,"<="&DATE($B$3,12,31)) -> 0 | F12: =IF($C$14=0,"",$C12/$C$14) -> 0 | G12: =SUMPRODUCT((반품접수!$K$3:$K$1002=$A12)*1,IFERROR(SUMIF(처리내역!$B$3:$B$1502,반품접수!$A$3:$A$1002,처리내역!$G$3:$G$1502),0)) -> 0
A13: 기타 | B13: =COUNTIFS(반품접수!$K$3:$K$1002,$A13,반품접수!$B$3:$B$1002,">="&DATE($B$3,1,1),반품접수!$B$3:$B$1002,"<="&DATE($B$3,12,31)) -> 0 | C13: =SUMIFS(반품접수!$I$3:$I$1002,반품접수!$K$3:$K$1002,$A13,반품접수!$B$3:$B$1002,">="&DATE($B$3,1,1),반품접수!$B$3:$B$1002,"<="&DATE($B$3,12,31)) -> 0 | D13: =SUMIFS(반품접수!$I$3:$I$1002,반품접수!$K$3:$K$1002,$A13,반품접수!$H$3:$H$1002,"원재료",반품접수!$B$3:$B$1002,">="&DATE($B$3,1,1),반품접수!$B$3:$B$1002,"<="&DATE($B$3,12,31)) -> 0 | E13: =SUMIFS(반품접수!$I$3:$I$1002,반품접수!$K$3:$K$1002,$A13,반품접수!$H$3:$H$1002,"부자재",반품접수!$B$3:$B$1002,">="&DATE($B$3,1,1),반품접수!$B$3:$B$1002,"<="&DATE($B$3,12,31)) -> 0 | F13: =IF($C$14=0,"",$C13/$C$14) -> 0 | G13: =SUMPRODUCT((반품접수!$K$3:$K$1002=$A13)*1,IFERROR(SUMIF(처리내역!$B$3:$B$1502,반품접수!$A$3:$A$1002,처리내역!$G$3:$G$1502),0)) -> 0
A14: 합계 | B14: =SUM(B6:B13) -> 5 | C14: =SUM(C6:C13) -> 256 | D14: =SUM(D6:D13) -> 6 | E14: =SUM(E6:E13) -> 250
A16: ※ 처리비용은 각 접수건에 연결된 처리내역의 비용 합계입니다.

Sheet 거래처별집계
A1: 거래처별집계
A3: 대상 연도 | B3: 2026
A5: 거래처명 | B5: 접수 건수 | C5: 접수 수량 | D5: 미처리 건수 | E5: 재입고 | F5: 폐기 | G5: 완료율
A6: =IF(거래처목록!$A3="","",거래처목록!$A3) -> ○○소재 | B6: =IF($A6="","",COUNTIFS(반품접수!$C$3:$C$1002,$A6,반품접수!$B$3:$B$1002,">="&DATE($B$3,1,1),반품접수!$B$3:$B$1002,"<="&DATE($B$3,12,31))) -> 2 | C6: =IF($A6="","",SUMIFS(반품접수!$I$3:$I$1002,반품접수!$C$3:$C$1002,$A6,반품접수!$B$3:$B$1002,">="&DATE($B$3,1,1),반품접수!$B$3:$B$1002,"<="&DATE($B$3,12,31))) -> 4 | D6: =IF($A6="","",COUNTIFS(반품접수!$C$3:$C$1002,$A6,반품접수!$O$3:$O$1002,"미처리",반품접수!$B$3:$B$1002,">="&DATE($B$3,1,1),반품접수!$B$3:$B$1002,"<="&DATE($B$3,12,31))+COUNTIFS(반품접수!$C$3:$C$1002,$A6,반품접수!$O$3:$O$1002,"부분처리",반품접수!$B$3:$B$1002,">="&DATE($B$3,1,1),반품접수!$B$3:$B$1002,"<="&DATE($B$3,12,31))) -> 2 | E6: =IF($A6="","",SUMPRODUCT((반품접수!$C$3:$C$1002=$A6)*1,IFERROR(SUMIFS(처리내역!$E$3:$E$1502,처리내역!$B$3:$B$1502,반품접수!$A$3:$A$1002,처리내역!$D$3:$D$1502,"재입고"),0))) -> 0 | F6: =IF($A6="","",SUMPRODUCT((반품접수!$C$3:$C$1002=$A6)*1,IFERROR(SUMIFS(처리내역!$E$3:$E$1502,처리내역!$B$3:$B$1502,반품접수!$A$3:$A$1002,처리내역!$D$3:$D$1502,"폐기"),0))) -> 2 | G6: =IF($A6="","",IF($B6=0,"",($B6-$D6)/$B6)) -> 0
A7: =IF(거래처목록!$A4="","",거래처목록!$A4) -> △△부품 | B7: =IF($A7="","",COUNTIFS(반품접수!$C$3:$C$1002,$A7,반품접수!$B$3:$B$1002,">="&DATE($B$3,1,1),반품접수!$B$3:$B$1002,"<="&DATE($B$3,12,31))) -> 1 | C7: =IF($A7="","",SUMIFS(반품접수!$I$3:$I$1002,반품접수!$C$3:$C$1002,$A7,반품접수!$B$3:$B$1002,">="&DATE($B$3,1,1),반품접수!$B$3:$B$1002,"<="&DATE($B$3,12,31))) -> 2 | D7: =IF($A7="","",COUNTIFS(반품접수!$C$3:$C$1002,$A7,반품접수!$O$3:$O$1002,"미처리",반품접수!$B$3:$B$1002,">="&DATE($B$3,1,1),반품접수!$B$3:$B$1002,"<="&DATE($B$3,12,31))+COUNTIFS(반품접수!$C$3:$C$1002,$A7,반품접수!$O$3:$O$1002,"부분처리",반품접수!$B$3:$B$1002,">="&DATE($B$3,1,1),반품접수!$B$3:$B$1002,"<="&DATE($B$3,12,31))) -> 0 | E7: =IF($A7="","",SUMPRODUCT((반품접수!$C$3:$C$1002=$A7)*1,IFERROR(SUMIFS(처리내역!$E$3:$E$1502,처리내역!$B$3:$B$1502,반품접수!$A$3:$A$1002,처리내역!$D$3:$D$1502,"재입고"),0))) -> 0 | F7: =IF($A7="","",SUMPRODUCT((반품접수!$C$3:$C$1002=$A7)*1,IFERROR(SUMIFS(처리내역!$E$3:$E$1502,처리내역!$B$3:$B$1502,반품접수!$A$3:$A$1002,처리내역!$D$3:$D$1502,"폐기"),0))) -> 0 | G7: =IF($A7="","",IF($B7=0,"",($B7-$D7)/$B7)) -> 1
A8: =IF(거래처목록!$A5="","",거래처목록!$A5) -> □□유통 | B8: =IF($A8="","",COUNTIFS(반품접수!$C$3:$C$1002,$A8,반품접수!$B$3:$B$1002,">="&DATE($B$3,1,1),반품접수!$B$3:$B$1002,"<="&DATE($B$3,12,31))) -> 2 | C8: =IF($A8="","",SUMIFS(반품접수!$I$3:$I$1002,반품접수!$C$3:$C$1002,$A8,반품접수!$B$3:$B$1002,">="&DATE($B$3,1,1),반품접수!$B$3:$B$1002,"<="&DATE($B$3,12,31))) -> 250 | D8: =IF($A8="","",COUNTIFS(반품접수!$C$3:$C$1002,$A8,반품접수!$O$3:$O$1002,"미처리",반품접수!$B$3:$B$1002,">="&DATE($B$3,1,1),반품접수!$B$3:$B$1002,"<="&DATE($B$3,12,31))+COUNTIFS(반품접수!$C$3:$C$1002,$A8,반품접수!$O$3:$O$1002,"부분처리",반품접수!$B$3:$B$1002,">="&DATE($B$3,1,1),반품접수!$B$3:$B$1002,"<="&DATE($B$3,12,31))) -> 1 | E8: =IF($A8="","",SUMPRODUCT((반품접수!$C$3:$C$1002=$A8)*1,IFERROR(SUMIFS(처리내역!$E$3:$E$1502,처리내역!$B$3:$B$1502,반품접수!$A$3:$A$1002,처리내역!$D$3:$D$1502,"재입고"),0))) -> 30 | F8: =IF($A8="","",SUMPRODUCT((반품접수!$C$3:$C$1002=$A8)*1,IFERROR(SUMIFS(처리내역!$E$3:$E$1502,처리내역!$B$3:$B$1502,반품접수!$A$3:$A$1002,처리내역!$D$3:$D$1502,"폐기"),0))) -> 20 | G8: =IF($A8="","",IF($B8=0,"",($B8-$D8)/$B8)) -> 0.5
