Workbook

Sheet 사용안내
B2: 회의록 · 할 일(액션아이템) 추적
B4: 핵심 | C4: 회의에서 나온 할 일을 따로 쌓아두면 기한이 언제인지, 누가 안 했는지가 한눈에 보입니다.
B5: 입력 규칙 | C5: 파란색 글씨 칸만 입력하세요. 검은색은 자동 계산입니다.
B6: ① 구성원목록 | C6: 참석자와 소속을 등록합니다.
B7: ② 회의록 | C7: 회의마다 한 줄. 회의번호는 자동으로 매겨집니다.
B8: ③ 액션아이템 | C8: 회의에서 나온 할 일을 한 줄씩. 회의번호로 연결됩니다.
B9: ④ 미완료현황 | C9: 아직 안 끝난 할 일만 모아서, 기한이 급한 순으로 보여줍니다.
B10: ⑤ 담당자별현황 | C10: 담당자별로 몇 건 맡았고 몇 건 남았는지 보여줍니다.
B11: ⑥ 회의록 출력 | C11: 회의번호를 고르면 그 회의의 회의록과 할 일이 한 장에 인쇄됩니다.
B12: 기한 표시 | C12: 기한이 지나면 빨강, 며칠 안 남았으면 노랑으로 표시됩니다.
B13: 완료 처리 | C13: 지우지 말고 상태를 '완료'로 바꾸고 완료일을 넣으세요.
B15: 설정 | C15: 값을 바꾸면 모든 계산에 반영됩니다
B16: 기한 임박 기준(일) | C16: 3
B18: ※ 회의 300건, 할 일 1,000건까지 처리합니다.

Sheet 구성원목록
A1: 구성원목록
A2: 이름 | B2: 소속 | C2: 직위 | D2: 연락처
A3: 김팀장 | B3: 기획팀 | C3: 팀장 | D3: 010-0000-0001
A4: 이대리 | B4: 개발팀 | C4: 대리 | D4: 010-0000-0002
A5: 박주임 | B5: 디자인팀 | C5: 주임 | D5: 010-0000-0003

Sheet 회의록
A1: 회의록 (회의번호는 자동)
A2: 회의번호(자동) | B2: 회의일 | C2: 회의명 | D2: 장소 | E2: 주관자 | F2: 참석자 | G2: 안건 | H2: 논의·결정사항 | I2: 할일 수(자동)
A3: =IF($B3="","",TEXT($B3,"yymmdd")&"-"&TEXT(COUNTIFS($B$3:$B3,$B3),"0")) -> 260901-1 | B3: 46266 | C3: 9월 정기회의 | D3: 대회의실 | E3: 김팀장 | F3: 김팀장, 이대리, 박주임 | G3: 3분기 실적 / 4분기 계획 | H3: 3분기 목표 달성. 4분기 신규 기능 2건 추가 결정. | I3: =IF($A3="","",COUNTIFS(액션아이템!$A$3:$A$1002,$A3)) -> 3
A4: =IF($B4="","",TEXT($B4,"yymmdd")&"-"&TEXT(COUNTIFS($B$3:$B4,$B4),"0")) -> 260908-1 | B4: 46273 | C4: 디자인 리뷰 | D4: 소회의실 | E4: 박주임 | F4: 박주임, 이대리 | G4: 시안 검토 | H4: B안 채택. 색상만 수정 후 확정하기로 함. | I4: =IF($A4="","",COUNTIFS(액션아이템!$A$3:$A$1002,$A4)) -> 1
A5: =IF($B5="","",TEXT($B5,"yymmdd")&"-"&TEXT(COUNTIFS($B$3:$B5,$B5),"0")) | I5: =IF($A5="","",COUNTIFS(액션아이템!$A$3:$A$1002,$A5))
A6: =IF($B6="","",TEXT($B6,"yymmdd")&"-"&TEXT(COUNTIFS($B$3:$B6,$B6),"0")) | I6: =IF($A6="","",COUNTIFS(액션아이템!$A$3:$A$1002,$A6))
A7: =IF($B7="","",TEXT($B7,"yymmdd")&"-"&TEXT(COUNTIFS($B$3:$B7,$B7),"0")) | I7: =IF($A7="","",COUNTIFS(액션아이템!$A$3:$A$1002,$A7))
A8: =IF($B8="","",TEXT($B8,"yymmdd")&"-"&TEXT(COUNTIFS($B$3:$B8,$B8),"0")) | I8: =IF($A8="","",COUNTIFS(액션아이템!$A$3:$A$1002,$A8))
A9: =IF($B9="","",TEXT($B9,"yymmdd")&"-"&TEXT(COUNTIFS($B$3:$B9,$B9),"0")) | I9: =IF($A9="","",COUNTIFS(액션아이템!$A$3:$A$1002,$A9))
A10: =IF($B10="","",TEXT($B10,"yymmdd")&"-"&TEXT(COUNTIFS($B$3:$B10,$B10),"0")) | I10: =IF($A10="","",COUNTIFS(액션아이템!$A$3:$A$1002,$A10))
A11: =IF($B11="","",TEXT($B11,"yymmdd")&"-"&TEXT(COUNTIFS($B$3:$B11,$B11),"0")) | I11: =IF($A11="","",COUNTIFS(액션아이템!$A$3:$A$1002,$A11))
A12: =IF($B12="","",TEXT($B12,"yymmdd")&"-"&TEXT(COUNTIFS($B$3:$B12,$B12),"0")) | I12: =IF($A12="","",COUNTIFS(액션아이템!$A$3:$A$1002,$A12))
A13: =IF($B13="","",TEXT($B13,"yymmdd")&"-"&TEXT(COUNTIFS($B$3:$B13,$B13),"0")) | I13: =IF($A13="","",COUNTIFS(액션아이템!$A$3:$A$1002,$A13))
A14: =IF($B14="","",TEXT($B14,"yymmdd")&"-"&TEXT(COUNTIFS($B$3:$B14,$B14),"0")) | I14: =IF($A14="","",COUNTIFS(액션아이템!$A$3:$A$1002,$A14))
A15: =IF($B15="","",TEXT($B15,"yymmdd")&"-"&TEXT(COUNTIFS($B$3:$B15,$B15),"0")) | I15: =IF($A15="","",COUNTIFS(액션아이템!$A$3:$A$1002,$A15))
A16: =IF($B16="","",TEXT($B16,"yymmdd")&"-"&TEXT(COUNTIFS($B$3:$B16,$B16),"0")) | I16: =IF($A16="","",COUNTIFS(액션아이템!$A$3:$A$1002,$A16))
... A302: =IF($B302="","",TEXT($B302,"yymmdd")&"-"&TEXT(COUNTIFS($B$3:$B302,$B302),"0")) | I302: =IF($A302="","",COUNTIFS(액션아이템!$A$3:$A$1002,$A302))

Sheet 액션아이템
A1: 액션아이템 (회의에서 나온 할 일)
A2: 회의번호 | B2: 회의명(자동) | C2: 할 일 | D2: 담당자 | E2: 기한 | F2: 상태 | G2: 완료일 | H2: D-Day(자동) | I2: 지연일(자동) | J2: 비고 | K2: 조회키(자동) | L2: 회의내순번(자동)
A3: 260901-1 | B3: =IF($A3="","",IFERROR(INDEX(회의록!$C$3:$C$302,MATCH($A3,회의록!$A$3:$A$302,0)),"회의번호없음")) -> 9월 정기회의 | C3: 4분기 기능 명세 작성 | D3: 이대리 | E3: 46285 | F3: 진행중 | H3: =IF(OR($C3="",$E3="",$F3="완료",$F3="취소"),"",$E3-TODAY()) -> 6 | I3: =IF(OR($C3="",$E3=""),"",IF($F3="완료",IF($G3="","",MAX(0,$G3-$E3)),IF($F3="취소","",MAX(0,TODAY()-$E3)))) -> 0 | K3: =IF($A3="","",$A3&"|"&$L3) -> 260901-1|1 | L3: =IF($A3="","",COUNTIFS($A$3:$A3,$A3)) -> 1
A4: 260901-1 | B4: =IF($A4="","",IFERROR(INDEX(회의록!$C$3:$C$302,MATCH($A4,회의록!$A$3:$A$302,0)),"회의번호없음")) -> 9월 정기회의 | C4: 예산안 재검토 | D4: 김팀장 | E4: 46275 | F4: 진행중 | H4: =IF(OR($C4="",$E4="",$F4="완료",$F4="취소"),"",$E4-TODAY()) -> -4 | I4: =IF(OR($C4="",$E4=""),"",IF($F4="완료",IF($G4="","",MAX(0,$G4-$E4)),IF($F4="취소","",MAX(0,TODAY()-$E4)))) -> 4 | K4: =IF($A4="","",$A4&"|"&$L4) -> 260901-1|2 | L4: =IF($A4="","",COUNTIFS($A$3:$A4,$A4)) -> 2
A5: 260901-1 | B5: =IF($A5="","",IFERROR(INDEX(회의록!$C$3:$C$302,MATCH($A5,회의록!$A$3:$A$302,0)),"회의번호없음")) -> 9월 정기회의 | C5: 실적 자료 정리 | D5: 박주임 | E5: 46270 | F5: 완료 | G5: 46269 | H5: =IF(OR($C5="",$E5="",$F5="완료",$F5="취소"),"",$E5-TODAY()) | I5: =IF(OR($C5="",$E5=""),"",IF($F5="완료",IF($G5="","",MAX(0,$G5-$E5)),IF($F5="취소","",MAX(0,TODAY()-$E5)))) -> 0 | K5: =IF($A5="","",$A5&"|"&$L5) -> 260901-1|3 | L5: =IF($A5="","",COUNTIFS($A$3:$A5,$A5)) -> 3
A6: 260908-1 | B6: =IF($A6="","",IFERROR(INDEX(회의록!$C$3:$C$302,MATCH($A6,회의록!$A$3:$A$302,0)),"회의번호없음")) -> 디자인 리뷰 | C6: 색상 수정본 전달 | D6: 박주임 | E6: 46281 | F6: 진행중 | H6: =IF(OR($C6="",$E6="",$F6="완료",$F6="취소"),"",$E6-TODAY()) -> 2 | I6: =IF(OR($C6="",$E6=""),"",IF($F6="완료",IF($G6="","",MAX(0,$G6-$E6)),IF($F6="취소","",MAX(0,TODAY()-$E6)))) -> 0 | K6: =IF($A6="","",$A6&"|"&$L6) -> 260908-1|1 | L6: =IF($A6="","",COUNTIFS($A$3:$A6,$A6)) -> 1
B7: =IF($A7="","",IFERROR(INDEX(회의록!$C$3:$C$302,MATCH($A7,회의록!$A$3:$A$302,0)),"회의번호없음")) | H7: =IF(OR($C7="",$E7="",$F7="완료",$F7="취소"),"",$E7-TODAY()) | I7: =IF(OR($C7="",$E7=""),"",IF($F7="완료",IF($G7="","",MAX(0,$G7-$E7)),IF($F7="취소","",MAX(0,TODAY()-$E7)))) | K7: =IF($A7="","",$A7&"|"&$L7) | L7: =IF($A7="","",COUNTIFS($A$3:$A7,$A7))
B8: =IF($A8="","",IFERROR(INDEX(회의록!$C$3:$C$302,MATCH($A8,회의록!$A$3:$A$302,0)),"회의번호없음")) | H8: =IF(OR($C8="",$E8="",$F8="완료",$F8="취소"),"",$E8-TODAY()) | I8: =IF(OR($C8="",$E8=""),"",IF($F8="완료",IF($G8="","",MAX(0,$G8-$E8)),IF($F8="취소","",MAX(0,TODAY()-$E8)))) | K8: =IF($A8="","",$A8&"|"&$L8) | L8: =IF($A8="","",COUNTIFS($A$3:$A8,$A8))
B9: =IF($A9="","",IFERROR(INDEX(회의록!$C$3:$C$302,MATCH($A9,회의록!$A$3:$A$302,0)),"회의번호없음")) | H9: =IF(OR($C9="",$E9="",$F9="완료",$F9="취소"),"",$E9-TODAY()) | I9: =IF(OR($C9="",$E9=""),"",IF($F9="완료",IF($G9="","",MAX(0,$G9-$E9)),IF($F9="취소","",MAX(0,TODAY()-$E9)))) | K9: =IF($A9="","",$A9&"|"&$L9) | L9: =IF($A9="","",COUNTIFS($A$3:$A9,$A9))
B10: =IF($A10="","",IFERROR(INDEX(회의록!$C$3:$C$302,MATCH($A10,회의록!$A$3:$A$302,0)),"회의번호없음")) | H10: =IF(OR($C10="",$E10="",$F10="완료",$F10="취소"),"",$E10-TODAY()) | I10: =IF(OR($C10="",$E10=""),"",IF($F10="완료",IF($G10="","",MAX(0,$G10-$E10)),IF($F10="취소","",MAX(0,TODAY()-$E10)))) | K10: =IF($A10="","",$A10&"|"&$L10) | L10: =IF($A10="","",COUNTIFS($A$3:$A10,$A10))
B11: =IF($A11="","",IFERROR(INDEX(회의록!$C$3:$C$302,MATCH($A11,회의록!$A$3:$A$302,0)),"회의번호없음")) | H11: =IF(OR($C11="",$E11="",$F11="완료",$F11="취소"),"",$E11-TODAY()) | I11: =IF(OR($C11="",$E11=""),"",IF($F11="완료",IF($G11="","",MAX(0,$G11-$E11)),IF($F11="취소","",MAX(0,TODAY()-$E11)))) | K11: =IF($A11="","",$A11&"|"&$L11) | L11: =IF($A11="","",COUNTIFS($A$3:$A11,$A11))
B12: =IF($A12="","",IFERROR(INDEX(회의록!$C$3:$C$302,MATCH($A12,회의록!$A$3:$A$302,0)),"회의번호없음")) | H12: =IF(OR($C12="",$E12="",$F12="완료",$F12="취소"),"",$E12-TODAY()) | I12: =IF(OR($C12="",$E12=""),"",IF($F12="완료",IF($G12="","",MAX(0,$G12-$E12)),IF($F12="취소","",MAX(0,TODAY()-$E12)))) | K12: =IF($A12="","",$A12&"|"&$L12) | L12: =IF($A12="","",COUNTIFS($A$3:$A12,$A12))
B13: =IF($A13="","",IFERROR(INDEX(회의록!$C$3:$C$302,MATCH($A13,회의록!$A$3:$A$302,0)),"회의번호없음")) | H13: =IF(OR($C13="",$E13="",$F13="완료",$F13="취소"),"",$E13-TODAY()) | I13: =IF(OR($C13="",$E13=""),"",IF($F13="완료",IF($G13="","",MAX(0,$G13-$E13)),IF($F13="취소","",MAX(0,TODAY()-$E13)))) | K13: =IF($A13="","",$A13&"|"&$L13) | L13: =IF($A13="","",COUNTIFS($A$3:$A13,$A13))
B14: =IF($A14="","",IFERROR(INDEX(회의록!$C$3:$C$302,MATCH($A14,회의록!$A$3:$A$302,0)),"회의번호없음")) | H14: =IF(OR($C14="",$E14="",$F14="완료",$F14="취소"),"",$E14-TODAY()) | I14: =IF(OR($C14="",$E14=""),"",IF($F14="완료",IF($G14="","",MAX(0,$G14-$E14)),IF($F14="취소","",MAX(0,TODAY()-$E14)))) | K14: =IF($A14="","",$A14&"|"&$L14) | L14: =IF($A14="","",COUNTIFS($A$3:$A14,$A14))
B15: =IF($A15="","",IFERROR(INDEX(회의록!$C$3:$C$302,MATCH($A15,회의록!$A$3:$A$302,0)),"회의번호없음")) | H15: =IF(OR($C15="",$E15="",$F15="완료",$F15="취소"),"",$E15-TODAY()) | I15: =IF(OR($C15="",$E15=""),"",IF($F15="완료",IF($G15="","",MAX(0,$G15-$E15)),IF($F15="취소","",MAX(0,TODAY()-$E15)))) | K15: =IF($A15="","",$A15&"|"&$L15) | L15: =IF($A15="","",COUNTIFS($A$3:$A15,$A15))
B16: =IF($A16="","",IFERROR(INDEX(회의록!$C$3:$C$302,MATCH($A16,회의록!$A$3:$A$302,0)),"회의번호없음")) | H16: =IF(OR($C16="",$E16="",$F16="완료",$F16="취소"),"",$E16-TODAY()) | I16: =IF(OR($C16="",$E16=""),"",IF($F16="완료",IF($G16="","",MAX(0,$G16-$E16)),IF($F16="취소","",MAX(0,TODAY()-$E16)))) | K16: =IF($A16="","",$A16&"|"&$L16) | L16: =IF($A16="","",COUNTIFS($A$3:$A16,$A16))
B17: =IF($A17="","",IFERROR(INDEX(회의록!$C$3:$C$302,MATCH($A17,회의록!$A$3:$A$302,0)),"회의번호없음")) | H17: =IF(OR($C17="",$E17="",$F17="완료",$F17="취소"),"",$E17-TODAY()) | I17: =IF(OR($C17="",$E17=""),"",IF($F17="완료",IF($G17="","",MAX(0,$G17-$E17)),IF($F17="취소","",MAX(0,TODAY()-$E17)))) | K17: =IF($A17="","",$A17&"|"&$L17) | L17: =IF($A17="","",COUNTIFS($A$3:$A17,$A17))
B18: =IF($A18="","",IFERROR(INDEX(회의록!$C$3:$C$302,MATCH($A18,회의록!$A$3:$A$302,0)),"회의번호없음")) | H18: =IF(OR($C18="",$E18="",$F18="완료",$F18="취소"),"",$E18-TODAY()) | I18: =IF(OR($C18="",$E18=""),"",IF($F18="완료",IF($G18="","",MAX(0,$G18-$E18)),IF($F18="취소","",MAX(0,TODAY()-$E18)))) | K18: =IF($A18="","",$A18&"|"&$L18) | L18: =IF($A18="","",COUNTIFS($A$3:$A18,$A18))
... B1002: =IF($A1002="","",IFERROR(INDEX(회의록!$C$3:$C$302,MATCH($A1002,회의록!$A$3:$A$302,0)),"회의번호없음")) | H1002: =IF(OR($C1002="",$E1002="",$F1002="완료",$F1002="취소"),"",$E1002-TODAY()) | I1002: =IF(OR($C1002="",$E1002=""),"",IF($F1002="완료",IF($G1002="","",MAX(0,$G1002-$E1002)),IF($F1002="취소","",MAX(0,TODAY()-$E1002)))) | K1002: =IF($A1002="","",$A1002&"|"&$L1002) | L1002: =IF($A1002="","",COUNTIFS($A$3:$A1002,$A1002))
A1004: ※ D-Day가 음수면 기한이 지난 것입니다. 완료·취소 건은 계산하지 않습니다.

Sheet 미완료현황
A1: 미완료현황 (아직 안 끝난 할 일)
A3: 미완료 | B3: =COUNTIFS(액션아이템!$F$3:$F$1002,"진행중")+COUNTIFS(액션아이템!$F$3:$F$1002,"보류") -> 3 | D3: 기한 초과 | E3: =COUNTIFS(액션아이템!$H$3:$H$1002,"<0") -> 1 | G3: 임박 | H3: =COUNTIFS(액션아이템!$H$3:$H$1002,">=0",액션아이템!$H$3:$H$1002,"<="&사용안내!$C$16) -> 1
A5: 순위 | B5: 할 일 | C5: 담당자 | D5: 회의명 | E5: 기한 | F5: D-Day | G5: 상태 | H5: 지연일 | J5: 대상(자동) | K5: 정렬키(자동) | L5: 순위(자동)
A6: =IF($B6="","",1) -> 1 | B6: =IFERROR(INDEX(액션아이템!$C$3:$C$1002,MATCH(1,미완료현황!$L$6:$L$1005,0)),"") -> 예산안 재검토 | C6: =IF($B6="","",IFERROR(INDEX(액션아이템!$D$3:$D$1002,MATCH(1,미완료현황!$L$6:$L$1005,0)),"")) -> 김팀장 | D6: =IF($B6="","",IFERROR(INDEX(액션아이템!$B$3:$B$1002,MATCH(1,미완료현황!$L$6:$L$1005,0)),"")) -> 9월 정기회의 | E6: =IF($B6="","",IFERROR(INDEX(액션아이템!$E$3:$E$1002,MATCH(1,미완료현황!$L$6:$L$1005,0)),"")) -> 46275 | F6: =IF($B6="","",IFERROR(INDEX(액션아이템!$H$3:$H$1002,MATCH(1,미완료현황!$L$6:$L$1005,0)),"")) -> -4 | G6: =IF($B6="","",IFERROR(INDEX(액션아이템!$F$3:$F$1002,MATCH(1,미완료현황!$L$6:$L$1005,0)),"")) -> 진행중 | H6: =IF($B6="","",IFERROR(INDEX(액션아이템!$I$3:$I$1002,MATCH(1,미완료현황!$L$6:$L$1005,0)),"")) -> 4 | J6: =IF(액션아이템!$C3="",FALSE(),OR(액션아이템!$F3="진행중",액션아이템!$F3="보류")) -> TRUE | K6: =IF($J6=FALSE(),"",IF(액션아이템!$E3="",99999999,액션아이템!$E3)*100+ROW()/1000) -> 4628500 | L6: =IF($K6="","",RANK($K6,$K$6:$K$1005,1)) -> 3
A7: =IF($B7="","",2) -> 2 | B7: =IFERROR(INDEX(액션아이템!$C$3:$C$1002,MATCH(2,미완료현황!$L$6:$L$1005,0)),"") -> 색상 수정본 전달 | C7: =IF($B7="","",IFERROR(INDEX(액션아이템!$D$3:$D$1002,MATCH(2,미완료현황!$L$6:$L$1005,0)),"")) -> 박주임 | D7: =IF($B7="","",IFERROR(INDEX(액션아이템!$B$3:$B$1002,MATCH(2,미완료현황!$L$6:$L$1005,0)),"")) -> 디자인 리뷰 | E7: =IF($B7="","",IFERROR(INDEX(액션아이템!$E$3:$E$1002,MATCH(2,미완료현황!$L$6:$L$1005,0)),"")) -> 46281 | F7: =IF($B7="","",IFERROR(INDEX(액션아이템!$H$3:$H$1002,MATCH(2,미완료현황!$L$6:$L$1005,0)),"")) -> 2 | G7: =IF($B7="","",IFERROR(INDEX(액션아이템!$F$3:$F$1002,MATCH(2,미완료현황!$L$6:$L$1005,0)),"")) -> 진행중 | H7: =IF($B7="","",IFERROR(INDEX(액션아이템!$I$3:$I$1002,MATCH(2,미완료현황!$L$6:$L$1005,0)),"")) -> 0 | J7: =IF(액션아이템!$C4="",FALSE(),OR(액션아이템!$F4="진행중",액션아이템!$F4="보류")) -> TRUE | K7: =IF($J7=FALSE(),"",IF(액션아이템!$E4="",99999999,액션아이템!$E4)*100+ROW()/1000) -> 4627500 | L7: =IF($K7="","",RANK($K7,$K$6:$K$1005,1)) -> 1
A8: =IF($B8="","",3) -> 3 | B8: =IFERROR(INDEX(액션아이템!$C$3:$C$1002,MATCH(3,미완료현황!$L$6:$L$1005,0)),"") -> 4분기 기능 명세 작성 | C8: =IF($B8="","",IFERROR(INDEX(액션아이템!$D$3:$D$1002,MATCH(3,미완료현황!$L$6:$L$1005,0)),"")) -> 이대리 | D8: =IF($B8="","",IFERROR(INDEX(액션아이템!$B$3:$B$1002,MATCH(3,미완료현황!$L$6:$L$1005,0)),"")) -> 9월 정기회의 | E8: =IF($B8="","",IFERROR(INDEX(액션아이템!$E$3:$E$1002,MATCH(3,미완료현황!$L$6:$L$1005,0)),"")) -> 46285 | F8: =IF($B8="","",IFERROR(INDEX(액션아이템!$H$3:$H$1002,MATCH(3,미완료현황!$L$6:$L$1005,0)),"")) -> 6 | G8: =IF($B8="","",IFERROR(INDEX(액션아이템!$F$3:$F$1002,MATCH(3,미완료현황!$L$6:$L$1005,0)),"")) -> 진행중 | H8: =IF($B8="","",IFERROR(INDEX(액션아이템!$I$3:$I$1002,MATCH(3,미완료현황!$L$6:$L$1005,0)),"")) -> 0 | J8: =IF(액션아이템!$C5="",FALSE(),OR(액션아이템!$F5="진행중",액션아이템!$F5="보류")) -> FALSE | K8: =IF($J8=FALSE(),"",IF(액션아이템!$E5="",99999999,액션아이템!$E5)*100+ROW()/1000) | L8: =IF($K8="","",RANK($K8,$K$6:$K$1005,1))
A9: =IF($B9="","",4) | B9: =IFERROR(INDEX(액션아이템!$C$3:$C$1002,MATCH(4,미완료현황!$L$6:$L$1005,0)),"") | C9: =IF($B9="","",IFERROR(INDEX(액션아이템!$D$3:$D$1002,MATCH(4,미완료현황!$L$6:$L$1005,0)),"")) | D9: =IF($B9="","",IFERROR(INDEX(액션아이템!$B$3:$B$1002,MATCH(4,미완료현황!$L$6:$L$1005,0)),"")) | E9: =IF($B9="","",IFERROR(INDEX(액션아이템!$E$3:$E$1002,MATCH(4,미완료현황!$L$6:$L$1005,0)),"")) | F9: =IF($B9="","",IFERROR(INDEX(액션아이템!$H$3:$H$1002,MATCH(4,미완료현황!$L$6:$L$1005,0)),"")) | G9: =IF($B9="","",IFERROR(INDEX(액션아이템!$F$3:$F$1002,MATCH(4,미완료현황!$L$6:$L$1005,0)),"")) | H9: =IF($B9="","",IFERROR(INDEX(액션아이템!$I$3:$I$1002,MATCH(4,미완료현황!$L$6:$L$1005,0)),"")) | J9: =IF(액션아이템!$C6="",FALSE(),OR(액션아이템!$F6="진행중",액션아이템!$F6="보류")) -> TRUE | K9: =IF($J9=FALSE(),"",IF(액션아이템!$E6="",99999999,액션아이템!$E6)*100+ROW()/1000) -> 4628100 | L9: =IF($K9="","",RANK($K9,$K$6:$K$1005,1)) -> 2
A10: =IF($B10="","",5) | B10: =IFERROR(INDEX(액션아이템!$C$3:$C$1002,MATCH(5,미완료현황!$L$6:$L$1005,0)),"") | C10: =IF($B10="","",IFERROR(INDEX(액션아이템!$D$3:$D$1002,MATCH(5,미완료현황!$L$6:$L$1005,0)),"")) | D10: =IF($B10="","",IFERROR(INDEX(액션아이템!$B$3:$B$1002,MATCH(5,미완료현황!$L$6:$L$1005,0)),"")) | E10: =IF($B10="","",IFERROR(INDEX(액션아이템!$E$3:$E$1002,MATCH(5,미완료현황!$L$6:$L$1005,0)),"")) | F10: =IF($B10="","",IFERROR(INDEX(액션아이템!$H$3:$H$1002,MATCH(5,미완료현황!$L$6:$L$1005,0)),"")) | G10: =IF($B10="","",IFERROR(INDEX(액션아이템!$F$3:$F$1002,MATCH(5,미완료현황!$L$6:$L$1005,0)),"")) | H10: =IF($B10="","",IFERROR(INDEX(액션아이템!$I$3:$I$1002,MATCH(5,미완료현황!$L$6:$L$1005,0)),"")) | J10: =IF(액션아이템!$C7="",FALSE(),OR(액션아이템!$F7="진행중",액션아이템!$F7="보류")) -> FALSE | K10: =IF($J10=FALSE(),"",IF(액션아이템!$E7="",99999999,액션아이템!$E7)*100+ROW()/1000) | L10: =IF($K10="","",RANK($K10,$K$6:$K$1005,1))
A11: =IF($B11="","",6) | B11: =IFERROR(INDEX(액션아이템!$C$3:$C$1002,MATCH(6,미완료현황!$L$6:$L$1005,0)),"") | C11: =IF($B11="","",IFERROR(INDEX(액션아이템!$D$3:$D$1002,MATCH(6,미완료현황!$L$6:$L$1005,0)),"")) | D11: =IF($B11="","",IFERROR(INDEX(액션아이템!$B$3:$B$1002,MATCH(6,미완료현황!$L$6:$L$1005,0)),"")) | E11: =IF($B11="","",IFERROR(INDEX(액션아이템!$E$3:$E$1002,MATCH(6,미완료현황!$L$6:$L$1005,0)),"")) | F11: =IF($B11="","",IFERROR(INDEX(액션아이템!$H$3:$H$1002,MATCH(6,미완료현황!$L$6:$L$1005,0)),"")) | G11: =IF($B11="","",IFERROR(INDEX(액션아이템!$F$3:$F$1002,MATCH(6,미완료현황!$L$6:$L$1005,0)),"")) | H11: =IF($B11="","",IFERROR(INDEX(액션아이템!$I$3:$I$1002,MATCH(6,미완료현황!$L$6:$L$1005,0)),"")) | J11: =IF(액션아이템!$C8="",FALSE(),OR(액션아이템!$F8="진행중",액션아이템!$F8="보류")) -> FALSE | K11: =IF($J11=FALSE(),"",IF(액션아이템!$E8="",99999999,액션아이템!$E8)*100+ROW()/1000) | L11: =IF($K11="","",RANK($K11,$K$6:$K$1005,1))
A12: =IF($B12="","",7) | B12: =IFERROR(INDEX(액션아이템!$C$3:$C$1002,MATCH(7,미완료현황!$L$6:$L$1005,0)),"") | C12: =IF($B12="","",IFERROR(INDEX(액션아이템!$D$3:$D$1002,MATCH(7,미완료현황!$L$6:$L$1005,0)),"")) | D12: =IF($B12="","",IFERROR(INDEX(액션아이템!$B$3:$B$1002,MATCH(7,미완료현황!$L$6:$L$1005,0)),"")) | E12: =IF($B12="","",IFERROR(INDEX(액션아이템!$E$3:$E$1002,MATCH(7,미완료현황!$L$6:$L$1005,0)),"")) | F12: =IF($B12="","",IFERROR(INDEX(액션아이템!$H$3:$H$1002,MATCH(7,미완료현황!$L$6:$L$1005,0)),"")) | G12: =IF($B12="","",IFERROR(INDEX(액션아이템!$F$3:$F$1002,MATCH(7,미완료현황!$L$6:$L$1005,0)),"")) | H12: =IF($B12="","",IFERROR(INDEX(액션아이템!$I$3:$I$1002,MATCH(7,미완료현황!$L$6:$L$1005,0)),"")) | J12: =IF(액션아이템!$C9="",FALSE(),OR(액션아이템!$F9="진행중",액션아이템!$F9="보류")) -> FALSE | K12: =IF($J12=FALSE(),"",IF(액션아이템!$E9="",99999999,액션아이템!$E9)*100+ROW()/1000) | L12: =IF($K12="","",RANK($K12,$K$6:$K$1005,1))
A13: =IF($B13="","",8) | B13: =IFERROR(INDEX(액션아이템!$C$3:$C$1002,MATCH(8,미완료현황!$L$6:$L$1005,0)),"") | C13: =IF($B13="","",IFERROR(INDEX(액션아이템!$D$3:$D$1002,MATCH(8,미완료현황!$L$6:$L$1005,0)),"")) | D13: =IF($B13="","",IFERROR(INDEX(액션아이템!$B$3:$B$1002,MATCH(8,미완료현황!$L$6:$L$1005,0)),"")) | E13: =IF($B13="","",IFERROR(INDEX(액션아이템!$E$3:$E$1002,MATCH(8,미완료현황!$L$6:$L$1005,0)),"")) | F13: =IF($B13="","",IFERROR(INDEX(액션아이템!$H$3:$H$1002,MATCH(8,미완료현황!$L$6:$L$1005,0)),"")) | G13: =IF($B13="","",IFERROR(INDEX(액션아이템!$F$3:$F$1002,MATCH(8,미완료현황!$L$6:$L$1005,0)),"")) | H13: =IF($B13="","",IFERROR(INDEX(액션아이템!$I$3:$I$1002,MATCH(8,미완료현황!$L$6:$L$1005,0)),"")) | J13: =IF(액션아이템!$C10="",FALSE(),OR(액션아이템!$F10="진행중",액션아이템!$F10="보류")) -> FALSE | K13: =IF($J13=FALSE(),"",IF(액션아이템!$E10="",99999999,액션아이템!$E10)*100+ROW()/1000) | L13: =IF($K13="","",RANK($K13,$K$6:$K$1005,1))
A14: =IF($B14="","",9) | B14: =IFERROR(INDEX(액션아이템!$C$3:$C$1002,MATCH(9,미완료현황!$L$6:$L$1005,0)),"") | C14: =IF($B14="","",IFERROR(INDEX(액션아이템!$D$3:$D$1002,MATCH(9,미완료현황!$L$6:$L$1005,0)),"")) | D14: =IF($B14="","",IFERROR(INDEX(액션아이템!$B$3:$B$1002,MATCH(9,미완료현황!$L$6:$L$1005,0)),"")) | E14: =IF($B14="","",IFERROR(INDEX(액션아이템!$E$3:$E$1002,MATCH(9,미완료현황!$L$6:$L$1005,0)),"")) | F14: =IF($B14="","",IFERROR(INDEX(액션아이템!$H$3:$H$1002,MATCH(9,미완료현황!$L$6:$L$1005,0)),"")) | G14: =IF($B14="","",IFERROR(INDEX(액션아이템!$F$3:$F$1002,MATCH(9,미완료현황!$L$6:$L$1005,0)),"")) | H14: =IF($B14="","",IFERROR(INDEX(액션아이템!$I$3:$I$1002,MATCH(9,미완료현황!$L$6:$L$1005,0)),"")) | J14: =IF(액션아이템!$C11="",FALSE(),OR(액션아이템!$F11="진행중",액션아이템!$F11="보류")) -> FALSE | K14: =IF($J14=FALSE(),"",IF(액션아이템!$E11="",99999999,액션아이템!$E11)*100+ROW()/1000) | L14: =IF($K14="","",RANK($K14,$K$6:$K$1005,1))
A15: =IF($B15="","",10) | B15: =IFERROR(INDEX(액션아이템!$C$3:$C$1002,MATCH(10,미완료현황!$L$6:$L$1005,0)),"") | C15: =IF($B15="","",IFERROR(INDEX(액션아이템!$D$3:$D$1002,MATCH(10,미완료현황!$L$6:$L$1005,0)),"")) | D15: =IF($B15="","",IFERROR(INDEX(액션아이템!$B$3:$B$1002,MATCH(10,미완료현황!$L$6:$L$1005,0)),"")) | E15: =IF($B15="","",IFERROR(INDEX(액션아이템!$E$3:$E$1002,MATCH(10,미완료현황!$L$6:$L$1005,0)),"")) | F15: =IF($B15="","",IFERROR(INDEX(액션아이템!$H$3:$H$1002,MATCH(10,미완료현황!$L$6:$L$1005,0)),"")) | G15: =IF($B15="","",IFERROR(INDEX(액션아이템!$F$3:$F$1002,MATCH(10,미완료현황!$L$6:$L$1005,0)),"")) | H15: =IF($B15="","",IFERROR(INDEX(액션아이템!$I$3:$I$1002,MATCH(10,미완료현황!$L$6:$L$1005,0)),"")) | J15: =IF(액션아이템!$C12="",FALSE(),OR(액션아이템!$F12="진행중",액션아이템!$F12="보류")) -> FALSE | K15: =IF($J15=FALSE(),"",IF(액션아이템!$E12="",99999999,액션아이템!$E12)*100+ROW()/1000) | L15: =IF($K15="","",RANK($K15,$K$6:$K$1005,1))
A16: =IF($B16="","",11) | B16: =IFERROR(INDEX(액션아이템!$C$3:$C$1002,MATCH(11,미완료현황!$L$6:$L$1005,0)),"") | C16: =IF($B16="","",IFERROR(INDEX(액션아이템!$D$3:$D$1002,MATCH(11,미완료현황!$L$6:$L$1005,0)),"")) | D16: =IF($B16="","",IFERROR(INDEX(액션아이템!$B$3:$B$1002,MATCH(11,미완료현황!$L$6:$L$1005,0)),"")) | E16: =IF($B16="","",IFERROR(INDEX(액션아이템!$E$3:$E$1002,MATCH(11,미완료현황!$L$6:$L$1005,0)),"")) | F16: =IF($B16="","",IFERROR(INDEX(액션아이템!$H$3:$H$1002,MATCH(11,미완료현황!$L$6:$L$1005,0)),"")) | G16: =IF($B16="","",IFERROR(INDEX(액션아이템!$F$3:$F$1002,MATCH(11,미완료현황!$L$6:$L$1005,0)),"")) | H16: =IF($B16="","",IFERROR(INDEX(액션아이템!$I$3:$I$1002,MATCH(11,미완료현황!$L$6:$L$1005,0)),"")) | J16: =IF(액션아이템!$C13="",FALSE(),OR(액션아이템!$F13="진행중",액션아이템!$F13="보류")) -> FALSE | K16: =IF($J16=FALSE(),"",IF(액션아이템!$E13="",99999999,액션아이템!$E13)*100+ROW()/1000) | L16: =IF($K16="","",RANK($K16,$K$6:$K$1005,1))
A17: =IF($B17="","",12) | B17: =IFERROR(INDEX(액션아이템!$C$3:$C$1002,MATCH(12,미완료현황!$L$6:$L$1005,0)),"") | C17: =IF($B17="","",IFERROR(INDEX(액션아이템!$D$3:$D$1002,MATCH(12,미완료현황!$L$6:$L$1005,0)),"")) | D17: =IF($B17="","",IFERROR(INDEX(액션아이템!$B$3:$B$1002,MATCH(12,미완료현황!$L$6:$L$1005,0)),"")) | E17: =IF($B17="","",IFERROR(INDEX(액션아이템!$E$3:$E$1002,MATCH(12,미완료현황!$L$6:$L$1005,0)),"")) | F17: =IF($B17="","",IFERROR(INDEX(액션아이템!$H$3:$H$1002,MATCH(12,미완료현황!$L$6:$L$1005,0)),"")) | G17: =IF($B17="","",IFERROR(INDEX(액션아이템!$F$3:$F$1002,MATCH(12,미완료현황!$L$6:$L$1005,0)),"")) | H17: =IF($B17="","",IFERROR(INDEX(액션아이템!$I$3:$I$1002,MATCH(12,미완료현황!$L$6:$L$1005,0)),"")) | J17: =IF(액션아이템!$C14="",FALSE(),OR(액션아이템!$F14="진행중",액션아이템!$F14="보류")) -> FALSE | K17: =IF($J17=FALSE(),"",IF(액션아이템!$E14="",99999999,액션아이템!$E14)*100+ROW()/1000) | L17: =IF($K17="","",RANK($K17,$K$6:$K$1005,1))
A18: =IF($B18="","",13) | B18: =IFERROR(INDEX(액션아이템!$C$3:$C$1002,MATCH(13,미완료현황!$L$6:$L$1005,0)),"") | C18: =IF($B18="","",IFERROR(INDEX(액션아이템!$D$3:$D$1002,MATCH(13,미완료현황!$L$6:$L$1005,0)),"")) | D18: =IF($B18="","",IFERROR(INDEX(액션아이템!$B$3:$B$1002,MATCH(13,미완료현황!$L$6:$L$1005,0)),"")) | E18: =IF($B18="","",IFERROR(INDEX(액션아이템!$E$3:$E$1002,MATCH(13,미완료현황!$L$6:$L$1005,0)),"")) | F18: =IF($B18="","",IFERROR(INDEX(액션아이템!$H$3:$H$1002,MATCH(13,미완료현황!$L$6:$L$1005,0)),"")) | G18: =IF($B18="","",IFERROR(INDEX(액션아이템!$F$3:$F$1002,MATCH(13,미완료현황!$L$6:$L$1005,0)),"")) | H18: =IF($B18="","",IFERROR(INDEX(액션아이템!$I$3:$I$1002,MATCH(13,미완료현황!$L$6:$L$1005,0)),"")) | J18: =IF(액션아이템!$C15="",FALSE(),OR(액션아이템!$F15="진행중",액션아이템!$F15="보류")) -> FALSE | K18: =IF($J18=FALSE(),"",IF(액션아이템!$E15="",99999999,액션아이템!$E15)*100+ROW()/1000) | L18: =IF($K18="","",RANK($K18,$K$6:$K$1005,1))
A19: =IF($B19="","",14) | B19: =IFERROR(INDEX(액션아이템!$C$3:$C$1002,MATCH(14,미완료현황!$L$6:$L$1005,0)),"") | C19: =IF($B19="","",IFERROR(INDEX(액션아이템!$D$3:$D$1002,MATCH(14,미완료현황!$L$6:$L$1005,0)),"")) | D19: =IF($B19="","",IFERROR(INDEX(액션아이템!$B$3:$B$1002,MATCH(14,미완료현황!$L$6:$L$1005,0)),"")) | E19: =IF($B19="","",IFERROR(INDEX(액션아이템!$E$3:$E$1002,MATCH(14,미완료현황!$L$6:$L$1005,0)),"")) | F19: =IF($B19="","",IFERROR(INDEX(액션아이템!$H$3:$H$1002,MATCH(14,미완료현황!$L$6:$L$1005,0)),"")) | G19: =IF($B19="","",IFERROR(INDEX(액션아이템!$F$3:$F$1002,MATCH(14,미완료현황!$L$6:$L$1005,0)),"")) | H19: =IF($B19="","",IFERROR(INDEX(액션아이템!$I$3:$I$1002,MATCH(14,미완료현황!$L$6:$L$1005,0)),"")) | J19: =IF(액션아이템!$C16="",FALSE(),OR(액션아이템!$F16="진행중",액션아이템!$F16="보류")) -> FALSE | K19: =IF($J19=FALSE(),"",IF(액션아이템!$E16="",99999999,액션아이템!$E16)*100+ROW()/1000) | L19: =IF($K19="","",RANK($K19,$K$6:$K$1005,1))
A20: =IF($B20="","",15) | B20: =IFERROR(INDEX(액션아이템!$C$3:$C$1002,MATCH(15,미완료현황!$L$6:$L$1005,0)),"") | C20: =IF($B20="","",IFERROR(INDEX(액션아이템!$D$3:$D$1002,MATCH(15,미완료현황!$L$6:$L$1005,0)),"")) | D20: =IF($B20="","",IFERROR(INDEX(액션아이템!$B$3:$B$1002,MATCH(15,미완료현황!$L$6:$L$1005,0)),"")) | E20: =IF($B20="","",IFERROR(INDEX(액션아이템!$E$3:$E$1002,MATCH(15,미완료현황!$L$6:$L$1005,0)),"")) | F20: =IF($B20="","",IFERROR(INDEX(액션아이템!$H$3:$H$1002,MATCH(15,미완료현황!$L$6:$L$1005,0)),"")) | G20: =IF($B20="","",IFERROR(INDEX(액션아이템!$F$3:$F$1002,MATCH(15,미완료현황!$L$6:$L$1005,0)),"")) | H20: =IF($B20="","",IFERROR(INDEX(액션아이템!$I$3:$I$1002,MATCH(15,미완료현황!$L$6:$L$1005,0)),"")) | J20: =IF(액션아이템!$C17="",FALSE(),OR(액션아이템!$F17="진행중",액션아이템!$F17="보류")) -> FALSE | K20: =IF($J20=FALSE(),"",IF(액션아이템!$E17="",99999999,액션아이템!$E17)*100+ROW()/1000) | L20: =IF($K20="","",RANK($K20,$K$6:$K$1005,1))
A21: =IF($B21="","",16) | B21: =IFERROR(INDEX(액션아이템!$C$3:$C$1002,MATCH(16,미완료현황!$L$6:$L$1005,0)),"") | C21: =IF($B21="","",IFERROR(INDEX(액션아이템!$D$3:$D$1002,MATCH(16,미완료현황!$L$6:$L$1005,0)),"")) | D21: =IF($B21="","",IFERROR(INDEX(액션아이템!$B$3:$B$1002,MATCH(16,미완료현황!$L$6:$L$1005,0)),"")) | E21: =IF($B21="","",IFERROR(INDEX(액션아이템!$E$3:$E$1002,MATCH(16,미완료현황!$L$6:$L$1005,0)),"")) | F21: =IF($B21="","",IFERROR(INDEX(액션아이템!$H$3:$H$1002,MATCH(16,미완료현황!$L$6:$L$1005,0)),"")) | G21: =IF($B21="","",IFERROR(INDEX(액션아이템!$F$3:$F$1002,MATCH(16,미완료현황!$L$6:$L$1005,0)),"")) | H21: =IF($B21="","",IFERROR(INDEX(액션아이템!$I$3:$I$1002,MATCH(16,미완료현황!$L$6:$L$1005,0)),"")) | J21: =IF(액션아이템!$C18="",FALSE(),OR(액션아이템!$F18="진행중",액션아이템!$F18="보류")) -> FALSE | K21: =IF($J21=FALSE(),"",IF(액션아이템!$E18="",99999999,액션아이템!$E18)*100+ROW()/1000) | L21: =IF($K21="","",RANK($K21,$K$6:$K$1005,1))
A22: =IF($B22="","",17) | B22: =IFERROR(INDEX(액션아이템!$C$3:$C$1002,MATCH(17,미완료현황!$L$6:$L$1005,0)),"") | C22: =IF($B22="","",IFERROR(INDEX(액션아이템!$D$3:$D$1002,MATCH(17,미완료현황!$L$6:$L$1005,0)),"")) | D22: =IF($B22="","",IFERROR(INDEX(액션아이템!$B$3:$B$1002,MATCH(17,미완료현황!$L$6:$L$1005,0)),"")) | E22: =IF($B22="","",IFERROR(INDEX(액션아이템!$E$3:$E$1002,MATCH(17,미완료현황!$L$6:$L$1005,0)),"")) | F22: =IF($B22="","",IFERROR(INDEX(액션아이템!$H$3:$H$1002,MATCH(17,미완료현황!$L$6:$L$1005,0)),"")) | G22: =IF($B22="","",IFERROR(INDEX(액션아이템!$F$3:$F$1002,MATCH(17,미완료현황!$L$6:$L$1005,0)),"")) | H22: =IF($B22="","",IFERROR(INDEX(액션아이템!$I$3:$I$1002,MATCH(17,미완료현황!$L$6:$L$1005,0)),"")) | J22: =IF(액션아이템!$C19="",FALSE(),OR(액션아이템!$F19="진행중",액션아이템!$F19="보류")) -> FALSE | K22: =IF($J22=FALSE(),"",IF(액션아이템!$E19="",99999999,액션아이템!$E19)*100+ROW()/1000) | L22: =IF($K22="","",RANK($K22,$K$6:$K$1005,1))
A23: =IF($B23="","",18) | B23: =IFERROR(INDEX(액션아이템!$C$3:$C$1002,MATCH(18,미완료현황!$L$6:$L$1005,0)),"") | C23: =IF($B23="","",IFERROR(INDEX(액션아이템!$D$3:$D$1002,MATCH(18,미완료현황!$L$6:$L$1005,0)),"")) | D23: =IF($B23="","",IFERROR(INDEX(액션아이템!$B$3:$B$1002,MATCH(18,미완료현황!$L$6:$L$1005,0)),"")) | E23: =IF($B23="","",IFERROR(INDEX(액션아이템!$E$3:$E$1002,MATCH(18,미완료현황!$L$6:$L$1005,0)),"")) | F23: =IF($B23="","",IFERROR(INDEX(액션아이템!$H$3:$H$1002,MATCH(18,미완료현황!$L$6:$L$1005,0)),"")) | G23: =IF($B23="","",IFERROR(INDEX(액션아이템!$F$3:$F$1002,MATCH(18,미완료현황!$L$6:$L$1005,0)),"")) | H23: =IF($B23="","",IFERROR(INDEX(액션아이템!$I$3:$I$1002,MATCH(18,미완료현황!$L$6:$L$1005,0)),"")) | J23: =IF(액션아이템!$C20="",FALSE(),OR(액션아이템!$F20="진행중",액션아이템!$F20="보류")) -> FALSE | K23: =IF($J23=FALSE(),"",IF(액션아이템!$E20="",99999999,액션아이템!$E20)*100+ROW()/1000) | L23: =IF($K23="","",RANK($K23,$K$6:$K$1005,1))
A24: =IF($B24="","",19) | B24: =IFERROR(INDEX(액션아이템!$C$3:$C$1002,MATCH(19,미완료현황!$L$6:$L$1005,0)),"") | C24: =IF($B24="","",IFERROR(INDEX(액션아이템!$D$3:$D$1002,MATCH(19,미완료현황!$L$6:$L$1005,0)),"")) | D24: =IF($B24="","",IFERROR(INDEX(액션아이템!$B$3:$B$1002,MATCH(19,미완료현황!$L$6:$L$1005,0)),"")) | E24: =IF($B24="","",IFERROR(INDEX(액션아이템!$E$3:$E$1002,MATCH(19,미완료현황!$L$6:$L$1005,0)),"")) | F24: =IF($B24="","",IFERROR(INDEX(액션아이템!$H$3:$H$1002,MATCH(19,미완료현황!$L$6:$L$1005,0)),"")) | G24: =IF($B24="","",IFERROR(INDEX(액션아이템!$F$3:$F$1002,MATCH(19,미완료현황!$L$6:$L$1005,0)),"")) | H24: =IF($B24="","",IFERROR(INDEX(액션아이템!$I$3:$I$1002,MATCH(19,미완료현황!$L$6:$L$1005,0)),"")) | J24: =IF(액션아이템!$C21="",FALSE(),OR(액션아이템!$F21="진행중",액션아이템!$F21="보류")) -> FALSE | K24: =IF($J24=FALSE(),"",IF(액션아이템!$E21="",99999999,액션아이템!$E21)*100+ROW()/1000) | L24: =IF($K24="","",RANK($K24,$K$6:$K$1005,1))
A25: =IF($B25="","",20) | B25: =IFERROR(INDEX(액션아이템!$C$3:$C$1002,MATCH(20,미완료현황!$L$6:$L$1005,0)),"") | C25: =IF($B25="","",IFERROR(INDEX(액션아이템!$D$3:$D$1002,MATCH(20,미완료현황!$L$6:$L$1005,0)),"")) | D25: =IF($B25="","",IFERROR(INDEX(액션아이템!$B$3:$B$1002,MATCH(20,미완료현황!$L$6:$L$1005,0)),"")) | E25: =IF($B25="","",IFERROR(INDEX(액션아이템!$E$3:$E$1002,MATCH(20,미완료현황!$L$6:$L$1005,0)),"")) | F25: =IF($B25="","",IFERROR(INDEX(액션아이템!$H$3:$H$1002,MATCH(20,미완료현황!$L$6:$L$1005,0)),"")) | G25: =IF($B25="","",IFERROR(INDEX(액션아이템!$F$3:$F$1002,MATCH(20,미완료현황!$L$6:$L$1005,0)),"")) | H25: =IF($B25="","",IFERROR(INDEX(액션아이템!$I$3:$I$1002,MATCH(20,미완료현황!$L$6:$L$1005,0)),"")) | J25: =IF(액션아이템!$C22="",FALSE(),OR(액션아이템!$F22="진행중",액션아이템!$F22="보류")) -> FALSE | K25: =IF($J25=FALSE(),"",IF(액션아이템!$E22="",99999999,액션아이템!$E22)*100+ROW()/1000) | L25: =IF($K25="","",RANK($K25,$K$6:$K$1005,1))
A26: =IF($B26="","",21) | B26: =IFERROR(INDEX(액션아이템!$C$3:$C$1002,MATCH(21,미완료현황!$L$6:$L$1005,0)),"") | C26: =IF($B26="","",IFERROR(INDEX(액션아이템!$D$3:$D$1002,MATCH(21,미완료현황!$L$6:$L$1005,0)),"")) | D26: =IF($B26="","",IFERROR(INDEX(액션아이템!$B$3:$B$1002,MATCH(21,미완료현황!$L$6:$L$1005,0)),"")) | E26: =IF($B26="","",IFERROR(INDEX(액션아이템!$E$3:$E$1002,MATCH(21,미완료현황!$L$6:$L$1005,0)),"")) | F26: =IF($B26="","",IFERROR(INDEX(액션아이템!$H$3:$H$1002,MATCH(21,미완료현황!$L$6:$L$1005,0)),"")) | G26: =IF($B26="","",IFERROR(INDEX(액션아이템!$F$3:$F$1002,MATCH(21,미완료현황!$L$6:$L$1005,0)),"")) | H26: =IF($B26="","",IFERROR(INDEX(액션아이템!$I$3:$I$1002,MATCH(21,미완료현황!$L$6:$L$1005,0)),"")) | J26: =IF(액션아이템!$C23="",FALSE(),OR(액션아이템!$F23="진행중",액션아이템!$F23="보류")) -> FALSE | K26: =IF($J26=FALSE(),"",IF(액션아이템!$E23="",99999999,액션아이템!$E23)*100+ROW()/1000) | L26: =IF($K26="","",RANK($K26,$K$6:$K$1005,1))
A27: =IF($B27="","",22) | B27: =IFERROR(INDEX(액션아이템!$C$3:$C$1002,MATCH(22,미완료현황!$L$6:$L$1005,0)),"") | C27: =IF($B27="","",IFERROR(INDEX(액션아이템!$D$3:$D$1002,MATCH(22,미완료현황!$L$6:$L$1005,0)),"")) | D27: =IF($B27="","",IFERROR(INDEX(액션아이템!$B$3:$B$1002,MATCH(22,미완료현황!$L$6:$L$1005,0)),"")) | E27: =IF($B27="","",IFERROR(INDEX(액션아이템!$E$3:$E$1002,MATCH(22,미완료현황!$L$6:$L$1005,0)),"")) | F27: =IF($B27="","",IFERROR(INDEX(액션아이템!$H$3:$H$1002,MATCH(22,미완료현황!$L$6:$L$1005,0)),"")) | G27: =IF($B27="","",IFERROR(INDEX(액션아이템!$F$3:$F$1002,MATCH(22,미완료현황!$L$6:$L$1005,0)),"")) | H27: =IF($B27="","",IFERROR(INDEX(액션아이템!$I$3:$I$1002,MATCH(22,미완료현황!$L$6:$L$1005,0)),"")) | J27: =IF(액션아이템!$C24="",FALSE(),OR(액션아이템!$F24="진행중",액션아이템!$F24="보류")) -> FALSE | K27: =IF($J27=FALSE(),"",IF(액션아이템!$E24="",99999999,액션아이템!$E24)*100+ROW()/1000) | L27: =IF($K27="","",RANK($K27,$K$6:$K$1005,1))
A28: =IF($B28="","",23) | B28: =IFERROR(INDEX(액션아이템!$C$3:$C$1002,MATCH(23,미완료현황!$L$6:$L$1005,0)),"") | C28: =IF($B28="","",IFERROR(INDEX(액션아이템!$D$3:$D$1002,MATCH(23,미완료현황!$L$6:$L$1005,0)),"")) | D28: =IF($B28="","",IFERROR(INDEX(액션아이템!$B$3:$B$1002,MATCH(23,미완료현황!$L$6:$L$1005,0)),"")) | E28: =IF($B28="","",IFERROR(INDEX(액션아이템!$E$3:$E$1002,MATCH(23,미완료현황!$L$6:$L$1005,0)),"")) | F28: =IF($B28="","",IFERROR(INDEX(액션아이템!$H$3:$H$1002,MATCH(23,미완료현황!$L$6:$L$1005,0)),"")) | G28: =IF($B28="","",IFERROR(INDEX(액션아이템!$F$3:$F$1002,MATCH(23,미완료현황!$L$6:$L$1005,0)),"")) | H28: =IF($B28="","",IFERROR(INDEX(액션아이템!$I$3:$I$1002,MATCH(23,미완료현황!$L$6:$L$1005,0)),"")) | J28: =IF(액션아이템!$C25="",FALSE(),OR(액션아이템!$F25="진행중",액션아이템!$F25="보류")) -> FALSE | K28: =IF($J28=FALSE(),"",IF(액션아이템!$E25="",99999999,액션아이템!$E25)*100+ROW()/1000) | L28: =IF($K28="","",RANK($K28,$K$6:$K$1005,1))
A29: =IF($B29="","",24) | B29: =IFERROR(INDEX(액션아이템!$C$3:$C$1002,MATCH(24,미완료현황!$L$6:$L$1005,0)),"") | C29: =IF($B29="","",IFERROR(INDEX(액션아이템!$D$3:$D$1002,MATCH(24,미완료현황!$L$6:$L$1005,0)),"")) | D29: =IF($B29="","",IFERROR(INDEX(액션아이템!$B$3:$B$1002,MATCH(24,미완료현황!$L$6:$L$1005,0)),"")) | E29: =IF($B29="","",IFERROR(INDEX(액션아이템!$E$3:$E$1002,MATCH(24,미완료현황!$L$6:$L$1005,0)),"")) | F29: =IF($B29="","",IFERROR(INDEX(액션아이템!$H$3:$H$1002,MATCH(24,미완료현황!$L$6:$L$1005,0)),"")) | G29: =IF($B29="","",IFERROR(INDEX(액션아이템!$F$3:$F$1002,MATCH(24,미완료현황!$L$6:$L$1005,0)),"")) | H29: =IF($B29="","",IFERROR(INDEX(액션아이템!$I$3:$I$1002,MATCH(24,미완료현황!$L$6:$L$1005,0)),"")) | J29: =IF(액션아이템!$C26="",FALSE(),OR(액션아이템!$F26="진행중",액션아이템!$F26="보류")) -> FALSE | K29: =IF($J29=FALSE(),"",IF(액션아이템!$E26="",99999999,액션아이템!$E26)*100+ROW()/1000) | L29: =IF($K29="","",RANK($K29,$K$6:$K$1005,1))
A30: =IF($B30="","",25) | B30: =IFERROR(INDEX(액션아이템!$C$3:$C$1002,MATCH(25,미완료현황!$L$6:$L$1005,0)),"") | C30: =IF($B30="","",IFERROR(INDEX(액션아이템!$D$3:$D$1002,MATCH(25,미완료현황!$L$6:$L$1005,0)),"")) | D30: =IF($B30="","",IFERROR(INDEX(액션아이템!$B$3:$B$1002,MATCH(25,미완료현황!$L$6:$L$1005,0)),"")) | E30: =IF($B30="","",IFERROR(INDEX(액션아이템!$E$3:$E$1002,MATCH(25,미완료현황!$L$6:$L$1005,0)),"")) | F30: =IF($B30="","",IFERROR(INDEX(액션아이템!$H$3:$H$1002,MATCH(25,미완료현황!$L$6:$L$1005,0)),"")) | G30: =IF($B30="","",IFERROR(INDEX(액션아이템!$F$3:$F$1002,MATCH(25,미완료현황!$L$6:$L$1005,0)),"")) | H30: =IF($B30="","",IFERROR(INDEX(액션아이템!$I$3:$I$1002,MATCH(25,미완료현황!$L$6:$L$1005,0)),"")) | J30: =IF(액션아이템!$C27="",FALSE(),OR(액션아이템!$F27="진행중",액션아이템!$F27="보류")) -> FALSE | K30: =IF($J30=FALSE(),"",IF(액션아이템!$E27="",99999999,액션아이템!$E27)*100+ROW()/1000) | L30: =IF($K30="","",RANK($K30,$K$6:$K$1005,1))
A31: =IF($B31="","",26) | B31: =IFERROR(INDEX(액션아이템!$C$3:$C$1002,MATCH(26,미완료현황!$L$6:$L$1005,0)),"") | C31: =IF($B31="","",IFERROR(INDEX(액션아이템!$D$3:$D$1002,MATCH(26,미완료현황!$L$6:$L$1005,0)),"")) | D31: =IF($B31="","",IFERROR(INDEX(액션아이템!$B$3:$B$1002,MATCH(26,미완료현황!$L$6:$L$1005,0)),"")) | E31: =IF($B31="","",IFERROR(INDEX(액션아이템!$E$3:$E$1002,MATCH(26,미완료현황!$L$6:$L$1005,0)),"")) | F31: =IF($B31="","",IFERROR(INDEX(액션아이템!$H$3:$H$1002,MATCH(26,미완료현황!$L$6:$L$1005,0)),"")) | G31: =IF($B31="","",IFERROR(INDEX(액션아이템!$F$3:$F$1002,MATCH(26,미완료현황!$L$6:$L$1005,0)),"")) | H31: =IF($B31="","",IFERROR(INDEX(액션아이템!$I$3:$I$1002,MATCH(26,미완료현황!$L$6:$L$1005,0)),"")) | J31: =IF(액션아이템!$C28="",FALSE(),OR(액션아이템!$F28="진행중",액션아이템!$F28="보류")) -> FALSE | K31: =IF($J31=FALSE(),"",IF(액션아이템!$E28="",99999999,액션아이템!$E28)*100+ROW()/1000) | L31: =IF($K31="","",RANK($K31,$K$6:$K$1005,1))
A32: =IF($B32="","",27) | B32: =IFERROR(INDEX(액션아이템!$C$3:$C$1002,MATCH(27,미완료현황!$L$6:$L$1005,0)),"") | C32: =IF($B32="","",IFERROR(INDEX(액션아이템!$D$3:$D$1002,MATCH(27,미완료현황!$L$6:$L$1005,0)),"")) | D32: =IF($B32="","",IFERROR(INDEX(액션아이템!$B$3:$B$1002,MATCH(27,미완료현황!$L$6:$L$1005,0)),"")) | E32: =IF($B32="","",IFERROR(INDEX(액션아이템!$E$3:$E$1002,MATCH(27,미완료현황!$L$6:$L$1005,0)),"")) | F32: =IF($B32="","",IFERROR(INDEX(액션아이템!$H$3:$H$1002,MATCH(27,미완료현황!$L$6:$L$1005,0)),"")) | G32: =IF($B32="","",IFERROR(INDEX(액션아이템!$F$3:$F$1002,MATCH(27,미완료현황!$L$6:$L$1005,0)),"")) | H32: =IF($B32="","",IFERROR(INDEX(액션아이템!$I$3:$I$1002,MATCH(27,미완료현황!$L$6:$L$1005,0)),"")) | J32: =IF(액션아이템!$C29="",FALSE(),OR(액션아이템!$F29="진행중",액션아이템!$F29="보류")) -> FALSE | K32: =IF($J32=FALSE(),"",IF(액션아이템!$E29="",99999999,액션아이템!$E29)*100+ROW()/1000) | L32: =IF($K32="","",RANK($K32,$K$6:$K$1005,1))
A33: =IF($B33="","",28) | B33: =IFERROR(INDEX(액션아이템!$C$3:$C$1002,MATCH(28,미완료현황!$L$6:$L$1005,0)),"") | C33: =IF($B33="","",IFERROR(INDEX(액션아이템!$D$3:$D$1002,MATCH(28,미완료현황!$L$6:$L$1005,0)),"")) | D33: =IF($B33="","",IFERROR(INDEX(액션아이템!$B$3:$B$1002,MATCH(28,미완료현황!$L$6:$L$1005,0)),"")) | E33: =IF($B33="","",IFERROR(INDEX(액션아이템!$E$3:$E$1002,MATCH(28,미완료현황!$L$6:$L$1005,0)),"")) | F33: =IF($B33="","",IFERROR(INDEX(액션아이템!$H$3:$H$1002,MATCH(28,미완료현황!$L$6:$L$1005,0)),"")) | G33: =IF($B33="","",IFERROR(INDEX(액션아이템!$F$3:$F$1002,MATCH(28,미완료현황!$L$6:$L$1005,0)),"")) | H33: =IF($B33="","",IFERROR(INDEX(액션아이템!$I$3:$I$1002,MATCH(28,미완료현황!$L$6:$L$1005,0)),"")) | J33: =IF(액션아이템!$C30="",FALSE(),OR(액션아이템!$F30="진행중",액션아이템!$F30="보류")) -> FALSE | K33: =IF($J33=FALSE(),"",IF(액션아이템!$E30="",99999999,액션아이템!$E30)*100+ROW()/1000) | L33: =IF($K33="","",RANK($K33,$K$6:$K$1005,1))
A34: =IF($B34="","",29) | B34: =IFERROR(INDEX(액션아이템!$C$3:$C$1002,MATCH(29,미완료현황!$L$6:$L$1005,0)),"") | C34: =IF($B34="","",IFERROR(INDEX(액션아이템!$D$3:$D$1002,MATCH(29,미완료현황!$L$6:$L$1005,0)),"")) | D34: =IF($B34="","",IFERROR(INDEX(액션아이템!$B$3:$B$1002,MATCH(29,미완료현황!$L$6:$L$1005,0)),"")) | E34: =IF($B34="","",IFERROR(INDEX(액션아이템!$E$3:$E$1002,MATCH(29,미완료현황!$L$6:$L$1005,0)),"")) | F34: =IF($B34="","",IFERROR(INDEX(액션아이템!$H$3:$H$1002,MATCH(29,미완료현황!$L$6:$L$1005,0)),"")) | G34: =IF($B34="","",IFERROR(INDEX(액션아이템!$F$3:$F$1002,MATCH(29,미완료현황!$L$6:$L$1005,0)),"")) | H34: =IF($B34="","",IFERROR(INDEX(액션아이템!$I$3:$I$1002,MATCH(29,미완료현황!$L$6:$L$1005,0)),"")) | J34: =IF(액션아이템!$C31="",FALSE(),OR(액션아이템!$F31="진행중",액션아이템!$F31="보류")) -> FALSE | K34: =IF($J34=FALSE(),"",IF(액션아이템!$E31="",99999999,액션아이템!$E31)*100+ROW()/1000) | L34: =IF($K34="","",RANK($K34,$K$6:$K$1005,1))
A35: =IF($B35="","",30) | B35: =IFERROR(INDEX(액션아이템!$C$3:$C$1002,MATCH(30,미완료현황!$L$6:$L$1005,0)),"") | C35: =IF($B35="","",IFERROR(INDEX(액션아이템!$D$3:$D$1002,MATCH(30,미완료현황!$L$6:$L$1005,0)),"")) | D35: =IF($B35="","",IFERROR(INDEX(액션아이템!$B$3:$B$1002,MATCH(30,미완료현황!$L$6:$L$1005,0)),"")) | E35: =IF($B35="","",IFERROR(INDEX(액션아이템!$E$3:$E$1002,MATCH(30,미완료현황!$L$6:$L$1005,0)),"")) | F35: =IF($B35="","",IFERROR(INDEX(액션아이템!$H$3:$H$1002,MATCH(30,미완료현황!$L$6:$L$1005,0)),"")) | G35: =IF($B35="","",IFERROR(INDEX(액션아이템!$F$3:$F$1002,MATCH(30,미완료현황!$L$6:$L$1005,0)),"")) | H35: =IF($B35="","",IFERROR(INDEX(액션아이템!$I$3:$I$1002,MATCH(30,미완료현황!$L$6:$L$1005,0)),"")) | J35: =IF(액션아이템!$C32="",FALSE(),OR(액션아이템!$F32="진행중",액션아이템!$F32="보류")) -> FALSE | K35: =IF($J35=FALSE(),"",IF(액션아이템!$E32="",99999999,액션아이템!$E32)*100+ROW()/1000) | L35: =IF($K35="","",RANK($K35,$K$6:$K$1005,1))
A36: =IF($B36="","",31) | B36: =IFERROR(INDEX(액션아이템!$C$3:$C$1002,MATCH(31,미완료현황!$L$6:$L$1005,0)),"") | C36: =IF($B36="","",IFERROR(INDEX(액션아이템!$D$3:$D$1002,MATCH(31,미완료현황!$L$6:$L$1005,0)),"")) | D36: =IF($B36="","",IFERROR(INDEX(액션아이템!$B$3:$B$1002,MATCH(31,미완료현황!$L$6:$L$1005,0)),"")) | E36: =IF($B36="","",IFERROR(INDEX(액션아이템!$E$3:$E$1002,MATCH(31,미완료현황!$L$6:$L$1005,0)),"")) | F36: =IF($B36="","",IFERROR(INDEX(액션아이템!$H$3:$H$1002,MATCH(31,미완료현황!$L$6:$L$1005,0)),"")) | G36: =IF($B36="","",IFERROR(INDEX(액션아이템!$F$3:$F$1002,MATCH(31,미완료현황!$L$6:$L$1005,0)),"")) | H36: =IF($B36="","",IFERROR(INDEX(액션아이템!$I$3:$I$1002,MATCH(31,미완료현황!$L$6:$L$1005,0)),"")) | J36: =IF(액션아이템!$C33="",FALSE(),OR(액션아이템!$F33="진행중",액션아이템!$F33="보류")) -> FALSE | K36: =IF($J36=FALSE(),"",IF(액션아이템!$E33="",99999999,액션아이템!$E33)*100+ROW()/1000) | L36: =IF($K36="","",RANK($K36,$K$6:$K$1005,1))
A37: =IF($B37="","",32) | B37: =IFERROR(INDEX(액션아이템!$C$3:$C$1002,MATCH(32,미완료현황!$L$6:$L$1005,0)),"") | C37: =IF($B37="","",IFERROR(INDEX(액션아이템!$D$3:$D$1002,MATCH(32,미완료현황!$L$6:$L$1005,0)),"")) | D37: =IF($B37="","",IFERROR(INDEX(액션아이템!$B$3:$B$1002,MATCH(32,미완료현황!$L$6:$L$1005,0)),"")) | E37: =IF($B37="","",IFERROR(INDEX(액션아이템!$E$3:$E$1002,MATCH(32,미완료현황!$L$6:$L$1005,0)),"")) | F37: =IF($B37="","",IFERROR(INDEX(액션아이템!$H$3:$H$1002,MATCH(32,미완료현황!$L$6:$L$1005,0)),"")) | G37: =IF($B37="","",IFERROR(INDEX(액션아이템!$F$3:$F$1002,MATCH(32,미완료현황!$L$6:$L$1005,0)),"")) | H37: =IF($B37="","",IFERROR(INDEX(액션아이템!$I$3:$I$1002,MATCH(32,미완료현황!$L$6:$L$1005,0)),"")) | J37: =IF(액션아이템!$C34="",FALSE(),OR(액션아이템!$F34="진행중",액션아이템!$F34="보류")) -> FALSE | K37: =IF($J37=FALSE(),"",IF(액션아이템!$E34="",99999999,액션아이템!$E34)*100+ROW()/1000) | L37: =IF($K37="","",RANK($K37,$K$6:$K$1005,1))
A38: =IF($B38="","",33) | B38: =IFERROR(INDEX(액션아이템!$C$3:$C$1002,MATCH(33,미완료현황!$L$6:$L$1005,0)),"") | C38: =IF($B38="","",IFERROR(INDEX(액션아이템!$D$3:$D$1002,MATCH(33,미완료현황!$L$6:$L$1005,0)),"")) | D38: =IF($B38="","",IFERROR(INDEX(액션아이템!$B$3:$B$1002,MATCH(33,미완료현황!$L$6:$L$1005,0)),"")) | E38: =IF($B38="","",IFERROR(INDEX(액션아이템!$E$3:$E$1002,MATCH(33,미완료현황!$L$6:$L$1005,0)),"")) | F38: =IF($B38="","",IFERROR(INDEX(액션아이템!$H$3:$H$1002,MATCH(33,미완료현황!$L$6:$L$1005,0)),"")) | G38: =IF($B38="","",IFERROR(INDEX(액션아이템!$F$3:$F$1002,MATCH(33,미완료현황!$L$6:$L$1005,0)),"")) | H38: =IF($B38="","",IFERROR(INDEX(액션아이템!$I$3:$I$1002,MATCH(33,미완료현황!$L$6:$L$1005,0)),"")) | J38: =IF(액션아이템!$C35="",FALSE(),OR(액션아이템!$F35="진행중",액션아이템!$F35="보류")) -> FALSE | K38: =IF($J38=FALSE(),"",IF(액션아이템!$E35="",99999999,액션아이템!$E35)*100+ROW()/1000) | L38: =IF($K38="","",RANK($K38,$K$6:$K$1005,1))
A39: =IF($B39="","",34) | B39: =IFERROR(INDEX(액션아이템!$C$3:$C$1002,MATCH(34,미완료현황!$L$6:$L$1005,0)),"") | C39: =IF($B39="","",IFERROR(INDEX(액션아이템!$D$3:$D$1002,MATCH(34,미완료현황!$L$6:$L$1005,0)),"")) | D39: =IF($B39="","",IFERROR(INDEX(액션아이템!$B$3:$B$1002,MATCH(34,미완료현황!$L$6:$L$1005,0)),"")) | E39: =IF($B39="","",IFERROR(INDEX(액션아이템!$E$3:$E$1002,MATCH(34,미완료현황!$L$6:$L$1005,0)),"")) | F39: =IF($B39="","",IFERROR(INDEX(액션아이템!$H$3:$H$1002,MATCH(34,미완료현황!$L$6:$L$1005,0)),"")) | G39: =IF($B39="","",IFERROR(INDEX(액션아이템!$F$3:$F$1002,MATCH(34,미완료현황!$L$6:$L$1005,0)),"")) | H39: =IF($B39="","",IFERROR(INDEX(액션아이템!$I$3:$I$1002,MATCH(34,미완료현황!$L$6:$L$1005,0)),"")) | J39: =IF(액션아이템!$C36="",FALSE(),OR(액션아이템!$F36="진행중",액션아이템!$F36="보류")) -> FALSE | K39: =IF($J39=FALSE(),"",IF(액션아이템!$E36="",99999999,액션아이템!$E36)*100+ROW()/1000) | L39: =IF($K39="","",RANK($K39,$K$6:$K$1005,1))
A40: =IF($B40="","",35) | B40: =IFERROR(INDEX(액션아이템!$C$3:$C$1002,MATCH(35,미완료현황!$L$6:$L$1005,0)),"") | C40: =IF($B40="","",IFERROR(INDEX(액션아이템!$D$3:$D$1002,MATCH(35,미완료현황!$L$6:$L$1005,0)),"")) | D40: =IF($B40="","",IFERROR(INDEX(액션아이템!$B$3:$B$1002,MATCH(35,미완료현황!$L$6:$L$1005,0)),"")) | E40: =IF($B40="","",IFERROR(INDEX(액션아이템!$E$3:$E$1002,MATCH(35,미완료현황!$L$6:$L$1005,0)),"")) | F40: =IF($B40="","",IFERROR(INDEX(액션아이템!$H$3:$H$1002,MATCH(35,미완료현황!$L$6:$L$1005,0)),"")) | G40: =IF($B40="","",IFERROR(INDEX(액션아이템!$F$3:$F$1002,MATCH(35,미완료현황!$L$6:$L$1005,0)),"")) | H40: =IF($B40="","",IFERROR(INDEX(액션아이템!$I$3:$I$1002,MATCH(35,미완료현황!$L$6:$L$1005,0)),"")) | J40: =IF(액션아이템!$C37="",FALSE(),OR(액션아이템!$F37="진행중",액션아이템!$F37="보류")) -> FALSE | K40: =IF($J40=FALSE(),"",IF(액션아이템!$E37="",99999999,액션아이템!$E37)*100+ROW()/1000) | L40: =IF($K40="","",RANK($K40,$K$6:$K$1005,1))
A41: =IF($B41="","",36) | B41: =IFERROR(INDEX(액션아이템!$C$3:$C$1002,MATCH(36,미완료현황!$L$6:$L$1005,0)),"") | C41: =IF($B41="","",IFERROR(INDEX(액션아이템!$D$3:$D$1002,MATCH(36,미완료현황!$L$6:$L$1005,0)),"")) | D41: =IF($B41="","",IFERROR(INDEX(액션아이템!$B$3:$B$1002,MATCH(36,미완료현황!$L$6:$L$1005,0)),"")) | E41: =IF($B41="","",IFERROR(INDEX(액션아이템!$E$3:$E$1002,MATCH(36,미완료현황!$L$6:$L$1005,0)),"")) | F41: =IF($B41="","",IFERROR(INDEX(액션아이템!$H$3:$H$1002,MATCH(36,미완료현황!$L$6:$L$1005,0)),"")) | G41: =IF($B41="","",IFERROR(INDEX(액션아이템!$F$3:$F$1002,MATCH(36,미완료현황!$L$6:$L$1005,0)),"")) | H41: =IF($B41="","",IFERROR(INDEX(액션아이템!$I$3:$I$1002,MATCH(36,미완료현황!$L$6:$L$1005,0)),"")) | J41: =IF(액션아이템!$C38="",FALSE(),OR(액션아이템!$F38="진행중",액션아이템!$F38="보류")) -> FALSE | K41: =IF($J41=FALSE(),"",IF(액션아이템!$E38="",99999999,액션아이템!$E38)*100+ROW()/1000) | L41: =IF($K41="","",RANK($K41,$K$6:$K$1005,1))
A42: =IF($B42="","",37) | B42: =IFERROR(INDEX(액션아이템!$C$3:$C$1002,MATCH(37,미완료현황!$L$6:$L$1005,0)),"") | C42: =IF($B42="","",IFERROR(INDEX(액션아이템!$D$3:$D$1002,MATCH(37,미완료현황!$L$6:$L$1005,0)),"")) | D42: =IF($B42="","",IFERROR(INDEX(액션아이템!$B$3:$B$1002,MATCH(37,미완료현황!$L$6:$L$1005,0)),"")) | E42: =IF($B42="","",IFERROR(INDEX(액션아이템!$E$3:$E$1002,MATCH(37,미완료현황!$L$6:$L$1005,0)),"")) | F42: =IF($B42="","",IFERROR(INDEX(액션아이템!$H$3:$H$1002,MATCH(37,미완료현황!$L$6:$L$1005,0)),"")) | G42: =IF($B42="","",IFERROR(INDEX(액션아이템!$F$3:$F$1002,MATCH(37,미완료현황!$L$6:$L$1005,0)),"")) | H42: =IF($B42="","",IFERROR(INDEX(액션아이템!$I$3:$I$1002,MATCH(37,미완료현황!$L$6:$L$1005,0)),"")) | J42: =IF(액션아이템!$C39="",FALSE(),OR(액션아이템!$F39="진행중",액션아이템!$F39="보류")) -> FALSE | K42: =IF($J42=FALSE(),"",IF(액션아이템!$E39="",99999999,액션아이템!$E39)*100+ROW()/1000) | L42: =IF($K42="","",RANK($K42,$K$6:$K$1005,1))
...

Sheet 담당자별현황
A1: 담당자별현황
A3: 담당자 | B3: 소속 | C3: 전체 | D3: 진행중 | E3: 완료 | F3: 기한 초과 | G3: 완료율
A4: =IF(구성원목록!$A3="","",구성원목록!$A3) -> 김팀장 | B4: =IF($A4="","",구성원목록!$B3) -> 기획팀 | C4: =IF($A4="","",COUNTIFS(액션아이템!$D$3:$D$1002,$A4)) -> 1 | D4: =IF($A4="","",COUNTIFS(액션아이템!$D$3:$D$1002,$A4,액션아이템!$F$3:$F$1002,"진행중")) -> 1 | E4: =IF($A4="","",COUNTIFS(액션아이템!$D$3:$D$1002,$A4,액션아이템!$F$3:$F$1002,"완료")) -> 0 | F4: =IF($A4="","",COUNTIFS(액션아이템!$D$3:$D$1002,$A4,액션아이템!$H$3:$H$1002,"<0")) -> 1 | G4: =IF($A4="","",IF($C4=0,"",$E4/$C4)) -> 0
A5: =IF(구성원목록!$A4="","",구성원목록!$A4) -> 이대리 | B5: =IF($A5="","",구성원목록!$B4) -> 개발팀 | C5: =IF($A5="","",COUNTIFS(액션아이템!$D$3:$D$1002,$A5)) -> 1 | D5: =IF($A5="","",COUNTIFS(액션아이템!$D$3:$D$1002,$A5,액션아이템!$F$3:$F$1002,"진행중")) -> 1 | E5: =IF($A5="","",COUNTIFS(액션아이템!$D$3:$D$1002,$A5,액션아이템!$F$3:$F$1002,"완료")) -> 0 | F5: =IF($A5="","",COUNTIFS(액션아이템!$D$3:$D$1002,$A5,액션아이템!$H$3:$H$1002,"<0")) -> 0 | G5: =IF($A5="","",IF($C5=0,"",$E5/$C5)) -> 0
A6: =IF(구성원목록!$A5="","",구성원목록!$A5) -> 박주임 | B6: =IF($A6="","",구성원목록!$B5) -> 디자인팀 | C6: =IF($A6="","",COUNTIFS(액션아이템!$D$3:$D$1002,$A6)) -> 2 | D6: =IF($A6="","",COUNTIFS(액션아이템!$D$3:$D$1002,$A6,액션아이템!$F$3:$F$1002,"진행중")) -> 1 | E6: =IF($A6="","",COUNTIFS(액션아이템!$D$3:$D$1002,$A6,액션아이템!$F$3:$F$1002,"완료")) -> 1 | F6: =IF($A6="","",COUNTIFS(액션아이템!$D$3:$D$1002,$A6,액션아이템!$H$3:$H$1002,"<0")) -> 0 | G6: =IF($A6="","",IF($C6=0,"",$E6/$C6)) -> 0.5
A7: =IF(구성원목록!$A6="","",구성원목록!$A6) | B7: =IF($A7="","",구성원목록!$B6) | C7: =IF($A7="","",COUNTIFS(액션아이템!$D$3:$D$1002,$A7)) | D7: =IF($A7="","",COUNTIFS(액션아이템!$D$3:$D$1002,$A7,액션아이템!$F$3:$F$1002,"진행중")) | E7: =IF($A7="","",COUNTIFS(액션아이템!$D$3:$D$1002,$A7,액션아이템!$F$3:$F$1002,"완료")) | F7: =IF($A7="","",COUNTIFS(액션아이템!$D$3:$D$1002,$A7,액션아이템!$H$3:$H$1002,"<0")) | G7: =IF($A7="","",IF($C7=0,"",$E7/$C7))
A8: =IF(구성원목록!$A7="","",구성원목록!$A7) | B8: =IF($A8="","",구성원목록!$B7) | C8: =IF($A8="","",COUNTIFS(액션아이템!$D$3:$D$1002,$A8)) | D8: =IF($A8="","",COUNTIFS(액션아이템!$D$3:$D$1002,$A8,액션아이템!$F$3:$F$1002,"진행중")) | E8: =IF($A8="","",COUNTIFS(액션아이템!$D$3:$D$1002,$A8,액션아이템!$F$3:$F$1002,"완료")) | F8: =IF($A8="","",COUNTIFS(액션아이템!$D$3:$D$1002,$A8,액션아이템!$H$3:$H$1002,"<0")) | G8: =IF($A8="","",IF($C8=0,"",$E8/$C8))
A9: =IF(구성원목록!$A8="","",구성원목록!$A8) | B9: =IF($A9="","",구성원목록!$B8) | C9: =IF($A9="","",COUNTIFS(액션아이템!$D$3:$D$1002,$A9)) | D9: =IF($A9="","",COUNTIFS(액션아이템!$D$3:$D$1002,$A9,액션아이템!$F$3:$F$1002,"진행중")) | E9: =IF($A9="","",COUNTIFS(액션아이템!$D$3:$D$1002,$A9,액션아이템!$F$3:$F$1002,"완료")) | F9: =IF($A9="","",COUNTIFS(액션아이템!$D$3:$D$1002,$A9,액션아이템!$H$3:$H$1002,"<0")) | G9: =IF($A9="","",IF($C9=0,"",$E9/$C9))
A10: =IF(구성원목록!$A9="","",구성원목록!$A9) | B10: =IF($A10="","",구성원목록!$B9) | C10: =IF($A10="","",COUNTIFS(액션아이템!$D$3:$D$1002,$A10)) | D10: =IF($A10="","",COUNTIFS(액션아이템!$D$3:$D$1002,$A10,액션아이템!$F$3:$F$1002,"진행중")) | E10: =IF($A10="","",COUNTIFS(액션아이템!$D$3:$D$1002,$A10,액션아이템!$F$3:$F$1002,"완료")) | F10: =IF($A10="","",COUNTIFS(액션아이템!$D$3:$D$1002,$A10,액션아이템!$H$3:$H$1002,"<0")) | G10: =IF($A10="","",IF($C10=0,"",$E10/$C10))
A11: =IF(구성원목록!$A10="","",구성원목록!$A10) | B11: =IF($A11="","",구성원목록!$B10) | C11: =IF($A11="","",COUNTIFS(액션아이템!$D$3:$D$1002,$A11)) | D11: =IF($A11="","",COUNTIFS(액션아이템!$D$3:$D$1002,$A11,액션아이템!$F$3:$F$1002,"진행중")) | E11: =IF($A11="","",COUNTIFS(액션아이템!$D$3:$D$1002,$A11,액션아이템!$F$3:$F$1002,"완료")) | F11: =IF($A11="","",COUNTIFS(액션아이템!$D$3:$D$1002,$A11,액션아이템!$H$3:$H$1002,"<0")) | G11: =IF($A11="","",IF($C11=0,"",$E11/$C11))
A12: =IF(구성원목록!$A11="","",구성원목록!$A11) | B12: =IF($A12="","",구성원목록!$B11) | C12: =IF($A12="","",COUNTIFS(액션아이템!$D$3:$D$1002,$A12)) | D12: =IF($A12="","",COUNTIFS(액션아이템!$D$3:$D$1002,$A12,액션아이템!$F$3:$F$1002,"진행중")) | E12: =IF($A12="","",COUNTIFS(액션아이템!$D$3:$D$1002,$A12,액션아이템!$F$3:$F$1002,"완료")) | F12: =IF($A12="","",COUNTIFS(액션아이템!$D$3:$D$1002,$A12,액션아이템!$H$3:$H$1002,"<0")) | G12: =IF($A12="","",IF($C12=0,"",$E12/$C12))
A13: =IF(구성원목록!$A12="","",구성원목록!$A12) | B13: =IF($A13="","",구성원목록!$B12) | C13: =IF($A13="","",COUNTIFS(액션아이템!$D$3:$D$1002,$A13)) | D13: =IF($A13="","",COUNTIFS(액션아이템!$D$3:$D$1002,$A13,액션아이템!$F$3:$F$1002,"진행중")) | E13: =IF($A13="","",COUNTIFS(액션아이템!$D$3:$D$1002,$A13,액션아이템!$F$3:$F$1002,"완료")) | F13: =IF($A13="","",COUNTIFS(액션아이템!$D$3:$D$1002,$A13,액션아이템!$H$3:$H$1002,"<0")) | G13: =IF($A13="","",IF($C13=0,"",$E13/$C13))
A14: =IF(구성원목록!$A13="","",구성원목록!$A13) | B14: =IF($A14="","",구성원목록!$B13) | C14: =IF($A14="","",COUNTIFS(액션아이템!$D$3:$D$1002,$A14)) | D14: =IF($A14="","",COUNTIFS(액션아이템!$D$3:$D$1002,$A14,액션아이템!$F$3:$F$1002,"진행중")) | E14: =IF($A14="","",COUNTIFS(액션아이템!$D$3:$D$1002,$A14,액션아이템!$F$3:$F$1002,"완료")) | F14: =IF($A14="","",COUNTIFS(액션아이템!$D$3:$D$1002,$A14,액션아이템!$H$3:$H$1002,"<0")) | G14: =IF($A14="","",IF($C14=0,"",$E14/$C14))
A15: =IF(구성원목록!$A14="","",구성원목록!$A14) | B15: =IF($A15="","",구성원목록!$B14) | C15: =IF($A15="","",COUNTIFS(액션아이템!$D$3:$D$1002,$A15)) | D15: =IF($A15="","",COUNTIFS(액션아이템!$D$3:$D$1002,$A15,액션아이템!$F$3:$F$1002,"진행중")) | E15: =IF($A15="","",COUNTIFS(액션아이템!$D$3:$D$1002,$A15,액션아이템!$F$3:$F$1002,"완료")) | F15: =IF($A15="","",COUNTIFS(액션아이템!$D$3:$D$1002,$A15,액션아이템!$H$3:$H$1002,"<0")) | G15: =IF($A15="","",IF($C15=0,"",$E15/$C15))
... A203: =IF(구성원목록!$A202="","",구성원목록!$A202) | B203: =IF($A203="","",구성원목록!$B202) | C203: =IF($A203="","",COUNTIFS(액션아이템!$D$3:$D$1002,$A203)) | D203: =IF($A203="","",COUNTIFS(액션아이템!$D$3:$D$1002,$A203,액션아이템!$F$3:$F$1002,"진행중")) | E203: =IF($A203="","",COUNTIFS(액션아이템!$D$3:$D$1002,$A203,액션아이템!$F$3:$F$1002,"완료")) | F203: =IF($A203="","",COUNTIFS(액션아이템!$D$3:$D$1002,$A203,액션아이템!$H$3:$H$1002,"<0")) | G203: =IF($A203="","",IF($C203=0,"",$E203/$C203))
B205: 합계 | C205: =SUM(C4:C203) -> 4 | D205: =SUM(D4:D203) -> 3 | E205: =SUM(E4:E203) -> 1 | F205: =SUM(F4:F203) -> 1

Sheet 회의록_출력
B2: 회 의 록
B4: 회의번호 | C4: 260901-1 | D4: ← 이 칸만 바꾸세요
B6: 회 의 명 | C6: =IFERROR(INDEX(회의록!$C$3:$C$302,MATCH($C$4,회의록!$A$3:$A$302,0)),"") -> 9월 정기회의
B7: 일 시 | C7: =IFERROR(INDEX(회의록!$B$3:$B$302,MATCH($C$4,회의록!$A$3:$A$302,0)),"") -> 46266
B8: 장 소 | C8: =IFERROR(INDEX(회의록!$D$3:$D$302,MATCH($C$4,회의록!$A$3:$A$302,0)),"") -> 대회의실
B9: 주 관 자 | C9: =IFERROR(INDEX(회의록!$E$3:$E$302,MATCH($C$4,회의록!$A$3:$A$302,0)),"") -> 김팀장
B10: 참 석 자 | C10: =IFERROR(INDEX(회의록!$F$3:$F$302,MATCH($C$4,회의록!$A$3:$A$302,0)),"") -> 김팀장, 이대리, 박주임
B11: 안 건 | C11: =IFERROR(INDEX(회의록!$G$3:$G$302,MATCH($C$4,회의록!$A$3:$A$302,0)),"") -> 3분기 실적 / 4분기 계획
B12: 논의·결정사항 | C12: =IFERROR(INDEX(회의록!$H$3:$H$302,MATCH($C$4,회의록!$A$3:$A$302,0)),"") -> 3분기 목표 달성. 4분기 신규 기능 2건 추가 결정.
B17: 할 일 (액션아이템)
B18: No | C18: 할 일 | D18: 담당자 | E18: 기한 | F18: 상태
B19: 1 | C19: =IFERROR(INDEX(액션아이템!$C$3:$C$1002,MATCH($C$4&"|"&1,액션아이템!$K$3:$K$1002,0)),"") -> 4분기 기능 명세 작성 | D19: =IF($C19="","",IFERROR(INDEX(액션아이템!$D$3:$D$1002,MATCH($C$4&"|"&1,액션아이템!$K$3:$K$1002,0)),"")) -> 이대리 | E19: =IF($C19="","",IFERROR(INDEX(액션아이템!$E$3:$E$1002,MATCH($C$4&"|"&1,액션아이템!$K$3:$K$1002,0)),"")) -> 46285 | F19: =IF($C19="","",IFERROR(INDEX(액션아이템!$F$3:$F$1002,MATCH($C$4&"|"&1,액션아이템!$K$3:$K$1002,0)),"")) -> 진행중
B20: 2 | C20: =IFERROR(INDEX(액션아이템!$C$3:$C$1002,MATCH($C$4&"|"&2,액션아이템!$K$3:$K$1002,0)),"") -> 예산안 재검토 | D20: =IF($C20="","",IFERROR(INDEX(액션아이템!$D$3:$D$1002,MATCH($C$4&"|"&2,액션아이템!$K$3:$K$1002,0)),"")) -> 김팀장 | E20: =IF($C20="","",IFERROR(INDEX(액션아이템!$E$3:$E$1002,MATCH($C$4&"|"&2,액션아이템!$K$3:$K$1002,0)),"")) -> 46275 | F20: =IF($C20="","",IFERROR(INDEX(액션아이템!$F$3:$F$1002,MATCH($C$4&"|"&2,액션아이템!$K$3:$K$1002,0)),"")) -> 진행중
B21: 3 | C21: =IFERROR(INDEX(액션아이템!$C$3:$C$1002,MATCH($C$4&"|"&3,액션아이템!$K$3:$K$1002,0)),"") -> 실적 자료 정리 | D21: =IF($C21="","",IFERROR(INDEX(액션아이템!$D$3:$D$1002,MATCH($C$4&"|"&3,액션아이템!$K$3:$K$1002,0)),"")) -> 박주임 | E21: =IF($C21="","",IFERROR(INDEX(액션아이템!$E$3:$E$1002,MATCH($C$4&"|"&3,액션아이템!$K$3:$K$1002,0)),"")) -> 46270 | F21: =IF($C21="","",IFERROR(INDEX(액션아이템!$F$3:$F$1002,MATCH($C$4&"|"&3,액션아이템!$K$3:$K$1002,0)),"")) -> 완료
B22: 4 | C22: =IFERROR(INDEX(액션아이템!$C$3:$C$1002,MATCH($C$4&"|"&4,액션아이템!$K$3:$K$1002,0)),"") | D22: =IF($C22="","",IFERROR(INDEX(액션아이템!$D$3:$D$1002,MATCH($C$4&"|"&4,액션아이템!$K$3:$K$1002,0)),"")) | E22: =IF($C22="","",IFERROR(INDEX(액션아이템!$E$3:$E$1002,MATCH($C$4&"|"&4,액션아이템!$K$3:$K$1002,0)),"")) | F22: =IF($C22="","",IFERROR(INDEX(액션아이템!$F$3:$F$1002,MATCH($C$4&"|"&4,액션아이템!$K$3:$K$1002,0)),""))
B23: 5 | C23: =IFERROR(INDEX(액션아이템!$C$3:$C$1002,MATCH($C$4&"|"&5,액션아이템!$K$3:$K$1002,0)),"") | D23: =IF($C23="","",IFERROR(INDEX(액션아이템!$D$3:$D$1002,MATCH($C$4&"|"&5,액션아이템!$K$3:$K$1002,0)),"")) | E23: =IF($C23="","",IFERROR(INDEX(액션아이템!$E$3:$E$1002,MATCH($C$4&"|"&5,액션아이템!$K$3:$K$1002,0)),"")) | F23: =IF($C23="","",IFERROR(INDEX(액션아이템!$F$3:$F$1002,MATCH($C$4&"|"&5,액션아이템!$K$3:$K$1002,0)),""))
B24: 6 | C24: =IFERROR(INDEX(액션아이템!$C$3:$C$1002,MATCH($C$4&"|"&6,액션아이템!$K$3:$K$1002,0)),"") | D24: =IF($C24="","",IFERROR(INDEX(액션아이템!$D$3:$D$1002,MATCH($C$4&"|"&6,액션아이템!$K$3:$K$1002,0)),"")) | E24: =IF($C24="","",IFERROR(INDEX(액션아이템!$E$3:$E$1002,MATCH($C$4&"|"&6,액션아이템!$K$3:$K$1002,0)),"")) | F24: =IF($C24="","",IFERROR(INDEX(액션아이템!$F$3:$F$1002,MATCH($C$4&"|"&6,액션아이템!$K$3:$K$1002,0)),""))
B25: 7 | C25: =IFERROR(INDEX(액션아이템!$C$3:$C$1002,MATCH($C$4&"|"&7,액션아이템!$K$3:$K$1002,0)),"") | D25: =IF($C25="","",IFERROR(INDEX(액션아이템!$D$3:$D$1002,MATCH($C$4&"|"&7,액션아이템!$K$3:$K$1002,0)),"")) | E25: =IF($C25="","",IFERROR(INDEX(액션아이템!$E$3:$E$1002,MATCH($C$4&"|"&7,액션아이템!$K$3:$K$1002,0)),"")) | F25: =IF($C25="","",IFERROR(INDEX(액션아이템!$F$3:$F$1002,MATCH($C$4&"|"&7,액션아이템!$K$3:$K$1002,0)),""))
B26: 8 | C26: =IFERROR(INDEX(액션아이템!$C$3:$C$1002,MATCH($C$4&"|"&8,액션아이템!$K$3:$K$1002,0)),"") | D26: =IF($C26="","",IFERROR(INDEX(액션아이템!$D$3:$D$1002,MATCH($C$4&"|"&8,액션아이템!$K$3:$K$1002,0)),"")) | E26: =IF($C26="","",IFERROR(INDEX(액션아이템!$E$3:$E$1002,MATCH($C$4&"|"&8,액션아이템!$K$3:$K$1002,0)),"")) | F26: =IF($C26="","",IFERROR(INDEX(액션아이템!$F$3:$F$1002,MATCH($C$4&"|"&8,액션아이템!$K$3:$K$1002,0)),""))
B27: 9 | C27: =IFERROR(INDEX(액션아이템!$C$3:$C$1002,MATCH($C$4&"|"&9,액션아이템!$K$3:$K$1002,0)),"") | D27: =IF($C27="","",IFERROR(INDEX(액션아이템!$D$3:$D$1002,MATCH($C$4&"|"&9,액션아이템!$K$3:$K$1002,0)),"")) | E27: =IF($C27="","",IFERROR(INDEX(액션아이템!$E$3:$E$1002,MATCH($C$4&"|"&9,액션아이템!$K$3:$K$1002,0)),"")) | F27: =IF($C27="","",IFERROR(INDEX(액션아이템!$F$3:$F$1002,MATCH($C$4&"|"&9,액션아이템!$K$3:$K$1002,0)),""))
B28: 10 | C28: =IFERROR(INDEX(액션아이템!$C$3:$C$1002,MATCH($C$4&"|"&10,액션아이템!$K$3:$K$1002,0)),"") | D28: =IF($C28="","",IFERROR(INDEX(액션아이템!$D$3:$D$1002,MATCH($C$4&"|"&10,액션아이템!$K$3:$K$1002,0)),"")) | E28: =IF($C28="","",IFERROR(INDEX(액션아이템!$E$3:$E$1002,MATCH($C$4&"|"&10,액션아이템!$K$3:$K$1002,0)),"")) | F28: =IF($C28="","",IFERROR(INDEX(액션아이템!$F$3:$F$1002,MATCH($C$4&"|"&10,액션아이템!$K$3:$K$1002,0)),""))
B29: 11 | C29: =IFERROR(INDEX(액션아이템!$C$3:$C$1002,MATCH($C$4&"|"&11,액션아이템!$K$3:$K$1002,0)),"") | D29: =IF($C29="","",IFERROR(INDEX(액션아이템!$D$3:$D$1002,MATCH($C$4&"|"&11,액션아이템!$K$3:$K$1002,0)),"")) | E29: =IF($C29="","",IFERROR(INDEX(액션아이템!$E$3:$E$1002,MATCH($C$4&"|"&11,액션아이템!$K$3:$K$1002,0)),"")) | F29: =IF($C29="","",IFERROR(INDEX(액션아이템!$F$3:$F$1002,MATCH($C$4&"|"&11,액션아이템!$K$3:$K$1002,0)),""))
B30: 12 | C30: =IFERROR(INDEX(액션아이템!$C$3:$C$1002,MATCH($C$4&"|"&12,액션아이템!$K$3:$K$1002,0)),"") | D30: =IF($C30="","",IFERROR(INDEX(액션아이템!$D$3:$D$1002,MATCH($C$4&"|"&12,액션아이템!$K$3:$K$1002,0)),"")) | E30: =IF($C30="","",IFERROR(INDEX(액션아이템!$E$3:$E$1002,MATCH($C$4&"|"&12,액션아이템!$K$3:$K$1002,0)),"")) | F30: =IF($C30="","",IFERROR(INDEX(액션아이템!$F$3:$F$1002,MATCH($C$4&"|"&12,액션아이템!$K$3:$K$1002,0)),""))
B32: ※ 한 회의의 할 일이 12개를 넘으면 표시되지 않습니다.
