Workbook

Sheet 사용안내
B2: 재고관리 (입출고 · 안전재고 · 월간재고)
B4: 핵심 | C4: 입고·출고를 [입출고내역] 한 곳에만 입력합니다. 재고현황·월간재고가 전부 자동으로 따라옵니다.
B5: 입력 규칙 | C5: 파란색 글씨 칸만 입력하세요. 검은색은 자동 계산입니다.
B6: ① 품목마스터 | C6: 품번·품목명·초기재고·안전재고를 등록합니다. 여기 적은 순서가 모든 표의 순서가 됩니다.
B7: ② 입출고내역 | C7: 입고든 출고든 여기 한 줄씩. 입력 즉시 그 시점의 재고가 옆에 표시됩니다.
C8: 이전 재고에서 자동으로 더하고 빼므로 따로 계산할 필요가 없습니다.
B9: ③ 품목검색 | C9: 품목이 많아 찾기 힘들 때 씁니다. 이름 일부만 넣으면 걸리는 품목이 나옵니다.
B10: ④ 재고현황 | C10: 품목별 현재고와 안전재고 대비 충족률이 막대로 표시됩니다.
B11: ⑤ 월간재고 | C11: 월별 입고·출고·월말재고입니다. 품목마스터에 적은 순서 그대로 나옵니다.
B12: 안전재고란 | C12: 이 수량 밑으로 떨어지면 안 되는 최소 재고입니다. 미달하면 빨간색으로 표시됩니다.
B13: 재고 계산 방식 | C13: 초기재고 + 누적 입고 − 누적 출고
B15: ※ 실사 재고와 차이가 나면 [입출고내역]에 구분을 '조정'으로 넣고 수량에 차이만큼 기록하세요.
B16: ※ 이 파일은 1,000건까지 처리하도록 만들어졌습니다.

Sheet 품목마스터
A1: 품목마스터 (여기 적은 순서가 모든 표의 순서가 됩니다)
A2: 품번 | B2: 품목명 | C2: 규격 | D2: 단위 | E2: 분류 | F2: 초기재고 | G2: 안전재고 | H2: 비고
A3: A001 | B3: 육각볼트 M10 | C3: SUS304 L30 | D3: EA | E3: 체결부품 | F3: 500 | G3: 100
A4: A002 | B4: 평와셔 M10 | C4: SUS304 | D4: EA | E4: 체결부품 | F4: 800 | G4: 200
A5: B001 | B5: 베어링 6204 | C5: 내경20 | D5: EA | E5: 구동부품 | F5: 40 | G5: 10
A6: C001 | B6: 절삭유 | C6: 20L | D6: 통 | E6: 소모품 | F6: 12 | G6: 4

Sheet 입출고내역
A1: 입출고내역 (입고·출고·조정을 여기 한 곳에만 입력)
A2: 일자 | B2: 구분 | C2: 품번 | D2: 품목명(자동) | E2: 규격(자동) | F2: 단위(자동) | G2: 수량 | H2: 단가 | I2: 금액(자동) | J2: 거래처 | K2: 비고 | L2: 증감(자동) | M2: 이동후재고(자동)
D3: =IF($C3="","",IFERROR(INDEX(품목마스터!$B$3:$B$302,MATCH($C3,품목마스터!$A$3:$A$302,0)),"미등록품번")) | E3: =IF($C3="","",IFERROR(INDEX(품목마스터!$C$3:$C$302,MATCH($C3,품목마스터!$A$3:$A$302,0)),"")) | F3: =IF($C3="","",IFERROR(INDEX(품목마스터!$D$3:$D$302,MATCH($C3,품목마스터!$A$3:$A$302,0)),"")) | I3: =IF(OR($G3="",$H3=""),"",ROUND($G3*$H3,0)) | L3: =IF(OR($C3="",$G3=""),"",IF($B3="입고",$G3,IF($B3="출고",-$G3,$G3))) | M3: =IF($C3="","",IFERROR(INDEX(품목마스터!$F$3:$F$302,MATCH($C3,품목마스터!$A$3:$A$302,0)),0)+SUMIFS($L$3:$L3,$C$3:$C3,$C3))
D4: =IF($C4="","",IFERROR(INDEX(품목마스터!$B$3:$B$302,MATCH($C4,품목마스터!$A$3:$A$302,0)),"미등록품번")) | E4: =IF($C4="","",IFERROR(INDEX(품목마스터!$C$3:$C$302,MATCH($C4,품목마스터!$A$3:$A$302,0)),"")) | F4: =IF($C4="","",IFERROR(INDEX(품목마스터!$D$3:$D$302,MATCH($C4,품목마스터!$A$3:$A$302,0)),"")) | I4: =IF(OR($G4="",$H4=""),"",ROUND($G4*$H4,0)) | L4: =IF(OR($C4="",$G4=""),"",IF($B4="입고",$G4,IF($B4="출고",-$G4,$G4))) | M4: =IF($C4="","",IFERROR(INDEX(품목마스터!$F$3:$F$302,MATCH($C4,품목마스터!$A$3:$A$302,0)),0)+SUMIFS($L$3:$L4,$C$3:$C4,$C4))
D5: =IF($C5="","",IFERROR(INDEX(품목마스터!$B$3:$B$302,MATCH($C5,품목마스터!$A$3:$A$302,0)),"미등록품번")) | E5: =IF($C5="","",IFERROR(INDEX(품목마스터!$C$3:$C$302,MATCH($C5,품목마스터!$A$3:$A$302,0)),"")) | F5: =IF($C5="","",IFERROR(INDEX(품목마스터!$D$3:$D$302,MATCH($C5,품목마스터!$A$3:$A$302,0)),"")) | I5: =IF(OR($G5="",$H5=""),"",ROUND($G5*$H5,0)) | L5: =IF(OR($C5="",$G5=""),"",IF($B5="입고",$G5,IF($B5="출고",-$G5,$G5))) | M5: =IF($C5="","",IFERROR(INDEX(품목마스터!$F$3:$F$302,MATCH($C5,품목마스터!$A$3:$A$302,0)),0)+SUMIFS($L$3:$L5,$C$3:$C5,$C5))
D6: =IF($C6="","",IFERROR(INDEX(품목마스터!$B$3:$B$302,MATCH($C6,품목마스터!$A$3:$A$302,0)),"미등록품번")) | E6: =IF($C6="","",IFERROR(INDEX(품목마스터!$C$3:$C$302,MATCH($C6,품목마스터!$A$3:$A$302,0)),"")) | F6: =IF($C6="","",IFERROR(INDEX(품목마스터!$D$3:$D$302,MATCH($C6,품목마스터!$A$3:$A$302,0)),"")) | I6: =IF(OR($G6="",$H6=""),"",ROUND($G6*$H6,0)) | L6: =IF(OR($C6="",$G6=""),"",IF($B6="입고",$G6,IF($B6="출고",-$G6,$G6))) | M6: =IF($C6="","",IFERROR(INDEX(품목마스터!$F$3:$F$302,MATCH($C6,품목마스터!$A$3:$A$302,0)),0)+SUMIFS($L$3:$L6,$C$3:$C6,$C6))
D7: =IF($C7="","",IFERROR(INDEX(품목마스터!$B$3:$B$302,MATCH($C7,품목마스터!$A$3:$A$302,0)),"미등록품번")) | E7: =IF($C7="","",IFERROR(INDEX(품목마스터!$C$3:$C$302,MATCH($C7,품목마스터!$A$3:$A$302,0)),"")) | F7: =IF($C7="","",IFERROR(INDEX(품목마스터!$D$3:$D$302,MATCH($C7,품목마스터!$A$3:$A$302,0)),"")) | I7: =IF(OR($G7="",$H7=""),"",ROUND($G7*$H7,0)) | L7: =IF(OR($C7="",$G7=""),"",IF($B7="입고",$G7,IF($B7="출고",-$G7,$G7))) | M7: =IF($C7="","",IFERROR(INDEX(품목마스터!$F$3:$F$302,MATCH($C7,품목마스터!$A$3:$A$302,0)),0)+SUMIFS($L$3:$L7,$C$3:$C7,$C7))
D8: =IF($C8="","",IFERROR(INDEX(품목마스터!$B$3:$B$302,MATCH($C8,품목마스터!$A$3:$A$302,0)),"미등록품번")) | E8: =IF($C8="","",IFERROR(INDEX(품목마스터!$C$3:$C$302,MATCH($C8,품목마스터!$A$3:$A$302,0)),"")) | F8: =IF($C8="","",IFERROR(INDEX(품목마스터!$D$3:$D$302,MATCH($C8,품목마스터!$A$3:$A$302,0)),"")) | I8: =IF(OR($G8="",$H8=""),"",ROUND($G8*$H8,0)) | L8: =IF(OR($C8="",$G8=""),"",IF($B8="입고",$G8,IF($B8="출고",-$G8,$G8))) | M8: =IF($C8="","",IFERROR(INDEX(품목마스터!$F$3:$F$302,MATCH($C8,품목마스터!$A$3:$A$302,0)),0)+SUMIFS($L$3:$L8,$C$3:$C8,$C8))
D9: =IF($C9="","",IFERROR(INDEX(품목마스터!$B$3:$B$302,MATCH($C9,품목마스터!$A$3:$A$302,0)),"미등록품번")) | E9: =IF($C9="","",IFERROR(INDEX(품목마스터!$C$3:$C$302,MATCH($C9,품목마스터!$A$3:$A$302,0)),"")) | F9: =IF($C9="","",IFERROR(INDEX(품목마스터!$D$3:$D$302,MATCH($C9,품목마스터!$A$3:$A$302,0)),"")) | I9: =IF(OR($G9="",$H9=""),"",ROUND($G9*$H9,0)) | L9: =IF(OR($C9="",$G9=""),"",IF($B9="입고",$G9,IF($B9="출고",-$G9,$G9))) | M9: =IF($C9="","",IFERROR(INDEX(품목마스터!$F$3:$F$302,MATCH($C9,품목마스터!$A$3:$A$302,0)),0)+SUMIFS($L$3:$L9,$C$3:$C9,$C9))
D10: =IF($C10="","",IFERROR(INDEX(품목마스터!$B$3:$B$302,MATCH($C10,품목마스터!$A$3:$A$302,0)),"미등록품번")) | E10: =IF($C10="","",IFERROR(INDEX(품목마스터!$C$3:$C$302,MATCH($C10,품목마스터!$A$3:$A$302,0)),"")) | F10: =IF($C10="","",IFERROR(INDEX(품목마스터!$D$3:$D$302,MATCH($C10,품목마스터!$A$3:$A$302,0)),"")) | I10: =IF(OR($G10="",$H10=""),"",ROUND($G10*$H10,0)) | L10: =IF(OR($C10="",$G10=""),"",IF($B10="입고",$G10,IF($B10="출고",-$G10,$G10))) | M10: =IF($C10="","",IFERROR(INDEX(품목마스터!$F$3:$F$302,MATCH($C10,품목마스터!$A$3:$A$302,0)),0)+SUMIFS($L$3:$L10,$C$3:$C10,$C10))
D11: =IF($C11="","",IFERROR(INDEX(품목마스터!$B$3:$B$302,MATCH($C11,품목마스터!$A$3:$A$302,0)),"미등록품번")) | E11: =IF($C11="","",IFERROR(INDEX(품목마스터!$C$3:$C$302,MATCH($C11,품목마스터!$A$3:$A$302,0)),"")) | F11: =IF($C11="","",IFERROR(INDEX(품목마스터!$D$3:$D$302,MATCH($C11,품목마스터!$A$3:$A$302,0)),"")) | I11: =IF(OR($G11="",$H11=""),"",ROUND($G11*$H11,0)) | L11: =IF(OR($C11="",$G11=""),"",IF($B11="입고",$G11,IF($B11="출고",-$G11,$G11))) | M11: =IF($C11="","",IFERROR(INDEX(품목마스터!$F$3:$F$302,MATCH($C11,품목마스터!$A$3:$A$302,0)),0)+SUMIFS($L$3:$L11,$C$3:$C11,$C11))
D12: =IF($C12="","",IFERROR(INDEX(품목마스터!$B$3:$B$302,MATCH($C12,품목마스터!$A$3:$A$302,0)),"미등록품번")) | E12: =IF($C12="","",IFERROR(INDEX(품목마스터!$C$3:$C$302,MATCH($C12,품목마스터!$A$3:$A$302,0)),"")) | F12: =IF($C12="","",IFERROR(INDEX(품목마스터!$D$3:$D$302,MATCH($C12,품목마스터!$A$3:$A$302,0)),"")) | I12: =IF(OR($G12="",$H12=""),"",ROUND($G12*$H12,0)) | L12: =IF(OR($C12="",$G12=""),"",IF($B12="입고",$G12,IF($B12="출고",-$G12,$G12))) | M12: =IF($C12="","",IFERROR(INDEX(품목마스터!$F$3:$F$302,MATCH($C12,품목마스터!$A$3:$A$302,0)),0)+SUMIFS($L$3:$L12,$C$3:$C12,$C12))
D13: =IF($C13="","",IFERROR(INDEX(품목마스터!$B$3:$B$302,MATCH($C13,품목마스터!$A$3:$A$302,0)),"미등록품번")) | E13: =IF($C13="","",IFERROR(INDEX(품목마스터!$C$3:$C$302,MATCH($C13,품목마스터!$A$3:$A$302,0)),"")) | F13: =IF($C13="","",IFERROR(INDEX(품목마스터!$D$3:$D$302,MATCH($C13,품목마스터!$A$3:$A$302,0)),"")) | I13: =IF(OR($G13="",$H13=""),"",ROUND($G13*$H13,0)) | L13: =IF(OR($C13="",$G13=""),"",IF($B13="입고",$G13,IF($B13="출고",-$G13,$G13))) | M13: =IF($C13="","",IFERROR(INDEX(품목마스터!$F$3:$F$302,MATCH($C13,품목마스터!$A$3:$A$302,0)),0)+SUMIFS($L$3:$L13,$C$3:$C13,$C13))
D14: =IF($C14="","",IFERROR(INDEX(품목마스터!$B$3:$B$302,MATCH($C14,품목마스터!$A$3:$A$302,0)),"미등록품번")) | E14: =IF($C14="","",IFERROR(INDEX(품목마스터!$C$3:$C$302,MATCH($C14,품목마스터!$A$3:$A$302,0)),"")) | F14: =IF($C14="","",IFERROR(INDEX(품목마스터!$D$3:$D$302,MATCH($C14,품목마스터!$A$3:$A$302,0)),"")) | I14: =IF(OR($G14="",$H14=""),"",ROUND($G14*$H14,0)) | L14: =IF(OR($C14="",$G14=""),"",IF($B14="입고",$G14,IF($B14="출고",-$G14,$G14))) | M14: =IF($C14="","",IFERROR(INDEX(품목마스터!$F$3:$F$302,MATCH($C14,품목마스터!$A$3:$A$302,0)),0)+SUMIFS($L$3:$L14,$C$3:$C14,$C14))
... D1002: =IF($C1002="","",IFERROR(INDEX(품목마스터!$B$3:$B$302,MATCH($C1002,품목마스터!$A$3:$A$302,0)),"미등록품번")) | E1002: =IF($C1002="","",IFERROR(INDEX(품목마스터!$C$3:$C$302,MATCH($C1002,품목마스터!$A$3:$A$302,0)),"")) | F1002: =IF($C1002="","",IFERROR(INDEX(품목마스터!$D$3:$D$302,MATCH($C1002,품목마스터!$A$3:$A$302,0)),"")) | I1002: =IF(OR($G1002="",$H1002=""),"",ROUND($G1002*$H1002,0)) | L1002: =IF(OR($C1002="",$G1002=""),"",IF($B1002="입고",$G1002,IF($B1002="출고",-$G1002,$G1002))) | M1002: =IF($C1002="","",IFERROR(INDEX(품목마스터!$F$3:$F$302,MATCH($C1002,품목마스터!$A$3:$A$302,0)),0)+SUMIFS($L$3:$L1002,$C$3:$C1002,$C1002))
A1004: ※ '조정'은 실사 차이를 맞출 때 씁니다. 늘리면 양수(+), 줄이면 음수(-)로 수량을 넣으세요.
A1005: ※ 이동후재고가 음수면 빨간 배경으로 표시됩니다. 입력 누락을 확인하세요.

Sheet 품목검색
A1: 품목검색 (이름 일부만 넣으면 걸리는 품목이 나옵니다)
H2: 일치(자동) | I2: 순번(자동) | J2: 검색키(자동)
A3: 검색어 | B3: 볼트 | D3: ← 품목명 또는 규격의 일부를 넣으세요. 비우면 전체가 나옵니다. | H3: =IF(품목마스터!$A3="",FALSE(),IF($B$3="",TRUE(),ISNUMBER(SEARCH($B$3,품목마스터!$B3&" "&품목마스터!$C3&" "&품목마스터!$A3)))) -> TRUE | I3: =IF($H3=FALSE(),"",COUNTIF($H$3:$H3,TRUE())) -> 1 | J3: =IF($I3="","","R"&$I3) -> R1
A4: 검색 결과 | B4: =COUNTIF($H$3:$H$302,TRUE())&" 건" -> 1 건 | H4: =IF(품목마스터!$A4="",FALSE(),IF($B$3="",TRUE(),ISNUMBER(SEARCH($B$3,품목마스터!$B4&" "&품목마스터!$C4&" "&품목마스터!$A4)))) -> FALSE | I4: =IF($H4=FALSE(),"",COUNTIF($H$3:$H4,TRUE())) | J4: =IF($I4="","","R"&$I4)
H5: =IF(품목마스터!$A5="",FALSE(),IF($B$3="",TRUE(),ISNUMBER(SEARCH($B$3,품목마스터!$B5&" "&품목마스터!$C5&" "&품목마스터!$A5)))) -> FALSE | I5: =IF($H5=FALSE(),"",COUNTIF($H$3:$H5,TRUE())) | J5: =IF($I5="","","R"&$I5)
A6: 순번 | B6: 품번 | C6: 품목명 | D6: 규격 | E6: 단위 | F6: 현재고 | G6: 안전재고 | H6: =IF(품목마스터!$A6="",FALSE(),IF($B$3="",TRUE(),ISNUMBER(SEARCH($B$3,품목마스터!$B6&" "&품목마스터!$C6&" "&품목마스터!$A6)))) -> FALSE | I6: =IF($H6=FALSE(),"",COUNTIF($H$3:$H6,TRUE())) | J6: =IF($I6="","","R"&$I6)
A7: 1 | B7: =IFERROR(INDEX(품목마스터!$A$3:$A$302,MATCH("R"&1,품목검색!$J$3:$J$302,0)),"") -> A001 | C7: =IF($B7="","",IFERROR(INDEX(품목마스터!$B$3:$B$302,MATCH("R"&1,품목검색!$J$3:$J$302,0)),"")) -> 육각볼트 M10 | D7: =IF($B7="","",IFERROR(INDEX(품목마스터!$C$3:$C$302,MATCH("R"&1,품목검색!$J$3:$J$302,0)),"")) -> SUS304 L30 | E7: =IF($B7="","",IFERROR(INDEX(품목마스터!$D$3:$D$302,MATCH("R"&1,품목검색!$J$3:$J$302,0)),"")) -> EA | F7: =IF($B7="","",IFERROR(INDEX(품목마스터!$F$3:$F$302,MATCH("R"&1,품목검색!$J$3:$J$302,0)),0)+SUMIFS(입출고내역!$L$3:$L$1002,입출고내역!$C$3:$C$1002,$B7)) -> 500 | G7: =IF($B7="","",IFERROR(INDEX(품목마스터!$G$3:$G$302,MATCH("R"&1,품목검색!$J$3:$J$302,0)),0)) -> 100 | H7: =IF(품목마스터!$A7="",FALSE(),IF($B$3="",TRUE(),ISNUMBER(SEARCH($B$3,품목마스터!$B7&" "&품목마스터!$C7&" "&품목마스터!$A7)))) -> FALSE | I7: =IF($H7=FALSE(),"",COUNTIF($H$3:$H7,TRUE())) | J7: =IF($I7="","","R"&$I7)
A8: 2 | B8: =IFERROR(INDEX(품목마스터!$A$3:$A$302,MATCH("R"&2,품목검색!$J$3:$J$302,0)),"") | C8: =IF($B8="","",IFERROR(INDEX(품목마스터!$B$3:$B$302,MATCH("R"&2,품목검색!$J$3:$J$302,0)),"")) | D8: =IF($B8="","",IFERROR(INDEX(품목마스터!$C$3:$C$302,MATCH("R"&2,품목검색!$J$3:$J$302,0)),"")) | E8: =IF($B8="","",IFERROR(INDEX(품목마스터!$D$3:$D$302,MATCH("R"&2,품목검색!$J$3:$J$302,0)),"")) | F8: =IF($B8="","",IFERROR(INDEX(품목마스터!$F$3:$F$302,MATCH("R"&2,품목검색!$J$3:$J$302,0)),0)+SUMIFS(입출고내역!$L$3:$L$1002,입출고내역!$C$3:$C$1002,$B8)) | G8: =IF($B8="","",IFERROR(INDEX(품목마스터!$G$3:$G$302,MATCH("R"&2,품목검색!$J$3:$J$302,0)),0)) | H8: =IF(품목마스터!$A8="",FALSE(),IF($B$3="",TRUE(),ISNUMBER(SEARCH($B$3,품목마스터!$B8&" "&품목마스터!$C8&" "&품목마스터!$A8)))) -> FALSE | I8: =IF($H8=FALSE(),"",COUNTIF($H$3:$H8,TRUE())) | J8: =IF($I8="","","R"&$I8)
A9: 3 | B9: =IFERROR(INDEX(품목마스터!$A$3:$A$302,MATCH("R"&3,품목검색!$J$3:$J$302,0)),"") | C9: =IF($B9="","",IFERROR(INDEX(품목마스터!$B$3:$B$302,MATCH("R"&3,품목검색!$J$3:$J$302,0)),"")) | D9: =IF($B9="","",IFERROR(INDEX(품목마스터!$C$3:$C$302,MATCH("R"&3,품목검색!$J$3:$J$302,0)),"")) | E9: =IF($B9="","",IFERROR(INDEX(품목마스터!$D$3:$D$302,MATCH("R"&3,품목검색!$J$3:$J$302,0)),"")) | F9: =IF($B9="","",IFERROR(INDEX(품목마스터!$F$3:$F$302,MATCH("R"&3,품목검색!$J$3:$J$302,0)),0)+SUMIFS(입출고내역!$L$3:$L$1002,입출고내역!$C$3:$C$1002,$B9)) | G9: =IF($B9="","",IFERROR(INDEX(품목마스터!$G$3:$G$302,MATCH("R"&3,품목검색!$J$3:$J$302,0)),0)) | H9: =IF(품목마스터!$A9="",FALSE(),IF($B$3="",TRUE(),ISNUMBER(SEARCH($B$3,품목마스터!$B9&" "&품목마스터!$C9&" "&품목마스터!$A9)))) -> FALSE | I9: =IF($H9=FALSE(),"",COUNTIF($H$3:$H9,TRUE())) | J9: =IF($I9="","","R"&$I9)
A10: 4 | B10: =IFERROR(INDEX(품목마스터!$A$3:$A$302,MATCH("R"&4,품목검색!$J$3:$J$302,0)),"") | C10: =IF($B10="","",IFERROR(INDEX(품목마스터!$B$3:$B$302,MATCH("R"&4,품목검색!$J$3:$J$302,0)),"")) | D10: =IF($B10="","",IFERROR(INDEX(품목마스터!$C$3:$C$302,MATCH("R"&4,품목검색!$J$3:$J$302,0)),"")) | E10: =IF($B10="","",IFERROR(INDEX(품목마스터!$D$3:$D$302,MATCH("R"&4,품목검색!$J$3:$J$302,0)),"")) | F10: =IF($B10="","",IFERROR(INDEX(품목마스터!$F$3:$F$302,MATCH("R"&4,품목검색!$J$3:$J$302,0)),0)+SUMIFS(입출고내역!$L$3:$L$1002,입출고내역!$C$3:$C$1002,$B10)) | G10: =IF($B10="","",IFERROR(INDEX(품목마스터!$G$3:$G$302,MATCH("R"&4,품목검색!$J$3:$J$302,0)),0)) | H10: =IF(품목마스터!$A10="",FALSE(),IF($B$3="",TRUE(),ISNUMBER(SEARCH($B$3,품목마스터!$B10&" "&품목마스터!$C10&" "&품목마스터!$A10)))) -> FALSE | I10: =IF($H10=FALSE(),"",COUNTIF($H$3:$H10,TRUE())) | J10: =IF($I10="","","R"&$I10)
A11: 5 | B11: =IFERROR(INDEX(품목마스터!$A$3:$A$302,MATCH("R"&5,품목검색!$J$3:$J$302,0)),"") | C11: =IF($B11="","",IFERROR(INDEX(품목마스터!$B$3:$B$302,MATCH("R"&5,품목검색!$J$3:$J$302,0)),"")) | D11: =IF($B11="","",IFERROR(INDEX(품목마스터!$C$3:$C$302,MATCH("R"&5,품목검색!$J$3:$J$302,0)),"")) | E11: =IF($B11="","",IFERROR(INDEX(품목마스터!$D$3:$D$302,MATCH("R"&5,품목검색!$J$3:$J$302,0)),"")) | F11: =IF($B11="","",IFERROR(INDEX(품목마스터!$F$3:$F$302,MATCH("R"&5,품목검색!$J$3:$J$302,0)),0)+SUMIFS(입출고내역!$L$3:$L$1002,입출고내역!$C$3:$C$1002,$B11)) | G11: =IF($B11="","",IFERROR(INDEX(품목마스터!$G$3:$G$302,MATCH("R"&5,품목검색!$J$3:$J$302,0)),0)) | H11: =IF(품목마스터!$A11="",FALSE(),IF($B$3="",TRUE(),ISNUMBER(SEARCH($B$3,품목마스터!$B11&" "&품목마스터!$C11&" "&품목마스터!$A11)))) -> FALSE | I11: =IF($H11=FALSE(),"",COUNTIF($H$3:$H11,TRUE())) | J11: =IF($I11="","","R"&$I11)
A12: 6 | B12: =IFERROR(INDEX(품목마스터!$A$3:$A$302,MATCH("R"&6,품목검색!$J$3:$J$302,0)),"") | C12: =IF($B12="","",IFERROR(INDEX(품목마스터!$B$3:$B$302,MATCH("R"&6,품목검색!$J$3:$J$302,0)),"")) | D12: =IF($B12="","",IFERROR(INDEX(품목마스터!$C$3:$C$302,MATCH("R"&6,품목검색!$J$3:$J$302,0)),"")) | E12: =IF($B12="","",IFERROR(INDEX(품목마스터!$D$3:$D$302,MATCH("R"&6,품목검색!$J$3:$J$302,0)),"")) | F12: =IF($B12="","",IFERROR(INDEX(품목마스터!$F$3:$F$302,MATCH("R"&6,품목검색!$J$3:$J$302,0)),0)+SUMIFS(입출고내역!$L$3:$L$1002,입출고내역!$C$3:$C$1002,$B12)) | G12: =IF($B12="","",IFERROR(INDEX(품목마스터!$G$3:$G$302,MATCH("R"&6,품목검색!$J$3:$J$302,0)),0)) | H12: =IF(품목마스터!$A12="",FALSE(),IF($B$3="",TRUE(),ISNUMBER(SEARCH($B$3,품목마스터!$B12&" "&품목마스터!$C12&" "&품목마스터!$A12)))) -> FALSE | I12: =IF($H12=FALSE(),"",COUNTIF($H$3:$H12,TRUE())) | J12: =IF($I12="","","R"&$I12)
A13: 7 | B13: =IFERROR(INDEX(품목마스터!$A$3:$A$302,MATCH("R"&7,품목검색!$J$3:$J$302,0)),"") | C13: =IF($B13="","",IFERROR(INDEX(품목마스터!$B$3:$B$302,MATCH("R"&7,품목검색!$J$3:$J$302,0)),"")) | D13: =IF($B13="","",IFERROR(INDEX(품목마스터!$C$3:$C$302,MATCH("R"&7,품목검색!$J$3:$J$302,0)),"")) | E13: =IF($B13="","",IFERROR(INDEX(품목마스터!$D$3:$D$302,MATCH("R"&7,품목검색!$J$3:$J$302,0)),"")) | F13: =IF($B13="","",IFERROR(INDEX(품목마스터!$F$3:$F$302,MATCH("R"&7,품목검색!$J$3:$J$302,0)),0)+SUMIFS(입출고내역!$L$3:$L$1002,입출고내역!$C$3:$C$1002,$B13)) | G13: =IF($B13="","",IFERROR(INDEX(품목마스터!$G$3:$G$302,MATCH("R"&7,품목검색!$J$3:$J$302,0)),0)) | H13: =IF(품목마스터!$A13="",FALSE(),IF($B$3="",TRUE(),ISNUMBER(SEARCH($B$3,품목마스터!$B13&" "&품목마스터!$C13&" "&품목마스터!$A13)))) -> FALSE | I13: =IF($H13=FALSE(),"",COUNTIF($H$3:$H13,TRUE())) | J13: =IF($I13="","","R"&$I13)
A14: 8 | B14: =IFERROR(INDEX(품목마스터!$A$3:$A$302,MATCH("R"&8,품목검색!$J$3:$J$302,0)),"") | C14: =IF($B14="","",IFERROR(INDEX(품목마스터!$B$3:$B$302,MATCH("R"&8,품목검색!$J$3:$J$302,0)),"")) | D14: =IF($B14="","",IFERROR(INDEX(품목마스터!$C$3:$C$302,MATCH("R"&8,품목검색!$J$3:$J$302,0)),"")) | E14: =IF($B14="","",IFERROR(INDEX(품목마스터!$D$3:$D$302,MATCH("R"&8,품목검색!$J$3:$J$302,0)),"")) | F14: =IF($B14="","",IFERROR(INDEX(품목마스터!$F$3:$F$302,MATCH("R"&8,품목검색!$J$3:$J$302,0)),0)+SUMIFS(입출고내역!$L$3:$L$1002,입출고내역!$C$3:$C$1002,$B14)) | G14: =IF($B14="","",IFERROR(INDEX(품목마스터!$G$3:$G$302,MATCH("R"&8,품목검색!$J$3:$J$302,0)),0)) | H14: =IF(품목마스터!$A14="",FALSE(),IF($B$3="",TRUE(),ISNUMBER(SEARCH($B$3,품목마스터!$B14&" "&품목마스터!$C14&" "&품목마스터!$A14)))) -> FALSE | I14: =IF($H14=FALSE(),"",COUNTIF($H$3:$H14,TRUE())) | J14: =IF($I14="","","R"&$I14)
A15: 9 | B15: =IFERROR(INDEX(품목마스터!$A$3:$A$302,MATCH("R"&9,품목검색!$J$3:$J$302,0)),"") | C15: =IF($B15="","",IFERROR(INDEX(품목마스터!$B$3:$B$302,MATCH("R"&9,품목검색!$J$3:$J$302,0)),"")) | D15: =IF($B15="","",IFERROR(INDEX(품목마스터!$C$3:$C$302,MATCH("R"&9,품목검색!$J$3:$J$302,0)),"")) | E15: =IF($B15="","",IFERROR(INDEX(품목마스터!$D$3:$D$302,MATCH("R"&9,품목검색!$J$3:$J$302,0)),"")) | F15: =IF($B15="","",IFERROR(INDEX(품목마스터!$F$3:$F$302,MATCH("R"&9,품목검색!$J$3:$J$302,0)),0)+SUMIFS(입출고내역!$L$3:$L$1002,입출고내역!$C$3:$C$1002,$B15)) | G15: =IF($B15="","",IFERROR(INDEX(품목마스터!$G$3:$G$302,MATCH("R"&9,품목검색!$J$3:$J$302,0)),0)) | H15: =IF(품목마스터!$A15="",FALSE(),IF($B$3="",TRUE(),ISNUMBER(SEARCH($B$3,품목마스터!$B15&" "&품목마스터!$C15&" "&품목마스터!$A15)))) -> FALSE | I15: =IF($H15=FALSE(),"",COUNTIF($H$3:$H15,TRUE())) | J15: =IF($I15="","","R"&$I15)
A16: 10 | B16: =IFERROR(INDEX(품목마스터!$A$3:$A$302,MATCH("R"&10,품목검색!$J$3:$J$302,0)),"") | C16: =IF($B16="","",IFERROR(INDEX(품목마스터!$B$3:$B$302,MATCH("R"&10,품목검색!$J$3:$J$302,0)),"")) | D16: =IF($B16="","",IFERROR(INDEX(품목마스터!$C$3:$C$302,MATCH("R"&10,품목검색!$J$3:$J$302,0)),"")) | E16: =IF($B16="","",IFERROR(INDEX(품목마스터!$D$3:$D$302,MATCH("R"&10,품목검색!$J$3:$J$302,0)),"")) | F16: =IF($B16="","",IFERROR(INDEX(품목마스터!$F$3:$F$302,MATCH("R"&10,품목검색!$J$3:$J$302,0)),0)+SUMIFS(입출고내역!$L$3:$L$1002,입출고내역!$C$3:$C$1002,$B16)) | G16: =IF($B16="","",IFERROR(INDEX(품목마스터!$G$3:$G$302,MATCH("R"&10,품목검색!$J$3:$J$302,0)),0)) | H16: =IF(품목마스터!$A16="",FALSE(),IF($B$3="",TRUE(),ISNUMBER(SEARCH($B$3,품목마스터!$B16&" "&품목마스터!$C16&" "&품목마스터!$A16)))) -> FALSE | I16: =IF($H16=FALSE(),"",COUNTIF($H$3:$H16,TRUE())) | J16: =IF($I16="","","R"&$I16)
A17: 11 | B17: =IFERROR(INDEX(품목마스터!$A$3:$A$302,MATCH("R"&11,품목검색!$J$3:$J$302,0)),"") | C17: =IF($B17="","",IFERROR(INDEX(품목마스터!$B$3:$B$302,MATCH("R"&11,품목검색!$J$3:$J$302,0)),"")) | D17: =IF($B17="","",IFERROR(INDEX(품목마스터!$C$3:$C$302,MATCH("R"&11,품목검색!$J$3:$J$302,0)),"")) | E17: =IF($B17="","",IFERROR(INDEX(품목마스터!$D$3:$D$302,MATCH("R"&11,품목검색!$J$3:$J$302,0)),"")) | F17: =IF($B17="","",IFERROR(INDEX(품목마스터!$F$3:$F$302,MATCH("R"&11,품목검색!$J$3:$J$302,0)),0)+SUMIFS(입출고내역!$L$3:$L$1002,입출고내역!$C$3:$C$1002,$B17)) | G17: =IF($B17="","",IFERROR(INDEX(품목마스터!$G$3:$G$302,MATCH("R"&11,품목검색!$J$3:$J$302,0)),0)) | H17: =IF(품목마스터!$A17="",FALSE(),IF($B$3="",TRUE(),ISNUMBER(SEARCH($B$3,품목마스터!$B17&" "&품목마스터!$C17&" "&품목마스터!$A17)))) -> FALSE | I17: =IF($H17=FALSE(),"",COUNTIF($H$3:$H17,TRUE())) | J17: =IF($I17="","","R"&$I17)
A18: 12 | B18: =IFERROR(INDEX(품목마스터!$A$3:$A$302,MATCH("R"&12,품목검색!$J$3:$J$302,0)),"") | C18: =IF($B18="","",IFERROR(INDEX(품목마스터!$B$3:$B$302,MATCH("R"&12,품목검색!$J$3:$J$302,0)),"")) | D18: =IF($B18="","",IFERROR(INDEX(품목마스터!$C$3:$C$302,MATCH("R"&12,품목검색!$J$3:$J$302,0)),"")) | E18: =IF($B18="","",IFERROR(INDEX(품목마스터!$D$3:$D$302,MATCH("R"&12,품목검색!$J$3:$J$302,0)),"")) | F18: =IF($B18="","",IFERROR(INDEX(품목마스터!$F$3:$F$302,MATCH("R"&12,품목검색!$J$3:$J$302,0)),0)+SUMIFS(입출고내역!$L$3:$L$1002,입출고내역!$C$3:$C$1002,$B18)) | G18: =IF($B18="","",IFERROR(INDEX(품목마스터!$G$3:$G$302,MATCH("R"&12,품목검색!$J$3:$J$302,0)),0)) | H18: =IF(품목마스터!$A18="",FALSE(),IF($B$3="",TRUE(),ISNUMBER(SEARCH($B$3,품목마스터!$B18&" "&품목마스터!$C18&" "&품목마스터!$A18)))) -> FALSE | I18: =IF($H18=FALSE(),"",COUNTIF($H$3:$H18,TRUE())) | J18: =IF($I18="","","R"&$I18)
A19: 13 | B19: =IFERROR(INDEX(품목마스터!$A$3:$A$302,MATCH("R"&13,품목검색!$J$3:$J$302,0)),"") | C19: =IF($B19="","",IFERROR(INDEX(품목마스터!$B$3:$B$302,MATCH("R"&13,품목검색!$J$3:$J$302,0)),"")) | D19: =IF($B19="","",IFERROR(INDEX(품목마스터!$C$3:$C$302,MATCH("R"&13,품목검색!$J$3:$J$302,0)),"")) | E19: =IF($B19="","",IFERROR(INDEX(품목마스터!$D$3:$D$302,MATCH("R"&13,품목검색!$J$3:$J$302,0)),"")) | F19: =IF($B19="","",IFERROR(INDEX(품목마스터!$F$3:$F$302,MATCH("R"&13,품목검색!$J$3:$J$302,0)),0)+SUMIFS(입출고내역!$L$3:$L$1002,입출고내역!$C$3:$C$1002,$B19)) | G19: =IF($B19="","",IFERROR(INDEX(품목마스터!$G$3:$G$302,MATCH("R"&13,품목검색!$J$3:$J$302,0)),0)) | H19: =IF(품목마스터!$A19="",FALSE(),IF($B$3="",TRUE(),ISNUMBER(SEARCH($B$3,품목마스터!$B19&" "&품목마스터!$C19&" "&품목마스터!$A19)))) -> FALSE | I19: =IF($H19=FALSE(),"",COUNTIF($H$3:$H19,TRUE())) | J19: =IF($I19="","","R"&$I19)
A20: 14 | B20: =IFERROR(INDEX(품목마스터!$A$3:$A$302,MATCH("R"&14,품목검색!$J$3:$J$302,0)),"") | C20: =IF($B20="","",IFERROR(INDEX(품목마스터!$B$3:$B$302,MATCH("R"&14,품목검색!$J$3:$J$302,0)),"")) | D20: =IF($B20="","",IFERROR(INDEX(품목마스터!$C$3:$C$302,MATCH("R"&14,품목검색!$J$3:$J$302,0)),"")) | E20: =IF($B20="","",IFERROR(INDEX(품목마스터!$D$3:$D$302,MATCH("R"&14,품목검색!$J$3:$J$302,0)),"")) | F20: =IF($B20="","",IFERROR(INDEX(품목마스터!$F$3:$F$302,MATCH("R"&14,품목검색!$J$3:$J$302,0)),0)+SUMIFS(입출고내역!$L$3:$L$1002,입출고내역!$C$3:$C$1002,$B20)) | G20: =IF($B20="","",IFERROR(INDEX(품목마스터!$G$3:$G$302,MATCH("R"&14,품목검색!$J$3:$J$302,0)),0)) | H20: =IF(품목마스터!$A20="",FALSE(),IF($B$3="",TRUE(),ISNUMBER(SEARCH($B$3,품목마스터!$B20&" "&품목마스터!$C20&" "&품목마스터!$A20)))) -> FALSE | I20: =IF($H20=FALSE(),"",COUNTIF($H$3:$H20,TRUE())) | J20: =IF($I20="","","R"&$I20)
A21: 15 | B21: =IFERROR(INDEX(품목마스터!$A$3:$A$302,MATCH("R"&15,품목검색!$J$3:$J$302,0)),"") | C21: =IF($B21="","",IFERROR(INDEX(품목마스터!$B$3:$B$302,MATCH("R"&15,품목검색!$J$3:$J$302,0)),"")) | D21: =IF($B21="","",IFERROR(INDEX(품목마스터!$C$3:$C$302,MATCH("R"&15,품목검색!$J$3:$J$302,0)),"")) | E21: =IF($B21="","",IFERROR(INDEX(품목마스터!$D$3:$D$302,MATCH("R"&15,품목검색!$J$3:$J$302,0)),"")) | F21: =IF($B21="","",IFERROR(INDEX(품목마스터!$F$3:$F$302,MATCH("R"&15,품목검색!$J$3:$J$302,0)),0)+SUMIFS(입출고내역!$L$3:$L$1002,입출고내역!$C$3:$C$1002,$B21)) | G21: =IF($B21="","",IFERROR(INDEX(품목마스터!$G$3:$G$302,MATCH("R"&15,품목검색!$J$3:$J$302,0)),0)) | H21: =IF(품목마스터!$A21="",FALSE(),IF($B$3="",TRUE(),ISNUMBER(SEARCH($B$3,품목마스터!$B21&" "&품목마스터!$C21&" "&품목마스터!$A21)))) -> FALSE | I21: =IF($H21=FALSE(),"",COUNTIF($H$3:$H21,TRUE())) | J21: =IF($I21="","","R"&$I21)
A22: 16 | B22: =IFERROR(INDEX(품목마스터!$A$3:$A$302,MATCH("R"&16,품목검색!$J$3:$J$302,0)),"") | C22: =IF($B22="","",IFERROR(INDEX(품목마스터!$B$3:$B$302,MATCH("R"&16,품목검색!$J$3:$J$302,0)),"")) | D22: =IF($B22="","",IFERROR(INDEX(품목마스터!$C$3:$C$302,MATCH("R"&16,품목검색!$J$3:$J$302,0)),"")) | E22: =IF($B22="","",IFERROR(INDEX(품목마스터!$D$3:$D$302,MATCH("R"&16,품목검색!$J$3:$J$302,0)),"")) | F22: =IF($B22="","",IFERROR(INDEX(품목마스터!$F$3:$F$302,MATCH("R"&16,품목검색!$J$3:$J$302,0)),0)+SUMIFS(입출고내역!$L$3:$L$1002,입출고내역!$C$3:$C$1002,$B22)) | G22: =IF($B22="","",IFERROR(INDEX(품목마스터!$G$3:$G$302,MATCH("R"&16,품목검색!$J$3:$J$302,0)),0)) | H22: =IF(품목마스터!$A22="",FALSE(),IF($B$3="",TRUE(),ISNUMBER(SEARCH($B$3,품목마스터!$B22&" "&품목마스터!$C22&" "&품목마스터!$A22)))) -> FALSE | I22: =IF($H22=FALSE(),"",COUNTIF($H$3:$H22,TRUE())) | J22: =IF($I22="","","R"&$I22)
A23: 17 | B23: =IFERROR(INDEX(품목마스터!$A$3:$A$302,MATCH("R"&17,품목검색!$J$3:$J$302,0)),"") | C23: =IF($B23="","",IFERROR(INDEX(품목마스터!$B$3:$B$302,MATCH("R"&17,품목검색!$J$3:$J$302,0)),"")) | D23: =IF($B23="","",IFERROR(INDEX(품목마스터!$C$3:$C$302,MATCH("R"&17,품목검색!$J$3:$J$302,0)),"")) | E23: =IF($B23="","",IFERROR(INDEX(품목마스터!$D$3:$D$302,MATCH("R"&17,품목검색!$J$3:$J$302,0)),"")) | F23: =IF($B23="","",IFERROR(INDEX(품목마스터!$F$3:$F$302,MATCH("R"&17,품목검색!$J$3:$J$302,0)),0)+SUMIFS(입출고내역!$L$3:$L$1002,입출고내역!$C$3:$C$1002,$B23)) | G23: =IF($B23="","",IFERROR(INDEX(품목마스터!$G$3:$G$302,MATCH("R"&17,품목검색!$J$3:$J$302,0)),0)) | H23: =IF(품목마스터!$A23="",FALSE(),IF($B$3="",TRUE(),ISNUMBER(SEARCH($B$3,품목마스터!$B23&" "&품목마스터!$C23&" "&품목마스터!$A23)))) -> FALSE | I23: =IF($H23=FALSE(),"",COUNTIF($H$3:$H23,TRUE())) | J23: =IF($I23="","","R"&$I23)
A24: 18 | B24: =IFERROR(INDEX(품목마스터!$A$3:$A$302,MATCH("R"&18,품목검색!$J$3:$J$302,0)),"") | C24: =IF($B24="","",IFERROR(INDEX(품목마스터!$B$3:$B$302,MATCH("R"&18,품목검색!$J$3:$J$302,0)),"")) | D24: =IF($B24="","",IFERROR(INDEX(품목마스터!$C$3:$C$302,MATCH("R"&18,품목검색!$J$3:$J$302,0)),"")) | E24: =IF($B24="","",IFERROR(INDEX(품목마스터!$D$3:$D$302,MATCH("R"&18,품목검색!$J$3:$J$302,0)),"")) | F24: =IF($B24="","",IFERROR(INDEX(품목마스터!$F$3:$F$302,MATCH("R"&18,품목검색!$J$3:$J$302,0)),0)+SUMIFS(입출고내역!$L$3:$L$1002,입출고내역!$C$3:$C$1002,$B24)) | G24: =IF($B24="","",IFERROR(INDEX(품목마스터!$G$3:$G$302,MATCH("R"&18,품목검색!$J$3:$J$302,0)),0)) | H24: =IF(품목마스터!$A24="",FALSE(),IF($B$3="",TRUE(),ISNUMBER(SEARCH($B$3,품목마스터!$B24&" "&품목마스터!$C24&" "&품목마스터!$A24)))) -> FALSE | I24: =IF($H24=FALSE(),"",COUNTIF($H$3:$H24,TRUE())) | J24: =IF($I24="","","R"&$I24)
A25: 19 | B25: =IFERROR(INDEX(품목마스터!$A$3:$A$302,MATCH("R"&19,품목검색!$J$3:$J$302,0)),"") | C25: =IF($B25="","",IFERROR(INDEX(품목마스터!$B$3:$B$302,MATCH("R"&19,품목검색!$J$3:$J$302,0)),"")) | D25: =IF($B25="","",IFERROR(INDEX(품목마스터!$C$3:$C$302,MATCH("R"&19,품목검색!$J$3:$J$302,0)),"")) | E25: =IF($B25="","",IFERROR(INDEX(품목마스터!$D$3:$D$302,MATCH("R"&19,품목검색!$J$3:$J$302,0)),"")) | F25: =IF($B25="","",IFERROR(INDEX(품목마스터!$F$3:$F$302,MATCH("R"&19,품목검색!$J$3:$J$302,0)),0)+SUMIFS(입출고내역!$L$3:$L$1002,입출고내역!$C$3:$C$1002,$B25)) | G25: =IF($B25="","",IFERROR(INDEX(품목마스터!$G$3:$G$302,MATCH("R"&19,품목검색!$J$3:$J$302,0)),0)) | H25: =IF(품목마스터!$A25="",FALSE(),IF($B$3="",TRUE(),ISNUMBER(SEARCH($B$3,품목마스터!$B25&" "&품목마스터!$C25&" "&품목마스터!$A25)))) -> FALSE | I25: =IF($H25=FALSE(),"",COUNTIF($H$3:$H25,TRUE())) | J25: =IF($I25="","","R"&$I25)
A26: 20 | B26: =IFERROR(INDEX(품목마스터!$A$3:$A$302,MATCH("R"&20,품목검색!$J$3:$J$302,0)),"") | C26: =IF($B26="","",IFERROR(INDEX(품목마스터!$B$3:$B$302,MATCH("R"&20,품목검색!$J$3:$J$302,0)),"")) | D26: =IF($B26="","",IFERROR(INDEX(품목마스터!$C$3:$C$302,MATCH("R"&20,품목검색!$J$3:$J$302,0)),"")) | E26: =IF($B26="","",IFERROR(INDEX(품목마스터!$D$3:$D$302,MATCH("R"&20,품목검색!$J$3:$J$302,0)),"")) | F26: =IF($B26="","",IFERROR(INDEX(품목마스터!$F$3:$F$302,MATCH("R"&20,품목검색!$J$3:$J$302,0)),0)+SUMIFS(입출고내역!$L$3:$L$1002,입출고내역!$C$3:$C$1002,$B26)) | G26: =IF($B26="","",IFERROR(INDEX(품목마스터!$G$3:$G$302,MATCH("R"&20,품목검색!$J$3:$J$302,0)),0)) | H26: =IF(품목마스터!$A26="",FALSE(),IF($B$3="",TRUE(),ISNUMBER(SEARCH($B$3,품목마스터!$B26&" "&품목마스터!$C26&" "&품목마스터!$A26)))) -> FALSE | I26: =IF($H26=FALSE(),"",COUNTIF($H$3:$H26,TRUE())) | J26: =IF($I26="","","R"&$I26)
A27: 21 | B27: =IFERROR(INDEX(품목마스터!$A$3:$A$302,MATCH("R"&21,품목검색!$J$3:$J$302,0)),"") | C27: =IF($B27="","",IFERROR(INDEX(품목마스터!$B$3:$B$302,MATCH("R"&21,품목검색!$J$3:$J$302,0)),"")) | D27: =IF($B27="","",IFERROR(INDEX(품목마스터!$C$3:$C$302,MATCH("R"&21,품목검색!$J$3:$J$302,0)),"")) | E27: =IF($B27="","",IFERROR(INDEX(품목마스터!$D$3:$D$302,MATCH("R"&21,품목검색!$J$3:$J$302,0)),"")) | F27: =IF($B27="","",IFERROR(INDEX(품목마스터!$F$3:$F$302,MATCH("R"&21,품목검색!$J$3:$J$302,0)),0)+SUMIFS(입출고내역!$L$3:$L$1002,입출고내역!$C$3:$C$1002,$B27)) | G27: =IF($B27="","",IFERROR(INDEX(품목마스터!$G$3:$G$302,MATCH("R"&21,품목검색!$J$3:$J$302,0)),0)) | H27: =IF(품목마스터!$A27="",FALSE(),IF($B$3="",TRUE(),ISNUMBER(SEARCH($B$3,품목마스터!$B27&" "&품목마스터!$C27&" "&품목마스터!$A27)))) -> FALSE | I27: =IF($H27=FALSE(),"",COUNTIF($H$3:$H27,TRUE())) | J27: =IF($I27="","","R"&$I27)
A28: 22 | B28: =IFERROR(INDEX(품목마스터!$A$3:$A$302,MATCH("R"&22,품목검색!$J$3:$J$302,0)),"") | C28: =IF($B28="","",IFERROR(INDEX(품목마스터!$B$3:$B$302,MATCH("R"&22,품목검색!$J$3:$J$302,0)),"")) | D28: =IF($B28="","",IFERROR(INDEX(품목마스터!$C$3:$C$302,MATCH("R"&22,품목검색!$J$3:$J$302,0)),"")) | E28: =IF($B28="","",IFERROR(INDEX(품목마스터!$D$3:$D$302,MATCH("R"&22,품목검색!$J$3:$J$302,0)),"")) | F28: =IF($B28="","",IFERROR(INDEX(품목마스터!$F$3:$F$302,MATCH("R"&22,품목검색!$J$3:$J$302,0)),0)+SUMIFS(입출고내역!$L$3:$L$1002,입출고내역!$C$3:$C$1002,$B28)) | G28: =IF($B28="","",IFERROR(INDEX(품목마스터!$G$3:$G$302,MATCH("R"&22,품목검색!$J$3:$J$302,0)),0)) | H28: =IF(품목마스터!$A28="",FALSE(),IF($B$3="",TRUE(),ISNUMBER(SEARCH($B$3,품목마스터!$B28&" "&품목마스터!$C28&" "&품목마스터!$A28)))) -> FALSE | I28: =IF($H28=FALSE(),"",COUNTIF($H$3:$H28,TRUE())) | J28: =IF($I28="","","R"&$I28)
A29: 23 | B29: =IFERROR(INDEX(품목마스터!$A$3:$A$302,MATCH("R"&23,품목검색!$J$3:$J$302,0)),"") | C29: =IF($B29="","",IFERROR(INDEX(품목마스터!$B$3:$B$302,MATCH("R"&23,품목검색!$J$3:$J$302,0)),"")) | D29: =IF($B29="","",IFERROR(INDEX(품목마스터!$C$3:$C$302,MATCH("R"&23,품목검색!$J$3:$J$302,0)),"")) | E29: =IF($B29="","",IFERROR(INDEX(품목마스터!$D$3:$D$302,MATCH("R"&23,품목검색!$J$3:$J$302,0)),"")) | F29: =IF($B29="","",IFERROR(INDEX(품목마스터!$F$3:$F$302,MATCH("R"&23,품목검색!$J$3:$J$302,0)),0)+SUMIFS(입출고내역!$L$3:$L$1002,입출고내역!$C$3:$C$1002,$B29)) | G29: =IF($B29="","",IFERROR(INDEX(품목마스터!$G$3:$G$302,MATCH("R"&23,품목검색!$J$3:$J$302,0)),0)) | H29: =IF(품목마스터!$A29="",FALSE(),IF($B$3="",TRUE(),ISNUMBER(SEARCH($B$3,품목마스터!$B29&" "&품목마스터!$C29&" "&품목마스터!$A29)))) -> FALSE | I29: =IF($H29=FALSE(),"",COUNTIF($H$3:$H29,TRUE())) | J29: =IF($I29="","","R"&$I29)
A30: 24 | B30: =IFERROR(INDEX(품목마스터!$A$3:$A$302,MATCH("R"&24,품목검색!$J$3:$J$302,0)),"") | C30: =IF($B30="","",IFERROR(INDEX(품목마스터!$B$3:$B$302,MATCH("R"&24,품목검색!$J$3:$J$302,0)),"")) | D30: =IF($B30="","",IFERROR(INDEX(품목마스터!$C$3:$C$302,MATCH("R"&24,품목검색!$J$3:$J$302,0)),"")) | E30: =IF($B30="","",IFERROR(INDEX(품목마스터!$D$3:$D$302,MATCH("R"&24,품목검색!$J$3:$J$302,0)),"")) | F30: =IF($B30="","",IFERROR(INDEX(품목마스터!$F$3:$F$302,MATCH("R"&24,품목검색!$J$3:$J$302,0)),0)+SUMIFS(입출고내역!$L$3:$L$1002,입출고내역!$C$3:$C$1002,$B30)) | G30: =IF($B30="","",IFERROR(INDEX(품목마스터!$G$3:$G$302,MATCH("R"&24,품목검색!$J$3:$J$302,0)),0)) | H30: =IF(품목마스터!$A30="",FALSE(),IF($B$3="",TRUE(),ISNUMBER(SEARCH($B$3,품목마스터!$B30&" "&품목마스터!$C30&" "&품목마스터!$A30)))) -> FALSE | I30: =IF($H30=FALSE(),"",COUNTIF($H$3:$H30,TRUE())) | J30: =IF($I30="","","R"&$I30)
A31: 25 | B31: =IFERROR(INDEX(품목마스터!$A$3:$A$302,MATCH("R"&25,품목검색!$J$3:$J$302,0)),"") | C31: =IF($B31="","",IFERROR(INDEX(품목마스터!$B$3:$B$302,MATCH("R"&25,품목검색!$J$3:$J$302,0)),"")) | D31: =IF($B31="","",IFERROR(INDEX(품목마스터!$C$3:$C$302,MATCH("R"&25,품목검색!$J$3:$J$302,0)),"")) | E31: =IF($B31="","",IFERROR(INDEX(품목마스터!$D$3:$D$302,MATCH("R"&25,품목검색!$J$3:$J$302,0)),"")) | F31: =IF($B31="","",IFERROR(INDEX(품목마스터!$F$3:$F$302,MATCH("R"&25,품목검색!$J$3:$J$302,0)),0)+SUMIFS(입출고내역!$L$3:$L$1002,입출고내역!$C$3:$C$1002,$B31)) | G31: =IF($B31="","",IFERROR(INDEX(품목마스터!$G$3:$G$302,MATCH("R"&25,품목검색!$J$3:$J$302,0)),0)) | H31: =IF(품목마스터!$A31="",FALSE(),IF($B$3="",TRUE(),ISNUMBER(SEARCH($B$3,품목마스터!$B31&" "&품목마스터!$C31&" "&품목마스터!$A31)))) -> FALSE | I31: =IF($H31=FALSE(),"",COUNTIF($H$3:$H31,TRUE())) | J31: =IF($I31="","","R"&$I31)
A32: 26 | B32: =IFERROR(INDEX(품목마스터!$A$3:$A$302,MATCH("R"&26,품목검색!$J$3:$J$302,0)),"") | C32: =IF($B32="","",IFERROR(INDEX(품목마스터!$B$3:$B$302,MATCH("R"&26,품목검색!$J$3:$J$302,0)),"")) | D32: =IF($B32="","",IFERROR(INDEX(품목마스터!$C$3:$C$302,MATCH("R"&26,품목검색!$J$3:$J$302,0)),"")) | E32: =IF($B32="","",IFERROR(INDEX(품목마스터!$D$3:$D$302,MATCH("R"&26,품목검색!$J$3:$J$302,0)),"")) | F32: =IF($B32="","",IFERROR(INDEX(품목마스터!$F$3:$F$302,MATCH("R"&26,품목검색!$J$3:$J$302,0)),0)+SUMIFS(입출고내역!$L$3:$L$1002,입출고내역!$C$3:$C$1002,$B32)) | G32: =IF($B32="","",IFERROR(INDEX(품목마스터!$G$3:$G$302,MATCH("R"&26,품목검색!$J$3:$J$302,0)),0)) | H32: =IF(품목마스터!$A32="",FALSE(),IF($B$3="",TRUE(),ISNUMBER(SEARCH($B$3,품목마스터!$B32&" "&품목마스터!$C32&" "&품목마스터!$A32)))) -> FALSE | I32: =IF($H32=FALSE(),"",COUNTIF($H$3:$H32,TRUE())) | J32: =IF($I32="","","R"&$I32)
A33: 27 | B33: =IFERROR(INDEX(품목마스터!$A$3:$A$302,MATCH("R"&27,품목검색!$J$3:$J$302,0)),"") | C33: =IF($B33="","",IFERROR(INDEX(품목마스터!$B$3:$B$302,MATCH("R"&27,품목검색!$J$3:$J$302,0)),"")) | D33: =IF($B33="","",IFERROR(INDEX(품목마스터!$C$3:$C$302,MATCH("R"&27,품목검색!$J$3:$J$302,0)),"")) | E33: =IF($B33="","",IFERROR(INDEX(품목마스터!$D$3:$D$302,MATCH("R"&27,품목검색!$J$3:$J$302,0)),"")) | F33: =IF($B33="","",IFERROR(INDEX(품목마스터!$F$3:$F$302,MATCH("R"&27,품목검색!$J$3:$J$302,0)),0)+SUMIFS(입출고내역!$L$3:$L$1002,입출고내역!$C$3:$C$1002,$B33)) | G33: =IF($B33="","",IFERROR(INDEX(품목마스터!$G$3:$G$302,MATCH("R"&27,품목검색!$J$3:$J$302,0)),0)) | H33: =IF(품목마스터!$A33="",FALSE(),IF($B$3="",TRUE(),ISNUMBER(SEARCH($B$3,품목마스터!$B33&" "&품목마스터!$C33&" "&품목마스터!$A33)))) -> FALSE | I33: =IF($H33=FALSE(),"",COUNTIF($H$3:$H33,TRUE())) | J33: =IF($I33="","","R"&$I33)
A34: 28 | B34: =IFERROR(INDEX(품목마스터!$A$3:$A$302,MATCH("R"&28,품목검색!$J$3:$J$302,0)),"") | C34: =IF($B34="","",IFERROR(INDEX(품목마스터!$B$3:$B$302,MATCH("R"&28,품목검색!$J$3:$J$302,0)),"")) | D34: =IF($B34="","",IFERROR(INDEX(품목마스터!$C$3:$C$302,MATCH("R"&28,품목검색!$J$3:$J$302,0)),"")) | E34: =IF($B34="","",IFERROR(INDEX(품목마스터!$D$3:$D$302,MATCH("R"&28,품목검색!$J$3:$J$302,0)),"")) | F34: =IF($B34="","",IFERROR(INDEX(품목마스터!$F$3:$F$302,MATCH("R"&28,품목검색!$J$3:$J$302,0)),0)+SUMIFS(입출고내역!$L$3:$L$1002,입출고내역!$C$3:$C$1002,$B34)) | G34: =IF($B34="","",IFERROR(INDEX(품목마스터!$G$3:$G$302,MATCH("R"&28,품목검색!$J$3:$J$302,0)),0)) | H34: =IF(품목마스터!$A34="",FALSE(),IF($B$3="",TRUE(),ISNUMBER(SEARCH($B$3,품목마스터!$B34&" "&품목마스터!$C34&" "&품목마스터!$A34)))) -> FALSE | I34: =IF($H34=FALSE(),"",COUNTIF($H$3:$H34,TRUE())) | J34: =IF($I34="","","R"&$I34)
A35: 29 | B35: =IFERROR(INDEX(품목마스터!$A$3:$A$302,MATCH("R"&29,품목검색!$J$3:$J$302,0)),"") | C35: =IF($B35="","",IFERROR(INDEX(품목마스터!$B$3:$B$302,MATCH("R"&29,품목검색!$J$3:$J$302,0)),"")) | D35: =IF($B35="","",IFERROR(INDEX(품목마스터!$C$3:$C$302,MATCH("R"&29,품목검색!$J$3:$J$302,0)),"")) | E35: =IF($B35="","",IFERROR(INDEX(품목마스터!$D$3:$D$302,MATCH("R"&29,품목검색!$J$3:$J$302,0)),"")) | F35: =IF($B35="","",IFERROR(INDEX(품목마스터!$F$3:$F$302,MATCH("R"&29,품목검색!$J$3:$J$302,0)),0)+SUMIFS(입출고내역!$L$3:$L$1002,입출고내역!$C$3:$C$1002,$B35)) | G35: =IF($B35="","",IFERROR(INDEX(품목마스터!$G$3:$G$302,MATCH("R"&29,품목검색!$J$3:$J$302,0)),0)) | H35: =IF(품목마스터!$A35="",FALSE(),IF($B$3="",TRUE(),ISNUMBER(SEARCH($B$3,품목마스터!$B35&" "&품목마스터!$C35&" "&품목마스터!$A35)))) -> FALSE | I35: =IF($H35=FALSE(),"",COUNTIF($H$3:$H35,TRUE())) | J35: =IF($I35="","","R"&$I35)
A36: 30 | B36: =IFERROR(INDEX(품목마스터!$A$3:$A$302,MATCH("R"&30,품목검색!$J$3:$J$302,0)),"") | C36: =IF($B36="","",IFERROR(INDEX(품목마스터!$B$3:$B$302,MATCH("R"&30,품목검색!$J$3:$J$302,0)),"")) | D36: =IF($B36="","",IFERROR(INDEX(품목마스터!$C$3:$C$302,MATCH("R"&30,품목검색!$J$3:$J$302,0)),"")) | E36: =IF($B36="","",IFERROR(INDEX(품목마스터!$D$3:$D$302,MATCH("R"&30,품목검색!$J$3:$J$302,0)),"")) | F36: =IF($B36="","",IFERROR(INDEX(품목마스터!$F$3:$F$302,MATCH("R"&30,품목검색!$J$3:$J$302,0)),0)+SUMIFS(입출고내역!$L$3:$L$1002,입출고내역!$C$3:$C$1002,$B36)) | G36: =IF($B36="","",IFERROR(INDEX(품목마스터!$G$3:$G$302,MATCH("R"&30,품목검색!$J$3:$J$302,0)),0)) | H36: =IF(품목마스터!$A36="",FALSE(),IF($B$3="",TRUE(),ISNUMBER(SEARCH($B$3,품목마스터!$B36&" "&품목마스터!$C36&" "&품목마스터!$A36)))) -> FALSE | I36: =IF($H36=FALSE(),"",COUNTIF($H$3:$H36,TRUE())) | J36: =IF($I36="","","R"&$I36)
A37: 31 | B37: =IFERROR(INDEX(품목마스터!$A$3:$A$302,MATCH("R"&31,품목검색!$J$3:$J$302,0)),"") | C37: =IF($B37="","",IFERROR(INDEX(품목마스터!$B$3:$B$302,MATCH("R"&31,품목검색!$J$3:$J$302,0)),"")) | D37: =IF($B37="","",IFERROR(INDEX(품목마스터!$C$3:$C$302,MATCH("R"&31,품목검색!$J$3:$J$302,0)),"")) | E37: =IF($B37="","",IFERROR(INDEX(품목마스터!$D$3:$D$302,MATCH("R"&31,품목검색!$J$3:$J$302,0)),"")) | F37: =IF($B37="","",IFERROR(INDEX(품목마스터!$F$3:$F$302,MATCH("R"&31,품목검색!$J$3:$J$302,0)),0)+SUMIFS(입출고내역!$L$3:$L$1002,입출고내역!$C$3:$C$1002,$B37)) | G37: =IF($B37="","",IFERROR(INDEX(품목마스터!$G$3:$G$302,MATCH("R"&31,품목검색!$J$3:$J$302,0)),0)) | H37: =IF(품목마스터!$A37="",FALSE(),IF($B$3="",TRUE(),ISNUMBER(SEARCH($B$3,품목마스터!$B37&" "&품목마스터!$C37&" "&품목마스터!$A37)))) -> FALSE | I37: =IF($H37=FALSE(),"",COUNTIF($H$3:$H37,TRUE())) | J37: =IF($I37="","","R"&$I37)
A38: 32 | B38: =IFERROR(INDEX(품목마스터!$A$3:$A$302,MATCH("R"&32,품목검색!$J$3:$J$302,0)),"") | C38: =IF($B38="","",IFERROR(INDEX(품목마스터!$B$3:$B$302,MATCH("R"&32,품목검색!$J$3:$J$302,0)),"")) | D38: =IF($B38="","",IFERROR(INDEX(품목마스터!$C$3:$C$302,MATCH("R"&32,품목검색!$J$3:$J$302,0)),"")) | E38: =IF($B38="","",IFERROR(INDEX(품목마스터!$D$3:$D$302,MATCH("R"&32,품목검색!$J$3:$J$302,0)),"")) | F38: =IF($B38="","",IFERROR(INDEX(품목마스터!$F$3:$F$302,MATCH("R"&32,품목검색!$J$3:$J$302,0)),0)+SUMIFS(입출고내역!$L$3:$L$1002,입출고내역!$C$3:$C$1002,$B38)) | G38: =IF($B38="","",IFERROR(INDEX(품목마스터!$G$3:$G$302,MATCH("R"&32,품목검색!$J$3:$J$302,0)),0)) | H38: =IF(품목마스터!$A38="",FALSE(),IF($B$3="",TRUE(),ISNUMBER(SEARCH($B$3,품목마스터!$B38&" "&품목마스터!$C38&" "&품목마스터!$A38)))) -> FALSE | I38: =IF($H38=FALSE(),"",COUNTIF($H$3:$H38,TRUE())) | J38: =IF($I38="","","R"&$I38)
A39: 33 | B39: =IFERROR(INDEX(품목마스터!$A$3:$A$302,MATCH("R"&33,품목검색!$J$3:$J$302,0)),"") | C39: =IF($B39="","",IFERROR(INDEX(품목마스터!$B$3:$B$302,MATCH("R"&33,품목검색!$J$3:$J$302,0)),"")) | D39: =IF($B39="","",IFERROR(INDEX(품목마스터!$C$3:$C$302,MATCH("R"&33,품목검색!$J$3:$J$302,0)),"")) | E39: =IF($B39="","",IFERROR(INDEX(품목마스터!$D$3:$D$302,MATCH("R"&33,품목검색!$J$3:$J$302,0)),"")) | F39: =IF($B39="","",IFERROR(INDEX(품목마스터!$F$3:$F$302,MATCH("R"&33,품목검색!$J$3:$J$302,0)),0)+SUMIFS(입출고내역!$L$3:$L$1002,입출고내역!$C$3:$C$1002,$B39)) | G39: =IF($B39="","",IFERROR(INDEX(품목마스터!$G$3:$G$302,MATCH("R"&33,품목검색!$J$3:$J$302,0)),0)) | H39: =IF(품목마스터!$A39="",FALSE(),IF($B$3="",TRUE(),ISNUMBER(SEARCH($B$3,품목마스터!$B39&" "&품목마스터!$C39&" "&품목마스터!$A39)))) -> FALSE | I39: =IF($H39=FALSE(),"",COUNTIF($H$3:$H39,TRUE())) | J39: =IF($I39="","","R"&$I39)
A40: 34 | B40: =IFERROR(INDEX(품목마스터!$A$3:$A$302,MATCH("R"&34,품목검색!$J$3:$J$302,0)),"") | C40: =IF($B40="","",IFERROR(INDEX(품목마스터!$B$3:$B$302,MATCH("R"&34,품목검색!$J$3:$J$302,0)),"")) | D40: =IF($B40="","",IFERROR(INDEX(품목마스터!$C$3:$C$302,MATCH("R"&34,품목검색!$J$3:$J$302,0)),"")) | E40: =IF($B40="","",IFERROR(INDEX(품목마스터!$D$3:$D$302,MATCH("R"&34,품목검색!$J$3:$J$302,0)),"")) | F40: =IF($B40="","",IFERROR(INDEX(품목마스터!$F$3:$F$302,MATCH("R"&34,품목검색!$J$3:$J$302,0)),0)+SUMIFS(입출고내역!$L$3:$L$1002,입출고내역!$C$3:$C$1002,$B40)) | G40: =IF($B40="","",IFERROR(INDEX(품목마스터!$G$3:$G$302,MATCH("R"&34,품목검색!$J$3:$J$302,0)),0)) | H40: =IF(품목마스터!$A40="",FALSE(),IF($B$3="",TRUE(),ISNUMBER(SEARCH($B$3,품목마스터!$B40&" "&품목마스터!$C40&" "&품목마스터!$A40)))) -> FALSE | I40: =IF($H40=FALSE(),"",COUNTIF($H$3:$H40,TRUE())) | J40: =IF($I40="","","R"&$I40)
...

Sheet 재고현황
A1: 재고현황 (안전재고 대비 충족률)
A3: 품번 | B3: 품목명 | C3: 분류 | D3: 단위 | E3: 초기재고 | F3: 총입고 | G3: 총출고 | H3: 현재고 | I3: 안전재고 | J3: 충족률
A4: =IF(품목마스터!$A3="","",품목마스터!$A3) -> A001 | B4: =IF($A4="","",품목마스터!$B3) -> 육각볼트 M10 | C4: =IF($A4="","",품목마스터!$E3) -> 체결부품 | D4: =IF($A4="","",품목마스터!$D3) -> EA | E4: =IF($A4="","",IF(품목마스터!$F3="",0,품목마스터!$F3)) -> 500 | F4: =IF($A4="","",SUMIFS(입출고내역!$G$3:$G$1002,입출고내역!$C$3:$C$1002,$A4,입출고내역!$B$3:$B$1002,"입고")) -> 0 | G4: =IF($A4="","",SUMIFS(입출고내역!$G$3:$G$1002,입출고내역!$C$3:$C$1002,$A4,입출고내역!$B$3:$B$1002,"출고")) -> 0 | H4: =IF($A4="","",$E4+SUMIFS(입출고내역!$L$3:$L$1002,입출고내역!$C$3:$C$1002,$A4)) -> 500 | I4: =IF($A4="","",IF(품목마스터!$G3="",0,품목마스터!$G3)) -> 100 | J4: =IF($A4="","",IF($I4=0,"기준없음",TEXT($H4/$I4,"0%")&" "&REPT("■",MIN(10,ROUND($H4/$I4*10,0))))) -> 500% ■■■■■■■■■■
A5: =IF(품목마스터!$A4="","",품목마스터!$A4) -> A002 | B5: =IF($A5="","",품목마스터!$B4) -> 평와셔 M10 | C5: =IF($A5="","",품목마스터!$E4) -> 체결부품 | D5: =IF($A5="","",품목마스터!$D4) -> EA | E5: =IF($A5="","",IF(품목마스터!$F4="",0,품목마스터!$F4)) -> 800 | F5: =IF($A5="","",SUMIFS(입출고내역!$G$3:$G$1002,입출고내역!$C$3:$C$1002,$A5,입출고내역!$B$3:$B$1002,"입고")) -> 0 | G5: =IF($A5="","",SUMIFS(입출고내역!$G$3:$G$1002,입출고내역!$C$3:$C$1002,$A5,입출고내역!$B$3:$B$1002,"출고")) -> 0 | H5: =IF($A5="","",$E5+SUMIFS(입출고내역!$L$3:$L$1002,입출고내역!$C$3:$C$1002,$A5)) -> 800 | I5: =IF($A5="","",IF(품목마스터!$G4="",0,품목마스터!$G4)) -> 200 | J5: =IF($A5="","",IF($I5=0,"기준없음",TEXT($H5/$I5,"0%")&" "&REPT("■",MIN(10,ROUND($H5/$I5*10,0))))) -> 400% ■■■■■■■■■■
A6: =IF(품목마스터!$A5="","",품목마스터!$A5) -> B001 | B6: =IF($A6="","",품목마스터!$B5) -> 베어링 6204 | C6: =IF($A6="","",품목마스터!$E5) -> 구동부품 | D6: =IF($A6="","",품목마스터!$D5) -> EA | E6: =IF($A6="","",IF(품목마스터!$F5="",0,품목마스터!$F5)) -> 40 | F6: =IF($A6="","",SUMIFS(입출고내역!$G$3:$G$1002,입출고내역!$C$3:$C$1002,$A6,입출고내역!$B$3:$B$1002,"입고")) -> 0 | G6: =IF($A6="","",SUMIFS(입출고내역!$G$3:$G$1002,입출고내역!$C$3:$C$1002,$A6,입출고내역!$B$3:$B$1002,"출고")) -> 0 | H6: =IF($A6="","",$E6+SUMIFS(입출고내역!$L$3:$L$1002,입출고내역!$C$3:$C$1002,$A6)) -> 40 | I6: =IF($A6="","",IF(품목마스터!$G5="",0,품목마스터!$G5)) -> 10 | J6: =IF($A6="","",IF($I6=0,"기준없음",TEXT($H6/$I6,"0%")&" "&REPT("■",MIN(10,ROUND($H6/$I6*10,0))))) -> 400% ■■■■■■■■■■
A7: =IF(품목마스터!$A6="","",품목마스터!$A6) -> C001 | B7: =IF($A7="","",품목마스터!$B6) -> 절삭유 | C7: =IF($A7="","",품목마스터!$E6) -> 소모품 | D7: =IF($A7="","",품목마스터!$D6) -> 통 | E7: =IF($A7="","",IF(품목마스터!$F6="",0,품목마스터!$F6)) -> 12 | F7: =IF($A7="","",SUMIFS(입출고내역!$G$3:$G$1002,입출고내역!$C$3:$C$1002,$A7,입출고내역!$B$3:$B$1002,"입고")) -> 0 | G7: =IF($A7="","",SUMIFS(입출고내역!$G$3:$G$1002,입출고내역!$C$3:$C$1002,$A7,입출고내역!$B$3:$B$1002,"출고")) -> 0 | H7: =IF($A7="","",$E7+SUMIFS(입출고내역!$L$3:$L$1002,입출고내역!$C$3:$C$1002,$A7)) -> 12 | I7: =IF($A7="","",IF(품목마스터!$G6="",0,품목마스터!$G6)) -> 4 | J7: =IF($A7="","",IF($I7=0,"기준없음",TEXT($H7/$I7,"0%")&" "&REPT("■",MIN(10,ROUND($H7/$I7*10,0))))) -> 300% ■■■■■■■■■■
A8: =IF(품목마스터!$A7="","",품목마스터!$A7) | B8: =IF($A8="","",품목마스터!$B7) | C8: =IF($A8="","",품목마스터!$E7) | D8: =IF($A8="","",품목마스터!$D7) | E8: =IF($A8="","",IF(품목마스터!$F7="",0,품목마스터!$F7)) | F8: =IF($A8="","",SUMIFS(입출고내역!$G$3:$G$1002,입출고내역!$C$3:$C$1002,$A8,입출고내역!$B$3:$B$1002,"입고")) | G8: =IF($A8="","",SUMIFS(입출고내역!$G$3:$G$1002,입출고내역!$C$3:$C$1002,$A8,입출고내역!$B$3:$B$1002,"출고")) | H8: =IF($A8="","",$E8+SUMIFS(입출고내역!$L$3:$L$1002,입출고내역!$C$3:$C$1002,$A8)) | I8: =IF($A8="","",IF(품목마스터!$G7="",0,품목마스터!$G7)) | J8: =IF($A8="","",IF($I8=0,"기준없음",TEXT($H8/$I8,"0%")&" "&REPT("■",MIN(10,ROUND($H8/$I8*10,0)))))
A9: =IF(품목마스터!$A8="","",품목마스터!$A8) | B9: =IF($A9="","",품목마스터!$B8) | C9: =IF($A9="","",품목마스터!$E8) | D9: =IF($A9="","",품목마스터!$D8) | E9: =IF($A9="","",IF(품목마스터!$F8="",0,품목마스터!$F8)) | F9: =IF($A9="","",SUMIFS(입출고내역!$G$3:$G$1002,입출고내역!$C$3:$C$1002,$A9,입출고내역!$B$3:$B$1002,"입고")) | G9: =IF($A9="","",SUMIFS(입출고내역!$G$3:$G$1002,입출고내역!$C$3:$C$1002,$A9,입출고내역!$B$3:$B$1002,"출고")) | H9: =IF($A9="","",$E9+SUMIFS(입출고내역!$L$3:$L$1002,입출고내역!$C$3:$C$1002,$A9)) | I9: =IF($A9="","",IF(품목마스터!$G8="",0,품목마스터!$G8)) | J9: =IF($A9="","",IF($I9=0,"기준없음",TEXT($H9/$I9,"0%")&" "&REPT("■",MIN(10,ROUND($H9/$I9*10,0)))))
A10: =IF(품목마스터!$A9="","",품목마스터!$A9) | B10: =IF($A10="","",품목마스터!$B9) | C10: =IF($A10="","",품목마스터!$E9) | D10: =IF($A10="","",품목마스터!$D9) | E10: =IF($A10="","",IF(품목마스터!$F9="",0,품목마스터!$F9)) | F10: =IF($A10="","",SUMIFS(입출고내역!$G$3:$G$1002,입출고내역!$C$3:$C$1002,$A10,입출고내역!$B$3:$B$1002,"입고")) | G10: =IF($A10="","",SUMIFS(입출고내역!$G$3:$G$1002,입출고내역!$C$3:$C$1002,$A10,입출고내역!$B$3:$B$1002,"출고")) | H10: =IF($A10="","",$E10+SUMIFS(입출고내역!$L$3:$L$1002,입출고내역!$C$3:$C$1002,$A10)) | I10: =IF($A10="","",IF(품목마스터!$G9="",0,품목마스터!$G9)) | J10: =IF($A10="","",IF($I10=0,"기준없음",TEXT($H10/$I10,"0%")&" "&REPT("■",MIN(10,ROUND($H10/$I10*10,0)))))
A11: =IF(품목마스터!$A10="","",품목마스터!$A10) | B11: =IF($A11="","",품목마스터!$B10) | C11: =IF($A11="","",품목마스터!$E10) | D11: =IF($A11="","",품목마스터!$D10) | E11: =IF($A11="","",IF(품목마스터!$F10="",0,품목마스터!$F10)) | F11: =IF($A11="","",SUMIFS(입출고내역!$G$3:$G$1002,입출고내역!$C$3:$C$1002,$A11,입출고내역!$B$3:$B$1002,"입고")) | G11: =IF($A11="","",SUMIFS(입출고내역!$G$3:$G$1002,입출고내역!$C$3:$C$1002,$A11,입출고내역!$B$3:$B$1002,"출고")) | H11: =IF($A11="","",$E11+SUMIFS(입출고내역!$L$3:$L$1002,입출고내역!$C$3:$C$1002,$A11)) | I11: =IF($A11="","",IF(품목마스터!$G10="",0,품목마스터!$G10)) | J11: =IF($A11="","",IF($I11=0,"기준없음",TEXT($H11/$I11,"0%")&" "&REPT("■",MIN(10,ROUND($H11/$I11*10,0)))))
A12: =IF(품목마스터!$A11="","",품목마스터!$A11) | B12: =IF($A12="","",품목마스터!$B11) | C12: =IF($A12="","",품목마스터!$E11) | D12: =IF($A12="","",품목마스터!$D11) | E12: =IF($A12="","",IF(품목마스터!$F11="",0,품목마스터!$F11)) | F12: =IF($A12="","",SUMIFS(입출고내역!$G$3:$G$1002,입출고내역!$C$3:$C$1002,$A12,입출고내역!$B$3:$B$1002,"입고")) | G12: =IF($A12="","",SUMIFS(입출고내역!$G$3:$G$1002,입출고내역!$C$3:$C$1002,$A12,입출고내역!$B$3:$B$1002,"출고")) | H12: =IF($A12="","",$E12+SUMIFS(입출고내역!$L$3:$L$1002,입출고내역!$C$3:$C$1002,$A12)) | I12: =IF($A12="","",IF(품목마스터!$G11="",0,품목마스터!$G11)) | J12: =IF($A12="","",IF($I12=0,"기준없음",TEXT($H12/$I12,"0%")&" "&REPT("■",MIN(10,ROUND($H12/$I12*10,0)))))
A13: =IF(품목마스터!$A12="","",품목마스터!$A12) | B13: =IF($A13="","",품목마스터!$B12) | C13: =IF($A13="","",품목마스터!$E12) | D13: =IF($A13="","",품목마스터!$D12) | E13: =IF($A13="","",IF(품목마스터!$F12="",0,품목마스터!$F12)) | F13: =IF($A13="","",SUMIFS(입출고내역!$G$3:$G$1002,입출고내역!$C$3:$C$1002,$A13,입출고내역!$B$3:$B$1002,"입고")) | G13: =IF($A13="","",SUMIFS(입출고내역!$G$3:$G$1002,입출고내역!$C$3:$C$1002,$A13,입출고내역!$B$3:$B$1002,"출고")) | H13: =IF($A13="","",$E13+SUMIFS(입출고내역!$L$3:$L$1002,입출고내역!$C$3:$C$1002,$A13)) | I13: =IF($A13="","",IF(품목마스터!$G12="",0,품목마스터!$G12)) | J13: =IF($A13="","",IF($I13=0,"기준없음",TEXT($H13/$I13,"0%")&" "&REPT("■",MIN(10,ROUND($H13/$I13*10,0)))))
A14: =IF(품목마스터!$A13="","",품목마스터!$A13) | B14: =IF($A14="","",품목마스터!$B13) | C14: =IF($A14="","",품목마스터!$E13) | D14: =IF($A14="","",품목마스터!$D13) | E14: =IF($A14="","",IF(품목마스터!$F13="",0,품목마스터!$F13)) | F14: =IF($A14="","",SUMIFS(입출고내역!$G$3:$G$1002,입출고내역!$C$3:$C$1002,$A14,입출고내역!$B$3:$B$1002,"입고")) | G14: =IF($A14="","",SUMIFS(입출고내역!$G$3:$G$1002,입출고내역!$C$3:$C$1002,$A14,입출고내역!$B$3:$B$1002,"출고")) | H14: =IF($A14="","",$E14+SUMIFS(입출고내역!$L$3:$L$1002,입출고내역!$C$3:$C$1002,$A14)) | I14: =IF($A14="","",IF(품목마스터!$G13="",0,품목마스터!$G13)) | J14: =IF($A14="","",IF($I14=0,"기준없음",TEXT($H14/$I14,"0%")&" "&REPT("■",MIN(10,ROUND($H14/$I14*10,0)))))
A15: =IF(품목마스터!$A14="","",품목마스터!$A14) | B15: =IF($A15="","",품목마스터!$B14) | C15: =IF($A15="","",품목마스터!$E14) | D15: =IF($A15="","",품목마스터!$D14) | E15: =IF($A15="","",IF(품목마스터!$F14="",0,품목마스터!$F14)) | F15: =IF($A15="","",SUMIFS(입출고내역!$G$3:$G$1002,입출고내역!$C$3:$C$1002,$A15,입출고내역!$B$3:$B$1002,"입고")) | G15: =IF($A15="","",SUMIFS(입출고내역!$G$3:$G$1002,입출고내역!$C$3:$C$1002,$A15,입출고내역!$B$3:$B$1002,"출고")) | H15: =IF($A15="","",$E15+SUMIFS(입출고내역!$L$3:$L$1002,입출고내역!$C$3:$C$1002,$A15)) | I15: =IF($A15="","",IF(품목마스터!$G14="",0,품목마스터!$G14)) | J15: =IF($A15="","",IF($I15=0,"기준없음",TEXT($H15/$I15,"0%")&" "&REPT("■",MIN(10,ROUND($H15/$I15*10,0)))))
... A303: =IF(품목마스터!$A302="","",품목마스터!$A302) | B303: =IF($A303="","",품목마스터!$B302) | C303: =IF($A303="","",품목마스터!$E302) | D303: =IF($A303="","",품목마스터!$D302) | E303: =IF($A303="","",IF(품목마스터!$F302="",0,품목마스터!$F302)) | F303: =IF($A303="","",SUMIFS(입출고내역!$G$3:$G$1002,입출고내역!$C$3:$C$1002,$A303,입출고내역!$B$3:$B$1002,"입고")) | G303: =IF($A303="","",SUMIFS(입출고내역!$G$3:$G$1002,입출고내역!$C$3:$C$1002,$A303,입출고내역!$B$3:$B$1002,"출고")) | H303: =IF($A303="","",$E303+SUMIFS(입출고내역!$L$3:$L$1002,입출고내역!$C$3:$C$1002,$A303)) | I303: =IF($A303="","",IF(품목마스터!$G302="",0,품목마스터!$G302)) | J303: =IF($A303="","",IF($I303=0,"기준없음",TEXT($H303/$I303,"0%")&" "&REPT("■",MIN(10,ROUND($H303/$I303*10,0)))))
B305: 합계 | E305: =SUM(E4:E303) -> 1352 | F305: =SUM(F4:F303) -> 0 | G305: =SUM(G4:G303) -> 0 | H305: =SUM(H4:H303) -> 1352 | I305: =SUM(I4:I303) -> 314
A307: 미달 품목 수 | B307: =SUMPRODUCT(($A$4:$A$303<>"")*($I$4:$I$303>0)*($H$4:$H$303<$I$4:$I$303)) -> 0
A309: ※ ■ 열 개가 안전재고 100% 기준입니다. 넘어도 열 개로 표시됩니다.

Sheet 월간재고
A1: 월간재고 (품목마스터 순서 그대로)
A3: 대상 연도 | B3: 2026 | C3: 대상 월 | D3: 3 | E3: ← 두 칸만 바꾸면 아래가 전부 바뀝니다
A5: 품번 | B5: 품목명 | C5: 단위 | D5: 전월말재고 | E5: 당월입고 | F5: 당월출고 | G5: 월말재고 | H5: 안전재고
A6: =IF(품목마스터!$A3="","",품목마스터!$A3) -> A001 | B6: =IF($A6="","",품목마스터!$B3) -> 육각볼트 M10 | C6: =IF($A6="","",품목마스터!$D3) -> EA | D6: =IF($A6="","",IF(품목마스터!$F3="",0,품목마스터!$F3)+SUMIFS(입출고내역!$L$3:$L$1002,입출고내역!$C$3:$C$1002,$A6,입출고내역!$A$3:$A$1002,"<"&DATE($B$3,$D$3,1))) -> 500 | E6: =IF($A6="","",SUMIFS(입출고내역!$G$3:$G$1002,입출고내역!$C$3:$C$1002,$A6,입출고내역!$B$3:$B$1002,"입고",입출고내역!$A$3:$A$1002,">="&DATE($B$3,$D$3,1),입출고내역!$A$3:$A$1002,"<="&EOMONTH(DATE($B$3,$D$3,1),0))) -> 0 | F6: =IF($A6="","",SUMIFS(입출고내역!$G$3:$G$1002,입출고내역!$C$3:$C$1002,$A6,입출고내역!$B$3:$B$1002,"출고",입출고내역!$A$3:$A$1002,">="&DATE($B$3,$D$3,1),입출고내역!$A$3:$A$1002,"<="&EOMONTH(DATE($B$3,$D$3,1),0))) -> 0 | G6: =IF($A6="","",IF(품목마스터!$F3="",0,품목마스터!$F3)+SUMIFS(입출고내역!$L$3:$L$1002,입출고내역!$C$3:$C$1002,$A6,입출고내역!$A$3:$A$1002,"<="&EOMONTH(DATE($B$3,$D$3,1),0))) -> 500 | H6: =IF($A6="","",IF(품목마스터!$G3="",0,품목마스터!$G3)) -> 100
A7: =IF(품목마스터!$A4="","",품목마스터!$A4) -> A002 | B7: =IF($A7="","",품목마스터!$B4) -> 평와셔 M10 | C7: =IF($A7="","",품목마스터!$D4) -> EA | D7: =IF($A7="","",IF(품목마스터!$F4="",0,품목마스터!$F4)+SUMIFS(입출고내역!$L$3:$L$1002,입출고내역!$C$3:$C$1002,$A7,입출고내역!$A$3:$A$1002,"<"&DATE($B$3,$D$3,1))) -> 800 | E7: =IF($A7="","",SUMIFS(입출고내역!$G$3:$G$1002,입출고내역!$C$3:$C$1002,$A7,입출고내역!$B$3:$B$1002,"입고",입출고내역!$A$3:$A$1002,">="&DATE($B$3,$D$3,1),입출고내역!$A$3:$A$1002,"<="&EOMONTH(DATE($B$3,$D$3,1),0))) -> 0 | F7: =IF($A7="","",SUMIFS(입출고내역!$G$3:$G$1002,입출고내역!$C$3:$C$1002,$A7,입출고내역!$B$3:$B$1002,"출고",입출고내역!$A$3:$A$1002,">="&DATE($B$3,$D$3,1),입출고내역!$A$3:$A$1002,"<="&EOMONTH(DATE($B$3,$D$3,1),0))) -> 0 | G7: =IF($A7="","",IF(품목마스터!$F4="",0,품목마스터!$F4)+SUMIFS(입출고내역!$L$3:$L$1002,입출고내역!$C$3:$C$1002,$A7,입출고내역!$A$3:$A$1002,"<="&EOMONTH(DATE($B$3,$D$3,1),0))) -> 800 | H7: =IF($A7="","",IF(품목마스터!$G4="",0,품목마스터!$G4)) -> 200
A8: =IF(품목마스터!$A5="","",품목마스터!$A5) -> B001 | B8: =IF($A8="","",품목마스터!$B5) -> 베어링 6204 | C8: =IF($A8="","",품목마스터!$D5) -> EA | D8: =IF($A8="","",IF(품목마스터!$F5="",0,품목마스터!$F5)+SUMIFS(입출고내역!$L$3:$L$1002,입출고내역!$C$3:$C$1002,$A8,입출고내역!$A$3:$A$1002,"<"&DATE($B$3,$D$3,1))) -> 40 | E8: =IF($A8="","",SUMIFS(입출고내역!$G$3:$G$1002,입출고내역!$C$3:$C$1002,$A8,입출고내역!$B$3:$B$1002,"입고",입출고내역!$A$3:$A$1002,">="&DATE($B$3,$D$3,1),입출고내역!$A$3:$A$1002,"<="&EOMONTH(DATE($B$3,$D$3,1),0))) -> 0 | F8: =IF($A8="","",SUMIFS(입출고내역!$G$3:$G$1002,입출고내역!$C$3:$C$1002,$A8,입출고내역!$B$3:$B$1002,"출고",입출고내역!$A$3:$A$1002,">="&DATE($B$3,$D$3,1),입출고내역!$A$3:$A$1002,"<="&EOMONTH(DATE($B$3,$D$3,1),0))) -> 0 | G8: =IF($A8="","",IF(품목마스터!$F5="",0,품목마스터!$F5)+SUMIFS(입출고내역!$L$3:$L$1002,입출고내역!$C$3:$C$1002,$A8,입출고내역!$A$3:$A$1002,"<="&EOMONTH(DATE($B$3,$D$3,1),0))) -> 40 | H8: =IF($A8="","",IF(품목마스터!$G5="",0,품목마스터!$G5)) -> 10
A9: =IF(품목마스터!$A6="","",품목마스터!$A6) -> C001 | B9: =IF($A9="","",품목마스터!$B6) -> 절삭유 | C9: =IF($A9="","",품목마스터!$D6) -> 통 | D9: =IF($A9="","",IF(품목마스터!$F6="",0,품목마스터!$F6)+SUMIFS(입출고내역!$L$3:$L$1002,입출고내역!$C$3:$C$1002,$A9,입출고내역!$A$3:$A$1002,"<"&DATE($B$3,$D$3,1))) -> 12 | E9: =IF($A9="","",SUMIFS(입출고내역!$G$3:$G$1002,입출고내역!$C$3:$C$1002,$A9,입출고내역!$B$3:$B$1002,"입고",입출고내역!$A$3:$A$1002,">="&DATE($B$3,$D$3,1),입출고내역!$A$3:$A$1002,"<="&EOMONTH(DATE($B$3,$D$3,1),0))) -> 0 | F9: =IF($A9="","",SUMIFS(입출고내역!$G$3:$G$1002,입출고내역!$C$3:$C$1002,$A9,입출고내역!$B$3:$B$1002,"출고",입출고내역!$A$3:$A$1002,">="&DATE($B$3,$D$3,1),입출고내역!$A$3:$A$1002,"<="&EOMONTH(DATE($B$3,$D$3,1),0))) -> 0 | G9: =IF($A9="","",IF(품목마스터!$F6="",0,품목마스터!$F6)+SUMIFS(입출고내역!$L$3:$L$1002,입출고내역!$C$3:$C$1002,$A9,입출고내역!$A$3:$A$1002,"<="&EOMONTH(DATE($B$3,$D$3,1),0))) -> 12 | H9: =IF($A9="","",IF(품목마스터!$G6="",0,품목마스터!$G6)) -> 4
A10: =IF(품목마스터!$A7="","",품목마스터!$A7) | B10: =IF($A10="","",품목마스터!$B7) | C10: =IF($A10="","",품목마스터!$D7) | D10: =IF($A10="","",IF(품목마스터!$F7="",0,품목마스터!$F7)+SUMIFS(입출고내역!$L$3:$L$1002,입출고내역!$C$3:$C$1002,$A10,입출고내역!$A$3:$A$1002,"<"&DATE($B$3,$D$3,1))) | E10: =IF($A10="","",SUMIFS(입출고내역!$G$3:$G$1002,입출고내역!$C$3:$C$1002,$A10,입출고내역!$B$3:$B$1002,"입고",입출고내역!$A$3:$A$1002,">="&DATE($B$3,$D$3,1),입출고내역!$A$3:$A$1002,"<="&EOMONTH(DATE($B$3,$D$3,1),0))) | F10: =IF($A10="","",SUMIFS(입출고내역!$G$3:$G$1002,입출고내역!$C$3:$C$1002,$A10,입출고내역!$B$3:$B$1002,"출고",입출고내역!$A$3:$A$1002,">="&DATE($B$3,$D$3,1),입출고내역!$A$3:$A$1002,"<="&EOMONTH(DATE($B$3,$D$3,1),0))) | G10: =IF($A10="","",IF(품목마스터!$F7="",0,품목마스터!$F7)+SUMIFS(입출고내역!$L$3:$L$1002,입출고내역!$C$3:$C$1002,$A10,입출고내역!$A$3:$A$1002,"<="&EOMONTH(DATE($B$3,$D$3,1),0))) | H10: =IF($A10="","",IF(품목마스터!$G7="",0,품목마스터!$G7))
A11: =IF(품목마스터!$A8="","",품목마스터!$A8) | B11: =IF($A11="","",품목마스터!$B8) | C11: =IF($A11="","",품목마스터!$D8) | D11: =IF($A11="","",IF(품목마스터!$F8="",0,품목마스터!$F8)+SUMIFS(입출고내역!$L$3:$L$1002,입출고내역!$C$3:$C$1002,$A11,입출고내역!$A$3:$A$1002,"<"&DATE($B$3,$D$3,1))) | E11: =IF($A11="","",SUMIFS(입출고내역!$G$3:$G$1002,입출고내역!$C$3:$C$1002,$A11,입출고내역!$B$3:$B$1002,"입고",입출고내역!$A$3:$A$1002,">="&DATE($B$3,$D$3,1),입출고내역!$A$3:$A$1002,"<="&EOMONTH(DATE($B$3,$D$3,1),0))) | F11: =IF($A11="","",SUMIFS(입출고내역!$G$3:$G$1002,입출고내역!$C$3:$C$1002,$A11,입출고내역!$B$3:$B$1002,"출고",입출고내역!$A$3:$A$1002,">="&DATE($B$3,$D$3,1),입출고내역!$A$3:$A$1002,"<="&EOMONTH(DATE($B$3,$D$3,1),0))) | G11: =IF($A11="","",IF(품목마스터!$F8="",0,품목마스터!$F8)+SUMIFS(입출고내역!$L$3:$L$1002,입출고내역!$C$3:$C$1002,$A11,입출고내역!$A$3:$A$1002,"<="&EOMONTH(DATE($B$3,$D$3,1),0))) | H11: =IF($A11="","",IF(품목마스터!$G8="",0,품목마스터!$G8))
A12: =IF(품목마스터!$A9="","",품목마스터!$A9) | B12: =IF($A12="","",품목마스터!$B9) | C12: =IF($A12="","",품목마스터!$D9) | D12: =IF($A12="","",IF(품목마스터!$F9="",0,품목마스터!$F9)+SUMIFS(입출고내역!$L$3:$L$1002,입출고내역!$C$3:$C$1002,$A12,입출고내역!$A$3:$A$1002,"<"&DATE($B$3,$D$3,1))) | E12: =IF($A12="","",SUMIFS(입출고내역!$G$3:$G$1002,입출고내역!$C$3:$C$1002,$A12,입출고내역!$B$3:$B$1002,"입고",입출고내역!$A$3:$A$1002,">="&DATE($B$3,$D$3,1),입출고내역!$A$3:$A$1002,"<="&EOMONTH(DATE($B$3,$D$3,1),0))) | F12: =IF($A12="","",SUMIFS(입출고내역!$G$3:$G$1002,입출고내역!$C$3:$C$1002,$A12,입출고내역!$B$3:$B$1002,"출고",입출고내역!$A$3:$A$1002,">="&DATE($B$3,$D$3,1),입출고내역!$A$3:$A$1002,"<="&EOMONTH(DATE($B$3,$D$3,1),0))) | G12: =IF($A12="","",IF(품목마스터!$F9="",0,품목마스터!$F9)+SUMIFS(입출고내역!$L$3:$L$1002,입출고내역!$C$3:$C$1002,$A12,입출고내역!$A$3:$A$1002,"<="&EOMONTH(DATE($B$3,$D$3,1),0))) | H12: =IF($A12="","",IF(품목마스터!$G9="",0,품목마스터!$G9))
A13: =IF(품목마스터!$A10="","",품목마스터!$A10) | B13: =IF($A13="","",품목마스터!$B10) | C13: =IF($A13="","",품목마스터!$D10) | D13: =IF($A13="","",IF(품목마스터!$F10="",0,품목마스터!$F10)+SUMIFS(입출고내역!$L$3:$L$1002,입출고내역!$C$3:$C$1002,$A13,입출고내역!$A$3:$A$1002,"<"&DATE($B$3,$D$3,1))) | E13: =IF($A13="","",SUMIFS(입출고내역!$G$3:$G$1002,입출고내역!$C$3:$C$1002,$A13,입출고내역!$B$3:$B$1002,"입고",입출고내역!$A$3:$A$1002,">="&DATE($B$3,$D$3,1),입출고내역!$A$3:$A$1002,"<="&EOMONTH(DATE($B$3,$D$3,1),0))) | F13: =IF($A13="","",SUMIFS(입출고내역!$G$3:$G$1002,입출고내역!$C$3:$C$1002,$A13,입출고내역!$B$3:$B$1002,"출고",입출고내역!$A$3:$A$1002,">="&DATE($B$3,$D$3,1),입출고내역!$A$3:$A$1002,"<="&EOMONTH(DATE($B$3,$D$3,1),0))) | G13: =IF($A13="","",IF(품목마스터!$F10="",0,품목마스터!$F10)+SUMIFS(입출고내역!$L$3:$L$1002,입출고내역!$C$3:$C$1002,$A13,입출고내역!$A$3:$A$1002,"<="&EOMONTH(DATE($B$3,$D$3,1),0))) | H13: =IF($A13="","",IF(품목마스터!$G10="",0,품목마스터!$G10))
A14: =IF(품목마스터!$A11="","",품목마스터!$A11) | B14: =IF($A14="","",품목마스터!$B11) | C14: =IF($A14="","",품목마스터!$D11) | D14: =IF($A14="","",IF(품목마스터!$F11="",0,품목마스터!$F11)+SUMIFS(입출고내역!$L$3:$L$1002,입출고내역!$C$3:$C$1002,$A14,입출고내역!$A$3:$A$1002,"<"&DATE($B$3,$D$3,1))) | E14: =IF($A14="","",SUMIFS(입출고내역!$G$3:$G$1002,입출고내역!$C$3:$C$1002,$A14,입출고내역!$B$3:$B$1002,"입고",입출고내역!$A$3:$A$1002,">="&DATE($B$3,$D$3,1),입출고내역!$A$3:$A$1002,"<="&EOMONTH(DATE($B$3,$D$3,1),0))) | F14: =IF($A14="","",SUMIFS(입출고내역!$G$3:$G$1002,입출고내역!$C$3:$C$1002,$A14,입출고내역!$B$3:$B$1002,"출고",입출고내역!$A$3:$A$1002,">="&DATE($B$3,$D$3,1),입출고내역!$A$3:$A$1002,"<="&EOMONTH(DATE($B$3,$D$3,1),0))) | G14: =IF($A14="","",IF(품목마스터!$F11="",0,품목마스터!$F11)+SUMIFS(입출고내역!$L$3:$L$1002,입출고내역!$C$3:$C$1002,$A14,입출고내역!$A$3:$A$1002,"<="&EOMONTH(DATE($B$3,$D$3,1),0))) | H14: =IF($A14="","",IF(품목마스터!$G11="",0,품목마스터!$G11))
A15: =IF(품목마스터!$A12="","",품목마스터!$A12) | B15: =IF($A15="","",품목마스터!$B12) | C15: =IF($A15="","",품목마스터!$D12) | D15: =IF($A15="","",IF(품목마스터!$F12="",0,품목마스터!$F12)+SUMIFS(입출고내역!$L$3:$L$1002,입출고내역!$C$3:$C$1002,$A15,입출고내역!$A$3:$A$1002,"<"&DATE($B$3,$D$3,1))) | E15: =IF($A15="","",SUMIFS(입출고내역!$G$3:$G$1002,입출고내역!$C$3:$C$1002,$A15,입출고내역!$B$3:$B$1002,"입고",입출고내역!$A$3:$A$1002,">="&DATE($B$3,$D$3,1),입출고내역!$A$3:$A$1002,"<="&EOMONTH(DATE($B$3,$D$3,1),0))) | F15: =IF($A15="","",SUMIFS(입출고내역!$G$3:$G$1002,입출고내역!$C$3:$C$1002,$A15,입출고내역!$B$3:$B$1002,"출고",입출고내역!$A$3:$A$1002,">="&DATE($B$3,$D$3,1),입출고내역!$A$3:$A$1002,"<="&EOMONTH(DATE($B$3,$D$3,1),0))) | G15: =IF($A15="","",IF(품목마스터!$F12="",0,품목마스터!$F12)+SUMIFS(입출고내역!$L$3:$L$1002,입출고내역!$C$3:$C$1002,$A15,입출고내역!$A$3:$A$1002,"<="&EOMONTH(DATE($B$3,$D$3,1),0))) | H15: =IF($A15="","",IF(품목마스터!$G12="",0,품목마스터!$G12))
A16: =IF(품목마스터!$A13="","",품목마스터!$A13) | B16: =IF($A16="","",품목마스터!$B13) | C16: =IF($A16="","",품목마스터!$D13) | D16: =IF($A16="","",IF(품목마스터!$F13="",0,품목마스터!$F13)+SUMIFS(입출고내역!$L$3:$L$1002,입출고내역!$C$3:$C$1002,$A16,입출고내역!$A$3:$A$1002,"<"&DATE($B$3,$D$3,1))) | E16: =IF($A16="","",SUMIFS(입출고내역!$G$3:$G$1002,입출고내역!$C$3:$C$1002,$A16,입출고내역!$B$3:$B$1002,"입고",입출고내역!$A$3:$A$1002,">="&DATE($B$3,$D$3,1),입출고내역!$A$3:$A$1002,"<="&EOMONTH(DATE($B$3,$D$3,1),0))) | F16: =IF($A16="","",SUMIFS(입출고내역!$G$3:$G$1002,입출고내역!$C$3:$C$1002,$A16,입출고내역!$B$3:$B$1002,"출고",입출고내역!$A$3:$A$1002,">="&DATE($B$3,$D$3,1),입출고내역!$A$3:$A$1002,"<="&EOMONTH(DATE($B$3,$D$3,1),0))) | G16: =IF($A16="","",IF(품목마스터!$F13="",0,품목마스터!$F13)+SUMIFS(입출고내역!$L$3:$L$1002,입출고내역!$C$3:$C$1002,$A16,입출고내역!$A$3:$A$1002,"<="&EOMONTH(DATE($B$3,$D$3,1),0))) | H16: =IF($A16="","",IF(품목마스터!$G13="",0,품목마스터!$G13))
A17: =IF(품목마스터!$A14="","",품목마스터!$A14) | B17: =IF($A17="","",품목마스터!$B14) | C17: =IF($A17="","",품목마스터!$D14) | D17: =IF($A17="","",IF(품목마스터!$F14="",0,품목마스터!$F14)+SUMIFS(입출고내역!$L$3:$L$1002,입출고내역!$C$3:$C$1002,$A17,입출고내역!$A$3:$A$1002,"<"&DATE($B$3,$D$3,1))) | E17: =IF($A17="","",SUMIFS(입출고내역!$G$3:$G$1002,입출고내역!$C$3:$C$1002,$A17,입출고내역!$B$3:$B$1002,"입고",입출고내역!$A$3:$A$1002,">="&DATE($B$3,$D$3,1),입출고내역!$A$3:$A$1002,"<="&EOMONTH(DATE($B$3,$D$3,1),0))) | F17: =IF($A17="","",SUMIFS(입출고내역!$G$3:$G$1002,입출고내역!$C$3:$C$1002,$A17,입출고내역!$B$3:$B$1002,"출고",입출고내역!$A$3:$A$1002,">="&DATE($B$3,$D$3,1),입출고내역!$A$3:$A$1002,"<="&EOMONTH(DATE($B$3,$D$3,1),0))) | G17: =IF($A17="","",IF(품목마스터!$F14="",0,품목마스터!$F14)+SUMIFS(입출고내역!$L$3:$L$1002,입출고내역!$C$3:$C$1002,$A17,입출고내역!$A$3:$A$1002,"<="&EOMONTH(DATE($B$3,$D$3,1),0))) | H17: =IF($A17="","",IF(품목마스터!$G14="",0,품목마스터!$G14))
... A305: =IF(품목마스터!$A302="","",품목마스터!$A302) | B305: =IF($A305="","",품목마스터!$B302) | C305: =IF($A305="","",품목마스터!$D302) | D305: =IF($A305="","",IF(품목마스터!$F302="",0,품목마스터!$F302)+SUMIFS(입출고내역!$L$3:$L$1002,입출고내역!$C$3:$C$1002,$A305,입출고내역!$A$3:$A$1002,"<"&DATE($B$3,$D$3,1))) | E305: =IF($A305="","",SUMIFS(입출고내역!$G$3:$G$1002,입출고내역!$C$3:$C$1002,$A305,입출고내역!$B$3:$B$1002,"입고",입출고내역!$A$3:$A$1002,">="&DATE($B$3,$D$3,1),입출고내역!$A$3:$A$1002,"<="&EOMONTH(DATE($B$3,$D$3,1),0))) | F305: =IF($A305="","",SUMIFS(입출고내역!$G$3:$G$1002,입출고내역!$C$3:$C$1002,$A305,입출고내역!$B$3:$B$1002,"출고",입출고내역!$A$3:$A$1002,">="&DATE($B$3,$D$3,1),입출고내역!$A$3:$A$1002,"<="&EOMONTH(DATE($B$3,$D$3,1),0))) | G305: =IF($A305="","",IF(품목마스터!$F302="",0,품목마스터!$F302)+SUMIFS(입출고내역!$L$3:$L$1002,입출고내역!$C$3:$C$1002,$A305,입출고내역!$A$3:$A$1002,"<="&EOMONTH(DATE($B$3,$D$3,1),0))) | H305: =IF($A305="","",IF(품목마스터!$G302="",0,품목마스터!$G302))
B307: 합계 | D307: =SUM(D6:D305) -> 1352 | E307: =SUM(E6:E305) -> 0 | F307: =SUM(F6:F305) -> 0 | G307: =SUM(G6:G305) -> 1352 | H307: =SUM(H6:H305) -> 314
A309: ※ 월말재고가 안전재고보다 적으면 빨간 배경으로 표시됩니다.
