Workbook

Sheet 사용안내
B2: 소모품 소진속도 · 주문량 산출
B4: 핵심 | C4: 쓴 기록만 넣으면 하루 평균 얼마나 쓰는지, 며칠 뒤 떨어지는지, 몇 개 주문해야 하는지가 나옵니다.
B5: 입력 규칙 | C5: 파란색 글씨 칸만 입력하세요. 검은색은 자동 계산입니다.
B6: ① 품목마스터 | C6: 품번·품명·현재고·발주 후 도착까지 걸리는 날(리드타임)을 등록합니다.
C7: 최소발주량과 입수량(한 박스에 몇 개)을 넣으면 주문 단위에 맞춰 계산해줍니다.
B8: ② 사용내역 | C8: 쓸 때마다 한 줄. 날짜·품번·사용량만 넣으면 됩니다.
B9: ③ 소진분석 | C9: 하루 평균 사용량, 남은 날짜, 발주해야 할 날짜, 권장 주문량이 나옵니다.
B10: ④ 발주목록 | C10: 지금 주문해야 하는 것만 모아서 보여줍니다. 이대로 발주하면 됩니다.
B11: ⑤ 품목별 사용추이 | C11: 품목 하나를 골라 월별 사용량을 봅니다.
B12: 하루 평균 계산 | C12: 분석기간 동안의 총 사용량 ÷ 분석기간 일수
B13: 권장 주문량 | C13: (리드타임 + 안전일수) × 하루 평균 − 현재고. 입수량 단위로 올림합니다.
B15: 설정 | C15: 값을 바꾸면 모든 계산에 반영됩니다
B16: 분석 기간(일) | C16: 90
B17: 안전 재고일수 | C17: 14
B19: ※ 분석 기간은 최근 며칠의 사용량을 볼지입니다. 계절을 타는 품목은 길게 잡으세요.
B20: ※ 안전 재고일수는 예상보다 많이 쓸 때를 대비한 여유분입니다.

Sheet 품목마스터
A1: 품목마스터
A2: 품번 | B2: 품명 | C2: 규격 | D2: 단위 | E2: 현재고 | F2: 리드타임(일) | G2: 최소발주량 | H2: 입수량 | I2: 거래처
A3: M001 | B3: 생리식염수 500ml | C3: 500ml | D3: 병 | E3: 120 | F3: 5 | G3: 50 | H3: 20 | I3: ○○의약품
A4: M002 | B4: 일회용 주사기 10cc | C4: 10cc | D4: 개 | E4: 800 | F4: 7 | G4: 200 | H4: 100 | I4: ○○의약품
A5: M003 | B5: 소독용 알코올 | C5: 1L | D5: 통 | E5: 3 | F5: 3 | G5: 10 | H5: 6 | I5: △△상사
A6: M004 | B6: 라텍스 장갑 M | C6: M | D6: 박스 | E6: 2 | F6: 10 | G6: 5 | H6: 1 | I6: △△상사
A304: ※ 입수량은 한 번에 사는 묶음 단위입니다. 낱개로 사면 1을 넣으세요.

Sheet 사용내역
A1: 사용내역 (쓸 때마다 한 줄)
A2: 사용일 | B2: 품번 | C2: 품명(자동) | D2: 단위(자동) | E2: 사용량 | F2: 사용처/비고
A3: 46205 | B3: M001 | C3: =IF($B3="","",IFERROR(INDEX(품목마스터!$B$3:$B$302,MATCH($B3,품목마스터!$A$3:$A$302,0)),"미등록품번")) -> 생리식염수 500ml | D3: =IF($B3="","",IFERROR(INDEX(품목마스터!$D$3:$D$302,MATCH($B3,품목마스터!$A$3:$A$302,0)),"")) -> 병 | E3: 15 | F3: 처치실
A4: 46208 | B4: M003 | C4: =IF($B4="","",IFERROR(INDEX(품목마스터!$B$3:$B$302,MATCH($B4,품목마스터!$A$3:$A$302,0)),"미등록품번")) -> 소독용 알코올 | D4: =IF($B4="","",IFERROR(INDEX(품목마스터!$D$3:$D$302,MATCH($B4,품목마스터!$A$3:$A$302,0)),"")) -> 통 | E4: 12 | F4: 처치실
A5: 46211 | B5: M004 | C5: =IF($B5="","",IFERROR(INDEX(품목마스터!$B$3:$B$302,MATCH($B5,품목마스터!$A$3:$A$302,0)),"미등록품번")) -> 라텍스 장갑 M | D5: =IF($B5="","",IFERROR(INDEX(품목마스터!$D$3:$D$302,MATCH($B5,품목마스터!$A$3:$A$302,0)),"")) -> 박스 | E5: 4 | F5: 진료실
A6: 46221 | B6: M003 | C6: =IF($B6="","",IFERROR(INDEX(품목마스터!$B$3:$B$302,MATCH($B6,품목마스터!$A$3:$A$302,0)),"미등록품번")) -> 소독용 알코올 | D6: =IF($B6="","",IFERROR(INDEX(품목마스터!$D$3:$D$302,MATCH($B6,품목마스터!$A$3:$A$302,0)),"")) -> 통 | E6: 14 | F6: 처치실
A7: 46223 | B7: M001 | C7: =IF($B7="","",IFERROR(INDEX(품목마스터!$B$3:$B$302,MATCH($B7,품목마스터!$A$3:$A$302,0)),"미등록품번")) -> 생리식염수 500ml | D7: =IF($B7="","",IFERROR(INDEX(품목마스터!$D$3:$D$302,MATCH($B7,품목마스터!$A$3:$A$302,0)),"")) -> 병 | E7: 12 | F7: 처치실
A8: 46225 | B8: M004 | C8: =IF($B8="","",IFERROR(INDEX(품목마스터!$B$3:$B$302,MATCH($B8,품목마스터!$A$3:$A$302,0)),"미등록품번")) -> 라텍스 장갑 M | D8: =IF($B8="","",IFERROR(INDEX(품목마스터!$D$3:$D$302,MATCH($B8,품목마스터!$A$3:$A$302,0)),"")) -> 박스 | E8: 5 | F8: 진료실
A9: 46235 | B9: M002 | C9: =IF($B9="","",IFERROR(INDEX(품목마스터!$B$3:$B$302,MATCH($B9,품목마스터!$A$3:$A$302,0)),"미등록품번")) -> 일회용 주사기 10cc | D9: =IF($B9="","",IFERROR(INDEX(품목마스터!$D$3:$D$302,MATCH($B9,품목마스터!$A$3:$A$302,0)),"")) -> 개 | E9: 120 | F9: 처치실
A10: 46236 | B10: M003 | C10: =IF($B10="","",IFERROR(INDEX(품목마스터!$B$3:$B$302,MATCH($B10,품목마스터!$A$3:$A$302,0)),"미등록품번")) -> 소독용 알코올 | D10: =IF($B10="","",IFERROR(INDEX(품목마스터!$D$3:$D$302,MATCH($B10,품목마스터!$A$3:$A$302,0)),"")) -> 통 | E10: 13 | F10: 처치실
A11: 46239 | B11: M001 | C11: =IF($B11="","",IFERROR(INDEX(품목마스터!$B$3:$B$302,MATCH($B11,품목마스터!$A$3:$A$302,0)),"미등록품번")) -> 생리식염수 500ml | D11: =IF($B11="","",IFERROR(INDEX(품목마스터!$D$3:$D$302,MATCH($B11,품목마스터!$A$3:$A$302,0)),"")) -> 병 | E11: 18 | F11: 처치실
A12: 46239 | B12: M004 | C12: =IF($B12="","",IFERROR(INDEX(품목마스터!$B$3:$B$302,MATCH($B12,품목마스터!$A$3:$A$302,0)),"미등록품번")) -> 라텍스 장갑 M | D12: =IF($B12="","",IFERROR(INDEX(품목마스터!$D$3:$D$302,MATCH($B12,품목마스터!$A$3:$A$302,0)),"")) -> 박스 | E12: 4 | F12: 진료실
A13: 46251 | B13: M003 | C13: =IF($B13="","",IFERROR(INDEX(품목마스터!$B$3:$B$302,MATCH($B13,품목마스터!$A$3:$A$302,0)),"미등록품번")) -> 소독용 알코올 | D13: =IF($B13="","",IFERROR(INDEX(품목마스터!$D$3:$D$302,MATCH($B13,품목마스터!$A$3:$A$302,0)),"")) -> 통 | E13: 15 | F13: 처치실
A14: 46252 | B14: M002 | C14: =IF($B14="","",IFERROR(INDEX(품목마스터!$B$3:$B$302,MATCH($B14,품목마스터!$A$3:$A$302,0)),"미등록품번")) -> 일회용 주사기 10cc | D14: =IF($B14="","",IFERROR(INDEX(품목마스터!$D$3:$D$302,MATCH($B14,품목마스터!$A$3:$A$302,0)),"")) -> 개 | E14: 150 | F14: 처치실
... A22: 46275 | B22: M003 | C22: =IF($B22="","",IFERROR(INDEX(품목마스터!$B$3:$B$302,MATCH($B22,품목마스터!$A$3:$A$302,0)),"미등록품번")) -> 소독용 알코올 | D22: =IF($B22="","",IFERROR(INDEX(품목마스터!$D$3:$D$302,MATCH($B22,품목마스터!$A$3:$A$302,0)),"")) -> 통 | E22: 14 | F22: 처치실
C23: =IF($B23="","",IFERROR(INDEX(품목마스터!$B$3:$B$302,MATCH($B23,품목마스터!$A$3:$A$302,0)),"미등록품번")) | D23: =IF($B23="","",IFERROR(INDEX(품목마스터!$D$3:$D$302,MATCH($B23,품목마스터!$A$3:$A$302,0)),""))
C24: =IF($B24="","",IFERROR(INDEX(품목마스터!$B$3:$B$302,MATCH($B24,품목마스터!$A$3:$A$302,0)),"미등록품번")) | D24: =IF($B24="","",IFERROR(INDEX(품목마스터!$D$3:$D$302,MATCH($B24,품목마스터!$A$3:$A$302,0)),""))
C25: =IF($B25="","",IFERROR(INDEX(품목마스터!$B$3:$B$302,MATCH($B25,품목마스터!$A$3:$A$302,0)),"미등록품번")) | D25: =IF($B25="","",IFERROR(INDEX(품목마스터!$D$3:$D$302,MATCH($B25,품목마스터!$A$3:$A$302,0)),""))
C26: =IF($B26="","",IFERROR(INDEX(품목마스터!$B$3:$B$302,MATCH($B26,품목마스터!$A$3:$A$302,0)),"미등록품번")) | D26: =IF($B26="","",IFERROR(INDEX(품목마스터!$D$3:$D$302,MATCH($B26,품목마스터!$A$3:$A$302,0)),""))
C27: =IF($B27="","",IFERROR(INDEX(품목마스터!$B$3:$B$302,MATCH($B27,품목마스터!$A$3:$A$302,0)),"미등록품번")) | D27: =IF($B27="","",IFERROR(INDEX(품목마스터!$D$3:$D$302,MATCH($B27,품목마스터!$A$3:$A$302,0)),""))
C28: =IF($B28="","",IFERROR(INDEX(품목마스터!$B$3:$B$302,MATCH($B28,품목마스터!$A$3:$A$302,0)),"미등록품번")) | D28: =IF($B28="","",IFERROR(INDEX(품목마스터!$D$3:$D$302,MATCH($B28,품목마스터!$A$3:$A$302,0)),""))
C29: =IF($B29="","",IFERROR(INDEX(품목마스터!$B$3:$B$302,MATCH($B29,품목마스터!$A$3:$A$302,0)),"미등록품번")) | D29: =IF($B29="","",IFERROR(INDEX(품목마스터!$D$3:$D$302,MATCH($B29,품목마스터!$A$3:$A$302,0)),""))
C30: =IF($B30="","",IFERROR(INDEX(품목마스터!$B$3:$B$302,MATCH($B30,품목마스터!$A$3:$A$302,0)),"미등록품번")) | D30: =IF($B30="","",IFERROR(INDEX(품목마스터!$D$3:$D$302,MATCH($B30,품목마스터!$A$3:$A$302,0)),""))
C31: =IF($B31="","",IFERROR(INDEX(품목마스터!$B$3:$B$302,MATCH($B31,품목마스터!$A$3:$A$302,0)),"미등록품번")) | D31: =IF($B31="","",IFERROR(INDEX(품목마스터!$D$3:$D$302,MATCH($B31,품목마스터!$A$3:$A$302,0)),""))
C32: =IF($B32="","",IFERROR(INDEX(품목마스터!$B$3:$B$302,MATCH($B32,품목마스터!$A$3:$A$302,0)),"미등록품번")) | D32: =IF($B32="","",IFERROR(INDEX(품목마스터!$D$3:$D$302,MATCH($B32,품목마스터!$A$3:$A$302,0)),""))
C33: =IF($B33="","",IFERROR(INDEX(품목마스터!$B$3:$B$302,MATCH($B33,품목마스터!$A$3:$A$302,0)),"미등록품번")) | D33: =IF($B33="","",IFERROR(INDEX(품목마스터!$D$3:$D$302,MATCH($B33,품목마스터!$A$3:$A$302,0)),""))
C34: =IF($B34="","",IFERROR(INDEX(품목마스터!$B$3:$B$302,MATCH($B34,품목마스터!$A$3:$A$302,0)),"미등록품번")) | D34: =IF($B34="","",IFERROR(INDEX(품목마스터!$D$3:$D$302,MATCH($B34,품목마스터!$A$3:$A$302,0)),""))
... C3002: =IF($B3002="","",IFERROR(INDEX(품목마스터!$B$3:$B$302,MATCH($B3002,품목마스터!$A$3:$A$302,0)),"미등록품번")) | D3002: =IF($B3002="","",IFERROR(INDEX(품목마스터!$D$3:$D$302,MATCH($B3002,품목마스터!$A$3:$A$302,0)),""))

Sheet 소진분석
A1: 소진분석 (전부 자동)
A3: 기준일 | B3: =TODAY() -> 46279 | D3: 분석 기간 | E3: =사용안내!$C$16&"일" -> 90일 | G3: 발주 필요 품목 | H3: =SUMPRODUCT(($A$6:$A$305<>"")*($L$6:$L$305="발주")) -> 2
A5: 품번 | B5: 품명 | C5: 단위 | D5: 현재고 | E5: 기간 사용량 | F5: 하루 평균 | G5: 남은 일수 | H5: 소진 예상일 | I5: 리드타임 | J5: 발주 기한 | K5: 권장 주문량 | L5: 판정
A6: =IF(품목마스터!$A3="","",품목마스터!$A3) -> M001 | B6: =IF($A6="","",품목마스터!$B3) -> 생리식염수 500ml | C6: =IF($A6="","",품목마스터!$D3) -> 병 | D6: =IF($A6="","",IF(품목마스터!$E3="",0,품목마스터!$E3)) -> 120 | E6: =IF($A6="","",SUMIFS(사용내역!$E$3:$E$3002,사용내역!$B$3:$B$3002,$A6,사용내역!$A$3:$A$3002,">"&($B$3-사용안내!$C$16),사용내역!$A$3:$A$3002,"<="&$B$3)) -> 75 | F6: =IF($A6="","",IF(사용안내!$C$16=0,0,ROUND($E6/사용안내!$C$16,3))) -> 0.833 | G6: =IF($A6="","",IF($F6<=0,"사용기록없음",ROUND($D6/$F6,0))) -> 144 | H6: =IF(OR($A6="",$F6<=0),"",$B$3+$G6) -> 46423 | I6: =IF($A6="","",IF(품목마스터!$F3="",0,품목마스터!$F3)) -> 5 | J6: =IF(OR($A6="",$F6<=0),"",$H6-$I6) -> 46418 | K6: =IF(OR($A6="",$F6<=0),0,MAX(0,CEILING(MAX(0,($I6+사용안내!$C$17)*$F6-$D6),MAX(1,IF(품목마스터!$H3="",1,품목마스터!$H3))))) -> 0 | L6: =IF($A6="","",IF($F6<=0,"-",IF($J6<=$B$3,"발주",IF($J6<=$B$3+7,"임박","정상")))) -> 정상
A7: =IF(품목마스터!$A4="","",품목마스터!$A4) -> M002 | B7: =IF($A7="","",품목마스터!$B4) -> 일회용 주사기 10cc | C7: =IF($A7="","",품목마스터!$D4) -> 개 | D7: =IF($A7="","",IF(품목마스터!$E4="",0,품목마스터!$E4)) -> 800 | E7: =IF($A7="","",SUMIFS(사용내역!$E$3:$E$3002,사용내역!$B$3:$B$3002,$A7,사용내역!$A$3:$A$3002,">"&($B$3-사용안내!$C$16),사용내역!$A$3:$A$3002,"<="&$B$3)) -> 400 | F7: =IF($A7="","",IF(사용안내!$C$16=0,0,ROUND($E7/사용안내!$C$16,3))) -> 4.444 | G7: =IF($A7="","",IF($F7<=0,"사용기록없음",ROUND($D7/$F7,0))) -> 180 | H7: =IF(OR($A7="",$F7<=0),"",$B$3+$G7) -> 46459 | I7: =IF($A7="","",IF(품목마스터!$F4="",0,품목마스터!$F4)) -> 7 | J7: =IF(OR($A7="",$F7<=0),"",$H7-$I7) -> 46452 | K7: =IF(OR($A7="",$F7<=0),0,MAX(0,CEILING(MAX(0,($I7+사용안내!$C$17)*$F7-$D7),MAX(1,IF(품목마스터!$H4="",1,품목마스터!$H4))))) -> 0 | L7: =IF($A7="","",IF($F7<=0,"-",IF($J7<=$B$3,"발주",IF($J7<=$B$3+7,"임박","정상")))) -> 정상
A8: =IF(품목마스터!$A5="","",품목마스터!$A5) -> M003 | B8: =IF($A8="","",품목마스터!$B5) -> 소독용 알코올 | C8: =IF($A8="","",품목마스터!$D5) -> 통 | D8: =IF($A8="","",IF(품목마스터!$E5="",0,품목마스터!$E5)) -> 3 | E8: =IF($A8="","",SUMIFS(사용내역!$E$3:$E$3002,사용내역!$B$3:$B$3002,$A8,사용내역!$A$3:$A$3002,">"&($B$3-사용안내!$C$16),사용내역!$A$3:$A$3002,"<="&$B$3)) -> 80 | F8: =IF($A8="","",IF(사용안내!$C$16=0,0,ROUND($E8/사용안내!$C$16,3))) -> 0.889 | G8: =IF($A8="","",IF($F8<=0,"사용기록없음",ROUND($D8/$F8,0))) -> 3 | H8: =IF(OR($A8="",$F8<=0),"",$B$3+$G8) -> 46282 | I8: =IF($A8="","",IF(품목마스터!$F5="",0,품목마스터!$F5)) -> 3 | J8: =IF(OR($A8="",$F8<=0),"",$H8-$I8) -> 46279 | K8: =IF(OR($A8="",$F8<=0),0,MAX(0,CEILING(MAX(0,($I8+사용안내!$C$17)*$F8-$D8),MAX(1,IF(품목마스터!$H5="",1,품목마스터!$H5))))) -> 18 | L8: =IF($A8="","",IF($F8<=0,"-",IF($J8<=$B$3,"발주",IF($J8<=$B$3+7,"임박","정상")))) -> 발주
A9: =IF(품목마스터!$A6="","",품목마스터!$A6) -> M004 | B9: =IF($A9="","",품목마스터!$B6) -> 라텍스 장갑 M | C9: =IF($A9="","",품목마스터!$D6) -> 박스 | D9: =IF($A9="","",IF(품목마스터!$E6="",0,품목마스터!$E6)) -> 2 | E9: =IF($A9="","",SUMIFS(사용내역!$E$3:$E$3002,사용내역!$B$3:$B$3002,$A9,사용내역!$A$3:$A$3002,">"&($B$3-사용안내!$C$16),사용내역!$A$3:$A$3002,"<="&$B$3)) -> 25 | F9: =IF($A9="","",IF(사용안내!$C$16=0,0,ROUND($E9/사용안내!$C$16,3))) -> 0.278 | G9: =IF($A9="","",IF($F9<=0,"사용기록없음",ROUND($D9/$F9,0))) -> 7 | H9: =IF(OR($A9="",$F9<=0),"",$B$3+$G9) -> 46286 | I9: =IF($A9="","",IF(품목마스터!$F6="",0,품목마스터!$F6)) -> 10 | J9: =IF(OR($A9="",$F9<=0),"",$H9-$I9) -> 46276 | K9: =IF(OR($A9="",$F9<=0),0,MAX(0,CEILING(MAX(0,($I9+사용안내!$C$17)*$F9-$D9),MAX(1,IF(품목마스터!$H6="",1,품목마스터!$H6))))) -> 5 | L9: =IF($A9="","",IF($F9<=0,"-",IF($J9<=$B$3,"발주",IF($J9<=$B$3+7,"임박","정상")))) -> 발주
A10: =IF(품목마스터!$A7="","",품목마스터!$A7) | B10: =IF($A10="","",품목마스터!$B7) | C10: =IF($A10="","",품목마스터!$D7) | D10: =IF($A10="","",IF(품목마스터!$E7="",0,품목마스터!$E7)) | E10: =IF($A10="","",SUMIFS(사용내역!$E$3:$E$3002,사용내역!$B$3:$B$3002,$A10,사용내역!$A$3:$A$3002,">"&($B$3-사용안내!$C$16),사용내역!$A$3:$A$3002,"<="&$B$3)) | F10: =IF($A10="","",IF(사용안내!$C$16=0,0,ROUND($E10/사용안내!$C$16,3))) | G10: =IF($A10="","",IF($F10<=0,"사용기록없음",ROUND($D10/$F10,0))) | H10: =IF(OR($A10="",$F10<=0),"",$B$3+$G10) | I10: =IF($A10="","",IF(품목마스터!$F7="",0,품목마스터!$F7)) | J10: =IF(OR($A10="",$F10<=0),"",$H10-$I10) | K10: =IF(OR($A10="",$F10<=0),0,MAX(0,CEILING(MAX(0,($I10+사용안내!$C$17)*$F10-$D10),MAX(1,IF(품목마스터!$H7="",1,품목마스터!$H7))))) -> 0 | L10: =IF($A10="","",IF($F10<=0,"-",IF($J10<=$B$3,"발주",IF($J10<=$B$3+7,"임박","정상"))))
A11: =IF(품목마스터!$A8="","",품목마스터!$A8) | B11: =IF($A11="","",품목마스터!$B8) | C11: =IF($A11="","",품목마스터!$D8) | D11: =IF($A11="","",IF(품목마스터!$E8="",0,품목마스터!$E8)) | E11: =IF($A11="","",SUMIFS(사용내역!$E$3:$E$3002,사용내역!$B$3:$B$3002,$A11,사용내역!$A$3:$A$3002,">"&($B$3-사용안내!$C$16),사용내역!$A$3:$A$3002,"<="&$B$3)) | F11: =IF($A11="","",IF(사용안내!$C$16=0,0,ROUND($E11/사용안내!$C$16,3))) | G11: =IF($A11="","",IF($F11<=0,"사용기록없음",ROUND($D11/$F11,0))) | H11: =IF(OR($A11="",$F11<=0),"",$B$3+$G11) | I11: =IF($A11="","",IF(품목마스터!$F8="",0,품목마스터!$F8)) | J11: =IF(OR($A11="",$F11<=0),"",$H11-$I11) | K11: =IF(OR($A11="",$F11<=0),0,MAX(0,CEILING(MAX(0,($I11+사용안내!$C$17)*$F11-$D11),MAX(1,IF(품목마스터!$H8="",1,품목마스터!$H8))))) -> 0 | L11: =IF($A11="","",IF($F11<=0,"-",IF($J11<=$B$3,"발주",IF($J11<=$B$3+7,"임박","정상"))))
A12: =IF(품목마스터!$A9="","",품목마스터!$A9) | B12: =IF($A12="","",품목마스터!$B9) | C12: =IF($A12="","",품목마스터!$D9) | D12: =IF($A12="","",IF(품목마스터!$E9="",0,품목마스터!$E9)) | E12: =IF($A12="","",SUMIFS(사용내역!$E$3:$E$3002,사용내역!$B$3:$B$3002,$A12,사용내역!$A$3:$A$3002,">"&($B$3-사용안내!$C$16),사용내역!$A$3:$A$3002,"<="&$B$3)) | F12: =IF($A12="","",IF(사용안내!$C$16=0,0,ROUND($E12/사용안내!$C$16,3))) | G12: =IF($A12="","",IF($F12<=0,"사용기록없음",ROUND($D12/$F12,0))) | H12: =IF(OR($A12="",$F12<=0),"",$B$3+$G12) | I12: =IF($A12="","",IF(품목마스터!$F9="",0,품목마스터!$F9)) | J12: =IF(OR($A12="",$F12<=0),"",$H12-$I12) | K12: =IF(OR($A12="",$F12<=0),0,MAX(0,CEILING(MAX(0,($I12+사용안내!$C$17)*$F12-$D12),MAX(1,IF(품목마스터!$H9="",1,품목마스터!$H9))))) -> 0 | L12: =IF($A12="","",IF($F12<=0,"-",IF($J12<=$B$3,"발주",IF($J12<=$B$3+7,"임박","정상"))))
A13: =IF(품목마스터!$A10="","",품목마스터!$A10) | B13: =IF($A13="","",품목마스터!$B10) | C13: =IF($A13="","",품목마스터!$D10) | D13: =IF($A13="","",IF(품목마스터!$E10="",0,품목마스터!$E10)) | E13: =IF($A13="","",SUMIFS(사용내역!$E$3:$E$3002,사용내역!$B$3:$B$3002,$A13,사용내역!$A$3:$A$3002,">"&($B$3-사용안내!$C$16),사용내역!$A$3:$A$3002,"<="&$B$3)) | F13: =IF($A13="","",IF(사용안내!$C$16=0,0,ROUND($E13/사용안내!$C$16,3))) | G13: =IF($A13="","",IF($F13<=0,"사용기록없음",ROUND($D13/$F13,0))) | H13: =IF(OR($A13="",$F13<=0),"",$B$3+$G13) | I13: =IF($A13="","",IF(품목마스터!$F10="",0,품목마스터!$F10)) | J13: =IF(OR($A13="",$F13<=0),"",$H13-$I13) | K13: =IF(OR($A13="",$F13<=0),0,MAX(0,CEILING(MAX(0,($I13+사용안내!$C$17)*$F13-$D13),MAX(1,IF(품목마스터!$H10="",1,품목마스터!$H10))))) -> 0 | L13: =IF($A13="","",IF($F13<=0,"-",IF($J13<=$B$3,"발주",IF($J13<=$B$3+7,"임박","정상"))))
A14: =IF(품목마스터!$A11="","",품목마스터!$A11) | B14: =IF($A14="","",품목마스터!$B11) | C14: =IF($A14="","",품목마스터!$D11) | D14: =IF($A14="","",IF(품목마스터!$E11="",0,품목마스터!$E11)) | E14: =IF($A14="","",SUMIFS(사용내역!$E$3:$E$3002,사용내역!$B$3:$B$3002,$A14,사용내역!$A$3:$A$3002,">"&($B$3-사용안내!$C$16),사용내역!$A$3:$A$3002,"<="&$B$3)) | F14: =IF($A14="","",IF(사용안내!$C$16=0,0,ROUND($E14/사용안내!$C$16,3))) | G14: =IF($A14="","",IF($F14<=0,"사용기록없음",ROUND($D14/$F14,0))) | H14: =IF(OR($A14="",$F14<=0),"",$B$3+$G14) | I14: =IF($A14="","",IF(품목마스터!$F11="",0,품목마스터!$F11)) | J14: =IF(OR($A14="",$F14<=0),"",$H14-$I14) | K14: =IF(OR($A14="",$F14<=0),0,MAX(0,CEILING(MAX(0,($I14+사용안내!$C$17)*$F14-$D14),MAX(1,IF(품목마스터!$H11="",1,품목마스터!$H11))))) -> 0 | L14: =IF($A14="","",IF($F14<=0,"-",IF($J14<=$B$3,"발주",IF($J14<=$B$3+7,"임박","정상"))))
A15: =IF(품목마스터!$A12="","",품목마스터!$A12) | B15: =IF($A15="","",품목마스터!$B12) | C15: =IF($A15="","",품목마스터!$D12) | D15: =IF($A15="","",IF(품목마스터!$E12="",0,품목마스터!$E12)) | E15: =IF($A15="","",SUMIFS(사용내역!$E$3:$E$3002,사용내역!$B$3:$B$3002,$A15,사용내역!$A$3:$A$3002,">"&($B$3-사용안내!$C$16),사용내역!$A$3:$A$3002,"<="&$B$3)) | F15: =IF($A15="","",IF(사용안내!$C$16=0,0,ROUND($E15/사용안내!$C$16,3))) | G15: =IF($A15="","",IF($F15<=0,"사용기록없음",ROUND($D15/$F15,0))) | H15: =IF(OR($A15="",$F15<=0),"",$B$3+$G15) | I15: =IF($A15="","",IF(품목마스터!$F12="",0,품목마스터!$F12)) | J15: =IF(OR($A15="",$F15<=0),"",$H15-$I15) | K15: =IF(OR($A15="",$F15<=0),0,MAX(0,CEILING(MAX(0,($I15+사용안내!$C$17)*$F15-$D15),MAX(1,IF(품목마스터!$H12="",1,품목마스터!$H12))))) -> 0 | L15: =IF($A15="","",IF($F15<=0,"-",IF($J15<=$B$3,"발주",IF($J15<=$B$3+7,"임박","정상"))))
A16: =IF(품목마스터!$A13="","",품목마스터!$A13) | B16: =IF($A16="","",품목마스터!$B13) | C16: =IF($A16="","",품목마스터!$D13) | D16: =IF($A16="","",IF(품목마스터!$E13="",0,품목마스터!$E13)) | E16: =IF($A16="","",SUMIFS(사용내역!$E$3:$E$3002,사용내역!$B$3:$B$3002,$A16,사용내역!$A$3:$A$3002,">"&($B$3-사용안내!$C$16),사용내역!$A$3:$A$3002,"<="&$B$3)) | F16: =IF($A16="","",IF(사용안내!$C$16=0,0,ROUND($E16/사용안내!$C$16,3))) | G16: =IF($A16="","",IF($F16<=0,"사용기록없음",ROUND($D16/$F16,0))) | H16: =IF(OR($A16="",$F16<=0),"",$B$3+$G16) | I16: =IF($A16="","",IF(품목마스터!$F13="",0,품목마스터!$F13)) | J16: =IF(OR($A16="",$F16<=0),"",$H16-$I16) | K16: =IF(OR($A16="",$F16<=0),0,MAX(0,CEILING(MAX(0,($I16+사용안내!$C$17)*$F16-$D16),MAX(1,IF(품목마스터!$H13="",1,품목마스터!$H13))))) -> 0 | L16: =IF($A16="","",IF($F16<=0,"-",IF($J16<=$B$3,"발주",IF($J16<=$B$3+7,"임박","정상"))))
A17: =IF(품목마스터!$A14="","",품목마스터!$A14) | B17: =IF($A17="","",품목마스터!$B14) | C17: =IF($A17="","",품목마스터!$D14) | D17: =IF($A17="","",IF(품목마스터!$E14="",0,품목마스터!$E14)) | E17: =IF($A17="","",SUMIFS(사용내역!$E$3:$E$3002,사용내역!$B$3:$B$3002,$A17,사용내역!$A$3:$A$3002,">"&($B$3-사용안내!$C$16),사용내역!$A$3:$A$3002,"<="&$B$3)) | F17: =IF($A17="","",IF(사용안내!$C$16=0,0,ROUND($E17/사용안내!$C$16,3))) | G17: =IF($A17="","",IF($F17<=0,"사용기록없음",ROUND($D17/$F17,0))) | H17: =IF(OR($A17="",$F17<=0),"",$B$3+$G17) | I17: =IF($A17="","",IF(품목마스터!$F14="",0,품목마스터!$F14)) | J17: =IF(OR($A17="",$F17<=0),"",$H17-$I17) | K17: =IF(OR($A17="",$F17<=0),0,MAX(0,CEILING(MAX(0,($I17+사용안내!$C$17)*$F17-$D17),MAX(1,IF(품목마스터!$H14="",1,품목마스터!$H14))))) -> 0 | L17: =IF($A17="","",IF($F17<=0,"-",IF($J17<=$B$3,"발주",IF($J17<=$B$3+7,"임박","정상"))))
... A305: =IF(품목마스터!$A302="","",품목마스터!$A302) | B305: =IF($A305="","",품목마스터!$B302) | C305: =IF($A305="","",품목마스터!$D302) | D305: =IF($A305="","",IF(품목마스터!$E302="",0,품목마스터!$E302)) | E305: =IF($A305="","",SUMIFS(사용내역!$E$3:$E$3002,사용내역!$B$3:$B$3002,$A305,사용내역!$A$3:$A$3002,">"&($B$3-사용안내!$C$16),사용내역!$A$3:$A$3002,"<="&$B$3)) | F305: =IF($A305="","",IF(사용안내!$C$16=0,0,ROUND($E305/사용안내!$C$16,3))) | G305: =IF($A305="","",IF($F305<=0,"사용기록없음",ROUND($D305/$F305,0))) | H305: =IF(OR($A305="",$F305<=0),"",$B$3+$G305) | I305: =IF($A305="","",IF(품목마스터!$F302="",0,품목마스터!$F302)) | J305: =IF(OR($A305="",$F305<=0),"",$H305-$I305) | K305: =IF(OR($A305="",$F305<=0),0,MAX(0,CEILING(MAX(0,($I305+사용안내!$C$17)*$F305-$D305),MAX(1,IF(품목마스터!$H302="",1,품목마스터!$H302))))) -> 0 | L305: =IF($A305="","",IF($F305<=0,"-",IF($J305<=$B$3,"발주",IF($J305<=$B$3+7,"임박","정상"))))
A307: ※ 발주 기한 = 소진 예상일 − 리드타임. 이 날짜가 지났으면 '발주'로 표시됩니다.
A308: ※ 권장 주문량은 입수량 단위로 올림한 값입니다. 사용 기록이 없으면 0입니다.

Sheet 발주목록
A1: 발주목록 (지금 주문해야 하는 것만)
A3: 포함 기준 | B3: 발주 + 임박 | D3: 해당 품목 | E3: =COUNTIF($J$6:$J$305,TRUE()) -> 2
A5: 순번 | B5: 품번 | C5: 품명 | D5: 단위 | E5: 현재고 | F5: 권장 주문량 | G5: 거래처 | H5: 발주 기한 | J5: 대상(자동) | K5: 순번(자동) | L5: 키(자동)
A6: =IF($B6="","",1) -> 1 | B6: =IFERROR(INDEX(소진분석!$A$6:$A$305,MATCH("R"&1,발주목록!$L$6:$L$305,0)),"") -> M003 | C6: =IF($B6="","",IFERROR(INDEX(소진분석!$B$6:$B$305,MATCH("R"&1,발주목록!$L$6:$L$305,0)),"")) -> 소독용 알코올 | D6: =IF($B6="","",IFERROR(INDEX(소진분석!$C$6:$C$305,MATCH("R"&1,발주목록!$L$6:$L$305,0)),"")) -> 통 | E6: =IF($B6="","",IFERROR(INDEX(소진분석!$D$6:$D$305,MATCH("R"&1,발주목록!$L$6:$L$305,0)),"")) -> 3 | F6: =IF($B6="","",IFERROR(INDEX(소진분석!$K$6:$K$305,MATCH("R"&1,발주목록!$L$6:$L$305,0)),"")) -> 18 | G6: =IF($B6="","",IFERROR(INDEX(품목마스터!$I$3:$I$302,MATCH($B6,품목마스터!$A$3:$A$302,0)),"")) -> △△상사 | H6: =IF($B6="","",IFERROR(INDEX(소진분석!$J$6:$J$305,MATCH("R"&1,발주목록!$L$6:$L$305,0)),"")) -> 46279 | J6: =IF(소진분석!$A6="",FALSE(),IF($B$3="발주만",소진분석!$L6="발주",OR(소진분석!$L6="발주",소진분석!$L6="임박"))) -> FALSE | K6: =IF($J6=FALSE(),"",COUNTIF($J$6:$J6,TRUE())) | L6: =IF($K6="","","R"&$K6)
A7: =IF($B7="","",2) -> 2 | B7: =IFERROR(INDEX(소진분석!$A$6:$A$305,MATCH("R"&2,발주목록!$L$6:$L$305,0)),"") -> M004 | C7: =IF($B7="","",IFERROR(INDEX(소진분석!$B$6:$B$305,MATCH("R"&2,발주목록!$L$6:$L$305,0)),"")) -> 라텍스 장갑 M | D7: =IF($B7="","",IFERROR(INDEX(소진분석!$C$6:$C$305,MATCH("R"&2,발주목록!$L$6:$L$305,0)),"")) -> 박스 | E7: =IF($B7="","",IFERROR(INDEX(소진분석!$D$6:$D$305,MATCH("R"&2,발주목록!$L$6:$L$305,0)),"")) -> 2 | F7: =IF($B7="","",IFERROR(INDEX(소진분석!$K$6:$K$305,MATCH("R"&2,발주목록!$L$6:$L$305,0)),"")) -> 5 | G7: =IF($B7="","",IFERROR(INDEX(품목마스터!$I$3:$I$302,MATCH($B7,품목마스터!$A$3:$A$302,0)),"")) -> △△상사 | H7: =IF($B7="","",IFERROR(INDEX(소진분석!$J$6:$J$305,MATCH("R"&2,발주목록!$L$6:$L$305,0)),"")) -> 46276 | J7: =IF(소진분석!$A7="",FALSE(),IF($B$3="발주만",소진분석!$L7="발주",OR(소진분석!$L7="발주",소진분석!$L7="임박"))) -> FALSE | K7: =IF($J7=FALSE(),"",COUNTIF($J$6:$J7,TRUE())) | L7: =IF($K7="","","R"&$K7)
A8: =IF($B8="","",3) | B8: =IFERROR(INDEX(소진분석!$A$6:$A$305,MATCH("R"&3,발주목록!$L$6:$L$305,0)),"") | C8: =IF($B8="","",IFERROR(INDEX(소진분석!$B$6:$B$305,MATCH("R"&3,발주목록!$L$6:$L$305,0)),"")) | D8: =IF($B8="","",IFERROR(INDEX(소진분석!$C$6:$C$305,MATCH("R"&3,발주목록!$L$6:$L$305,0)),"")) | E8: =IF($B8="","",IFERROR(INDEX(소진분석!$D$6:$D$305,MATCH("R"&3,발주목록!$L$6:$L$305,0)),"")) | F8: =IF($B8="","",IFERROR(INDEX(소진분석!$K$6:$K$305,MATCH("R"&3,발주목록!$L$6:$L$305,0)),"")) | G8: =IF($B8="","",IFERROR(INDEX(품목마스터!$I$3:$I$302,MATCH($B8,품목마스터!$A$3:$A$302,0)),"")) | H8: =IF($B8="","",IFERROR(INDEX(소진분석!$J$6:$J$305,MATCH("R"&3,발주목록!$L$6:$L$305,0)),"")) | J8: =IF(소진분석!$A8="",FALSE(),IF($B$3="발주만",소진분석!$L8="발주",OR(소진분석!$L8="발주",소진분석!$L8="임박"))) -> TRUE | K8: =IF($J8=FALSE(),"",COUNTIF($J$6:$J8,TRUE())) -> 1 | L8: =IF($K8="","","R"&$K8) -> R1
A9: =IF($B9="","",4) | B9: =IFERROR(INDEX(소진분석!$A$6:$A$305,MATCH("R"&4,발주목록!$L$6:$L$305,0)),"") | C9: =IF($B9="","",IFERROR(INDEX(소진분석!$B$6:$B$305,MATCH("R"&4,발주목록!$L$6:$L$305,0)),"")) | D9: =IF($B9="","",IFERROR(INDEX(소진분석!$C$6:$C$305,MATCH("R"&4,발주목록!$L$6:$L$305,0)),"")) | E9: =IF($B9="","",IFERROR(INDEX(소진분석!$D$6:$D$305,MATCH("R"&4,발주목록!$L$6:$L$305,0)),"")) | F9: =IF($B9="","",IFERROR(INDEX(소진분석!$K$6:$K$305,MATCH("R"&4,발주목록!$L$6:$L$305,0)),"")) | G9: =IF($B9="","",IFERROR(INDEX(품목마스터!$I$3:$I$302,MATCH($B9,품목마스터!$A$3:$A$302,0)),"")) | H9: =IF($B9="","",IFERROR(INDEX(소진분석!$J$6:$J$305,MATCH("R"&4,발주목록!$L$6:$L$305,0)),"")) | J9: =IF(소진분석!$A9="",FALSE(),IF($B$3="발주만",소진분석!$L9="발주",OR(소진분석!$L9="발주",소진분석!$L9="임박"))) -> TRUE | K9: =IF($J9=FALSE(),"",COUNTIF($J$6:$J9,TRUE())) -> 2 | L9: =IF($K9="","","R"&$K9) -> R2
A10: =IF($B10="","",5) | B10: =IFERROR(INDEX(소진분석!$A$6:$A$305,MATCH("R"&5,발주목록!$L$6:$L$305,0)),"") | C10: =IF($B10="","",IFERROR(INDEX(소진분석!$B$6:$B$305,MATCH("R"&5,발주목록!$L$6:$L$305,0)),"")) | D10: =IF($B10="","",IFERROR(INDEX(소진분석!$C$6:$C$305,MATCH("R"&5,발주목록!$L$6:$L$305,0)),"")) | E10: =IF($B10="","",IFERROR(INDEX(소진분석!$D$6:$D$305,MATCH("R"&5,발주목록!$L$6:$L$305,0)),"")) | F10: =IF($B10="","",IFERROR(INDEX(소진분석!$K$6:$K$305,MATCH("R"&5,발주목록!$L$6:$L$305,0)),"")) | G10: =IF($B10="","",IFERROR(INDEX(품목마스터!$I$3:$I$302,MATCH($B10,품목마스터!$A$3:$A$302,0)),"")) | H10: =IF($B10="","",IFERROR(INDEX(소진분석!$J$6:$J$305,MATCH("R"&5,발주목록!$L$6:$L$305,0)),"")) | J10: =IF(소진분석!$A10="",FALSE(),IF($B$3="발주만",소진분석!$L10="발주",OR(소진분석!$L10="발주",소진분석!$L10="임박"))) -> FALSE | K10: =IF($J10=FALSE(),"",COUNTIF($J$6:$J10,TRUE())) | L10: =IF($K10="","","R"&$K10)
A11: =IF($B11="","",6) | B11: =IFERROR(INDEX(소진분석!$A$6:$A$305,MATCH("R"&6,발주목록!$L$6:$L$305,0)),"") | C11: =IF($B11="","",IFERROR(INDEX(소진분석!$B$6:$B$305,MATCH("R"&6,발주목록!$L$6:$L$305,0)),"")) | D11: =IF($B11="","",IFERROR(INDEX(소진분석!$C$6:$C$305,MATCH("R"&6,발주목록!$L$6:$L$305,0)),"")) | E11: =IF($B11="","",IFERROR(INDEX(소진분석!$D$6:$D$305,MATCH("R"&6,발주목록!$L$6:$L$305,0)),"")) | F11: =IF($B11="","",IFERROR(INDEX(소진분석!$K$6:$K$305,MATCH("R"&6,발주목록!$L$6:$L$305,0)),"")) | G11: =IF($B11="","",IFERROR(INDEX(품목마스터!$I$3:$I$302,MATCH($B11,품목마스터!$A$3:$A$302,0)),"")) | H11: =IF($B11="","",IFERROR(INDEX(소진분석!$J$6:$J$305,MATCH("R"&6,발주목록!$L$6:$L$305,0)),"")) | J11: =IF(소진분석!$A11="",FALSE(),IF($B$3="발주만",소진분석!$L11="발주",OR(소진분석!$L11="발주",소진분석!$L11="임박"))) -> FALSE | K11: =IF($J11=FALSE(),"",COUNTIF($J$6:$J11,TRUE())) | L11: =IF($K11="","","R"&$K11)
A12: =IF($B12="","",7) | B12: =IFERROR(INDEX(소진분석!$A$6:$A$305,MATCH("R"&7,발주목록!$L$6:$L$305,0)),"") | C12: =IF($B12="","",IFERROR(INDEX(소진분석!$B$6:$B$305,MATCH("R"&7,발주목록!$L$6:$L$305,0)),"")) | D12: =IF($B12="","",IFERROR(INDEX(소진분석!$C$6:$C$305,MATCH("R"&7,발주목록!$L$6:$L$305,0)),"")) | E12: =IF($B12="","",IFERROR(INDEX(소진분석!$D$6:$D$305,MATCH("R"&7,발주목록!$L$6:$L$305,0)),"")) | F12: =IF($B12="","",IFERROR(INDEX(소진분석!$K$6:$K$305,MATCH("R"&7,발주목록!$L$6:$L$305,0)),"")) | G12: =IF($B12="","",IFERROR(INDEX(품목마스터!$I$3:$I$302,MATCH($B12,품목마스터!$A$3:$A$302,0)),"")) | H12: =IF($B12="","",IFERROR(INDEX(소진분석!$J$6:$J$305,MATCH("R"&7,발주목록!$L$6:$L$305,0)),"")) | J12: =IF(소진분석!$A12="",FALSE(),IF($B$3="발주만",소진분석!$L12="발주",OR(소진분석!$L12="발주",소진분석!$L12="임박"))) -> FALSE | K12: =IF($J12=FALSE(),"",COUNTIF($J$6:$J12,TRUE())) | L12: =IF($K12="","","R"&$K12)
A13: =IF($B13="","",8) | B13: =IFERROR(INDEX(소진분석!$A$6:$A$305,MATCH("R"&8,발주목록!$L$6:$L$305,0)),"") | C13: =IF($B13="","",IFERROR(INDEX(소진분석!$B$6:$B$305,MATCH("R"&8,발주목록!$L$6:$L$305,0)),"")) | D13: =IF($B13="","",IFERROR(INDEX(소진분석!$C$6:$C$305,MATCH("R"&8,발주목록!$L$6:$L$305,0)),"")) | E13: =IF($B13="","",IFERROR(INDEX(소진분석!$D$6:$D$305,MATCH("R"&8,발주목록!$L$6:$L$305,0)),"")) | F13: =IF($B13="","",IFERROR(INDEX(소진분석!$K$6:$K$305,MATCH("R"&8,발주목록!$L$6:$L$305,0)),"")) | G13: =IF($B13="","",IFERROR(INDEX(품목마스터!$I$3:$I$302,MATCH($B13,품목마스터!$A$3:$A$302,0)),"")) | H13: =IF($B13="","",IFERROR(INDEX(소진분석!$J$6:$J$305,MATCH("R"&8,발주목록!$L$6:$L$305,0)),"")) | J13: =IF(소진분석!$A13="",FALSE(),IF($B$3="발주만",소진분석!$L13="발주",OR(소진분석!$L13="발주",소진분석!$L13="임박"))) -> FALSE | K13: =IF($J13=FALSE(),"",COUNTIF($J$6:$J13,TRUE())) | L13: =IF($K13="","","R"&$K13)
A14: =IF($B14="","",9) | B14: =IFERROR(INDEX(소진분석!$A$6:$A$305,MATCH("R"&9,발주목록!$L$6:$L$305,0)),"") | C14: =IF($B14="","",IFERROR(INDEX(소진분석!$B$6:$B$305,MATCH("R"&9,발주목록!$L$6:$L$305,0)),"")) | D14: =IF($B14="","",IFERROR(INDEX(소진분석!$C$6:$C$305,MATCH("R"&9,발주목록!$L$6:$L$305,0)),"")) | E14: =IF($B14="","",IFERROR(INDEX(소진분석!$D$6:$D$305,MATCH("R"&9,발주목록!$L$6:$L$305,0)),"")) | F14: =IF($B14="","",IFERROR(INDEX(소진분석!$K$6:$K$305,MATCH("R"&9,발주목록!$L$6:$L$305,0)),"")) | G14: =IF($B14="","",IFERROR(INDEX(품목마스터!$I$3:$I$302,MATCH($B14,품목마스터!$A$3:$A$302,0)),"")) | H14: =IF($B14="","",IFERROR(INDEX(소진분석!$J$6:$J$305,MATCH("R"&9,발주목록!$L$6:$L$305,0)),"")) | J14: =IF(소진분석!$A14="",FALSE(),IF($B$3="발주만",소진분석!$L14="발주",OR(소진분석!$L14="발주",소진분석!$L14="임박"))) -> FALSE | K14: =IF($J14=FALSE(),"",COUNTIF($J$6:$J14,TRUE())) | L14: =IF($K14="","","R"&$K14)
A15: =IF($B15="","",10) | B15: =IFERROR(INDEX(소진분석!$A$6:$A$305,MATCH("R"&10,발주목록!$L$6:$L$305,0)),"") | C15: =IF($B15="","",IFERROR(INDEX(소진분석!$B$6:$B$305,MATCH("R"&10,발주목록!$L$6:$L$305,0)),"")) | D15: =IF($B15="","",IFERROR(INDEX(소진분석!$C$6:$C$305,MATCH("R"&10,발주목록!$L$6:$L$305,0)),"")) | E15: =IF($B15="","",IFERROR(INDEX(소진분석!$D$6:$D$305,MATCH("R"&10,발주목록!$L$6:$L$305,0)),"")) | F15: =IF($B15="","",IFERROR(INDEX(소진분석!$K$6:$K$305,MATCH("R"&10,발주목록!$L$6:$L$305,0)),"")) | G15: =IF($B15="","",IFERROR(INDEX(품목마스터!$I$3:$I$302,MATCH($B15,품목마스터!$A$3:$A$302,0)),"")) | H15: =IF($B15="","",IFERROR(INDEX(소진분석!$J$6:$J$305,MATCH("R"&10,발주목록!$L$6:$L$305,0)),"")) | J15: =IF(소진분석!$A15="",FALSE(),IF($B$3="발주만",소진분석!$L15="발주",OR(소진분석!$L15="발주",소진분석!$L15="임박"))) -> FALSE | K15: =IF($J15=FALSE(),"",COUNTIF($J$6:$J15,TRUE())) | L15: =IF($K15="","","R"&$K15)
A16: =IF($B16="","",11) | B16: =IFERROR(INDEX(소진분석!$A$6:$A$305,MATCH("R"&11,발주목록!$L$6:$L$305,0)),"") | C16: =IF($B16="","",IFERROR(INDEX(소진분석!$B$6:$B$305,MATCH("R"&11,발주목록!$L$6:$L$305,0)),"")) | D16: =IF($B16="","",IFERROR(INDEX(소진분석!$C$6:$C$305,MATCH("R"&11,발주목록!$L$6:$L$305,0)),"")) | E16: =IF($B16="","",IFERROR(INDEX(소진분석!$D$6:$D$305,MATCH("R"&11,발주목록!$L$6:$L$305,0)),"")) | F16: =IF($B16="","",IFERROR(INDEX(소진분석!$K$6:$K$305,MATCH("R"&11,발주목록!$L$6:$L$305,0)),"")) | G16: =IF($B16="","",IFERROR(INDEX(품목마스터!$I$3:$I$302,MATCH($B16,품목마스터!$A$3:$A$302,0)),"")) | H16: =IF($B16="","",IFERROR(INDEX(소진분석!$J$6:$J$305,MATCH("R"&11,발주목록!$L$6:$L$305,0)),"")) | J16: =IF(소진분석!$A16="",FALSE(),IF($B$3="발주만",소진분석!$L16="발주",OR(소진분석!$L16="발주",소진분석!$L16="임박"))) -> FALSE | K16: =IF($J16=FALSE(),"",COUNTIF($J$6:$J16,TRUE())) | L16: =IF($K16="","","R"&$K16)
A17: =IF($B17="","",12) | B17: =IFERROR(INDEX(소진분석!$A$6:$A$305,MATCH("R"&12,발주목록!$L$6:$L$305,0)),"") | C17: =IF($B17="","",IFERROR(INDEX(소진분석!$B$6:$B$305,MATCH("R"&12,발주목록!$L$6:$L$305,0)),"")) | D17: =IF($B17="","",IFERROR(INDEX(소진분석!$C$6:$C$305,MATCH("R"&12,발주목록!$L$6:$L$305,0)),"")) | E17: =IF($B17="","",IFERROR(INDEX(소진분석!$D$6:$D$305,MATCH("R"&12,발주목록!$L$6:$L$305,0)),"")) | F17: =IF($B17="","",IFERROR(INDEX(소진분석!$K$6:$K$305,MATCH("R"&12,발주목록!$L$6:$L$305,0)),"")) | G17: =IF($B17="","",IFERROR(INDEX(품목마스터!$I$3:$I$302,MATCH($B17,품목마스터!$A$3:$A$302,0)),"")) | H17: =IF($B17="","",IFERROR(INDEX(소진분석!$J$6:$J$305,MATCH("R"&12,발주목록!$L$6:$L$305,0)),"")) | J17: =IF(소진분석!$A17="",FALSE(),IF($B$3="발주만",소진분석!$L17="발주",OR(소진분석!$L17="발주",소진분석!$L17="임박"))) -> FALSE | K17: =IF($J17=FALSE(),"",COUNTIF($J$6:$J17,TRUE())) | L17: =IF($K17="","","R"&$K17)
A18: =IF($B18="","",13) | B18: =IFERROR(INDEX(소진분석!$A$6:$A$305,MATCH("R"&13,발주목록!$L$6:$L$305,0)),"") | C18: =IF($B18="","",IFERROR(INDEX(소진분석!$B$6:$B$305,MATCH("R"&13,발주목록!$L$6:$L$305,0)),"")) | D18: =IF($B18="","",IFERROR(INDEX(소진분석!$C$6:$C$305,MATCH("R"&13,발주목록!$L$6:$L$305,0)),"")) | E18: =IF($B18="","",IFERROR(INDEX(소진분석!$D$6:$D$305,MATCH("R"&13,발주목록!$L$6:$L$305,0)),"")) | F18: =IF($B18="","",IFERROR(INDEX(소진분석!$K$6:$K$305,MATCH("R"&13,발주목록!$L$6:$L$305,0)),"")) | G18: =IF($B18="","",IFERROR(INDEX(품목마스터!$I$3:$I$302,MATCH($B18,품목마스터!$A$3:$A$302,0)),"")) | H18: =IF($B18="","",IFERROR(INDEX(소진분석!$J$6:$J$305,MATCH("R"&13,발주목록!$L$6:$L$305,0)),"")) | J18: =IF(소진분석!$A18="",FALSE(),IF($B$3="발주만",소진분석!$L18="발주",OR(소진분석!$L18="발주",소진분석!$L18="임박"))) -> FALSE | K18: =IF($J18=FALSE(),"",COUNTIF($J$6:$J18,TRUE())) | L18: =IF($K18="","","R"&$K18)
A19: =IF($B19="","",14) | B19: =IFERROR(INDEX(소진분석!$A$6:$A$305,MATCH("R"&14,발주목록!$L$6:$L$305,0)),"") | C19: =IF($B19="","",IFERROR(INDEX(소진분석!$B$6:$B$305,MATCH("R"&14,발주목록!$L$6:$L$305,0)),"")) | D19: =IF($B19="","",IFERROR(INDEX(소진분석!$C$6:$C$305,MATCH("R"&14,발주목록!$L$6:$L$305,0)),"")) | E19: =IF($B19="","",IFERROR(INDEX(소진분석!$D$6:$D$305,MATCH("R"&14,발주목록!$L$6:$L$305,0)),"")) | F19: =IF($B19="","",IFERROR(INDEX(소진분석!$K$6:$K$305,MATCH("R"&14,발주목록!$L$6:$L$305,0)),"")) | G19: =IF($B19="","",IFERROR(INDEX(품목마스터!$I$3:$I$302,MATCH($B19,품목마스터!$A$3:$A$302,0)),"")) | H19: =IF($B19="","",IFERROR(INDEX(소진분석!$J$6:$J$305,MATCH("R"&14,발주목록!$L$6:$L$305,0)),"")) | J19: =IF(소진분석!$A19="",FALSE(),IF($B$3="발주만",소진분석!$L19="발주",OR(소진분석!$L19="발주",소진분석!$L19="임박"))) -> FALSE | K19: =IF($J19=FALSE(),"",COUNTIF($J$6:$J19,TRUE())) | L19: =IF($K19="","","R"&$K19)
A20: =IF($B20="","",15) | B20: =IFERROR(INDEX(소진분석!$A$6:$A$305,MATCH("R"&15,발주목록!$L$6:$L$305,0)),"") | C20: =IF($B20="","",IFERROR(INDEX(소진분석!$B$6:$B$305,MATCH("R"&15,발주목록!$L$6:$L$305,0)),"")) | D20: =IF($B20="","",IFERROR(INDEX(소진분석!$C$6:$C$305,MATCH("R"&15,발주목록!$L$6:$L$305,0)),"")) | E20: =IF($B20="","",IFERROR(INDEX(소진분석!$D$6:$D$305,MATCH("R"&15,발주목록!$L$6:$L$305,0)),"")) | F20: =IF($B20="","",IFERROR(INDEX(소진분석!$K$6:$K$305,MATCH("R"&15,발주목록!$L$6:$L$305,0)),"")) | G20: =IF($B20="","",IFERROR(INDEX(품목마스터!$I$3:$I$302,MATCH($B20,품목마스터!$A$3:$A$302,0)),"")) | H20: =IF($B20="","",IFERROR(INDEX(소진분석!$J$6:$J$305,MATCH("R"&15,발주목록!$L$6:$L$305,0)),"")) | J20: =IF(소진분석!$A20="",FALSE(),IF($B$3="발주만",소진분석!$L20="발주",OR(소진분석!$L20="발주",소진분석!$L20="임박"))) -> FALSE | K20: =IF($J20=FALSE(),"",COUNTIF($J$6:$J20,TRUE())) | L20: =IF($K20="","","R"&$K20)
A21: =IF($B21="","",16) | B21: =IFERROR(INDEX(소진분석!$A$6:$A$305,MATCH("R"&16,발주목록!$L$6:$L$305,0)),"") | C21: =IF($B21="","",IFERROR(INDEX(소진분석!$B$6:$B$305,MATCH("R"&16,발주목록!$L$6:$L$305,0)),"")) | D21: =IF($B21="","",IFERROR(INDEX(소진분석!$C$6:$C$305,MATCH("R"&16,발주목록!$L$6:$L$305,0)),"")) | E21: =IF($B21="","",IFERROR(INDEX(소진분석!$D$6:$D$305,MATCH("R"&16,발주목록!$L$6:$L$305,0)),"")) | F21: =IF($B21="","",IFERROR(INDEX(소진분석!$K$6:$K$305,MATCH("R"&16,발주목록!$L$6:$L$305,0)),"")) | G21: =IF($B21="","",IFERROR(INDEX(품목마스터!$I$3:$I$302,MATCH($B21,품목마스터!$A$3:$A$302,0)),"")) | H21: =IF($B21="","",IFERROR(INDEX(소진분석!$J$6:$J$305,MATCH("R"&16,발주목록!$L$6:$L$305,0)),"")) | J21: =IF(소진분석!$A21="",FALSE(),IF($B$3="발주만",소진분석!$L21="발주",OR(소진분석!$L21="발주",소진분석!$L21="임박"))) -> FALSE | K21: =IF($J21=FALSE(),"",COUNTIF($J$6:$J21,TRUE())) | L21: =IF($K21="","","R"&$K21)
A22: =IF($B22="","",17) | B22: =IFERROR(INDEX(소진분석!$A$6:$A$305,MATCH("R"&17,발주목록!$L$6:$L$305,0)),"") | C22: =IF($B22="","",IFERROR(INDEX(소진분석!$B$6:$B$305,MATCH("R"&17,발주목록!$L$6:$L$305,0)),"")) | D22: =IF($B22="","",IFERROR(INDEX(소진분석!$C$6:$C$305,MATCH("R"&17,발주목록!$L$6:$L$305,0)),"")) | E22: =IF($B22="","",IFERROR(INDEX(소진분석!$D$6:$D$305,MATCH("R"&17,발주목록!$L$6:$L$305,0)),"")) | F22: =IF($B22="","",IFERROR(INDEX(소진분석!$K$6:$K$305,MATCH("R"&17,발주목록!$L$6:$L$305,0)),"")) | G22: =IF($B22="","",IFERROR(INDEX(품목마스터!$I$3:$I$302,MATCH($B22,품목마스터!$A$3:$A$302,0)),"")) | H22: =IF($B22="","",IFERROR(INDEX(소진분석!$J$6:$J$305,MATCH("R"&17,발주목록!$L$6:$L$305,0)),"")) | J22: =IF(소진분석!$A22="",FALSE(),IF($B$3="발주만",소진분석!$L22="발주",OR(소진분석!$L22="발주",소진분석!$L22="임박"))) -> FALSE | K22: =IF($J22=FALSE(),"",COUNTIF($J$6:$J22,TRUE())) | L22: =IF($K22="","","R"&$K22)
A23: =IF($B23="","",18) | B23: =IFERROR(INDEX(소진분석!$A$6:$A$305,MATCH("R"&18,발주목록!$L$6:$L$305,0)),"") | C23: =IF($B23="","",IFERROR(INDEX(소진분석!$B$6:$B$305,MATCH("R"&18,발주목록!$L$6:$L$305,0)),"")) | D23: =IF($B23="","",IFERROR(INDEX(소진분석!$C$6:$C$305,MATCH("R"&18,발주목록!$L$6:$L$305,0)),"")) | E23: =IF($B23="","",IFERROR(INDEX(소진분석!$D$6:$D$305,MATCH("R"&18,발주목록!$L$6:$L$305,0)),"")) | F23: =IF($B23="","",IFERROR(INDEX(소진분석!$K$6:$K$305,MATCH("R"&18,발주목록!$L$6:$L$305,0)),"")) | G23: =IF($B23="","",IFERROR(INDEX(품목마스터!$I$3:$I$302,MATCH($B23,품목마스터!$A$3:$A$302,0)),"")) | H23: =IF($B23="","",IFERROR(INDEX(소진분석!$J$6:$J$305,MATCH("R"&18,발주목록!$L$6:$L$305,0)),"")) | J23: =IF(소진분석!$A23="",FALSE(),IF($B$3="발주만",소진분석!$L23="발주",OR(소진분석!$L23="발주",소진분석!$L23="임박"))) -> FALSE | K23: =IF($J23=FALSE(),"",COUNTIF($J$6:$J23,TRUE())) | L23: =IF($K23="","","R"&$K23)
A24: =IF($B24="","",19) | B24: =IFERROR(INDEX(소진분석!$A$6:$A$305,MATCH("R"&19,발주목록!$L$6:$L$305,0)),"") | C24: =IF($B24="","",IFERROR(INDEX(소진분석!$B$6:$B$305,MATCH("R"&19,발주목록!$L$6:$L$305,0)),"")) | D24: =IF($B24="","",IFERROR(INDEX(소진분석!$C$6:$C$305,MATCH("R"&19,발주목록!$L$6:$L$305,0)),"")) | E24: =IF($B24="","",IFERROR(INDEX(소진분석!$D$6:$D$305,MATCH("R"&19,발주목록!$L$6:$L$305,0)),"")) | F24: =IF($B24="","",IFERROR(INDEX(소진분석!$K$6:$K$305,MATCH("R"&19,발주목록!$L$6:$L$305,0)),"")) | G24: =IF($B24="","",IFERROR(INDEX(품목마스터!$I$3:$I$302,MATCH($B24,품목마스터!$A$3:$A$302,0)),"")) | H24: =IF($B24="","",IFERROR(INDEX(소진분석!$J$6:$J$305,MATCH("R"&19,발주목록!$L$6:$L$305,0)),"")) | J24: =IF(소진분석!$A24="",FALSE(),IF($B$3="발주만",소진분석!$L24="발주",OR(소진분석!$L24="발주",소진분석!$L24="임박"))) -> FALSE | K24: =IF($J24=FALSE(),"",COUNTIF($J$6:$J24,TRUE())) | L24: =IF($K24="","","R"&$K24)
A25: =IF($B25="","",20) | B25: =IFERROR(INDEX(소진분석!$A$6:$A$305,MATCH("R"&20,발주목록!$L$6:$L$305,0)),"") | C25: =IF($B25="","",IFERROR(INDEX(소진분석!$B$6:$B$305,MATCH("R"&20,발주목록!$L$6:$L$305,0)),"")) | D25: =IF($B25="","",IFERROR(INDEX(소진분석!$C$6:$C$305,MATCH("R"&20,발주목록!$L$6:$L$305,0)),"")) | E25: =IF($B25="","",IFERROR(INDEX(소진분석!$D$6:$D$305,MATCH("R"&20,발주목록!$L$6:$L$305,0)),"")) | F25: =IF($B25="","",IFERROR(INDEX(소진분석!$K$6:$K$305,MATCH("R"&20,발주목록!$L$6:$L$305,0)),"")) | G25: =IF($B25="","",IFERROR(INDEX(품목마스터!$I$3:$I$302,MATCH($B25,품목마스터!$A$3:$A$302,0)),"")) | H25: =IF($B25="","",IFERROR(INDEX(소진분석!$J$6:$J$305,MATCH("R"&20,발주목록!$L$6:$L$305,0)),"")) | J25: =IF(소진분석!$A25="",FALSE(),IF($B$3="발주만",소진분석!$L25="발주",OR(소진분석!$L25="발주",소진분석!$L25="임박"))) -> FALSE | K25: =IF($J25=FALSE(),"",COUNTIF($J$6:$J25,TRUE())) | L25: =IF($K25="","","R"&$K25)
A26: =IF($B26="","",21) | B26: =IFERROR(INDEX(소진분석!$A$6:$A$305,MATCH("R"&21,발주목록!$L$6:$L$305,0)),"") | C26: =IF($B26="","",IFERROR(INDEX(소진분석!$B$6:$B$305,MATCH("R"&21,발주목록!$L$6:$L$305,0)),"")) | D26: =IF($B26="","",IFERROR(INDEX(소진분석!$C$6:$C$305,MATCH("R"&21,발주목록!$L$6:$L$305,0)),"")) | E26: =IF($B26="","",IFERROR(INDEX(소진분석!$D$6:$D$305,MATCH("R"&21,발주목록!$L$6:$L$305,0)),"")) | F26: =IF($B26="","",IFERROR(INDEX(소진분석!$K$6:$K$305,MATCH("R"&21,발주목록!$L$6:$L$305,0)),"")) | G26: =IF($B26="","",IFERROR(INDEX(품목마스터!$I$3:$I$302,MATCH($B26,품목마스터!$A$3:$A$302,0)),"")) | H26: =IF($B26="","",IFERROR(INDEX(소진분석!$J$6:$J$305,MATCH("R"&21,발주목록!$L$6:$L$305,0)),"")) | J26: =IF(소진분석!$A26="",FALSE(),IF($B$3="발주만",소진분석!$L26="발주",OR(소진분석!$L26="발주",소진분석!$L26="임박"))) -> FALSE | K26: =IF($J26=FALSE(),"",COUNTIF($J$6:$J26,TRUE())) | L26: =IF($K26="","","R"&$K26)
A27: =IF($B27="","",22) | B27: =IFERROR(INDEX(소진분석!$A$6:$A$305,MATCH("R"&22,발주목록!$L$6:$L$305,0)),"") | C27: =IF($B27="","",IFERROR(INDEX(소진분석!$B$6:$B$305,MATCH("R"&22,발주목록!$L$6:$L$305,0)),"")) | D27: =IF($B27="","",IFERROR(INDEX(소진분석!$C$6:$C$305,MATCH("R"&22,발주목록!$L$6:$L$305,0)),"")) | E27: =IF($B27="","",IFERROR(INDEX(소진분석!$D$6:$D$305,MATCH("R"&22,발주목록!$L$6:$L$305,0)),"")) | F27: =IF($B27="","",IFERROR(INDEX(소진분석!$K$6:$K$305,MATCH("R"&22,발주목록!$L$6:$L$305,0)),"")) | G27: =IF($B27="","",IFERROR(INDEX(품목마스터!$I$3:$I$302,MATCH($B27,품목마스터!$A$3:$A$302,0)),"")) | H27: =IF($B27="","",IFERROR(INDEX(소진분석!$J$6:$J$305,MATCH("R"&22,발주목록!$L$6:$L$305,0)),"")) | J27: =IF(소진분석!$A27="",FALSE(),IF($B$3="발주만",소진분석!$L27="발주",OR(소진분석!$L27="발주",소진분석!$L27="임박"))) -> FALSE | K27: =IF($J27=FALSE(),"",COUNTIF($J$6:$J27,TRUE())) | L27: =IF($K27="","","R"&$K27)
A28: =IF($B28="","",23) | B28: =IFERROR(INDEX(소진분석!$A$6:$A$305,MATCH("R"&23,발주목록!$L$6:$L$305,0)),"") | C28: =IF($B28="","",IFERROR(INDEX(소진분석!$B$6:$B$305,MATCH("R"&23,발주목록!$L$6:$L$305,0)),"")) | D28: =IF($B28="","",IFERROR(INDEX(소진분석!$C$6:$C$305,MATCH("R"&23,발주목록!$L$6:$L$305,0)),"")) | E28: =IF($B28="","",IFERROR(INDEX(소진분석!$D$6:$D$305,MATCH("R"&23,발주목록!$L$6:$L$305,0)),"")) | F28: =IF($B28="","",IFERROR(INDEX(소진분석!$K$6:$K$305,MATCH("R"&23,발주목록!$L$6:$L$305,0)),"")) | G28: =IF($B28="","",IFERROR(INDEX(품목마스터!$I$3:$I$302,MATCH($B28,품목마스터!$A$3:$A$302,0)),"")) | H28: =IF($B28="","",IFERROR(INDEX(소진분석!$J$6:$J$305,MATCH("R"&23,발주목록!$L$6:$L$305,0)),"")) | J28: =IF(소진분석!$A28="",FALSE(),IF($B$3="발주만",소진분석!$L28="발주",OR(소진분석!$L28="발주",소진분석!$L28="임박"))) -> FALSE | K28: =IF($J28=FALSE(),"",COUNTIF($J$6:$J28,TRUE())) | L28: =IF($K28="","","R"&$K28)
A29: =IF($B29="","",24) | B29: =IFERROR(INDEX(소진분석!$A$6:$A$305,MATCH("R"&24,발주목록!$L$6:$L$305,0)),"") | C29: =IF($B29="","",IFERROR(INDEX(소진분석!$B$6:$B$305,MATCH("R"&24,발주목록!$L$6:$L$305,0)),"")) | D29: =IF($B29="","",IFERROR(INDEX(소진분석!$C$6:$C$305,MATCH("R"&24,발주목록!$L$6:$L$305,0)),"")) | E29: =IF($B29="","",IFERROR(INDEX(소진분석!$D$6:$D$305,MATCH("R"&24,발주목록!$L$6:$L$305,0)),"")) | F29: =IF($B29="","",IFERROR(INDEX(소진분석!$K$6:$K$305,MATCH("R"&24,발주목록!$L$6:$L$305,0)),"")) | G29: =IF($B29="","",IFERROR(INDEX(품목마스터!$I$3:$I$302,MATCH($B29,품목마스터!$A$3:$A$302,0)),"")) | H29: =IF($B29="","",IFERROR(INDEX(소진분석!$J$6:$J$305,MATCH("R"&24,발주목록!$L$6:$L$305,0)),"")) | J29: =IF(소진분석!$A29="",FALSE(),IF($B$3="발주만",소진분석!$L29="발주",OR(소진분석!$L29="발주",소진분석!$L29="임박"))) -> FALSE | K29: =IF($J29=FALSE(),"",COUNTIF($J$6:$J29,TRUE())) | L29: =IF($K29="","","R"&$K29)
A30: =IF($B30="","",25) | B30: =IFERROR(INDEX(소진분석!$A$6:$A$305,MATCH("R"&25,발주목록!$L$6:$L$305,0)),"") | C30: =IF($B30="","",IFERROR(INDEX(소진분석!$B$6:$B$305,MATCH("R"&25,발주목록!$L$6:$L$305,0)),"")) | D30: =IF($B30="","",IFERROR(INDEX(소진분석!$C$6:$C$305,MATCH("R"&25,발주목록!$L$6:$L$305,0)),"")) | E30: =IF($B30="","",IFERROR(INDEX(소진분석!$D$6:$D$305,MATCH("R"&25,발주목록!$L$6:$L$305,0)),"")) | F30: =IF($B30="","",IFERROR(INDEX(소진분석!$K$6:$K$305,MATCH("R"&25,발주목록!$L$6:$L$305,0)),"")) | G30: =IF($B30="","",IFERROR(INDEX(품목마스터!$I$3:$I$302,MATCH($B30,품목마스터!$A$3:$A$302,0)),"")) | H30: =IF($B30="","",IFERROR(INDEX(소진분석!$J$6:$J$305,MATCH("R"&25,발주목록!$L$6:$L$305,0)),"")) | J30: =IF(소진분석!$A30="",FALSE(),IF($B$3="발주만",소진분석!$L30="발주",OR(소진분석!$L30="발주",소진분석!$L30="임박"))) -> FALSE | K30: =IF($J30=FALSE(),"",COUNTIF($J$6:$J30,TRUE())) | L30: =IF($K30="","","R"&$K30)
A31: =IF($B31="","",26) | B31: =IFERROR(INDEX(소진분석!$A$6:$A$305,MATCH("R"&26,발주목록!$L$6:$L$305,0)),"") | C31: =IF($B31="","",IFERROR(INDEX(소진분석!$B$6:$B$305,MATCH("R"&26,발주목록!$L$6:$L$305,0)),"")) | D31: =IF($B31="","",IFERROR(INDEX(소진분석!$C$6:$C$305,MATCH("R"&26,발주목록!$L$6:$L$305,0)),"")) | E31: =IF($B31="","",IFERROR(INDEX(소진분석!$D$6:$D$305,MATCH("R"&26,발주목록!$L$6:$L$305,0)),"")) | F31: =IF($B31="","",IFERROR(INDEX(소진분석!$K$6:$K$305,MATCH("R"&26,발주목록!$L$6:$L$305,0)),"")) | G31: =IF($B31="","",IFERROR(INDEX(품목마스터!$I$3:$I$302,MATCH($B31,품목마스터!$A$3:$A$302,0)),"")) | H31: =IF($B31="","",IFERROR(INDEX(소진분석!$J$6:$J$305,MATCH("R"&26,발주목록!$L$6:$L$305,0)),"")) | J31: =IF(소진분석!$A31="",FALSE(),IF($B$3="발주만",소진분석!$L31="발주",OR(소진분석!$L31="발주",소진분석!$L31="임박"))) -> FALSE | K31: =IF($J31=FALSE(),"",COUNTIF($J$6:$J31,TRUE())) | L31: =IF($K31="","","R"&$K31)
A32: =IF($B32="","",27) | B32: =IFERROR(INDEX(소진분석!$A$6:$A$305,MATCH("R"&27,발주목록!$L$6:$L$305,0)),"") | C32: =IF($B32="","",IFERROR(INDEX(소진분석!$B$6:$B$305,MATCH("R"&27,발주목록!$L$6:$L$305,0)),"")) | D32: =IF($B32="","",IFERROR(INDEX(소진분석!$C$6:$C$305,MATCH("R"&27,발주목록!$L$6:$L$305,0)),"")) | E32: =IF($B32="","",IFERROR(INDEX(소진분석!$D$6:$D$305,MATCH("R"&27,발주목록!$L$6:$L$305,0)),"")) | F32: =IF($B32="","",IFERROR(INDEX(소진분석!$K$6:$K$305,MATCH("R"&27,발주목록!$L$6:$L$305,0)),"")) | G32: =IF($B32="","",IFERROR(INDEX(품목마스터!$I$3:$I$302,MATCH($B32,품목마스터!$A$3:$A$302,0)),"")) | H32: =IF($B32="","",IFERROR(INDEX(소진분석!$J$6:$J$305,MATCH("R"&27,발주목록!$L$6:$L$305,0)),"")) | J32: =IF(소진분석!$A32="",FALSE(),IF($B$3="발주만",소진분석!$L32="발주",OR(소진분석!$L32="발주",소진분석!$L32="임박"))) -> FALSE | K32: =IF($J32=FALSE(),"",COUNTIF($J$6:$J32,TRUE())) | L32: =IF($K32="","","R"&$K32)
A33: =IF($B33="","",28) | B33: =IFERROR(INDEX(소진분석!$A$6:$A$305,MATCH("R"&28,발주목록!$L$6:$L$305,0)),"") | C33: =IF($B33="","",IFERROR(INDEX(소진분석!$B$6:$B$305,MATCH("R"&28,발주목록!$L$6:$L$305,0)),"")) | D33: =IF($B33="","",IFERROR(INDEX(소진분석!$C$6:$C$305,MATCH("R"&28,발주목록!$L$6:$L$305,0)),"")) | E33: =IF($B33="","",IFERROR(INDEX(소진분석!$D$6:$D$305,MATCH("R"&28,발주목록!$L$6:$L$305,0)),"")) | F33: =IF($B33="","",IFERROR(INDEX(소진분석!$K$6:$K$305,MATCH("R"&28,발주목록!$L$6:$L$305,0)),"")) | G33: =IF($B33="","",IFERROR(INDEX(품목마스터!$I$3:$I$302,MATCH($B33,품목마스터!$A$3:$A$302,0)),"")) | H33: =IF($B33="","",IFERROR(INDEX(소진분석!$J$6:$J$305,MATCH("R"&28,발주목록!$L$6:$L$305,0)),"")) | J33: =IF(소진분석!$A33="",FALSE(),IF($B$3="발주만",소진분석!$L33="발주",OR(소진분석!$L33="발주",소진분석!$L33="임박"))) -> FALSE | K33: =IF($J33=FALSE(),"",COUNTIF($J$6:$J33,TRUE())) | L33: =IF($K33="","","R"&$K33)
A34: =IF($B34="","",29) | B34: =IFERROR(INDEX(소진분석!$A$6:$A$305,MATCH("R"&29,발주목록!$L$6:$L$305,0)),"") | C34: =IF($B34="","",IFERROR(INDEX(소진분석!$B$6:$B$305,MATCH("R"&29,발주목록!$L$6:$L$305,0)),"")) | D34: =IF($B34="","",IFERROR(INDEX(소진분석!$C$6:$C$305,MATCH("R"&29,발주목록!$L$6:$L$305,0)),"")) | E34: =IF($B34="","",IFERROR(INDEX(소진분석!$D$6:$D$305,MATCH("R"&29,발주목록!$L$6:$L$305,0)),"")) | F34: =IF($B34="","",IFERROR(INDEX(소진분석!$K$6:$K$305,MATCH("R"&29,발주목록!$L$6:$L$305,0)),"")) | G34: =IF($B34="","",IFERROR(INDEX(품목마스터!$I$3:$I$302,MATCH($B34,품목마스터!$A$3:$A$302,0)),"")) | H34: =IF($B34="","",IFERROR(INDEX(소진분석!$J$6:$J$305,MATCH("R"&29,발주목록!$L$6:$L$305,0)),"")) | J34: =IF(소진분석!$A34="",FALSE(),IF($B$3="발주만",소진분석!$L34="발주",OR(소진분석!$L34="발주",소진분석!$L34="임박"))) -> FALSE | K34: =IF($J34=FALSE(),"",COUNTIF($J$6:$J34,TRUE())) | L34: =IF($K34="","","R"&$K34)
A35: =IF($B35="","",30) | B35: =IFERROR(INDEX(소진분석!$A$6:$A$305,MATCH("R"&30,발주목록!$L$6:$L$305,0)),"") | C35: =IF($B35="","",IFERROR(INDEX(소진분석!$B$6:$B$305,MATCH("R"&30,발주목록!$L$6:$L$305,0)),"")) | D35: =IF($B35="","",IFERROR(INDEX(소진분석!$C$6:$C$305,MATCH("R"&30,발주목록!$L$6:$L$305,0)),"")) | E35: =IF($B35="","",IFERROR(INDEX(소진분석!$D$6:$D$305,MATCH("R"&30,발주목록!$L$6:$L$305,0)),"")) | F35: =IF($B35="","",IFERROR(INDEX(소진분석!$K$6:$K$305,MATCH("R"&30,발주목록!$L$6:$L$305,0)),"")) | G35: =IF($B35="","",IFERROR(INDEX(품목마스터!$I$3:$I$302,MATCH($B35,품목마스터!$A$3:$A$302,0)),"")) | H35: =IF($B35="","",IFERROR(INDEX(소진분석!$J$6:$J$305,MATCH("R"&30,발주목록!$L$6:$L$305,0)),"")) | J35: =IF(소진분석!$A35="",FALSE(),IF($B$3="발주만",소진분석!$L35="발주",OR(소진분석!$L35="발주",소진분석!$L35="임박"))) -> FALSE | K35: =IF($J35=FALSE(),"",COUNTIF($J$6:$J35,TRUE())) | L35: =IF($K35="","","R"&$K35)
A36: =IF($B36="","",31) | B36: =IFERROR(INDEX(소진분석!$A$6:$A$305,MATCH("R"&31,발주목록!$L$6:$L$305,0)),"") | C36: =IF($B36="","",IFERROR(INDEX(소진분석!$B$6:$B$305,MATCH("R"&31,발주목록!$L$6:$L$305,0)),"")) | D36: =IF($B36="","",IFERROR(INDEX(소진분석!$C$6:$C$305,MATCH("R"&31,발주목록!$L$6:$L$305,0)),"")) | E36: =IF($B36="","",IFERROR(INDEX(소진분석!$D$6:$D$305,MATCH("R"&31,발주목록!$L$6:$L$305,0)),"")) | F36: =IF($B36="","",IFERROR(INDEX(소진분석!$K$6:$K$305,MATCH("R"&31,발주목록!$L$6:$L$305,0)),"")) | G36: =IF($B36="","",IFERROR(INDEX(품목마스터!$I$3:$I$302,MATCH($B36,품목마스터!$A$3:$A$302,0)),"")) | H36: =IF($B36="","",IFERROR(INDEX(소진분석!$J$6:$J$305,MATCH("R"&31,발주목록!$L$6:$L$305,0)),"")) | J36: =IF(소진분석!$A36="",FALSE(),IF($B$3="발주만",소진분석!$L36="발주",OR(소진분석!$L36="발주",소진분석!$L36="임박"))) -> FALSE | K36: =IF($J36=FALSE(),"",COUNTIF($J$6:$J36,TRUE())) | L36: =IF($K36="","","R"&$K36)
A37: =IF($B37="","",32) | B37: =IFERROR(INDEX(소진분석!$A$6:$A$305,MATCH("R"&32,발주목록!$L$6:$L$305,0)),"") | C37: =IF($B37="","",IFERROR(INDEX(소진분석!$B$6:$B$305,MATCH("R"&32,발주목록!$L$6:$L$305,0)),"")) | D37: =IF($B37="","",IFERROR(INDEX(소진분석!$C$6:$C$305,MATCH("R"&32,발주목록!$L$6:$L$305,0)),"")) | E37: =IF($B37="","",IFERROR(INDEX(소진분석!$D$6:$D$305,MATCH("R"&32,발주목록!$L$6:$L$305,0)),"")) | F37: =IF($B37="","",IFERROR(INDEX(소진분석!$K$6:$K$305,MATCH("R"&32,발주목록!$L$6:$L$305,0)),"")) | G37: =IF($B37="","",IFERROR(INDEX(품목마스터!$I$3:$I$302,MATCH($B37,품목마스터!$A$3:$A$302,0)),"")) | H37: =IF($B37="","",IFERROR(INDEX(소진분석!$J$6:$J$305,MATCH("R"&32,발주목록!$L$6:$L$305,0)),"")) | J37: =IF(소진분석!$A37="",FALSE(),IF($B$3="발주만",소진분석!$L37="발주",OR(소진분석!$L37="발주",소진분석!$L37="임박"))) -> FALSE | K37: =IF($J37=FALSE(),"",COUNTIF($J$6:$J37,TRUE())) | L37: =IF($K37="","","R"&$K37)
A38: =IF($B38="","",33) | B38: =IFERROR(INDEX(소진분석!$A$6:$A$305,MATCH("R"&33,발주목록!$L$6:$L$305,0)),"") | C38: =IF($B38="","",IFERROR(INDEX(소진분석!$B$6:$B$305,MATCH("R"&33,발주목록!$L$6:$L$305,0)),"")) | D38: =IF($B38="","",IFERROR(INDEX(소진분석!$C$6:$C$305,MATCH("R"&33,발주목록!$L$6:$L$305,0)),"")) | E38: =IF($B38="","",IFERROR(INDEX(소진분석!$D$6:$D$305,MATCH("R"&33,발주목록!$L$6:$L$305,0)),"")) | F38: =IF($B38="","",IFERROR(INDEX(소진분석!$K$6:$K$305,MATCH("R"&33,발주목록!$L$6:$L$305,0)),"")) | G38: =IF($B38="","",IFERROR(INDEX(품목마스터!$I$3:$I$302,MATCH($B38,품목마스터!$A$3:$A$302,0)),"")) | H38: =IF($B38="","",IFERROR(INDEX(소진분석!$J$6:$J$305,MATCH("R"&33,발주목록!$L$6:$L$305,0)),"")) | J38: =IF(소진분석!$A38="",FALSE(),IF($B$3="발주만",소진분석!$L38="발주",OR(소진분석!$L38="발주",소진분석!$L38="임박"))) -> FALSE | K38: =IF($J38=FALSE(),"",COUNTIF($J$6:$J38,TRUE())) | L38: =IF($K38="","","R"&$K38)
A39: =IF($B39="","",34) | B39: =IFERROR(INDEX(소진분석!$A$6:$A$305,MATCH("R"&34,발주목록!$L$6:$L$305,0)),"") | C39: =IF($B39="","",IFERROR(INDEX(소진분석!$B$6:$B$305,MATCH("R"&34,발주목록!$L$6:$L$305,0)),"")) | D39: =IF($B39="","",IFERROR(INDEX(소진분석!$C$6:$C$305,MATCH("R"&34,발주목록!$L$6:$L$305,0)),"")) | E39: =IF($B39="","",IFERROR(INDEX(소진분석!$D$6:$D$305,MATCH("R"&34,발주목록!$L$6:$L$305,0)),"")) | F39: =IF($B39="","",IFERROR(INDEX(소진분석!$K$6:$K$305,MATCH("R"&34,발주목록!$L$6:$L$305,0)),"")) | G39: =IF($B39="","",IFERROR(INDEX(품목마스터!$I$3:$I$302,MATCH($B39,품목마스터!$A$3:$A$302,0)),"")) | H39: =IF($B39="","",IFERROR(INDEX(소진분석!$J$6:$J$305,MATCH("R"&34,발주목록!$L$6:$L$305,0)),"")) | J39: =IF(소진분석!$A39="",FALSE(),IF($B$3="발주만",소진분석!$L39="발주",OR(소진분석!$L39="발주",소진분석!$L39="임박"))) -> FALSE | K39: =IF($J39=FALSE(),"",COUNTIF($J$6:$J39,TRUE())) | L39: =IF($K39="","","R"&$K39)
A40: =IF($B40="","",35) | B40: =IFERROR(INDEX(소진분석!$A$6:$A$305,MATCH("R"&35,발주목록!$L$6:$L$305,0)),"") | C40: =IF($B40="","",IFERROR(INDEX(소진분석!$B$6:$B$305,MATCH("R"&35,발주목록!$L$6:$L$305,0)),"")) | D40: =IF($B40="","",IFERROR(INDEX(소진분석!$C$6:$C$305,MATCH("R"&35,발주목록!$L$6:$L$305,0)),"")) | E40: =IF($B40="","",IFERROR(INDEX(소진분석!$D$6:$D$305,MATCH("R"&35,발주목록!$L$6:$L$305,0)),"")) | F40: =IF($B40="","",IFERROR(INDEX(소진분석!$K$6:$K$305,MATCH("R"&35,발주목록!$L$6:$L$305,0)),"")) | G40: =IF($B40="","",IFERROR(INDEX(품목마스터!$I$3:$I$302,MATCH($B40,품목마스터!$A$3:$A$302,0)),"")) | H40: =IF($B40="","",IFERROR(INDEX(소진분석!$J$6:$J$305,MATCH("R"&35,발주목록!$L$6:$L$305,0)),"")) | J40: =IF(소진분석!$A40="",FALSE(),IF($B$3="발주만",소진분석!$L40="발주",OR(소진분석!$L40="발주",소진분석!$L40="임박"))) -> FALSE | K40: =IF($J40=FALSE(),"",COUNTIF($J$6:$J40,TRUE())) | L40: =IF($K40="","","R"&$K40)
A41: =IF($B41="","",36) | B41: =IFERROR(INDEX(소진분석!$A$6:$A$305,MATCH("R"&36,발주목록!$L$6:$L$305,0)),"") | C41: =IF($B41="","",IFERROR(INDEX(소진분석!$B$6:$B$305,MATCH("R"&36,발주목록!$L$6:$L$305,0)),"")) | D41: =IF($B41="","",IFERROR(INDEX(소진분석!$C$6:$C$305,MATCH("R"&36,발주목록!$L$6:$L$305,0)),"")) | E41: =IF($B41="","",IFERROR(INDEX(소진분석!$D$6:$D$305,MATCH("R"&36,발주목록!$L$6:$L$305,0)),"")) | F41: =IF($B41="","",IFERROR(INDEX(소진분석!$K$6:$K$305,MATCH("R"&36,발주목록!$L$6:$L$305,0)),"")) | G41: =IF($B41="","",IFERROR(INDEX(품목마스터!$I$3:$I$302,MATCH($B41,품목마스터!$A$3:$A$302,0)),"")) | H41: =IF($B41="","",IFERROR(INDEX(소진분석!$J$6:$J$305,MATCH("R"&36,발주목록!$L$6:$L$305,0)),"")) | J41: =IF(소진분석!$A41="",FALSE(),IF($B$3="발주만",소진분석!$L41="발주",OR(소진분석!$L41="발주",소진분석!$L41="임박"))) -> FALSE | K41: =IF($J41=FALSE(),"",COUNTIF($J$6:$J41,TRUE())) | L41: =IF($K41="","","R"&$K41)
A42: =IF($B42="","",37) | B42: =IFERROR(INDEX(소진분석!$A$6:$A$305,MATCH("R"&37,발주목록!$L$6:$L$305,0)),"") | C42: =IF($B42="","",IFERROR(INDEX(소진분석!$B$6:$B$305,MATCH("R"&37,발주목록!$L$6:$L$305,0)),"")) | D42: =IF($B42="","",IFERROR(INDEX(소진분석!$C$6:$C$305,MATCH("R"&37,발주목록!$L$6:$L$305,0)),"")) | E42: =IF($B42="","",IFERROR(INDEX(소진분석!$D$6:$D$305,MATCH("R"&37,발주목록!$L$6:$L$305,0)),"")) | F42: =IF($B42="","",IFERROR(INDEX(소진분석!$K$6:$K$305,MATCH("R"&37,발주목록!$L$6:$L$305,0)),"")) | G42: =IF($B42="","",IFERROR(INDEX(품목마스터!$I$3:$I$302,MATCH($B42,품목마스터!$A$3:$A$302,0)),"")) | H42: =IF($B42="","",IFERROR(INDEX(소진분석!$J$6:$J$305,MATCH("R"&37,발주목록!$L$6:$L$305,0)),"")) | J42: =IF(소진분석!$A42="",FALSE(),IF($B$3="발주만",소진분석!$L42="발주",OR(소진분석!$L42="발주",소진분석!$L42="임박"))) -> FALSE | K42: =IF($J42=FALSE(),"",COUNTIF($J$6:$J42,TRUE())) | L42: =IF($K42="","","R"&$K42)
...

Sheet 품목별_사용추이
A1: 품목별 사용추이
A3: 품번 | B3: M001 | C3: =IFERROR(INDEX(품목마스터!$B$3:$B$302,MATCH($B$3,품목마스터!$A$3:$A$302,0)),"") -> 생리식염수 500ml
A4: 대상 연도 | B4: 2026
A6: 월 | B6: 사용량 | C6: 사용 건수 | D6: 하루 평균 | E6: 비고
A7: 1 | B7: =SUMIFS(사용내역!$E$3:$E$3002,사용내역!$B$3:$B$3002,$B$3,사용내역!$A$3:$A$3002,">="&DATE($B$4,1,1),사용내역!$A$3:$A$3002,"<="&EOMONTH(DATE($B$4,1,1),0)) -> 0 | C7: =COUNTIFS(사용내역!$B$3:$B$3002,$B$3,사용내역!$A$3:$A$3002,">="&DATE($B$4,1,1),사용내역!$A$3:$A$3002,"<="&EOMONTH(DATE($B$4,1,1),0)) -> 0 | D7: =IF($B7=0,0,ROUND($B7/DAY(EOMONTH(DATE($B$4,1,1),0)),2)) -> 0
A8: 2 | B8: =SUMIFS(사용내역!$E$3:$E$3002,사용내역!$B$3:$B$3002,$B$3,사용내역!$A$3:$A$3002,">="&DATE($B$4,2,1),사용내역!$A$3:$A$3002,"<="&EOMONTH(DATE($B$4,2,1),0)) -> 0 | C8: =COUNTIFS(사용내역!$B$3:$B$3002,$B$3,사용내역!$A$3:$A$3002,">="&DATE($B$4,2,1),사용내역!$A$3:$A$3002,"<="&EOMONTH(DATE($B$4,2,1),0)) -> 0 | D8: =IF($B8=0,0,ROUND($B8/DAY(EOMONTH(DATE($B$4,2,1),0)),2)) -> 0
A9: 3 | B9: =SUMIFS(사용내역!$E$3:$E$3002,사용내역!$B$3:$B$3002,$B$3,사용내역!$A$3:$A$3002,">="&DATE($B$4,3,1),사용내역!$A$3:$A$3002,"<="&EOMONTH(DATE($B$4,3,1),0)) -> 0 | C9: =COUNTIFS(사용내역!$B$3:$B$3002,$B$3,사용내역!$A$3:$A$3002,">="&DATE($B$4,3,1),사용내역!$A$3:$A$3002,"<="&EOMONTH(DATE($B$4,3,1),0)) -> 0 | D9: =IF($B9=0,0,ROUND($B9/DAY(EOMONTH(DATE($B$4,3,1),0)),2)) -> 0
A10: 4 | B10: =SUMIFS(사용내역!$E$3:$E$3002,사용내역!$B$3:$B$3002,$B$3,사용내역!$A$3:$A$3002,">="&DATE($B$4,4,1),사용내역!$A$3:$A$3002,"<="&EOMONTH(DATE($B$4,4,1),0)) -> 0 | C10: =COUNTIFS(사용내역!$B$3:$B$3002,$B$3,사용내역!$A$3:$A$3002,">="&DATE($B$4,4,1),사용내역!$A$3:$A$3002,"<="&EOMONTH(DATE($B$4,4,1),0)) -> 0 | D10: =IF($B10=0,0,ROUND($B10/DAY(EOMONTH(DATE($B$4,4,1),0)),2)) -> 0
A11: 5 | B11: =SUMIFS(사용내역!$E$3:$E$3002,사용내역!$B$3:$B$3002,$B$3,사용내역!$A$3:$A$3002,">="&DATE($B$4,5,1),사용내역!$A$3:$A$3002,"<="&EOMONTH(DATE($B$4,5,1),0)) -> 0 | C11: =COUNTIFS(사용내역!$B$3:$B$3002,$B$3,사용내역!$A$3:$A$3002,">="&DATE($B$4,5,1),사용내역!$A$3:$A$3002,"<="&EOMONTH(DATE($B$4,5,1),0)) -> 0 | D11: =IF($B11=0,0,ROUND($B11/DAY(EOMONTH(DATE($B$4,5,1),0)),2)) -> 0
A12: 6 | B12: =SUMIFS(사용내역!$E$3:$E$3002,사용내역!$B$3:$B$3002,$B$3,사용내역!$A$3:$A$3002,">="&DATE($B$4,6,1),사용내역!$A$3:$A$3002,"<="&EOMONTH(DATE($B$4,6,1),0)) -> 0 | C12: =COUNTIFS(사용내역!$B$3:$B$3002,$B$3,사용내역!$A$3:$A$3002,">="&DATE($B$4,6,1),사용내역!$A$3:$A$3002,"<="&EOMONTH(DATE($B$4,6,1),0)) -> 0 | D12: =IF($B12=0,0,ROUND($B12/DAY(EOMONTH(DATE($B$4,6,1),0)),2)) -> 0
A13: 7 | B13: =SUMIFS(사용내역!$E$3:$E$3002,사용내역!$B$3:$B$3002,$B$3,사용내역!$A$3:$A$3002,">="&DATE($B$4,7,1),사용내역!$A$3:$A$3002,"<="&EOMONTH(DATE($B$4,7,1),0)) -> 27 | C13: =COUNTIFS(사용내역!$B$3:$B$3002,$B$3,사용내역!$A$3:$A$3002,">="&DATE($B$4,7,1),사용내역!$A$3:$A$3002,"<="&EOMONTH(DATE($B$4,7,1),0)) -> 2 | D13: =IF($B13=0,0,ROUND($B13/DAY(EOMONTH(DATE($B$4,7,1),0)),2)) -> 0.87
A14: 8 | B14: =SUMIFS(사용내역!$E$3:$E$3002,사용내역!$B$3:$B$3002,$B$3,사용내역!$A$3:$A$3002,">="&DATE($B$4,8,1),사용내역!$A$3:$A$3002,"<="&EOMONTH(DATE($B$4,8,1),0)) -> 32 | C14: =COUNTIFS(사용내역!$B$3:$B$3002,$B$3,사용내역!$A$3:$A$3002,">="&DATE($B$4,8,1),사용내역!$A$3:$A$3002,"<="&EOMONTH(DATE($B$4,8,1),0)) -> 2 | D14: =IF($B14=0,0,ROUND($B14/DAY(EOMONTH(DATE($B$4,8,1),0)),2)) -> 1.03
A15: 9 | B15: =SUMIFS(사용내역!$E$3:$E$3002,사용내역!$B$3:$B$3002,$B$3,사용내역!$A$3:$A$3002,">="&DATE($B$4,9,1),사용내역!$A$3:$A$3002,"<="&EOMONTH(DATE($B$4,9,1),0)) -> 16 | C15: =COUNTIFS(사용내역!$B$3:$B$3002,$B$3,사용내역!$A$3:$A$3002,">="&DATE($B$4,9,1),사용내역!$A$3:$A$3002,"<="&EOMONTH(DATE($B$4,9,1),0)) -> 1 | D15: =IF($B15=0,0,ROUND($B15/DAY(EOMONTH(DATE($B$4,9,1),0)),2)) -> 0.53
A16: 10 | B16: =SUMIFS(사용내역!$E$3:$E$3002,사용내역!$B$3:$B$3002,$B$3,사용내역!$A$3:$A$3002,">="&DATE($B$4,10,1),사용내역!$A$3:$A$3002,"<="&EOMONTH(DATE($B$4,10,1),0)) -> 0 | C16: =COUNTIFS(사용내역!$B$3:$B$3002,$B$3,사용내역!$A$3:$A$3002,">="&DATE($B$4,10,1),사용내역!$A$3:$A$3002,"<="&EOMONTH(DATE($B$4,10,1),0)) -> 0 | D16: =IF($B16=0,0,ROUND($B16/DAY(EOMONTH(DATE($B$4,10,1),0)),2)) -> 0
A17: 11 | B17: =SUMIFS(사용내역!$E$3:$E$3002,사용내역!$B$3:$B$3002,$B$3,사용내역!$A$3:$A$3002,">="&DATE($B$4,11,1),사용내역!$A$3:$A$3002,"<="&EOMONTH(DATE($B$4,11,1),0)) -> 0 | C17: =COUNTIFS(사용내역!$B$3:$B$3002,$B$3,사용내역!$A$3:$A$3002,">="&DATE($B$4,11,1),사용내역!$A$3:$A$3002,"<="&EOMONTH(DATE($B$4,11,1),0)) -> 0 | D17: =IF($B17=0,0,ROUND($B17/DAY(EOMONTH(DATE($B$4,11,1),0)),2)) -> 0
A18: 12 | B18: =SUMIFS(사용내역!$E$3:$E$3002,사용내역!$B$3:$B$3002,$B$3,사용내역!$A$3:$A$3002,">="&DATE($B$4,12,1),사용내역!$A$3:$A$3002,"<="&EOMONTH(DATE($B$4,12,1),0)) -> 0 | C18: =COUNTIFS(사용내역!$B$3:$B$3002,$B$3,사용내역!$A$3:$A$3002,">="&DATE($B$4,12,1),사용내역!$A$3:$A$3002,"<="&EOMONTH(DATE($B$4,12,1),0)) -> 0 | D18: =IF($B18=0,0,ROUND($B18/DAY(EOMONTH(DATE($B$4,12,1),0)),2)) -> 0
A19: 합계 | B19: =SUM(B7:B18) -> 75 | C19: =SUM(C7:C18) -> 5
