Workbook

Sheet 사용안내
B2: 경조사 · 기념일 관리
B4: 핵심 | C4: 생일·창립일·계약기념일을 등록해두면 올해 언제인지, 며칠 남았는지 자동으로 나옵니다.
B5: 입력 규칙 | C5: 파란색 글씨 칸만 입력하세요. 검은색은 자동 계산입니다.
B6: ① 대상목록 | C6: 거래처 담당자·직원 등 챙길 사람을 등록합니다.
B7: ② 기념일등록 | C7: 생일·창립일 등 매년 돌아오는 날을 등록합니다.
B8: ③ 경조사내역 | C8: 실제로 챙긴 기록입니다. 언제 얼마를 보냈는지 남깁니다.
B9: ④ 다가오는 일정 | C9: 앞으로 90일 안에 오는 기념일을 순서대로 보여줍니다.
B10: ⑤ 월별달력 | C10: 월을 고르면 그 달의 기념일이 나옵니다.
B11: ⑥ 거래처별 이력 | C11: 어느 거래처에 얼마나 썼는지 집계합니다.
B12: 올해 기념일 계산 | C12: 등록한 날짜의 월·일만 가져와 올해 날짜로 만듭니다. 지났으면 내년으로 넘깁니다.
B13: 주의 | C13: 음력 생일은 지원하지 않습니다. 양력으로 변환해서 넣으세요.
B15: 설정 | C15: 값을 바꾸면 모든 계산에 반영됩니다
B16: 알림 기준(일) | C16: 14

Sheet 대상목록
A1: 대상목록
A2: 이름 | B2: 구분 | C2: 거래처/소속 | D2: 직위 | E2: 연락처 | F2: 비고
A3: 김사장 | B3: 거래처 | C3: ○○상사 | D3: 대표 | E3: 010-0000-0001
A4: 이과장 | B4: 거래처 | C4: △△유통 | D4: 과장 | E4: 010-0000-0002
A5: 박직원 | B5: 내부 | C5: 영업팀 | D5: 대리 | E5: 010-0000-0003

Sheet 기념일등록
A1: 기념일등록 (매년 돌아오는 날)
A2: No(자동) | B2: 이름 | C2: 거래처(자동) | D2: 종류 | E2: 기준일 | F2: 월(자동) | G2: 일(자동) | H2: 올해 날짜(자동) | I2: D-Day(자동) | J2: 비고
A3: =IF($B3="","",ROW()-2) -> 1 | B3: 김사장 | C3: =IF($B3="","",IFERROR(INDEX(대상목록!$C$3:$C$302,MATCH($B3,대상목록!$A$3:$A$302,0)),"")) -> ○○상사 | D3: 생일 | E3: 27662 | F3: =IF($E3="","",MONTH($E3)) -> 9 | G3: =IF($E3="","",DAY($E3)) -> 25 | H3: =IF($E3="","",IF(DATE(YEAR(TODAY()),$F3,$G3)<TODAY(),DATE(YEAR(TODAY())+1,$F3,$G3),DATE(YEAR(TODAY()),$F3,$G3))) -> 46290 | I3: =IF($H3="","",$H3-TODAY()) -> 11
A4: =IF($B4="","",ROW()-2) -> 2 | B4: 이과장 | C4: =IF($B4="","",IFERROR(INDEX(대상목록!$C$3:$C$302,MATCH($B4,대상목록!$A$3:$A$302,0)),"")) -> △△유통 | D4: 생일 | E4: 30020 | F4: =IF($E4="","",MONTH($E4)) -> 3 | G4: =IF($E4="","",DAY($E4)) -> 10 | H4: =IF($E4="","",IF(DATE(YEAR(TODAY()),$F4,$G4)<TODAY(),DATE(YEAR(TODAY())+1,$F4,$G4),DATE(YEAR(TODAY()),$F4,$G4))) -> 46456 | I4: =IF($H4="","",$H4-TODAY()) -> 177
A5: =IF($B5="","",ROW()-2) -> 3 | B5: 김사장 | C5: =IF($B5="","",IFERROR(INDEX(대상목록!$C$3:$C$302,MATCH($B5,대상목록!$A$3:$A$302,0)),"")) -> ○○상사 | D5: 창립기념일 | E5: 38615 | F5: =IF($E5="","",MONTH($E5)) -> 9 | G5: =IF($E5="","",DAY($E5)) -> 20 | H5: =IF($E5="","",IF(DATE(YEAR(TODAY()),$F5,$G5)<TODAY(),DATE(YEAR(TODAY())+1,$F5,$G5),DATE(YEAR(TODAY()),$F5,$G5))) -> 46285 | I5: =IF($H5="","",$H5-TODAY()) -> 6
A6: =IF($B6="","",ROW()-2) -> 4 | B6: 박직원 | C6: =IF($B6="","",IFERROR(INDEX(대상목록!$C$3:$C$302,MATCH($B6,대상목록!$A$3:$A$302,0)),"")) -> 영업팀 | D6: 입사기념일 | E6: 44501 | F6: =IF($E6="","",MONTH($E6)) -> 11 | G6: =IF($E6="","",DAY($E6)) -> 1 | H6: =IF($E6="","",IF(DATE(YEAR(TODAY()),$F6,$G6)<TODAY(),DATE(YEAR(TODAY())+1,$F6,$G6),DATE(YEAR(TODAY()),$F6,$G6))) -> 46327 | I6: =IF($H6="","",$H6-TODAY()) -> 48
A7: =IF($B7="","",ROW()-2) | C7: =IF($B7="","",IFERROR(INDEX(대상목록!$C$3:$C$302,MATCH($B7,대상목록!$A$3:$A$302,0)),"")) | F7: =IF($E7="","",MONTH($E7)) | G7: =IF($E7="","",DAY($E7)) | H7: =IF($E7="","",IF(DATE(YEAR(TODAY()),$F7,$G7)<TODAY(),DATE(YEAR(TODAY())+1,$F7,$G7),DATE(YEAR(TODAY()),$F7,$G7))) | I7: =IF($H7="","",$H7-TODAY())
A8: =IF($B8="","",ROW()-2) | C8: =IF($B8="","",IFERROR(INDEX(대상목록!$C$3:$C$302,MATCH($B8,대상목록!$A$3:$A$302,0)),"")) | F8: =IF($E8="","",MONTH($E8)) | G8: =IF($E8="","",DAY($E8)) | H8: =IF($E8="","",IF(DATE(YEAR(TODAY()),$F8,$G8)<TODAY(),DATE(YEAR(TODAY())+1,$F8,$G8),DATE(YEAR(TODAY()),$F8,$G8))) | I8: =IF($H8="","",$H8-TODAY())
A9: =IF($B9="","",ROW()-2) | C9: =IF($B9="","",IFERROR(INDEX(대상목록!$C$3:$C$302,MATCH($B9,대상목록!$A$3:$A$302,0)),"")) | F9: =IF($E9="","",MONTH($E9)) | G9: =IF($E9="","",DAY($E9)) | H9: =IF($E9="","",IF(DATE(YEAR(TODAY()),$F9,$G9)<TODAY(),DATE(YEAR(TODAY())+1,$F9,$G9),DATE(YEAR(TODAY()),$F9,$G9))) | I9: =IF($H9="","",$H9-TODAY())
A10: =IF($B10="","",ROW()-2) | C10: =IF($B10="","",IFERROR(INDEX(대상목록!$C$3:$C$302,MATCH($B10,대상목록!$A$3:$A$302,0)),"")) | F10: =IF($E10="","",MONTH($E10)) | G10: =IF($E10="","",DAY($E10)) | H10: =IF($E10="","",IF(DATE(YEAR(TODAY()),$F10,$G10)<TODAY(),DATE(YEAR(TODAY())+1,$F10,$G10),DATE(YEAR(TODAY()),$F10,$G10))) | I10: =IF($H10="","",$H10-TODAY())
A11: =IF($B11="","",ROW()-2) | C11: =IF($B11="","",IFERROR(INDEX(대상목록!$C$3:$C$302,MATCH($B11,대상목록!$A$3:$A$302,0)),"")) | F11: =IF($E11="","",MONTH($E11)) | G11: =IF($E11="","",DAY($E11)) | H11: =IF($E11="","",IF(DATE(YEAR(TODAY()),$F11,$G11)<TODAY(),DATE(YEAR(TODAY())+1,$F11,$G11),DATE(YEAR(TODAY()),$F11,$G11))) | I11: =IF($H11="","",$H11-TODAY())
A12: =IF($B12="","",ROW()-2) | C12: =IF($B12="","",IFERROR(INDEX(대상목록!$C$3:$C$302,MATCH($B12,대상목록!$A$3:$A$302,0)),"")) | F12: =IF($E12="","",MONTH($E12)) | G12: =IF($E12="","",DAY($E12)) | H12: =IF($E12="","",IF(DATE(YEAR(TODAY()),$F12,$G12)<TODAY(),DATE(YEAR(TODAY())+1,$F12,$G12),DATE(YEAR(TODAY()),$F12,$G12))) | I12: =IF($H12="","",$H12-TODAY())
A13: =IF($B13="","",ROW()-2) | C13: =IF($B13="","",IFERROR(INDEX(대상목록!$C$3:$C$302,MATCH($B13,대상목록!$A$3:$A$302,0)),"")) | F13: =IF($E13="","",MONTH($E13)) | G13: =IF($E13="","",DAY($E13)) | H13: =IF($E13="","",IF(DATE(YEAR(TODAY()),$F13,$G13)<TODAY(),DATE(YEAR(TODAY())+1,$F13,$G13),DATE(YEAR(TODAY()),$F13,$G13))) | I13: =IF($H13="","",$H13-TODAY())
A14: =IF($B14="","",ROW()-2) | C14: =IF($B14="","",IFERROR(INDEX(대상목록!$C$3:$C$302,MATCH($B14,대상목록!$A$3:$A$302,0)),"")) | F14: =IF($E14="","",MONTH($E14)) | G14: =IF($E14="","",DAY($E14)) | H14: =IF($E14="","",IF(DATE(YEAR(TODAY()),$F14,$G14)<TODAY(),DATE(YEAR(TODAY())+1,$F14,$G14),DATE(YEAR(TODAY()),$F14,$G14))) | I14: =IF($H14="","",$H14-TODAY())
A15: =IF($B15="","",ROW()-2) | C15: =IF($B15="","",IFERROR(INDEX(대상목록!$C$3:$C$302,MATCH($B15,대상목록!$A$3:$A$302,0)),"")) | F15: =IF($E15="","",MONTH($E15)) | G15: =IF($E15="","",DAY($E15)) | H15: =IF($E15="","",IF(DATE(YEAR(TODAY()),$F15,$G15)<TODAY(),DATE(YEAR(TODAY())+1,$F15,$G15),DATE(YEAR(TODAY()),$F15,$G15))) | I15: =IF($H15="","",$H15-TODAY())
A16: =IF($B16="","",ROW()-2) | C16: =IF($B16="","",IFERROR(INDEX(대상목록!$C$3:$C$302,MATCH($B16,대상목록!$A$3:$A$302,0)),"")) | F16: =IF($E16="","",MONTH($E16)) | G16: =IF($E16="","",DAY($E16)) | H16: =IF($E16="","",IF(DATE(YEAR(TODAY()),$F16,$G16)<TODAY(),DATE(YEAR(TODAY())+1,$F16,$G16),DATE(YEAR(TODAY()),$F16,$G16))) | I16: =IF($H16="","",$H16-TODAY())
A17: =IF($B17="","",ROW()-2) | C17: =IF($B17="","",IFERROR(INDEX(대상목록!$C$3:$C$302,MATCH($B17,대상목록!$A$3:$A$302,0)),"")) | F17: =IF($E17="","",MONTH($E17)) | G17: =IF($E17="","",DAY($E17)) | H17: =IF($E17="","",IF(DATE(YEAR(TODAY()),$F17,$G17)<TODAY(),DATE(YEAR(TODAY())+1,$F17,$G17),DATE(YEAR(TODAY()),$F17,$G17))) | I17: =IF($H17="","",$H17-TODAY())
A18: =IF($B18="","",ROW()-2) | C18: =IF($B18="","",IFERROR(INDEX(대상목록!$C$3:$C$302,MATCH($B18,대상목록!$A$3:$A$302,0)),"")) | F18: =IF($E18="","",MONTH($E18)) | G18: =IF($E18="","",DAY($E18)) | H18: =IF($E18="","",IF(DATE(YEAR(TODAY()),$F18,$G18)<TODAY(),DATE(YEAR(TODAY())+1,$F18,$G18),DATE(YEAR(TODAY()),$F18,$G18))) | I18: =IF($H18="","",$H18-TODAY())
... A502: =IF($B502="","",ROW()-2) | C502: =IF($B502="","",IFERROR(INDEX(대상목록!$C$3:$C$302,MATCH($B502,대상목록!$A$3:$A$302,0)),"")) | F502: =IF($E502="","",MONTH($E502)) | G502: =IF($E502="","",DAY($E502)) | H502: =IF($E502="","",IF(DATE(YEAR(TODAY()),$F502,$G502)<TODAY(),DATE(YEAR(TODAY())+1,$F502,$G502),DATE(YEAR(TODAY()),$F502,$G502))) | I502: =IF($H502="","",$H502-TODAY())
A504: ※ 기준일은 태어난 해·창립한 해를 그대로 넣으세요. 월·일만 사용합니다.
A505: ※ 2월 29일은 윤년이 아닌 해에 3월 1일로 넘어갑니다.

Sheet 경조사내역
A1: 경조사내역 (실제로 챙긴 기록)
A2: 일자 | B2: 이름 | C2: 거래처(자동) | D2: 종류 | E2: 내용 | F2: 금액 | G2: 비고
A3: 45920 | B3: 김사장 | C3: =IF($B3="","",IFERROR(INDEX(대상목록!$C$3:$C$302,MATCH($B3,대상목록!$A$3:$A$302,0)),"")) -> ○○상사 | D3: 창립 | E3: 창립기념 화환 | F3: 100000 | G3: ← 예시 행입니다. 지우고 쓰세요.
A4: 45925 | B4: 김사장 | C4: =IF($B4="","",IFERROR(INDEX(대상목록!$C$3:$C$302,MATCH($B4,대상목록!$A$3:$A$302,0)),"")) -> ○○상사 | D4: 생일 | E4: 생일 선물 (홍삼세트) | F4: 150000
A5: 46091 | B5: 이과장 | C5: =IF($B5="","",IFERROR(INDEX(대상목록!$C$3:$C$302,MATCH($B5,대상목록!$A$3:$A$302,0)),"")) -> △△유통 | D5: 생일 | E5: 생일 축하 기프티콘 | F5: 50000
A6: 46160 | B6: 김사장 | C6: =IF($B6="","",IFERROR(INDEX(대상목록!$C$3:$C$302,MATCH($B6,대상목록!$A$3:$A$302,0)),"")) -> ○○상사 | D6: 결혼 | E6: 자녀 결혼 축의금 | F6: 200000
A7: 46195 | B7: 박직원 | C7: =IF($B7="","",IFERROR(INDEX(대상목록!$C$3:$C$302,MATCH($B7,대상목록!$A$3:$A$302,0)),"")) -> 영업팀 | D7: 출산 | E7: 출산 축하금 | F7: 300000
A8: 46248 | B8: 이과장 | C8: =IF($B8="","",IFERROR(INDEX(대상목록!$C$3:$C$302,MATCH($B8,대상목록!$A$3:$A$302,0)),"")) -> △△유통 | D8: 부고 | E8: 조의금 (모친상) | F8: 100000
C9: =IF($B9="","",IFERROR(INDEX(대상목록!$C$3:$C$302,MATCH($B9,대상목록!$A$3:$A$302,0)),""))
C10: =IF($B10="","",IFERROR(INDEX(대상목록!$C$3:$C$302,MATCH($B10,대상목록!$A$3:$A$302,0)),""))
C11: =IF($B11="","",IFERROR(INDEX(대상목록!$C$3:$C$302,MATCH($B11,대상목록!$A$3:$A$302,0)),""))
C12: =IF($B12="","",IFERROR(INDEX(대상목록!$C$3:$C$302,MATCH($B12,대상목록!$A$3:$A$302,0)),""))
C13: =IF($B13="","",IFERROR(INDEX(대상목록!$C$3:$C$302,MATCH($B13,대상목록!$A$3:$A$302,0)),""))
C14: =IF($B14="","",IFERROR(INDEX(대상목록!$C$3:$C$302,MATCH($B14,대상목록!$A$3:$A$302,0)),""))
C15: =IF($B15="","",IFERROR(INDEX(대상목록!$C$3:$C$302,MATCH($B15,대상목록!$A$3:$A$302,0)),""))
C16: =IF($B16="","",IFERROR(INDEX(대상목록!$C$3:$C$302,MATCH($B16,대상목록!$A$3:$A$302,0)),""))
C17: =IF($B17="","",IFERROR(INDEX(대상목록!$C$3:$C$302,MATCH($B17,대상목록!$A$3:$A$302,0)),""))
C18: =IF($B18="","",IFERROR(INDEX(대상목록!$C$3:$C$302,MATCH($B18,대상목록!$A$3:$A$302,0)),""))
C19: =IF($B19="","",IFERROR(INDEX(대상목록!$C$3:$C$302,MATCH($B19,대상목록!$A$3:$A$302,0)),""))
C20: =IF($B20="","",IFERROR(INDEX(대상목록!$C$3:$C$302,MATCH($B20,대상목록!$A$3:$A$302,0)),""))
... C1002: =IF($B1002="","",IFERROR(INDEX(대상목록!$C$3:$C$302,MATCH($B1002,대상목록!$A$3:$A$302,0)),""))

Sheet 다가오는일정
A1: 다가오는 일정 (앞으로 90일)
A3: 오늘 | B3: =TODAY() -> 46279 | D3: 알림 대상 | E3: =COUNTIFS(기념일등록!$I$3:$I$502,">=0",기념일등록!$I$3:$I$502,"<="&사용안내!$C$16) -> 2
A5: 순위 | B5: 날짜 | C5: D-Day | D5: 이름 | E5: 거래처 | F5: 종류 | G5: 작년 기록
A6: =IF($D6="","",1) -> 1 | B6: =IFERROR(INDEX(기념일등록!$H$3:$H$502,MATCH(1,다가오는일정!$K$6:$K$505,0)),"") -> 46285 | C6: =IF($B6="","",IFERROR(INDEX(기념일등록!$I$3:$I$502,MATCH(1,다가오는일정!$K$6:$K$505,0)),"")) -> 6 | D6: =IFERROR(INDEX(기념일등록!$B$3:$B$502,MATCH(1,다가오는일정!$K$6:$K$505,0)),"") -> 김사장 | E6: =IF($D6="","",IFERROR(INDEX(기념일등록!$C$3:$C$502,MATCH(1,다가오는일정!$K$6:$K$505,0)),"")) -> ○○상사 | F6: =IF($D6="","",IFERROR(INDEX(기념일등록!$D$3:$D$502,MATCH(1,다가오는일정!$K$6:$K$505,0)),"")) -> 창립기념일 | G6: =IF($D6="","",SUMIFS(경조사내역!$F$3:$F$1002,경조사내역!$B$3:$B$1002,$D6,경조사내역!$A$3:$A$1002,">="&DATE(YEAR(TODAY())-1,1,1),경조사내역!$A$3:$A$1002,"<="&DATE(YEAR(TODAY())-1,12,31))) -> 250000 | I6: =IF(기념일등록!$B3="",FALSE(),AND(기념일등록!$I3>=0,기념일등록!$I3<=90)) -> TRUE | J6: =IF($I6=FALSE(),"",기념일등록!$I3*1000+ROW()) -> 11006 | K6: =IF($J6="","",RANK($J6,$J$6:$J$505,1)) -> 2
A7: =IF($D7="","",2) -> 2 | B7: =IFERROR(INDEX(기념일등록!$H$3:$H$502,MATCH(2,다가오는일정!$K$6:$K$505,0)),"") -> 46290 | C7: =IF($B7="","",IFERROR(INDEX(기념일등록!$I$3:$I$502,MATCH(2,다가오는일정!$K$6:$K$505,0)),"")) -> 11 | D7: =IFERROR(INDEX(기념일등록!$B$3:$B$502,MATCH(2,다가오는일정!$K$6:$K$505,0)),"") -> 김사장 | E7: =IF($D7="","",IFERROR(INDEX(기념일등록!$C$3:$C$502,MATCH(2,다가오는일정!$K$6:$K$505,0)),"")) -> ○○상사 | F7: =IF($D7="","",IFERROR(INDEX(기념일등록!$D$3:$D$502,MATCH(2,다가오는일정!$K$6:$K$505,0)),"")) -> 생일 | G7: =IF($D7="","",SUMIFS(경조사내역!$F$3:$F$1002,경조사내역!$B$3:$B$1002,$D7,경조사내역!$A$3:$A$1002,">="&DATE(YEAR(TODAY())-1,1,1),경조사내역!$A$3:$A$1002,"<="&DATE(YEAR(TODAY())-1,12,31))) -> 250000 | I7: =IF(기념일등록!$B4="",FALSE(),AND(기념일등록!$I4>=0,기념일등록!$I4<=90)) -> FALSE | J7: =IF($I7=FALSE(),"",기념일등록!$I4*1000+ROW()) | K7: =IF($J7="","",RANK($J7,$J$6:$J$505,1))
A8: =IF($D8="","",3) -> 3 | B8: =IFERROR(INDEX(기념일등록!$H$3:$H$502,MATCH(3,다가오는일정!$K$6:$K$505,0)),"") -> 46327 | C8: =IF($B8="","",IFERROR(INDEX(기념일등록!$I$3:$I$502,MATCH(3,다가오는일정!$K$6:$K$505,0)),"")) -> 48 | D8: =IFERROR(INDEX(기념일등록!$B$3:$B$502,MATCH(3,다가오는일정!$K$6:$K$505,0)),"") -> 박직원 | E8: =IF($D8="","",IFERROR(INDEX(기념일등록!$C$3:$C$502,MATCH(3,다가오는일정!$K$6:$K$505,0)),"")) -> 영업팀 | F8: =IF($D8="","",IFERROR(INDEX(기념일등록!$D$3:$D$502,MATCH(3,다가오는일정!$K$6:$K$505,0)),"")) -> 입사기념일 | G8: =IF($D8="","",SUMIFS(경조사내역!$F$3:$F$1002,경조사내역!$B$3:$B$1002,$D8,경조사내역!$A$3:$A$1002,">="&DATE(YEAR(TODAY())-1,1,1),경조사내역!$A$3:$A$1002,"<="&DATE(YEAR(TODAY())-1,12,31))) -> 0 | I8: =IF(기념일등록!$B5="",FALSE(),AND(기념일등록!$I5>=0,기념일등록!$I5<=90)) -> TRUE | J8: =IF($I8=FALSE(),"",기념일등록!$I5*1000+ROW()) -> 6008 | K8: =IF($J8="","",RANK($J8,$J$6:$J$505,1)) -> 1
A9: =IF($D9="","",4) | B9: =IFERROR(INDEX(기념일등록!$H$3:$H$502,MATCH(4,다가오는일정!$K$6:$K$505,0)),"") | C9: =IF($B9="","",IFERROR(INDEX(기념일등록!$I$3:$I$502,MATCH(4,다가오는일정!$K$6:$K$505,0)),"")) | D9: =IFERROR(INDEX(기념일등록!$B$3:$B$502,MATCH(4,다가오는일정!$K$6:$K$505,0)),"") | E9: =IF($D9="","",IFERROR(INDEX(기념일등록!$C$3:$C$502,MATCH(4,다가오는일정!$K$6:$K$505,0)),"")) | F9: =IF($D9="","",IFERROR(INDEX(기념일등록!$D$3:$D$502,MATCH(4,다가오는일정!$K$6:$K$505,0)),"")) | G9: =IF($D9="","",SUMIFS(경조사내역!$F$3:$F$1002,경조사내역!$B$3:$B$1002,$D9,경조사내역!$A$3:$A$1002,">="&DATE(YEAR(TODAY())-1,1,1),경조사내역!$A$3:$A$1002,"<="&DATE(YEAR(TODAY())-1,12,31))) | I9: =IF(기념일등록!$B6="",FALSE(),AND(기념일등록!$I6>=0,기념일등록!$I6<=90)) -> TRUE | J9: =IF($I9=FALSE(),"",기념일등록!$I6*1000+ROW()) -> 48009 | K9: =IF($J9="","",RANK($J9,$J$6:$J$505,1)) -> 3
A10: =IF($D10="","",5) | B10: =IFERROR(INDEX(기념일등록!$H$3:$H$502,MATCH(5,다가오는일정!$K$6:$K$505,0)),"") | C10: =IF($B10="","",IFERROR(INDEX(기념일등록!$I$3:$I$502,MATCH(5,다가오는일정!$K$6:$K$505,0)),"")) | D10: =IFERROR(INDEX(기념일등록!$B$3:$B$502,MATCH(5,다가오는일정!$K$6:$K$505,0)),"") | E10: =IF($D10="","",IFERROR(INDEX(기념일등록!$C$3:$C$502,MATCH(5,다가오는일정!$K$6:$K$505,0)),"")) | F10: =IF($D10="","",IFERROR(INDEX(기념일등록!$D$3:$D$502,MATCH(5,다가오는일정!$K$6:$K$505,0)),"")) | G10: =IF($D10="","",SUMIFS(경조사내역!$F$3:$F$1002,경조사내역!$B$3:$B$1002,$D10,경조사내역!$A$3:$A$1002,">="&DATE(YEAR(TODAY())-1,1,1),경조사내역!$A$3:$A$1002,"<="&DATE(YEAR(TODAY())-1,12,31))) | I10: =IF(기념일등록!$B7="",FALSE(),AND(기념일등록!$I7>=0,기념일등록!$I7<=90)) -> FALSE | J10: =IF($I10=FALSE(),"",기념일등록!$I7*1000+ROW()) | K10: =IF($J10="","",RANK($J10,$J$6:$J$505,1))
A11: =IF($D11="","",6) | B11: =IFERROR(INDEX(기념일등록!$H$3:$H$502,MATCH(6,다가오는일정!$K$6:$K$505,0)),"") | C11: =IF($B11="","",IFERROR(INDEX(기념일등록!$I$3:$I$502,MATCH(6,다가오는일정!$K$6:$K$505,0)),"")) | D11: =IFERROR(INDEX(기념일등록!$B$3:$B$502,MATCH(6,다가오는일정!$K$6:$K$505,0)),"") | E11: =IF($D11="","",IFERROR(INDEX(기념일등록!$C$3:$C$502,MATCH(6,다가오는일정!$K$6:$K$505,0)),"")) | F11: =IF($D11="","",IFERROR(INDEX(기념일등록!$D$3:$D$502,MATCH(6,다가오는일정!$K$6:$K$505,0)),"")) | G11: =IF($D11="","",SUMIFS(경조사내역!$F$3:$F$1002,경조사내역!$B$3:$B$1002,$D11,경조사내역!$A$3:$A$1002,">="&DATE(YEAR(TODAY())-1,1,1),경조사내역!$A$3:$A$1002,"<="&DATE(YEAR(TODAY())-1,12,31))) | I11: =IF(기념일등록!$B8="",FALSE(),AND(기념일등록!$I8>=0,기념일등록!$I8<=90)) -> FALSE | J11: =IF($I11=FALSE(),"",기념일등록!$I8*1000+ROW()) | K11: =IF($J11="","",RANK($J11,$J$6:$J$505,1))
A12: =IF($D12="","",7) | B12: =IFERROR(INDEX(기념일등록!$H$3:$H$502,MATCH(7,다가오는일정!$K$6:$K$505,0)),"") | C12: =IF($B12="","",IFERROR(INDEX(기념일등록!$I$3:$I$502,MATCH(7,다가오는일정!$K$6:$K$505,0)),"")) | D12: =IFERROR(INDEX(기념일등록!$B$3:$B$502,MATCH(7,다가오는일정!$K$6:$K$505,0)),"") | E12: =IF($D12="","",IFERROR(INDEX(기념일등록!$C$3:$C$502,MATCH(7,다가오는일정!$K$6:$K$505,0)),"")) | F12: =IF($D12="","",IFERROR(INDEX(기념일등록!$D$3:$D$502,MATCH(7,다가오는일정!$K$6:$K$505,0)),"")) | G12: =IF($D12="","",SUMIFS(경조사내역!$F$3:$F$1002,경조사내역!$B$3:$B$1002,$D12,경조사내역!$A$3:$A$1002,">="&DATE(YEAR(TODAY())-1,1,1),경조사내역!$A$3:$A$1002,"<="&DATE(YEAR(TODAY())-1,12,31))) | I12: =IF(기념일등록!$B9="",FALSE(),AND(기념일등록!$I9>=0,기념일등록!$I9<=90)) -> FALSE | J12: =IF($I12=FALSE(),"",기념일등록!$I9*1000+ROW()) | K12: =IF($J12="","",RANK($J12,$J$6:$J$505,1))
A13: =IF($D13="","",8) | B13: =IFERROR(INDEX(기념일등록!$H$3:$H$502,MATCH(8,다가오는일정!$K$6:$K$505,0)),"") | C13: =IF($B13="","",IFERROR(INDEX(기념일등록!$I$3:$I$502,MATCH(8,다가오는일정!$K$6:$K$505,0)),"")) | D13: =IFERROR(INDEX(기념일등록!$B$3:$B$502,MATCH(8,다가오는일정!$K$6:$K$505,0)),"") | E13: =IF($D13="","",IFERROR(INDEX(기념일등록!$C$3:$C$502,MATCH(8,다가오는일정!$K$6:$K$505,0)),"")) | F13: =IF($D13="","",IFERROR(INDEX(기념일등록!$D$3:$D$502,MATCH(8,다가오는일정!$K$6:$K$505,0)),"")) | G13: =IF($D13="","",SUMIFS(경조사내역!$F$3:$F$1002,경조사내역!$B$3:$B$1002,$D13,경조사내역!$A$3:$A$1002,">="&DATE(YEAR(TODAY())-1,1,1),경조사내역!$A$3:$A$1002,"<="&DATE(YEAR(TODAY())-1,12,31))) | I13: =IF(기념일등록!$B10="",FALSE(),AND(기념일등록!$I10>=0,기념일등록!$I10<=90)) -> FALSE | J13: =IF($I13=FALSE(),"",기념일등록!$I10*1000+ROW()) | K13: =IF($J13="","",RANK($J13,$J$6:$J$505,1))
A14: =IF($D14="","",9) | B14: =IFERROR(INDEX(기념일등록!$H$3:$H$502,MATCH(9,다가오는일정!$K$6:$K$505,0)),"") | C14: =IF($B14="","",IFERROR(INDEX(기념일등록!$I$3:$I$502,MATCH(9,다가오는일정!$K$6:$K$505,0)),"")) | D14: =IFERROR(INDEX(기념일등록!$B$3:$B$502,MATCH(9,다가오는일정!$K$6:$K$505,0)),"") | E14: =IF($D14="","",IFERROR(INDEX(기념일등록!$C$3:$C$502,MATCH(9,다가오는일정!$K$6:$K$505,0)),"")) | F14: =IF($D14="","",IFERROR(INDEX(기념일등록!$D$3:$D$502,MATCH(9,다가오는일정!$K$6:$K$505,0)),"")) | G14: =IF($D14="","",SUMIFS(경조사내역!$F$3:$F$1002,경조사내역!$B$3:$B$1002,$D14,경조사내역!$A$3:$A$1002,">="&DATE(YEAR(TODAY())-1,1,1),경조사내역!$A$3:$A$1002,"<="&DATE(YEAR(TODAY())-1,12,31))) | I14: =IF(기념일등록!$B11="",FALSE(),AND(기념일등록!$I11>=0,기념일등록!$I11<=90)) -> FALSE | J14: =IF($I14=FALSE(),"",기념일등록!$I11*1000+ROW()) | K14: =IF($J14="","",RANK($J14,$J$6:$J$505,1))
A15: =IF($D15="","",10) | B15: =IFERROR(INDEX(기념일등록!$H$3:$H$502,MATCH(10,다가오는일정!$K$6:$K$505,0)),"") | C15: =IF($B15="","",IFERROR(INDEX(기념일등록!$I$3:$I$502,MATCH(10,다가오는일정!$K$6:$K$505,0)),"")) | D15: =IFERROR(INDEX(기념일등록!$B$3:$B$502,MATCH(10,다가오는일정!$K$6:$K$505,0)),"") | E15: =IF($D15="","",IFERROR(INDEX(기념일등록!$C$3:$C$502,MATCH(10,다가오는일정!$K$6:$K$505,0)),"")) | F15: =IF($D15="","",IFERROR(INDEX(기념일등록!$D$3:$D$502,MATCH(10,다가오는일정!$K$6:$K$505,0)),"")) | G15: =IF($D15="","",SUMIFS(경조사내역!$F$3:$F$1002,경조사내역!$B$3:$B$1002,$D15,경조사내역!$A$3:$A$1002,">="&DATE(YEAR(TODAY())-1,1,1),경조사내역!$A$3:$A$1002,"<="&DATE(YEAR(TODAY())-1,12,31))) | I15: =IF(기념일등록!$B12="",FALSE(),AND(기념일등록!$I12>=0,기념일등록!$I12<=90)) -> FALSE | J15: =IF($I15=FALSE(),"",기념일등록!$I12*1000+ROW()) | K15: =IF($J15="","",RANK($J15,$J$6:$J$505,1))
A16: =IF($D16="","",11) | B16: =IFERROR(INDEX(기념일등록!$H$3:$H$502,MATCH(11,다가오는일정!$K$6:$K$505,0)),"") | C16: =IF($B16="","",IFERROR(INDEX(기념일등록!$I$3:$I$502,MATCH(11,다가오는일정!$K$6:$K$505,0)),"")) | D16: =IFERROR(INDEX(기념일등록!$B$3:$B$502,MATCH(11,다가오는일정!$K$6:$K$505,0)),"") | E16: =IF($D16="","",IFERROR(INDEX(기념일등록!$C$3:$C$502,MATCH(11,다가오는일정!$K$6:$K$505,0)),"")) | F16: =IF($D16="","",IFERROR(INDEX(기념일등록!$D$3:$D$502,MATCH(11,다가오는일정!$K$6:$K$505,0)),"")) | G16: =IF($D16="","",SUMIFS(경조사내역!$F$3:$F$1002,경조사내역!$B$3:$B$1002,$D16,경조사내역!$A$3:$A$1002,">="&DATE(YEAR(TODAY())-1,1,1),경조사내역!$A$3:$A$1002,"<="&DATE(YEAR(TODAY())-1,12,31))) | I16: =IF(기념일등록!$B13="",FALSE(),AND(기념일등록!$I13>=0,기념일등록!$I13<=90)) -> FALSE | J16: =IF($I16=FALSE(),"",기념일등록!$I13*1000+ROW()) | K16: =IF($J16="","",RANK($J16,$J$6:$J$505,1))
A17: =IF($D17="","",12) | B17: =IFERROR(INDEX(기념일등록!$H$3:$H$502,MATCH(12,다가오는일정!$K$6:$K$505,0)),"") | C17: =IF($B17="","",IFERROR(INDEX(기념일등록!$I$3:$I$502,MATCH(12,다가오는일정!$K$6:$K$505,0)),"")) | D17: =IFERROR(INDEX(기념일등록!$B$3:$B$502,MATCH(12,다가오는일정!$K$6:$K$505,0)),"") | E17: =IF($D17="","",IFERROR(INDEX(기념일등록!$C$3:$C$502,MATCH(12,다가오는일정!$K$6:$K$505,0)),"")) | F17: =IF($D17="","",IFERROR(INDEX(기념일등록!$D$3:$D$502,MATCH(12,다가오는일정!$K$6:$K$505,0)),"")) | G17: =IF($D17="","",SUMIFS(경조사내역!$F$3:$F$1002,경조사내역!$B$3:$B$1002,$D17,경조사내역!$A$3:$A$1002,">="&DATE(YEAR(TODAY())-1,1,1),경조사내역!$A$3:$A$1002,"<="&DATE(YEAR(TODAY())-1,12,31))) | I17: =IF(기념일등록!$B14="",FALSE(),AND(기념일등록!$I14>=0,기념일등록!$I14<=90)) -> FALSE | J17: =IF($I17=FALSE(),"",기념일등록!$I14*1000+ROW()) | K17: =IF($J17="","",RANK($J17,$J$6:$J$505,1))
A18: =IF($D18="","",13) | B18: =IFERROR(INDEX(기념일등록!$H$3:$H$502,MATCH(13,다가오는일정!$K$6:$K$505,0)),"") | C18: =IF($B18="","",IFERROR(INDEX(기념일등록!$I$3:$I$502,MATCH(13,다가오는일정!$K$6:$K$505,0)),"")) | D18: =IFERROR(INDEX(기념일등록!$B$3:$B$502,MATCH(13,다가오는일정!$K$6:$K$505,0)),"") | E18: =IF($D18="","",IFERROR(INDEX(기념일등록!$C$3:$C$502,MATCH(13,다가오는일정!$K$6:$K$505,0)),"")) | F18: =IF($D18="","",IFERROR(INDEX(기념일등록!$D$3:$D$502,MATCH(13,다가오는일정!$K$6:$K$505,0)),"")) | G18: =IF($D18="","",SUMIFS(경조사내역!$F$3:$F$1002,경조사내역!$B$3:$B$1002,$D18,경조사내역!$A$3:$A$1002,">="&DATE(YEAR(TODAY())-1,1,1),경조사내역!$A$3:$A$1002,"<="&DATE(YEAR(TODAY())-1,12,31))) | I18: =IF(기념일등록!$B15="",FALSE(),AND(기념일등록!$I15>=0,기념일등록!$I15<=90)) -> FALSE | J18: =IF($I18=FALSE(),"",기념일등록!$I15*1000+ROW()) | K18: =IF($J18="","",RANK($J18,$J$6:$J$505,1))
A19: =IF($D19="","",14) | B19: =IFERROR(INDEX(기념일등록!$H$3:$H$502,MATCH(14,다가오는일정!$K$6:$K$505,0)),"") | C19: =IF($B19="","",IFERROR(INDEX(기념일등록!$I$3:$I$502,MATCH(14,다가오는일정!$K$6:$K$505,0)),"")) | D19: =IFERROR(INDEX(기념일등록!$B$3:$B$502,MATCH(14,다가오는일정!$K$6:$K$505,0)),"") | E19: =IF($D19="","",IFERROR(INDEX(기념일등록!$C$3:$C$502,MATCH(14,다가오는일정!$K$6:$K$505,0)),"")) | F19: =IF($D19="","",IFERROR(INDEX(기념일등록!$D$3:$D$502,MATCH(14,다가오는일정!$K$6:$K$505,0)),"")) | G19: =IF($D19="","",SUMIFS(경조사내역!$F$3:$F$1002,경조사내역!$B$3:$B$1002,$D19,경조사내역!$A$3:$A$1002,">="&DATE(YEAR(TODAY())-1,1,1),경조사내역!$A$3:$A$1002,"<="&DATE(YEAR(TODAY())-1,12,31))) | I19: =IF(기념일등록!$B16="",FALSE(),AND(기념일등록!$I16>=0,기념일등록!$I16<=90)) -> FALSE | J19: =IF($I19=FALSE(),"",기념일등록!$I16*1000+ROW()) | K19: =IF($J19="","",RANK($J19,$J$6:$J$505,1))
A20: =IF($D20="","",15) | B20: =IFERROR(INDEX(기념일등록!$H$3:$H$502,MATCH(15,다가오는일정!$K$6:$K$505,0)),"") | C20: =IF($B20="","",IFERROR(INDEX(기념일등록!$I$3:$I$502,MATCH(15,다가오는일정!$K$6:$K$505,0)),"")) | D20: =IFERROR(INDEX(기념일등록!$B$3:$B$502,MATCH(15,다가오는일정!$K$6:$K$505,0)),"") | E20: =IF($D20="","",IFERROR(INDEX(기념일등록!$C$3:$C$502,MATCH(15,다가오는일정!$K$6:$K$505,0)),"")) | F20: =IF($D20="","",IFERROR(INDEX(기념일등록!$D$3:$D$502,MATCH(15,다가오는일정!$K$6:$K$505,0)),"")) | G20: =IF($D20="","",SUMIFS(경조사내역!$F$3:$F$1002,경조사내역!$B$3:$B$1002,$D20,경조사내역!$A$3:$A$1002,">="&DATE(YEAR(TODAY())-1,1,1),경조사내역!$A$3:$A$1002,"<="&DATE(YEAR(TODAY())-1,12,31))) | I20: =IF(기념일등록!$B17="",FALSE(),AND(기념일등록!$I17>=0,기념일등록!$I17<=90)) -> FALSE | J20: =IF($I20=FALSE(),"",기념일등록!$I17*1000+ROW()) | K20: =IF($J20="","",RANK($J20,$J$6:$J$505,1))
A21: =IF($D21="","",16) | B21: =IFERROR(INDEX(기념일등록!$H$3:$H$502,MATCH(16,다가오는일정!$K$6:$K$505,0)),"") | C21: =IF($B21="","",IFERROR(INDEX(기념일등록!$I$3:$I$502,MATCH(16,다가오는일정!$K$6:$K$505,0)),"")) | D21: =IFERROR(INDEX(기념일등록!$B$3:$B$502,MATCH(16,다가오는일정!$K$6:$K$505,0)),"") | E21: =IF($D21="","",IFERROR(INDEX(기념일등록!$C$3:$C$502,MATCH(16,다가오는일정!$K$6:$K$505,0)),"")) | F21: =IF($D21="","",IFERROR(INDEX(기념일등록!$D$3:$D$502,MATCH(16,다가오는일정!$K$6:$K$505,0)),"")) | G21: =IF($D21="","",SUMIFS(경조사내역!$F$3:$F$1002,경조사내역!$B$3:$B$1002,$D21,경조사내역!$A$3:$A$1002,">="&DATE(YEAR(TODAY())-1,1,1),경조사내역!$A$3:$A$1002,"<="&DATE(YEAR(TODAY())-1,12,31))) | I21: =IF(기념일등록!$B18="",FALSE(),AND(기념일등록!$I18>=0,기념일등록!$I18<=90)) -> FALSE | J21: =IF($I21=FALSE(),"",기념일등록!$I18*1000+ROW()) | K21: =IF($J21="","",RANK($J21,$J$6:$J$505,1))
A22: =IF($D22="","",17) | B22: =IFERROR(INDEX(기념일등록!$H$3:$H$502,MATCH(17,다가오는일정!$K$6:$K$505,0)),"") | C22: =IF($B22="","",IFERROR(INDEX(기념일등록!$I$3:$I$502,MATCH(17,다가오는일정!$K$6:$K$505,0)),"")) | D22: =IFERROR(INDEX(기념일등록!$B$3:$B$502,MATCH(17,다가오는일정!$K$6:$K$505,0)),"") | E22: =IF($D22="","",IFERROR(INDEX(기념일등록!$C$3:$C$502,MATCH(17,다가오는일정!$K$6:$K$505,0)),"")) | F22: =IF($D22="","",IFERROR(INDEX(기념일등록!$D$3:$D$502,MATCH(17,다가오는일정!$K$6:$K$505,0)),"")) | G22: =IF($D22="","",SUMIFS(경조사내역!$F$3:$F$1002,경조사내역!$B$3:$B$1002,$D22,경조사내역!$A$3:$A$1002,">="&DATE(YEAR(TODAY())-1,1,1),경조사내역!$A$3:$A$1002,"<="&DATE(YEAR(TODAY())-1,12,31))) | I22: =IF(기념일등록!$B19="",FALSE(),AND(기념일등록!$I19>=0,기념일등록!$I19<=90)) -> FALSE | J22: =IF($I22=FALSE(),"",기념일등록!$I19*1000+ROW()) | K22: =IF($J22="","",RANK($J22,$J$6:$J$505,1))
A23: =IF($D23="","",18) | B23: =IFERROR(INDEX(기념일등록!$H$3:$H$502,MATCH(18,다가오는일정!$K$6:$K$505,0)),"") | C23: =IF($B23="","",IFERROR(INDEX(기념일등록!$I$3:$I$502,MATCH(18,다가오는일정!$K$6:$K$505,0)),"")) | D23: =IFERROR(INDEX(기념일등록!$B$3:$B$502,MATCH(18,다가오는일정!$K$6:$K$505,0)),"") | E23: =IF($D23="","",IFERROR(INDEX(기념일등록!$C$3:$C$502,MATCH(18,다가오는일정!$K$6:$K$505,0)),"")) | F23: =IF($D23="","",IFERROR(INDEX(기념일등록!$D$3:$D$502,MATCH(18,다가오는일정!$K$6:$K$505,0)),"")) | G23: =IF($D23="","",SUMIFS(경조사내역!$F$3:$F$1002,경조사내역!$B$3:$B$1002,$D23,경조사내역!$A$3:$A$1002,">="&DATE(YEAR(TODAY())-1,1,1),경조사내역!$A$3:$A$1002,"<="&DATE(YEAR(TODAY())-1,12,31))) | I23: =IF(기념일등록!$B20="",FALSE(),AND(기념일등록!$I20>=0,기념일등록!$I20<=90)) -> FALSE | J23: =IF($I23=FALSE(),"",기념일등록!$I20*1000+ROW()) | K23: =IF($J23="","",RANK($J23,$J$6:$J$505,1))
A24: =IF($D24="","",19) | B24: =IFERROR(INDEX(기념일등록!$H$3:$H$502,MATCH(19,다가오는일정!$K$6:$K$505,0)),"") | C24: =IF($B24="","",IFERROR(INDEX(기념일등록!$I$3:$I$502,MATCH(19,다가오는일정!$K$6:$K$505,0)),"")) | D24: =IFERROR(INDEX(기념일등록!$B$3:$B$502,MATCH(19,다가오는일정!$K$6:$K$505,0)),"") | E24: =IF($D24="","",IFERROR(INDEX(기념일등록!$C$3:$C$502,MATCH(19,다가오는일정!$K$6:$K$505,0)),"")) | F24: =IF($D24="","",IFERROR(INDEX(기념일등록!$D$3:$D$502,MATCH(19,다가오는일정!$K$6:$K$505,0)),"")) | G24: =IF($D24="","",SUMIFS(경조사내역!$F$3:$F$1002,경조사내역!$B$3:$B$1002,$D24,경조사내역!$A$3:$A$1002,">="&DATE(YEAR(TODAY())-1,1,1),경조사내역!$A$3:$A$1002,"<="&DATE(YEAR(TODAY())-1,12,31))) | I24: =IF(기념일등록!$B21="",FALSE(),AND(기념일등록!$I21>=0,기념일등록!$I21<=90)) -> FALSE | J24: =IF($I24=FALSE(),"",기념일등록!$I21*1000+ROW()) | K24: =IF($J24="","",RANK($J24,$J$6:$J$505,1))
A25: =IF($D25="","",20) | B25: =IFERROR(INDEX(기념일등록!$H$3:$H$502,MATCH(20,다가오는일정!$K$6:$K$505,0)),"") | C25: =IF($B25="","",IFERROR(INDEX(기념일등록!$I$3:$I$502,MATCH(20,다가오는일정!$K$6:$K$505,0)),"")) | D25: =IFERROR(INDEX(기념일등록!$B$3:$B$502,MATCH(20,다가오는일정!$K$6:$K$505,0)),"") | E25: =IF($D25="","",IFERROR(INDEX(기념일등록!$C$3:$C$502,MATCH(20,다가오는일정!$K$6:$K$505,0)),"")) | F25: =IF($D25="","",IFERROR(INDEX(기념일등록!$D$3:$D$502,MATCH(20,다가오는일정!$K$6:$K$505,0)),"")) | G25: =IF($D25="","",SUMIFS(경조사내역!$F$3:$F$1002,경조사내역!$B$3:$B$1002,$D25,경조사내역!$A$3:$A$1002,">="&DATE(YEAR(TODAY())-1,1,1),경조사내역!$A$3:$A$1002,"<="&DATE(YEAR(TODAY())-1,12,31))) | I25: =IF(기념일등록!$B22="",FALSE(),AND(기념일등록!$I22>=0,기념일등록!$I22<=90)) -> FALSE | J25: =IF($I25=FALSE(),"",기념일등록!$I22*1000+ROW()) | K25: =IF($J25="","",RANK($J25,$J$6:$J$505,1))
A26: =IF($D26="","",21) | B26: =IFERROR(INDEX(기념일등록!$H$3:$H$502,MATCH(21,다가오는일정!$K$6:$K$505,0)),"") | C26: =IF($B26="","",IFERROR(INDEX(기념일등록!$I$3:$I$502,MATCH(21,다가오는일정!$K$6:$K$505,0)),"")) | D26: =IFERROR(INDEX(기념일등록!$B$3:$B$502,MATCH(21,다가오는일정!$K$6:$K$505,0)),"") | E26: =IF($D26="","",IFERROR(INDEX(기념일등록!$C$3:$C$502,MATCH(21,다가오는일정!$K$6:$K$505,0)),"")) | F26: =IF($D26="","",IFERROR(INDEX(기념일등록!$D$3:$D$502,MATCH(21,다가오는일정!$K$6:$K$505,0)),"")) | G26: =IF($D26="","",SUMIFS(경조사내역!$F$3:$F$1002,경조사내역!$B$3:$B$1002,$D26,경조사내역!$A$3:$A$1002,">="&DATE(YEAR(TODAY())-1,1,1),경조사내역!$A$3:$A$1002,"<="&DATE(YEAR(TODAY())-1,12,31))) | I26: =IF(기념일등록!$B23="",FALSE(),AND(기념일등록!$I23>=0,기념일등록!$I23<=90)) -> FALSE | J26: =IF($I26=FALSE(),"",기념일등록!$I23*1000+ROW()) | K26: =IF($J26="","",RANK($J26,$J$6:$J$505,1))
A27: =IF($D27="","",22) | B27: =IFERROR(INDEX(기념일등록!$H$3:$H$502,MATCH(22,다가오는일정!$K$6:$K$505,0)),"") | C27: =IF($B27="","",IFERROR(INDEX(기념일등록!$I$3:$I$502,MATCH(22,다가오는일정!$K$6:$K$505,0)),"")) | D27: =IFERROR(INDEX(기념일등록!$B$3:$B$502,MATCH(22,다가오는일정!$K$6:$K$505,0)),"") | E27: =IF($D27="","",IFERROR(INDEX(기념일등록!$C$3:$C$502,MATCH(22,다가오는일정!$K$6:$K$505,0)),"")) | F27: =IF($D27="","",IFERROR(INDEX(기념일등록!$D$3:$D$502,MATCH(22,다가오는일정!$K$6:$K$505,0)),"")) | G27: =IF($D27="","",SUMIFS(경조사내역!$F$3:$F$1002,경조사내역!$B$3:$B$1002,$D27,경조사내역!$A$3:$A$1002,">="&DATE(YEAR(TODAY())-1,1,1),경조사내역!$A$3:$A$1002,"<="&DATE(YEAR(TODAY())-1,12,31))) | I27: =IF(기념일등록!$B24="",FALSE(),AND(기념일등록!$I24>=0,기념일등록!$I24<=90)) -> FALSE | J27: =IF($I27=FALSE(),"",기념일등록!$I24*1000+ROW()) | K27: =IF($J27="","",RANK($J27,$J$6:$J$505,1))
A28: =IF($D28="","",23) | B28: =IFERROR(INDEX(기념일등록!$H$3:$H$502,MATCH(23,다가오는일정!$K$6:$K$505,0)),"") | C28: =IF($B28="","",IFERROR(INDEX(기념일등록!$I$3:$I$502,MATCH(23,다가오는일정!$K$6:$K$505,0)),"")) | D28: =IFERROR(INDEX(기념일등록!$B$3:$B$502,MATCH(23,다가오는일정!$K$6:$K$505,0)),"") | E28: =IF($D28="","",IFERROR(INDEX(기념일등록!$C$3:$C$502,MATCH(23,다가오는일정!$K$6:$K$505,0)),"")) | F28: =IF($D28="","",IFERROR(INDEX(기념일등록!$D$3:$D$502,MATCH(23,다가오는일정!$K$6:$K$505,0)),"")) | G28: =IF($D28="","",SUMIFS(경조사내역!$F$3:$F$1002,경조사내역!$B$3:$B$1002,$D28,경조사내역!$A$3:$A$1002,">="&DATE(YEAR(TODAY())-1,1,1),경조사내역!$A$3:$A$1002,"<="&DATE(YEAR(TODAY())-1,12,31))) | I28: =IF(기념일등록!$B25="",FALSE(),AND(기념일등록!$I25>=0,기념일등록!$I25<=90)) -> FALSE | J28: =IF($I28=FALSE(),"",기념일등록!$I25*1000+ROW()) | K28: =IF($J28="","",RANK($J28,$J$6:$J$505,1))
A29: =IF($D29="","",24) | B29: =IFERROR(INDEX(기념일등록!$H$3:$H$502,MATCH(24,다가오는일정!$K$6:$K$505,0)),"") | C29: =IF($B29="","",IFERROR(INDEX(기념일등록!$I$3:$I$502,MATCH(24,다가오는일정!$K$6:$K$505,0)),"")) | D29: =IFERROR(INDEX(기념일등록!$B$3:$B$502,MATCH(24,다가오는일정!$K$6:$K$505,0)),"") | E29: =IF($D29="","",IFERROR(INDEX(기념일등록!$C$3:$C$502,MATCH(24,다가오는일정!$K$6:$K$505,0)),"")) | F29: =IF($D29="","",IFERROR(INDEX(기념일등록!$D$3:$D$502,MATCH(24,다가오는일정!$K$6:$K$505,0)),"")) | G29: =IF($D29="","",SUMIFS(경조사내역!$F$3:$F$1002,경조사내역!$B$3:$B$1002,$D29,경조사내역!$A$3:$A$1002,">="&DATE(YEAR(TODAY())-1,1,1),경조사내역!$A$3:$A$1002,"<="&DATE(YEAR(TODAY())-1,12,31))) | I29: =IF(기념일등록!$B26="",FALSE(),AND(기념일등록!$I26>=0,기념일등록!$I26<=90)) -> FALSE | J29: =IF($I29=FALSE(),"",기념일등록!$I26*1000+ROW()) | K29: =IF($J29="","",RANK($J29,$J$6:$J$505,1))
A30: =IF($D30="","",25) | B30: =IFERROR(INDEX(기념일등록!$H$3:$H$502,MATCH(25,다가오는일정!$K$6:$K$505,0)),"") | C30: =IF($B30="","",IFERROR(INDEX(기념일등록!$I$3:$I$502,MATCH(25,다가오는일정!$K$6:$K$505,0)),"")) | D30: =IFERROR(INDEX(기념일등록!$B$3:$B$502,MATCH(25,다가오는일정!$K$6:$K$505,0)),"") | E30: =IF($D30="","",IFERROR(INDEX(기념일등록!$C$3:$C$502,MATCH(25,다가오는일정!$K$6:$K$505,0)),"")) | F30: =IF($D30="","",IFERROR(INDEX(기념일등록!$D$3:$D$502,MATCH(25,다가오는일정!$K$6:$K$505,0)),"")) | G30: =IF($D30="","",SUMIFS(경조사내역!$F$3:$F$1002,경조사내역!$B$3:$B$1002,$D30,경조사내역!$A$3:$A$1002,">="&DATE(YEAR(TODAY())-1,1,1),경조사내역!$A$3:$A$1002,"<="&DATE(YEAR(TODAY())-1,12,31))) | I30: =IF(기념일등록!$B27="",FALSE(),AND(기념일등록!$I27>=0,기념일등록!$I27<=90)) -> FALSE | J30: =IF($I30=FALSE(),"",기념일등록!$I27*1000+ROW()) | K30: =IF($J30="","",RANK($J30,$J$6:$J$505,1))
A31: =IF($D31="","",26) | B31: =IFERROR(INDEX(기념일등록!$H$3:$H$502,MATCH(26,다가오는일정!$K$6:$K$505,0)),"") | C31: =IF($B31="","",IFERROR(INDEX(기념일등록!$I$3:$I$502,MATCH(26,다가오는일정!$K$6:$K$505,0)),"")) | D31: =IFERROR(INDEX(기념일등록!$B$3:$B$502,MATCH(26,다가오는일정!$K$6:$K$505,0)),"") | E31: =IF($D31="","",IFERROR(INDEX(기념일등록!$C$3:$C$502,MATCH(26,다가오는일정!$K$6:$K$505,0)),"")) | F31: =IF($D31="","",IFERROR(INDEX(기념일등록!$D$3:$D$502,MATCH(26,다가오는일정!$K$6:$K$505,0)),"")) | G31: =IF($D31="","",SUMIFS(경조사내역!$F$3:$F$1002,경조사내역!$B$3:$B$1002,$D31,경조사내역!$A$3:$A$1002,">="&DATE(YEAR(TODAY())-1,1,1),경조사내역!$A$3:$A$1002,"<="&DATE(YEAR(TODAY())-1,12,31))) | I31: =IF(기념일등록!$B28="",FALSE(),AND(기념일등록!$I28>=0,기념일등록!$I28<=90)) -> FALSE | J31: =IF($I31=FALSE(),"",기념일등록!$I28*1000+ROW()) | K31: =IF($J31="","",RANK($J31,$J$6:$J$505,1))
A32: =IF($D32="","",27) | B32: =IFERROR(INDEX(기념일등록!$H$3:$H$502,MATCH(27,다가오는일정!$K$6:$K$505,0)),"") | C32: =IF($B32="","",IFERROR(INDEX(기념일등록!$I$3:$I$502,MATCH(27,다가오는일정!$K$6:$K$505,0)),"")) | D32: =IFERROR(INDEX(기념일등록!$B$3:$B$502,MATCH(27,다가오는일정!$K$6:$K$505,0)),"") | E32: =IF($D32="","",IFERROR(INDEX(기념일등록!$C$3:$C$502,MATCH(27,다가오는일정!$K$6:$K$505,0)),"")) | F32: =IF($D32="","",IFERROR(INDEX(기념일등록!$D$3:$D$502,MATCH(27,다가오는일정!$K$6:$K$505,0)),"")) | G32: =IF($D32="","",SUMIFS(경조사내역!$F$3:$F$1002,경조사내역!$B$3:$B$1002,$D32,경조사내역!$A$3:$A$1002,">="&DATE(YEAR(TODAY())-1,1,1),경조사내역!$A$3:$A$1002,"<="&DATE(YEAR(TODAY())-1,12,31))) | I32: =IF(기념일등록!$B29="",FALSE(),AND(기념일등록!$I29>=0,기념일등록!$I29<=90)) -> FALSE | J32: =IF($I32=FALSE(),"",기념일등록!$I29*1000+ROW()) | K32: =IF($J32="","",RANK($J32,$J$6:$J$505,1))
A33: =IF($D33="","",28) | B33: =IFERROR(INDEX(기념일등록!$H$3:$H$502,MATCH(28,다가오는일정!$K$6:$K$505,0)),"") | C33: =IF($B33="","",IFERROR(INDEX(기념일등록!$I$3:$I$502,MATCH(28,다가오는일정!$K$6:$K$505,0)),"")) | D33: =IFERROR(INDEX(기념일등록!$B$3:$B$502,MATCH(28,다가오는일정!$K$6:$K$505,0)),"") | E33: =IF($D33="","",IFERROR(INDEX(기념일등록!$C$3:$C$502,MATCH(28,다가오는일정!$K$6:$K$505,0)),"")) | F33: =IF($D33="","",IFERROR(INDEX(기념일등록!$D$3:$D$502,MATCH(28,다가오는일정!$K$6:$K$505,0)),"")) | G33: =IF($D33="","",SUMIFS(경조사내역!$F$3:$F$1002,경조사내역!$B$3:$B$1002,$D33,경조사내역!$A$3:$A$1002,">="&DATE(YEAR(TODAY())-1,1,1),경조사내역!$A$3:$A$1002,"<="&DATE(YEAR(TODAY())-1,12,31))) | I33: =IF(기념일등록!$B30="",FALSE(),AND(기념일등록!$I30>=0,기념일등록!$I30<=90)) -> FALSE | J33: =IF($I33=FALSE(),"",기념일등록!$I30*1000+ROW()) | K33: =IF($J33="","",RANK($J33,$J$6:$J$505,1))
A34: =IF($D34="","",29) | B34: =IFERROR(INDEX(기념일등록!$H$3:$H$502,MATCH(29,다가오는일정!$K$6:$K$505,0)),"") | C34: =IF($B34="","",IFERROR(INDEX(기념일등록!$I$3:$I$502,MATCH(29,다가오는일정!$K$6:$K$505,0)),"")) | D34: =IFERROR(INDEX(기념일등록!$B$3:$B$502,MATCH(29,다가오는일정!$K$6:$K$505,0)),"") | E34: =IF($D34="","",IFERROR(INDEX(기념일등록!$C$3:$C$502,MATCH(29,다가오는일정!$K$6:$K$505,0)),"")) | F34: =IF($D34="","",IFERROR(INDEX(기념일등록!$D$3:$D$502,MATCH(29,다가오는일정!$K$6:$K$505,0)),"")) | G34: =IF($D34="","",SUMIFS(경조사내역!$F$3:$F$1002,경조사내역!$B$3:$B$1002,$D34,경조사내역!$A$3:$A$1002,">="&DATE(YEAR(TODAY())-1,1,1),경조사내역!$A$3:$A$1002,"<="&DATE(YEAR(TODAY())-1,12,31))) | I34: =IF(기념일등록!$B31="",FALSE(),AND(기념일등록!$I31>=0,기념일등록!$I31<=90)) -> FALSE | J34: =IF($I34=FALSE(),"",기념일등록!$I31*1000+ROW()) | K34: =IF($J34="","",RANK($J34,$J$6:$J$505,1))
A35: =IF($D35="","",30) | B35: =IFERROR(INDEX(기념일등록!$H$3:$H$502,MATCH(30,다가오는일정!$K$6:$K$505,0)),"") | C35: =IF($B35="","",IFERROR(INDEX(기념일등록!$I$3:$I$502,MATCH(30,다가오는일정!$K$6:$K$505,0)),"")) | D35: =IFERROR(INDEX(기념일등록!$B$3:$B$502,MATCH(30,다가오는일정!$K$6:$K$505,0)),"") | E35: =IF($D35="","",IFERROR(INDEX(기념일등록!$C$3:$C$502,MATCH(30,다가오는일정!$K$6:$K$505,0)),"")) | F35: =IF($D35="","",IFERROR(INDEX(기념일등록!$D$3:$D$502,MATCH(30,다가오는일정!$K$6:$K$505,0)),"")) | G35: =IF($D35="","",SUMIFS(경조사내역!$F$3:$F$1002,경조사내역!$B$3:$B$1002,$D35,경조사내역!$A$3:$A$1002,">="&DATE(YEAR(TODAY())-1,1,1),경조사내역!$A$3:$A$1002,"<="&DATE(YEAR(TODAY())-1,12,31))) | I35: =IF(기념일등록!$B32="",FALSE(),AND(기념일등록!$I32>=0,기념일등록!$I32<=90)) -> FALSE | J35: =IF($I35=FALSE(),"",기념일등록!$I32*1000+ROW()) | K35: =IF($J35="","",RANK($J35,$J$6:$J$505,1))
A36: =IF($D36="","",31) | B36: =IFERROR(INDEX(기념일등록!$H$3:$H$502,MATCH(31,다가오는일정!$K$6:$K$505,0)),"") | C36: =IF($B36="","",IFERROR(INDEX(기념일등록!$I$3:$I$502,MATCH(31,다가오는일정!$K$6:$K$505,0)),"")) | D36: =IFERROR(INDEX(기념일등록!$B$3:$B$502,MATCH(31,다가오는일정!$K$6:$K$505,0)),"") | E36: =IF($D36="","",IFERROR(INDEX(기념일등록!$C$3:$C$502,MATCH(31,다가오는일정!$K$6:$K$505,0)),"")) | F36: =IF($D36="","",IFERROR(INDEX(기념일등록!$D$3:$D$502,MATCH(31,다가오는일정!$K$6:$K$505,0)),"")) | G36: =IF($D36="","",SUMIFS(경조사내역!$F$3:$F$1002,경조사내역!$B$3:$B$1002,$D36,경조사내역!$A$3:$A$1002,">="&DATE(YEAR(TODAY())-1,1,1),경조사내역!$A$3:$A$1002,"<="&DATE(YEAR(TODAY())-1,12,31))) | I36: =IF(기념일등록!$B33="",FALSE(),AND(기념일등록!$I33>=0,기념일등록!$I33<=90)) -> FALSE | J36: =IF($I36=FALSE(),"",기념일등록!$I33*1000+ROW()) | K36: =IF($J36="","",RANK($J36,$J$6:$J$505,1))
A37: =IF($D37="","",32) | B37: =IFERROR(INDEX(기념일등록!$H$3:$H$502,MATCH(32,다가오는일정!$K$6:$K$505,0)),"") | C37: =IF($B37="","",IFERROR(INDEX(기념일등록!$I$3:$I$502,MATCH(32,다가오는일정!$K$6:$K$505,0)),"")) | D37: =IFERROR(INDEX(기념일등록!$B$3:$B$502,MATCH(32,다가오는일정!$K$6:$K$505,0)),"") | E37: =IF($D37="","",IFERROR(INDEX(기념일등록!$C$3:$C$502,MATCH(32,다가오는일정!$K$6:$K$505,0)),"")) | F37: =IF($D37="","",IFERROR(INDEX(기념일등록!$D$3:$D$502,MATCH(32,다가오는일정!$K$6:$K$505,0)),"")) | G37: =IF($D37="","",SUMIFS(경조사내역!$F$3:$F$1002,경조사내역!$B$3:$B$1002,$D37,경조사내역!$A$3:$A$1002,">="&DATE(YEAR(TODAY())-1,1,1),경조사내역!$A$3:$A$1002,"<="&DATE(YEAR(TODAY())-1,12,31))) | I37: =IF(기념일등록!$B34="",FALSE(),AND(기념일등록!$I34>=0,기념일등록!$I34<=90)) -> FALSE | J37: =IF($I37=FALSE(),"",기념일등록!$I34*1000+ROW()) | K37: =IF($J37="","",RANK($J37,$J$6:$J$505,1))
A38: =IF($D38="","",33) | B38: =IFERROR(INDEX(기념일등록!$H$3:$H$502,MATCH(33,다가오는일정!$K$6:$K$505,0)),"") | C38: =IF($B38="","",IFERROR(INDEX(기념일등록!$I$3:$I$502,MATCH(33,다가오는일정!$K$6:$K$505,0)),"")) | D38: =IFERROR(INDEX(기념일등록!$B$3:$B$502,MATCH(33,다가오는일정!$K$6:$K$505,0)),"") | E38: =IF($D38="","",IFERROR(INDEX(기념일등록!$C$3:$C$502,MATCH(33,다가오는일정!$K$6:$K$505,0)),"")) | F38: =IF($D38="","",IFERROR(INDEX(기념일등록!$D$3:$D$502,MATCH(33,다가오는일정!$K$6:$K$505,0)),"")) | G38: =IF($D38="","",SUMIFS(경조사내역!$F$3:$F$1002,경조사내역!$B$3:$B$1002,$D38,경조사내역!$A$3:$A$1002,">="&DATE(YEAR(TODAY())-1,1,1),경조사내역!$A$3:$A$1002,"<="&DATE(YEAR(TODAY())-1,12,31))) | I38: =IF(기념일등록!$B35="",FALSE(),AND(기념일등록!$I35>=0,기념일등록!$I35<=90)) -> FALSE | J38: =IF($I38=FALSE(),"",기념일등록!$I35*1000+ROW()) | K38: =IF($J38="","",RANK($J38,$J$6:$J$505,1))
A39: =IF($D39="","",34) | B39: =IFERROR(INDEX(기념일등록!$H$3:$H$502,MATCH(34,다가오는일정!$K$6:$K$505,0)),"") | C39: =IF($B39="","",IFERROR(INDEX(기념일등록!$I$3:$I$502,MATCH(34,다가오는일정!$K$6:$K$505,0)),"")) | D39: =IFERROR(INDEX(기념일등록!$B$3:$B$502,MATCH(34,다가오는일정!$K$6:$K$505,0)),"") | E39: =IF($D39="","",IFERROR(INDEX(기념일등록!$C$3:$C$502,MATCH(34,다가오는일정!$K$6:$K$505,0)),"")) | F39: =IF($D39="","",IFERROR(INDEX(기념일등록!$D$3:$D$502,MATCH(34,다가오는일정!$K$6:$K$505,0)),"")) | G39: =IF($D39="","",SUMIFS(경조사내역!$F$3:$F$1002,경조사내역!$B$3:$B$1002,$D39,경조사내역!$A$3:$A$1002,">="&DATE(YEAR(TODAY())-1,1,1),경조사내역!$A$3:$A$1002,"<="&DATE(YEAR(TODAY())-1,12,31))) | I39: =IF(기념일등록!$B36="",FALSE(),AND(기념일등록!$I36>=0,기념일등록!$I36<=90)) -> FALSE | J39: =IF($I39=FALSE(),"",기념일등록!$I36*1000+ROW()) | K39: =IF($J39="","",RANK($J39,$J$6:$J$505,1))
A40: =IF($D40="","",35) | B40: =IFERROR(INDEX(기념일등록!$H$3:$H$502,MATCH(35,다가오는일정!$K$6:$K$505,0)),"") | C40: =IF($B40="","",IFERROR(INDEX(기념일등록!$I$3:$I$502,MATCH(35,다가오는일정!$K$6:$K$505,0)),"")) | D40: =IFERROR(INDEX(기념일등록!$B$3:$B$502,MATCH(35,다가오는일정!$K$6:$K$505,0)),"") | E40: =IF($D40="","",IFERROR(INDEX(기념일등록!$C$3:$C$502,MATCH(35,다가오는일정!$K$6:$K$505,0)),"")) | F40: =IF($D40="","",IFERROR(INDEX(기념일등록!$D$3:$D$502,MATCH(35,다가오는일정!$K$6:$K$505,0)),"")) | G40: =IF($D40="","",SUMIFS(경조사내역!$F$3:$F$1002,경조사내역!$B$3:$B$1002,$D40,경조사내역!$A$3:$A$1002,">="&DATE(YEAR(TODAY())-1,1,1),경조사내역!$A$3:$A$1002,"<="&DATE(YEAR(TODAY())-1,12,31))) | I40: =IF(기념일등록!$B37="",FALSE(),AND(기념일등록!$I37>=0,기념일등록!$I37<=90)) -> FALSE | J40: =IF($I40=FALSE(),"",기념일등록!$I37*1000+ROW()) | K40: =IF($J40="","",RANK($J40,$J$6:$J$505,1))
A41: =IF($D41="","",36) | B41: =IFERROR(INDEX(기념일등록!$H$3:$H$502,MATCH(36,다가오는일정!$K$6:$K$505,0)),"") | C41: =IF($B41="","",IFERROR(INDEX(기념일등록!$I$3:$I$502,MATCH(36,다가오는일정!$K$6:$K$505,0)),"")) | D41: =IFERROR(INDEX(기념일등록!$B$3:$B$502,MATCH(36,다가오는일정!$K$6:$K$505,0)),"") | E41: =IF($D41="","",IFERROR(INDEX(기념일등록!$C$3:$C$502,MATCH(36,다가오는일정!$K$6:$K$505,0)),"")) | F41: =IF($D41="","",IFERROR(INDEX(기념일등록!$D$3:$D$502,MATCH(36,다가오는일정!$K$6:$K$505,0)),"")) | G41: =IF($D41="","",SUMIFS(경조사내역!$F$3:$F$1002,경조사내역!$B$3:$B$1002,$D41,경조사내역!$A$3:$A$1002,">="&DATE(YEAR(TODAY())-1,1,1),경조사내역!$A$3:$A$1002,"<="&DATE(YEAR(TODAY())-1,12,31))) | I41: =IF(기념일등록!$B38="",FALSE(),AND(기념일등록!$I38>=0,기념일등록!$I38<=90)) -> FALSE | J41: =IF($I41=FALSE(),"",기념일등록!$I38*1000+ROW()) | K41: =IF($J41="","",RANK($J41,$J$6:$J$505,1))
A42: =IF($D42="","",37) | B42: =IFERROR(INDEX(기념일등록!$H$3:$H$502,MATCH(37,다가오는일정!$K$6:$K$505,0)),"") | C42: =IF($B42="","",IFERROR(INDEX(기념일등록!$I$3:$I$502,MATCH(37,다가오는일정!$K$6:$K$505,0)),"")) | D42: =IFERROR(INDEX(기념일등록!$B$3:$B$502,MATCH(37,다가오는일정!$K$6:$K$505,0)),"") | E42: =IF($D42="","",IFERROR(INDEX(기념일등록!$C$3:$C$502,MATCH(37,다가오는일정!$K$6:$K$505,0)),"")) | F42: =IF($D42="","",IFERROR(INDEX(기념일등록!$D$3:$D$502,MATCH(37,다가오는일정!$K$6:$K$505,0)),"")) | G42: =IF($D42="","",SUMIFS(경조사내역!$F$3:$F$1002,경조사내역!$B$3:$B$1002,$D42,경조사내역!$A$3:$A$1002,">="&DATE(YEAR(TODAY())-1,1,1),경조사내역!$A$3:$A$1002,"<="&DATE(YEAR(TODAY())-1,12,31))) | I42: =IF(기념일등록!$B39="",FALSE(),AND(기념일등록!$I39>=0,기념일등록!$I39<=90)) -> FALSE | J42: =IF($I42=FALSE(),"",기념일등록!$I39*1000+ROW()) | K42: =IF($J42="","",RANK($J42,$J$6:$J$505,1))
...

Sheet 월별달력
A1: 월별달력
A3: 대상 월 | B3: 9 | C3: ← 1~12 중 하나
A5: 순번 | B5: 일 | C5: 이름 | D5: 거래처 | E5: 종류 | F5: 비고
A6: =IF($C6="","",1) -> 1 | B6: =IFERROR(INDEX(기념일등록!$G$3:$G$502,MATCH(1,월별달력!$J$6:$J$505,0)),"") -> 20 | C6: =IFERROR(INDEX(기념일등록!$B$3:$B$502,MATCH(1,월별달력!$J$6:$J$505,0)),"") -> 김사장 | D6: =IF($C6="","",IFERROR(INDEX(기념일등록!$C$3:$C$502,MATCH(1,월별달력!$J$6:$J$505,0)),"")) -> ○○상사 | E6: =IF($C6="","",IFERROR(INDEX(기념일등록!$D$3:$D$502,MATCH(1,월별달력!$J$6:$J$505,0)),"")) -> 창립기념일 | F6: =IF($C6="","",IFERROR(IF(INDEX(기념일등록!$J$3:$J$502,MATCH(1,월별달력!$J$6:$J$505,0))="","",INDEX(기념일등록!$J$3:$J$502,MATCH(1,월별달력!$J$6:$J$505,0))),"")) | H6: =IF(기념일등록!$B3="",FALSE(),기념일등록!$F3=$B$3) -> TRUE | I6: =IF($H6=FALSE(),"",IF(기념일등록!$G3="",99999,기념일등록!$G3)*1000+ROW()) -> 25006 | J6: =IF($I6="","",RANK($I6,$I$6:$I$505,1)) -> 2
A7: =IF($C7="","",2) -> 2 | B7: =IFERROR(INDEX(기념일등록!$G$3:$G$502,MATCH(2,월별달력!$J$6:$J$505,0)),"") -> 25 | C7: =IFERROR(INDEX(기념일등록!$B$3:$B$502,MATCH(2,월별달력!$J$6:$J$505,0)),"") -> 김사장 | D7: =IF($C7="","",IFERROR(INDEX(기념일등록!$C$3:$C$502,MATCH(2,월별달력!$J$6:$J$505,0)),"")) -> ○○상사 | E7: =IF($C7="","",IFERROR(INDEX(기념일등록!$D$3:$D$502,MATCH(2,월별달력!$J$6:$J$505,0)),"")) -> 생일 | F7: =IF($C7="","",IFERROR(IF(INDEX(기념일등록!$J$3:$J$502,MATCH(2,월별달력!$J$6:$J$505,0))="","",INDEX(기념일등록!$J$3:$J$502,MATCH(2,월별달력!$J$6:$J$505,0))),"")) | H7: =IF(기념일등록!$B4="",FALSE(),기념일등록!$F4=$B$3) -> FALSE | I7: =IF($H7=FALSE(),"",IF(기념일등록!$G4="",99999,기념일등록!$G4)*1000+ROW()) | J7: =IF($I7="","",RANK($I7,$I$6:$I$505,1))
A8: =IF($C8="","",3) | B8: =IFERROR(INDEX(기념일등록!$G$3:$G$502,MATCH(3,월별달력!$J$6:$J$505,0)),"") | C8: =IFERROR(INDEX(기념일등록!$B$3:$B$502,MATCH(3,월별달력!$J$6:$J$505,0)),"") | D8: =IF($C8="","",IFERROR(INDEX(기념일등록!$C$3:$C$502,MATCH(3,월별달력!$J$6:$J$505,0)),"")) | E8: =IF($C8="","",IFERROR(INDEX(기념일등록!$D$3:$D$502,MATCH(3,월별달력!$J$6:$J$505,0)),"")) | F8: =IF($C8="","",IFERROR(IF(INDEX(기념일등록!$J$3:$J$502,MATCH(3,월별달력!$J$6:$J$505,0))="","",INDEX(기념일등록!$J$3:$J$502,MATCH(3,월별달력!$J$6:$J$505,0))),"")) | H8: =IF(기념일등록!$B5="",FALSE(),기념일등록!$F5=$B$3) -> TRUE | I8: =IF($H8=FALSE(),"",IF(기념일등록!$G5="",99999,기념일등록!$G5)*1000+ROW()) -> 20008 | J8: =IF($I8="","",RANK($I8,$I$6:$I$505,1)) -> 1
A9: =IF($C9="","",4) | B9: =IFERROR(INDEX(기념일등록!$G$3:$G$502,MATCH(4,월별달력!$J$6:$J$505,0)),"") | C9: =IFERROR(INDEX(기념일등록!$B$3:$B$502,MATCH(4,월별달력!$J$6:$J$505,0)),"") | D9: =IF($C9="","",IFERROR(INDEX(기념일등록!$C$3:$C$502,MATCH(4,월별달력!$J$6:$J$505,0)),"")) | E9: =IF($C9="","",IFERROR(INDEX(기념일등록!$D$3:$D$502,MATCH(4,월별달력!$J$6:$J$505,0)),"")) | F9: =IF($C9="","",IFERROR(IF(INDEX(기념일등록!$J$3:$J$502,MATCH(4,월별달력!$J$6:$J$505,0))="","",INDEX(기념일등록!$J$3:$J$502,MATCH(4,월별달력!$J$6:$J$505,0))),"")) | H9: =IF(기념일등록!$B6="",FALSE(),기념일등록!$F6=$B$3) -> FALSE | I9: =IF($H9=FALSE(),"",IF(기념일등록!$G6="",99999,기념일등록!$G6)*1000+ROW()) | J9: =IF($I9="","",RANK($I9,$I$6:$I$505,1))
A10: =IF($C10="","",5) | B10: =IFERROR(INDEX(기념일등록!$G$3:$G$502,MATCH(5,월별달력!$J$6:$J$505,0)),"") | C10: =IFERROR(INDEX(기념일등록!$B$3:$B$502,MATCH(5,월별달력!$J$6:$J$505,0)),"") | D10: =IF($C10="","",IFERROR(INDEX(기념일등록!$C$3:$C$502,MATCH(5,월별달력!$J$6:$J$505,0)),"")) | E10: =IF($C10="","",IFERROR(INDEX(기념일등록!$D$3:$D$502,MATCH(5,월별달력!$J$6:$J$505,0)),"")) | F10: =IF($C10="","",IFERROR(IF(INDEX(기념일등록!$J$3:$J$502,MATCH(5,월별달력!$J$6:$J$505,0))="","",INDEX(기념일등록!$J$3:$J$502,MATCH(5,월별달력!$J$6:$J$505,0))),"")) | H10: =IF(기념일등록!$B7="",FALSE(),기념일등록!$F7=$B$3) -> FALSE | I10: =IF($H10=FALSE(),"",IF(기념일등록!$G7="",99999,기념일등록!$G7)*1000+ROW()) | J10: =IF($I10="","",RANK($I10,$I$6:$I$505,1))
A11: =IF($C11="","",6) | B11: =IFERROR(INDEX(기념일등록!$G$3:$G$502,MATCH(6,월별달력!$J$6:$J$505,0)),"") | C11: =IFERROR(INDEX(기념일등록!$B$3:$B$502,MATCH(6,월별달력!$J$6:$J$505,0)),"") | D11: =IF($C11="","",IFERROR(INDEX(기념일등록!$C$3:$C$502,MATCH(6,월별달력!$J$6:$J$505,0)),"")) | E11: =IF($C11="","",IFERROR(INDEX(기념일등록!$D$3:$D$502,MATCH(6,월별달력!$J$6:$J$505,0)),"")) | F11: =IF($C11="","",IFERROR(IF(INDEX(기념일등록!$J$3:$J$502,MATCH(6,월별달력!$J$6:$J$505,0))="","",INDEX(기념일등록!$J$3:$J$502,MATCH(6,월별달력!$J$6:$J$505,0))),"")) | H11: =IF(기념일등록!$B8="",FALSE(),기념일등록!$F8=$B$3) -> FALSE | I11: =IF($H11=FALSE(),"",IF(기념일등록!$G8="",99999,기념일등록!$G8)*1000+ROW()) | J11: =IF($I11="","",RANK($I11,$I$6:$I$505,1))
A12: =IF($C12="","",7) | B12: =IFERROR(INDEX(기념일등록!$G$3:$G$502,MATCH(7,월별달력!$J$6:$J$505,0)),"") | C12: =IFERROR(INDEX(기념일등록!$B$3:$B$502,MATCH(7,월별달력!$J$6:$J$505,0)),"") | D12: =IF($C12="","",IFERROR(INDEX(기념일등록!$C$3:$C$502,MATCH(7,월별달력!$J$6:$J$505,0)),"")) | E12: =IF($C12="","",IFERROR(INDEX(기념일등록!$D$3:$D$502,MATCH(7,월별달력!$J$6:$J$505,0)),"")) | F12: =IF($C12="","",IFERROR(IF(INDEX(기념일등록!$J$3:$J$502,MATCH(7,월별달력!$J$6:$J$505,0))="","",INDEX(기념일등록!$J$3:$J$502,MATCH(7,월별달력!$J$6:$J$505,0))),"")) | H12: =IF(기념일등록!$B9="",FALSE(),기념일등록!$F9=$B$3) -> FALSE | I12: =IF($H12=FALSE(),"",IF(기념일등록!$G9="",99999,기념일등록!$G9)*1000+ROW()) | J12: =IF($I12="","",RANK($I12,$I$6:$I$505,1))
A13: =IF($C13="","",8) | B13: =IFERROR(INDEX(기념일등록!$G$3:$G$502,MATCH(8,월별달력!$J$6:$J$505,0)),"") | C13: =IFERROR(INDEX(기념일등록!$B$3:$B$502,MATCH(8,월별달력!$J$6:$J$505,0)),"") | D13: =IF($C13="","",IFERROR(INDEX(기념일등록!$C$3:$C$502,MATCH(8,월별달력!$J$6:$J$505,0)),"")) | E13: =IF($C13="","",IFERROR(INDEX(기념일등록!$D$3:$D$502,MATCH(8,월별달력!$J$6:$J$505,0)),"")) | F13: =IF($C13="","",IFERROR(IF(INDEX(기념일등록!$J$3:$J$502,MATCH(8,월별달력!$J$6:$J$505,0))="","",INDEX(기념일등록!$J$3:$J$502,MATCH(8,월별달력!$J$6:$J$505,0))),"")) | H13: =IF(기념일등록!$B10="",FALSE(),기념일등록!$F10=$B$3) -> FALSE | I13: =IF($H13=FALSE(),"",IF(기념일등록!$G10="",99999,기념일등록!$G10)*1000+ROW()) | J13: =IF($I13="","",RANK($I13,$I$6:$I$505,1))
A14: =IF($C14="","",9) | B14: =IFERROR(INDEX(기념일등록!$G$3:$G$502,MATCH(9,월별달력!$J$6:$J$505,0)),"") | C14: =IFERROR(INDEX(기념일등록!$B$3:$B$502,MATCH(9,월별달력!$J$6:$J$505,0)),"") | D14: =IF($C14="","",IFERROR(INDEX(기념일등록!$C$3:$C$502,MATCH(9,월별달력!$J$6:$J$505,0)),"")) | E14: =IF($C14="","",IFERROR(INDEX(기념일등록!$D$3:$D$502,MATCH(9,월별달력!$J$6:$J$505,0)),"")) | F14: =IF($C14="","",IFERROR(IF(INDEX(기념일등록!$J$3:$J$502,MATCH(9,월별달력!$J$6:$J$505,0))="","",INDEX(기념일등록!$J$3:$J$502,MATCH(9,월별달력!$J$6:$J$505,0))),"")) | H14: =IF(기념일등록!$B11="",FALSE(),기념일등록!$F11=$B$3) -> FALSE | I14: =IF($H14=FALSE(),"",IF(기념일등록!$G11="",99999,기념일등록!$G11)*1000+ROW()) | J14: =IF($I14="","",RANK($I14,$I$6:$I$505,1))
A15: =IF($C15="","",10) | B15: =IFERROR(INDEX(기념일등록!$G$3:$G$502,MATCH(10,월별달력!$J$6:$J$505,0)),"") | C15: =IFERROR(INDEX(기념일등록!$B$3:$B$502,MATCH(10,월별달력!$J$6:$J$505,0)),"") | D15: =IF($C15="","",IFERROR(INDEX(기념일등록!$C$3:$C$502,MATCH(10,월별달력!$J$6:$J$505,0)),"")) | E15: =IF($C15="","",IFERROR(INDEX(기념일등록!$D$3:$D$502,MATCH(10,월별달력!$J$6:$J$505,0)),"")) | F15: =IF($C15="","",IFERROR(IF(INDEX(기념일등록!$J$3:$J$502,MATCH(10,월별달력!$J$6:$J$505,0))="","",INDEX(기념일등록!$J$3:$J$502,MATCH(10,월별달력!$J$6:$J$505,0))),"")) | H15: =IF(기념일등록!$B12="",FALSE(),기념일등록!$F12=$B$3) -> FALSE | I15: =IF($H15=FALSE(),"",IF(기념일등록!$G12="",99999,기념일등록!$G12)*1000+ROW()) | J15: =IF($I15="","",RANK($I15,$I$6:$I$505,1))
A16: =IF($C16="","",11) | B16: =IFERROR(INDEX(기념일등록!$G$3:$G$502,MATCH(11,월별달력!$J$6:$J$505,0)),"") | C16: =IFERROR(INDEX(기념일등록!$B$3:$B$502,MATCH(11,월별달력!$J$6:$J$505,0)),"") | D16: =IF($C16="","",IFERROR(INDEX(기념일등록!$C$3:$C$502,MATCH(11,월별달력!$J$6:$J$505,0)),"")) | E16: =IF($C16="","",IFERROR(INDEX(기념일등록!$D$3:$D$502,MATCH(11,월별달력!$J$6:$J$505,0)),"")) | F16: =IF($C16="","",IFERROR(IF(INDEX(기념일등록!$J$3:$J$502,MATCH(11,월별달력!$J$6:$J$505,0))="","",INDEX(기념일등록!$J$3:$J$502,MATCH(11,월별달력!$J$6:$J$505,0))),"")) | H16: =IF(기념일등록!$B13="",FALSE(),기념일등록!$F13=$B$3) -> FALSE | I16: =IF($H16=FALSE(),"",IF(기념일등록!$G13="",99999,기념일등록!$G13)*1000+ROW()) | J16: =IF($I16="","",RANK($I16,$I$6:$I$505,1))
A17: =IF($C17="","",12) | B17: =IFERROR(INDEX(기념일등록!$G$3:$G$502,MATCH(12,월별달력!$J$6:$J$505,0)),"") | C17: =IFERROR(INDEX(기념일등록!$B$3:$B$502,MATCH(12,월별달력!$J$6:$J$505,0)),"") | D17: =IF($C17="","",IFERROR(INDEX(기념일등록!$C$3:$C$502,MATCH(12,월별달력!$J$6:$J$505,0)),"")) | E17: =IF($C17="","",IFERROR(INDEX(기념일등록!$D$3:$D$502,MATCH(12,월별달력!$J$6:$J$505,0)),"")) | F17: =IF($C17="","",IFERROR(IF(INDEX(기념일등록!$J$3:$J$502,MATCH(12,월별달력!$J$6:$J$505,0))="","",INDEX(기념일등록!$J$3:$J$502,MATCH(12,월별달력!$J$6:$J$505,0))),"")) | H17: =IF(기념일등록!$B14="",FALSE(),기념일등록!$F14=$B$3) -> FALSE | I17: =IF($H17=FALSE(),"",IF(기념일등록!$G14="",99999,기념일등록!$G14)*1000+ROW()) | J17: =IF($I17="","",RANK($I17,$I$6:$I$505,1))
A18: =IF($C18="","",13) | B18: =IFERROR(INDEX(기념일등록!$G$3:$G$502,MATCH(13,월별달력!$J$6:$J$505,0)),"") | C18: =IFERROR(INDEX(기념일등록!$B$3:$B$502,MATCH(13,월별달력!$J$6:$J$505,0)),"") | D18: =IF($C18="","",IFERROR(INDEX(기념일등록!$C$3:$C$502,MATCH(13,월별달력!$J$6:$J$505,0)),"")) | E18: =IF($C18="","",IFERROR(INDEX(기념일등록!$D$3:$D$502,MATCH(13,월별달력!$J$6:$J$505,0)),"")) | F18: =IF($C18="","",IFERROR(IF(INDEX(기념일등록!$J$3:$J$502,MATCH(13,월별달력!$J$6:$J$505,0))="","",INDEX(기념일등록!$J$3:$J$502,MATCH(13,월별달력!$J$6:$J$505,0))),"")) | H18: =IF(기념일등록!$B15="",FALSE(),기념일등록!$F15=$B$3) -> FALSE | I18: =IF($H18=FALSE(),"",IF(기념일등록!$G15="",99999,기념일등록!$G15)*1000+ROW()) | J18: =IF($I18="","",RANK($I18,$I$6:$I$505,1))
A19: =IF($C19="","",14) | B19: =IFERROR(INDEX(기념일등록!$G$3:$G$502,MATCH(14,월별달력!$J$6:$J$505,0)),"") | C19: =IFERROR(INDEX(기념일등록!$B$3:$B$502,MATCH(14,월별달력!$J$6:$J$505,0)),"") | D19: =IF($C19="","",IFERROR(INDEX(기념일등록!$C$3:$C$502,MATCH(14,월별달력!$J$6:$J$505,0)),"")) | E19: =IF($C19="","",IFERROR(INDEX(기념일등록!$D$3:$D$502,MATCH(14,월별달력!$J$6:$J$505,0)),"")) | F19: =IF($C19="","",IFERROR(IF(INDEX(기념일등록!$J$3:$J$502,MATCH(14,월별달력!$J$6:$J$505,0))="","",INDEX(기념일등록!$J$3:$J$502,MATCH(14,월별달력!$J$6:$J$505,0))),"")) | H19: =IF(기념일등록!$B16="",FALSE(),기념일등록!$F16=$B$3) -> FALSE | I19: =IF($H19=FALSE(),"",IF(기념일등록!$G16="",99999,기념일등록!$G16)*1000+ROW()) | J19: =IF($I19="","",RANK($I19,$I$6:$I$505,1))
A20: =IF($C20="","",15) | B20: =IFERROR(INDEX(기념일등록!$G$3:$G$502,MATCH(15,월별달력!$J$6:$J$505,0)),"") | C20: =IFERROR(INDEX(기념일등록!$B$3:$B$502,MATCH(15,월별달력!$J$6:$J$505,0)),"") | D20: =IF($C20="","",IFERROR(INDEX(기념일등록!$C$3:$C$502,MATCH(15,월별달력!$J$6:$J$505,0)),"")) | E20: =IF($C20="","",IFERROR(INDEX(기념일등록!$D$3:$D$502,MATCH(15,월별달력!$J$6:$J$505,0)),"")) | F20: =IF($C20="","",IFERROR(IF(INDEX(기념일등록!$J$3:$J$502,MATCH(15,월별달력!$J$6:$J$505,0))="","",INDEX(기념일등록!$J$3:$J$502,MATCH(15,월별달력!$J$6:$J$505,0))),"")) | H20: =IF(기념일등록!$B17="",FALSE(),기념일등록!$F17=$B$3) -> FALSE | I20: =IF($H20=FALSE(),"",IF(기념일등록!$G17="",99999,기념일등록!$G17)*1000+ROW()) | J20: =IF($I20="","",RANK($I20,$I$6:$I$505,1))
A21: =IF($C21="","",16) | B21: =IFERROR(INDEX(기념일등록!$G$3:$G$502,MATCH(16,월별달력!$J$6:$J$505,0)),"") | C21: =IFERROR(INDEX(기념일등록!$B$3:$B$502,MATCH(16,월별달력!$J$6:$J$505,0)),"") | D21: =IF($C21="","",IFERROR(INDEX(기념일등록!$C$3:$C$502,MATCH(16,월별달력!$J$6:$J$505,0)),"")) | E21: =IF($C21="","",IFERROR(INDEX(기념일등록!$D$3:$D$502,MATCH(16,월별달력!$J$6:$J$505,0)),"")) | F21: =IF($C21="","",IFERROR(IF(INDEX(기념일등록!$J$3:$J$502,MATCH(16,월별달력!$J$6:$J$505,0))="","",INDEX(기념일등록!$J$3:$J$502,MATCH(16,월별달력!$J$6:$J$505,0))),"")) | H21: =IF(기념일등록!$B18="",FALSE(),기념일등록!$F18=$B$3) -> FALSE | I21: =IF($H21=FALSE(),"",IF(기념일등록!$G18="",99999,기념일등록!$G18)*1000+ROW()) | J21: =IF($I21="","",RANK($I21,$I$6:$I$505,1))
A22: =IF($C22="","",17) | B22: =IFERROR(INDEX(기념일등록!$G$3:$G$502,MATCH(17,월별달력!$J$6:$J$505,0)),"") | C22: =IFERROR(INDEX(기념일등록!$B$3:$B$502,MATCH(17,월별달력!$J$6:$J$505,0)),"") | D22: =IF($C22="","",IFERROR(INDEX(기념일등록!$C$3:$C$502,MATCH(17,월별달력!$J$6:$J$505,0)),"")) | E22: =IF($C22="","",IFERROR(INDEX(기념일등록!$D$3:$D$502,MATCH(17,월별달력!$J$6:$J$505,0)),"")) | F22: =IF($C22="","",IFERROR(IF(INDEX(기념일등록!$J$3:$J$502,MATCH(17,월별달력!$J$6:$J$505,0))="","",INDEX(기념일등록!$J$3:$J$502,MATCH(17,월별달력!$J$6:$J$505,0))),"")) | H22: =IF(기념일등록!$B19="",FALSE(),기념일등록!$F19=$B$3) -> FALSE | I22: =IF($H22=FALSE(),"",IF(기념일등록!$G19="",99999,기념일등록!$G19)*1000+ROW()) | J22: =IF($I22="","",RANK($I22,$I$6:$I$505,1))
A23: =IF($C23="","",18) | B23: =IFERROR(INDEX(기념일등록!$G$3:$G$502,MATCH(18,월별달력!$J$6:$J$505,0)),"") | C23: =IFERROR(INDEX(기념일등록!$B$3:$B$502,MATCH(18,월별달력!$J$6:$J$505,0)),"") | D23: =IF($C23="","",IFERROR(INDEX(기념일등록!$C$3:$C$502,MATCH(18,월별달력!$J$6:$J$505,0)),"")) | E23: =IF($C23="","",IFERROR(INDEX(기념일등록!$D$3:$D$502,MATCH(18,월별달력!$J$6:$J$505,0)),"")) | F23: =IF($C23="","",IFERROR(IF(INDEX(기념일등록!$J$3:$J$502,MATCH(18,월별달력!$J$6:$J$505,0))="","",INDEX(기념일등록!$J$3:$J$502,MATCH(18,월별달력!$J$6:$J$505,0))),"")) | H23: =IF(기념일등록!$B20="",FALSE(),기념일등록!$F20=$B$3) -> FALSE | I23: =IF($H23=FALSE(),"",IF(기념일등록!$G20="",99999,기념일등록!$G20)*1000+ROW()) | J23: =IF($I23="","",RANK($I23,$I$6:$I$505,1))
A24: =IF($C24="","",19) | B24: =IFERROR(INDEX(기념일등록!$G$3:$G$502,MATCH(19,월별달력!$J$6:$J$505,0)),"") | C24: =IFERROR(INDEX(기념일등록!$B$3:$B$502,MATCH(19,월별달력!$J$6:$J$505,0)),"") | D24: =IF($C24="","",IFERROR(INDEX(기념일등록!$C$3:$C$502,MATCH(19,월별달력!$J$6:$J$505,0)),"")) | E24: =IF($C24="","",IFERROR(INDEX(기념일등록!$D$3:$D$502,MATCH(19,월별달력!$J$6:$J$505,0)),"")) | F24: =IF($C24="","",IFERROR(IF(INDEX(기념일등록!$J$3:$J$502,MATCH(19,월별달력!$J$6:$J$505,0))="","",INDEX(기념일등록!$J$3:$J$502,MATCH(19,월별달력!$J$6:$J$505,0))),"")) | H24: =IF(기념일등록!$B21="",FALSE(),기념일등록!$F21=$B$3) -> FALSE | I24: =IF($H24=FALSE(),"",IF(기념일등록!$G21="",99999,기념일등록!$G21)*1000+ROW()) | J24: =IF($I24="","",RANK($I24,$I$6:$I$505,1))
A25: =IF($C25="","",20) | B25: =IFERROR(INDEX(기념일등록!$G$3:$G$502,MATCH(20,월별달력!$J$6:$J$505,0)),"") | C25: =IFERROR(INDEX(기념일등록!$B$3:$B$502,MATCH(20,월별달력!$J$6:$J$505,0)),"") | D25: =IF($C25="","",IFERROR(INDEX(기념일등록!$C$3:$C$502,MATCH(20,월별달력!$J$6:$J$505,0)),"")) | E25: =IF($C25="","",IFERROR(INDEX(기념일등록!$D$3:$D$502,MATCH(20,월별달력!$J$6:$J$505,0)),"")) | F25: =IF($C25="","",IFERROR(IF(INDEX(기념일등록!$J$3:$J$502,MATCH(20,월별달력!$J$6:$J$505,0))="","",INDEX(기념일등록!$J$3:$J$502,MATCH(20,월별달력!$J$6:$J$505,0))),"")) | H25: =IF(기념일등록!$B22="",FALSE(),기념일등록!$F22=$B$3) -> FALSE | I25: =IF($H25=FALSE(),"",IF(기념일등록!$G22="",99999,기념일등록!$G22)*1000+ROW()) | J25: =IF($I25="","",RANK($I25,$I$6:$I$505,1))
A26: =IF($C26="","",21) | B26: =IFERROR(INDEX(기념일등록!$G$3:$G$502,MATCH(21,월별달력!$J$6:$J$505,0)),"") | C26: =IFERROR(INDEX(기념일등록!$B$3:$B$502,MATCH(21,월별달력!$J$6:$J$505,0)),"") | D26: =IF($C26="","",IFERROR(INDEX(기념일등록!$C$3:$C$502,MATCH(21,월별달력!$J$6:$J$505,0)),"")) | E26: =IF($C26="","",IFERROR(INDEX(기념일등록!$D$3:$D$502,MATCH(21,월별달력!$J$6:$J$505,0)),"")) | F26: =IF($C26="","",IFERROR(IF(INDEX(기념일등록!$J$3:$J$502,MATCH(21,월별달력!$J$6:$J$505,0))="","",INDEX(기념일등록!$J$3:$J$502,MATCH(21,월별달력!$J$6:$J$505,0))),"")) | H26: =IF(기념일등록!$B23="",FALSE(),기념일등록!$F23=$B$3) -> FALSE | I26: =IF($H26=FALSE(),"",IF(기념일등록!$G23="",99999,기념일등록!$G23)*1000+ROW()) | J26: =IF($I26="","",RANK($I26,$I$6:$I$505,1))
A27: =IF($C27="","",22) | B27: =IFERROR(INDEX(기념일등록!$G$3:$G$502,MATCH(22,월별달력!$J$6:$J$505,0)),"") | C27: =IFERROR(INDEX(기념일등록!$B$3:$B$502,MATCH(22,월별달력!$J$6:$J$505,0)),"") | D27: =IF($C27="","",IFERROR(INDEX(기념일등록!$C$3:$C$502,MATCH(22,월별달력!$J$6:$J$505,0)),"")) | E27: =IF($C27="","",IFERROR(INDEX(기념일등록!$D$3:$D$502,MATCH(22,월별달력!$J$6:$J$505,0)),"")) | F27: =IF($C27="","",IFERROR(IF(INDEX(기념일등록!$J$3:$J$502,MATCH(22,월별달력!$J$6:$J$505,0))="","",INDEX(기념일등록!$J$3:$J$502,MATCH(22,월별달력!$J$6:$J$505,0))),"")) | H27: =IF(기념일등록!$B24="",FALSE(),기념일등록!$F24=$B$3) -> FALSE | I27: =IF($H27=FALSE(),"",IF(기념일등록!$G24="",99999,기념일등록!$G24)*1000+ROW()) | J27: =IF($I27="","",RANK($I27,$I$6:$I$505,1))
A28: =IF($C28="","",23) | B28: =IFERROR(INDEX(기념일등록!$G$3:$G$502,MATCH(23,월별달력!$J$6:$J$505,0)),"") | C28: =IFERROR(INDEX(기념일등록!$B$3:$B$502,MATCH(23,월별달력!$J$6:$J$505,0)),"") | D28: =IF($C28="","",IFERROR(INDEX(기념일등록!$C$3:$C$502,MATCH(23,월별달력!$J$6:$J$505,0)),"")) | E28: =IF($C28="","",IFERROR(INDEX(기념일등록!$D$3:$D$502,MATCH(23,월별달력!$J$6:$J$505,0)),"")) | F28: =IF($C28="","",IFERROR(IF(INDEX(기념일등록!$J$3:$J$502,MATCH(23,월별달력!$J$6:$J$505,0))="","",INDEX(기념일등록!$J$3:$J$502,MATCH(23,월별달력!$J$6:$J$505,0))),"")) | H28: =IF(기념일등록!$B25="",FALSE(),기념일등록!$F25=$B$3) -> FALSE | I28: =IF($H28=FALSE(),"",IF(기념일등록!$G25="",99999,기념일등록!$G25)*1000+ROW()) | J28: =IF($I28="","",RANK($I28,$I$6:$I$505,1))
A29: =IF($C29="","",24) | B29: =IFERROR(INDEX(기념일등록!$G$3:$G$502,MATCH(24,월별달력!$J$6:$J$505,0)),"") | C29: =IFERROR(INDEX(기념일등록!$B$3:$B$502,MATCH(24,월별달력!$J$6:$J$505,0)),"") | D29: =IF($C29="","",IFERROR(INDEX(기념일등록!$C$3:$C$502,MATCH(24,월별달력!$J$6:$J$505,0)),"")) | E29: =IF($C29="","",IFERROR(INDEX(기념일등록!$D$3:$D$502,MATCH(24,월별달력!$J$6:$J$505,0)),"")) | F29: =IF($C29="","",IFERROR(IF(INDEX(기념일등록!$J$3:$J$502,MATCH(24,월별달력!$J$6:$J$505,0))="","",INDEX(기념일등록!$J$3:$J$502,MATCH(24,월별달력!$J$6:$J$505,0))),"")) | H29: =IF(기념일등록!$B26="",FALSE(),기념일등록!$F26=$B$3) -> FALSE | I29: =IF($H29=FALSE(),"",IF(기념일등록!$G26="",99999,기념일등록!$G26)*1000+ROW()) | J29: =IF($I29="","",RANK($I29,$I$6:$I$505,1))
A30: =IF($C30="","",25) | B30: =IFERROR(INDEX(기념일등록!$G$3:$G$502,MATCH(25,월별달력!$J$6:$J$505,0)),"") | C30: =IFERROR(INDEX(기념일등록!$B$3:$B$502,MATCH(25,월별달력!$J$6:$J$505,0)),"") | D30: =IF($C30="","",IFERROR(INDEX(기념일등록!$C$3:$C$502,MATCH(25,월별달력!$J$6:$J$505,0)),"")) | E30: =IF($C30="","",IFERROR(INDEX(기념일등록!$D$3:$D$502,MATCH(25,월별달력!$J$6:$J$505,0)),"")) | F30: =IF($C30="","",IFERROR(IF(INDEX(기념일등록!$J$3:$J$502,MATCH(25,월별달력!$J$6:$J$505,0))="","",INDEX(기념일등록!$J$3:$J$502,MATCH(25,월별달력!$J$6:$J$505,0))),"")) | H30: =IF(기념일등록!$B27="",FALSE(),기념일등록!$F27=$B$3) -> FALSE | I30: =IF($H30=FALSE(),"",IF(기념일등록!$G27="",99999,기념일등록!$G27)*1000+ROW()) | J30: =IF($I30="","",RANK($I30,$I$6:$I$505,1))
A31: =IF($C31="","",26) | B31: =IFERROR(INDEX(기념일등록!$G$3:$G$502,MATCH(26,월별달력!$J$6:$J$505,0)),"") | C31: =IFERROR(INDEX(기념일등록!$B$3:$B$502,MATCH(26,월별달력!$J$6:$J$505,0)),"") | D31: =IF($C31="","",IFERROR(INDEX(기념일등록!$C$3:$C$502,MATCH(26,월별달력!$J$6:$J$505,0)),"")) | E31: =IF($C31="","",IFERROR(INDEX(기념일등록!$D$3:$D$502,MATCH(26,월별달력!$J$6:$J$505,0)),"")) | F31: =IF($C31="","",IFERROR(IF(INDEX(기념일등록!$J$3:$J$502,MATCH(26,월별달력!$J$6:$J$505,0))="","",INDEX(기념일등록!$J$3:$J$502,MATCH(26,월별달력!$J$6:$J$505,0))),"")) | H31: =IF(기념일등록!$B28="",FALSE(),기념일등록!$F28=$B$3) -> FALSE | I31: =IF($H31=FALSE(),"",IF(기념일등록!$G28="",99999,기념일등록!$G28)*1000+ROW()) | J31: =IF($I31="","",RANK($I31,$I$6:$I$505,1))
A32: =IF($C32="","",27) | B32: =IFERROR(INDEX(기념일등록!$G$3:$G$502,MATCH(27,월별달력!$J$6:$J$505,0)),"") | C32: =IFERROR(INDEX(기념일등록!$B$3:$B$502,MATCH(27,월별달력!$J$6:$J$505,0)),"") | D32: =IF($C32="","",IFERROR(INDEX(기념일등록!$C$3:$C$502,MATCH(27,월별달력!$J$6:$J$505,0)),"")) | E32: =IF($C32="","",IFERROR(INDEX(기념일등록!$D$3:$D$502,MATCH(27,월별달력!$J$6:$J$505,0)),"")) | F32: =IF($C32="","",IFERROR(IF(INDEX(기념일등록!$J$3:$J$502,MATCH(27,월별달력!$J$6:$J$505,0))="","",INDEX(기념일등록!$J$3:$J$502,MATCH(27,월별달력!$J$6:$J$505,0))),"")) | H32: =IF(기념일등록!$B29="",FALSE(),기념일등록!$F29=$B$3) -> FALSE | I32: =IF($H32=FALSE(),"",IF(기념일등록!$G29="",99999,기념일등록!$G29)*1000+ROW()) | J32: =IF($I32="","",RANK($I32,$I$6:$I$505,1))
A33: =IF($C33="","",28) | B33: =IFERROR(INDEX(기념일등록!$G$3:$G$502,MATCH(28,월별달력!$J$6:$J$505,0)),"") | C33: =IFERROR(INDEX(기념일등록!$B$3:$B$502,MATCH(28,월별달력!$J$6:$J$505,0)),"") | D33: =IF($C33="","",IFERROR(INDEX(기념일등록!$C$3:$C$502,MATCH(28,월별달력!$J$6:$J$505,0)),"")) | E33: =IF($C33="","",IFERROR(INDEX(기념일등록!$D$3:$D$502,MATCH(28,월별달력!$J$6:$J$505,0)),"")) | F33: =IF($C33="","",IFERROR(IF(INDEX(기념일등록!$J$3:$J$502,MATCH(28,월별달력!$J$6:$J$505,0))="","",INDEX(기념일등록!$J$3:$J$502,MATCH(28,월별달력!$J$6:$J$505,0))),"")) | H33: =IF(기념일등록!$B30="",FALSE(),기념일등록!$F30=$B$3) -> FALSE | I33: =IF($H33=FALSE(),"",IF(기념일등록!$G30="",99999,기념일등록!$G30)*1000+ROW()) | J33: =IF($I33="","",RANK($I33,$I$6:$I$505,1))
A34: =IF($C34="","",29) | B34: =IFERROR(INDEX(기념일등록!$G$3:$G$502,MATCH(29,월별달력!$J$6:$J$505,0)),"") | C34: =IFERROR(INDEX(기념일등록!$B$3:$B$502,MATCH(29,월별달력!$J$6:$J$505,0)),"") | D34: =IF($C34="","",IFERROR(INDEX(기념일등록!$C$3:$C$502,MATCH(29,월별달력!$J$6:$J$505,0)),"")) | E34: =IF($C34="","",IFERROR(INDEX(기념일등록!$D$3:$D$502,MATCH(29,월별달력!$J$6:$J$505,0)),"")) | F34: =IF($C34="","",IFERROR(IF(INDEX(기념일등록!$J$3:$J$502,MATCH(29,월별달력!$J$6:$J$505,0))="","",INDEX(기념일등록!$J$3:$J$502,MATCH(29,월별달력!$J$6:$J$505,0))),"")) | H34: =IF(기념일등록!$B31="",FALSE(),기념일등록!$F31=$B$3) -> FALSE | I34: =IF($H34=FALSE(),"",IF(기념일등록!$G31="",99999,기념일등록!$G31)*1000+ROW()) | J34: =IF($I34="","",RANK($I34,$I$6:$I$505,1))
A35: =IF($C35="","",30) | B35: =IFERROR(INDEX(기념일등록!$G$3:$G$502,MATCH(30,월별달력!$J$6:$J$505,0)),"") | C35: =IFERROR(INDEX(기념일등록!$B$3:$B$502,MATCH(30,월별달력!$J$6:$J$505,0)),"") | D35: =IF($C35="","",IFERROR(INDEX(기념일등록!$C$3:$C$502,MATCH(30,월별달력!$J$6:$J$505,0)),"")) | E35: =IF($C35="","",IFERROR(INDEX(기념일등록!$D$3:$D$502,MATCH(30,월별달력!$J$6:$J$505,0)),"")) | F35: =IF($C35="","",IFERROR(IF(INDEX(기념일등록!$J$3:$J$502,MATCH(30,월별달력!$J$6:$J$505,0))="","",INDEX(기념일등록!$J$3:$J$502,MATCH(30,월별달력!$J$6:$J$505,0))),"")) | H35: =IF(기념일등록!$B32="",FALSE(),기념일등록!$F32=$B$3) -> FALSE | I35: =IF($H35=FALSE(),"",IF(기념일등록!$G32="",99999,기념일등록!$G32)*1000+ROW()) | J35: =IF($I35="","",RANK($I35,$I$6:$I$505,1))
