Workbook

Sheet 사용안내
B2: 정기 반복주문 일괄생성
B4: 핵심 | C4: 매번 같은 양을 주문하는 거래처는 한 번만 등록해두면, 날짜만 고르면 그날 나갈 목록이 자동으로 나옵니다.
B5: 입력 규칙 | C5: 파란색 글씨 칸만 입력하세요. 검은색은 자동 계산입니다.
B6: ① 거래처목록 | C6: 거래처코드·거래처명·연락처를 등록합니다.
B7: ② 품목목록 | C7: 품목명·규격·단위·단가를 등록합니다.
B8: ③ 정기주문설정 | C8: 정기적으로 나가는 건을 한 줄씩 등록합니다. 여기가 핵심입니다.
C9: 주기를 매주로 하면 요일을, 매월로 하면 날짜를 넣으세요. 격주는 시작일 기준으로 2주마다입니다.
B10: ④ 주문생성 | C10: 기준일을 고르면 그날 발생할 정기주문이 자동으로 나열됩니다.
C11: 그 목록을 복사해서 [주문내역]에 붙여넣으면 됩니다.
B12: ⑤ 주문내역 | C12: 실제로 나간 주문을 기록합니다. 정기분과 임시분을 함께 관리합니다.
B13: ⑥ 거래처별집계 / 월별집계 | C13: 전부 자동입니다.
B14: 주기 판정 방식 | C14: 매주=요일 일치, 격주=시작일부터 2주 간격, 매월=날짜 일치, 매일=매일
B16: ※ 엑셀만으로는 버튼 한 번에 자동 등록이 되지 않습니다. 대신 [주문생성]에서
B17: 그날 나갈 목록을 만들어주니, 복사해서 [주문내역]에 붙여넣는 방식입니다.

Sheet 거래처목록
A1: 거래처목록
A2: 거래처코드 | B2: 거래처명 | C2: 담당자 | D2: 연락처 | E2: 비고
A3: C001 | B3: ○○식당 | C3: 김사장 | D3: 010-0000-0001
A4: C002 | B4: △△치킨 | C4: 이사장 | D4: 010-0000-0002
A5: C003 | B5: □□분식 | C5: 박사장 | D5: 010-0000-0003

Sheet 품목목록
A1: 품목목록
A2: 품목코드 | B2: 품목명 | C2: 규격 | D2: 단위 | E2: 기본단가
A3: P001 | B3: 폐식용유 수거 | C3: 18L | D3: 통 | E3: 12000
A4: P002 | B4: 식용유 납품 | C4: 18L | D4: 통 | E4: 42000
A5: P003 | B5: 위생용품 세트 | C5: 표준 | D5: SET | E5: 18000

Sheet 정기주문설정
A1: 정기주문설정 (정기적으로 나가는 건을 한 번만 등록)
A2: 번호(자동) | B2: 거래처코드 | C2: 거래처명(자동) | D2: 품목코드 | E2: 품목명(자동) | F2: 단위(자동) | G2: 기본수량 | H2: 단가 | I2: 주기 | J2: 요일(매주·격주) | K2: 일자(매월) | L2: 시작일 | M2: 사용여부 | O2: 요일 | P2: 번호
A3: =IF($B3="","",ROW()-2) -> 1 | B3: C001 | C3: =IF($B3="","",IFERROR(INDEX(거래처목록!$B$3:$B$302,MATCH($B3,거래처목록!$A$3:$A$302,0)),"미등록")) -> ○○식당 | D3: P001 | E3: =IF($D3="","",IFERROR(INDEX(품목목록!$B$3:$B$202,MATCH($D3,품목목록!$A$3:$A$202,0)),"미등록")) -> 폐식용유 수거 | F3: =IF($D3="","",IFERROR(INDEX(품목목록!$D$3:$D$202,MATCH($D3,품목목록!$A$3:$A$202,0)),"")) -> 통 | G3: 2 | H3: =IF($D3="","",IFERROR(INDEX(품목목록!$E$3:$E$202,MATCH($D3,품목목록!$A$3:$A$202,0)),0)) -> 12000 | I3: 매주 | J3: 화 | L3: 46028 | M3: 사용 | O3: 일 | P3: 1
A4: =IF($B4="","",ROW()-2) -> 2 | B4: C002 | C4: =IF($B4="","",IFERROR(INDEX(거래처목록!$B$3:$B$302,MATCH($B4,거래처목록!$A$3:$A$302,0)),"미등록")) -> △△치킨 | D4: P001 | E4: =IF($D4="","",IFERROR(INDEX(품목목록!$B$3:$B$202,MATCH($D4,품목목록!$A$3:$A$202,0)),"미등록")) -> 폐식용유 수거 | F4: =IF($D4="","",IFERROR(INDEX(품목목록!$D$3:$D$202,MATCH($D4,품목목록!$A$3:$A$202,0)),"")) -> 통 | G4: 3 | H4: =IF($D4="","",IFERROR(INDEX(품목목록!$E$3:$E$202,MATCH($D4,품목목록!$A$3:$A$202,0)),0)) -> 12000 | I4: 매주 | J4: 화 | L4: 46028 | M4: 사용 | O4: 월 | P4: 2
A5: =IF($B5="","",ROW()-2) -> 3 | B5: C003 | C5: =IF($B5="","",IFERROR(INDEX(거래처목록!$B$3:$B$302,MATCH($B5,거래처목록!$A$3:$A$302,0)),"미등록")) -> □□분식 | D5: P002 | E5: =IF($D5="","",IFERROR(INDEX(품목목록!$B$3:$B$202,MATCH($D5,품목목록!$A$3:$A$202,0)),"미등록")) -> 식용유 납품 | F5: =IF($D5="","",IFERROR(INDEX(품목목록!$D$3:$D$202,MATCH($D5,품목목록!$A$3:$A$202,0)),"")) -> 통 | G5: 1 | H5: =IF($D5="","",IFERROR(INDEX(품목목록!$E$3:$E$202,MATCH($D5,품목목록!$A$3:$A$202,0)),0)) -> 42000 | I5: 매월 | K5: 15 | L5: 46037 | M5: 사용 | O5: 화 | P5: 3
A6: =IF($B6="","",ROW()-2) -> 4 | B6: C001 | C6: =IF($B6="","",IFERROR(INDEX(거래처목록!$B$3:$B$302,MATCH($B6,거래처목록!$A$3:$A$302,0)),"미등록")) -> ○○식당 | D6: P003 | E6: =IF($D6="","",IFERROR(INDEX(품목목록!$B$3:$B$202,MATCH($D6,품목목록!$A$3:$A$202,0)),"미등록")) -> 위생용품 세트 | F6: =IF($D6="","",IFERROR(INDEX(품목목록!$D$3:$D$202,MATCH($D6,품목목록!$A$3:$A$202,0)),"")) -> SET | G6: 1 | H6: =IF($D6="","",IFERROR(INDEX(품목목록!$E$3:$E$202,MATCH($D6,품목목록!$A$3:$A$202,0)),0)) -> 18000 | I6: 격주 | J6: 금 | L6: 46024 | M6: 사용 | O6: 수 | P6: 4
A7: =IF($B7="","",ROW()-2) | C7: =IF($B7="","",IFERROR(INDEX(거래처목록!$B$3:$B$302,MATCH($B7,거래처목록!$A$3:$A$302,0)),"미등록")) | E7: =IF($D7="","",IFERROR(INDEX(품목목록!$B$3:$B$202,MATCH($D7,품목목록!$A$3:$A$202,0)),"미등록")) | F7: =IF($D7="","",IFERROR(INDEX(품목목록!$D$3:$D$202,MATCH($D7,품목목록!$A$3:$A$202,0)),"")) | H7: =IF($D7="","",IFERROR(INDEX(품목목록!$E$3:$E$202,MATCH($D7,품목목록!$A$3:$A$202,0)),0)) | O7: 목 | P7: 5
A8: =IF($B8="","",ROW()-2) | C8: =IF($B8="","",IFERROR(INDEX(거래처목록!$B$3:$B$302,MATCH($B8,거래처목록!$A$3:$A$302,0)),"미등록")) | E8: =IF($D8="","",IFERROR(INDEX(품목목록!$B$3:$B$202,MATCH($D8,품목목록!$A$3:$A$202,0)),"미등록")) | F8: =IF($D8="","",IFERROR(INDEX(품목목록!$D$3:$D$202,MATCH($D8,품목목록!$A$3:$A$202,0)),"")) | H8: =IF($D8="","",IFERROR(INDEX(품목목록!$E$3:$E$202,MATCH($D8,품목목록!$A$3:$A$202,0)),0)) | O8: 금 | P8: 6
A9: =IF($B9="","",ROW()-2) | C9: =IF($B9="","",IFERROR(INDEX(거래처목록!$B$3:$B$302,MATCH($B9,거래처목록!$A$3:$A$302,0)),"미등록")) | E9: =IF($D9="","",IFERROR(INDEX(품목목록!$B$3:$B$202,MATCH($D9,품목목록!$A$3:$A$202,0)),"미등록")) | F9: =IF($D9="","",IFERROR(INDEX(품목목록!$D$3:$D$202,MATCH($D9,품목목록!$A$3:$A$202,0)),"")) | H9: =IF($D9="","",IFERROR(INDEX(품목목록!$E$3:$E$202,MATCH($D9,품목목록!$A$3:$A$202,0)),0)) | O9: 토 | P9: 7
A10: =IF($B10="","",ROW()-2) | C10: =IF($B10="","",IFERROR(INDEX(거래처목록!$B$3:$B$302,MATCH($B10,거래처목록!$A$3:$A$302,0)),"미등록")) | E10: =IF($D10="","",IFERROR(INDEX(품목목록!$B$3:$B$202,MATCH($D10,품목목록!$A$3:$A$202,0)),"미등록")) | F10: =IF($D10="","",IFERROR(INDEX(품목목록!$D$3:$D$202,MATCH($D10,품목목록!$A$3:$A$202,0)),"")) | H10: =IF($D10="","",IFERROR(INDEX(품목목록!$E$3:$E$202,MATCH($D10,품목목록!$A$3:$A$202,0)),0))
A11: =IF($B11="","",ROW()-2) | C11: =IF($B11="","",IFERROR(INDEX(거래처목록!$B$3:$B$302,MATCH($B11,거래처목록!$A$3:$A$302,0)),"미등록")) | E11: =IF($D11="","",IFERROR(INDEX(품목목록!$B$3:$B$202,MATCH($D11,품목목록!$A$3:$A$202,0)),"미등록")) | F11: =IF($D11="","",IFERROR(INDEX(품목목록!$D$3:$D$202,MATCH($D11,품목목록!$A$3:$A$202,0)),"")) | H11: =IF($D11="","",IFERROR(INDEX(품목목록!$E$3:$E$202,MATCH($D11,품목목록!$A$3:$A$202,0)),0))
A12: =IF($B12="","",ROW()-2) | C12: =IF($B12="","",IFERROR(INDEX(거래처목록!$B$3:$B$302,MATCH($B12,거래처목록!$A$3:$A$302,0)),"미등록")) | E12: =IF($D12="","",IFERROR(INDEX(품목목록!$B$3:$B$202,MATCH($D12,품목목록!$A$3:$A$202,0)),"미등록")) | F12: =IF($D12="","",IFERROR(INDEX(품목목록!$D$3:$D$202,MATCH($D12,품목목록!$A$3:$A$202,0)),"")) | H12: =IF($D12="","",IFERROR(INDEX(품목목록!$E$3:$E$202,MATCH($D12,품목목록!$A$3:$A$202,0)),0))
A13: =IF($B13="","",ROW()-2) | C13: =IF($B13="","",IFERROR(INDEX(거래처목록!$B$3:$B$302,MATCH($B13,거래처목록!$A$3:$A$302,0)),"미등록")) | E13: =IF($D13="","",IFERROR(INDEX(품목목록!$B$3:$B$202,MATCH($D13,품목목록!$A$3:$A$202,0)),"미등록")) | F13: =IF($D13="","",IFERROR(INDEX(품목목록!$D$3:$D$202,MATCH($D13,품목목록!$A$3:$A$202,0)),"")) | H13: =IF($D13="","",IFERROR(INDEX(품목목록!$E$3:$E$202,MATCH($D13,품목목록!$A$3:$A$202,0)),0))
A14: =IF($B14="","",ROW()-2) | C14: =IF($B14="","",IFERROR(INDEX(거래처목록!$B$3:$B$302,MATCH($B14,거래처목록!$A$3:$A$302,0)),"미등록")) | E14: =IF($D14="","",IFERROR(INDEX(품목목록!$B$3:$B$202,MATCH($D14,품목목록!$A$3:$A$202,0)),"미등록")) | F14: =IF($D14="","",IFERROR(INDEX(품목목록!$D$3:$D$202,MATCH($D14,품목목록!$A$3:$A$202,0)),"")) | H14: =IF($D14="","",IFERROR(INDEX(품목목록!$E$3:$E$202,MATCH($D14,품목목록!$A$3:$A$202,0)),0))
A15: =IF($B15="","",ROW()-2) | C15: =IF($B15="","",IFERROR(INDEX(거래처목록!$B$3:$B$302,MATCH($B15,거래처목록!$A$3:$A$302,0)),"미등록")) | E15: =IF($D15="","",IFERROR(INDEX(품목목록!$B$3:$B$202,MATCH($D15,품목목록!$A$3:$A$202,0)),"미등록")) | F15: =IF($D15="","",IFERROR(INDEX(품목목록!$D$3:$D$202,MATCH($D15,품목목록!$A$3:$A$202,0)),"")) | H15: =IF($D15="","",IFERROR(INDEX(품목목록!$E$3:$E$202,MATCH($D15,품목목록!$A$3:$A$202,0)),0))
A16: =IF($B16="","",ROW()-2) | C16: =IF($B16="","",IFERROR(INDEX(거래처목록!$B$3:$B$302,MATCH($B16,거래처목록!$A$3:$A$302,0)),"미등록")) | E16: =IF($D16="","",IFERROR(INDEX(품목목록!$B$3:$B$202,MATCH($D16,품목목록!$A$3:$A$202,0)),"미등록")) | F16: =IF($D16="","",IFERROR(INDEX(품목목록!$D$3:$D$202,MATCH($D16,품목목록!$A$3:$A$202,0)),"")) | H16: =IF($D16="","",IFERROR(INDEX(품목목록!$E$3:$E$202,MATCH($D16,품목목록!$A$3:$A$202,0)),0))
A17: =IF($B17="","",ROW()-2) | C17: =IF($B17="","",IFERROR(INDEX(거래처목록!$B$3:$B$302,MATCH($B17,거래처목록!$A$3:$A$302,0)),"미등록")) | E17: =IF($D17="","",IFERROR(INDEX(품목목록!$B$3:$B$202,MATCH($D17,품목목록!$A$3:$A$202,0)),"미등록")) | F17: =IF($D17="","",IFERROR(INDEX(품목목록!$D$3:$D$202,MATCH($D17,품목목록!$A$3:$A$202,0)),"")) | H17: =IF($D17="","",IFERROR(INDEX(품목목록!$E$3:$E$202,MATCH($D17,품목목록!$A$3:$A$202,0)),0))
A18: =IF($B18="","",ROW()-2) | C18: =IF($B18="","",IFERROR(INDEX(거래처목록!$B$3:$B$302,MATCH($B18,거래처목록!$A$3:$A$302,0)),"미등록")) | E18: =IF($D18="","",IFERROR(INDEX(품목목록!$B$3:$B$202,MATCH($D18,품목목록!$A$3:$A$202,0)),"미등록")) | F18: =IF($D18="","",IFERROR(INDEX(품목목록!$D$3:$D$202,MATCH($D18,품목목록!$A$3:$A$202,0)),"")) | H18: =IF($D18="","",IFERROR(INDEX(품목목록!$E$3:$E$202,MATCH($D18,품목목록!$A$3:$A$202,0)),0))
A19: =IF($B19="","",ROW()-2) | C19: =IF($B19="","",IFERROR(INDEX(거래처목록!$B$3:$B$302,MATCH($B19,거래처목록!$A$3:$A$302,0)),"미등록")) | E19: =IF($D19="","",IFERROR(INDEX(품목목록!$B$3:$B$202,MATCH($D19,품목목록!$A$3:$A$202,0)),"미등록")) | F19: =IF($D19="","",IFERROR(INDEX(품목목록!$D$3:$D$202,MATCH($D19,품목목록!$A$3:$A$202,0)),"")) | H19: =IF($D19="","",IFERROR(INDEX(품목목록!$E$3:$E$202,MATCH($D19,품목목록!$A$3:$A$202,0)),0))
A20: =IF($B20="","",ROW()-2) | C20: =IF($B20="","",IFERROR(INDEX(거래처목록!$B$3:$B$302,MATCH($B20,거래처목록!$A$3:$A$302,0)),"미등록")) | E20: =IF($D20="","",IFERROR(INDEX(품목목록!$B$3:$B$202,MATCH($D20,품목목록!$A$3:$A$202,0)),"미등록")) | F20: =IF($D20="","",IFERROR(INDEX(품목목록!$D$3:$D$202,MATCH($D20,품목목록!$A$3:$A$202,0)),"")) | H20: =IF($D20="","",IFERROR(INDEX(품목목록!$E$3:$E$202,MATCH($D20,품목목록!$A$3:$A$202,0)),0))
A21: =IF($B21="","",ROW()-2) | C21: =IF($B21="","",IFERROR(INDEX(거래처목록!$B$3:$B$302,MATCH($B21,거래처목록!$A$3:$A$302,0)),"미등록")) | E21: =IF($D21="","",IFERROR(INDEX(품목목록!$B$3:$B$202,MATCH($D21,품목목록!$A$3:$A$202,0)),"미등록")) | F21: =IF($D21="","",IFERROR(INDEX(품목목록!$D$3:$D$202,MATCH($D21,품목목록!$A$3:$A$202,0)),"")) | H21: =IF($D21="","",IFERROR(INDEX(품목목록!$E$3:$E$202,MATCH($D21,품목목록!$A$3:$A$202,0)),0))
... A302: =IF($B302="","",ROW()-2) | C302: =IF($B302="","",IFERROR(INDEX(거래처목록!$B$3:$B$302,MATCH($B302,거래처목록!$A$3:$A$302,0)),"미등록")) | E302: =IF($D302="","",IFERROR(INDEX(품목목록!$B$3:$B$202,MATCH($D302,품목목록!$A$3:$A$202,0)),"미등록")) | F302: =IF($D302="","",IFERROR(INDEX(품목목록!$D$3:$D$202,MATCH($D302,품목목록!$A$3:$A$202,0)),"")) | H302: =IF($D302="","",IFERROR(INDEX(품목목록!$E$3:$E$202,MATCH($D302,품목목록!$A$3:$A$202,0)),0))
A304: ※ 격주는 [시작일]을 기준으로 2주마다 발생합니다. 시작일을 반드시 넣으세요.
A305: ※ 잠시 쉬는 거래처는 지우지 말고 [사용여부]를 '중지'로 바꾸세요.

Sheet 주문생성
A1: 주문생성 (기준일을 고르면 그날 나갈 목록이 나옵니다)
A3: 기준일 | B3: 46280 | C3: =CHOOSE(WEEKDAY($B$3),"일","월","화","수","목","금","토")&"요일" -> 화요일 | D3: ← 이 칸만 바꾸세요 | F3: 해당 건수 | G3: =COUNTIF($K$6:$K$305,TRUE()) -> 3
A5: 주문일 | B5: 거래처코드 | C5: 거래처명 | D5: 품목코드 | E5: 품목명 | F5: 단위 | G5: 수량 | H5: 단가 | I5: 금액 | K5: 대상(자동) | L5: 순번(자동) | M5: 키(자동)
A6: =IF($C6="","",$B$3) -> 46280 | B6: =IFERROR(INDEX(정기주문설정!$B$3:$B$302,MATCH("R"&1,주문생성!$M$6:$M$305,0)),"") -> C001 | C6: =IF($B6="","",IFERROR(INDEX(정기주문설정!$C$3:$C$302,MATCH("R"&1,주문생성!$M$6:$M$305,0)),"")) -> ○○식당 | D6: =IF($B6="","",IFERROR(INDEX(정기주문설정!$D$3:$D$302,MATCH("R"&1,주문생성!$M$6:$M$305,0)),"")) -> P001 | E6: =IF($B6="","",IFERROR(INDEX(정기주문설정!$E$3:$E$302,MATCH("R"&1,주문생성!$M$6:$M$305,0)),"")) -> 폐식용유 수거 | F6: =IF($B6="","",IFERROR(INDEX(정기주문설정!$F$3:$F$302,MATCH("R"&1,주문생성!$M$6:$M$305,0)),"")) -> 통 | G6: =IF($B6="","",IFERROR(INDEX(정기주문설정!$G$3:$G$302,MATCH("R"&1,주문생성!$M$6:$M$305,0)),"")) -> 2 | H6: =IF($B6="","",IFERROR(INDEX(정기주문설정!$H$3:$H$302,MATCH("R"&1,주문생성!$M$6:$M$305,0)),"")) -> 12000 | I6: =IF($B6="","",ROUND($G6*$H6,0)) -> 24000 | K6: =IF(정기주문설정!$B3="",FALSE(),IF(정기주문설정!$M3="중지",FALSE(),IF(정기주문설정!$L3<>"",IF($B$3<정기주문설정!$L3,FALSE(),IF(정기주문설정!$I3="매일",TRUE(),IF(정기주문설정!$I3="매주",(WEEKDAY($B$3)=IFERROR(MATCH(정기주문설정!$J3,정기주문설정!$O$3:$O$9,0),0)),IF(정기주문설정!$I3="격주",AND((WEEKDAY($B$3)=IFERROR(MATCH(정기주문설정!$J3,정기주문설정!$O$3:$O$9,0),0)),MOD(INT(($B$3-정기주문설정!$L3)/7),2)=0),IF(정기주문설정!$I3="매월",DAY($B$3)=정기주문설정!$K3,FALSE()))))),IF(정기주문설정!$I3="매일",TRUE(),IF(정기주문설정!$I3="매주",(WEEKDAY($B$3)=IFERROR(MATCH(정기주문설정!$J3,정기주문설정!$O$3:$O$9,0),0)),IF(정기주문설정!$I3="매월",DAY($B$3)=정기주문설정!$K3,FALSE())))))) -> TRUE | L6: =IF($K6=FALSE(),"",COUNTIF($K$6:$K6,TRUE())) -> 1 | M6: =IF($L6="","","R"&$L6) -> R1
A7: =IF($C7="","",$B$3) -> 46280 | B7: =IFERROR(INDEX(정기주문설정!$B$3:$B$302,MATCH("R"&2,주문생성!$M$6:$M$305,0)),"") -> C002 | C7: =IF($B7="","",IFERROR(INDEX(정기주문설정!$C$3:$C$302,MATCH("R"&2,주문생성!$M$6:$M$305,0)),"")) -> △△치킨 | D7: =IF($B7="","",IFERROR(INDEX(정기주문설정!$D$3:$D$302,MATCH("R"&2,주문생성!$M$6:$M$305,0)),"")) -> P001 | E7: =IF($B7="","",IFERROR(INDEX(정기주문설정!$E$3:$E$302,MATCH("R"&2,주문생성!$M$6:$M$305,0)),"")) -> 폐식용유 수거 | F7: =IF($B7="","",IFERROR(INDEX(정기주문설정!$F$3:$F$302,MATCH("R"&2,주문생성!$M$6:$M$305,0)),"")) -> 통 | G7: =IF($B7="","",IFERROR(INDEX(정기주문설정!$G$3:$G$302,MATCH("R"&2,주문생성!$M$6:$M$305,0)),"")) -> 3 | H7: =IF($B7="","",IFERROR(INDEX(정기주문설정!$H$3:$H$302,MATCH("R"&2,주문생성!$M$6:$M$305,0)),"")) -> 12000 | I7: =IF($B7="","",ROUND($G7*$H7,0)) -> 36000 | K7: =IF(정기주문설정!$B4="",FALSE(),IF(정기주문설정!$M4="중지",FALSE(),IF(정기주문설정!$L4<>"",IF($B$3<정기주문설정!$L4,FALSE(),IF(정기주문설정!$I4="매일",TRUE(),IF(정기주문설정!$I4="매주",(WEEKDAY($B$3)=IFERROR(MATCH(정기주문설정!$J4,정기주문설정!$O$3:$O$9,0),0)),IF(정기주문설정!$I4="격주",AND((WEEKDAY($B$3)=IFERROR(MATCH(정기주문설정!$J4,정기주문설정!$O$3:$O$9,0),0)),MOD(INT(($B$3-정기주문설정!$L4)/7),2)=0),IF(정기주문설정!$I4="매월",DAY($B$3)=정기주문설정!$K4,FALSE()))))),IF(정기주문설정!$I4="매일",TRUE(),IF(정기주문설정!$I4="매주",(WEEKDAY($B$3)=IFERROR(MATCH(정기주문설정!$J4,정기주문설정!$O$3:$O$9,0),0)),IF(정기주문설정!$I4="매월",DAY($B$3)=정기주문설정!$K4,FALSE())))))) -> TRUE | L7: =IF($K7=FALSE(),"",COUNTIF($K$6:$K7,TRUE())) -> 2 | M7: =IF($L7="","","R"&$L7) -> R2
A8: =IF($C8="","",$B$3) -> 46280 | B8: =IFERROR(INDEX(정기주문설정!$B$3:$B$302,MATCH("R"&3,주문생성!$M$6:$M$305,0)),"") -> C003 | C8: =IF($B8="","",IFERROR(INDEX(정기주문설정!$C$3:$C$302,MATCH("R"&3,주문생성!$M$6:$M$305,0)),"")) -> □□분식 | D8: =IF($B8="","",IFERROR(INDEX(정기주문설정!$D$3:$D$302,MATCH("R"&3,주문생성!$M$6:$M$305,0)),"")) -> P002 | E8: =IF($B8="","",IFERROR(INDEX(정기주문설정!$E$3:$E$302,MATCH("R"&3,주문생성!$M$6:$M$305,0)),"")) -> 식용유 납품 | F8: =IF($B8="","",IFERROR(INDEX(정기주문설정!$F$3:$F$302,MATCH("R"&3,주문생성!$M$6:$M$305,0)),"")) -> 통 | G8: =IF($B8="","",IFERROR(INDEX(정기주문설정!$G$3:$G$302,MATCH("R"&3,주문생성!$M$6:$M$305,0)),"")) -> 1 | H8: =IF($B8="","",IFERROR(INDEX(정기주문설정!$H$3:$H$302,MATCH("R"&3,주문생성!$M$6:$M$305,0)),"")) -> 42000 | I8: =IF($B8="","",ROUND($G8*$H8,0)) -> 42000 | K8: =IF(정기주문설정!$B5="",FALSE(),IF(정기주문설정!$M5="중지",FALSE(),IF(정기주문설정!$L5<>"",IF($B$3<정기주문설정!$L5,FALSE(),IF(정기주문설정!$I5="매일",TRUE(),IF(정기주문설정!$I5="매주",(WEEKDAY($B$3)=IFERROR(MATCH(정기주문설정!$J5,정기주문설정!$O$3:$O$9,0),0)),IF(정기주문설정!$I5="격주",AND((WEEKDAY($B$3)=IFERROR(MATCH(정기주문설정!$J5,정기주문설정!$O$3:$O$9,0),0)),MOD(INT(($B$3-정기주문설정!$L5)/7),2)=0),IF(정기주문설정!$I5="매월",DAY($B$3)=정기주문설정!$K5,FALSE()))))),IF(정기주문설정!$I5="매일",TRUE(),IF(정기주문설정!$I5="매주",(WEEKDAY($B$3)=IFERROR(MATCH(정기주문설정!$J5,정기주문설정!$O$3:$O$9,0),0)),IF(정기주문설정!$I5="매월",DAY($B$3)=정기주문설정!$K5,FALSE())))))) -> TRUE | L8: =IF($K8=FALSE(),"",COUNTIF($K$6:$K8,TRUE())) -> 3 | M8: =IF($L8="","","R"&$L8) -> R3
A9: =IF($C9="","",$B$3) | B9: =IFERROR(INDEX(정기주문설정!$B$3:$B$302,MATCH("R"&4,주문생성!$M$6:$M$305,0)),"") | C9: =IF($B9="","",IFERROR(INDEX(정기주문설정!$C$3:$C$302,MATCH("R"&4,주문생성!$M$6:$M$305,0)),"")) | D9: =IF($B9="","",IFERROR(INDEX(정기주문설정!$D$3:$D$302,MATCH("R"&4,주문생성!$M$6:$M$305,0)),"")) | E9: =IF($B9="","",IFERROR(INDEX(정기주문설정!$E$3:$E$302,MATCH("R"&4,주문생성!$M$6:$M$305,0)),"")) | F9: =IF($B9="","",IFERROR(INDEX(정기주문설정!$F$3:$F$302,MATCH("R"&4,주문생성!$M$6:$M$305,0)),"")) | G9: =IF($B9="","",IFERROR(INDEX(정기주문설정!$G$3:$G$302,MATCH("R"&4,주문생성!$M$6:$M$305,0)),"")) | H9: =IF($B9="","",IFERROR(INDEX(정기주문설정!$H$3:$H$302,MATCH("R"&4,주문생성!$M$6:$M$305,0)),"")) | I9: =IF($B9="","",ROUND($G9*$H9,0)) | K9: =IF(정기주문설정!$B6="",FALSE(),IF(정기주문설정!$M6="중지",FALSE(),IF(정기주문설정!$L6<>"",IF($B$3<정기주문설정!$L6,FALSE(),IF(정기주문설정!$I6="매일",TRUE(),IF(정기주문설정!$I6="매주",(WEEKDAY($B$3)=IFERROR(MATCH(정기주문설정!$J6,정기주문설정!$O$3:$O$9,0),0)),IF(정기주문설정!$I6="격주",AND((WEEKDAY($B$3)=IFERROR(MATCH(정기주문설정!$J6,정기주문설정!$O$3:$O$9,0),0)),MOD(INT(($B$3-정기주문설정!$L6)/7),2)=0),IF(정기주문설정!$I6="매월",DAY($B$3)=정기주문설정!$K6,FALSE()))))),IF(정기주문설정!$I6="매일",TRUE(),IF(정기주문설정!$I6="매주",(WEEKDAY($B$3)=IFERROR(MATCH(정기주문설정!$J6,정기주문설정!$O$3:$O$9,0),0)),IF(정기주문설정!$I6="매월",DAY($B$3)=정기주문설정!$K6,FALSE())))))) -> FALSE | L9: =IF($K9=FALSE(),"",COUNTIF($K$6:$K9,TRUE())) | M9: =IF($L9="","","R"&$L9)
A10: =IF($C10="","",$B$3) | B10: =IFERROR(INDEX(정기주문설정!$B$3:$B$302,MATCH("R"&5,주문생성!$M$6:$M$305,0)),"") | C10: =IF($B10="","",IFERROR(INDEX(정기주문설정!$C$3:$C$302,MATCH("R"&5,주문생성!$M$6:$M$305,0)),"")) | D10: =IF($B10="","",IFERROR(INDEX(정기주문설정!$D$3:$D$302,MATCH("R"&5,주문생성!$M$6:$M$305,0)),"")) | E10: =IF($B10="","",IFERROR(INDEX(정기주문설정!$E$3:$E$302,MATCH("R"&5,주문생성!$M$6:$M$305,0)),"")) | F10: =IF($B10="","",IFERROR(INDEX(정기주문설정!$F$3:$F$302,MATCH("R"&5,주문생성!$M$6:$M$305,0)),"")) | G10: =IF($B10="","",IFERROR(INDEX(정기주문설정!$G$3:$G$302,MATCH("R"&5,주문생성!$M$6:$M$305,0)),"")) | H10: =IF($B10="","",IFERROR(INDEX(정기주문설정!$H$3:$H$302,MATCH("R"&5,주문생성!$M$6:$M$305,0)),"")) | I10: =IF($B10="","",ROUND($G10*$H10,0)) | K10: =IF(정기주문설정!$B7="",FALSE(),IF(정기주문설정!$M7="중지",FALSE(),IF(정기주문설정!$L7<>"",IF($B$3<정기주문설정!$L7,FALSE(),IF(정기주문설정!$I7="매일",TRUE(),IF(정기주문설정!$I7="매주",(WEEKDAY($B$3)=IFERROR(MATCH(정기주문설정!$J7,정기주문설정!$O$3:$O$9,0),0)),IF(정기주문설정!$I7="격주",AND((WEEKDAY($B$3)=IFERROR(MATCH(정기주문설정!$J7,정기주문설정!$O$3:$O$9,0),0)),MOD(INT(($B$3-정기주문설정!$L7)/7),2)=0),IF(정기주문설정!$I7="매월",DAY($B$3)=정기주문설정!$K7,FALSE()))))),IF(정기주문설정!$I7="매일",TRUE(),IF(정기주문설정!$I7="매주",(WEEKDAY($B$3)=IFERROR(MATCH(정기주문설정!$J7,정기주문설정!$O$3:$O$9,0),0)),IF(정기주문설정!$I7="매월",DAY($B$3)=정기주문설정!$K7,FALSE())))))) -> FALSE | L10: =IF($K10=FALSE(),"",COUNTIF($K$6:$K10,TRUE())) | M10: =IF($L10="","","R"&$L10)
A11: =IF($C11="","",$B$3) | B11: =IFERROR(INDEX(정기주문설정!$B$3:$B$302,MATCH("R"&6,주문생성!$M$6:$M$305,0)),"") | C11: =IF($B11="","",IFERROR(INDEX(정기주문설정!$C$3:$C$302,MATCH("R"&6,주문생성!$M$6:$M$305,0)),"")) | D11: =IF($B11="","",IFERROR(INDEX(정기주문설정!$D$3:$D$302,MATCH("R"&6,주문생성!$M$6:$M$305,0)),"")) | E11: =IF($B11="","",IFERROR(INDEX(정기주문설정!$E$3:$E$302,MATCH("R"&6,주문생성!$M$6:$M$305,0)),"")) | F11: =IF($B11="","",IFERROR(INDEX(정기주문설정!$F$3:$F$302,MATCH("R"&6,주문생성!$M$6:$M$305,0)),"")) | G11: =IF($B11="","",IFERROR(INDEX(정기주문설정!$G$3:$G$302,MATCH("R"&6,주문생성!$M$6:$M$305,0)),"")) | H11: =IF($B11="","",IFERROR(INDEX(정기주문설정!$H$3:$H$302,MATCH("R"&6,주문생성!$M$6:$M$305,0)),"")) | I11: =IF($B11="","",ROUND($G11*$H11,0)) | K11: =IF(정기주문설정!$B8="",FALSE(),IF(정기주문설정!$M8="중지",FALSE(),IF(정기주문설정!$L8<>"",IF($B$3<정기주문설정!$L8,FALSE(),IF(정기주문설정!$I8="매일",TRUE(),IF(정기주문설정!$I8="매주",(WEEKDAY($B$3)=IFERROR(MATCH(정기주문설정!$J8,정기주문설정!$O$3:$O$9,0),0)),IF(정기주문설정!$I8="격주",AND((WEEKDAY($B$3)=IFERROR(MATCH(정기주문설정!$J8,정기주문설정!$O$3:$O$9,0),0)),MOD(INT(($B$3-정기주문설정!$L8)/7),2)=0),IF(정기주문설정!$I8="매월",DAY($B$3)=정기주문설정!$K8,FALSE()))))),IF(정기주문설정!$I8="매일",TRUE(),IF(정기주문설정!$I8="매주",(WEEKDAY($B$3)=IFERROR(MATCH(정기주문설정!$J8,정기주문설정!$O$3:$O$9,0),0)),IF(정기주문설정!$I8="매월",DAY($B$3)=정기주문설정!$K8,FALSE())))))) -> FALSE | L11: =IF($K11=FALSE(),"",COUNTIF($K$6:$K11,TRUE())) | M11: =IF($L11="","","R"&$L11)
A12: =IF($C12="","",$B$3) | B12: =IFERROR(INDEX(정기주문설정!$B$3:$B$302,MATCH("R"&7,주문생성!$M$6:$M$305,0)),"") | C12: =IF($B12="","",IFERROR(INDEX(정기주문설정!$C$3:$C$302,MATCH("R"&7,주문생성!$M$6:$M$305,0)),"")) | D12: =IF($B12="","",IFERROR(INDEX(정기주문설정!$D$3:$D$302,MATCH("R"&7,주문생성!$M$6:$M$305,0)),"")) | E12: =IF($B12="","",IFERROR(INDEX(정기주문설정!$E$3:$E$302,MATCH("R"&7,주문생성!$M$6:$M$305,0)),"")) | F12: =IF($B12="","",IFERROR(INDEX(정기주문설정!$F$3:$F$302,MATCH("R"&7,주문생성!$M$6:$M$305,0)),"")) | G12: =IF($B12="","",IFERROR(INDEX(정기주문설정!$G$3:$G$302,MATCH("R"&7,주문생성!$M$6:$M$305,0)),"")) | H12: =IF($B12="","",IFERROR(INDEX(정기주문설정!$H$3:$H$302,MATCH("R"&7,주문생성!$M$6:$M$305,0)),"")) | I12: =IF($B12="","",ROUND($G12*$H12,0)) | K12: =IF(정기주문설정!$B9="",FALSE(),IF(정기주문설정!$M9="중지",FALSE(),IF(정기주문설정!$L9<>"",IF($B$3<정기주문설정!$L9,FALSE(),IF(정기주문설정!$I9="매일",TRUE(),IF(정기주문설정!$I9="매주",(WEEKDAY($B$3)=IFERROR(MATCH(정기주문설정!$J9,정기주문설정!$O$3:$O$9,0),0)),IF(정기주문설정!$I9="격주",AND((WEEKDAY($B$3)=IFERROR(MATCH(정기주문설정!$J9,정기주문설정!$O$3:$O$9,0),0)),MOD(INT(($B$3-정기주문설정!$L9)/7),2)=0),IF(정기주문설정!$I9="매월",DAY($B$3)=정기주문설정!$K9,FALSE()))))),IF(정기주문설정!$I9="매일",TRUE(),IF(정기주문설정!$I9="매주",(WEEKDAY($B$3)=IFERROR(MATCH(정기주문설정!$J9,정기주문설정!$O$3:$O$9,0),0)),IF(정기주문설정!$I9="매월",DAY($B$3)=정기주문설정!$K9,FALSE())))))) -> FALSE | L12: =IF($K12=FALSE(),"",COUNTIF($K$6:$K12,TRUE())) | M12: =IF($L12="","","R"&$L12)
A13: =IF($C13="","",$B$3) | B13: =IFERROR(INDEX(정기주문설정!$B$3:$B$302,MATCH("R"&8,주문생성!$M$6:$M$305,0)),"") | C13: =IF($B13="","",IFERROR(INDEX(정기주문설정!$C$3:$C$302,MATCH("R"&8,주문생성!$M$6:$M$305,0)),"")) | D13: =IF($B13="","",IFERROR(INDEX(정기주문설정!$D$3:$D$302,MATCH("R"&8,주문생성!$M$6:$M$305,0)),"")) | E13: =IF($B13="","",IFERROR(INDEX(정기주문설정!$E$3:$E$302,MATCH("R"&8,주문생성!$M$6:$M$305,0)),"")) | F13: =IF($B13="","",IFERROR(INDEX(정기주문설정!$F$3:$F$302,MATCH("R"&8,주문생성!$M$6:$M$305,0)),"")) | G13: =IF($B13="","",IFERROR(INDEX(정기주문설정!$G$3:$G$302,MATCH("R"&8,주문생성!$M$6:$M$305,0)),"")) | H13: =IF($B13="","",IFERROR(INDEX(정기주문설정!$H$3:$H$302,MATCH("R"&8,주문생성!$M$6:$M$305,0)),"")) | I13: =IF($B13="","",ROUND($G13*$H13,0)) | K13: =IF(정기주문설정!$B10="",FALSE(),IF(정기주문설정!$M10="중지",FALSE(),IF(정기주문설정!$L10<>"",IF($B$3<정기주문설정!$L10,FALSE(),IF(정기주문설정!$I10="매일",TRUE(),IF(정기주문설정!$I10="매주",(WEEKDAY($B$3)=IFERROR(MATCH(정기주문설정!$J10,정기주문설정!$O$3:$O$9,0),0)),IF(정기주문설정!$I10="격주",AND((WEEKDAY($B$3)=IFERROR(MATCH(정기주문설정!$J10,정기주문설정!$O$3:$O$9,0),0)),MOD(INT(($B$3-정기주문설정!$L10)/7),2)=0),IF(정기주문설정!$I10="매월",DAY($B$3)=정기주문설정!$K10,FALSE()))))),IF(정기주문설정!$I10="매일",TRUE(),IF(정기주문설정!$I10="매주",(WEEKDAY($B$3)=IFERROR(MATCH(정기주문설정!$J10,정기주문설정!$O$3:$O$9,0),0)),IF(정기주문설정!$I10="매월",DAY($B$3)=정기주문설정!$K10,FALSE())))))) -> FALSE | L13: =IF($K13=FALSE(),"",COUNTIF($K$6:$K13,TRUE())) | M13: =IF($L13="","","R"&$L13)
A14: =IF($C14="","",$B$3) | B14: =IFERROR(INDEX(정기주문설정!$B$3:$B$302,MATCH("R"&9,주문생성!$M$6:$M$305,0)),"") | C14: =IF($B14="","",IFERROR(INDEX(정기주문설정!$C$3:$C$302,MATCH("R"&9,주문생성!$M$6:$M$305,0)),"")) | D14: =IF($B14="","",IFERROR(INDEX(정기주문설정!$D$3:$D$302,MATCH("R"&9,주문생성!$M$6:$M$305,0)),"")) | E14: =IF($B14="","",IFERROR(INDEX(정기주문설정!$E$3:$E$302,MATCH("R"&9,주문생성!$M$6:$M$305,0)),"")) | F14: =IF($B14="","",IFERROR(INDEX(정기주문설정!$F$3:$F$302,MATCH("R"&9,주문생성!$M$6:$M$305,0)),"")) | G14: =IF($B14="","",IFERROR(INDEX(정기주문설정!$G$3:$G$302,MATCH("R"&9,주문생성!$M$6:$M$305,0)),"")) | H14: =IF($B14="","",IFERROR(INDEX(정기주문설정!$H$3:$H$302,MATCH("R"&9,주문생성!$M$6:$M$305,0)),"")) | I14: =IF($B14="","",ROUND($G14*$H14,0)) | K14: =IF(정기주문설정!$B11="",FALSE(),IF(정기주문설정!$M11="중지",FALSE(),IF(정기주문설정!$L11<>"",IF($B$3<정기주문설정!$L11,FALSE(),IF(정기주문설정!$I11="매일",TRUE(),IF(정기주문설정!$I11="매주",(WEEKDAY($B$3)=IFERROR(MATCH(정기주문설정!$J11,정기주문설정!$O$3:$O$9,0),0)),IF(정기주문설정!$I11="격주",AND((WEEKDAY($B$3)=IFERROR(MATCH(정기주문설정!$J11,정기주문설정!$O$3:$O$9,0),0)),MOD(INT(($B$3-정기주문설정!$L11)/7),2)=0),IF(정기주문설정!$I11="매월",DAY($B$3)=정기주문설정!$K11,FALSE()))))),IF(정기주문설정!$I11="매일",TRUE(),IF(정기주문설정!$I11="매주",(WEEKDAY($B$3)=IFERROR(MATCH(정기주문설정!$J11,정기주문설정!$O$3:$O$9,0),0)),IF(정기주문설정!$I11="매월",DAY($B$3)=정기주문설정!$K11,FALSE())))))) -> FALSE | L14: =IF($K14=FALSE(),"",COUNTIF($K$6:$K14,TRUE())) | M14: =IF($L14="","","R"&$L14)
A15: =IF($C15="","",$B$3) | B15: =IFERROR(INDEX(정기주문설정!$B$3:$B$302,MATCH("R"&10,주문생성!$M$6:$M$305,0)),"") | C15: =IF($B15="","",IFERROR(INDEX(정기주문설정!$C$3:$C$302,MATCH("R"&10,주문생성!$M$6:$M$305,0)),"")) | D15: =IF($B15="","",IFERROR(INDEX(정기주문설정!$D$3:$D$302,MATCH("R"&10,주문생성!$M$6:$M$305,0)),"")) | E15: =IF($B15="","",IFERROR(INDEX(정기주문설정!$E$3:$E$302,MATCH("R"&10,주문생성!$M$6:$M$305,0)),"")) | F15: =IF($B15="","",IFERROR(INDEX(정기주문설정!$F$3:$F$302,MATCH("R"&10,주문생성!$M$6:$M$305,0)),"")) | G15: =IF($B15="","",IFERROR(INDEX(정기주문설정!$G$3:$G$302,MATCH("R"&10,주문생성!$M$6:$M$305,0)),"")) | H15: =IF($B15="","",IFERROR(INDEX(정기주문설정!$H$3:$H$302,MATCH("R"&10,주문생성!$M$6:$M$305,0)),"")) | I15: =IF($B15="","",ROUND($G15*$H15,0)) | K15: =IF(정기주문설정!$B12="",FALSE(),IF(정기주문설정!$M12="중지",FALSE(),IF(정기주문설정!$L12<>"",IF($B$3<정기주문설정!$L12,FALSE(),IF(정기주문설정!$I12="매일",TRUE(),IF(정기주문설정!$I12="매주",(WEEKDAY($B$3)=IFERROR(MATCH(정기주문설정!$J12,정기주문설정!$O$3:$O$9,0),0)),IF(정기주문설정!$I12="격주",AND((WEEKDAY($B$3)=IFERROR(MATCH(정기주문설정!$J12,정기주문설정!$O$3:$O$9,0),0)),MOD(INT(($B$3-정기주문설정!$L12)/7),2)=0),IF(정기주문설정!$I12="매월",DAY($B$3)=정기주문설정!$K12,FALSE()))))),IF(정기주문설정!$I12="매일",TRUE(),IF(정기주문설정!$I12="매주",(WEEKDAY($B$3)=IFERROR(MATCH(정기주문설정!$J12,정기주문설정!$O$3:$O$9,0),0)),IF(정기주문설정!$I12="매월",DAY($B$3)=정기주문설정!$K12,FALSE())))))) -> FALSE | L15: =IF($K15=FALSE(),"",COUNTIF($K$6:$K15,TRUE())) | M15: =IF($L15="","","R"&$L15)
A16: =IF($C16="","",$B$3) | B16: =IFERROR(INDEX(정기주문설정!$B$3:$B$302,MATCH("R"&11,주문생성!$M$6:$M$305,0)),"") | C16: =IF($B16="","",IFERROR(INDEX(정기주문설정!$C$3:$C$302,MATCH("R"&11,주문생성!$M$6:$M$305,0)),"")) | D16: =IF($B16="","",IFERROR(INDEX(정기주문설정!$D$3:$D$302,MATCH("R"&11,주문생성!$M$6:$M$305,0)),"")) | E16: =IF($B16="","",IFERROR(INDEX(정기주문설정!$E$3:$E$302,MATCH("R"&11,주문생성!$M$6:$M$305,0)),"")) | F16: =IF($B16="","",IFERROR(INDEX(정기주문설정!$F$3:$F$302,MATCH("R"&11,주문생성!$M$6:$M$305,0)),"")) | G16: =IF($B16="","",IFERROR(INDEX(정기주문설정!$G$3:$G$302,MATCH("R"&11,주문생성!$M$6:$M$305,0)),"")) | H16: =IF($B16="","",IFERROR(INDEX(정기주문설정!$H$3:$H$302,MATCH("R"&11,주문생성!$M$6:$M$305,0)),"")) | I16: =IF($B16="","",ROUND($G16*$H16,0)) | K16: =IF(정기주문설정!$B13="",FALSE(),IF(정기주문설정!$M13="중지",FALSE(),IF(정기주문설정!$L13<>"",IF($B$3<정기주문설정!$L13,FALSE(),IF(정기주문설정!$I13="매일",TRUE(),IF(정기주문설정!$I13="매주",(WEEKDAY($B$3)=IFERROR(MATCH(정기주문설정!$J13,정기주문설정!$O$3:$O$9,0),0)),IF(정기주문설정!$I13="격주",AND((WEEKDAY($B$3)=IFERROR(MATCH(정기주문설정!$J13,정기주문설정!$O$3:$O$9,0),0)),MOD(INT(($B$3-정기주문설정!$L13)/7),2)=0),IF(정기주문설정!$I13="매월",DAY($B$3)=정기주문설정!$K13,FALSE()))))),IF(정기주문설정!$I13="매일",TRUE(),IF(정기주문설정!$I13="매주",(WEEKDAY($B$3)=IFERROR(MATCH(정기주문설정!$J13,정기주문설정!$O$3:$O$9,0),0)),IF(정기주문설정!$I13="매월",DAY($B$3)=정기주문설정!$K13,FALSE())))))) -> FALSE | L16: =IF($K16=FALSE(),"",COUNTIF($K$6:$K16,TRUE())) | M16: =IF($L16="","","R"&$L16)
A17: =IF($C17="","",$B$3) | B17: =IFERROR(INDEX(정기주문설정!$B$3:$B$302,MATCH("R"&12,주문생성!$M$6:$M$305,0)),"") | C17: =IF($B17="","",IFERROR(INDEX(정기주문설정!$C$3:$C$302,MATCH("R"&12,주문생성!$M$6:$M$305,0)),"")) | D17: =IF($B17="","",IFERROR(INDEX(정기주문설정!$D$3:$D$302,MATCH("R"&12,주문생성!$M$6:$M$305,0)),"")) | E17: =IF($B17="","",IFERROR(INDEX(정기주문설정!$E$3:$E$302,MATCH("R"&12,주문생성!$M$6:$M$305,0)),"")) | F17: =IF($B17="","",IFERROR(INDEX(정기주문설정!$F$3:$F$302,MATCH("R"&12,주문생성!$M$6:$M$305,0)),"")) | G17: =IF($B17="","",IFERROR(INDEX(정기주문설정!$G$3:$G$302,MATCH("R"&12,주문생성!$M$6:$M$305,0)),"")) | H17: =IF($B17="","",IFERROR(INDEX(정기주문설정!$H$3:$H$302,MATCH("R"&12,주문생성!$M$6:$M$305,0)),"")) | I17: =IF($B17="","",ROUND($G17*$H17,0)) | K17: =IF(정기주문설정!$B14="",FALSE(),IF(정기주문설정!$M14="중지",FALSE(),IF(정기주문설정!$L14<>"",IF($B$3<정기주문설정!$L14,FALSE(),IF(정기주문설정!$I14="매일",TRUE(),IF(정기주문설정!$I14="매주",(WEEKDAY($B$3)=IFERROR(MATCH(정기주문설정!$J14,정기주문설정!$O$3:$O$9,0),0)),IF(정기주문설정!$I14="격주",AND((WEEKDAY($B$3)=IFERROR(MATCH(정기주문설정!$J14,정기주문설정!$O$3:$O$9,0),0)),MOD(INT(($B$3-정기주문설정!$L14)/7),2)=0),IF(정기주문설정!$I14="매월",DAY($B$3)=정기주문설정!$K14,FALSE()))))),IF(정기주문설정!$I14="매일",TRUE(),IF(정기주문설정!$I14="매주",(WEEKDAY($B$3)=IFERROR(MATCH(정기주문설정!$J14,정기주문설정!$O$3:$O$9,0),0)),IF(정기주문설정!$I14="매월",DAY($B$3)=정기주문설정!$K14,FALSE())))))) -> FALSE | L17: =IF($K17=FALSE(),"",COUNTIF($K$6:$K17,TRUE())) | M17: =IF($L17="","","R"&$L17)
A18: =IF($C18="","",$B$3) | B18: =IFERROR(INDEX(정기주문설정!$B$3:$B$302,MATCH("R"&13,주문생성!$M$6:$M$305,0)),"") | C18: =IF($B18="","",IFERROR(INDEX(정기주문설정!$C$3:$C$302,MATCH("R"&13,주문생성!$M$6:$M$305,0)),"")) | D18: =IF($B18="","",IFERROR(INDEX(정기주문설정!$D$3:$D$302,MATCH("R"&13,주문생성!$M$6:$M$305,0)),"")) | E18: =IF($B18="","",IFERROR(INDEX(정기주문설정!$E$3:$E$302,MATCH("R"&13,주문생성!$M$6:$M$305,0)),"")) | F18: =IF($B18="","",IFERROR(INDEX(정기주문설정!$F$3:$F$302,MATCH("R"&13,주문생성!$M$6:$M$305,0)),"")) | G18: =IF($B18="","",IFERROR(INDEX(정기주문설정!$G$3:$G$302,MATCH("R"&13,주문생성!$M$6:$M$305,0)),"")) | H18: =IF($B18="","",IFERROR(INDEX(정기주문설정!$H$3:$H$302,MATCH("R"&13,주문생성!$M$6:$M$305,0)),"")) | I18: =IF($B18="","",ROUND($G18*$H18,0)) | K18: =IF(정기주문설정!$B15="",FALSE(),IF(정기주문설정!$M15="중지",FALSE(),IF(정기주문설정!$L15<>"",IF($B$3<정기주문설정!$L15,FALSE(),IF(정기주문설정!$I15="매일",TRUE(),IF(정기주문설정!$I15="매주",(WEEKDAY($B$3)=IFERROR(MATCH(정기주문설정!$J15,정기주문설정!$O$3:$O$9,0),0)),IF(정기주문설정!$I15="격주",AND((WEEKDAY($B$3)=IFERROR(MATCH(정기주문설정!$J15,정기주문설정!$O$3:$O$9,0),0)),MOD(INT(($B$3-정기주문설정!$L15)/7),2)=0),IF(정기주문설정!$I15="매월",DAY($B$3)=정기주문설정!$K15,FALSE()))))),IF(정기주문설정!$I15="매일",TRUE(),IF(정기주문설정!$I15="매주",(WEEKDAY($B$3)=IFERROR(MATCH(정기주문설정!$J15,정기주문설정!$O$3:$O$9,0),0)),IF(정기주문설정!$I15="매월",DAY($B$3)=정기주문설정!$K15,FALSE())))))) -> FALSE | L18: =IF($K18=FALSE(),"",COUNTIF($K$6:$K18,TRUE())) | M18: =IF($L18="","","R"&$L18)
A19: =IF($C19="","",$B$3) | B19: =IFERROR(INDEX(정기주문설정!$B$3:$B$302,MATCH("R"&14,주문생성!$M$6:$M$305,0)),"") | C19: =IF($B19="","",IFERROR(INDEX(정기주문설정!$C$3:$C$302,MATCH("R"&14,주문생성!$M$6:$M$305,0)),"")) | D19: =IF($B19="","",IFERROR(INDEX(정기주문설정!$D$3:$D$302,MATCH("R"&14,주문생성!$M$6:$M$305,0)),"")) | E19: =IF($B19="","",IFERROR(INDEX(정기주문설정!$E$3:$E$302,MATCH("R"&14,주문생성!$M$6:$M$305,0)),"")) | F19: =IF($B19="","",IFERROR(INDEX(정기주문설정!$F$3:$F$302,MATCH("R"&14,주문생성!$M$6:$M$305,0)),"")) | G19: =IF($B19="","",IFERROR(INDEX(정기주문설정!$G$3:$G$302,MATCH("R"&14,주문생성!$M$6:$M$305,0)),"")) | H19: =IF($B19="","",IFERROR(INDEX(정기주문설정!$H$3:$H$302,MATCH("R"&14,주문생성!$M$6:$M$305,0)),"")) | I19: =IF($B19="","",ROUND($G19*$H19,0)) | K19: =IF(정기주문설정!$B16="",FALSE(),IF(정기주문설정!$M16="중지",FALSE(),IF(정기주문설정!$L16<>"",IF($B$3<정기주문설정!$L16,FALSE(),IF(정기주문설정!$I16="매일",TRUE(),IF(정기주문설정!$I16="매주",(WEEKDAY($B$3)=IFERROR(MATCH(정기주문설정!$J16,정기주문설정!$O$3:$O$9,0),0)),IF(정기주문설정!$I16="격주",AND((WEEKDAY($B$3)=IFERROR(MATCH(정기주문설정!$J16,정기주문설정!$O$3:$O$9,0),0)),MOD(INT(($B$3-정기주문설정!$L16)/7),2)=0),IF(정기주문설정!$I16="매월",DAY($B$3)=정기주문설정!$K16,FALSE()))))),IF(정기주문설정!$I16="매일",TRUE(),IF(정기주문설정!$I16="매주",(WEEKDAY($B$3)=IFERROR(MATCH(정기주문설정!$J16,정기주문설정!$O$3:$O$9,0),0)),IF(정기주문설정!$I16="매월",DAY($B$3)=정기주문설정!$K16,FALSE())))))) -> FALSE | L19: =IF($K19=FALSE(),"",COUNTIF($K$6:$K19,TRUE())) | M19: =IF($L19="","","R"&$L19)
A20: =IF($C20="","",$B$3) | B20: =IFERROR(INDEX(정기주문설정!$B$3:$B$302,MATCH("R"&15,주문생성!$M$6:$M$305,0)),"") | C20: =IF($B20="","",IFERROR(INDEX(정기주문설정!$C$3:$C$302,MATCH("R"&15,주문생성!$M$6:$M$305,0)),"")) | D20: =IF($B20="","",IFERROR(INDEX(정기주문설정!$D$3:$D$302,MATCH("R"&15,주문생성!$M$6:$M$305,0)),"")) | E20: =IF($B20="","",IFERROR(INDEX(정기주문설정!$E$3:$E$302,MATCH("R"&15,주문생성!$M$6:$M$305,0)),"")) | F20: =IF($B20="","",IFERROR(INDEX(정기주문설정!$F$3:$F$302,MATCH("R"&15,주문생성!$M$6:$M$305,0)),"")) | G20: =IF($B20="","",IFERROR(INDEX(정기주문설정!$G$3:$G$302,MATCH("R"&15,주문생성!$M$6:$M$305,0)),"")) | H20: =IF($B20="","",IFERROR(INDEX(정기주문설정!$H$3:$H$302,MATCH("R"&15,주문생성!$M$6:$M$305,0)),"")) | I20: =IF($B20="","",ROUND($G20*$H20,0)) | K20: =IF(정기주문설정!$B17="",FALSE(),IF(정기주문설정!$M17="중지",FALSE(),IF(정기주문설정!$L17<>"",IF($B$3<정기주문설정!$L17,FALSE(),IF(정기주문설정!$I17="매일",TRUE(),IF(정기주문설정!$I17="매주",(WEEKDAY($B$3)=IFERROR(MATCH(정기주문설정!$J17,정기주문설정!$O$3:$O$9,0),0)),IF(정기주문설정!$I17="격주",AND((WEEKDAY($B$3)=IFERROR(MATCH(정기주문설정!$J17,정기주문설정!$O$3:$O$9,0),0)),MOD(INT(($B$3-정기주문설정!$L17)/7),2)=0),IF(정기주문설정!$I17="매월",DAY($B$3)=정기주문설정!$K17,FALSE()))))),IF(정기주문설정!$I17="매일",TRUE(),IF(정기주문설정!$I17="매주",(WEEKDAY($B$3)=IFERROR(MATCH(정기주문설정!$J17,정기주문설정!$O$3:$O$9,0),0)),IF(정기주문설정!$I17="매월",DAY($B$3)=정기주문설정!$K17,FALSE())))))) -> FALSE | L20: =IF($K20=FALSE(),"",COUNTIF($K$6:$K20,TRUE())) | M20: =IF($L20="","","R"&$L20)
A21: =IF($C21="","",$B$3) | B21: =IFERROR(INDEX(정기주문설정!$B$3:$B$302,MATCH("R"&16,주문생성!$M$6:$M$305,0)),"") | C21: =IF($B21="","",IFERROR(INDEX(정기주문설정!$C$3:$C$302,MATCH("R"&16,주문생성!$M$6:$M$305,0)),"")) | D21: =IF($B21="","",IFERROR(INDEX(정기주문설정!$D$3:$D$302,MATCH("R"&16,주문생성!$M$6:$M$305,0)),"")) | E21: =IF($B21="","",IFERROR(INDEX(정기주문설정!$E$3:$E$302,MATCH("R"&16,주문생성!$M$6:$M$305,0)),"")) | F21: =IF($B21="","",IFERROR(INDEX(정기주문설정!$F$3:$F$302,MATCH("R"&16,주문생성!$M$6:$M$305,0)),"")) | G21: =IF($B21="","",IFERROR(INDEX(정기주문설정!$G$3:$G$302,MATCH("R"&16,주문생성!$M$6:$M$305,0)),"")) | H21: =IF($B21="","",IFERROR(INDEX(정기주문설정!$H$3:$H$302,MATCH("R"&16,주문생성!$M$6:$M$305,0)),"")) | I21: =IF($B21="","",ROUND($G21*$H21,0)) | K21: =IF(정기주문설정!$B18="",FALSE(),IF(정기주문설정!$M18="중지",FALSE(),IF(정기주문설정!$L18<>"",IF($B$3<정기주문설정!$L18,FALSE(),IF(정기주문설정!$I18="매일",TRUE(),IF(정기주문설정!$I18="매주",(WEEKDAY($B$3)=IFERROR(MATCH(정기주문설정!$J18,정기주문설정!$O$3:$O$9,0),0)),IF(정기주문설정!$I18="격주",AND((WEEKDAY($B$3)=IFERROR(MATCH(정기주문설정!$J18,정기주문설정!$O$3:$O$9,0),0)),MOD(INT(($B$3-정기주문설정!$L18)/7),2)=0),IF(정기주문설정!$I18="매월",DAY($B$3)=정기주문설정!$K18,FALSE()))))),IF(정기주문설정!$I18="매일",TRUE(),IF(정기주문설정!$I18="매주",(WEEKDAY($B$3)=IFERROR(MATCH(정기주문설정!$J18,정기주문설정!$O$3:$O$9,0),0)),IF(정기주문설정!$I18="매월",DAY($B$3)=정기주문설정!$K18,FALSE())))))) -> FALSE | L21: =IF($K21=FALSE(),"",COUNTIF($K$6:$K21,TRUE())) | M21: =IF($L21="","","R"&$L21)
A22: =IF($C22="","",$B$3) | B22: =IFERROR(INDEX(정기주문설정!$B$3:$B$302,MATCH("R"&17,주문생성!$M$6:$M$305,0)),"") | C22: =IF($B22="","",IFERROR(INDEX(정기주문설정!$C$3:$C$302,MATCH("R"&17,주문생성!$M$6:$M$305,0)),"")) | D22: =IF($B22="","",IFERROR(INDEX(정기주문설정!$D$3:$D$302,MATCH("R"&17,주문생성!$M$6:$M$305,0)),"")) | E22: =IF($B22="","",IFERROR(INDEX(정기주문설정!$E$3:$E$302,MATCH("R"&17,주문생성!$M$6:$M$305,0)),"")) | F22: =IF($B22="","",IFERROR(INDEX(정기주문설정!$F$3:$F$302,MATCH("R"&17,주문생성!$M$6:$M$305,0)),"")) | G22: =IF($B22="","",IFERROR(INDEX(정기주문설정!$G$3:$G$302,MATCH("R"&17,주문생성!$M$6:$M$305,0)),"")) | H22: =IF($B22="","",IFERROR(INDEX(정기주문설정!$H$3:$H$302,MATCH("R"&17,주문생성!$M$6:$M$305,0)),"")) | I22: =IF($B22="","",ROUND($G22*$H22,0)) | K22: =IF(정기주문설정!$B19="",FALSE(),IF(정기주문설정!$M19="중지",FALSE(),IF(정기주문설정!$L19<>"",IF($B$3<정기주문설정!$L19,FALSE(),IF(정기주문설정!$I19="매일",TRUE(),IF(정기주문설정!$I19="매주",(WEEKDAY($B$3)=IFERROR(MATCH(정기주문설정!$J19,정기주문설정!$O$3:$O$9,0),0)),IF(정기주문설정!$I19="격주",AND((WEEKDAY($B$3)=IFERROR(MATCH(정기주문설정!$J19,정기주문설정!$O$3:$O$9,0),0)),MOD(INT(($B$3-정기주문설정!$L19)/7),2)=0),IF(정기주문설정!$I19="매월",DAY($B$3)=정기주문설정!$K19,FALSE()))))),IF(정기주문설정!$I19="매일",TRUE(),IF(정기주문설정!$I19="매주",(WEEKDAY($B$3)=IFERROR(MATCH(정기주문설정!$J19,정기주문설정!$O$3:$O$9,0),0)),IF(정기주문설정!$I19="매월",DAY($B$3)=정기주문설정!$K19,FALSE())))))) -> FALSE | L22: =IF($K22=FALSE(),"",COUNTIF($K$6:$K22,TRUE())) | M22: =IF($L22="","","R"&$L22)
A23: =IF($C23="","",$B$3) | B23: =IFERROR(INDEX(정기주문설정!$B$3:$B$302,MATCH("R"&18,주문생성!$M$6:$M$305,0)),"") | C23: =IF($B23="","",IFERROR(INDEX(정기주문설정!$C$3:$C$302,MATCH("R"&18,주문생성!$M$6:$M$305,0)),"")) | D23: =IF($B23="","",IFERROR(INDEX(정기주문설정!$D$3:$D$302,MATCH("R"&18,주문생성!$M$6:$M$305,0)),"")) | E23: =IF($B23="","",IFERROR(INDEX(정기주문설정!$E$3:$E$302,MATCH("R"&18,주문생성!$M$6:$M$305,0)),"")) | F23: =IF($B23="","",IFERROR(INDEX(정기주문설정!$F$3:$F$302,MATCH("R"&18,주문생성!$M$6:$M$305,0)),"")) | G23: =IF($B23="","",IFERROR(INDEX(정기주문설정!$G$3:$G$302,MATCH("R"&18,주문생성!$M$6:$M$305,0)),"")) | H23: =IF($B23="","",IFERROR(INDEX(정기주문설정!$H$3:$H$302,MATCH("R"&18,주문생성!$M$6:$M$305,0)),"")) | I23: =IF($B23="","",ROUND($G23*$H23,0)) | K23: =IF(정기주문설정!$B20="",FALSE(),IF(정기주문설정!$M20="중지",FALSE(),IF(정기주문설정!$L20<>"",IF($B$3<정기주문설정!$L20,FALSE(),IF(정기주문설정!$I20="매일",TRUE(),IF(정기주문설정!$I20="매주",(WEEKDAY($B$3)=IFERROR(MATCH(정기주문설정!$J20,정기주문설정!$O$3:$O$9,0),0)),IF(정기주문설정!$I20="격주",AND((WEEKDAY($B$3)=IFERROR(MATCH(정기주문설정!$J20,정기주문설정!$O$3:$O$9,0),0)),MOD(INT(($B$3-정기주문설정!$L20)/7),2)=0),IF(정기주문설정!$I20="매월",DAY($B$3)=정기주문설정!$K20,FALSE()))))),IF(정기주문설정!$I20="매일",TRUE(),IF(정기주문설정!$I20="매주",(WEEKDAY($B$3)=IFERROR(MATCH(정기주문설정!$J20,정기주문설정!$O$3:$O$9,0),0)),IF(정기주문설정!$I20="매월",DAY($B$3)=정기주문설정!$K20,FALSE())))))) -> FALSE | L23: =IF($K23=FALSE(),"",COUNTIF($K$6:$K23,TRUE())) | M23: =IF($L23="","","R"&$L23)
A24: =IF($C24="","",$B$3) | B24: =IFERROR(INDEX(정기주문설정!$B$3:$B$302,MATCH("R"&19,주문생성!$M$6:$M$305,0)),"") | C24: =IF($B24="","",IFERROR(INDEX(정기주문설정!$C$3:$C$302,MATCH("R"&19,주문생성!$M$6:$M$305,0)),"")) | D24: =IF($B24="","",IFERROR(INDEX(정기주문설정!$D$3:$D$302,MATCH("R"&19,주문생성!$M$6:$M$305,0)),"")) | E24: =IF($B24="","",IFERROR(INDEX(정기주문설정!$E$3:$E$302,MATCH("R"&19,주문생성!$M$6:$M$305,0)),"")) | F24: =IF($B24="","",IFERROR(INDEX(정기주문설정!$F$3:$F$302,MATCH("R"&19,주문생성!$M$6:$M$305,0)),"")) | G24: =IF($B24="","",IFERROR(INDEX(정기주문설정!$G$3:$G$302,MATCH("R"&19,주문생성!$M$6:$M$305,0)),"")) | H24: =IF($B24="","",IFERROR(INDEX(정기주문설정!$H$3:$H$302,MATCH("R"&19,주문생성!$M$6:$M$305,0)),"")) | I24: =IF($B24="","",ROUND($G24*$H24,0)) | K24: =IF(정기주문설정!$B21="",FALSE(),IF(정기주문설정!$M21="중지",FALSE(),IF(정기주문설정!$L21<>"",IF($B$3<정기주문설정!$L21,FALSE(),IF(정기주문설정!$I21="매일",TRUE(),IF(정기주문설정!$I21="매주",(WEEKDAY($B$3)=IFERROR(MATCH(정기주문설정!$J21,정기주문설정!$O$3:$O$9,0),0)),IF(정기주문설정!$I21="격주",AND((WEEKDAY($B$3)=IFERROR(MATCH(정기주문설정!$J21,정기주문설정!$O$3:$O$9,0),0)),MOD(INT(($B$3-정기주문설정!$L21)/7),2)=0),IF(정기주문설정!$I21="매월",DAY($B$3)=정기주문설정!$K21,FALSE()))))),IF(정기주문설정!$I21="매일",TRUE(),IF(정기주문설정!$I21="매주",(WEEKDAY($B$3)=IFERROR(MATCH(정기주문설정!$J21,정기주문설정!$O$3:$O$9,0),0)),IF(정기주문설정!$I21="매월",DAY($B$3)=정기주문설정!$K21,FALSE())))))) -> FALSE | L24: =IF($K24=FALSE(),"",COUNTIF($K$6:$K24,TRUE())) | M24: =IF($L24="","","R"&$L24)
A25: =IF($C25="","",$B$3) | B25: =IFERROR(INDEX(정기주문설정!$B$3:$B$302,MATCH("R"&20,주문생성!$M$6:$M$305,0)),"") | C25: =IF($B25="","",IFERROR(INDEX(정기주문설정!$C$3:$C$302,MATCH("R"&20,주문생성!$M$6:$M$305,0)),"")) | D25: =IF($B25="","",IFERROR(INDEX(정기주문설정!$D$3:$D$302,MATCH("R"&20,주문생성!$M$6:$M$305,0)),"")) | E25: =IF($B25="","",IFERROR(INDEX(정기주문설정!$E$3:$E$302,MATCH("R"&20,주문생성!$M$6:$M$305,0)),"")) | F25: =IF($B25="","",IFERROR(INDEX(정기주문설정!$F$3:$F$302,MATCH("R"&20,주문생성!$M$6:$M$305,0)),"")) | G25: =IF($B25="","",IFERROR(INDEX(정기주문설정!$G$3:$G$302,MATCH("R"&20,주문생성!$M$6:$M$305,0)),"")) | H25: =IF($B25="","",IFERROR(INDEX(정기주문설정!$H$3:$H$302,MATCH("R"&20,주문생성!$M$6:$M$305,0)),"")) | I25: =IF($B25="","",ROUND($G25*$H25,0)) | K25: =IF(정기주문설정!$B22="",FALSE(),IF(정기주문설정!$M22="중지",FALSE(),IF(정기주문설정!$L22<>"",IF($B$3<정기주문설정!$L22,FALSE(),IF(정기주문설정!$I22="매일",TRUE(),IF(정기주문설정!$I22="매주",(WEEKDAY($B$3)=IFERROR(MATCH(정기주문설정!$J22,정기주문설정!$O$3:$O$9,0),0)),IF(정기주문설정!$I22="격주",AND((WEEKDAY($B$3)=IFERROR(MATCH(정기주문설정!$J22,정기주문설정!$O$3:$O$9,0),0)),MOD(INT(($B$3-정기주문설정!$L22)/7),2)=0),IF(정기주문설정!$I22="매월",DAY($B$3)=정기주문설정!$K22,FALSE()))))),IF(정기주문설정!$I22="매일",TRUE(),IF(정기주문설정!$I22="매주",(WEEKDAY($B$3)=IFERROR(MATCH(정기주문설정!$J22,정기주문설정!$O$3:$O$9,0),0)),IF(정기주문설정!$I22="매월",DAY($B$3)=정기주문설정!$K22,FALSE())))))) -> FALSE | L25: =IF($K25=FALSE(),"",COUNTIF($K$6:$K25,TRUE())) | M25: =IF($L25="","","R"&$L25)
A26: =IF($C26="","",$B$3) | B26: =IFERROR(INDEX(정기주문설정!$B$3:$B$302,MATCH("R"&21,주문생성!$M$6:$M$305,0)),"") | C26: =IF($B26="","",IFERROR(INDEX(정기주문설정!$C$3:$C$302,MATCH("R"&21,주문생성!$M$6:$M$305,0)),"")) | D26: =IF($B26="","",IFERROR(INDEX(정기주문설정!$D$3:$D$302,MATCH("R"&21,주문생성!$M$6:$M$305,0)),"")) | E26: =IF($B26="","",IFERROR(INDEX(정기주문설정!$E$3:$E$302,MATCH("R"&21,주문생성!$M$6:$M$305,0)),"")) | F26: =IF($B26="","",IFERROR(INDEX(정기주문설정!$F$3:$F$302,MATCH("R"&21,주문생성!$M$6:$M$305,0)),"")) | G26: =IF($B26="","",IFERROR(INDEX(정기주문설정!$G$3:$G$302,MATCH("R"&21,주문생성!$M$6:$M$305,0)),"")) | H26: =IF($B26="","",IFERROR(INDEX(정기주문설정!$H$3:$H$302,MATCH("R"&21,주문생성!$M$6:$M$305,0)),"")) | I26: =IF($B26="","",ROUND($G26*$H26,0)) | K26: =IF(정기주문설정!$B23="",FALSE(),IF(정기주문설정!$M23="중지",FALSE(),IF(정기주문설정!$L23<>"",IF($B$3<정기주문설정!$L23,FALSE(),IF(정기주문설정!$I23="매일",TRUE(),IF(정기주문설정!$I23="매주",(WEEKDAY($B$3)=IFERROR(MATCH(정기주문설정!$J23,정기주문설정!$O$3:$O$9,0),0)),IF(정기주문설정!$I23="격주",AND((WEEKDAY($B$3)=IFERROR(MATCH(정기주문설정!$J23,정기주문설정!$O$3:$O$9,0),0)),MOD(INT(($B$3-정기주문설정!$L23)/7),2)=0),IF(정기주문설정!$I23="매월",DAY($B$3)=정기주문설정!$K23,FALSE()))))),IF(정기주문설정!$I23="매일",TRUE(),IF(정기주문설정!$I23="매주",(WEEKDAY($B$3)=IFERROR(MATCH(정기주문설정!$J23,정기주문설정!$O$3:$O$9,0),0)),IF(정기주문설정!$I23="매월",DAY($B$3)=정기주문설정!$K23,FALSE())))))) -> FALSE | L26: =IF($K26=FALSE(),"",COUNTIF($K$6:$K26,TRUE())) | M26: =IF($L26="","","R"&$L26)
A27: =IF($C27="","",$B$3) | B27: =IFERROR(INDEX(정기주문설정!$B$3:$B$302,MATCH("R"&22,주문생성!$M$6:$M$305,0)),"") | C27: =IF($B27="","",IFERROR(INDEX(정기주문설정!$C$3:$C$302,MATCH("R"&22,주문생성!$M$6:$M$305,0)),"")) | D27: =IF($B27="","",IFERROR(INDEX(정기주문설정!$D$3:$D$302,MATCH("R"&22,주문생성!$M$6:$M$305,0)),"")) | E27: =IF($B27="","",IFERROR(INDEX(정기주문설정!$E$3:$E$302,MATCH("R"&22,주문생성!$M$6:$M$305,0)),"")) | F27: =IF($B27="","",IFERROR(INDEX(정기주문설정!$F$3:$F$302,MATCH("R"&22,주문생성!$M$6:$M$305,0)),"")) | G27: =IF($B27="","",IFERROR(INDEX(정기주문설정!$G$3:$G$302,MATCH("R"&22,주문생성!$M$6:$M$305,0)),"")) | H27: =IF($B27="","",IFERROR(INDEX(정기주문설정!$H$3:$H$302,MATCH("R"&22,주문생성!$M$6:$M$305,0)),"")) | I27: =IF($B27="","",ROUND($G27*$H27,0)) | K27: =IF(정기주문설정!$B24="",FALSE(),IF(정기주문설정!$M24="중지",FALSE(),IF(정기주문설정!$L24<>"",IF($B$3<정기주문설정!$L24,FALSE(),IF(정기주문설정!$I24="매일",TRUE(),IF(정기주문설정!$I24="매주",(WEEKDAY($B$3)=IFERROR(MATCH(정기주문설정!$J24,정기주문설정!$O$3:$O$9,0),0)),IF(정기주문설정!$I24="격주",AND((WEEKDAY($B$3)=IFERROR(MATCH(정기주문설정!$J24,정기주문설정!$O$3:$O$9,0),0)),MOD(INT(($B$3-정기주문설정!$L24)/7),2)=0),IF(정기주문설정!$I24="매월",DAY($B$3)=정기주문설정!$K24,FALSE()))))),IF(정기주문설정!$I24="매일",TRUE(),IF(정기주문설정!$I24="매주",(WEEKDAY($B$3)=IFERROR(MATCH(정기주문설정!$J24,정기주문설정!$O$3:$O$9,0),0)),IF(정기주문설정!$I24="매월",DAY($B$3)=정기주문설정!$K24,FALSE())))))) -> FALSE | L27: =IF($K27=FALSE(),"",COUNTIF($K$6:$K27,TRUE())) | M27: =IF($L27="","","R"&$L27)
A28: =IF($C28="","",$B$3) | B28: =IFERROR(INDEX(정기주문설정!$B$3:$B$302,MATCH("R"&23,주문생성!$M$6:$M$305,0)),"") | C28: =IF($B28="","",IFERROR(INDEX(정기주문설정!$C$3:$C$302,MATCH("R"&23,주문생성!$M$6:$M$305,0)),"")) | D28: =IF($B28="","",IFERROR(INDEX(정기주문설정!$D$3:$D$302,MATCH("R"&23,주문생성!$M$6:$M$305,0)),"")) | E28: =IF($B28="","",IFERROR(INDEX(정기주문설정!$E$3:$E$302,MATCH("R"&23,주문생성!$M$6:$M$305,0)),"")) | F28: =IF($B28="","",IFERROR(INDEX(정기주문설정!$F$3:$F$302,MATCH("R"&23,주문생성!$M$6:$M$305,0)),"")) | G28: =IF($B28="","",IFERROR(INDEX(정기주문설정!$G$3:$G$302,MATCH("R"&23,주문생성!$M$6:$M$305,0)),"")) | H28: =IF($B28="","",IFERROR(INDEX(정기주문설정!$H$3:$H$302,MATCH("R"&23,주문생성!$M$6:$M$305,0)),"")) | I28: =IF($B28="","",ROUND($G28*$H28,0)) | K28: =IF(정기주문설정!$B25="",FALSE(),IF(정기주문설정!$M25="중지",FALSE(),IF(정기주문설정!$L25<>"",IF($B$3<정기주문설정!$L25,FALSE(),IF(정기주문설정!$I25="매일",TRUE(),IF(정기주문설정!$I25="매주",(WEEKDAY($B$3)=IFERROR(MATCH(정기주문설정!$J25,정기주문설정!$O$3:$O$9,0),0)),IF(정기주문설정!$I25="격주",AND((WEEKDAY($B$3)=IFERROR(MATCH(정기주문설정!$J25,정기주문설정!$O$3:$O$9,0),0)),MOD(INT(($B$3-정기주문설정!$L25)/7),2)=0),IF(정기주문설정!$I25="매월",DAY($B$3)=정기주문설정!$K25,FALSE()))))),IF(정기주문설정!$I25="매일",TRUE(),IF(정기주문설정!$I25="매주",(WEEKDAY($B$3)=IFERROR(MATCH(정기주문설정!$J25,정기주문설정!$O$3:$O$9,0),0)),IF(정기주문설정!$I25="매월",DAY($B$3)=정기주문설정!$K25,FALSE())))))) -> FALSE | L28: =IF($K28=FALSE(),"",COUNTIF($K$6:$K28,TRUE())) | M28: =IF($L28="","","R"&$L28)
A29: =IF($C29="","",$B$3) | B29: =IFERROR(INDEX(정기주문설정!$B$3:$B$302,MATCH("R"&24,주문생성!$M$6:$M$305,0)),"") | C29: =IF($B29="","",IFERROR(INDEX(정기주문설정!$C$3:$C$302,MATCH("R"&24,주문생성!$M$6:$M$305,0)),"")) | D29: =IF($B29="","",IFERROR(INDEX(정기주문설정!$D$3:$D$302,MATCH("R"&24,주문생성!$M$6:$M$305,0)),"")) | E29: =IF($B29="","",IFERROR(INDEX(정기주문설정!$E$3:$E$302,MATCH("R"&24,주문생성!$M$6:$M$305,0)),"")) | F29: =IF($B29="","",IFERROR(INDEX(정기주문설정!$F$3:$F$302,MATCH("R"&24,주문생성!$M$6:$M$305,0)),"")) | G29: =IF($B29="","",IFERROR(INDEX(정기주문설정!$G$3:$G$302,MATCH("R"&24,주문생성!$M$6:$M$305,0)),"")) | H29: =IF($B29="","",IFERROR(INDEX(정기주문설정!$H$3:$H$302,MATCH("R"&24,주문생성!$M$6:$M$305,0)),"")) | I29: =IF($B29="","",ROUND($G29*$H29,0)) | K29: =IF(정기주문설정!$B26="",FALSE(),IF(정기주문설정!$M26="중지",FALSE(),IF(정기주문설정!$L26<>"",IF($B$3<정기주문설정!$L26,FALSE(),IF(정기주문설정!$I26="매일",TRUE(),IF(정기주문설정!$I26="매주",(WEEKDAY($B$3)=IFERROR(MATCH(정기주문설정!$J26,정기주문설정!$O$3:$O$9,0),0)),IF(정기주문설정!$I26="격주",AND((WEEKDAY($B$3)=IFERROR(MATCH(정기주문설정!$J26,정기주문설정!$O$3:$O$9,0),0)),MOD(INT(($B$3-정기주문설정!$L26)/7),2)=0),IF(정기주문설정!$I26="매월",DAY($B$3)=정기주문설정!$K26,FALSE()))))),IF(정기주문설정!$I26="매일",TRUE(),IF(정기주문설정!$I26="매주",(WEEKDAY($B$3)=IFERROR(MATCH(정기주문설정!$J26,정기주문설정!$O$3:$O$9,0),0)),IF(정기주문설정!$I26="매월",DAY($B$3)=정기주문설정!$K26,FALSE())))))) -> FALSE | L29: =IF($K29=FALSE(),"",COUNTIF($K$6:$K29,TRUE())) | M29: =IF($L29="","","R"&$L29)
A30: =IF($C30="","",$B$3) | B30: =IFERROR(INDEX(정기주문설정!$B$3:$B$302,MATCH("R"&25,주문생성!$M$6:$M$305,0)),"") | C30: =IF($B30="","",IFERROR(INDEX(정기주문설정!$C$3:$C$302,MATCH("R"&25,주문생성!$M$6:$M$305,0)),"")) | D30: =IF($B30="","",IFERROR(INDEX(정기주문설정!$D$3:$D$302,MATCH("R"&25,주문생성!$M$6:$M$305,0)),"")) | E30: =IF($B30="","",IFERROR(INDEX(정기주문설정!$E$3:$E$302,MATCH("R"&25,주문생성!$M$6:$M$305,0)),"")) | F30: =IF($B30="","",IFERROR(INDEX(정기주문설정!$F$3:$F$302,MATCH("R"&25,주문생성!$M$6:$M$305,0)),"")) | G30: =IF($B30="","",IFERROR(INDEX(정기주문설정!$G$3:$G$302,MATCH("R"&25,주문생성!$M$6:$M$305,0)),"")) | H30: =IF($B30="","",IFERROR(INDEX(정기주문설정!$H$3:$H$302,MATCH("R"&25,주문생성!$M$6:$M$305,0)),"")) | I30: =IF($B30="","",ROUND($G30*$H30,0)) | K30: =IF(정기주문설정!$B27="",FALSE(),IF(정기주문설정!$M27="중지",FALSE(),IF(정기주문설정!$L27<>"",IF($B$3<정기주문설정!$L27,FALSE(),IF(정기주문설정!$I27="매일",TRUE(),IF(정기주문설정!$I27="매주",(WEEKDAY($B$3)=IFERROR(MATCH(정기주문설정!$J27,정기주문설정!$O$3:$O$9,0),0)),IF(정기주문설정!$I27="격주",AND((WEEKDAY($B$3)=IFERROR(MATCH(정기주문설정!$J27,정기주문설정!$O$3:$O$9,0),0)),MOD(INT(($B$3-정기주문설정!$L27)/7),2)=0),IF(정기주문설정!$I27="매월",DAY($B$3)=정기주문설정!$K27,FALSE()))))),IF(정기주문설정!$I27="매일",TRUE(),IF(정기주문설정!$I27="매주",(WEEKDAY($B$3)=IFERROR(MATCH(정기주문설정!$J27,정기주문설정!$O$3:$O$9,0),0)),IF(정기주문설정!$I27="매월",DAY($B$3)=정기주문설정!$K27,FALSE())))))) -> FALSE | L30: =IF($K30=FALSE(),"",COUNTIF($K$6:$K30,TRUE())) | M30: =IF($L30="","","R"&$L30)
A31: =IF($C31="","",$B$3) | B31: =IFERROR(INDEX(정기주문설정!$B$3:$B$302,MATCH("R"&26,주문생성!$M$6:$M$305,0)),"") | C31: =IF($B31="","",IFERROR(INDEX(정기주문설정!$C$3:$C$302,MATCH("R"&26,주문생성!$M$6:$M$305,0)),"")) | D31: =IF($B31="","",IFERROR(INDEX(정기주문설정!$D$3:$D$302,MATCH("R"&26,주문생성!$M$6:$M$305,0)),"")) | E31: =IF($B31="","",IFERROR(INDEX(정기주문설정!$E$3:$E$302,MATCH("R"&26,주문생성!$M$6:$M$305,0)),"")) | F31: =IF($B31="","",IFERROR(INDEX(정기주문설정!$F$3:$F$302,MATCH("R"&26,주문생성!$M$6:$M$305,0)),"")) | G31: =IF($B31="","",IFERROR(INDEX(정기주문설정!$G$3:$G$302,MATCH("R"&26,주문생성!$M$6:$M$305,0)),"")) | H31: =IF($B31="","",IFERROR(INDEX(정기주문설정!$H$3:$H$302,MATCH("R"&26,주문생성!$M$6:$M$305,0)),"")) | I31: =IF($B31="","",ROUND($G31*$H31,0)) | K31: =IF(정기주문설정!$B28="",FALSE(),IF(정기주문설정!$M28="중지",FALSE(),IF(정기주문설정!$L28<>"",IF($B$3<정기주문설정!$L28,FALSE(),IF(정기주문설정!$I28="매일",TRUE(),IF(정기주문설정!$I28="매주",(WEEKDAY($B$3)=IFERROR(MATCH(정기주문설정!$J28,정기주문설정!$O$3:$O$9,0),0)),IF(정기주문설정!$I28="격주",AND((WEEKDAY($B$3)=IFERROR(MATCH(정기주문설정!$J28,정기주문설정!$O$3:$O$9,0),0)),MOD(INT(($B$3-정기주문설정!$L28)/7),2)=0),IF(정기주문설정!$I28="매월",DAY($B$3)=정기주문설정!$K28,FALSE()))))),IF(정기주문설정!$I28="매일",TRUE(),IF(정기주문설정!$I28="매주",(WEEKDAY($B$3)=IFERROR(MATCH(정기주문설정!$J28,정기주문설정!$O$3:$O$9,0),0)),IF(정기주문설정!$I28="매월",DAY($B$3)=정기주문설정!$K28,FALSE())))))) -> FALSE | L31: =IF($K31=FALSE(),"",COUNTIF($K$6:$K31,TRUE())) | M31: =IF($L31="","","R"&$L31)
A32: =IF($C32="","",$B$3) | B32: =IFERROR(INDEX(정기주문설정!$B$3:$B$302,MATCH("R"&27,주문생성!$M$6:$M$305,0)),"") | C32: =IF($B32="","",IFERROR(INDEX(정기주문설정!$C$3:$C$302,MATCH("R"&27,주문생성!$M$6:$M$305,0)),"")) | D32: =IF($B32="","",IFERROR(INDEX(정기주문설정!$D$3:$D$302,MATCH("R"&27,주문생성!$M$6:$M$305,0)),"")) | E32: =IF($B32="","",IFERROR(INDEX(정기주문설정!$E$3:$E$302,MATCH("R"&27,주문생성!$M$6:$M$305,0)),"")) | F32: =IF($B32="","",IFERROR(INDEX(정기주문설정!$F$3:$F$302,MATCH("R"&27,주문생성!$M$6:$M$305,0)),"")) | G32: =IF($B32="","",IFERROR(INDEX(정기주문설정!$G$3:$G$302,MATCH("R"&27,주문생성!$M$6:$M$305,0)),"")) | H32: =IF($B32="","",IFERROR(INDEX(정기주문설정!$H$3:$H$302,MATCH("R"&27,주문생성!$M$6:$M$305,0)),"")) | I32: =IF($B32="","",ROUND($G32*$H32,0)) | K32: =IF(정기주문설정!$B29="",FALSE(),IF(정기주문설정!$M29="중지",FALSE(),IF(정기주문설정!$L29<>"",IF($B$3<정기주문설정!$L29,FALSE(),IF(정기주문설정!$I29="매일",TRUE(),IF(정기주문설정!$I29="매주",(WEEKDAY($B$3)=IFERROR(MATCH(정기주문설정!$J29,정기주문설정!$O$3:$O$9,0),0)),IF(정기주문설정!$I29="격주",AND((WEEKDAY($B$3)=IFERROR(MATCH(정기주문설정!$J29,정기주문설정!$O$3:$O$9,0),0)),MOD(INT(($B$3-정기주문설정!$L29)/7),2)=0),IF(정기주문설정!$I29="매월",DAY($B$3)=정기주문설정!$K29,FALSE()))))),IF(정기주문설정!$I29="매일",TRUE(),IF(정기주문설정!$I29="매주",(WEEKDAY($B$3)=IFERROR(MATCH(정기주문설정!$J29,정기주문설정!$O$3:$O$9,0),0)),IF(정기주문설정!$I29="매월",DAY($B$3)=정기주문설정!$K29,FALSE())))))) -> FALSE | L32: =IF($K32=FALSE(),"",COUNTIF($K$6:$K32,TRUE())) | M32: =IF($L32="","","R"&$L32)
A33: =IF($C33="","",$B$3) | B33: =IFERROR(INDEX(정기주문설정!$B$3:$B$302,MATCH("R"&28,주문생성!$M$6:$M$305,0)),"") | C33: =IF($B33="","",IFERROR(INDEX(정기주문설정!$C$3:$C$302,MATCH("R"&28,주문생성!$M$6:$M$305,0)),"")) | D33: =IF($B33="","",IFERROR(INDEX(정기주문설정!$D$3:$D$302,MATCH("R"&28,주문생성!$M$6:$M$305,0)),"")) | E33: =IF($B33="","",IFERROR(INDEX(정기주문설정!$E$3:$E$302,MATCH("R"&28,주문생성!$M$6:$M$305,0)),"")) | F33: =IF($B33="","",IFERROR(INDEX(정기주문설정!$F$3:$F$302,MATCH("R"&28,주문생성!$M$6:$M$305,0)),"")) | G33: =IF($B33="","",IFERROR(INDEX(정기주문설정!$G$3:$G$302,MATCH("R"&28,주문생성!$M$6:$M$305,0)),"")) | H33: =IF($B33="","",IFERROR(INDEX(정기주문설정!$H$3:$H$302,MATCH("R"&28,주문생성!$M$6:$M$305,0)),"")) | I33: =IF($B33="","",ROUND($G33*$H33,0)) | K33: =IF(정기주문설정!$B30="",FALSE(),IF(정기주문설정!$M30="중지",FALSE(),IF(정기주문설정!$L30<>"",IF($B$3<정기주문설정!$L30,FALSE(),IF(정기주문설정!$I30="매일",TRUE(),IF(정기주문설정!$I30="매주",(WEEKDAY($B$3)=IFERROR(MATCH(정기주문설정!$J30,정기주문설정!$O$3:$O$9,0),0)),IF(정기주문설정!$I30="격주",AND((WEEKDAY($B$3)=IFERROR(MATCH(정기주문설정!$J30,정기주문설정!$O$3:$O$9,0),0)),MOD(INT(($B$3-정기주문설정!$L30)/7),2)=0),IF(정기주문설정!$I30="매월",DAY($B$3)=정기주문설정!$K30,FALSE()))))),IF(정기주문설정!$I30="매일",TRUE(),IF(정기주문설정!$I30="매주",(WEEKDAY($B$3)=IFERROR(MATCH(정기주문설정!$J30,정기주문설정!$O$3:$O$9,0),0)),IF(정기주문설정!$I30="매월",DAY($B$3)=정기주문설정!$K30,FALSE())))))) -> FALSE | L33: =IF($K33=FALSE(),"",COUNTIF($K$6:$K33,TRUE())) | M33: =IF($L33="","","R"&$L33)
A34: =IF($C34="","",$B$3) | B34: =IFERROR(INDEX(정기주문설정!$B$3:$B$302,MATCH("R"&29,주문생성!$M$6:$M$305,0)),"") | C34: =IF($B34="","",IFERROR(INDEX(정기주문설정!$C$3:$C$302,MATCH("R"&29,주문생성!$M$6:$M$305,0)),"")) | D34: =IF($B34="","",IFERROR(INDEX(정기주문설정!$D$3:$D$302,MATCH("R"&29,주문생성!$M$6:$M$305,0)),"")) | E34: =IF($B34="","",IFERROR(INDEX(정기주문설정!$E$3:$E$302,MATCH("R"&29,주문생성!$M$6:$M$305,0)),"")) | F34: =IF($B34="","",IFERROR(INDEX(정기주문설정!$F$3:$F$302,MATCH("R"&29,주문생성!$M$6:$M$305,0)),"")) | G34: =IF($B34="","",IFERROR(INDEX(정기주문설정!$G$3:$G$302,MATCH("R"&29,주문생성!$M$6:$M$305,0)),"")) | H34: =IF($B34="","",IFERROR(INDEX(정기주문설정!$H$3:$H$302,MATCH("R"&29,주문생성!$M$6:$M$305,0)),"")) | I34: =IF($B34="","",ROUND($G34*$H34,0)) | K34: =IF(정기주문설정!$B31="",FALSE(),IF(정기주문설정!$M31="중지",FALSE(),IF(정기주문설정!$L31<>"",IF($B$3<정기주문설정!$L31,FALSE(),IF(정기주문설정!$I31="매일",TRUE(),IF(정기주문설정!$I31="매주",(WEEKDAY($B$3)=IFERROR(MATCH(정기주문설정!$J31,정기주문설정!$O$3:$O$9,0),0)),IF(정기주문설정!$I31="격주",AND((WEEKDAY($B$3)=IFERROR(MATCH(정기주문설정!$J31,정기주문설정!$O$3:$O$9,0),0)),MOD(INT(($B$3-정기주문설정!$L31)/7),2)=0),IF(정기주문설정!$I31="매월",DAY($B$3)=정기주문설정!$K31,FALSE()))))),IF(정기주문설정!$I31="매일",TRUE(),IF(정기주문설정!$I31="매주",(WEEKDAY($B$3)=IFERROR(MATCH(정기주문설정!$J31,정기주문설정!$O$3:$O$9,0),0)),IF(정기주문설정!$I31="매월",DAY($B$3)=정기주문설정!$K31,FALSE())))))) -> FALSE | L34: =IF($K34=FALSE(),"",COUNTIF($K$6:$K34,TRUE())) | M34: =IF($L34="","","R"&$L34)
A35: =IF($C35="","",$B$3) | B35: =IFERROR(INDEX(정기주문설정!$B$3:$B$302,MATCH("R"&30,주문생성!$M$6:$M$305,0)),"") | C35: =IF($B35="","",IFERROR(INDEX(정기주문설정!$C$3:$C$302,MATCH("R"&30,주문생성!$M$6:$M$305,0)),"")) | D35: =IF($B35="","",IFERROR(INDEX(정기주문설정!$D$3:$D$302,MATCH("R"&30,주문생성!$M$6:$M$305,0)),"")) | E35: =IF($B35="","",IFERROR(INDEX(정기주문설정!$E$3:$E$302,MATCH("R"&30,주문생성!$M$6:$M$305,0)),"")) | F35: =IF($B35="","",IFERROR(INDEX(정기주문설정!$F$3:$F$302,MATCH("R"&30,주문생성!$M$6:$M$305,0)),"")) | G35: =IF($B35="","",IFERROR(INDEX(정기주문설정!$G$3:$G$302,MATCH("R"&30,주문생성!$M$6:$M$305,0)),"")) | H35: =IF($B35="","",IFERROR(INDEX(정기주문설정!$H$3:$H$302,MATCH("R"&30,주문생성!$M$6:$M$305,0)),"")) | I35: =IF($B35="","",ROUND($G35*$H35,0)) | K35: =IF(정기주문설정!$B32="",FALSE(),IF(정기주문설정!$M32="중지",FALSE(),IF(정기주문설정!$L32<>"",IF($B$3<정기주문설정!$L32,FALSE(),IF(정기주문설정!$I32="매일",TRUE(),IF(정기주문설정!$I32="매주",(WEEKDAY($B$3)=IFERROR(MATCH(정기주문설정!$J32,정기주문설정!$O$3:$O$9,0),0)),IF(정기주문설정!$I32="격주",AND((WEEKDAY($B$3)=IFERROR(MATCH(정기주문설정!$J32,정기주문설정!$O$3:$O$9,0),0)),MOD(INT(($B$3-정기주문설정!$L32)/7),2)=0),IF(정기주문설정!$I32="매월",DAY($B$3)=정기주문설정!$K32,FALSE()))))),IF(정기주문설정!$I32="매일",TRUE(),IF(정기주문설정!$I32="매주",(WEEKDAY($B$3)=IFERROR(MATCH(정기주문설정!$J32,정기주문설정!$O$3:$O$9,0),0)),IF(정기주문설정!$I32="매월",DAY($B$3)=정기주문설정!$K32,FALSE())))))) -> FALSE | L35: =IF($K35=FALSE(),"",COUNTIF($K$6:$K35,TRUE())) | M35: =IF($L35="","","R"&$L35)
A36: =IF($C36="","",$B$3) | B36: =IFERROR(INDEX(정기주문설정!$B$3:$B$302,MATCH("R"&31,주문생성!$M$6:$M$305,0)),"") | C36: =IF($B36="","",IFERROR(INDEX(정기주문설정!$C$3:$C$302,MATCH("R"&31,주문생성!$M$6:$M$305,0)),"")) | D36: =IF($B36="","",IFERROR(INDEX(정기주문설정!$D$3:$D$302,MATCH("R"&31,주문생성!$M$6:$M$305,0)),"")) | E36: =IF($B36="","",IFERROR(INDEX(정기주문설정!$E$3:$E$302,MATCH("R"&31,주문생성!$M$6:$M$305,0)),"")) | F36: =IF($B36="","",IFERROR(INDEX(정기주문설정!$F$3:$F$302,MATCH("R"&31,주문생성!$M$6:$M$305,0)),"")) | G36: =IF($B36="","",IFERROR(INDEX(정기주문설정!$G$3:$G$302,MATCH("R"&31,주문생성!$M$6:$M$305,0)),"")) | H36: =IF($B36="","",IFERROR(INDEX(정기주문설정!$H$3:$H$302,MATCH("R"&31,주문생성!$M$6:$M$305,0)),"")) | I36: =IF($B36="","",ROUND($G36*$H36,0)) | K36: =IF(정기주문설정!$B33="",FALSE(),IF(정기주문설정!$M33="중지",FALSE(),IF(정기주문설정!$L33<>"",IF($B$3<정기주문설정!$L33,FALSE(),IF(정기주문설정!$I33="매일",TRUE(),IF(정기주문설정!$I33="매주",(WEEKDAY($B$3)=IFERROR(MATCH(정기주문설정!$J33,정기주문설정!$O$3:$O$9,0),0)),IF(정기주문설정!$I33="격주",AND((WEEKDAY($B$3)=IFERROR(MATCH(정기주문설정!$J33,정기주문설정!$O$3:$O$9,0),0)),MOD(INT(($B$3-정기주문설정!$L33)/7),2)=0),IF(정기주문설정!$I33="매월",DAY($B$3)=정기주문설정!$K33,FALSE()))))),IF(정기주문설정!$I33="매일",TRUE(),IF(정기주문설정!$I33="매주",(WEEKDAY($B$3)=IFERROR(MATCH(정기주문설정!$J33,정기주문설정!$O$3:$O$9,0),0)),IF(정기주문설정!$I33="매월",DAY($B$3)=정기주문설정!$K33,FALSE())))))) -> FALSE | L36: =IF($K36=FALSE(),"",COUNTIF($K$6:$K36,TRUE())) | M36: =IF($L36="","","R"&$L36)
A37: =IF($C37="","",$B$3) | B37: =IFERROR(INDEX(정기주문설정!$B$3:$B$302,MATCH("R"&32,주문생성!$M$6:$M$305,0)),"") | C37: =IF($B37="","",IFERROR(INDEX(정기주문설정!$C$3:$C$302,MATCH("R"&32,주문생성!$M$6:$M$305,0)),"")) | D37: =IF($B37="","",IFERROR(INDEX(정기주문설정!$D$3:$D$302,MATCH("R"&32,주문생성!$M$6:$M$305,0)),"")) | E37: =IF($B37="","",IFERROR(INDEX(정기주문설정!$E$3:$E$302,MATCH("R"&32,주문생성!$M$6:$M$305,0)),"")) | F37: =IF($B37="","",IFERROR(INDEX(정기주문설정!$F$3:$F$302,MATCH("R"&32,주문생성!$M$6:$M$305,0)),"")) | G37: =IF($B37="","",IFERROR(INDEX(정기주문설정!$G$3:$G$302,MATCH("R"&32,주문생성!$M$6:$M$305,0)),"")) | H37: =IF($B37="","",IFERROR(INDEX(정기주문설정!$H$3:$H$302,MATCH("R"&32,주문생성!$M$6:$M$305,0)),"")) | I37: =IF($B37="","",ROUND($G37*$H37,0)) | K37: =IF(정기주문설정!$B34="",FALSE(),IF(정기주문설정!$M34="중지",FALSE(),IF(정기주문설정!$L34<>"",IF($B$3<정기주문설정!$L34,FALSE(),IF(정기주문설정!$I34="매일",TRUE(),IF(정기주문설정!$I34="매주",(WEEKDAY($B$3)=IFERROR(MATCH(정기주문설정!$J34,정기주문설정!$O$3:$O$9,0),0)),IF(정기주문설정!$I34="격주",AND((WEEKDAY($B$3)=IFERROR(MATCH(정기주문설정!$J34,정기주문설정!$O$3:$O$9,0),0)),MOD(INT(($B$3-정기주문설정!$L34)/7),2)=0),IF(정기주문설정!$I34="매월",DAY($B$3)=정기주문설정!$K34,FALSE()))))),IF(정기주문설정!$I34="매일",TRUE(),IF(정기주문설정!$I34="매주",(WEEKDAY($B$3)=IFERROR(MATCH(정기주문설정!$J34,정기주문설정!$O$3:$O$9,0),0)),IF(정기주문설정!$I34="매월",DAY($B$3)=정기주문설정!$K34,FALSE())))))) -> FALSE | L37: =IF($K37=FALSE(),"",COUNTIF($K$6:$K37,TRUE())) | M37: =IF($L37="","","R"&$L37)
A38: =IF($C38="","",$B$3) | B38: =IFERROR(INDEX(정기주문설정!$B$3:$B$302,MATCH("R"&33,주문생성!$M$6:$M$305,0)),"") | C38: =IF($B38="","",IFERROR(INDEX(정기주문설정!$C$3:$C$302,MATCH("R"&33,주문생성!$M$6:$M$305,0)),"")) | D38: =IF($B38="","",IFERROR(INDEX(정기주문설정!$D$3:$D$302,MATCH("R"&33,주문생성!$M$6:$M$305,0)),"")) | E38: =IF($B38="","",IFERROR(INDEX(정기주문설정!$E$3:$E$302,MATCH("R"&33,주문생성!$M$6:$M$305,0)),"")) | F38: =IF($B38="","",IFERROR(INDEX(정기주문설정!$F$3:$F$302,MATCH("R"&33,주문생성!$M$6:$M$305,0)),"")) | G38: =IF($B38="","",IFERROR(INDEX(정기주문설정!$G$3:$G$302,MATCH("R"&33,주문생성!$M$6:$M$305,0)),"")) | H38: =IF($B38="","",IFERROR(INDEX(정기주문설정!$H$3:$H$302,MATCH("R"&33,주문생성!$M$6:$M$305,0)),"")) | I38: =IF($B38="","",ROUND($G38*$H38,0)) | K38: =IF(정기주문설정!$B35="",FALSE(),IF(정기주문설정!$M35="중지",FALSE(),IF(정기주문설정!$L35<>"",IF($B$3<정기주문설정!$L35,FALSE(),IF(정기주문설정!$I35="매일",TRUE(),IF(정기주문설정!$I35="매주",(WEEKDAY($B$3)=IFERROR(MATCH(정기주문설정!$J35,정기주문설정!$O$3:$O$9,0),0)),IF(정기주문설정!$I35="격주",AND((WEEKDAY($B$3)=IFERROR(MATCH(정기주문설정!$J35,정기주문설정!$O$3:$O$9,0),0)),MOD(INT(($B$3-정기주문설정!$L35)/7),2)=0),IF(정기주문설정!$I35="매월",DAY($B$3)=정기주문설정!$K35,FALSE()))))),IF(정기주문설정!$I35="매일",TRUE(),IF(정기주문설정!$I35="매주",(WEEKDAY($B$3)=IFERROR(MATCH(정기주문설정!$J35,정기주문설정!$O$3:$O$9,0),0)),IF(정기주문설정!$I35="매월",DAY($B$3)=정기주문설정!$K35,FALSE())))))) -> FALSE | L38: =IF($K38=FALSE(),"",COUNTIF($K$6:$K38,TRUE())) | M38: =IF($L38="","","R"&$L38)
A39: =IF($C39="","",$B$3) | B39: =IFERROR(INDEX(정기주문설정!$B$3:$B$302,MATCH("R"&34,주문생성!$M$6:$M$305,0)),"") | C39: =IF($B39="","",IFERROR(INDEX(정기주문설정!$C$3:$C$302,MATCH("R"&34,주문생성!$M$6:$M$305,0)),"")) | D39: =IF($B39="","",IFERROR(INDEX(정기주문설정!$D$3:$D$302,MATCH("R"&34,주문생성!$M$6:$M$305,0)),"")) | E39: =IF($B39="","",IFERROR(INDEX(정기주문설정!$E$3:$E$302,MATCH("R"&34,주문생성!$M$6:$M$305,0)),"")) | F39: =IF($B39="","",IFERROR(INDEX(정기주문설정!$F$3:$F$302,MATCH("R"&34,주문생성!$M$6:$M$305,0)),"")) | G39: =IF($B39="","",IFERROR(INDEX(정기주문설정!$G$3:$G$302,MATCH("R"&34,주문생성!$M$6:$M$305,0)),"")) | H39: =IF($B39="","",IFERROR(INDEX(정기주문설정!$H$3:$H$302,MATCH("R"&34,주문생성!$M$6:$M$305,0)),"")) | I39: =IF($B39="","",ROUND($G39*$H39,0)) | K39: =IF(정기주문설정!$B36="",FALSE(),IF(정기주문설정!$M36="중지",FALSE(),IF(정기주문설정!$L36<>"",IF($B$3<정기주문설정!$L36,FALSE(),IF(정기주문설정!$I36="매일",TRUE(),IF(정기주문설정!$I36="매주",(WEEKDAY($B$3)=IFERROR(MATCH(정기주문설정!$J36,정기주문설정!$O$3:$O$9,0),0)),IF(정기주문설정!$I36="격주",AND((WEEKDAY($B$3)=IFERROR(MATCH(정기주문설정!$J36,정기주문설정!$O$3:$O$9,0),0)),MOD(INT(($B$3-정기주문설정!$L36)/7),2)=0),IF(정기주문설정!$I36="매월",DAY($B$3)=정기주문설정!$K36,FALSE()))))),IF(정기주문설정!$I36="매일",TRUE(),IF(정기주문설정!$I36="매주",(WEEKDAY($B$3)=IFERROR(MATCH(정기주문설정!$J36,정기주문설정!$O$3:$O$9,0),0)),IF(정기주문설정!$I36="매월",DAY($B$3)=정기주문설정!$K36,FALSE())))))) -> FALSE | L39: =IF($K39=FALSE(),"",COUNTIF($K$6:$K39,TRUE())) | M39: =IF($L39="","","R"&$L39)
A40: =IF($C40="","",$B$3) | B40: =IFERROR(INDEX(정기주문설정!$B$3:$B$302,MATCH("R"&35,주문생성!$M$6:$M$305,0)),"") | C40: =IF($B40="","",IFERROR(INDEX(정기주문설정!$C$3:$C$302,MATCH("R"&35,주문생성!$M$6:$M$305,0)),"")) | D40: =IF($B40="","",IFERROR(INDEX(정기주문설정!$D$3:$D$302,MATCH("R"&35,주문생성!$M$6:$M$305,0)),"")) | E40: =IF($B40="","",IFERROR(INDEX(정기주문설정!$E$3:$E$302,MATCH("R"&35,주문생성!$M$6:$M$305,0)),"")) | F40: =IF($B40="","",IFERROR(INDEX(정기주문설정!$F$3:$F$302,MATCH("R"&35,주문생성!$M$6:$M$305,0)),"")) | G40: =IF($B40="","",IFERROR(INDEX(정기주문설정!$G$3:$G$302,MATCH("R"&35,주문생성!$M$6:$M$305,0)),"")) | H40: =IF($B40="","",IFERROR(INDEX(정기주문설정!$H$3:$H$302,MATCH("R"&35,주문생성!$M$6:$M$305,0)),"")) | I40: =IF($B40="","",ROUND($G40*$H40,0)) | K40: =IF(정기주문설정!$B37="",FALSE(),IF(정기주문설정!$M37="중지",FALSE(),IF(정기주문설정!$L37<>"",IF($B$3<정기주문설정!$L37,FALSE(),IF(정기주문설정!$I37="매일",TRUE(),IF(정기주문설정!$I37="매주",(WEEKDAY($B$3)=IFERROR(MATCH(정기주문설정!$J37,정기주문설정!$O$3:$O$9,0),0)),IF(정기주문설정!$I37="격주",AND((WEEKDAY($B$3)=IFERROR(MATCH(정기주문설정!$J37,정기주문설정!$O$3:$O$9,0),0)),MOD(INT(($B$3-정기주문설정!$L37)/7),2)=0),IF(정기주문설정!$I37="매월",DAY($B$3)=정기주문설정!$K37,FALSE()))))),IF(정기주문설정!$I37="매일",TRUE(),IF(정기주문설정!$I37="매주",(WEEKDAY($B$3)=IFERROR(MATCH(정기주문설정!$J37,정기주문설정!$O$3:$O$9,0),0)),IF(정기주문설정!$I37="매월",DAY($B$3)=정기주문설정!$K37,FALSE())))))) -> FALSE | L40: =IF($K40=FALSE(),"",COUNTIF($K$6:$K40,TRUE())) | M40: =IF($L40="","","R"&$L40)
A41: =IF($C41="","",$B$3) | B41: =IFERROR(INDEX(정기주문설정!$B$3:$B$302,MATCH("R"&36,주문생성!$M$6:$M$305,0)),"") | C41: =IF($B41="","",IFERROR(INDEX(정기주문설정!$C$3:$C$302,MATCH("R"&36,주문생성!$M$6:$M$305,0)),"")) | D41: =IF($B41="","",IFERROR(INDEX(정기주문설정!$D$3:$D$302,MATCH("R"&36,주문생성!$M$6:$M$305,0)),"")) | E41: =IF($B41="","",IFERROR(INDEX(정기주문설정!$E$3:$E$302,MATCH("R"&36,주문생성!$M$6:$M$305,0)),"")) | F41: =IF($B41="","",IFERROR(INDEX(정기주문설정!$F$3:$F$302,MATCH("R"&36,주문생성!$M$6:$M$305,0)),"")) | G41: =IF($B41="","",IFERROR(INDEX(정기주문설정!$G$3:$G$302,MATCH("R"&36,주문생성!$M$6:$M$305,0)),"")) | H41: =IF($B41="","",IFERROR(INDEX(정기주문설정!$H$3:$H$302,MATCH("R"&36,주문생성!$M$6:$M$305,0)),"")) | I41: =IF($B41="","",ROUND($G41*$H41,0)) | K41: =IF(정기주문설정!$B38="",FALSE(),IF(정기주문설정!$M38="중지",FALSE(),IF(정기주문설정!$L38<>"",IF($B$3<정기주문설정!$L38,FALSE(),IF(정기주문설정!$I38="매일",TRUE(),IF(정기주문설정!$I38="매주",(WEEKDAY($B$3)=IFERROR(MATCH(정기주문설정!$J38,정기주문설정!$O$3:$O$9,0),0)),IF(정기주문설정!$I38="격주",AND((WEEKDAY($B$3)=IFERROR(MATCH(정기주문설정!$J38,정기주문설정!$O$3:$O$9,0),0)),MOD(INT(($B$3-정기주문설정!$L38)/7),2)=0),IF(정기주문설정!$I38="매월",DAY($B$3)=정기주문설정!$K38,FALSE()))))),IF(정기주문설정!$I38="매일",TRUE(),IF(정기주문설정!$I38="매주",(WEEKDAY($B$3)=IFERROR(MATCH(정기주문설정!$J38,정기주문설정!$O$3:$O$9,0),0)),IF(정기주문설정!$I38="매월",DAY($B$3)=정기주문설정!$K38,FALSE())))))) -> FALSE | L41: =IF($K41=FALSE(),"",COUNTIF($K$6:$K41,TRUE())) | M41: =IF($L41="","","R"&$L41)
