Workbook

Sheet 사용안내
B2: 샘플 · 견본 대여 관리
B4: 핵심 | C4: 빌려준 수량에서 돌아온 수량을 빼면 아직 안 온 게 남습니다. 며칠 지났는지도 자동으로 나옵니다.
B5: 입력 규칙 | C5: 파란색 글씨 칸만 입력하세요. 검은색은 자동 계산입니다.
B6: ① 대여처목록 | C6: 샘플을 가져가는 거래처·부서·담당자를 등록합니다.
B7: ② 품목목록 | C7: 빌려주는 샘플·견본·장비를 등록합니다.
B8: ③ 대여내역 | C8: 빌려줄 때마다 한 줄. 반납예정일을 넣으면 연체 여부가 자동으로 나옵니다.
B9: ④ 반납내역 | C9: 돌아올 때마다 한 줄. 나눠서 돌아와도 여러 줄로 넣으면 됩니다.
B10: ⑤ 미반납현황 | C10: 아직 안 돌아온 것만 모아서, 오래된 순으로 보여줍니다.
B11: ⑥ 품목별현황 | C11: 품목별 총 대여·반납·미반납 수량입니다.
B12: ⑦ 대여처별현황 | C12: 어느 거래처가 많이 안 돌려주는지 보여줍니다.
B13: 미반납 계산 | C13: 대여 수량 − 반납 수량 합계
B15: 설정 | C15: 값을 바꾸면 모든 계산에 반영됩니다
B16: 연체 경고 기준(일) | C16: 7

Sheet 대여처목록
A1: 대여처목록
A2: 대여처 | B2: 담당자 | C2: 연락처 | D2: 비고
A3: ○○상사 | B3: 김과장 | C3: 010-0000-0001
A4: △△디자인 | B4: 이대리 | C4: 010-0000-0002
A5: 영업2팀 | B5: 박주임 | C5: 내선 204

Sheet 품목목록
A1: 품목목록
A2: 품번 | B2: 품명 | C2: 규격 | D2: 단위 | E2: 보유수량
A3: S001 | B3: 원단 샘플북 A | C3: 2026 S/S | D3: 권 | E3: 10
A4: S002 | B4: 컬러칩 세트 | C4: 표준 | D4: 세트 | E4: 5
A5: S003 | B5: 시연용 노트북 | C5: 15인치 | D5: 대 | E5: 3

Sheet 대여내역
A1: 대여내역 (빌려줄 때마다 한 줄)
A2: 대여번호(자동) | B2: 대여일 | C2: 대여처 | D2: 품번 | E2: 품명(자동) | F2: 단위(자동) | G2: 대여수량 | H2: 반납예정일 | I2: 반납수량(자동) | J2: 미반납(자동) | K2: D-Day(자동) | L2: 상태(자동)
A3: =IF($B3="","",TEXT($B3,"yymmdd")&"-"&TEXT(COUNTIFS($B$3:$B3,$B3),"00")) -> 260801-01 | B3: 46235 | C3: ○○상사 | D3: S001 | E3: =IF($D3="","",IFERROR(INDEX(품목목록!$B$3:$B$202,MATCH($D3,품목목록!$A$3:$A$202,0)),"미등록품번")) -> 원단 샘플북 A | F3: =IF($D3="","",IFERROR(INDEX(품목목록!$D$3:$D$202,MATCH($D3,품목목록!$A$3:$A$202,0)),"")) -> 권 | G3: 3 | H3: 46265 | I3: =IF($A3="","",SUMIFS(반납내역!$D$3:$D$1502,반납내역!$B$3:$B$1502,$A3)) -> 3 | J3: =IF($A3="","",IF($G3="","",$G3-$I3)) -> 0 | K3: =IF(OR($A3="",$J3="",$J3<=0,$H3=""),"",TODAY()-$H3) | L3: =IF($A3="","",IF($G3="","",IF($J3<=0,"반납완료",IF($I3>0,"부분반납","미반납")))) -> 반납완료
A4: =IF($B4="","",TEXT($B4,"yymmdd")&"-"&TEXT(COUNTIFS($B$3:$B4,$B4),"00")) -> 260901-01 | B4: 46266 | C4: △△디자인 | D4: S002 | E4: =IF($D4="","",IFERROR(INDEX(품목목록!$B$3:$B$202,MATCH($D4,품목목록!$A$3:$A$202,0)),"미등록품번")) -> 컬러칩 세트 | F4: =IF($D4="","",IFERROR(INDEX(품목목록!$D$3:$D$202,MATCH($D4,품목목록!$A$3:$A$202,0)),"")) -> 세트 | G4: 2 | H4: 46295 | I4: =IF($A4="","",SUMIFS(반납내역!$D$3:$D$1502,반납내역!$B$3:$B$1502,$A4)) -> 0 | J4: =IF($A4="","",IF($G4="","",$G4-$I4)) -> 2 | K4: =IF(OR($A4="",$J4="",$J4<=0,$H4=""),"",TODAY()-$H4) -> -16 | L4: =IF($A4="","",IF($G4="","",IF($J4<=0,"반납완료",IF($I4>0,"부분반납","미반납")))) -> 미반납
A5: =IF($B5="","",TEXT($B5,"yymmdd")&"-"&TEXT(COUNTIFS($B$3:$B5,$B5),"00")) -> 260905-01 | B5: 46270 | C5: 영업2팀 | D5: S003 | E5: =IF($D5="","",IFERROR(INDEX(품목목록!$B$3:$B$202,MATCH($D5,품목목록!$A$3:$A$202,0)),"미등록품번")) -> 시연용 노트북 | F5: =IF($D5="","",IFERROR(INDEX(품목목록!$D$3:$D$202,MATCH($D5,품목목록!$A$3:$A$202,0)),"")) -> 대 | G5: 1 | H5: 46277 | I5: =IF($A5="","",SUMIFS(반납내역!$D$3:$D$1502,반납내역!$B$3:$B$1502,$A5)) -> 1 | J5: =IF($A5="","",IF($G5="","",$G5-$I5)) -> 0 | K5: =IF(OR($A5="",$J5="",$J5<=0,$H5=""),"",TODAY()-$H5) | L5: =IF($A5="","",IF($G5="","",IF($J5<=0,"반납완료",IF($I5>0,"부분반납","미반납")))) -> 반납완료
A6: =IF($B6="","",TEXT($B6,"yymmdd")&"-"&TEXT(COUNTIFS($B$3:$B6,$B6),"00")) -> 260910-01 | B6: 46275 | C6: ○○상사 | D6: S001 | E6: =IF($D6="","",IFERROR(INDEX(품목목록!$B$3:$B$202,MATCH($D6,품목목록!$A$3:$A$202,0)),"미등록품번")) -> 원단 샘플북 A | F6: =IF($D6="","",IFERROR(INDEX(품목목록!$D$3:$D$202,MATCH($D6,품목목록!$A$3:$A$202,0)),"")) -> 권 | G6: 2 | H6: 46305 | I6: =IF($A6="","",SUMIFS(반납내역!$D$3:$D$1502,반납내역!$B$3:$B$1502,$A6)) -> 0 | J6: =IF($A6="","",IF($G6="","",$G6-$I6)) -> 2 | K6: =IF(OR($A6="",$J6="",$J6<=0,$H6=""),"",TODAY()-$H6) -> -26 | L6: =IF($A6="","",IF($G6="","",IF($J6<=0,"반납완료",IF($I6>0,"부분반납","미반납")))) -> 미반납
A7: =IF($B7="","",TEXT($B7,"yymmdd")&"-"&TEXT(COUNTIFS($B$3:$B7,$B7),"00")) | E7: =IF($D7="","",IFERROR(INDEX(품목목록!$B$3:$B$202,MATCH($D7,품목목록!$A$3:$A$202,0)),"미등록품번")) | F7: =IF($D7="","",IFERROR(INDEX(품목목록!$D$3:$D$202,MATCH($D7,품목목록!$A$3:$A$202,0)),"")) | I7: =IF($A7="","",SUMIFS(반납내역!$D$3:$D$1502,반납내역!$B$3:$B$1502,$A7)) | J7: =IF($A7="","",IF($G7="","",$G7-$I7)) | K7: =IF(OR($A7="",$J7="",$J7<=0,$H7=""),"",TODAY()-$H7) | L7: =IF($A7="","",IF($G7="","",IF($J7<=0,"반납완료",IF($I7>0,"부분반납","미반납"))))
A8: =IF($B8="","",TEXT($B8,"yymmdd")&"-"&TEXT(COUNTIFS($B$3:$B8,$B8),"00")) | E8: =IF($D8="","",IFERROR(INDEX(품목목록!$B$3:$B$202,MATCH($D8,품목목록!$A$3:$A$202,0)),"미등록품번")) | F8: =IF($D8="","",IFERROR(INDEX(품목목록!$D$3:$D$202,MATCH($D8,품목목록!$A$3:$A$202,0)),"")) | I8: =IF($A8="","",SUMIFS(반납내역!$D$3:$D$1502,반납내역!$B$3:$B$1502,$A8)) | J8: =IF($A8="","",IF($G8="","",$G8-$I8)) | K8: =IF(OR($A8="",$J8="",$J8<=0,$H8=""),"",TODAY()-$H8) | L8: =IF($A8="","",IF($G8="","",IF($J8<=0,"반납완료",IF($I8>0,"부분반납","미반납"))))
A9: =IF($B9="","",TEXT($B9,"yymmdd")&"-"&TEXT(COUNTIFS($B$3:$B9,$B9),"00")) | E9: =IF($D9="","",IFERROR(INDEX(품목목록!$B$3:$B$202,MATCH($D9,품목목록!$A$3:$A$202,0)),"미등록품번")) | F9: =IF($D9="","",IFERROR(INDEX(품목목록!$D$3:$D$202,MATCH($D9,품목목록!$A$3:$A$202,0)),"")) | I9: =IF($A9="","",SUMIFS(반납내역!$D$3:$D$1502,반납내역!$B$3:$B$1502,$A9)) | J9: =IF($A9="","",IF($G9="","",$G9-$I9)) | K9: =IF(OR($A9="",$J9="",$J9<=0,$H9=""),"",TODAY()-$H9) | L9: =IF($A9="","",IF($G9="","",IF($J9<=0,"반납완료",IF($I9>0,"부분반납","미반납"))))
A10: =IF($B10="","",TEXT($B10,"yymmdd")&"-"&TEXT(COUNTIFS($B$3:$B10,$B10),"00")) | E10: =IF($D10="","",IFERROR(INDEX(품목목록!$B$3:$B$202,MATCH($D10,품목목록!$A$3:$A$202,0)),"미등록품번")) | F10: =IF($D10="","",IFERROR(INDEX(품목목록!$D$3:$D$202,MATCH($D10,품목목록!$A$3:$A$202,0)),"")) | I10: =IF($A10="","",SUMIFS(반납내역!$D$3:$D$1502,반납내역!$B$3:$B$1502,$A10)) | J10: =IF($A10="","",IF($G10="","",$G10-$I10)) | K10: =IF(OR($A10="",$J10="",$J10<=0,$H10=""),"",TODAY()-$H10) | L10: =IF($A10="","",IF($G10="","",IF($J10<=0,"반납완료",IF($I10>0,"부분반납","미반납"))))
A11: =IF($B11="","",TEXT($B11,"yymmdd")&"-"&TEXT(COUNTIFS($B$3:$B11,$B11),"00")) | E11: =IF($D11="","",IFERROR(INDEX(품목목록!$B$3:$B$202,MATCH($D11,품목목록!$A$3:$A$202,0)),"미등록품번")) | F11: =IF($D11="","",IFERROR(INDEX(품목목록!$D$3:$D$202,MATCH($D11,품목목록!$A$3:$A$202,0)),"")) | I11: =IF($A11="","",SUMIFS(반납내역!$D$3:$D$1502,반납내역!$B$3:$B$1502,$A11)) | J11: =IF($A11="","",IF($G11="","",$G11-$I11)) | K11: =IF(OR($A11="",$J11="",$J11<=0,$H11=""),"",TODAY()-$H11) | L11: =IF($A11="","",IF($G11="","",IF($J11<=0,"반납완료",IF($I11>0,"부분반납","미반납"))))
A12: =IF($B12="","",TEXT($B12,"yymmdd")&"-"&TEXT(COUNTIFS($B$3:$B12,$B12),"00")) | E12: =IF($D12="","",IFERROR(INDEX(품목목록!$B$3:$B$202,MATCH($D12,품목목록!$A$3:$A$202,0)),"미등록품번")) | F12: =IF($D12="","",IFERROR(INDEX(품목목록!$D$3:$D$202,MATCH($D12,품목목록!$A$3:$A$202,0)),"")) | I12: =IF($A12="","",SUMIFS(반납내역!$D$3:$D$1502,반납내역!$B$3:$B$1502,$A12)) | J12: =IF($A12="","",IF($G12="","",$G12-$I12)) | K12: =IF(OR($A12="",$J12="",$J12<=0,$H12=""),"",TODAY()-$H12) | L12: =IF($A12="","",IF($G12="","",IF($J12<=0,"반납완료",IF($I12>0,"부분반납","미반납"))))
A13: =IF($B13="","",TEXT($B13,"yymmdd")&"-"&TEXT(COUNTIFS($B$3:$B13,$B13),"00")) | E13: =IF($D13="","",IFERROR(INDEX(품목목록!$B$3:$B$202,MATCH($D13,품목목록!$A$3:$A$202,0)),"미등록품번")) | F13: =IF($D13="","",IFERROR(INDEX(품목목록!$D$3:$D$202,MATCH($D13,품목목록!$A$3:$A$202,0)),"")) | I13: =IF($A13="","",SUMIFS(반납내역!$D$3:$D$1502,반납내역!$B$3:$B$1502,$A13)) | J13: =IF($A13="","",IF($G13="","",$G13-$I13)) | K13: =IF(OR($A13="",$J13="",$J13<=0,$H13=""),"",TODAY()-$H13) | L13: =IF($A13="","",IF($G13="","",IF($J13<=0,"반납완료",IF($I13>0,"부분반납","미반납"))))
A14: =IF($B14="","",TEXT($B14,"yymmdd")&"-"&TEXT(COUNTIFS($B$3:$B14,$B14),"00")) | E14: =IF($D14="","",IFERROR(INDEX(품목목록!$B$3:$B$202,MATCH($D14,품목목록!$A$3:$A$202,0)),"미등록품번")) | F14: =IF($D14="","",IFERROR(INDEX(품목목록!$D$3:$D$202,MATCH($D14,품목목록!$A$3:$A$202,0)),"")) | I14: =IF($A14="","",SUMIFS(반납내역!$D$3:$D$1502,반납내역!$B$3:$B$1502,$A14)) | J14: =IF($A14="","",IF($G14="","",$G14-$I14)) | K14: =IF(OR($A14="",$J14="",$J14<=0,$H14=""),"",TODAY()-$H14) | L14: =IF($A14="","",IF($G14="","",IF($J14<=0,"반납완료",IF($I14>0,"부분반납","미반납"))))
A15: =IF($B15="","",TEXT($B15,"yymmdd")&"-"&TEXT(COUNTIFS($B$3:$B15,$B15),"00")) | E15: =IF($D15="","",IFERROR(INDEX(품목목록!$B$3:$B$202,MATCH($D15,품목목록!$A$3:$A$202,0)),"미등록품번")) | F15: =IF($D15="","",IFERROR(INDEX(품목목록!$D$3:$D$202,MATCH($D15,품목목록!$A$3:$A$202,0)),"")) | I15: =IF($A15="","",SUMIFS(반납내역!$D$3:$D$1502,반납내역!$B$3:$B$1502,$A15)) | J15: =IF($A15="","",IF($G15="","",$G15-$I15)) | K15: =IF(OR($A15="",$J15="",$J15<=0,$H15=""),"",TODAY()-$H15) | L15: =IF($A15="","",IF($G15="","",IF($J15<=0,"반납완료",IF($I15>0,"부분반납","미반납"))))
A16: =IF($B16="","",TEXT($B16,"yymmdd")&"-"&TEXT(COUNTIFS($B$3:$B16,$B16),"00")) | E16: =IF($D16="","",IFERROR(INDEX(품목목록!$B$3:$B$202,MATCH($D16,품목목록!$A$3:$A$202,0)),"미등록품번")) | F16: =IF($D16="","",IFERROR(INDEX(품목목록!$D$3:$D$202,MATCH($D16,품목목록!$A$3:$A$202,0)),"")) | I16: =IF($A16="","",SUMIFS(반납내역!$D$3:$D$1502,반납내역!$B$3:$B$1502,$A16)) | J16: =IF($A16="","",IF($G16="","",$G16-$I16)) | K16: =IF(OR($A16="",$J16="",$J16<=0,$H16=""),"",TODAY()-$H16) | L16: =IF($A16="","",IF($G16="","",IF($J16<=0,"반납완료",IF($I16>0,"부분반납","미반납"))))
A17: =IF($B17="","",TEXT($B17,"yymmdd")&"-"&TEXT(COUNTIFS($B$3:$B17,$B17),"00")) | E17: =IF($D17="","",IFERROR(INDEX(품목목록!$B$3:$B$202,MATCH($D17,품목목록!$A$3:$A$202,0)),"미등록품번")) | F17: =IF($D17="","",IFERROR(INDEX(품목목록!$D$3:$D$202,MATCH($D17,품목목록!$A$3:$A$202,0)),"")) | I17: =IF($A17="","",SUMIFS(반납내역!$D$3:$D$1502,반납내역!$B$3:$B$1502,$A17)) | J17: =IF($A17="","",IF($G17="","",$G17-$I17)) | K17: =IF(OR($A17="",$J17="",$J17<=0,$H17=""),"",TODAY()-$H17) | L17: =IF($A17="","",IF($G17="","",IF($J17<=0,"반납완료",IF($I17>0,"부분반납","미반납"))))
A18: =IF($B18="","",TEXT($B18,"yymmdd")&"-"&TEXT(COUNTIFS($B$3:$B18,$B18),"00")) | E18: =IF($D18="","",IFERROR(INDEX(품목목록!$B$3:$B$202,MATCH($D18,품목목록!$A$3:$A$202,0)),"미등록품번")) | F18: =IF($D18="","",IFERROR(INDEX(품목목록!$D$3:$D$202,MATCH($D18,품목목록!$A$3:$A$202,0)),"")) | I18: =IF($A18="","",SUMIFS(반납내역!$D$3:$D$1502,반납내역!$B$3:$B$1502,$A18)) | J18: =IF($A18="","",IF($G18="","",$G18-$I18)) | K18: =IF(OR($A18="",$J18="",$J18<=0,$H18=""),"",TODAY()-$H18) | L18: =IF($A18="","",IF($G18="","",IF($J18<=0,"반납완료",IF($I18>0,"부분반납","미반납"))))
... A1002: =IF($B1002="","",TEXT($B1002,"yymmdd")&"-"&TEXT(COUNTIFS($B$3:$B1002,$B1002),"00")) | E1002: =IF($D1002="","",IFERROR(INDEX(품목목록!$B$3:$B$202,MATCH($D1002,품목목록!$A$3:$A$202,0)),"미등록품번")) | F1002: =IF($D1002="","",IFERROR(INDEX(품목목록!$D$3:$D$202,MATCH($D1002,품목목록!$A$3:$A$202,0)),"")) | I1002: =IF($A1002="","",SUMIFS(반납내역!$D$3:$D$1502,반납내역!$B$3:$B$1502,$A1002)) | J1002: =IF($A1002="","",IF($G1002="","",$G1002-$I1002)) | K1002: =IF(OR($A1002="",$J1002="",$J1002<=0,$H1002=""),"",TODAY()-$H1002) | L1002: =IF($A1002="","",IF($G1002="","",IF($J1002<=0,"반납완료",IF($I1002>0,"부분반납","미반납"))))

Sheet 반납내역
A1: 반납내역 (나눠서 돌아와도 여러 줄로)
A2: 반납일 | B2: 대여번호 | C2: 품명(자동) | D2: 반납수량 | E2: 상태 | F2: 비고
A3: 46254 | B3: 260801-01 | C3: =IF($B3="","",IFERROR(INDEX(대여내역!$E$3:$E$1002,MATCH($B3,대여내역!$A$3:$A$1002,0)),"대여번호없음")) -> 원단 샘플북 A | D3: 3 | E3: 정상
A4: 46277 | B4: 260905-01 | C4: =IF($B4="","",IFERROR(INDEX(대여내역!$E$3:$E$1002,MATCH($B4,대여내역!$A$3:$A$1002,0)),"대여번호없음")) -> 시연용 노트북 | D4: 1 | E4: 정상
C5: =IF($B5="","",IFERROR(INDEX(대여내역!$E$3:$E$1002,MATCH($B5,대여내역!$A$3:$A$1002,0)),"대여번호없음"))
C6: =IF($B6="","",IFERROR(INDEX(대여내역!$E$3:$E$1002,MATCH($B6,대여내역!$A$3:$A$1002,0)),"대여번호없음"))
C7: =IF($B7="","",IFERROR(INDEX(대여내역!$E$3:$E$1002,MATCH($B7,대여내역!$A$3:$A$1002,0)),"대여번호없음"))
C8: =IF($B8="","",IFERROR(INDEX(대여내역!$E$3:$E$1002,MATCH($B8,대여내역!$A$3:$A$1002,0)),"대여번호없음"))
C9: =IF($B9="","",IFERROR(INDEX(대여내역!$E$3:$E$1002,MATCH($B9,대여내역!$A$3:$A$1002,0)),"대여번호없음"))
C10: =IF($B10="","",IFERROR(INDEX(대여내역!$E$3:$E$1002,MATCH($B10,대여내역!$A$3:$A$1002,0)),"대여번호없음"))
C11: =IF($B11="","",IFERROR(INDEX(대여내역!$E$3:$E$1002,MATCH($B11,대여내역!$A$3:$A$1002,0)),"대여번호없음"))
C12: =IF($B12="","",IFERROR(INDEX(대여내역!$E$3:$E$1002,MATCH($B12,대여내역!$A$3:$A$1002,0)),"대여번호없음"))
C13: =IF($B13="","",IFERROR(INDEX(대여내역!$E$3:$E$1002,MATCH($B13,대여내역!$A$3:$A$1002,0)),"대여번호없음"))
C14: =IF($B14="","",IFERROR(INDEX(대여내역!$E$3:$E$1002,MATCH($B14,대여내역!$A$3:$A$1002,0)),"대여번호없음"))
C15: =IF($B15="","",IFERROR(INDEX(대여내역!$E$3:$E$1002,MATCH($B15,대여내역!$A$3:$A$1002,0)),"대여번호없음"))
C16: =IF($B16="","",IFERROR(INDEX(대여내역!$E$3:$E$1002,MATCH($B16,대여내역!$A$3:$A$1002,0)),"대여번호없음"))
... C1502: =IF($B1502="","",IFERROR(INDEX(대여내역!$E$3:$E$1002,MATCH($B1502,대여내역!$A$3:$A$1002,0)),"대여번호없음"))

Sheet 미반납현황
A1: 미반납현황
A3: 미반납 건수 | B3: =COUNTIF(대여내역!$L$3:$L$1002,"미반납")+COUNTIF(대여내역!$L$3:$L$1002,"부분반납") -> 2 | D3: 연체 건수 | E3: =COUNTIFS(대여내역!$J$3:$J$1002,">0",대여내역!$H$3:$H$1002,"<"&TODAY()) -> 0 | G3: 미반납 수량 | H3: =SUMIFS(대여내역!$J$3:$J$1002,대여내역!$J$3:$J$1002,">0") -> 4
A5: 순번 | B5: 대여번호 | C5: 대여일 | D5: 대여처 | E5: 품명 | F5: 대여수량 | G5: 미반납 | H5: 반납예정일 | I5: D-Day
A6: =IF($B6="","",1) -> 1 | B6: =IFERROR(INDEX(대여내역!$A$3:$A$1002,MATCH("R"&1,미반납현황!$M$6:$M$1005,0)),"") -> 260901-01 | C6: =IF($B6="","",IFERROR(INDEX(대여내역!$B$3:$B$1002,MATCH("R"&1,미반납현황!$M$6:$M$1005,0)),"")) -> 46266 | D6: =IF($B6="","",IFERROR(INDEX(대여내역!$C$3:$C$1002,MATCH("R"&1,미반납현황!$M$6:$M$1005,0)),"")) -> △△디자인 | E6: =IF($B6="","",IFERROR(INDEX(대여내역!$E$3:$E$1002,MATCH("R"&1,미반납현황!$M$6:$M$1005,0)),"")) -> 컬러칩 세트 | F6: =IF($B6="","",IFERROR(INDEX(대여내역!$G$3:$G$1002,MATCH("R"&1,미반납현황!$M$6:$M$1005,0)),"")) -> 2 | G6: =IF($B6="","",IFERROR(INDEX(대여내역!$J$3:$J$1002,MATCH("R"&1,미반납현황!$M$6:$M$1005,0)),"")) -> 2 | H6: =IF($B6="","",IFERROR(INDEX(대여내역!$H$3:$H$1002,MATCH("R"&1,미반납현황!$M$6:$M$1005,0)),"")) -> 46295 | I6: =IF($B6="","",IFERROR(INDEX(대여내역!$K$3:$K$1002,MATCH("R"&1,미반납현황!$M$6:$M$1005,0)),"")) -> -16 | K6: =IF(대여내역!$A3="",FALSE(),OR(대여내역!$L3="미반납",대여내역!$L3="부분반납")) -> FALSE | L6: =IF($K6=FALSE(),"",COUNTIF($K$6:$K6,TRUE())) | M6: =IF($L6="","","R"&$L6)
A7: =IF($B7="","",2) -> 2 | B7: =IFERROR(INDEX(대여내역!$A$3:$A$1002,MATCH("R"&2,미반납현황!$M$6:$M$1005,0)),"") -> 260910-01 | C7: =IF($B7="","",IFERROR(INDEX(대여내역!$B$3:$B$1002,MATCH("R"&2,미반납현황!$M$6:$M$1005,0)),"")) -> 46275 | D7: =IF($B7="","",IFERROR(INDEX(대여내역!$C$3:$C$1002,MATCH("R"&2,미반납현황!$M$6:$M$1005,0)),"")) -> ○○상사 | E7: =IF($B7="","",IFERROR(INDEX(대여내역!$E$3:$E$1002,MATCH("R"&2,미반납현황!$M$6:$M$1005,0)),"")) -> 원단 샘플북 A | F7: =IF($B7="","",IFERROR(INDEX(대여내역!$G$3:$G$1002,MATCH("R"&2,미반납현황!$M$6:$M$1005,0)),"")) -> 2 | G7: =IF($B7="","",IFERROR(INDEX(대여내역!$J$3:$J$1002,MATCH("R"&2,미반납현황!$M$6:$M$1005,0)),"")) -> 2 | H7: =IF($B7="","",IFERROR(INDEX(대여내역!$H$3:$H$1002,MATCH("R"&2,미반납현황!$M$6:$M$1005,0)),"")) -> 46305 | I7: =IF($B7="","",IFERROR(INDEX(대여내역!$K$3:$K$1002,MATCH("R"&2,미반납현황!$M$6:$M$1005,0)),"")) -> -26 | K7: =IF(대여내역!$A4="",FALSE(),OR(대여내역!$L4="미반납",대여내역!$L4="부분반납")) -> TRUE | L7: =IF($K7=FALSE(),"",COUNTIF($K$6:$K7,TRUE())) -> 1 | M7: =IF($L7="","","R"&$L7) -> R1
A8: =IF($B8="","",3) | B8: =IFERROR(INDEX(대여내역!$A$3:$A$1002,MATCH("R"&3,미반납현황!$M$6:$M$1005,0)),"") | C8: =IF($B8="","",IFERROR(INDEX(대여내역!$B$3:$B$1002,MATCH("R"&3,미반납현황!$M$6:$M$1005,0)),"")) | D8: =IF($B8="","",IFERROR(INDEX(대여내역!$C$3:$C$1002,MATCH("R"&3,미반납현황!$M$6:$M$1005,0)),"")) | E8: =IF($B8="","",IFERROR(INDEX(대여내역!$E$3:$E$1002,MATCH("R"&3,미반납현황!$M$6:$M$1005,0)),"")) | F8: =IF($B8="","",IFERROR(INDEX(대여내역!$G$3:$G$1002,MATCH("R"&3,미반납현황!$M$6:$M$1005,0)),"")) | G8: =IF($B8="","",IFERROR(INDEX(대여내역!$J$3:$J$1002,MATCH("R"&3,미반납현황!$M$6:$M$1005,0)),"")) | H8: =IF($B8="","",IFERROR(INDEX(대여내역!$H$3:$H$1002,MATCH("R"&3,미반납현황!$M$6:$M$1005,0)),"")) | I8: =IF($B8="","",IFERROR(INDEX(대여내역!$K$3:$K$1002,MATCH("R"&3,미반납현황!$M$6:$M$1005,0)),"")) | K8: =IF(대여내역!$A5="",FALSE(),OR(대여내역!$L5="미반납",대여내역!$L5="부분반납")) -> FALSE | L8: =IF($K8=FALSE(),"",COUNTIF($K$6:$K8,TRUE())) | M8: =IF($L8="","","R"&$L8)
A9: =IF($B9="","",4) | B9: =IFERROR(INDEX(대여내역!$A$3:$A$1002,MATCH("R"&4,미반납현황!$M$6:$M$1005,0)),"") | C9: =IF($B9="","",IFERROR(INDEX(대여내역!$B$3:$B$1002,MATCH("R"&4,미반납현황!$M$6:$M$1005,0)),"")) | D9: =IF($B9="","",IFERROR(INDEX(대여내역!$C$3:$C$1002,MATCH("R"&4,미반납현황!$M$6:$M$1005,0)),"")) | E9: =IF($B9="","",IFERROR(INDEX(대여내역!$E$3:$E$1002,MATCH("R"&4,미반납현황!$M$6:$M$1005,0)),"")) | F9: =IF($B9="","",IFERROR(INDEX(대여내역!$G$3:$G$1002,MATCH("R"&4,미반납현황!$M$6:$M$1005,0)),"")) | G9: =IF($B9="","",IFERROR(INDEX(대여내역!$J$3:$J$1002,MATCH("R"&4,미반납현황!$M$6:$M$1005,0)),"")) | H9: =IF($B9="","",IFERROR(INDEX(대여내역!$H$3:$H$1002,MATCH("R"&4,미반납현황!$M$6:$M$1005,0)),"")) | I9: =IF($B9="","",IFERROR(INDEX(대여내역!$K$3:$K$1002,MATCH("R"&4,미반납현황!$M$6:$M$1005,0)),"")) | K9: =IF(대여내역!$A6="",FALSE(),OR(대여내역!$L6="미반납",대여내역!$L6="부분반납")) -> TRUE | L9: =IF($K9=FALSE(),"",COUNTIF($K$6:$K9,TRUE())) -> 2 | M9: =IF($L9="","","R"&$L9) -> R2
A10: =IF($B10="","",5) | B10: =IFERROR(INDEX(대여내역!$A$3:$A$1002,MATCH("R"&5,미반납현황!$M$6:$M$1005,0)),"") | C10: =IF($B10="","",IFERROR(INDEX(대여내역!$B$3:$B$1002,MATCH("R"&5,미반납현황!$M$6:$M$1005,0)),"")) | D10: =IF($B10="","",IFERROR(INDEX(대여내역!$C$3:$C$1002,MATCH("R"&5,미반납현황!$M$6:$M$1005,0)),"")) | E10: =IF($B10="","",IFERROR(INDEX(대여내역!$E$3:$E$1002,MATCH("R"&5,미반납현황!$M$6:$M$1005,0)),"")) | F10: =IF($B10="","",IFERROR(INDEX(대여내역!$G$3:$G$1002,MATCH("R"&5,미반납현황!$M$6:$M$1005,0)),"")) | G10: =IF($B10="","",IFERROR(INDEX(대여내역!$J$3:$J$1002,MATCH("R"&5,미반납현황!$M$6:$M$1005,0)),"")) | H10: =IF($B10="","",IFERROR(INDEX(대여내역!$H$3:$H$1002,MATCH("R"&5,미반납현황!$M$6:$M$1005,0)),"")) | I10: =IF($B10="","",IFERROR(INDEX(대여내역!$K$3:$K$1002,MATCH("R"&5,미반납현황!$M$6:$M$1005,0)),"")) | K10: =IF(대여내역!$A7="",FALSE(),OR(대여내역!$L7="미반납",대여내역!$L7="부분반납")) -> FALSE | L10: =IF($K10=FALSE(),"",COUNTIF($K$6:$K10,TRUE())) | M10: =IF($L10="","","R"&$L10)
A11: =IF($B11="","",6) | B11: =IFERROR(INDEX(대여내역!$A$3:$A$1002,MATCH("R"&6,미반납현황!$M$6:$M$1005,0)),"") | C11: =IF($B11="","",IFERROR(INDEX(대여내역!$B$3:$B$1002,MATCH("R"&6,미반납현황!$M$6:$M$1005,0)),"")) | D11: =IF($B11="","",IFERROR(INDEX(대여내역!$C$3:$C$1002,MATCH("R"&6,미반납현황!$M$6:$M$1005,0)),"")) | E11: =IF($B11="","",IFERROR(INDEX(대여내역!$E$3:$E$1002,MATCH("R"&6,미반납현황!$M$6:$M$1005,0)),"")) | F11: =IF($B11="","",IFERROR(INDEX(대여내역!$G$3:$G$1002,MATCH("R"&6,미반납현황!$M$6:$M$1005,0)),"")) | G11: =IF($B11="","",IFERROR(INDEX(대여내역!$J$3:$J$1002,MATCH("R"&6,미반납현황!$M$6:$M$1005,0)),"")) | H11: =IF($B11="","",IFERROR(INDEX(대여내역!$H$3:$H$1002,MATCH("R"&6,미반납현황!$M$6:$M$1005,0)),"")) | I11: =IF($B11="","",IFERROR(INDEX(대여내역!$K$3:$K$1002,MATCH("R"&6,미반납현황!$M$6:$M$1005,0)),"")) | K11: =IF(대여내역!$A8="",FALSE(),OR(대여내역!$L8="미반납",대여내역!$L8="부분반납")) -> FALSE | L11: =IF($K11=FALSE(),"",COUNTIF($K$6:$K11,TRUE())) | M11: =IF($L11="","","R"&$L11)
A12: =IF($B12="","",7) | B12: =IFERROR(INDEX(대여내역!$A$3:$A$1002,MATCH("R"&7,미반납현황!$M$6:$M$1005,0)),"") | C12: =IF($B12="","",IFERROR(INDEX(대여내역!$B$3:$B$1002,MATCH("R"&7,미반납현황!$M$6:$M$1005,0)),"")) | D12: =IF($B12="","",IFERROR(INDEX(대여내역!$C$3:$C$1002,MATCH("R"&7,미반납현황!$M$6:$M$1005,0)),"")) | E12: =IF($B12="","",IFERROR(INDEX(대여내역!$E$3:$E$1002,MATCH("R"&7,미반납현황!$M$6:$M$1005,0)),"")) | F12: =IF($B12="","",IFERROR(INDEX(대여내역!$G$3:$G$1002,MATCH("R"&7,미반납현황!$M$6:$M$1005,0)),"")) | G12: =IF($B12="","",IFERROR(INDEX(대여내역!$J$3:$J$1002,MATCH("R"&7,미반납현황!$M$6:$M$1005,0)),"")) | H12: =IF($B12="","",IFERROR(INDEX(대여내역!$H$3:$H$1002,MATCH("R"&7,미반납현황!$M$6:$M$1005,0)),"")) | I12: =IF($B12="","",IFERROR(INDEX(대여내역!$K$3:$K$1002,MATCH("R"&7,미반납현황!$M$6:$M$1005,0)),"")) | K12: =IF(대여내역!$A9="",FALSE(),OR(대여내역!$L9="미반납",대여내역!$L9="부분반납")) -> FALSE | L12: =IF($K12=FALSE(),"",COUNTIF($K$6:$K12,TRUE())) | M12: =IF($L12="","","R"&$L12)
A13: =IF($B13="","",8) | B13: =IFERROR(INDEX(대여내역!$A$3:$A$1002,MATCH("R"&8,미반납현황!$M$6:$M$1005,0)),"") | C13: =IF($B13="","",IFERROR(INDEX(대여내역!$B$3:$B$1002,MATCH("R"&8,미반납현황!$M$6:$M$1005,0)),"")) | D13: =IF($B13="","",IFERROR(INDEX(대여내역!$C$3:$C$1002,MATCH("R"&8,미반납현황!$M$6:$M$1005,0)),"")) | E13: =IF($B13="","",IFERROR(INDEX(대여내역!$E$3:$E$1002,MATCH("R"&8,미반납현황!$M$6:$M$1005,0)),"")) | F13: =IF($B13="","",IFERROR(INDEX(대여내역!$G$3:$G$1002,MATCH("R"&8,미반납현황!$M$6:$M$1005,0)),"")) | G13: =IF($B13="","",IFERROR(INDEX(대여내역!$J$3:$J$1002,MATCH("R"&8,미반납현황!$M$6:$M$1005,0)),"")) | H13: =IF($B13="","",IFERROR(INDEX(대여내역!$H$3:$H$1002,MATCH("R"&8,미반납현황!$M$6:$M$1005,0)),"")) | I13: =IF($B13="","",IFERROR(INDEX(대여내역!$K$3:$K$1002,MATCH("R"&8,미반납현황!$M$6:$M$1005,0)),"")) | K13: =IF(대여내역!$A10="",FALSE(),OR(대여내역!$L10="미반납",대여내역!$L10="부분반납")) -> FALSE | L13: =IF($K13=FALSE(),"",COUNTIF($K$6:$K13,TRUE())) | M13: =IF($L13="","","R"&$L13)
A14: =IF($B14="","",9) | B14: =IFERROR(INDEX(대여내역!$A$3:$A$1002,MATCH("R"&9,미반납현황!$M$6:$M$1005,0)),"") | C14: =IF($B14="","",IFERROR(INDEX(대여내역!$B$3:$B$1002,MATCH("R"&9,미반납현황!$M$6:$M$1005,0)),"")) | D14: =IF($B14="","",IFERROR(INDEX(대여내역!$C$3:$C$1002,MATCH("R"&9,미반납현황!$M$6:$M$1005,0)),"")) | E14: =IF($B14="","",IFERROR(INDEX(대여내역!$E$3:$E$1002,MATCH("R"&9,미반납현황!$M$6:$M$1005,0)),"")) | F14: =IF($B14="","",IFERROR(INDEX(대여내역!$G$3:$G$1002,MATCH("R"&9,미반납현황!$M$6:$M$1005,0)),"")) | G14: =IF($B14="","",IFERROR(INDEX(대여내역!$J$3:$J$1002,MATCH("R"&9,미반납현황!$M$6:$M$1005,0)),"")) | H14: =IF($B14="","",IFERROR(INDEX(대여내역!$H$3:$H$1002,MATCH("R"&9,미반납현황!$M$6:$M$1005,0)),"")) | I14: =IF($B14="","",IFERROR(INDEX(대여내역!$K$3:$K$1002,MATCH("R"&9,미반납현황!$M$6:$M$1005,0)),"")) | K14: =IF(대여내역!$A11="",FALSE(),OR(대여내역!$L11="미반납",대여내역!$L11="부분반납")) -> FALSE | L14: =IF($K14=FALSE(),"",COUNTIF($K$6:$K14,TRUE())) | M14: =IF($L14="","","R"&$L14)
A15: =IF($B15="","",10) | B15: =IFERROR(INDEX(대여내역!$A$3:$A$1002,MATCH("R"&10,미반납현황!$M$6:$M$1005,0)),"") | C15: =IF($B15="","",IFERROR(INDEX(대여내역!$B$3:$B$1002,MATCH("R"&10,미반납현황!$M$6:$M$1005,0)),"")) | D15: =IF($B15="","",IFERROR(INDEX(대여내역!$C$3:$C$1002,MATCH("R"&10,미반납현황!$M$6:$M$1005,0)),"")) | E15: =IF($B15="","",IFERROR(INDEX(대여내역!$E$3:$E$1002,MATCH("R"&10,미반납현황!$M$6:$M$1005,0)),"")) | F15: =IF($B15="","",IFERROR(INDEX(대여내역!$G$3:$G$1002,MATCH("R"&10,미반납현황!$M$6:$M$1005,0)),"")) | G15: =IF($B15="","",IFERROR(INDEX(대여내역!$J$3:$J$1002,MATCH("R"&10,미반납현황!$M$6:$M$1005,0)),"")) | H15: =IF($B15="","",IFERROR(INDEX(대여내역!$H$3:$H$1002,MATCH("R"&10,미반납현황!$M$6:$M$1005,0)),"")) | I15: =IF($B15="","",IFERROR(INDEX(대여내역!$K$3:$K$1002,MATCH("R"&10,미반납현황!$M$6:$M$1005,0)),"")) | K15: =IF(대여내역!$A12="",FALSE(),OR(대여내역!$L12="미반납",대여내역!$L12="부분반납")) -> FALSE | L15: =IF($K15=FALSE(),"",COUNTIF($K$6:$K15,TRUE())) | M15: =IF($L15="","","R"&$L15)
A16: =IF($B16="","",11) | B16: =IFERROR(INDEX(대여내역!$A$3:$A$1002,MATCH("R"&11,미반납현황!$M$6:$M$1005,0)),"") | C16: =IF($B16="","",IFERROR(INDEX(대여내역!$B$3:$B$1002,MATCH("R"&11,미반납현황!$M$6:$M$1005,0)),"")) | D16: =IF($B16="","",IFERROR(INDEX(대여내역!$C$3:$C$1002,MATCH("R"&11,미반납현황!$M$6:$M$1005,0)),"")) | E16: =IF($B16="","",IFERROR(INDEX(대여내역!$E$3:$E$1002,MATCH("R"&11,미반납현황!$M$6:$M$1005,0)),"")) | F16: =IF($B16="","",IFERROR(INDEX(대여내역!$G$3:$G$1002,MATCH("R"&11,미반납현황!$M$6:$M$1005,0)),"")) | G16: =IF($B16="","",IFERROR(INDEX(대여내역!$J$3:$J$1002,MATCH("R"&11,미반납현황!$M$6:$M$1005,0)),"")) | H16: =IF($B16="","",IFERROR(INDEX(대여내역!$H$3:$H$1002,MATCH("R"&11,미반납현황!$M$6:$M$1005,0)),"")) | I16: =IF($B16="","",IFERROR(INDEX(대여내역!$K$3:$K$1002,MATCH("R"&11,미반납현황!$M$6:$M$1005,0)),"")) | K16: =IF(대여내역!$A13="",FALSE(),OR(대여내역!$L13="미반납",대여내역!$L13="부분반납")) -> FALSE | L16: =IF($K16=FALSE(),"",COUNTIF($K$6:$K16,TRUE())) | M16: =IF($L16="","","R"&$L16)
A17: =IF($B17="","",12) | B17: =IFERROR(INDEX(대여내역!$A$3:$A$1002,MATCH("R"&12,미반납현황!$M$6:$M$1005,0)),"") | C17: =IF($B17="","",IFERROR(INDEX(대여내역!$B$3:$B$1002,MATCH("R"&12,미반납현황!$M$6:$M$1005,0)),"")) | D17: =IF($B17="","",IFERROR(INDEX(대여내역!$C$3:$C$1002,MATCH("R"&12,미반납현황!$M$6:$M$1005,0)),"")) | E17: =IF($B17="","",IFERROR(INDEX(대여내역!$E$3:$E$1002,MATCH("R"&12,미반납현황!$M$6:$M$1005,0)),"")) | F17: =IF($B17="","",IFERROR(INDEX(대여내역!$G$3:$G$1002,MATCH("R"&12,미반납현황!$M$6:$M$1005,0)),"")) | G17: =IF($B17="","",IFERROR(INDEX(대여내역!$J$3:$J$1002,MATCH("R"&12,미반납현황!$M$6:$M$1005,0)),"")) | H17: =IF($B17="","",IFERROR(INDEX(대여내역!$H$3:$H$1002,MATCH("R"&12,미반납현황!$M$6:$M$1005,0)),"")) | I17: =IF($B17="","",IFERROR(INDEX(대여내역!$K$3:$K$1002,MATCH("R"&12,미반납현황!$M$6:$M$1005,0)),"")) | K17: =IF(대여내역!$A14="",FALSE(),OR(대여내역!$L14="미반납",대여내역!$L14="부분반납")) -> FALSE | L17: =IF($K17=FALSE(),"",COUNTIF($K$6:$K17,TRUE())) | M17: =IF($L17="","","R"&$L17)
A18: =IF($B18="","",13) | B18: =IFERROR(INDEX(대여내역!$A$3:$A$1002,MATCH("R"&13,미반납현황!$M$6:$M$1005,0)),"") | C18: =IF($B18="","",IFERROR(INDEX(대여내역!$B$3:$B$1002,MATCH("R"&13,미반납현황!$M$6:$M$1005,0)),"")) | D18: =IF($B18="","",IFERROR(INDEX(대여내역!$C$3:$C$1002,MATCH("R"&13,미반납현황!$M$6:$M$1005,0)),"")) | E18: =IF($B18="","",IFERROR(INDEX(대여내역!$E$3:$E$1002,MATCH("R"&13,미반납현황!$M$6:$M$1005,0)),"")) | F18: =IF($B18="","",IFERROR(INDEX(대여내역!$G$3:$G$1002,MATCH("R"&13,미반납현황!$M$6:$M$1005,0)),"")) | G18: =IF($B18="","",IFERROR(INDEX(대여내역!$J$3:$J$1002,MATCH("R"&13,미반납현황!$M$6:$M$1005,0)),"")) | H18: =IF($B18="","",IFERROR(INDEX(대여내역!$H$3:$H$1002,MATCH("R"&13,미반납현황!$M$6:$M$1005,0)),"")) | I18: =IF($B18="","",IFERROR(INDEX(대여내역!$K$3:$K$1002,MATCH("R"&13,미반납현황!$M$6:$M$1005,0)),"")) | K18: =IF(대여내역!$A15="",FALSE(),OR(대여내역!$L15="미반납",대여내역!$L15="부분반납")) -> FALSE | L18: =IF($K18=FALSE(),"",COUNTIF($K$6:$K18,TRUE())) | M18: =IF($L18="","","R"&$L18)
A19: =IF($B19="","",14) | B19: =IFERROR(INDEX(대여내역!$A$3:$A$1002,MATCH("R"&14,미반납현황!$M$6:$M$1005,0)),"") | C19: =IF($B19="","",IFERROR(INDEX(대여내역!$B$3:$B$1002,MATCH("R"&14,미반납현황!$M$6:$M$1005,0)),"")) | D19: =IF($B19="","",IFERROR(INDEX(대여내역!$C$3:$C$1002,MATCH("R"&14,미반납현황!$M$6:$M$1005,0)),"")) | E19: =IF($B19="","",IFERROR(INDEX(대여내역!$E$3:$E$1002,MATCH("R"&14,미반납현황!$M$6:$M$1005,0)),"")) | F19: =IF($B19="","",IFERROR(INDEX(대여내역!$G$3:$G$1002,MATCH("R"&14,미반납현황!$M$6:$M$1005,0)),"")) | G19: =IF($B19="","",IFERROR(INDEX(대여내역!$J$3:$J$1002,MATCH("R"&14,미반납현황!$M$6:$M$1005,0)),"")) | H19: =IF($B19="","",IFERROR(INDEX(대여내역!$H$3:$H$1002,MATCH("R"&14,미반납현황!$M$6:$M$1005,0)),"")) | I19: =IF($B19="","",IFERROR(INDEX(대여내역!$K$3:$K$1002,MATCH("R"&14,미반납현황!$M$6:$M$1005,0)),"")) | K19: =IF(대여내역!$A16="",FALSE(),OR(대여내역!$L16="미반납",대여내역!$L16="부분반납")) -> FALSE | L19: =IF($K19=FALSE(),"",COUNTIF($K$6:$K19,TRUE())) | M19: =IF($L19="","","R"&$L19)
A20: =IF($B20="","",15) | B20: =IFERROR(INDEX(대여내역!$A$3:$A$1002,MATCH("R"&15,미반납현황!$M$6:$M$1005,0)),"") | C20: =IF($B20="","",IFERROR(INDEX(대여내역!$B$3:$B$1002,MATCH("R"&15,미반납현황!$M$6:$M$1005,0)),"")) | D20: =IF($B20="","",IFERROR(INDEX(대여내역!$C$3:$C$1002,MATCH("R"&15,미반납현황!$M$6:$M$1005,0)),"")) | E20: =IF($B20="","",IFERROR(INDEX(대여내역!$E$3:$E$1002,MATCH("R"&15,미반납현황!$M$6:$M$1005,0)),"")) | F20: =IF($B20="","",IFERROR(INDEX(대여내역!$G$3:$G$1002,MATCH("R"&15,미반납현황!$M$6:$M$1005,0)),"")) | G20: =IF($B20="","",IFERROR(INDEX(대여내역!$J$3:$J$1002,MATCH("R"&15,미반납현황!$M$6:$M$1005,0)),"")) | H20: =IF($B20="","",IFERROR(INDEX(대여내역!$H$3:$H$1002,MATCH("R"&15,미반납현황!$M$6:$M$1005,0)),"")) | I20: =IF($B20="","",IFERROR(INDEX(대여내역!$K$3:$K$1002,MATCH("R"&15,미반납현황!$M$6:$M$1005,0)),"")) | K20: =IF(대여내역!$A17="",FALSE(),OR(대여내역!$L17="미반납",대여내역!$L17="부분반납")) -> FALSE | L20: =IF($K20=FALSE(),"",COUNTIF($K$6:$K20,TRUE())) | M20: =IF($L20="","","R"&$L20)
A21: =IF($B21="","",16) | B21: =IFERROR(INDEX(대여내역!$A$3:$A$1002,MATCH("R"&16,미반납현황!$M$6:$M$1005,0)),"") | C21: =IF($B21="","",IFERROR(INDEX(대여내역!$B$3:$B$1002,MATCH("R"&16,미반납현황!$M$6:$M$1005,0)),"")) | D21: =IF($B21="","",IFERROR(INDEX(대여내역!$C$3:$C$1002,MATCH("R"&16,미반납현황!$M$6:$M$1005,0)),"")) | E21: =IF($B21="","",IFERROR(INDEX(대여내역!$E$3:$E$1002,MATCH("R"&16,미반납현황!$M$6:$M$1005,0)),"")) | F21: =IF($B21="","",IFERROR(INDEX(대여내역!$G$3:$G$1002,MATCH("R"&16,미반납현황!$M$6:$M$1005,0)),"")) | G21: =IF($B21="","",IFERROR(INDEX(대여내역!$J$3:$J$1002,MATCH("R"&16,미반납현황!$M$6:$M$1005,0)),"")) | H21: =IF($B21="","",IFERROR(INDEX(대여내역!$H$3:$H$1002,MATCH("R"&16,미반납현황!$M$6:$M$1005,0)),"")) | I21: =IF($B21="","",IFERROR(INDEX(대여내역!$K$3:$K$1002,MATCH("R"&16,미반납현황!$M$6:$M$1005,0)),"")) | K21: =IF(대여내역!$A18="",FALSE(),OR(대여내역!$L18="미반납",대여내역!$L18="부분반납")) -> FALSE | L21: =IF($K21=FALSE(),"",COUNTIF($K$6:$K21,TRUE())) | M21: =IF($L21="","","R"&$L21)
A22: =IF($B22="","",17) | B22: =IFERROR(INDEX(대여내역!$A$3:$A$1002,MATCH("R"&17,미반납현황!$M$6:$M$1005,0)),"") | C22: =IF($B22="","",IFERROR(INDEX(대여내역!$B$3:$B$1002,MATCH("R"&17,미반납현황!$M$6:$M$1005,0)),"")) | D22: =IF($B22="","",IFERROR(INDEX(대여내역!$C$3:$C$1002,MATCH("R"&17,미반납현황!$M$6:$M$1005,0)),"")) | E22: =IF($B22="","",IFERROR(INDEX(대여내역!$E$3:$E$1002,MATCH("R"&17,미반납현황!$M$6:$M$1005,0)),"")) | F22: =IF($B22="","",IFERROR(INDEX(대여내역!$G$3:$G$1002,MATCH("R"&17,미반납현황!$M$6:$M$1005,0)),"")) | G22: =IF($B22="","",IFERROR(INDEX(대여내역!$J$3:$J$1002,MATCH("R"&17,미반납현황!$M$6:$M$1005,0)),"")) | H22: =IF($B22="","",IFERROR(INDEX(대여내역!$H$3:$H$1002,MATCH("R"&17,미반납현황!$M$6:$M$1005,0)),"")) | I22: =IF($B22="","",IFERROR(INDEX(대여내역!$K$3:$K$1002,MATCH("R"&17,미반납현황!$M$6:$M$1005,0)),"")) | K22: =IF(대여내역!$A19="",FALSE(),OR(대여내역!$L19="미반납",대여내역!$L19="부분반납")) -> FALSE | L22: =IF($K22=FALSE(),"",COUNTIF($K$6:$K22,TRUE())) | M22: =IF($L22="","","R"&$L22)
A23: =IF($B23="","",18) | B23: =IFERROR(INDEX(대여내역!$A$3:$A$1002,MATCH("R"&18,미반납현황!$M$6:$M$1005,0)),"") | C23: =IF($B23="","",IFERROR(INDEX(대여내역!$B$3:$B$1002,MATCH("R"&18,미반납현황!$M$6:$M$1005,0)),"")) | D23: =IF($B23="","",IFERROR(INDEX(대여내역!$C$3:$C$1002,MATCH("R"&18,미반납현황!$M$6:$M$1005,0)),"")) | E23: =IF($B23="","",IFERROR(INDEX(대여내역!$E$3:$E$1002,MATCH("R"&18,미반납현황!$M$6:$M$1005,0)),"")) | F23: =IF($B23="","",IFERROR(INDEX(대여내역!$G$3:$G$1002,MATCH("R"&18,미반납현황!$M$6:$M$1005,0)),"")) | G23: =IF($B23="","",IFERROR(INDEX(대여내역!$J$3:$J$1002,MATCH("R"&18,미반납현황!$M$6:$M$1005,0)),"")) | H23: =IF($B23="","",IFERROR(INDEX(대여내역!$H$3:$H$1002,MATCH("R"&18,미반납현황!$M$6:$M$1005,0)),"")) | I23: =IF($B23="","",IFERROR(INDEX(대여내역!$K$3:$K$1002,MATCH("R"&18,미반납현황!$M$6:$M$1005,0)),"")) | K23: =IF(대여내역!$A20="",FALSE(),OR(대여내역!$L20="미반납",대여내역!$L20="부분반납")) -> FALSE | L23: =IF($K23=FALSE(),"",COUNTIF($K$6:$K23,TRUE())) | M23: =IF($L23="","","R"&$L23)
A24: =IF($B24="","",19) | B24: =IFERROR(INDEX(대여내역!$A$3:$A$1002,MATCH("R"&19,미반납현황!$M$6:$M$1005,0)),"") | C24: =IF($B24="","",IFERROR(INDEX(대여내역!$B$3:$B$1002,MATCH("R"&19,미반납현황!$M$6:$M$1005,0)),"")) | D24: =IF($B24="","",IFERROR(INDEX(대여내역!$C$3:$C$1002,MATCH("R"&19,미반납현황!$M$6:$M$1005,0)),"")) | E24: =IF($B24="","",IFERROR(INDEX(대여내역!$E$3:$E$1002,MATCH("R"&19,미반납현황!$M$6:$M$1005,0)),"")) | F24: =IF($B24="","",IFERROR(INDEX(대여내역!$G$3:$G$1002,MATCH("R"&19,미반납현황!$M$6:$M$1005,0)),"")) | G24: =IF($B24="","",IFERROR(INDEX(대여내역!$J$3:$J$1002,MATCH("R"&19,미반납현황!$M$6:$M$1005,0)),"")) | H24: =IF($B24="","",IFERROR(INDEX(대여내역!$H$3:$H$1002,MATCH("R"&19,미반납현황!$M$6:$M$1005,0)),"")) | I24: =IF($B24="","",IFERROR(INDEX(대여내역!$K$3:$K$1002,MATCH("R"&19,미반납현황!$M$6:$M$1005,0)),"")) | K24: =IF(대여내역!$A21="",FALSE(),OR(대여내역!$L21="미반납",대여내역!$L21="부분반납")) -> FALSE | L24: =IF($K24=FALSE(),"",COUNTIF($K$6:$K24,TRUE())) | M24: =IF($L24="","","R"&$L24)
A25: =IF($B25="","",20) | B25: =IFERROR(INDEX(대여내역!$A$3:$A$1002,MATCH("R"&20,미반납현황!$M$6:$M$1005,0)),"") | C25: =IF($B25="","",IFERROR(INDEX(대여내역!$B$3:$B$1002,MATCH("R"&20,미반납현황!$M$6:$M$1005,0)),"")) | D25: =IF($B25="","",IFERROR(INDEX(대여내역!$C$3:$C$1002,MATCH("R"&20,미반납현황!$M$6:$M$1005,0)),"")) | E25: =IF($B25="","",IFERROR(INDEX(대여내역!$E$3:$E$1002,MATCH("R"&20,미반납현황!$M$6:$M$1005,0)),"")) | F25: =IF($B25="","",IFERROR(INDEX(대여내역!$G$3:$G$1002,MATCH("R"&20,미반납현황!$M$6:$M$1005,0)),"")) | G25: =IF($B25="","",IFERROR(INDEX(대여내역!$J$3:$J$1002,MATCH("R"&20,미반납현황!$M$6:$M$1005,0)),"")) | H25: =IF($B25="","",IFERROR(INDEX(대여내역!$H$3:$H$1002,MATCH("R"&20,미반납현황!$M$6:$M$1005,0)),"")) | I25: =IF($B25="","",IFERROR(INDEX(대여내역!$K$3:$K$1002,MATCH("R"&20,미반납현황!$M$6:$M$1005,0)),"")) | K25: =IF(대여내역!$A22="",FALSE(),OR(대여내역!$L22="미반납",대여내역!$L22="부분반납")) -> FALSE | L25: =IF($K25=FALSE(),"",COUNTIF($K$6:$K25,TRUE())) | M25: =IF($L25="","","R"&$L25)
A26: =IF($B26="","",21) | B26: =IFERROR(INDEX(대여내역!$A$3:$A$1002,MATCH("R"&21,미반납현황!$M$6:$M$1005,0)),"") | C26: =IF($B26="","",IFERROR(INDEX(대여내역!$B$3:$B$1002,MATCH("R"&21,미반납현황!$M$6:$M$1005,0)),"")) | D26: =IF($B26="","",IFERROR(INDEX(대여내역!$C$3:$C$1002,MATCH("R"&21,미반납현황!$M$6:$M$1005,0)),"")) | E26: =IF($B26="","",IFERROR(INDEX(대여내역!$E$3:$E$1002,MATCH("R"&21,미반납현황!$M$6:$M$1005,0)),"")) | F26: =IF($B26="","",IFERROR(INDEX(대여내역!$G$3:$G$1002,MATCH("R"&21,미반납현황!$M$6:$M$1005,0)),"")) | G26: =IF($B26="","",IFERROR(INDEX(대여내역!$J$3:$J$1002,MATCH("R"&21,미반납현황!$M$6:$M$1005,0)),"")) | H26: =IF($B26="","",IFERROR(INDEX(대여내역!$H$3:$H$1002,MATCH("R"&21,미반납현황!$M$6:$M$1005,0)),"")) | I26: =IF($B26="","",IFERROR(INDEX(대여내역!$K$3:$K$1002,MATCH("R"&21,미반납현황!$M$6:$M$1005,0)),"")) | K26: =IF(대여내역!$A23="",FALSE(),OR(대여내역!$L23="미반납",대여내역!$L23="부분반납")) -> FALSE | L26: =IF($K26=FALSE(),"",COUNTIF($K$6:$K26,TRUE())) | M26: =IF($L26="","","R"&$L26)
A27: =IF($B27="","",22) | B27: =IFERROR(INDEX(대여내역!$A$3:$A$1002,MATCH("R"&22,미반납현황!$M$6:$M$1005,0)),"") | C27: =IF($B27="","",IFERROR(INDEX(대여내역!$B$3:$B$1002,MATCH("R"&22,미반납현황!$M$6:$M$1005,0)),"")) | D27: =IF($B27="","",IFERROR(INDEX(대여내역!$C$3:$C$1002,MATCH("R"&22,미반납현황!$M$6:$M$1005,0)),"")) | E27: =IF($B27="","",IFERROR(INDEX(대여내역!$E$3:$E$1002,MATCH("R"&22,미반납현황!$M$6:$M$1005,0)),"")) | F27: =IF($B27="","",IFERROR(INDEX(대여내역!$G$3:$G$1002,MATCH("R"&22,미반납현황!$M$6:$M$1005,0)),"")) | G27: =IF($B27="","",IFERROR(INDEX(대여내역!$J$3:$J$1002,MATCH("R"&22,미반납현황!$M$6:$M$1005,0)),"")) | H27: =IF($B27="","",IFERROR(INDEX(대여내역!$H$3:$H$1002,MATCH("R"&22,미반납현황!$M$6:$M$1005,0)),"")) | I27: =IF($B27="","",IFERROR(INDEX(대여내역!$K$3:$K$1002,MATCH("R"&22,미반납현황!$M$6:$M$1005,0)),"")) | K27: =IF(대여내역!$A24="",FALSE(),OR(대여내역!$L24="미반납",대여내역!$L24="부분반납")) -> FALSE | L27: =IF($K27=FALSE(),"",COUNTIF($K$6:$K27,TRUE())) | M27: =IF($L27="","","R"&$L27)
A28: =IF($B28="","",23) | B28: =IFERROR(INDEX(대여내역!$A$3:$A$1002,MATCH("R"&23,미반납현황!$M$6:$M$1005,0)),"") | C28: =IF($B28="","",IFERROR(INDEX(대여내역!$B$3:$B$1002,MATCH("R"&23,미반납현황!$M$6:$M$1005,0)),"")) | D28: =IF($B28="","",IFERROR(INDEX(대여내역!$C$3:$C$1002,MATCH("R"&23,미반납현황!$M$6:$M$1005,0)),"")) | E28: =IF($B28="","",IFERROR(INDEX(대여내역!$E$3:$E$1002,MATCH("R"&23,미반납현황!$M$6:$M$1005,0)),"")) | F28: =IF($B28="","",IFERROR(INDEX(대여내역!$G$3:$G$1002,MATCH("R"&23,미반납현황!$M$6:$M$1005,0)),"")) | G28: =IF($B28="","",IFERROR(INDEX(대여내역!$J$3:$J$1002,MATCH("R"&23,미반납현황!$M$6:$M$1005,0)),"")) | H28: =IF($B28="","",IFERROR(INDEX(대여내역!$H$3:$H$1002,MATCH("R"&23,미반납현황!$M$6:$M$1005,0)),"")) | I28: =IF($B28="","",IFERROR(INDEX(대여내역!$K$3:$K$1002,MATCH("R"&23,미반납현황!$M$6:$M$1005,0)),"")) | K28: =IF(대여내역!$A25="",FALSE(),OR(대여내역!$L25="미반납",대여내역!$L25="부분반납")) -> FALSE | L28: =IF($K28=FALSE(),"",COUNTIF($K$6:$K28,TRUE())) | M28: =IF($L28="","","R"&$L28)
A29: =IF($B29="","",24) | B29: =IFERROR(INDEX(대여내역!$A$3:$A$1002,MATCH("R"&24,미반납현황!$M$6:$M$1005,0)),"") | C29: =IF($B29="","",IFERROR(INDEX(대여내역!$B$3:$B$1002,MATCH("R"&24,미반납현황!$M$6:$M$1005,0)),"")) | D29: =IF($B29="","",IFERROR(INDEX(대여내역!$C$3:$C$1002,MATCH("R"&24,미반납현황!$M$6:$M$1005,0)),"")) | E29: =IF($B29="","",IFERROR(INDEX(대여내역!$E$3:$E$1002,MATCH("R"&24,미반납현황!$M$6:$M$1005,0)),"")) | F29: =IF($B29="","",IFERROR(INDEX(대여내역!$G$3:$G$1002,MATCH("R"&24,미반납현황!$M$6:$M$1005,0)),"")) | G29: =IF($B29="","",IFERROR(INDEX(대여내역!$J$3:$J$1002,MATCH("R"&24,미반납현황!$M$6:$M$1005,0)),"")) | H29: =IF($B29="","",IFERROR(INDEX(대여내역!$H$3:$H$1002,MATCH("R"&24,미반납현황!$M$6:$M$1005,0)),"")) | I29: =IF($B29="","",IFERROR(INDEX(대여내역!$K$3:$K$1002,MATCH("R"&24,미반납현황!$M$6:$M$1005,0)),"")) | K29: =IF(대여내역!$A26="",FALSE(),OR(대여내역!$L26="미반납",대여내역!$L26="부분반납")) -> FALSE | L29: =IF($K29=FALSE(),"",COUNTIF($K$6:$K29,TRUE())) | M29: =IF($L29="","","R"&$L29)
A30: =IF($B30="","",25) | B30: =IFERROR(INDEX(대여내역!$A$3:$A$1002,MATCH("R"&25,미반납현황!$M$6:$M$1005,0)),"") | C30: =IF($B30="","",IFERROR(INDEX(대여내역!$B$3:$B$1002,MATCH("R"&25,미반납현황!$M$6:$M$1005,0)),"")) | D30: =IF($B30="","",IFERROR(INDEX(대여내역!$C$3:$C$1002,MATCH("R"&25,미반납현황!$M$6:$M$1005,0)),"")) | E30: =IF($B30="","",IFERROR(INDEX(대여내역!$E$3:$E$1002,MATCH("R"&25,미반납현황!$M$6:$M$1005,0)),"")) | F30: =IF($B30="","",IFERROR(INDEX(대여내역!$G$3:$G$1002,MATCH("R"&25,미반납현황!$M$6:$M$1005,0)),"")) | G30: =IF($B30="","",IFERROR(INDEX(대여내역!$J$3:$J$1002,MATCH("R"&25,미반납현황!$M$6:$M$1005,0)),"")) | H30: =IF($B30="","",IFERROR(INDEX(대여내역!$H$3:$H$1002,MATCH("R"&25,미반납현황!$M$6:$M$1005,0)),"")) | I30: =IF($B30="","",IFERROR(INDEX(대여내역!$K$3:$K$1002,MATCH("R"&25,미반납현황!$M$6:$M$1005,0)),"")) | K30: =IF(대여내역!$A27="",FALSE(),OR(대여내역!$L27="미반납",대여내역!$L27="부분반납")) -> FALSE | L30: =IF($K30=FALSE(),"",COUNTIF($K$6:$K30,TRUE())) | M30: =IF($L30="","","R"&$L30)
A31: =IF($B31="","",26) | B31: =IFERROR(INDEX(대여내역!$A$3:$A$1002,MATCH("R"&26,미반납현황!$M$6:$M$1005,0)),"") | C31: =IF($B31="","",IFERROR(INDEX(대여내역!$B$3:$B$1002,MATCH("R"&26,미반납현황!$M$6:$M$1005,0)),"")) | D31: =IF($B31="","",IFERROR(INDEX(대여내역!$C$3:$C$1002,MATCH("R"&26,미반납현황!$M$6:$M$1005,0)),"")) | E31: =IF($B31="","",IFERROR(INDEX(대여내역!$E$3:$E$1002,MATCH("R"&26,미반납현황!$M$6:$M$1005,0)),"")) | F31: =IF($B31="","",IFERROR(INDEX(대여내역!$G$3:$G$1002,MATCH("R"&26,미반납현황!$M$6:$M$1005,0)),"")) | G31: =IF($B31="","",IFERROR(INDEX(대여내역!$J$3:$J$1002,MATCH("R"&26,미반납현황!$M$6:$M$1005,0)),"")) | H31: =IF($B31="","",IFERROR(INDEX(대여내역!$H$3:$H$1002,MATCH("R"&26,미반납현황!$M$6:$M$1005,0)),"")) | I31: =IF($B31="","",IFERROR(INDEX(대여내역!$K$3:$K$1002,MATCH("R"&26,미반납현황!$M$6:$M$1005,0)),"")) | K31: =IF(대여내역!$A28="",FALSE(),OR(대여내역!$L28="미반납",대여내역!$L28="부분반납")) -> FALSE | L31: =IF($K31=FALSE(),"",COUNTIF($K$6:$K31,TRUE())) | M31: =IF($L31="","","R"&$L31)
A32: =IF($B32="","",27) | B32: =IFERROR(INDEX(대여내역!$A$3:$A$1002,MATCH("R"&27,미반납현황!$M$6:$M$1005,0)),"") | C32: =IF($B32="","",IFERROR(INDEX(대여내역!$B$3:$B$1002,MATCH("R"&27,미반납현황!$M$6:$M$1005,0)),"")) | D32: =IF($B32="","",IFERROR(INDEX(대여내역!$C$3:$C$1002,MATCH("R"&27,미반납현황!$M$6:$M$1005,0)),"")) | E32: =IF($B32="","",IFERROR(INDEX(대여내역!$E$3:$E$1002,MATCH("R"&27,미반납현황!$M$6:$M$1005,0)),"")) | F32: =IF($B32="","",IFERROR(INDEX(대여내역!$G$3:$G$1002,MATCH("R"&27,미반납현황!$M$6:$M$1005,0)),"")) | G32: =IF($B32="","",IFERROR(INDEX(대여내역!$J$3:$J$1002,MATCH("R"&27,미반납현황!$M$6:$M$1005,0)),"")) | H32: =IF($B32="","",IFERROR(INDEX(대여내역!$H$3:$H$1002,MATCH("R"&27,미반납현황!$M$6:$M$1005,0)),"")) | I32: =IF($B32="","",IFERROR(INDEX(대여내역!$K$3:$K$1002,MATCH("R"&27,미반납현황!$M$6:$M$1005,0)),"")) | K32: =IF(대여내역!$A29="",FALSE(),OR(대여내역!$L29="미반납",대여내역!$L29="부분반납")) -> FALSE | L32: =IF($K32=FALSE(),"",COUNTIF($K$6:$K32,TRUE())) | M32: =IF($L32="","","R"&$L32)
A33: =IF($B33="","",28) | B33: =IFERROR(INDEX(대여내역!$A$3:$A$1002,MATCH("R"&28,미반납현황!$M$6:$M$1005,0)),"") | C33: =IF($B33="","",IFERROR(INDEX(대여내역!$B$3:$B$1002,MATCH("R"&28,미반납현황!$M$6:$M$1005,0)),"")) | D33: =IF($B33="","",IFERROR(INDEX(대여내역!$C$3:$C$1002,MATCH("R"&28,미반납현황!$M$6:$M$1005,0)),"")) | E33: =IF($B33="","",IFERROR(INDEX(대여내역!$E$3:$E$1002,MATCH("R"&28,미반납현황!$M$6:$M$1005,0)),"")) | F33: =IF($B33="","",IFERROR(INDEX(대여내역!$G$3:$G$1002,MATCH("R"&28,미반납현황!$M$6:$M$1005,0)),"")) | G33: =IF($B33="","",IFERROR(INDEX(대여내역!$J$3:$J$1002,MATCH("R"&28,미반납현황!$M$6:$M$1005,0)),"")) | H33: =IF($B33="","",IFERROR(INDEX(대여내역!$H$3:$H$1002,MATCH("R"&28,미반납현황!$M$6:$M$1005,0)),"")) | I33: =IF($B33="","",IFERROR(INDEX(대여내역!$K$3:$K$1002,MATCH("R"&28,미반납현황!$M$6:$M$1005,0)),"")) | K33: =IF(대여내역!$A30="",FALSE(),OR(대여내역!$L30="미반납",대여내역!$L30="부분반납")) -> FALSE | L33: =IF($K33=FALSE(),"",COUNTIF($K$6:$K33,TRUE())) | M33: =IF($L33="","","R"&$L33)
A34: =IF($B34="","",29) | B34: =IFERROR(INDEX(대여내역!$A$3:$A$1002,MATCH("R"&29,미반납현황!$M$6:$M$1005,0)),"") | C34: =IF($B34="","",IFERROR(INDEX(대여내역!$B$3:$B$1002,MATCH("R"&29,미반납현황!$M$6:$M$1005,0)),"")) | D34: =IF($B34="","",IFERROR(INDEX(대여내역!$C$3:$C$1002,MATCH("R"&29,미반납현황!$M$6:$M$1005,0)),"")) | E34: =IF($B34="","",IFERROR(INDEX(대여내역!$E$3:$E$1002,MATCH("R"&29,미반납현황!$M$6:$M$1005,0)),"")) | F34: =IF($B34="","",IFERROR(INDEX(대여내역!$G$3:$G$1002,MATCH("R"&29,미반납현황!$M$6:$M$1005,0)),"")) | G34: =IF($B34="","",IFERROR(INDEX(대여내역!$J$3:$J$1002,MATCH("R"&29,미반납현황!$M$6:$M$1005,0)),"")) | H34: =IF($B34="","",IFERROR(INDEX(대여내역!$H$3:$H$1002,MATCH("R"&29,미반납현황!$M$6:$M$1005,0)),"")) | I34: =IF($B34="","",IFERROR(INDEX(대여내역!$K$3:$K$1002,MATCH("R"&29,미반납현황!$M$6:$M$1005,0)),"")) | K34: =IF(대여내역!$A31="",FALSE(),OR(대여내역!$L31="미반납",대여내역!$L31="부분반납")) -> FALSE | L34: =IF($K34=FALSE(),"",COUNTIF($K$6:$K34,TRUE())) | M34: =IF($L34="","","R"&$L34)
A35: =IF($B35="","",30) | B35: =IFERROR(INDEX(대여내역!$A$3:$A$1002,MATCH("R"&30,미반납현황!$M$6:$M$1005,0)),"") | C35: =IF($B35="","",IFERROR(INDEX(대여내역!$B$3:$B$1002,MATCH("R"&30,미반납현황!$M$6:$M$1005,0)),"")) | D35: =IF($B35="","",IFERROR(INDEX(대여내역!$C$3:$C$1002,MATCH("R"&30,미반납현황!$M$6:$M$1005,0)),"")) | E35: =IF($B35="","",IFERROR(INDEX(대여내역!$E$3:$E$1002,MATCH("R"&30,미반납현황!$M$6:$M$1005,0)),"")) | F35: =IF($B35="","",IFERROR(INDEX(대여내역!$G$3:$G$1002,MATCH("R"&30,미반납현황!$M$6:$M$1005,0)),"")) | G35: =IF($B35="","",IFERROR(INDEX(대여내역!$J$3:$J$1002,MATCH("R"&30,미반납현황!$M$6:$M$1005,0)),"")) | H35: =IF($B35="","",IFERROR(INDEX(대여내역!$H$3:$H$1002,MATCH("R"&30,미반납현황!$M$6:$M$1005,0)),"")) | I35: =IF($B35="","",IFERROR(INDEX(대여내역!$K$3:$K$1002,MATCH("R"&30,미반납현황!$M$6:$M$1005,0)),"")) | K35: =IF(대여내역!$A32="",FALSE(),OR(대여내역!$L32="미반납",대여내역!$L32="부분반납")) -> FALSE | L35: =IF($K35=FALSE(),"",COUNTIF($K$6:$K35,TRUE())) | M35: =IF($L35="","","R"&$L35)
A36: =IF($B36="","",31) | B36: =IFERROR(INDEX(대여내역!$A$3:$A$1002,MATCH("R"&31,미반납현황!$M$6:$M$1005,0)),"") | C36: =IF($B36="","",IFERROR(INDEX(대여내역!$B$3:$B$1002,MATCH("R"&31,미반납현황!$M$6:$M$1005,0)),"")) | D36: =IF($B36="","",IFERROR(INDEX(대여내역!$C$3:$C$1002,MATCH("R"&31,미반납현황!$M$6:$M$1005,0)),"")) | E36: =IF($B36="","",IFERROR(INDEX(대여내역!$E$3:$E$1002,MATCH("R"&31,미반납현황!$M$6:$M$1005,0)),"")) | F36: =IF($B36="","",IFERROR(INDEX(대여내역!$G$3:$G$1002,MATCH("R"&31,미반납현황!$M$6:$M$1005,0)),"")) | G36: =IF($B36="","",IFERROR(INDEX(대여내역!$J$3:$J$1002,MATCH("R"&31,미반납현황!$M$6:$M$1005,0)),"")) | H36: =IF($B36="","",IFERROR(INDEX(대여내역!$H$3:$H$1002,MATCH("R"&31,미반납현황!$M$6:$M$1005,0)),"")) | I36: =IF($B36="","",IFERROR(INDEX(대여내역!$K$3:$K$1002,MATCH("R"&31,미반납현황!$M$6:$M$1005,0)),"")) | K36: =IF(대여내역!$A33="",FALSE(),OR(대여내역!$L33="미반납",대여내역!$L33="부분반납")) -> FALSE | L36: =IF($K36=FALSE(),"",COUNTIF($K$6:$K36,TRUE())) | M36: =IF($L36="","","R"&$L36)
A37: =IF($B37="","",32) | B37: =IFERROR(INDEX(대여내역!$A$3:$A$1002,MATCH("R"&32,미반납현황!$M$6:$M$1005,0)),"") | C37: =IF($B37="","",IFERROR(INDEX(대여내역!$B$3:$B$1002,MATCH("R"&32,미반납현황!$M$6:$M$1005,0)),"")) | D37: =IF($B37="","",IFERROR(INDEX(대여내역!$C$3:$C$1002,MATCH("R"&32,미반납현황!$M$6:$M$1005,0)),"")) | E37: =IF($B37="","",IFERROR(INDEX(대여내역!$E$3:$E$1002,MATCH("R"&32,미반납현황!$M$6:$M$1005,0)),"")) | F37: =IF($B37="","",IFERROR(INDEX(대여내역!$G$3:$G$1002,MATCH("R"&32,미반납현황!$M$6:$M$1005,0)),"")) | G37: =IF($B37="","",IFERROR(INDEX(대여내역!$J$3:$J$1002,MATCH("R"&32,미반납현황!$M$6:$M$1005,0)),"")) | H37: =IF($B37="","",IFERROR(INDEX(대여내역!$H$3:$H$1002,MATCH("R"&32,미반납현황!$M$6:$M$1005,0)),"")) | I37: =IF($B37="","",IFERROR(INDEX(대여내역!$K$3:$K$1002,MATCH("R"&32,미반납현황!$M$6:$M$1005,0)),"")) | K37: =IF(대여내역!$A34="",FALSE(),OR(대여내역!$L34="미반납",대여내역!$L34="부분반납")) -> FALSE | L37: =IF($K37=FALSE(),"",COUNTIF($K$6:$K37,TRUE())) | M37: =IF($L37="","","R"&$L37)
A38: =IF($B38="","",33) | B38: =IFERROR(INDEX(대여내역!$A$3:$A$1002,MATCH("R"&33,미반납현황!$M$6:$M$1005,0)),"") | C38: =IF($B38="","",IFERROR(INDEX(대여내역!$B$3:$B$1002,MATCH("R"&33,미반납현황!$M$6:$M$1005,0)),"")) | D38: =IF($B38="","",IFERROR(INDEX(대여내역!$C$3:$C$1002,MATCH("R"&33,미반납현황!$M$6:$M$1005,0)),"")) | E38: =IF($B38="","",IFERROR(INDEX(대여내역!$E$3:$E$1002,MATCH("R"&33,미반납현황!$M$6:$M$1005,0)),"")) | F38: =IF($B38="","",IFERROR(INDEX(대여내역!$G$3:$G$1002,MATCH("R"&33,미반납현황!$M$6:$M$1005,0)),"")) | G38: =IF($B38="","",IFERROR(INDEX(대여내역!$J$3:$J$1002,MATCH("R"&33,미반납현황!$M$6:$M$1005,0)),"")) | H38: =IF($B38="","",IFERROR(INDEX(대여내역!$H$3:$H$1002,MATCH("R"&33,미반납현황!$M$6:$M$1005,0)),"")) | I38: =IF($B38="","",IFERROR(INDEX(대여내역!$K$3:$K$1002,MATCH("R"&33,미반납현황!$M$6:$M$1005,0)),"")) | K38: =IF(대여내역!$A35="",FALSE(),OR(대여내역!$L35="미반납",대여내역!$L35="부분반납")) -> FALSE | L38: =IF($K38=FALSE(),"",COUNTIF($K$6:$K38,TRUE())) | M38: =IF($L38="","","R"&$L38)
A39: =IF($B39="","",34) | B39: =IFERROR(INDEX(대여내역!$A$3:$A$1002,MATCH("R"&34,미반납현황!$M$6:$M$1005,0)),"") | C39: =IF($B39="","",IFERROR(INDEX(대여내역!$B$3:$B$1002,MATCH("R"&34,미반납현황!$M$6:$M$1005,0)),"")) | D39: =IF($B39="","",IFERROR(INDEX(대여내역!$C$3:$C$1002,MATCH("R"&34,미반납현황!$M$6:$M$1005,0)),"")) | E39: =IF($B39="","",IFERROR(INDEX(대여내역!$E$3:$E$1002,MATCH("R"&34,미반납현황!$M$6:$M$1005,0)),"")) | F39: =IF($B39="","",IFERROR(INDEX(대여내역!$G$3:$G$1002,MATCH("R"&34,미반납현황!$M$6:$M$1005,0)),"")) | G39: =IF($B39="","",IFERROR(INDEX(대여내역!$J$3:$J$1002,MATCH("R"&34,미반납현황!$M$6:$M$1005,0)),"")) | H39: =IF($B39="","",IFERROR(INDEX(대여내역!$H$3:$H$1002,MATCH("R"&34,미반납현황!$M$6:$M$1005,0)),"")) | I39: =IF($B39="","",IFERROR(INDEX(대여내역!$K$3:$K$1002,MATCH("R"&34,미반납현황!$M$6:$M$1005,0)),"")) | K39: =IF(대여내역!$A36="",FALSE(),OR(대여내역!$L36="미반납",대여내역!$L36="부분반납")) -> FALSE | L39: =IF($K39=FALSE(),"",COUNTIF($K$6:$K39,TRUE())) | M39: =IF($L39="","","R"&$L39)
A40: =IF($B40="","",35) | B40: =IFERROR(INDEX(대여내역!$A$3:$A$1002,MATCH("R"&35,미반납현황!$M$6:$M$1005,0)),"") | C40: =IF($B40="","",IFERROR(INDEX(대여내역!$B$3:$B$1002,MATCH("R"&35,미반납현황!$M$6:$M$1005,0)),"")) | D40: =IF($B40="","",IFERROR(INDEX(대여내역!$C$3:$C$1002,MATCH("R"&35,미반납현황!$M$6:$M$1005,0)),"")) | E40: =IF($B40="","",IFERROR(INDEX(대여내역!$E$3:$E$1002,MATCH("R"&35,미반납현황!$M$6:$M$1005,0)),"")) | F40: =IF($B40="","",IFERROR(INDEX(대여내역!$G$3:$G$1002,MATCH("R"&35,미반납현황!$M$6:$M$1005,0)),"")) | G40: =IF($B40="","",IFERROR(INDEX(대여내역!$J$3:$J$1002,MATCH("R"&35,미반납현황!$M$6:$M$1005,0)),"")) | H40: =IF($B40="","",IFERROR(INDEX(대여내역!$H$3:$H$1002,MATCH("R"&35,미반납현황!$M$6:$M$1005,0)),"")) | I40: =IF($B40="","",IFERROR(INDEX(대여내역!$K$3:$K$1002,MATCH("R"&35,미반납현황!$M$6:$M$1005,0)),"")) | K40: =IF(대여내역!$A37="",FALSE(),OR(대여내역!$L37="미반납",대여내역!$L37="부분반납")) -> FALSE | L40: =IF($K40=FALSE(),"",COUNTIF($K$6:$K40,TRUE())) | M40: =IF($L40="","","R"&$L40)
A41: =IF($B41="","",36) | B41: =IFERROR(INDEX(대여내역!$A$3:$A$1002,MATCH("R"&36,미반납현황!$M$6:$M$1005,0)),"") | C41: =IF($B41="","",IFERROR(INDEX(대여내역!$B$3:$B$1002,MATCH("R"&36,미반납현황!$M$6:$M$1005,0)),"")) | D41: =IF($B41="","",IFERROR(INDEX(대여내역!$C$3:$C$1002,MATCH("R"&36,미반납현황!$M$6:$M$1005,0)),"")) | E41: =IF($B41="","",IFERROR(INDEX(대여내역!$E$3:$E$1002,MATCH("R"&36,미반납현황!$M$6:$M$1005,0)),"")) | F41: =IF($B41="","",IFERROR(INDEX(대여내역!$G$3:$G$1002,MATCH("R"&36,미반납현황!$M$6:$M$1005,0)),"")) | G41: =IF($B41="","",IFERROR(INDEX(대여내역!$J$3:$J$1002,MATCH("R"&36,미반납현황!$M$6:$M$1005,0)),"")) | H41: =IF($B41="","",IFERROR(INDEX(대여내역!$H$3:$H$1002,MATCH("R"&36,미반납현황!$M$6:$M$1005,0)),"")) | I41: =IF($B41="","",IFERROR(INDEX(대여내역!$K$3:$K$1002,MATCH("R"&36,미반납현황!$M$6:$M$1005,0)),"")) | K41: =IF(대여내역!$A38="",FALSE(),OR(대여내역!$L38="미반납",대여내역!$L38="부분반납")) -> FALSE | L41: =IF($K41=FALSE(),"",COUNTIF($K$6:$K41,TRUE())) | M41: =IF($L41="","","R"&$L41)
A42: =IF($B42="","",37) | B42: =IFERROR(INDEX(대여내역!$A$3:$A$1002,MATCH("R"&37,미반납현황!$M$6:$M$1005,0)),"") | C42: =IF($B42="","",IFERROR(INDEX(대여내역!$B$3:$B$1002,MATCH("R"&37,미반납현황!$M$6:$M$1005,0)),"")) | D42: =IF($B42="","",IFERROR(INDEX(대여내역!$C$3:$C$1002,MATCH("R"&37,미반납현황!$M$6:$M$1005,0)),"")) | E42: =IF($B42="","",IFERROR(INDEX(대여내역!$E$3:$E$1002,MATCH("R"&37,미반납현황!$M$6:$M$1005,0)),"")) | F42: =IF($B42="","",IFERROR(INDEX(대여내역!$G$3:$G$1002,MATCH("R"&37,미반납현황!$M$6:$M$1005,0)),"")) | G42: =IF($B42="","",IFERROR(INDEX(대여내역!$J$3:$J$1002,MATCH("R"&37,미반납현황!$M$6:$M$1005,0)),"")) | H42: =IF($B42="","",IFERROR(INDEX(대여내역!$H$3:$H$1002,MATCH("R"&37,미반납현황!$M$6:$M$1005,0)),"")) | I42: =IF($B42="","",IFERROR(INDEX(대여내역!$K$3:$K$1002,MATCH("R"&37,미반납현황!$M$6:$M$1005,0)),"")) | K42: =IF(대여내역!$A39="",FALSE(),OR(대여내역!$L39="미반납",대여내역!$L39="부분반납")) -> FALSE | L42: =IF($K42=FALSE(),"",COUNTIF($K$6:$K42,TRUE())) | M42: =IF($L42="","","R"&$L42)
...

Sheet 품목별현황
A1: 품목별현황
A3: 품번 | B3: 품명 | C3: 단위 | D3: 보유수량 | E3: 대여중 | F3: 총 대여 | G3: 총 반납
A4: =IF(품목목록!$A3="","",품목목록!$A3) -> S001 | B4: =IF($A4="","",품목목록!$B3) -> 원단 샘플북 A | C4: =IF($A4="","",품목목록!$D3) -> 권 | D4: =IF($A4="","",IF(품목목록!$E3="",0,품목목록!$E3)) -> 10 | E4: =IF($A4="","",SUMIFS(대여내역!$J$3:$J$1002,대여내역!$D$3:$D$1002,$A4,대여내역!$J$3:$J$1002,">0")) -> 2 | F4: =IF($A4="","",SUMIFS(대여내역!$G$3:$G$1002,대여내역!$D$3:$D$1002,$A4)) -> 5 | G4: =IF($A4="","",SUMIFS(대여내역!$I$3:$I$1002,대여내역!$D$3:$D$1002,$A4)) -> 3
A5: =IF(품목목록!$A4="","",품목목록!$A4) -> S002 | B5: =IF($A5="","",품목목록!$B4) -> 컬러칩 세트 | C5: =IF($A5="","",품목목록!$D4) -> 세트 | D5: =IF($A5="","",IF(품목목록!$E4="",0,품목목록!$E4)) -> 5 | E5: =IF($A5="","",SUMIFS(대여내역!$J$3:$J$1002,대여내역!$D$3:$D$1002,$A5,대여내역!$J$3:$J$1002,">0")) -> 2 | F5: =IF($A5="","",SUMIFS(대여내역!$G$3:$G$1002,대여내역!$D$3:$D$1002,$A5)) -> 2 | G5: =IF($A5="","",SUMIFS(대여내역!$I$3:$I$1002,대여내역!$D$3:$D$1002,$A5)) -> 0
A6: =IF(품목목록!$A5="","",품목목록!$A5) -> S003 | B6: =IF($A6="","",품목목록!$B5) -> 시연용 노트북 | C6: =IF($A6="","",품목목록!$D5) -> 대 | D6: =IF($A6="","",IF(품목목록!$E5="",0,품목목록!$E5)) -> 3 | E6: =IF($A6="","",SUMIFS(대여내역!$J$3:$J$1002,대여내역!$D$3:$D$1002,$A6,대여내역!$J$3:$J$1002,">0")) -> 0 | F6: =IF($A6="","",SUMIFS(대여내역!$G$3:$G$1002,대여내역!$D$3:$D$1002,$A6)) -> 1 | G6: =IF($A6="","",SUMIFS(대여내역!$I$3:$I$1002,대여내역!$D$3:$D$1002,$A6)) -> 1
A7: =IF(품목목록!$A6="","",품목목록!$A6) | B7: =IF($A7="","",품목목록!$B6) | C7: =IF($A7="","",품목목록!$D6) | D7: =IF($A7="","",IF(품목목록!$E6="",0,품목목록!$E6)) | E7: =IF($A7="","",SUMIFS(대여내역!$J$3:$J$1002,대여내역!$D$3:$D$1002,$A7,대여내역!$J$3:$J$1002,">0")) | F7: =IF($A7="","",SUMIFS(대여내역!$G$3:$G$1002,대여내역!$D$3:$D$1002,$A7)) | G7: =IF($A7="","",SUMIFS(대여내역!$I$3:$I$1002,대여내역!$D$3:$D$1002,$A7))
A8: =IF(품목목록!$A7="","",품목목록!$A7) | B8: =IF($A8="","",품목목록!$B7) | C8: =IF($A8="","",품목목록!$D7) | D8: =IF($A8="","",IF(품목목록!$E7="",0,품목목록!$E7)) | E8: =IF($A8="","",SUMIFS(대여내역!$J$3:$J$1002,대여내역!$D$3:$D$1002,$A8,대여내역!$J$3:$J$1002,">0")) | F8: =IF($A8="","",SUMIFS(대여내역!$G$3:$G$1002,대여내역!$D$3:$D$1002,$A8)) | G8: =IF($A8="","",SUMIFS(대여내역!$I$3:$I$1002,대여내역!$D$3:$D$1002,$A8))
A9: =IF(품목목록!$A8="","",품목목록!$A8) | B9: =IF($A9="","",품목목록!$B8) | C9: =IF($A9="","",품목목록!$D8) | D9: =IF($A9="","",IF(품목목록!$E8="",0,품목목록!$E8)) | E9: =IF($A9="","",SUMIFS(대여내역!$J$3:$J$1002,대여내역!$D$3:$D$1002,$A9,대여내역!$J$3:$J$1002,">0")) | F9: =IF($A9="","",SUMIFS(대여내역!$G$3:$G$1002,대여내역!$D$3:$D$1002,$A9)) | G9: =IF($A9="","",SUMIFS(대여내역!$I$3:$I$1002,대여내역!$D$3:$D$1002,$A9))
A10: =IF(품목목록!$A9="","",품목목록!$A9) | B10: =IF($A10="","",품목목록!$B9) | C10: =IF($A10="","",품목목록!$D9) | D10: =IF($A10="","",IF(품목목록!$E9="",0,품목목록!$E9)) | E10: =IF($A10="","",SUMIFS(대여내역!$J$3:$J$1002,대여내역!$D$3:$D$1002,$A10,대여내역!$J$3:$J$1002,">0")) | F10: =IF($A10="","",SUMIFS(대여내역!$G$3:$G$1002,대여내역!$D$3:$D$1002,$A10)) | G10: =IF($A10="","",SUMIFS(대여내역!$I$3:$I$1002,대여내역!$D$3:$D$1002,$A10))
A11: =IF(품목목록!$A10="","",품목목록!$A10) | B11: =IF($A11="","",품목목록!$B10) | C11: =IF($A11="","",품목목록!$D10) | D11: =IF($A11="","",IF(품목목록!$E10="",0,품목목록!$E10)) | E11: =IF($A11="","",SUMIFS(대여내역!$J$3:$J$1002,대여내역!$D$3:$D$1002,$A11,대여내역!$J$3:$J$1002,">0")) | F11: =IF($A11="","",SUMIFS(대여내역!$G$3:$G$1002,대여내역!$D$3:$D$1002,$A11)) | G11: =IF($A11="","",SUMIFS(대여내역!$I$3:$I$1002,대여내역!$D$3:$D$1002,$A11))
A12: =IF(품목목록!$A11="","",품목목록!$A11) | B12: =IF($A12="","",품목목록!$B11) | C12: =IF($A12="","",품목목록!$D11) | D12: =IF($A12="","",IF(품목목록!$E11="",0,품목목록!$E11)) | E12: =IF($A12="","",SUMIFS(대여내역!$J$3:$J$1002,대여내역!$D$3:$D$1002,$A12,대여내역!$J$3:$J$1002,">0")) | F12: =IF($A12="","",SUMIFS(대여내역!$G$3:$G$1002,대여내역!$D$3:$D$1002,$A12)) | G12: =IF($A12="","",SUMIFS(대여내역!$I$3:$I$1002,대여내역!$D$3:$D$1002,$A12))
A13: =IF(품목목록!$A12="","",품목목록!$A12) | B13: =IF($A13="","",품목목록!$B12) | C13: =IF($A13="","",품목목록!$D12) | D13: =IF($A13="","",IF(품목목록!$E12="",0,품목목록!$E12)) | E13: =IF($A13="","",SUMIFS(대여내역!$J$3:$J$1002,대여내역!$D$3:$D$1002,$A13,대여내역!$J$3:$J$1002,">0")) | F13: =IF($A13="","",SUMIFS(대여내역!$G$3:$G$1002,대여내역!$D$3:$D$1002,$A13)) | G13: =IF($A13="","",SUMIFS(대여내역!$I$3:$I$1002,대여내역!$D$3:$D$1002,$A13))
A14: =IF(품목목록!$A13="","",품목목록!$A13) | B14: =IF($A14="","",품목목록!$B13) | C14: =IF($A14="","",품목목록!$D13) | D14: =IF($A14="","",IF(품목목록!$E13="",0,품목목록!$E13)) | E14: =IF($A14="","",SUMIFS(대여내역!$J$3:$J$1002,대여내역!$D$3:$D$1002,$A14,대여내역!$J$3:$J$1002,">0")) | F14: =IF($A14="","",SUMIFS(대여내역!$G$3:$G$1002,대여내역!$D$3:$D$1002,$A14)) | G14: =IF($A14="","",SUMIFS(대여내역!$I$3:$I$1002,대여내역!$D$3:$D$1002,$A14))
A15: =IF(품목목록!$A14="","",품목목록!$A14) | B15: =IF($A15="","",품목목록!$B14) | C15: =IF($A15="","",품목목록!$D14) | D15: =IF($A15="","",IF(품목목록!$E14="",0,품목목록!$E14)) | E15: =IF($A15="","",SUMIFS(대여내역!$J$3:$J$1002,대여내역!$D$3:$D$1002,$A15,대여내역!$J$3:$J$1002,">0")) | F15: =IF($A15="","",SUMIFS(대여내역!$G$3:$G$1002,대여내역!$D$3:$D$1002,$A15)) | G15: =IF($A15="","",SUMIFS(대여내역!$I$3:$I$1002,대여내역!$D$3:$D$1002,$A15))
... A203: =IF(품목목록!$A202="","",품목목록!$A202) | B203: =IF($A203="","",품목목록!$B202) | C203: =IF($A203="","",품목목록!$D202) | D203: =IF($A203="","",IF(품목목록!$E202="",0,품목목록!$E202)) | E203: =IF($A203="","",SUMIFS(대여내역!$J$3:$J$1002,대여내역!$D$3:$D$1002,$A203,대여내역!$J$3:$J$1002,">0")) | F203: =IF($A203="","",SUMIFS(대여내역!$G$3:$G$1002,대여내역!$D$3:$D$1002,$A203)) | G203: =IF($A203="","",SUMIFS(대여내역!$I$3:$I$1002,대여내역!$D$3:$D$1002,$A203))

Sheet 대여처별현황
A1: 대여처별현황
A3: 대여처 | B3: 담당자 | C3: 대여 건수 | D3: 미반납 건수 | E3: 미반납 수량 | F3: 반납률
A4: =IF(대여처목록!$A3="","",대여처목록!$A3) -> ○○상사 | B4: =IF($A4="","",대여처목록!$B3) -> 김과장 | C4: =IF($A4="","",COUNTIFS(대여내역!$C$3:$C$1002,$A4)) -> 2 | D4: =IF($A4="","",COUNTIFS(대여내역!$C$3:$C$1002,$A4,대여내역!$J$3:$J$1002,">0")) -> 1 | E4: =IF($A4="","",SUMIFS(대여내역!$J$3:$J$1002,대여내역!$C$3:$C$1002,$A4,대여내역!$J$3:$J$1002,">0")) -> 2 | F4: =IF($A4="","",IF(SUMIFS(대여내역!$G$3:$G$1002,대여내역!$C$3:$C$1002,$A4)=0,"",SUMIFS(대여내역!$I$3:$I$1002,대여내역!$C$3:$C$1002,$A4)/SUMIFS(대여내역!$G$3:$G$1002,대여내역!$C$3:$C$1002,$A4))) -> 0.6
A5: =IF(대여처목록!$A4="","",대여처목록!$A4) -> △△디자인 | B5: =IF($A5="","",대여처목록!$B4) -> 이대리 | C5: =IF($A5="","",COUNTIFS(대여내역!$C$3:$C$1002,$A5)) -> 1 | D5: =IF($A5="","",COUNTIFS(대여내역!$C$3:$C$1002,$A5,대여내역!$J$3:$J$1002,">0")) -> 1 | E5: =IF($A5="","",SUMIFS(대여내역!$J$3:$J$1002,대여내역!$C$3:$C$1002,$A5,대여내역!$J$3:$J$1002,">0")) -> 2 | F5: =IF($A5="","",IF(SUMIFS(대여내역!$G$3:$G$1002,대여내역!$C$3:$C$1002,$A5)=0,"",SUMIFS(대여내역!$I$3:$I$1002,대여내역!$C$3:$C$1002,$A5)/SUMIFS(대여내역!$G$3:$G$1002,대여내역!$C$3:$C$1002,$A5))) -> 0
A6: =IF(대여처목록!$A5="","",대여처목록!$A5) -> 영업2팀 | B6: =IF($A6="","",대여처목록!$B5) -> 박주임 | C6: =IF($A6="","",COUNTIFS(대여내역!$C$3:$C$1002,$A6)) -> 1 | D6: =IF($A6="","",COUNTIFS(대여내역!$C$3:$C$1002,$A6,대여내역!$J$3:$J$1002,">0")) -> 0 | E6: =IF($A6="","",SUMIFS(대여내역!$J$3:$J$1002,대여내역!$C$3:$C$1002,$A6,대여내역!$J$3:$J$1002,">0")) -> 0 | F6: =IF($A6="","",IF(SUMIFS(대여내역!$G$3:$G$1002,대여내역!$C$3:$C$1002,$A6)=0,"",SUMIFS(대여내역!$I$3:$I$1002,대여내역!$C$3:$C$1002,$A6)/SUMIFS(대여내역!$G$3:$G$1002,대여내역!$C$3:$C$1002,$A6))) -> 1
A7: =IF(대여처목록!$A6="","",대여처목록!$A6) | B7: =IF($A7="","",대여처목록!$B6) | C7: =IF($A7="","",COUNTIFS(대여내역!$C$3:$C$1002,$A7)) | D7: =IF($A7="","",COUNTIFS(대여내역!$C$3:$C$1002,$A7,대여내역!$J$3:$J$1002,">0")) | E7: =IF($A7="","",SUMIFS(대여내역!$J$3:$J$1002,대여내역!$C$3:$C$1002,$A7,대여내역!$J$3:$J$1002,">0")) | F7: =IF($A7="","",IF(SUMIFS(대여내역!$G$3:$G$1002,대여내역!$C$3:$C$1002,$A7)=0,"",SUMIFS(대여내역!$I$3:$I$1002,대여내역!$C$3:$C$1002,$A7)/SUMIFS(대여내역!$G$3:$G$1002,대여내역!$C$3:$C$1002,$A7)))
A8: =IF(대여처목록!$A7="","",대여처목록!$A7) | B8: =IF($A8="","",대여처목록!$B7) | C8: =IF($A8="","",COUNTIFS(대여내역!$C$3:$C$1002,$A8)) | D8: =IF($A8="","",COUNTIFS(대여내역!$C$3:$C$1002,$A8,대여내역!$J$3:$J$1002,">0")) | E8: =IF($A8="","",SUMIFS(대여내역!$J$3:$J$1002,대여내역!$C$3:$C$1002,$A8,대여내역!$J$3:$J$1002,">0")) | F8: =IF($A8="","",IF(SUMIFS(대여내역!$G$3:$G$1002,대여내역!$C$3:$C$1002,$A8)=0,"",SUMIFS(대여내역!$I$3:$I$1002,대여내역!$C$3:$C$1002,$A8)/SUMIFS(대여내역!$G$3:$G$1002,대여내역!$C$3:$C$1002,$A8)))
A9: =IF(대여처목록!$A8="","",대여처목록!$A8) | B9: =IF($A9="","",대여처목록!$B8) | C9: =IF($A9="","",COUNTIFS(대여내역!$C$3:$C$1002,$A9)) | D9: =IF($A9="","",COUNTIFS(대여내역!$C$3:$C$1002,$A9,대여내역!$J$3:$J$1002,">0")) | E9: =IF($A9="","",SUMIFS(대여내역!$J$3:$J$1002,대여내역!$C$3:$C$1002,$A9,대여내역!$J$3:$J$1002,">0")) | F9: =IF($A9="","",IF(SUMIFS(대여내역!$G$3:$G$1002,대여내역!$C$3:$C$1002,$A9)=0,"",SUMIFS(대여내역!$I$3:$I$1002,대여내역!$C$3:$C$1002,$A9)/SUMIFS(대여내역!$G$3:$G$1002,대여내역!$C$3:$C$1002,$A9)))
A10: =IF(대여처목록!$A9="","",대여처목록!$A9) | B10: =IF($A10="","",대여처목록!$B9) | C10: =IF($A10="","",COUNTIFS(대여내역!$C$3:$C$1002,$A10)) | D10: =IF($A10="","",COUNTIFS(대여내역!$C$3:$C$1002,$A10,대여내역!$J$3:$J$1002,">0")) | E10: =IF($A10="","",SUMIFS(대여내역!$J$3:$J$1002,대여내역!$C$3:$C$1002,$A10,대여내역!$J$3:$J$1002,">0")) | F10: =IF($A10="","",IF(SUMIFS(대여내역!$G$3:$G$1002,대여내역!$C$3:$C$1002,$A10)=0,"",SUMIFS(대여내역!$I$3:$I$1002,대여내역!$C$3:$C$1002,$A10)/SUMIFS(대여내역!$G$3:$G$1002,대여내역!$C$3:$C$1002,$A10)))
A11: =IF(대여처목록!$A10="","",대여처목록!$A10) | B11: =IF($A11="","",대여처목록!$B10) | C11: =IF($A11="","",COUNTIFS(대여내역!$C$3:$C$1002,$A11)) | D11: =IF($A11="","",COUNTIFS(대여내역!$C$3:$C$1002,$A11,대여내역!$J$3:$J$1002,">0")) | E11: =IF($A11="","",SUMIFS(대여내역!$J$3:$J$1002,대여내역!$C$3:$C$1002,$A11,대여내역!$J$3:$J$1002,">0")) | F11: =IF($A11="","",IF(SUMIFS(대여내역!$G$3:$G$1002,대여내역!$C$3:$C$1002,$A11)=0,"",SUMIFS(대여내역!$I$3:$I$1002,대여내역!$C$3:$C$1002,$A11)/SUMIFS(대여내역!$G$3:$G$1002,대여내역!$C$3:$C$1002,$A11)))
A12: =IF(대여처목록!$A11="","",대여처목록!$A11) | B12: =IF($A12="","",대여처목록!$B11) | C12: =IF($A12="","",COUNTIFS(대여내역!$C$3:$C$1002,$A12)) | D12: =IF($A12="","",COUNTIFS(대여내역!$C$3:$C$1002,$A12,대여내역!$J$3:$J$1002,">0")) | E12: =IF($A12="","",SUMIFS(대여내역!$J$3:$J$1002,대여내역!$C$3:$C$1002,$A12,대여내역!$J$3:$J$1002,">0")) | F12: =IF($A12="","",IF(SUMIFS(대여내역!$G$3:$G$1002,대여내역!$C$3:$C$1002,$A12)=0,"",SUMIFS(대여내역!$I$3:$I$1002,대여내역!$C$3:$C$1002,$A12)/SUMIFS(대여내역!$G$3:$G$1002,대여내역!$C$3:$C$1002,$A12)))
A13: =IF(대여처목록!$A12="","",대여처목록!$A12) | B13: =IF($A13="","",대여처목록!$B12) | C13: =IF($A13="","",COUNTIFS(대여내역!$C$3:$C$1002,$A13)) | D13: =IF($A13="","",COUNTIFS(대여내역!$C$3:$C$1002,$A13,대여내역!$J$3:$J$1002,">0")) | E13: =IF($A13="","",SUMIFS(대여내역!$J$3:$J$1002,대여내역!$C$3:$C$1002,$A13,대여내역!$J$3:$J$1002,">0")) | F13: =IF($A13="","",IF(SUMIFS(대여내역!$G$3:$G$1002,대여내역!$C$3:$C$1002,$A13)=0,"",SUMIFS(대여내역!$I$3:$I$1002,대여내역!$C$3:$C$1002,$A13)/SUMIFS(대여내역!$G$3:$G$1002,대여내역!$C$3:$C$1002,$A13)))
A14: =IF(대여처목록!$A13="","",대여처목록!$A13) | B14: =IF($A14="","",대여처목록!$B13) | C14: =IF($A14="","",COUNTIFS(대여내역!$C$3:$C$1002,$A14)) | D14: =IF($A14="","",COUNTIFS(대여내역!$C$3:$C$1002,$A14,대여내역!$J$3:$J$1002,">0")) | E14: =IF($A14="","",SUMIFS(대여내역!$J$3:$J$1002,대여내역!$C$3:$C$1002,$A14,대여내역!$J$3:$J$1002,">0")) | F14: =IF($A14="","",IF(SUMIFS(대여내역!$G$3:$G$1002,대여내역!$C$3:$C$1002,$A14)=0,"",SUMIFS(대여내역!$I$3:$I$1002,대여내역!$C$3:$C$1002,$A14)/SUMIFS(대여내역!$G$3:$G$1002,대여내역!$C$3:$C$1002,$A14)))
A15: =IF(대여처목록!$A14="","",대여처목록!$A14) | B15: =IF($A15="","",대여처목록!$B14) | C15: =IF($A15="","",COUNTIFS(대여내역!$C$3:$C$1002,$A15)) | D15: =IF($A15="","",COUNTIFS(대여내역!$C$3:$C$1002,$A15,대여내역!$J$3:$J$1002,">0")) | E15: =IF($A15="","",SUMIFS(대여내역!$J$3:$J$1002,대여내역!$C$3:$C$1002,$A15,대여내역!$J$3:$J$1002,">0")) | F15: =IF($A15="","",IF(SUMIFS(대여내역!$G$3:$G$1002,대여내역!$C$3:$C$1002,$A15)=0,"",SUMIFS(대여내역!$I$3:$I$1002,대여내역!$C$3:$C$1002,$A15)/SUMIFS(대여내역!$G$3:$G$1002,대여내역!$C$3:$C$1002,$A15)))
... A203: =IF(대여처목록!$A202="","",대여처목록!$A202) | B203: =IF($A203="","",대여처목록!$B202) | C203: =IF($A203="","",COUNTIFS(대여내역!$C$3:$C$1002,$A203)) | D203: =IF($A203="","",COUNTIFS(대여내역!$C$3:$C$1002,$A203,대여내역!$J$3:$J$1002,">0")) | E203: =IF($A203="","",SUMIFS(대여내역!$J$3:$J$1002,대여내역!$C$3:$C$1002,$A203,대여내역!$J$3:$J$1002,">0")) | F203: =IF($A203="","",IF(SUMIFS(대여내역!$G$3:$G$1002,대여내역!$C$3:$C$1002,$A203)=0,"",SUMIFS(대여내역!$I$3:$I$1002,대여내역!$C$3:$C$1002,$A203)/SUMIFS(대여내역!$G$3:$G$1002,대여내역!$C$3:$C$1002,$A203)))
