Workbook

Sheet 사용안내
B2: 프로젝트별 투입시간 집계
B4: 핵심 | C4: 누가 어느 프로젝트에 몇 시간 썼는지만 넣으면 프로젝트별·사람별·월별로 자동 집계됩니다.
B5: 입력 규칙 | C5: 파란색 글씨 칸만 입력하세요. 검은색은 자동 계산입니다.
B6: ① 구성원목록 | C6: 이름·소속·직위를 등록합니다.
B7: ② 프로젝트목록 | C7: 프로젝트명·기간·예상 투입시간을 등록합니다.
B8: ③ 업무일지 | C8: 일한 날마다 한 줄. 시작·종료 시각을 넣으면 시간이 자동 계산됩니다.
C9: 시각은 콜론(:) 없이 숫자 네 자리로 넣으세요. 오전 9시 → 900, 오후 6시 → 1800
B10: ④ 프로젝트별집계 | C10: 프로젝트별 총 투입시간과 예상 대비 진행 상황입니다.
B11: ⑤ 담당자별집계 | C11: 사람별로 어느 프로젝트에 얼마나 썼는지 나옵니다.
B12: ⑥ 월별집계 | C12: 월별 총 투입시간입니다.
B13: ⑦ 교차집계 | C13: 프로젝트 × 담당자 표입니다. 누가 어디에 붙어 있는지 한눈에 보입니다.
B15: ※ 업무일지 3,000건 / 프로젝트 60개 / 구성원 40명까지 처리합니다.

Sheet 구성원목록
A1: 구성원목록
A2: 이름 | B2: 소속 | C2: 직위 | D2: 비고
A3: 김담당 | B3: 기획팀 | C3: 대리
A4: 이담당 | B4: 개발팀 | C4: 과장
A5: 박담당 | B5: 디자인팀 | C5: 주임

Sheet 프로젝트목록
A1: 프로젝트목록
A2: 코드 | B2: 프로젝트명 | C2: 시작일 | D2: 종료일 | E2: 예상 투입시간 | F2: 상태
A3: PJ01 | B3: OO운영사업 | C3: 46204 | D3: 46387 | E3: 800 | F3: 진행
A4: PJ02 | B4: 신규 앱 개발 | C4: 46266 | D4: 46477 | E4: 1200 | F4: 진행
A5: PJ03 | B5: 홈페이지 개편 | C5: 46235 | D5: 46326 | E5: 300 | F5: 진행

Sheet 업무일지
A1: 업무일지 (일한 날마다 한 줄)
A2: 작업일 | B2: 이름 | C2: 프로젝트코드 | D2: 프로젝트명(자동) | E2: 업무내용 | F2: 시작시각 (예: 900) | G2: 종료시각 (예: 1800) | H2: 휴게(분) | I2: 투입시간(자동) | J2: 시작(분,자동) | K2: 종료(분,자동)
A3: 46266 | B3: 김담당 | C3: PJ01 | D3: =IF($C3="","",IFERROR(INDEX(프로젝트목록!$B$3:$B$62,MATCH($C3,프로젝트목록!$A$3:$A$62,0)),"미등록코드")) -> OO운영사업 | E3: 요구사항 정리 | F3: 900 | G3: 1800 | H3: 60 | I3: =IF(OR($J3="",$K3=""),"",ROUND(MAX(0,($K3-$J3)-IF($H3="",0,$H3))/60,2)) -> 8 | J3: =IF($F3="","",IF($F3<1,ROUND($F3*1440,0),INT($F3/100)*60+MOD($F3,100))) -> 540 | K3: =IF($G3="","",IF($G3<1,ROUND($G3*1440,0),INT($G3/100)*60+MOD($G3,100))) -> 1080
A4: 46266 | B4: 이담당 | C4: PJ02 | D4: =IF($C4="","",IFERROR(INDEX(프로젝트목록!$B$3:$B$62,MATCH($C4,프로젝트목록!$A$3:$A$62,0)),"미등록코드")) -> 신규 앱 개발 | E4: 설계 | F4: 900 | G4: 1900 | H4: 60 | I4: =IF(OR($J4="",$K4=""),"",ROUND(MAX(0,($K4-$J4)-IF($H4="",0,$H4))/60,2)) -> 9 | J4: =IF($F4="","",IF($F4<1,ROUND($F4*1440,0),INT($F4/100)*60+MOD($F4,100))) -> 540 | K4: =IF($G4="","",IF($G4<1,ROUND($G4*1440,0),INT($G4/100)*60+MOD($G4,100))) -> 1140
A5: 46267 | B5: 김담당 | C5: PJ01 | D5: =IF($C5="","",IFERROR(INDEX(프로젝트목록!$B$3:$B$62,MATCH($C5,프로젝트목록!$A$3:$A$62,0)),"미등록코드")) -> OO운영사업 | E5: 회의 | F5: 1000 | G5: 1200 | H5: 0 | I5: =IF(OR($J5="",$K5=""),"",ROUND(MAX(0,($K5-$J5)-IF($H5="",0,$H5))/60,2)) -> 2 | J5: =IF($F5="","",IF($F5<1,ROUND($F5*1440,0),INT($F5/100)*60+MOD($F5,100))) -> 600 | K5: =IF($G5="","",IF($G5<1,ROUND($G5*1440,0),INT($G5/100)*60+MOD($G5,100))) -> 720
A6: 46267 | B6: 김담당 | C6: PJ03 | D6: =IF($C6="","",IFERROR(INDEX(프로젝트목록!$B$3:$B$62,MATCH($C6,프로젝트목록!$A$3:$A$62,0)),"미등록코드")) -> 홈페이지 개편 | E6: 기획서 작성 | F6: 1300 | G6: 1800 | H6: 0 | I6: =IF(OR($J6="",$K6=""),"",ROUND(MAX(0,($K6-$J6)-IF($H6="",0,$H6))/60,2)) -> 5 | J6: =IF($F6="","",IF($F6<1,ROUND($F6*1440,0),INT($F6/100)*60+MOD($F6,100))) -> 780 | K6: =IF($G6="","",IF($G6<1,ROUND($G6*1440,0),INT($G6/100)*60+MOD($G6,100))) -> 1080
A7: 46258 | B7: 김담당 | C7: PJ01 | D7: =IF($C7="","",IFERROR(INDEX(프로젝트목록!$B$3:$B$62,MATCH($C7,프로젝트목록!$A$3:$A$62,0)),"미등록코드")) -> OO운영사업 | E7: 현황 분석 | F7: 900 | G7: 1800 | H7: 60 | I7: =IF(OR($J7="",$K7=""),"",ROUND(MAX(0,($K7-$J7)-IF($H7="",0,$H7))/60,2)) -> 8 | J7: =IF($F7="","",IF($F7<1,ROUND($F7*1440,0),INT($F7/100)*60+MOD($F7,100))) -> 540 | K7: =IF($G7="","",IF($G7<1,ROUND($G7*1440,0),INT($G7/100)*60+MOD($G7,100))) -> 1080
A8: 46259 | B8: 김담당 | C8: PJ01 | D8: =IF($C8="","",IFERROR(INDEX(프로젝트목록!$B$3:$B$62,MATCH($C8,프로젝트목록!$A$3:$A$62,0)),"미등록코드")) -> OO운영사업 | E8: 인터뷰 정리 | F8: 900 | G8: 1800 | H8: 60 | I8: =IF(OR($J8="",$K8=""),"",ROUND(MAX(0,($K8-$J8)-IF($H8="",0,$H8))/60,2)) -> 8 | J8: =IF($F8="","",IF($F8<1,ROUND($F8*1440,0),INT($F8/100)*60+MOD($F8,100))) -> 540 | K8: =IF($G8="","",IF($G8<1,ROUND($G8*1440,0),INT($G8/100)*60+MOD($G8,100))) -> 1080
A9: 46260 | B9: 이담당 | C9: PJ02 | D9: =IF($C9="","",IFERROR(INDEX(프로젝트목록!$B$3:$B$62,MATCH($C9,프로젝트목록!$A$3:$A$62,0)),"미등록코드")) -> 신규 앱 개발 | E9: 화면 설계 | F9: 900 | G9: 1830 | H9: 60 | I9: =IF(OR($J9="",$K9=""),"",ROUND(MAX(0,($K9-$J9)-IF($H9="",0,$H9))/60,2)) -> 8.5 | J9: =IF($F9="","",IF($F9<1,ROUND($F9*1440,0),INT($F9/100)*60+MOD($F9,100))) -> 540 | K9: =IF($G9="","",IF($G9<1,ROUND($G9*1440,0),INT($G9/100)*60+MOD($G9,100))) -> 1110
A10: 46261 | B10: 이담당 | C10: PJ02 | D10: =IF($C10="","",IFERROR(INDEX(프로젝트목록!$B$3:$B$62,MATCH($C10,프로젝트목록!$A$3:$A$62,0)),"미등록코드")) -> 신규 앱 개발 | E10: 화면 설계 | F10: 900 | G10: 1800 | H10: 60 | I10: =IF(OR($J10="",$K10=""),"",ROUND(MAX(0,($K10-$J10)-IF($H10="",0,$H10))/60,2)) -> 8 | J10: =IF($F10="","",IF($F10<1,ROUND($F10*1440,0),INT($F10/100)*60+MOD($F10,100))) -> 540 | K10: =IF($G10="","",IF($G10<1,ROUND($G10*1440,0),INT($G10/100)*60+MOD($G10,100))) -> 1080
A11: 46262 | B11: 박담당 | C11: PJ03 | D11: =IF($C11="","",IFERROR(INDEX(프로젝트목록!$B$3:$B$62,MATCH($C11,프로젝트목록!$A$3:$A$62,0)),"미등록코드")) -> 홈페이지 개편 | E11: 디자인 시안 | F11: 1000 | G11: 1900 | H11: 60 | I11: =IF(OR($J11="",$K11=""),"",ROUND(MAX(0,($K11-$J11)-IF($H11="",0,$H11))/60,2)) -> 8 | J11: =IF($F11="","",IF($F11<1,ROUND($F11*1440,0),INT($F11/100)*60+MOD($F11,100))) -> 600 | K11: =IF($G11="","",IF($G11<1,ROUND($G11*1440,0),INT($G11/100)*60+MOD($G11,100))) -> 1140
A12: 46265 | B12: 김담당 | C12: PJ01 | D12: =IF($C12="","",IFERROR(INDEX(프로젝트목록!$B$3:$B$62,MATCH($C12,프로젝트목록!$A$3:$A$62,0)),"미등록코드")) -> OO운영사업 | E12: 요건 검토 회의 | F12: 900 | G12: 1700 | H12: 60 | I12: =IF(OR($J12="",$K12=""),"",ROUND(MAX(0,($K12-$J12)-IF($H12="",0,$H12))/60,2)) -> 7 | J12: =IF($F12="","",IF($F12<1,ROUND($F12*1440,0),INT($F12/100)*60+MOD($F12,100))) -> 540 | K12: =IF($G12="","",IF($G12<1,ROUND($G12*1440,0),INT($G12/100)*60+MOD($G12,100))) -> 1020
A13: 46267 | B13: 이담당 | C13: PJ02 | D13: =IF($C13="","",IFERROR(INDEX(프로젝트목록!$B$3:$B$62,MATCH($C13,프로젝트목록!$A$3:$A$62,0)),"미등록코드")) -> 신규 앱 개발 | E13: 데이터 모델링 | F13: 900 | G13: 1900 | H13: 60 | I13: =IF(OR($J13="",$K13=""),"",ROUND(MAX(0,($K13-$J13)-IF($H13="",0,$H13))/60,2)) -> 9 | J13: =IF($F13="","",IF($F13<1,ROUND($F13*1440,0),INT($F13/100)*60+MOD($F13,100))) -> 540 | K13: =IF($G13="","",IF($G13<1,ROUND($G13*1440,0),INT($G13/100)*60+MOD($G13,100))) -> 1140
A14: 46268 | B14: 박담당 | C14: PJ03 | D14: =IF($C14="","",IFERROR(INDEX(프로젝트목록!$B$3:$B$62,MATCH($C14,프로젝트목록!$A$3:$A$62,0)),"미등록코드")) -> 홈페이지 개편 | E14: 시안 수정 | F14: 900 | G14: 1800 | H14: 60 | I14: =IF(OR($J14="",$K14=""),"",ROUND(MAX(0,($K14-$J14)-IF($H14="",0,$H14))/60,2)) -> 8 | J14: =IF($F14="","",IF($F14<1,ROUND($F14*1440,0),INT($F14/100)*60+MOD($F14,100))) -> 540 | K14: =IF($G14="","",IF($G14<1,ROUND($G14*1440,0),INT($G14/100)*60+MOD($G14,100))) -> 1080
... A21: 46279 | B21: 김담당 | C21: PJ01 | D21: =IF($C21="","",IFERROR(INDEX(프로젝트목록!$B$3:$B$62,MATCH($C21,프로젝트목록!$A$3:$A$62,0)),"미등록코드")) -> OO운영사업 | E21: 중간 보고 | F21: 1000 | G21: 1200 | H21: 0 | I21: =IF(OR($J21="",$K21=""),"",ROUND(MAX(0,($K21-$J21)-IF($H21="",0,$H21))/60,2)) -> 2 | J21: =IF($F21="","",IF($F21<1,ROUND($F21*1440,0),INT($F21/100)*60+MOD($F21,100))) -> 600 | K21: =IF($G21="","",IF($G21<1,ROUND($G21*1440,0),INT($G21/100)*60+MOD($G21,100))) -> 720
D22: =IF($C22="","",IFERROR(INDEX(프로젝트목록!$B$3:$B$62,MATCH($C22,프로젝트목록!$A$3:$A$62,0)),"미등록코드")) | I22: =IF(OR($J22="",$K22=""),"",ROUND(MAX(0,($K22-$J22)-IF($H22="",0,$H22))/60,2)) | J22: =IF($F22="","",IF($F22<1,ROUND($F22*1440,0),INT($F22/100)*60+MOD($F22,100))) | K22: =IF($G22="","",IF($G22<1,ROUND($G22*1440,0),INT($G22/100)*60+MOD($G22,100)))
D23: =IF($C23="","",IFERROR(INDEX(프로젝트목록!$B$3:$B$62,MATCH($C23,프로젝트목록!$A$3:$A$62,0)),"미등록코드")) | I23: =IF(OR($J23="",$K23=""),"",ROUND(MAX(0,($K23-$J23)-IF($H23="",0,$H23))/60,2)) | J23: =IF($F23="","",IF($F23<1,ROUND($F23*1440,0),INT($F23/100)*60+MOD($F23,100))) | K23: =IF($G23="","",IF($G23<1,ROUND($G23*1440,0),INT($G23/100)*60+MOD($G23,100)))
D24: =IF($C24="","",IFERROR(INDEX(프로젝트목록!$B$3:$B$62,MATCH($C24,프로젝트목록!$A$3:$A$62,0)),"미등록코드")) | I24: =IF(OR($J24="",$K24=""),"",ROUND(MAX(0,($K24-$J24)-IF($H24="",0,$H24))/60,2)) | J24: =IF($F24="","",IF($F24<1,ROUND($F24*1440,0),INT($F24/100)*60+MOD($F24,100))) | K24: =IF($G24="","",IF($G24<1,ROUND($G24*1440,0),INT($G24/100)*60+MOD($G24,100)))
D25: =IF($C25="","",IFERROR(INDEX(프로젝트목록!$B$3:$B$62,MATCH($C25,프로젝트목록!$A$3:$A$62,0)),"미등록코드")) | I25: =IF(OR($J25="",$K25=""),"",ROUND(MAX(0,($K25-$J25)-IF($H25="",0,$H25))/60,2)) | J25: =IF($F25="","",IF($F25<1,ROUND($F25*1440,0),INT($F25/100)*60+MOD($F25,100))) | K25: =IF($G25="","",IF($G25<1,ROUND($G25*1440,0),INT($G25/100)*60+MOD($G25,100)))
D26: =IF($C26="","",IFERROR(INDEX(프로젝트목록!$B$3:$B$62,MATCH($C26,프로젝트목록!$A$3:$A$62,0)),"미등록코드")) | I26: =IF(OR($J26="",$K26=""),"",ROUND(MAX(0,($K26-$J26)-IF($H26="",0,$H26))/60,2)) | J26: =IF($F26="","",IF($F26<1,ROUND($F26*1440,0),INT($F26/100)*60+MOD($F26,100))) | K26: =IF($G26="","",IF($G26<1,ROUND($G26*1440,0),INT($G26/100)*60+MOD($G26,100)))
D27: =IF($C27="","",IFERROR(INDEX(프로젝트목록!$B$3:$B$62,MATCH($C27,프로젝트목록!$A$3:$A$62,0)),"미등록코드")) | I27: =IF(OR($J27="",$K27=""),"",ROUND(MAX(0,($K27-$J27)-IF($H27="",0,$H27))/60,2)) | J27: =IF($F27="","",IF($F27<1,ROUND($F27*1440,0),INT($F27/100)*60+MOD($F27,100))) | K27: =IF($G27="","",IF($G27<1,ROUND($G27*1440,0),INT($G27/100)*60+MOD($G27,100)))
D28: =IF($C28="","",IFERROR(INDEX(프로젝트목록!$B$3:$B$62,MATCH($C28,프로젝트목록!$A$3:$A$62,0)),"미등록코드")) | I28: =IF(OR($J28="",$K28=""),"",ROUND(MAX(0,($K28-$J28)-IF($H28="",0,$H28))/60,2)) | J28: =IF($F28="","",IF($F28<1,ROUND($F28*1440,0),INT($F28/100)*60+MOD($F28,100))) | K28: =IF($G28="","",IF($G28<1,ROUND($G28*1440,0),INT($G28/100)*60+MOD($G28,100)))
D29: =IF($C29="","",IFERROR(INDEX(프로젝트목록!$B$3:$B$62,MATCH($C29,프로젝트목록!$A$3:$A$62,0)),"미등록코드")) | I29: =IF(OR($J29="",$K29=""),"",ROUND(MAX(0,($K29-$J29)-IF($H29="",0,$H29))/60,2)) | J29: =IF($F29="","",IF($F29<1,ROUND($F29*1440,0),INT($F29/100)*60+MOD($F29,100))) | K29: =IF($G29="","",IF($G29<1,ROUND($G29*1440,0),INT($G29/100)*60+MOD($G29,100)))
D30: =IF($C30="","",IFERROR(INDEX(프로젝트목록!$B$3:$B$62,MATCH($C30,프로젝트목록!$A$3:$A$62,0)),"미등록코드")) | I30: =IF(OR($J30="",$K30=""),"",ROUND(MAX(0,($K30-$J30)-IF($H30="",0,$H30))/60,2)) | J30: =IF($F30="","",IF($F30<1,ROUND($F30*1440,0),INT($F30/100)*60+MOD($F30,100))) | K30: =IF($G30="","",IF($G30<1,ROUND($G30*1440,0),INT($G30/100)*60+MOD($G30,100)))
D31: =IF($C31="","",IFERROR(INDEX(프로젝트목록!$B$3:$B$62,MATCH($C31,프로젝트목록!$A$3:$A$62,0)),"미등록코드")) | I31: =IF(OR($J31="",$K31=""),"",ROUND(MAX(0,($K31-$J31)-IF($H31="",0,$H31))/60,2)) | J31: =IF($F31="","",IF($F31<1,ROUND($F31*1440,0),INT($F31/100)*60+MOD($F31,100))) | K31: =IF($G31="","",IF($G31<1,ROUND($G31*1440,0),INT($G31/100)*60+MOD($G31,100)))
D32: =IF($C32="","",IFERROR(INDEX(프로젝트목록!$B$3:$B$62,MATCH($C32,프로젝트목록!$A$3:$A$62,0)),"미등록코드")) | I32: =IF(OR($J32="",$K32=""),"",ROUND(MAX(0,($K32-$J32)-IF($H32="",0,$H32))/60,2)) | J32: =IF($F32="","",IF($F32<1,ROUND($F32*1440,0),INT($F32/100)*60+MOD($F32,100))) | K32: =IF($G32="","",IF($G32<1,ROUND($G32*1440,0),INT($G32/100)*60+MOD($G32,100)))
D33: =IF($C33="","",IFERROR(INDEX(프로젝트목록!$B$3:$B$62,MATCH($C33,프로젝트목록!$A$3:$A$62,0)),"미등록코드")) | I33: =IF(OR($J33="",$K33=""),"",ROUND(MAX(0,($K33-$J33)-IF($H33="",0,$H33))/60,2)) | J33: =IF($F33="","",IF($F33<1,ROUND($F33*1440,0),INT($F33/100)*60+MOD($F33,100))) | K33: =IF($G33="","",IF($G33<1,ROUND($G33*1440,0),INT($G33/100)*60+MOD($G33,100)))
... D3002: =IF($C3002="","",IFERROR(INDEX(프로젝트목록!$B$3:$B$62,MATCH($C3002,프로젝트목록!$A$3:$A$62,0)),"미등록코드")) | I3002: =IF(OR($J3002="",$K3002=""),"",ROUND(MAX(0,($K3002-$J3002)-IF($H3002="",0,$H3002))/60,2)) | J3002: =IF($F3002="","",IF($F3002<1,ROUND($F3002*1440,0),INT($F3002/100)*60+MOD($F3002,100))) | K3002: =IF($G3002="","",IF($G3002<1,ROUND($G3002*1440,0),INT($G3002/100)*60+MOD($G3002,100)))

Sheet 프로젝트별집계
A1: 프로젝트별집계
A3: 코드 | B3: 프로젝트명 | C3: 상태 | D3: 예상시간 | E3: 투입시간 | F3: 잔여 | G3: 소진율 | H3: 참여 인원
A4: =IF(프로젝트목록!$A3="","",프로젝트목록!$A3) -> PJ01 | B4: =IF($A4="","",프로젝트목록!$B3) -> OO운영사업 | C4: =IF($A4="","",프로젝트목록!$F3) -> 진행 | D4: =IF($A4="","",IF(프로젝트목록!$E3="",0,프로젝트목록!$E3)) -> 800 | E4: =IF($A4="","",ROUND(SUMIFS(업무일지!$I$3:$I$3002,업무일지!$C$3:$C$3002,$A4),2)) -> 51.5 | F4: =IF($A4="","",ROUND($D4-$E4,2)) -> 748.5 | G4: =IF($A4="","",IF($D4=0,"",$E4/$D4)) -> 0.064375 | H4: =IF($A4="","",SUMPRODUCT((구성원목록!$A$3:$A$42<>"")*(COUNTIFS(업무일지!$C$3:$C$3002,$A4,업무일지!$B$3:$B$3002,구성원목록!$A$3:$A$42)>0))) -> 1
A5: =IF(프로젝트목록!$A4="","",프로젝트목록!$A4) -> PJ02 | B5: =IF($A5="","",프로젝트목록!$B4) -> 신규 앱 개발 | C5: =IF($A5="","",프로젝트목록!$F4) -> 진행 | D5: =IF($A5="","",IF(프로젝트목록!$E4="",0,프로젝트목록!$E4)) -> 1200 | E5: =IF($A5="","",ROUND(SUMIFS(업무일지!$I$3:$I$3002,업무일지!$C$3:$C$3002,$A5),2)) -> 52.5 | F5: =IF($A5="","",ROUND($D5-$E5,2)) -> 1147.5 | G5: =IF($A5="","",IF($D5=0,"",$E5/$D5)) -> 0.04375 | H5: =IF($A5="","",SUMPRODUCT((구성원목록!$A$3:$A$42<>"")*(COUNTIFS(업무일지!$C$3:$C$3002,$A5,업무일지!$B$3:$B$3002,구성원목록!$A$3:$A$42)>0))) -> 1
A6: =IF(프로젝트목록!$A5="","",프로젝트목록!$A5) -> PJ03 | B6: =IF($A6="","",프로젝트목록!$B5) -> 홈페이지 개편 | C6: =IF($A6="","",프로젝트목록!$F5) -> 진행 | D6: =IF($A6="","",IF(프로젝트목록!$E5="",0,프로젝트목록!$E5)) -> 300 | E6: =IF($A6="","",ROUND(SUMIFS(업무일지!$I$3:$I$3002,업무일지!$C$3:$C$3002,$A6),2)) -> 36.5 | F6: =IF($A6="","",ROUND($D6-$E6,2)) -> 263.5 | G6: =IF($A6="","",IF($D6=0,"",$E6/$D6)) -> 0.12166667 | H6: =IF($A6="","",SUMPRODUCT((구성원목록!$A$3:$A$42<>"")*(COUNTIFS(업무일지!$C$3:$C$3002,$A6,업무일지!$B$3:$B$3002,구성원목록!$A$3:$A$42)>0))) -> 2
A7: =IF(프로젝트목록!$A6="","",프로젝트목록!$A6) | B7: =IF($A7="","",프로젝트목록!$B6) | C7: =IF($A7="","",프로젝트목록!$F6) | D7: =IF($A7="","",IF(프로젝트목록!$E6="",0,프로젝트목록!$E6)) | E7: =IF($A7="","",ROUND(SUMIFS(업무일지!$I$3:$I$3002,업무일지!$C$3:$C$3002,$A7),2)) | F7: =IF($A7="","",ROUND($D7-$E7,2)) | G7: =IF($A7="","",IF($D7=0,"",$E7/$D7)) | H7: =IF($A7="","",SUMPRODUCT((구성원목록!$A$3:$A$42<>"")*(COUNTIFS(업무일지!$C$3:$C$3002,$A7,업무일지!$B$3:$B$3002,구성원목록!$A$3:$A$42)>0)))
A8: =IF(프로젝트목록!$A7="","",프로젝트목록!$A7) | B8: =IF($A8="","",프로젝트목록!$B7) | C8: =IF($A8="","",프로젝트목록!$F7) | D8: =IF($A8="","",IF(프로젝트목록!$E7="",0,프로젝트목록!$E7)) | E8: =IF($A8="","",ROUND(SUMIFS(업무일지!$I$3:$I$3002,업무일지!$C$3:$C$3002,$A8),2)) | F8: =IF($A8="","",ROUND($D8-$E8,2)) | G8: =IF($A8="","",IF($D8=0,"",$E8/$D8)) | H8: =IF($A8="","",SUMPRODUCT((구성원목록!$A$3:$A$42<>"")*(COUNTIFS(업무일지!$C$3:$C$3002,$A8,업무일지!$B$3:$B$3002,구성원목록!$A$3:$A$42)>0)))
A9: =IF(프로젝트목록!$A8="","",프로젝트목록!$A8) | B9: =IF($A9="","",프로젝트목록!$B8) | C9: =IF($A9="","",프로젝트목록!$F8) | D9: =IF($A9="","",IF(프로젝트목록!$E8="",0,프로젝트목록!$E8)) | E9: =IF($A9="","",ROUND(SUMIFS(업무일지!$I$3:$I$3002,업무일지!$C$3:$C$3002,$A9),2)) | F9: =IF($A9="","",ROUND($D9-$E9,2)) | G9: =IF($A9="","",IF($D9=0,"",$E9/$D9)) | H9: =IF($A9="","",SUMPRODUCT((구성원목록!$A$3:$A$42<>"")*(COUNTIFS(업무일지!$C$3:$C$3002,$A9,업무일지!$B$3:$B$3002,구성원목록!$A$3:$A$42)>0)))
A10: =IF(프로젝트목록!$A9="","",프로젝트목록!$A9) | B10: =IF($A10="","",프로젝트목록!$B9) | C10: =IF($A10="","",프로젝트목록!$F9) | D10: =IF($A10="","",IF(프로젝트목록!$E9="",0,프로젝트목록!$E9)) | E10: =IF($A10="","",ROUND(SUMIFS(업무일지!$I$3:$I$3002,업무일지!$C$3:$C$3002,$A10),2)) | F10: =IF($A10="","",ROUND($D10-$E10,2)) | G10: =IF($A10="","",IF($D10=0,"",$E10/$D10)) | H10: =IF($A10="","",SUMPRODUCT((구성원목록!$A$3:$A$42<>"")*(COUNTIFS(업무일지!$C$3:$C$3002,$A10,업무일지!$B$3:$B$3002,구성원목록!$A$3:$A$42)>0)))
A11: =IF(프로젝트목록!$A10="","",프로젝트목록!$A10) | B11: =IF($A11="","",프로젝트목록!$B10) | C11: =IF($A11="","",프로젝트목록!$F10) | D11: =IF($A11="","",IF(프로젝트목록!$E10="",0,프로젝트목록!$E10)) | E11: =IF($A11="","",ROUND(SUMIFS(업무일지!$I$3:$I$3002,업무일지!$C$3:$C$3002,$A11),2)) | F11: =IF($A11="","",ROUND($D11-$E11,2)) | G11: =IF($A11="","",IF($D11=0,"",$E11/$D11)) | H11: =IF($A11="","",SUMPRODUCT((구성원목록!$A$3:$A$42<>"")*(COUNTIFS(업무일지!$C$3:$C$3002,$A11,업무일지!$B$3:$B$3002,구성원목록!$A$3:$A$42)>0)))
A12: =IF(프로젝트목록!$A11="","",프로젝트목록!$A11) | B12: =IF($A12="","",프로젝트목록!$B11) | C12: =IF($A12="","",프로젝트목록!$F11) | D12: =IF($A12="","",IF(프로젝트목록!$E11="",0,프로젝트목록!$E11)) | E12: =IF($A12="","",ROUND(SUMIFS(업무일지!$I$3:$I$3002,업무일지!$C$3:$C$3002,$A12),2)) | F12: =IF($A12="","",ROUND($D12-$E12,2)) | G12: =IF($A12="","",IF($D12=0,"",$E12/$D12)) | H12: =IF($A12="","",SUMPRODUCT((구성원목록!$A$3:$A$42<>"")*(COUNTIFS(업무일지!$C$3:$C$3002,$A12,업무일지!$B$3:$B$3002,구성원목록!$A$3:$A$42)>0)))
A13: =IF(프로젝트목록!$A12="","",프로젝트목록!$A12) | B13: =IF($A13="","",프로젝트목록!$B12) | C13: =IF($A13="","",프로젝트목록!$F12) | D13: =IF($A13="","",IF(프로젝트목록!$E12="",0,프로젝트목록!$E12)) | E13: =IF($A13="","",ROUND(SUMIFS(업무일지!$I$3:$I$3002,업무일지!$C$3:$C$3002,$A13),2)) | F13: =IF($A13="","",ROUND($D13-$E13,2)) | G13: =IF($A13="","",IF($D13=0,"",$E13/$D13)) | H13: =IF($A13="","",SUMPRODUCT((구성원목록!$A$3:$A$42<>"")*(COUNTIFS(업무일지!$C$3:$C$3002,$A13,업무일지!$B$3:$B$3002,구성원목록!$A$3:$A$42)>0)))
A14: =IF(프로젝트목록!$A13="","",프로젝트목록!$A13) | B14: =IF($A14="","",프로젝트목록!$B13) | C14: =IF($A14="","",프로젝트목록!$F13) | D14: =IF($A14="","",IF(프로젝트목록!$E13="",0,프로젝트목록!$E13)) | E14: =IF($A14="","",ROUND(SUMIFS(업무일지!$I$3:$I$3002,업무일지!$C$3:$C$3002,$A14),2)) | F14: =IF($A14="","",ROUND($D14-$E14,2)) | G14: =IF($A14="","",IF($D14=0,"",$E14/$D14)) | H14: =IF($A14="","",SUMPRODUCT((구성원목록!$A$3:$A$42<>"")*(COUNTIFS(업무일지!$C$3:$C$3002,$A14,업무일지!$B$3:$B$3002,구성원목록!$A$3:$A$42)>0)))
A15: =IF(프로젝트목록!$A14="","",프로젝트목록!$A14) | B15: =IF($A15="","",프로젝트목록!$B14) | C15: =IF($A15="","",프로젝트목록!$F14) | D15: =IF($A15="","",IF(프로젝트목록!$E14="",0,프로젝트목록!$E14)) | E15: =IF($A15="","",ROUND(SUMIFS(업무일지!$I$3:$I$3002,업무일지!$C$3:$C$3002,$A15),2)) | F15: =IF($A15="","",ROUND($D15-$E15,2)) | G15: =IF($A15="","",IF($D15=0,"",$E15/$D15)) | H15: =IF($A15="","",SUMPRODUCT((구성원목록!$A$3:$A$42<>"")*(COUNTIFS(업무일지!$C$3:$C$3002,$A15,업무일지!$B$3:$B$3002,구성원목록!$A$3:$A$42)>0)))
... A63: =IF(프로젝트목록!$A62="","",프로젝트목록!$A62) | B63: =IF($A63="","",프로젝트목록!$B62) | C63: =IF($A63="","",프로젝트목록!$F62) | D63: =IF($A63="","",IF(프로젝트목록!$E62="",0,프로젝트목록!$E62)) | E63: =IF($A63="","",ROUND(SUMIFS(업무일지!$I$3:$I$3002,업무일지!$C$3:$C$3002,$A63),2)) | F63: =IF($A63="","",ROUND($D63-$E63,2)) | G63: =IF($A63="","",IF($D63=0,"",$E63/$D63)) | H63: =IF($A63="","",SUMPRODUCT((구성원목록!$A$3:$A$42<>"")*(COUNTIFS(업무일지!$C$3:$C$3002,$A63,업무일지!$B$3:$B$3002,구성원목록!$A$3:$A$42)>0)))
B65: 합계 | D65: =ROUND(SUM(D4:D63),2) -> 2300 | E65: =ROUND(SUM(E4:E63),2) -> 140.5 | F65: =ROUND(SUM(F4:F63),2) -> 2159.5

Sheet 담당자별집계
A1: 담당자별집계
A3: 대상 연도 | B3: 2026 | C3: 대상 월(0=연간) | D3: 0
A5: 이름 | B5: 소속 | C5: 작업일수 | D5: 총 투입시간 | E5: 참여 프로젝트 | F5: 일평균
A6: =IF(구성원목록!$A3="","",구성원목록!$A3) -> 김담당 | B6: =IF($A6="","",구성원목록!$B3) -> 기획팀 | C6: =IF($A6="","",COUNTIFS(업무일지!$B$3:$B$3002,$A6,업무일지!$A$3:$A$3002,">="&IF($D$3=0,DATE($B$3,1,1),DATE($B$3,$D$3,1)),업무일지!$A$3:$A$3002,"<="&IF($D$3=0,DATE($B$3,12,31),EOMONTH(DATE($B$3,$D$3,1),0)))) -> 9 | D6: =IF($A6="","",ROUND(SUMIFS(업무일지!$I$3:$I$3002,업무일지!$B$3:$B$3002,$A6,업무일지!$A$3:$A$3002,">="&IF($D$3=0,DATE($B$3,1,1),DATE($B$3,$D$3,1)),업무일지!$A$3:$A$3002,"<="&IF($D$3=0,DATE($B$3,12,31),EOMONTH(DATE($B$3,$D$3,1),0))),2)) -> 56.5 | E6: =IF($A6="","",SUMPRODUCT((프로젝트목록!$A$3:$A$62<>"")*(COUNTIFS(업무일지!$B$3:$B$3002,$A6,업무일지!$C$3:$C$3002,프로젝트목록!$A$3:$A$62,업무일지!$A$3:$A$3002,">="&IF($D$3=0,DATE($B$3,1,1),DATE($B$3,$D$3,1)),업무일지!$A$3:$A$3002,"<="&IF($D$3=0,DATE($B$3,12,31),EOMONTH(DATE($B$3,$D$3,1),0)))>0))) -> 2 | F6: =IF($A6="","",IF($C6=0,0,ROUND($D6/$C6,2))) -> 6.28
A7: =IF(구성원목록!$A4="","",구성원목록!$A4) -> 이담당 | B7: =IF($A7="","",구성원목록!$B4) -> 개발팀 | C7: =IF($A7="","",COUNTIFS(업무일지!$B$3:$B$3002,$A7,업무일지!$A$3:$A$3002,">="&IF($D$3=0,DATE($B$3,1,1),DATE($B$3,$D$3,1)),업무일지!$A$3:$A$3002,"<="&IF($D$3=0,DATE($B$3,12,31),EOMONTH(DATE($B$3,$D$3,1),0)))) -> 6 | D7: =IF($A7="","",ROUND(SUMIFS(업무일지!$I$3:$I$3002,업무일지!$B$3:$B$3002,$A7,업무일지!$A$3:$A$3002,">="&IF($D$3=0,DATE($B$3,1,1),DATE($B$3,$D$3,1)),업무일지!$A$3:$A$3002,"<="&IF($D$3=0,DATE($B$3,12,31),EOMONTH(DATE($B$3,$D$3,1),0))),2)) -> 52.5 | E7: =IF($A7="","",SUMPRODUCT((프로젝트목록!$A$3:$A$62<>"")*(COUNTIFS(업무일지!$B$3:$B$3002,$A7,업무일지!$C$3:$C$3002,프로젝트목록!$A$3:$A$62,업무일지!$A$3:$A$3002,">="&IF($D$3=0,DATE($B$3,1,1),DATE($B$3,$D$3,1)),업무일지!$A$3:$A$3002,"<="&IF($D$3=0,DATE($B$3,12,31),EOMONTH(DATE($B$3,$D$3,1),0)))>0))) -> 1 | F7: =IF($A7="","",IF($C7=0,0,ROUND($D7/$C7,2))) -> 8.75
A8: =IF(구성원목록!$A5="","",구성원목록!$A5) -> 박담당 | B8: =IF($A8="","",구성원목록!$B5) -> 디자인팀 | C8: =IF($A8="","",COUNTIFS(업무일지!$B$3:$B$3002,$A8,업무일지!$A$3:$A$3002,">="&IF($D$3=0,DATE($B$3,1,1),DATE($B$3,$D$3,1)),업무일지!$A$3:$A$3002,"<="&IF($D$3=0,DATE($B$3,12,31),EOMONTH(DATE($B$3,$D$3,1),0)))) -> 4 | D8: =IF($A8="","",ROUND(SUMIFS(업무일지!$I$3:$I$3002,업무일지!$B$3:$B$3002,$A8,업무일지!$A$3:$A$3002,">="&IF($D$3=0,DATE($B$3,1,1),DATE($B$3,$D$3,1)),업무일지!$A$3:$A$3002,"<="&IF($D$3=0,DATE($B$3,12,31),EOMONTH(DATE($B$3,$D$3,1),0))),2)) -> 31.5 | E8: =IF($A8="","",SUMPRODUCT((프로젝트목록!$A$3:$A$62<>"")*(COUNTIFS(업무일지!$B$3:$B$3002,$A8,업무일지!$C$3:$C$3002,프로젝트목록!$A$3:$A$62,업무일지!$A$3:$A$3002,">="&IF($D$3=0,DATE($B$3,1,1),DATE($B$3,$D$3,1)),업무일지!$A$3:$A$3002,"<="&IF($D$3=0,DATE($B$3,12,31),EOMONTH(DATE($B$3,$D$3,1),0)))>0))) -> 1 | F8: =IF($A8="","",IF($C8=0,0,ROUND($D8/$C8,2))) -> 7.88
A9: =IF(구성원목록!$A6="","",구성원목록!$A6) | B9: =IF($A9="","",구성원목록!$B6) | C9: =IF($A9="","",COUNTIFS(업무일지!$B$3:$B$3002,$A9,업무일지!$A$3:$A$3002,">="&IF($D$3=0,DATE($B$3,1,1),DATE($B$3,$D$3,1)),업무일지!$A$3:$A$3002,"<="&IF($D$3=0,DATE($B$3,12,31),EOMONTH(DATE($B$3,$D$3,1),0)))) | D9: =IF($A9="","",ROUND(SUMIFS(업무일지!$I$3:$I$3002,업무일지!$B$3:$B$3002,$A9,업무일지!$A$3:$A$3002,">="&IF($D$3=0,DATE($B$3,1,1),DATE($B$3,$D$3,1)),업무일지!$A$3:$A$3002,"<="&IF($D$3=0,DATE($B$3,12,31),EOMONTH(DATE($B$3,$D$3,1),0))),2)) | E9: =IF($A9="","",SUMPRODUCT((프로젝트목록!$A$3:$A$62<>"")*(COUNTIFS(업무일지!$B$3:$B$3002,$A9,업무일지!$C$3:$C$3002,프로젝트목록!$A$3:$A$62,업무일지!$A$3:$A$3002,">="&IF($D$3=0,DATE($B$3,1,1),DATE($B$3,$D$3,1)),업무일지!$A$3:$A$3002,"<="&IF($D$3=0,DATE($B$3,12,31),EOMONTH(DATE($B$3,$D$3,1),0)))>0))) | F9: =IF($A9="","",IF($C9=0,0,ROUND($D9/$C9,2)))
A10: =IF(구성원목록!$A7="","",구성원목록!$A7) | B10: =IF($A10="","",구성원목록!$B7) | C10: =IF($A10="","",COUNTIFS(업무일지!$B$3:$B$3002,$A10,업무일지!$A$3:$A$3002,">="&IF($D$3=0,DATE($B$3,1,1),DATE($B$3,$D$3,1)),업무일지!$A$3:$A$3002,"<="&IF($D$3=0,DATE($B$3,12,31),EOMONTH(DATE($B$3,$D$3,1),0)))) | D10: =IF($A10="","",ROUND(SUMIFS(업무일지!$I$3:$I$3002,업무일지!$B$3:$B$3002,$A10,업무일지!$A$3:$A$3002,">="&IF($D$3=0,DATE($B$3,1,1),DATE($B$3,$D$3,1)),업무일지!$A$3:$A$3002,"<="&IF($D$3=0,DATE($B$3,12,31),EOMONTH(DATE($B$3,$D$3,1),0))),2)) | E10: =IF($A10="","",SUMPRODUCT((프로젝트목록!$A$3:$A$62<>"")*(COUNTIFS(업무일지!$B$3:$B$3002,$A10,업무일지!$C$3:$C$3002,프로젝트목록!$A$3:$A$62,업무일지!$A$3:$A$3002,">="&IF($D$3=0,DATE($B$3,1,1),DATE($B$3,$D$3,1)),업무일지!$A$3:$A$3002,"<="&IF($D$3=0,DATE($B$3,12,31),EOMONTH(DATE($B$3,$D$3,1),0)))>0))) | F10: =IF($A10="","",IF($C10=0,0,ROUND($D10/$C10,2)))
A11: =IF(구성원목록!$A8="","",구성원목록!$A8) | B11: =IF($A11="","",구성원목록!$B8) | C11: =IF($A11="","",COUNTIFS(업무일지!$B$3:$B$3002,$A11,업무일지!$A$3:$A$3002,">="&IF($D$3=0,DATE($B$3,1,1),DATE($B$3,$D$3,1)),업무일지!$A$3:$A$3002,"<="&IF($D$3=0,DATE($B$3,12,31),EOMONTH(DATE($B$3,$D$3,1),0)))) | D11: =IF($A11="","",ROUND(SUMIFS(업무일지!$I$3:$I$3002,업무일지!$B$3:$B$3002,$A11,업무일지!$A$3:$A$3002,">="&IF($D$3=0,DATE($B$3,1,1),DATE($B$3,$D$3,1)),업무일지!$A$3:$A$3002,"<="&IF($D$3=0,DATE($B$3,12,31),EOMONTH(DATE($B$3,$D$3,1),0))),2)) | E11: =IF($A11="","",SUMPRODUCT((프로젝트목록!$A$3:$A$62<>"")*(COUNTIFS(업무일지!$B$3:$B$3002,$A11,업무일지!$C$3:$C$3002,프로젝트목록!$A$3:$A$62,업무일지!$A$3:$A$3002,">="&IF($D$3=0,DATE($B$3,1,1),DATE($B$3,$D$3,1)),업무일지!$A$3:$A$3002,"<="&IF($D$3=0,DATE($B$3,12,31),EOMONTH(DATE($B$3,$D$3,1),0)))>0))) | F11: =IF($A11="","",IF($C11=0,0,ROUND($D11/$C11,2)))
A12: =IF(구성원목록!$A9="","",구성원목록!$A9) | B12: =IF($A12="","",구성원목록!$B9) | C12: =IF($A12="","",COUNTIFS(업무일지!$B$3:$B$3002,$A12,업무일지!$A$3:$A$3002,">="&IF($D$3=0,DATE($B$3,1,1),DATE($B$3,$D$3,1)),업무일지!$A$3:$A$3002,"<="&IF($D$3=0,DATE($B$3,12,31),EOMONTH(DATE($B$3,$D$3,1),0)))) | D12: =IF($A12="","",ROUND(SUMIFS(업무일지!$I$3:$I$3002,업무일지!$B$3:$B$3002,$A12,업무일지!$A$3:$A$3002,">="&IF($D$3=0,DATE($B$3,1,1),DATE($B$3,$D$3,1)),업무일지!$A$3:$A$3002,"<="&IF($D$3=0,DATE($B$3,12,31),EOMONTH(DATE($B$3,$D$3,1),0))),2)) | E12: =IF($A12="","",SUMPRODUCT((프로젝트목록!$A$3:$A$62<>"")*(COUNTIFS(업무일지!$B$3:$B$3002,$A12,업무일지!$C$3:$C$3002,프로젝트목록!$A$3:$A$62,업무일지!$A$3:$A$3002,">="&IF($D$3=0,DATE($B$3,1,1),DATE($B$3,$D$3,1)),업무일지!$A$3:$A$3002,"<="&IF($D$3=0,DATE($B$3,12,31),EOMONTH(DATE($B$3,$D$3,1),0)))>0))) | F12: =IF($A12="","",IF($C12=0,0,ROUND($D12/$C12,2)))
A13: =IF(구성원목록!$A10="","",구성원목록!$A10) | B13: =IF($A13="","",구성원목록!$B10) | C13: =IF($A13="","",COUNTIFS(업무일지!$B$3:$B$3002,$A13,업무일지!$A$3:$A$3002,">="&IF($D$3=0,DATE($B$3,1,1),DATE($B$3,$D$3,1)),업무일지!$A$3:$A$3002,"<="&IF($D$3=0,DATE($B$3,12,31),EOMONTH(DATE($B$3,$D$3,1),0)))) | D13: =IF($A13="","",ROUND(SUMIFS(업무일지!$I$3:$I$3002,업무일지!$B$3:$B$3002,$A13,업무일지!$A$3:$A$3002,">="&IF($D$3=0,DATE($B$3,1,1),DATE($B$3,$D$3,1)),업무일지!$A$3:$A$3002,"<="&IF($D$3=0,DATE($B$3,12,31),EOMONTH(DATE($B$3,$D$3,1),0))),2)) | E13: =IF($A13="","",SUMPRODUCT((프로젝트목록!$A$3:$A$62<>"")*(COUNTIFS(업무일지!$B$3:$B$3002,$A13,업무일지!$C$3:$C$3002,프로젝트목록!$A$3:$A$62,업무일지!$A$3:$A$3002,">="&IF($D$3=0,DATE($B$3,1,1),DATE($B$3,$D$3,1)),업무일지!$A$3:$A$3002,"<="&IF($D$3=0,DATE($B$3,12,31),EOMONTH(DATE($B$3,$D$3,1),0)))>0))) | F13: =IF($A13="","",IF($C13=0,0,ROUND($D13/$C13,2)))
A14: =IF(구성원목록!$A11="","",구성원목록!$A11) | B14: =IF($A14="","",구성원목록!$B11) | C14: =IF($A14="","",COUNTIFS(업무일지!$B$3:$B$3002,$A14,업무일지!$A$3:$A$3002,">="&IF($D$3=0,DATE($B$3,1,1),DATE($B$3,$D$3,1)),업무일지!$A$3:$A$3002,"<="&IF($D$3=0,DATE($B$3,12,31),EOMONTH(DATE($B$3,$D$3,1),0)))) | D14: =IF($A14="","",ROUND(SUMIFS(업무일지!$I$3:$I$3002,업무일지!$B$3:$B$3002,$A14,업무일지!$A$3:$A$3002,">="&IF($D$3=0,DATE($B$3,1,1),DATE($B$3,$D$3,1)),업무일지!$A$3:$A$3002,"<="&IF($D$3=0,DATE($B$3,12,31),EOMONTH(DATE($B$3,$D$3,1),0))),2)) | E14: =IF($A14="","",SUMPRODUCT((프로젝트목록!$A$3:$A$62<>"")*(COUNTIFS(업무일지!$B$3:$B$3002,$A14,업무일지!$C$3:$C$3002,프로젝트목록!$A$3:$A$62,업무일지!$A$3:$A$3002,">="&IF($D$3=0,DATE($B$3,1,1),DATE($B$3,$D$3,1)),업무일지!$A$3:$A$3002,"<="&IF($D$3=0,DATE($B$3,12,31),EOMONTH(DATE($B$3,$D$3,1),0)))>0))) | F14: =IF($A14="","",IF($C14=0,0,ROUND($D14/$C14,2)))
A15: =IF(구성원목록!$A12="","",구성원목록!$A12) | B15: =IF($A15="","",구성원목록!$B12) | C15: =IF($A15="","",COUNTIFS(업무일지!$B$3:$B$3002,$A15,업무일지!$A$3:$A$3002,">="&IF($D$3=0,DATE($B$3,1,1),DATE($B$3,$D$3,1)),업무일지!$A$3:$A$3002,"<="&IF($D$3=0,DATE($B$3,12,31),EOMONTH(DATE($B$3,$D$3,1),0)))) | D15: =IF($A15="","",ROUND(SUMIFS(업무일지!$I$3:$I$3002,업무일지!$B$3:$B$3002,$A15,업무일지!$A$3:$A$3002,">="&IF($D$3=0,DATE($B$3,1,1),DATE($B$3,$D$3,1)),업무일지!$A$3:$A$3002,"<="&IF($D$3=0,DATE($B$3,12,31),EOMONTH(DATE($B$3,$D$3,1),0))),2)) | E15: =IF($A15="","",SUMPRODUCT((프로젝트목록!$A$3:$A$62<>"")*(COUNTIFS(업무일지!$B$3:$B$3002,$A15,업무일지!$C$3:$C$3002,프로젝트목록!$A$3:$A$62,업무일지!$A$3:$A$3002,">="&IF($D$3=0,DATE($B$3,1,1),DATE($B$3,$D$3,1)),업무일지!$A$3:$A$3002,"<="&IF($D$3=0,DATE($B$3,12,31),EOMONTH(DATE($B$3,$D$3,1),0)))>0))) | F15: =IF($A15="","",IF($C15=0,0,ROUND($D15/$C15,2)))
A16: =IF(구성원목록!$A13="","",구성원목록!$A13) | B16: =IF($A16="","",구성원목록!$B13) | C16: =IF($A16="","",COUNTIFS(업무일지!$B$3:$B$3002,$A16,업무일지!$A$3:$A$3002,">="&IF($D$3=0,DATE($B$3,1,1),DATE($B$3,$D$3,1)),업무일지!$A$3:$A$3002,"<="&IF($D$3=0,DATE($B$3,12,31),EOMONTH(DATE($B$3,$D$3,1),0)))) | D16: =IF($A16="","",ROUND(SUMIFS(업무일지!$I$3:$I$3002,업무일지!$B$3:$B$3002,$A16,업무일지!$A$3:$A$3002,">="&IF($D$3=0,DATE($B$3,1,1),DATE($B$3,$D$3,1)),업무일지!$A$3:$A$3002,"<="&IF($D$3=0,DATE($B$3,12,31),EOMONTH(DATE($B$3,$D$3,1),0))),2)) | E16: =IF($A16="","",SUMPRODUCT((프로젝트목록!$A$3:$A$62<>"")*(COUNTIFS(업무일지!$B$3:$B$3002,$A16,업무일지!$C$3:$C$3002,프로젝트목록!$A$3:$A$62,업무일지!$A$3:$A$3002,">="&IF($D$3=0,DATE($B$3,1,1),DATE($B$3,$D$3,1)),업무일지!$A$3:$A$3002,"<="&IF($D$3=0,DATE($B$3,12,31),EOMONTH(DATE($B$3,$D$3,1),0)))>0))) | F16: =IF($A16="","",IF($C16=0,0,ROUND($D16/$C16,2)))
A17: =IF(구성원목록!$A14="","",구성원목록!$A14) | B17: =IF($A17="","",구성원목록!$B14) | C17: =IF($A17="","",COUNTIFS(업무일지!$B$3:$B$3002,$A17,업무일지!$A$3:$A$3002,">="&IF($D$3=0,DATE($B$3,1,1),DATE($B$3,$D$3,1)),업무일지!$A$3:$A$3002,"<="&IF($D$3=0,DATE($B$3,12,31),EOMONTH(DATE($B$3,$D$3,1),0)))) | D17: =IF($A17="","",ROUND(SUMIFS(업무일지!$I$3:$I$3002,업무일지!$B$3:$B$3002,$A17,업무일지!$A$3:$A$3002,">="&IF($D$3=0,DATE($B$3,1,1),DATE($B$3,$D$3,1)),업무일지!$A$3:$A$3002,"<="&IF($D$3=0,DATE($B$3,12,31),EOMONTH(DATE($B$3,$D$3,1),0))),2)) | E17: =IF($A17="","",SUMPRODUCT((프로젝트목록!$A$3:$A$62<>"")*(COUNTIFS(업무일지!$B$3:$B$3002,$A17,업무일지!$C$3:$C$3002,프로젝트목록!$A$3:$A$62,업무일지!$A$3:$A$3002,">="&IF($D$3=0,DATE($B$3,1,1),DATE($B$3,$D$3,1)),업무일지!$A$3:$A$3002,"<="&IF($D$3=0,DATE($B$3,12,31),EOMONTH(DATE($B$3,$D$3,1),0)))>0))) | F17: =IF($A17="","",IF($C17=0,0,ROUND($D17/$C17,2)))
... A45: =IF(구성원목록!$A42="","",구성원목록!$A42) | B45: =IF($A45="","",구성원목록!$B42) | C45: =IF($A45="","",COUNTIFS(업무일지!$B$3:$B$3002,$A45,업무일지!$A$3:$A$3002,">="&IF($D$3=0,DATE($B$3,1,1),DATE($B$3,$D$3,1)),업무일지!$A$3:$A$3002,"<="&IF($D$3=0,DATE($B$3,12,31),EOMONTH(DATE($B$3,$D$3,1),0)))) | D45: =IF($A45="","",ROUND(SUMIFS(업무일지!$I$3:$I$3002,업무일지!$B$3:$B$3002,$A45,업무일지!$A$3:$A$3002,">="&IF($D$3=0,DATE($B$3,1,1),DATE($B$3,$D$3,1)),업무일지!$A$3:$A$3002,"<="&IF($D$3=0,DATE($B$3,12,31),EOMONTH(DATE($B$3,$D$3,1),0))),2)) | E45: =IF($A45="","",SUMPRODUCT((프로젝트목록!$A$3:$A$62<>"")*(COUNTIFS(업무일지!$B$3:$B$3002,$A45,업무일지!$C$3:$C$3002,프로젝트목록!$A$3:$A$62,업무일지!$A$3:$A$3002,">="&IF($D$3=0,DATE($B$3,1,1),DATE($B$3,$D$3,1)),업무일지!$A$3:$A$3002,"<="&IF($D$3=0,DATE($B$3,12,31),EOMONTH(DATE($B$3,$D$3,1),0)))>0))) | F45: =IF($A45="","",IF($C45=0,0,ROUND($D45/$C45,2)))

Sheet 월별집계
A1: 월별집계
A3: 대상 연도 | B3: 2026
A5: 월 | B5: 작업 건수 | C5: 총 투입시간 | D5: 참여 인원 | E5: 프로젝트 수
A6: 1 | B6: =COUNTIFS(업무일지!$A$3:$A$3002,">="&DATE($B$3,1,1),업무일지!$A$3:$A$3002,"<="&EOMONTH(DATE($B$3,1,1),0)) -> 0 | C6: =ROUND(SUMIFS(업무일지!$I$3:$I$3002,업무일지!$A$3:$A$3002,">="&DATE($B$3,1,1),업무일지!$A$3:$A$3002,"<="&EOMONTH(DATE($B$3,1,1),0)),2) -> 0 | D6: =SUMPRODUCT((구성원목록!$A$3:$A$42<>"")*(COUNTIFS(업무일지!$B$3:$B$3002,구성원목록!$A$3:$A$42,업무일지!$A$3:$A$3002,">="&DATE($B$3,1,1),업무일지!$A$3:$A$3002,"<="&EOMONTH(DATE($B$3,1,1),0))>0)) -> 0 | E6: =SUMPRODUCT((프로젝트목록!$A$3:$A$62<>"")*(COUNTIFS(업무일지!$C$3:$C$3002,프로젝트목록!$A$3:$A$62,업무일지!$A$3:$A$3002,">="&DATE($B$3,1,1),업무일지!$A$3:$A$3002,"<="&EOMONTH(DATE($B$3,1,1),0))>0)) -> 0
A7: 2 | B7: =COUNTIFS(업무일지!$A$3:$A$3002,">="&DATE($B$3,2,1),업무일지!$A$3:$A$3002,"<="&EOMONTH(DATE($B$3,2,1),0)) -> 0 | C7: =ROUND(SUMIFS(업무일지!$I$3:$I$3002,업무일지!$A$3:$A$3002,">="&DATE($B$3,2,1),업무일지!$A$3:$A$3002,"<="&EOMONTH(DATE($B$3,2,1),0)),2) -> 0 | D7: =SUMPRODUCT((구성원목록!$A$3:$A$42<>"")*(COUNTIFS(업무일지!$B$3:$B$3002,구성원목록!$A$3:$A$42,업무일지!$A$3:$A$3002,">="&DATE($B$3,2,1),업무일지!$A$3:$A$3002,"<="&EOMONTH(DATE($B$3,2,1),0))>0)) -> 0 | E7: =SUMPRODUCT((프로젝트목록!$A$3:$A$62<>"")*(COUNTIFS(업무일지!$C$3:$C$3002,프로젝트목록!$A$3:$A$62,업무일지!$A$3:$A$3002,">="&DATE($B$3,2,1),업무일지!$A$3:$A$3002,"<="&EOMONTH(DATE($B$3,2,1),0))>0)) -> 0
A8: 3 | B8: =COUNTIFS(업무일지!$A$3:$A$3002,">="&DATE($B$3,3,1),업무일지!$A$3:$A$3002,"<="&EOMONTH(DATE($B$3,3,1),0)) -> 0 | C8: =ROUND(SUMIFS(업무일지!$I$3:$I$3002,업무일지!$A$3:$A$3002,">="&DATE($B$3,3,1),업무일지!$A$3:$A$3002,"<="&EOMONTH(DATE($B$3,3,1),0)),2) -> 0 | D8: =SUMPRODUCT((구성원목록!$A$3:$A$42<>"")*(COUNTIFS(업무일지!$B$3:$B$3002,구성원목록!$A$3:$A$42,업무일지!$A$3:$A$3002,">="&DATE($B$3,3,1),업무일지!$A$3:$A$3002,"<="&EOMONTH(DATE($B$3,3,1),0))>0)) -> 0 | E8: =SUMPRODUCT((프로젝트목록!$A$3:$A$62<>"")*(COUNTIFS(업무일지!$C$3:$C$3002,프로젝트목록!$A$3:$A$62,업무일지!$A$3:$A$3002,">="&DATE($B$3,3,1),업무일지!$A$3:$A$3002,"<="&EOMONTH(DATE($B$3,3,1),0))>0)) -> 0
A9: 4 | B9: =COUNTIFS(업무일지!$A$3:$A$3002,">="&DATE($B$3,4,1),업무일지!$A$3:$A$3002,"<="&EOMONTH(DATE($B$3,4,1),0)) -> 0 | C9: =ROUND(SUMIFS(업무일지!$I$3:$I$3002,업무일지!$A$3:$A$3002,">="&DATE($B$3,4,1),업무일지!$A$3:$A$3002,"<="&EOMONTH(DATE($B$3,4,1),0)),2) -> 0 | D9: =SUMPRODUCT((구성원목록!$A$3:$A$42<>"")*(COUNTIFS(업무일지!$B$3:$B$3002,구성원목록!$A$3:$A$42,업무일지!$A$3:$A$3002,">="&DATE($B$3,4,1),업무일지!$A$3:$A$3002,"<="&EOMONTH(DATE($B$3,4,1),0))>0)) -> 0 | E9: =SUMPRODUCT((프로젝트목록!$A$3:$A$62<>"")*(COUNTIFS(업무일지!$C$3:$C$3002,프로젝트목록!$A$3:$A$62,업무일지!$A$3:$A$3002,">="&DATE($B$3,4,1),업무일지!$A$3:$A$3002,"<="&EOMONTH(DATE($B$3,4,1),0))>0)) -> 0
A10: 5 | B10: =COUNTIFS(업무일지!$A$3:$A$3002,">="&DATE($B$3,5,1),업무일지!$A$3:$A$3002,"<="&EOMONTH(DATE($B$3,5,1),0)) -> 0 | C10: =ROUND(SUMIFS(업무일지!$I$3:$I$3002,업무일지!$A$3:$A$3002,">="&DATE($B$3,5,1),업무일지!$A$3:$A$3002,"<="&EOMONTH(DATE($B$3,5,1),0)),2) -> 0 | D10: =SUMPRODUCT((구성원목록!$A$3:$A$42<>"")*(COUNTIFS(업무일지!$B$3:$B$3002,구성원목록!$A$3:$A$42,업무일지!$A$3:$A$3002,">="&DATE($B$3,5,1),업무일지!$A$3:$A$3002,"<="&EOMONTH(DATE($B$3,5,1),0))>0)) -> 0 | E10: =SUMPRODUCT((프로젝트목록!$A$3:$A$62<>"")*(COUNTIFS(업무일지!$C$3:$C$3002,프로젝트목록!$A$3:$A$62,업무일지!$A$3:$A$3002,">="&DATE($B$3,5,1),업무일지!$A$3:$A$3002,"<="&EOMONTH(DATE($B$3,5,1),0))>0)) -> 0
A11: 6 | B11: =COUNTIFS(업무일지!$A$3:$A$3002,">="&DATE($B$3,6,1),업무일지!$A$3:$A$3002,"<="&EOMONTH(DATE($B$3,6,1),0)) -> 0 | C11: =ROUND(SUMIFS(업무일지!$I$3:$I$3002,업무일지!$A$3:$A$3002,">="&DATE($B$3,6,1),업무일지!$A$3:$A$3002,"<="&EOMONTH(DATE($B$3,6,1),0)),2) -> 0 | D11: =SUMPRODUCT((구성원목록!$A$3:$A$42<>"")*(COUNTIFS(업무일지!$B$3:$B$3002,구성원목록!$A$3:$A$42,업무일지!$A$3:$A$3002,">="&DATE($B$3,6,1),업무일지!$A$3:$A$3002,"<="&EOMONTH(DATE($B$3,6,1),0))>0)) -> 0 | E11: =SUMPRODUCT((프로젝트목록!$A$3:$A$62<>"")*(COUNTIFS(업무일지!$C$3:$C$3002,프로젝트목록!$A$3:$A$62,업무일지!$A$3:$A$3002,">="&DATE($B$3,6,1),업무일지!$A$3:$A$3002,"<="&EOMONTH(DATE($B$3,6,1),0))>0)) -> 0
A12: 7 | B12: =COUNTIFS(업무일지!$A$3:$A$3002,">="&DATE($B$3,7,1),업무일지!$A$3:$A$3002,"<="&EOMONTH(DATE($B$3,7,1),0)) -> 0 | C12: =ROUND(SUMIFS(업무일지!$I$3:$I$3002,업무일지!$A$3:$A$3002,">="&DATE($B$3,7,1),업무일지!$A$3:$A$3002,"<="&EOMONTH(DATE($B$3,7,1),0)),2) -> 0 | D12: =SUMPRODUCT((구성원목록!$A$3:$A$42<>"")*(COUNTIFS(업무일지!$B$3:$B$3002,구성원목록!$A$3:$A$42,업무일지!$A$3:$A$3002,">="&DATE($B$3,7,1),업무일지!$A$3:$A$3002,"<="&EOMONTH(DATE($B$3,7,1),0))>0)) -> 0 | E12: =SUMPRODUCT((프로젝트목록!$A$3:$A$62<>"")*(COUNTIFS(업무일지!$C$3:$C$3002,프로젝트목록!$A$3:$A$62,업무일지!$A$3:$A$3002,">="&DATE($B$3,7,1),업무일지!$A$3:$A$3002,"<="&EOMONTH(DATE($B$3,7,1),0))>0)) -> 0
A13: 8 | B13: =COUNTIFS(업무일지!$A$3:$A$3002,">="&DATE($B$3,8,1),업무일지!$A$3:$A$3002,"<="&EOMONTH(DATE($B$3,8,1),0)) -> 6 | C13: =ROUND(SUMIFS(업무일지!$I$3:$I$3002,업무일지!$A$3:$A$3002,">="&DATE($B$3,8,1),업무일지!$A$3:$A$3002,"<="&EOMONTH(DATE($B$3,8,1),0)),2) -> 47.5 | D13: =SUMPRODUCT((구성원목록!$A$3:$A$42<>"")*(COUNTIFS(업무일지!$B$3:$B$3002,구성원목록!$A$3:$A$42,업무일지!$A$3:$A$3002,">="&DATE($B$3,8,1),업무일지!$A$3:$A$3002,"<="&EOMONTH(DATE($B$3,8,1),0))>0)) -> 3 | E13: =SUMPRODUCT((프로젝트목록!$A$3:$A$62<>"")*(COUNTIFS(업무일지!$C$3:$C$3002,프로젝트목록!$A$3:$A$62,업무일지!$A$3:$A$3002,">="&DATE($B$3,8,1),업무일지!$A$3:$A$3002,"<="&EOMONTH(DATE($B$3,8,1),0))>0)) -> 3
A14: 9 | B14: =COUNTIFS(업무일지!$A$3:$A$3002,">="&DATE($B$3,9,1),업무일지!$A$3:$A$3002,"<="&EOMONTH(DATE($B$3,9,1),0)) -> 13 | C14: =ROUND(SUMIFS(업무일지!$I$3:$I$3002,업무일지!$A$3:$A$3002,">="&DATE($B$3,9,1),업무일지!$A$3:$A$3002,"<="&EOMONTH(DATE($B$3,9,1),0)),2) -> 93 | D14: =SUMPRODUCT((구성원목록!$A$3:$A$42<>"")*(COUNTIFS(업무일지!$B$3:$B$3002,구성원목록!$A$3:$A$42,업무일지!$A$3:$A$3002,">="&DATE($B$3,9,1),업무일지!$A$3:$A$3002,"<="&EOMONTH(DATE($B$3,9,1),0))>0)) -> 3 | E14: =SUMPRODUCT((프로젝트목록!$A$3:$A$62<>"")*(COUNTIFS(업무일지!$C$3:$C$3002,프로젝트목록!$A$3:$A$62,업무일지!$A$3:$A$3002,">="&DATE($B$3,9,1),업무일지!$A$3:$A$3002,"<="&EOMONTH(DATE($B$3,9,1),0))>0)) -> 3
A15: 10 | B15: =COUNTIFS(업무일지!$A$3:$A$3002,">="&DATE($B$3,10,1),업무일지!$A$3:$A$3002,"<="&EOMONTH(DATE($B$3,10,1),0)) -> 0 | C15: =ROUND(SUMIFS(업무일지!$I$3:$I$3002,업무일지!$A$3:$A$3002,">="&DATE($B$3,10,1),업무일지!$A$3:$A$3002,"<="&EOMONTH(DATE($B$3,10,1),0)),2) -> 0 | D15: =SUMPRODUCT((구성원목록!$A$3:$A$42<>"")*(COUNTIFS(업무일지!$B$3:$B$3002,구성원목록!$A$3:$A$42,업무일지!$A$3:$A$3002,">="&DATE($B$3,10,1),업무일지!$A$3:$A$3002,"<="&EOMONTH(DATE($B$3,10,1),0))>0)) -> 0 | E15: =SUMPRODUCT((프로젝트목록!$A$3:$A$62<>"")*(COUNTIFS(업무일지!$C$3:$C$3002,프로젝트목록!$A$3:$A$62,업무일지!$A$3:$A$3002,">="&DATE($B$3,10,1),업무일지!$A$3:$A$3002,"<="&EOMONTH(DATE($B$3,10,1),0))>0)) -> 0
A16: 11 | B16: =COUNTIFS(업무일지!$A$3:$A$3002,">="&DATE($B$3,11,1),업무일지!$A$3:$A$3002,"<="&EOMONTH(DATE($B$3,11,1),0)) -> 0 | C16: =ROUND(SUMIFS(업무일지!$I$3:$I$3002,업무일지!$A$3:$A$3002,">="&DATE($B$3,11,1),업무일지!$A$3:$A$3002,"<="&EOMONTH(DATE($B$3,11,1),0)),2) -> 0 | D16: =SUMPRODUCT((구성원목록!$A$3:$A$42<>"")*(COUNTIFS(업무일지!$B$3:$B$3002,구성원목록!$A$3:$A$42,업무일지!$A$3:$A$3002,">="&DATE($B$3,11,1),업무일지!$A$3:$A$3002,"<="&EOMONTH(DATE($B$3,11,1),0))>0)) -> 0 | E16: =SUMPRODUCT((프로젝트목록!$A$3:$A$62<>"")*(COUNTIFS(업무일지!$C$3:$C$3002,프로젝트목록!$A$3:$A$62,업무일지!$A$3:$A$3002,">="&DATE($B$3,11,1),업무일지!$A$3:$A$3002,"<="&EOMONTH(DATE($B$3,11,1),0))>0)) -> 0
A17: 12 | B17: =COUNTIFS(업무일지!$A$3:$A$3002,">="&DATE($B$3,12,1),업무일지!$A$3:$A$3002,"<="&EOMONTH(DATE($B$3,12,1),0)) -> 0 | C17: =ROUND(SUMIFS(업무일지!$I$3:$I$3002,업무일지!$A$3:$A$3002,">="&DATE($B$3,12,1),업무일지!$A$3:$A$3002,"<="&EOMONTH(DATE($B$3,12,1),0)),2) -> 0 | D17: =SUMPRODUCT((구성원목록!$A$3:$A$42<>"")*(COUNTIFS(업무일지!$B$3:$B$3002,구성원목록!$A$3:$A$42,업무일지!$A$3:$A$3002,">="&DATE($B$3,12,1),업무일지!$A$3:$A$3002,"<="&EOMONTH(DATE($B$3,12,1),0))>0)) -> 0 | E17: =SUMPRODUCT((프로젝트목록!$A$3:$A$62<>"")*(COUNTIFS(업무일지!$C$3:$C$3002,프로젝트목록!$A$3:$A$62,업무일지!$A$3:$A$3002,">="&DATE($B$3,12,1),업무일지!$A$3:$A$3002,"<="&EOMONTH(DATE($B$3,12,1),0))>0)) -> 0
A18: 합계 | B18: =ROUND(SUM(B6:B17),2) -> 19 | C18: =ROUND(SUM(C6:C17),2) -> 140.5

Sheet 교차집계
A1: 교차집계 (프로젝트 × 담당자)
A3: 대상 연도 | B3: 2026
A5: 프로젝트 \ 담당자 | B5: =IF(구성원목록!$A3="","",구성원목록!$A3) -> 김담당 | C5: =IF(구성원목록!$A4="","",구성원목록!$A4) -> 이담당 | D5: =IF(구성원목록!$A5="","",구성원목록!$A5) -> 박담당 | E5: =IF(구성원목록!$A6="","",구성원목록!$A6) | F5: =IF(구성원목록!$A7="","",구성원목록!$A7) | G5: =IF(구성원목록!$A8="","",구성원목록!$A8) | H5: =IF(구성원목록!$A9="","",구성원목록!$A9) | I5: =IF(구성원목록!$A10="","",구성원목록!$A10) | J5: =IF(구성원목록!$A11="","",구성원목록!$A11) | K5: =IF(구성원목록!$A12="","",구성원목록!$A12) | L5: 합계
A6: =IF(프로젝트목록!$A3="","",프로젝트목록!$B3) -> OO운영사업 | B6: =IF(OR($A6="",B$5=""),"",ROUND(SUMIFS(업무일지!$I$3:$I$3002,업무일지!$C$3:$C$3002,프로젝트목록!$A3,업무일지!$B$3:$B$3002,B$5,업무일지!$A$3:$A$3002,">="&DATE($B$3,1,1),업무일지!$A$3:$A$3002,"<="&DATE($B$3,12,31)),2)) -> 51.5 | C6: =IF(OR($A6="",C$5=""),"",ROUND(SUMIFS(업무일지!$I$3:$I$3002,업무일지!$C$3:$C$3002,프로젝트목록!$A3,업무일지!$B$3:$B$3002,C$5,업무일지!$A$3:$A$3002,">="&DATE($B$3,1,1),업무일지!$A$3:$A$3002,"<="&DATE($B$3,12,31)),2)) -> 0 | D6: =IF(OR($A6="",D$5=""),"",ROUND(SUMIFS(업무일지!$I$3:$I$3002,업무일지!$C$3:$C$3002,프로젝트목록!$A3,업무일지!$B$3:$B$3002,D$5,업무일지!$A$3:$A$3002,">="&DATE($B$3,1,1),업무일지!$A$3:$A$3002,"<="&DATE($B$3,12,31)),2)) -> 0 | E6: =IF(OR($A6="",E$5=""),"",ROUND(SUMIFS(업무일지!$I$3:$I$3002,업무일지!$C$3:$C$3002,프로젝트목록!$A3,업무일지!$B$3:$B$3002,E$5,업무일지!$A$3:$A$3002,">="&DATE($B$3,1,1),업무일지!$A$3:$A$3002,"<="&DATE($B$3,12,31)),2)) | F6: =IF(OR($A6="",F$5=""),"",ROUND(SUMIFS(업무일지!$I$3:$I$3002,업무일지!$C$3:$C$3002,프로젝트목록!$A3,업무일지!$B$3:$B$3002,F$5,업무일지!$A$3:$A$3002,">="&DATE($B$3,1,1),업무일지!$A$3:$A$3002,"<="&DATE($B$3,12,31)),2)) | G6: =IF(OR($A6="",G$5=""),"",ROUND(SUMIFS(업무일지!$I$3:$I$3002,업무일지!$C$3:$C$3002,프로젝트목록!$A3,업무일지!$B$3:$B$3002,G$5,업무일지!$A$3:$A$3002,">="&DATE($B$3,1,1),업무일지!$A$3:$A$3002,"<="&DATE($B$3,12,31)),2)) | H6: =IF(OR($A6="",H$5=""),"",ROUND(SUMIFS(업무일지!$I$3:$I$3002,업무일지!$C$3:$C$3002,프로젝트목록!$A3,업무일지!$B$3:$B$3002,H$5,업무일지!$A$3:$A$3002,">="&DATE($B$3,1,1),업무일지!$A$3:$A$3002,"<="&DATE($B$3,12,31)),2)) | I6: =IF(OR($A6="",I$5=""),"",ROUND(SUMIFS(업무일지!$I$3:$I$3002,업무일지!$C$3:$C$3002,프로젝트목록!$A3,업무일지!$B$3:$B$3002,I$5,업무일지!$A$3:$A$3002,">="&DATE($B$3,1,1),업무일지!$A$3:$A$3002,"<="&DATE($B$3,12,31)),2)) | ... K6: =IF(OR($A6="",K$5=""),"",ROUND(SUMIFS(업무일지!$I$3:$I$3002,업무일지!$C$3:$C$3002,프로젝트목록!$A3,업무일지!$B$3:$B$3002,K$5,업무일지!$A$3:$A$3002,">="&DATE($B$3,1,1),업무일지!$A$3:$A$3002,"<="&DATE($B$3,12,31)),2)) | L6: =IF($A6="","",ROUND(SUM(B6:K6),2)) -> 51.5
A7: =IF(프로젝트목록!$A4="","",프로젝트목록!$B4) -> 신규 앱 개발 | B7: =IF(OR($A7="",B$5=""),"",ROUND(SUMIFS(업무일지!$I$3:$I$3002,업무일지!$C$3:$C$3002,프로젝트목록!$A4,업무일지!$B$3:$B$3002,B$5,업무일지!$A$3:$A$3002,">="&DATE($B$3,1,1),업무일지!$A$3:$A$3002,"<="&DATE($B$3,12,31)),2)) -> 0 | C7: =IF(OR($A7="",C$5=""),"",ROUND(SUMIFS(업무일지!$I$3:$I$3002,업무일지!$C$3:$C$3002,프로젝트목록!$A4,업무일지!$B$3:$B$3002,C$5,업무일지!$A$3:$A$3002,">="&DATE($B$3,1,1),업무일지!$A$3:$A$3002,"<="&DATE($B$3,12,31)),2)) -> 52.5 | D7: =IF(OR($A7="",D$5=""),"",ROUND(SUMIFS(업무일지!$I$3:$I$3002,업무일지!$C$3:$C$3002,프로젝트목록!$A4,업무일지!$B$3:$B$3002,D$5,업무일지!$A$3:$A$3002,">="&DATE($B$3,1,1),업무일지!$A$3:$A$3002,"<="&DATE($B$3,12,31)),2)) -> 0 | E7: =IF(OR($A7="",E$5=""),"",ROUND(SUMIFS(업무일지!$I$3:$I$3002,업무일지!$C$3:$C$3002,프로젝트목록!$A4,업무일지!$B$3:$B$3002,E$5,업무일지!$A$3:$A$3002,">="&DATE($B$3,1,1),업무일지!$A$3:$A$3002,"<="&DATE($B$3,12,31)),2)) | F7: =IF(OR($A7="",F$5=""),"",ROUND(SUMIFS(업무일지!$I$3:$I$3002,업무일지!$C$3:$C$3002,프로젝트목록!$A4,업무일지!$B$3:$B$3002,F$5,업무일지!$A$3:$A$3002,">="&DATE($B$3,1,1),업무일지!$A$3:$A$3002,"<="&DATE($B$3,12,31)),2)) | G7: =IF(OR($A7="",G$5=""),"",ROUND(SUMIFS(업무일지!$I$3:$I$3002,업무일지!$C$3:$C$3002,프로젝트목록!$A4,업무일지!$B$3:$B$3002,G$5,업무일지!$A$3:$A$3002,">="&DATE($B$3,1,1),업무일지!$A$3:$A$3002,"<="&DATE($B$3,12,31)),2)) | H7: =IF(OR($A7="",H$5=""),"",ROUND(SUMIFS(업무일지!$I$3:$I$3002,업무일지!$C$3:$C$3002,프로젝트목록!$A4,업무일지!$B$3:$B$3002,H$5,업무일지!$A$3:$A$3002,">="&DATE($B$3,1,1),업무일지!$A$3:$A$3002,"<="&DATE($B$3,12,31)),2)) | I7: =IF(OR($A7="",I$5=""),"",ROUND(SUMIFS(업무일지!$I$3:$I$3002,업무일지!$C$3:$C$3002,프로젝트목록!$A4,업무일지!$B$3:$B$3002,I$5,업무일지!$A$3:$A$3002,">="&DATE($B$3,1,1),업무일지!$A$3:$A$3002,"<="&DATE($B$3,12,31)),2)) | ... K7: =IF(OR($A7="",K$5=""),"",ROUND(SUMIFS(업무일지!$I$3:$I$3002,업무일지!$C$3:$C$3002,프로젝트목록!$A4,업무일지!$B$3:$B$3002,K$5,업무일지!$A$3:$A$3002,">="&DATE($B$3,1,1),업무일지!$A$3:$A$3002,"<="&DATE($B$3,12,31)),2)) | L7: =IF($A7="","",ROUND(SUM(B7:K7),2)) -> 52.5
A8: =IF(프로젝트목록!$A5="","",프로젝트목록!$B5) -> 홈페이지 개편 | B8: =IF(OR($A8="",B$5=""),"",ROUND(SUMIFS(업무일지!$I$3:$I$3002,업무일지!$C$3:$C$3002,프로젝트목록!$A5,업무일지!$B$3:$B$3002,B$5,업무일지!$A$3:$A$3002,">="&DATE($B$3,1,1),업무일지!$A$3:$A$3002,"<="&DATE($B$3,12,31)),2)) -> 5 | C8: =IF(OR($A8="",C$5=""),"",ROUND(SUMIFS(업무일지!$I$3:$I$3002,업무일지!$C$3:$C$3002,프로젝트목록!$A5,업무일지!$B$3:$B$3002,C$5,업무일지!$A$3:$A$3002,">="&DATE($B$3,1,1),업무일지!$A$3:$A$3002,"<="&DATE($B$3,12,31)),2)) -> 0 | D8: =IF(OR($A8="",D$5=""),"",ROUND(SUMIFS(업무일지!$I$3:$I$3002,업무일지!$C$3:$C$3002,프로젝트목록!$A5,업무일지!$B$3:$B$3002,D$5,업무일지!$A$3:$A$3002,">="&DATE($B$3,1,1),업무일지!$A$3:$A$3002,"<="&DATE($B$3,12,31)),2)) -> 31.5 | E8: =IF(OR($A8="",E$5=""),"",ROUND(SUMIFS(업무일지!$I$3:$I$3002,업무일지!$C$3:$C$3002,프로젝트목록!$A5,업무일지!$B$3:$B$3002,E$5,업무일지!$A$3:$A$3002,">="&DATE($B$3,1,1),업무일지!$A$3:$A$3002,"<="&DATE($B$3,12,31)),2)) | F8: =IF(OR($A8="",F$5=""),"",ROUND(SUMIFS(업무일지!$I$3:$I$3002,업무일지!$C$3:$C$3002,프로젝트목록!$A5,업무일지!$B$3:$B$3002,F$5,업무일지!$A$3:$A$3002,">="&DATE($B$3,1,1),업무일지!$A$3:$A$3002,"<="&DATE($B$3,12,31)),2)) | G8: =IF(OR($A8="",G$5=""),"",ROUND(SUMIFS(업무일지!$I$3:$I$3002,업무일지!$C$3:$C$3002,프로젝트목록!$A5,업무일지!$B$3:$B$3002,G$5,업무일지!$A$3:$A$3002,">="&DATE($B$3,1,1),업무일지!$A$3:$A$3002,"<="&DATE($B$3,12,31)),2)) | H8: =IF(OR($A8="",H$5=""),"",ROUND(SUMIFS(업무일지!$I$3:$I$3002,업무일지!$C$3:$C$3002,프로젝트목록!$A5,업무일지!$B$3:$B$3002,H$5,업무일지!$A$3:$A$3002,">="&DATE($B$3,1,1),업무일지!$A$3:$A$3002,"<="&DATE($B$3,12,31)),2)) | I8: =IF(OR($A8="",I$5=""),"",ROUND(SUMIFS(업무일지!$I$3:$I$3002,업무일지!$C$3:$C$3002,프로젝트목록!$A5,업무일지!$B$3:$B$3002,I$5,업무일지!$A$3:$A$3002,">="&DATE($B$3,1,1),업무일지!$A$3:$A$3002,"<="&DATE($B$3,12,31)),2)) | ... K8: =IF(OR($A8="",K$5=""),"",ROUND(SUMIFS(업무일지!$I$3:$I$3002,업무일지!$C$3:$C$3002,프로젝트목록!$A5,업무일지!$B$3:$B$3002,K$5,업무일지!$A$3:$A$3002,">="&DATE($B$3,1,1),업무일지!$A$3:$A$3002,"<="&DATE($B$3,12,31)),2)) | L8: =IF($A8="","",ROUND(SUM(B8:K8),2)) -> 36.5
A9: =IF(프로젝트목록!$A6="","",프로젝트목록!$B6) | B9: =IF(OR($A9="",B$5=""),"",ROUND(SUMIFS(업무일지!$I$3:$I$3002,업무일지!$C$3:$C$3002,프로젝트목록!$A6,업무일지!$B$3:$B$3002,B$5,업무일지!$A$3:$A$3002,">="&DATE($B$3,1,1),업무일지!$A$3:$A$3002,"<="&DATE($B$3,12,31)),2)) | C9: =IF(OR($A9="",C$5=""),"",ROUND(SUMIFS(업무일지!$I$3:$I$3002,업무일지!$C$3:$C$3002,프로젝트목록!$A6,업무일지!$B$3:$B$3002,C$5,업무일지!$A$3:$A$3002,">="&DATE($B$3,1,1),업무일지!$A$3:$A$3002,"<="&DATE($B$3,12,31)),2)) | D9: =IF(OR($A9="",D$5=""),"",ROUND(SUMIFS(업무일지!$I$3:$I$3002,업무일지!$C$3:$C$3002,프로젝트목록!$A6,업무일지!$B$3:$B$3002,D$5,업무일지!$A$3:$A$3002,">="&DATE($B$3,1,1),업무일지!$A$3:$A$3002,"<="&DATE($B$3,12,31)),2)) | E9: =IF(OR($A9="",E$5=""),"",ROUND(SUMIFS(업무일지!$I$3:$I$3002,업무일지!$C$3:$C$3002,프로젝트목록!$A6,업무일지!$B$3:$B$3002,E$5,업무일지!$A$3:$A$3002,">="&DATE($B$3,1,1),업무일지!$A$3:$A$3002,"<="&DATE($B$3,12,31)),2)) | F9: =IF(OR($A9="",F$5=""),"",ROUND(SUMIFS(업무일지!$I$3:$I$3002,업무일지!$C$3:$C$3002,프로젝트목록!$A6,업무일지!$B$3:$B$3002,F$5,업무일지!$A$3:$A$3002,">="&DATE($B$3,1,1),업무일지!$A$3:$A$3002,"<="&DATE($B$3,12,31)),2)) | G9: =IF(OR($A9="",G$5=""),"",ROUND(SUMIFS(업무일지!$I$3:$I$3002,업무일지!$C$3:$C$3002,프로젝트목록!$A6,업무일지!$B$3:$B$3002,G$5,업무일지!$A$3:$A$3002,">="&DATE($B$3,1,1),업무일지!$A$3:$A$3002,"<="&DATE($B$3,12,31)),2)) | H9: =IF(OR($A9="",H$5=""),"",ROUND(SUMIFS(업무일지!$I$3:$I$3002,업무일지!$C$3:$C$3002,프로젝트목록!$A6,업무일지!$B$3:$B$3002,H$5,업무일지!$A$3:$A$3002,">="&DATE($B$3,1,1),업무일지!$A$3:$A$3002,"<="&DATE($B$3,12,31)),2)) | I9: =IF(OR($A9="",I$5=""),"",ROUND(SUMIFS(업무일지!$I$3:$I$3002,업무일지!$C$3:$C$3002,프로젝트목록!$A6,업무일지!$B$3:$B$3002,I$5,업무일지!$A$3:$A$3002,">="&DATE($B$3,1,1),업무일지!$A$3:$A$3002,"<="&DATE($B$3,12,31)),2)) | ... K9: =IF(OR($A9="",K$5=""),"",ROUND(SUMIFS(업무일지!$I$3:$I$3002,업무일지!$C$3:$C$3002,프로젝트목록!$A6,업무일지!$B$3:$B$3002,K$5,업무일지!$A$3:$A$3002,">="&DATE($B$3,1,1),업무일지!$A$3:$A$3002,"<="&DATE($B$3,12,31)),2)) | L9: =IF($A9="","",ROUND(SUM(B9:K9),2))
A10: =IF(프로젝트목록!$A7="","",프로젝트목록!$B7) | B10: =IF(OR($A10="",B$5=""),"",ROUND(SUMIFS(업무일지!$I$3:$I$3002,업무일지!$C$3:$C$3002,프로젝트목록!$A7,업무일지!$B$3:$B$3002,B$5,업무일지!$A$3:$A$3002,">="&DATE($B$3,1,1),업무일지!$A$3:$A$3002,"<="&DATE($B$3,12,31)),2)) | C10: =IF(OR($A10="",C$5=""),"",ROUND(SUMIFS(업무일지!$I$3:$I$3002,업무일지!$C$3:$C$3002,프로젝트목록!$A7,업무일지!$B$3:$B$3002,C$5,업무일지!$A$3:$A$3002,">="&DATE($B$3,1,1),업무일지!$A$3:$A$3002,"<="&DATE($B$3,12,31)),2)) | D10: =IF(OR($A10="",D$5=""),"",ROUND(SUMIFS(업무일지!$I$3:$I$3002,업무일지!$C$3:$C$3002,프로젝트목록!$A7,업무일지!$B$3:$B$3002,D$5,업무일지!$A$3:$A$3002,">="&DATE($B$3,1,1),업무일지!$A$3:$A$3002,"<="&DATE($B$3,12,31)),2)) | E10: =IF(OR($A10="",E$5=""),"",ROUND(SUMIFS(업무일지!$I$3:$I$3002,업무일지!$C$3:$C$3002,프로젝트목록!$A7,업무일지!$B$3:$B$3002,E$5,업무일지!$A$3:$A$3002,">="&DATE($B$3,1,1),업무일지!$A$3:$A$3002,"<="&DATE($B$3,12,31)),2)) | F10: =IF(OR($A10="",F$5=""),"",ROUND(SUMIFS(업무일지!$I$3:$I$3002,업무일지!$C$3:$C$3002,프로젝트목록!$A7,업무일지!$B$3:$B$3002,F$5,업무일지!$A$3:$A$3002,">="&DATE($B$3,1,1),업무일지!$A$3:$A$3002,"<="&DATE($B$3,12,31)),2)) | G10: =IF(OR($A10="",G$5=""),"",ROUND(SUMIFS(업무일지!$I$3:$I$3002,업무일지!$C$3:$C$3002,프로젝트목록!$A7,업무일지!$B$3:$B$3002,G$5,업무일지!$A$3:$A$3002,">="&DATE($B$3,1,1),업무일지!$A$3:$A$3002,"<="&DATE($B$3,12,31)),2)) | H10: =IF(OR($A10="",H$5=""),"",ROUND(SUMIFS(업무일지!$I$3:$I$3002,업무일지!$C$3:$C$3002,프로젝트목록!$A7,업무일지!$B$3:$B$3002,H$5,업무일지!$A$3:$A$3002,">="&DATE($B$3,1,1),업무일지!$A$3:$A$3002,"<="&DATE($B$3,12,31)),2)) | I10: =IF(OR($A10="",I$5=""),"",ROUND(SUMIFS(업무일지!$I$3:$I$3002,업무일지!$C$3:$C$3002,프로젝트목록!$A7,업무일지!$B$3:$B$3002,I$5,업무일지!$A$3:$A$3002,">="&DATE($B$3,1,1),업무일지!$A$3:$A$3002,"<="&DATE($B$3,12,31)),2)) | ... K10: =IF(OR($A10="",K$5=""),"",ROUND(SUMIFS(업무일지!$I$3:$I$3002,업무일지!$C$3:$C$3002,프로젝트목록!$A7,업무일지!$B$3:$B$3002,K$5,업무일지!$A$3:$A$3002,">="&DATE($B$3,1,1),업무일지!$A$3:$A$3002,"<="&DATE($B$3,12,31)),2)) | L10: =IF($A10="","",ROUND(SUM(B10:K10),2))
A11: =IF(프로젝트목록!$A8="","",프로젝트목록!$B8) | B11: =IF(OR($A11="",B$5=""),"",ROUND(SUMIFS(업무일지!$I$3:$I$3002,업무일지!$C$3:$C$3002,프로젝트목록!$A8,업무일지!$B$3:$B$3002,B$5,업무일지!$A$3:$A$3002,">="&DATE($B$3,1,1),업무일지!$A$3:$A$3002,"<="&DATE($B$3,12,31)),2)) | C11: =IF(OR($A11="",C$5=""),"",ROUND(SUMIFS(업무일지!$I$3:$I$3002,업무일지!$C$3:$C$3002,프로젝트목록!$A8,업무일지!$B$3:$B$3002,C$5,업무일지!$A$3:$A$3002,">="&DATE($B$3,1,1),업무일지!$A$3:$A$3002,"<="&DATE($B$3,12,31)),2)) | D11: =IF(OR($A11="",D$5=""),"",ROUND(SUMIFS(업무일지!$I$3:$I$3002,업무일지!$C$3:$C$3002,프로젝트목록!$A8,업무일지!$B$3:$B$3002,D$5,업무일지!$A$3:$A$3002,">="&DATE($B$3,1,1),업무일지!$A$3:$A$3002,"<="&DATE($B$3,12,31)),2)) | E11: =IF(OR($A11="",E$5=""),"",ROUND(SUMIFS(업무일지!$I$3:$I$3002,업무일지!$C$3:$C$3002,프로젝트목록!$A8,업무일지!$B$3:$B$3002,E$5,업무일지!$A$3:$A$3002,">="&DATE($B$3,1,1),업무일지!$A$3:$A$3002,"<="&DATE($B$3,12,31)),2)) | F11: =IF(OR($A11="",F$5=""),"",ROUND(SUMIFS(업무일지!$I$3:$I$3002,업무일지!$C$3:$C$3002,프로젝트목록!$A8,업무일지!$B$3:$B$3002,F$5,업무일지!$A$3:$A$3002,">="&DATE($B$3,1,1),업무일지!$A$3:$A$3002,"<="&DATE($B$3,12,31)),2)) | G11: =IF(OR($A11="",G$5=""),"",ROUND(SUMIFS(업무일지!$I$3:$I$3002,업무일지!$C$3:$C$3002,프로젝트목록!$A8,업무일지!$B$3:$B$3002,G$5,업무일지!$A$3:$A$3002,">="&DATE($B$3,1,1),업무일지!$A$3:$A$3002,"<="&DATE($B$3,12,31)),2)) | H11: =IF(OR($A11="",H$5=""),"",ROUND(SUMIFS(업무일지!$I$3:$I$3002,업무일지!$C$3:$C$3002,프로젝트목록!$A8,업무일지!$B$3:$B$3002,H$5,업무일지!$A$3:$A$3002,">="&DATE($B$3,1,1),업무일지!$A$3:$A$3002,"<="&DATE($B$3,12,31)),2)) | I11: =IF(OR($A11="",I$5=""),"",ROUND(SUMIFS(업무일지!$I$3:$I$3002,업무일지!$C$3:$C$3002,프로젝트목록!$A8,업무일지!$B$3:$B$3002,I$5,업무일지!$A$3:$A$3002,">="&DATE($B$3,1,1),업무일지!$A$3:$A$3002,"<="&DATE($B$3,12,31)),2)) | ... K11: =IF(OR($A11="",K$5=""),"",ROUND(SUMIFS(업무일지!$I$3:$I$3002,업무일지!$C$3:$C$3002,프로젝트목록!$A8,업무일지!$B$3:$B$3002,K$5,업무일지!$A$3:$A$3002,">="&DATE($B$3,1,1),업무일지!$A$3:$A$3002,"<="&DATE($B$3,12,31)),2)) | L11: =IF($A11="","",ROUND(SUM(B11:K11),2))
A12: =IF(프로젝트목록!$A9="","",프로젝트목록!$B9) | B12: =IF(OR($A12="",B$5=""),"",ROUND(SUMIFS(업무일지!$I$3:$I$3002,업무일지!$C$3:$C$3002,프로젝트목록!$A9,업무일지!$B$3:$B$3002,B$5,업무일지!$A$3:$A$3002,">="&DATE($B$3,1,1),업무일지!$A$3:$A$3002,"<="&DATE($B$3,12,31)),2)) | C12: =IF(OR($A12="",C$5=""),"",ROUND(SUMIFS(업무일지!$I$3:$I$3002,업무일지!$C$3:$C$3002,프로젝트목록!$A9,업무일지!$B$3:$B$3002,C$5,업무일지!$A$3:$A$3002,">="&DATE($B$3,1,1),업무일지!$A$3:$A$3002,"<="&DATE($B$3,12,31)),2)) | D12: =IF(OR($A12="",D$5=""),"",ROUND(SUMIFS(업무일지!$I$3:$I$3002,업무일지!$C$3:$C$3002,프로젝트목록!$A9,업무일지!$B$3:$B$3002,D$5,업무일지!$A$3:$A$3002,">="&DATE($B$3,1,1),업무일지!$A$3:$A$3002,"<="&DATE($B$3,12,31)),2)) | E12: =IF(OR($A12="",E$5=""),"",ROUND(SUMIFS(업무일지!$I$3:$I$3002,업무일지!$C$3:$C$3002,프로젝트목록!$A9,업무일지!$B$3:$B$3002,E$5,업무일지!$A$3:$A$3002,">="&DATE($B$3,1,1),업무일지!$A$3:$A$3002,"<="&DATE($B$3,12,31)),2)) | F12: =IF(OR($A12="",F$5=""),"",ROUND(SUMIFS(업무일지!$I$3:$I$3002,업무일지!$C$3:$C$3002,프로젝트목록!$A9,업무일지!$B$3:$B$3002,F$5,업무일지!$A$3:$A$3002,">="&DATE($B$3,1,1),업무일지!$A$3:$A$3002,"<="&DATE($B$3,12,31)),2)) | G12: =IF(OR($A12="",G$5=""),"",ROUND(SUMIFS(업무일지!$I$3:$I$3002,업무일지!$C$3:$C$3002,프로젝트목록!$A9,업무일지!$B$3:$B$3002,G$5,업무일지!$A$3:$A$3002,">="&DATE($B$3,1,1),업무일지!$A$3:$A$3002,"<="&DATE($B$3,12,31)),2)) | H12: =IF(OR($A12="",H$5=""),"",ROUND(SUMIFS(업무일지!$I$3:$I$3002,업무일지!$C$3:$C$3002,프로젝트목록!$A9,업무일지!$B$3:$B$3002,H$5,업무일지!$A$3:$A$3002,">="&DATE($B$3,1,1),업무일지!$A$3:$A$3002,"<="&DATE($B$3,12,31)),2)) | I12: =IF(OR($A12="",I$5=""),"",ROUND(SUMIFS(업무일지!$I$3:$I$3002,업무일지!$C$3:$C$3002,프로젝트목록!$A9,업무일지!$B$3:$B$3002,I$5,업무일지!$A$3:$A$3002,">="&DATE($B$3,1,1),업무일지!$A$3:$A$3002,"<="&DATE($B$3,12,31)),2)) | ... K12: =IF(OR($A12="",K$5=""),"",ROUND(SUMIFS(업무일지!$I$3:$I$3002,업무일지!$C$3:$C$3002,프로젝트목록!$A9,업무일지!$B$3:$B$3002,K$5,업무일지!$A$3:$A$3002,">="&DATE($B$3,1,1),업무일지!$A$3:$A$3002,"<="&DATE($B$3,12,31)),2)) | L12: =IF($A12="","",ROUND(SUM(B12:K12),2))
A13: =IF(프로젝트목록!$A10="","",프로젝트목록!$B10) | B13: =IF(OR($A13="",B$5=""),"",ROUND(SUMIFS(업무일지!$I$3:$I$3002,업무일지!$C$3:$C$3002,프로젝트목록!$A10,업무일지!$B$3:$B$3002,B$5,업무일지!$A$3:$A$3002,">="&DATE($B$3,1,1),업무일지!$A$3:$A$3002,"<="&DATE($B$3,12,31)),2)) | C13: =IF(OR($A13="",C$5=""),"",ROUND(SUMIFS(업무일지!$I$3:$I$3002,업무일지!$C$3:$C$3002,프로젝트목록!$A10,업무일지!$B$3:$B$3002,C$5,업무일지!$A$3:$A$3002,">="&DATE($B$3,1,1),업무일지!$A$3:$A$3002,"<="&DATE($B$3,12,31)),2)) | D13: =IF(OR($A13="",D$5=""),"",ROUND(SUMIFS(업무일지!$I$3:$I$3002,업무일지!$C$3:$C$3002,프로젝트목록!$A10,업무일지!$B$3:$B$3002,D$5,업무일지!$A$3:$A$3002,">="&DATE($B$3,1,1),업무일지!$A$3:$A$3002,"<="&DATE($B$3,12,31)),2)) | E13: =IF(OR($A13="",E$5=""),"",ROUND(SUMIFS(업무일지!$I$3:$I$3002,업무일지!$C$3:$C$3002,프로젝트목록!$A10,업무일지!$B$3:$B$3002,E$5,업무일지!$A$3:$A$3002,">="&DATE($B$3,1,1),업무일지!$A$3:$A$3002,"<="&DATE($B$3,12,31)),2)) | F13: =IF(OR($A13="",F$5=""),"",ROUND(SUMIFS(업무일지!$I$3:$I$3002,업무일지!$C$3:$C$3002,프로젝트목록!$A10,업무일지!$B$3:$B$3002,F$5,업무일지!$A$3:$A$3002,">="&DATE($B$3,1,1),업무일지!$A$3:$A$3002,"<="&DATE($B$3,12,31)),2)) | G13: =IF(OR($A13="",G$5=""),"",ROUND(SUMIFS(업무일지!$I$3:$I$3002,업무일지!$C$3:$C$3002,프로젝트목록!$A10,업무일지!$B$3:$B$3002,G$5,업무일지!$A$3:$A$3002,">="&DATE($B$3,1,1),업무일지!$A$3:$A$3002,"<="&DATE($B$3,12,31)),2)) | H13: =IF(OR($A13="",H$5=""),"",ROUND(SUMIFS(업무일지!$I$3:$I$3002,업무일지!$C$3:$C$3002,프로젝트목록!$A10,업무일지!$B$3:$B$3002,H$5,업무일지!$A$3:$A$3002,">="&DATE($B$3,1,1),업무일지!$A$3:$A$3002,"<="&DATE($B$3,12,31)),2)) | I13: =IF(OR($A13="",I$5=""),"",ROUND(SUMIFS(업무일지!$I$3:$I$3002,업무일지!$C$3:$C$3002,프로젝트목록!$A10,업무일지!$B$3:$B$3002,I$5,업무일지!$A$3:$A$3002,">="&DATE($B$3,1,1),업무일지!$A$3:$A$3002,"<="&DATE($B$3,12,31)),2)) | ... K13: =IF(OR($A13="",K$5=""),"",ROUND(SUMIFS(업무일지!$I$3:$I$3002,업무일지!$C$3:$C$3002,프로젝트목록!$A10,업무일지!$B$3:$B$3002,K$5,업무일지!$A$3:$A$3002,">="&DATE($B$3,1,1),업무일지!$A$3:$A$3002,"<="&DATE($B$3,12,31)),2)) | L13: =IF($A13="","",ROUND(SUM(B13:K13),2))
A14: =IF(프로젝트목록!$A11="","",프로젝트목록!$B11) | B14: =IF(OR($A14="",B$5=""),"",ROUND(SUMIFS(업무일지!$I$3:$I$3002,업무일지!$C$3:$C$3002,프로젝트목록!$A11,업무일지!$B$3:$B$3002,B$5,업무일지!$A$3:$A$3002,">="&DATE($B$3,1,1),업무일지!$A$3:$A$3002,"<="&DATE($B$3,12,31)),2)) | C14: =IF(OR($A14="",C$5=""),"",ROUND(SUMIFS(업무일지!$I$3:$I$3002,업무일지!$C$3:$C$3002,프로젝트목록!$A11,업무일지!$B$3:$B$3002,C$5,업무일지!$A$3:$A$3002,">="&DATE($B$3,1,1),업무일지!$A$3:$A$3002,"<="&DATE($B$3,12,31)),2)) | D14: =IF(OR($A14="",D$5=""),"",ROUND(SUMIFS(업무일지!$I$3:$I$3002,업무일지!$C$3:$C$3002,프로젝트목록!$A11,업무일지!$B$3:$B$3002,D$5,업무일지!$A$3:$A$3002,">="&DATE($B$3,1,1),업무일지!$A$3:$A$3002,"<="&DATE($B$3,12,31)),2)) | E14: =IF(OR($A14="",E$5=""),"",ROUND(SUMIFS(업무일지!$I$3:$I$3002,업무일지!$C$3:$C$3002,프로젝트목록!$A11,업무일지!$B$3:$B$3002,E$5,업무일지!$A$3:$A$3002,">="&DATE($B$3,1,1),업무일지!$A$3:$A$3002,"<="&DATE($B$3,12,31)),2)) | F14: =IF(OR($A14="",F$5=""),"",ROUND(SUMIFS(업무일지!$I$3:$I$3002,업무일지!$C$3:$C$3002,프로젝트목록!$A11,업무일지!$B$3:$B$3002,F$5,업무일지!$A$3:$A$3002,">="&DATE($B$3,1,1),업무일지!$A$3:$A$3002,"<="&DATE($B$3,12,31)),2)) | G14: =IF(OR($A14="",G$5=""),"",ROUND(SUMIFS(업무일지!$I$3:$I$3002,업무일지!$C$3:$C$3002,프로젝트목록!$A11,업무일지!$B$3:$B$3002,G$5,업무일지!$A$3:$A$3002,">="&DATE($B$3,1,1),업무일지!$A$3:$A$3002,"<="&DATE($B$3,12,31)),2)) | H14: =IF(OR($A14="",H$5=""),"",ROUND(SUMIFS(업무일지!$I$3:$I$3002,업무일지!$C$3:$C$3002,프로젝트목록!$A11,업무일지!$B$3:$B$3002,H$5,업무일지!$A$3:$A$3002,">="&DATE($B$3,1,1),업무일지!$A$3:$A$3002,"<="&DATE($B$3,12,31)),2)) | I14: =IF(OR($A14="",I$5=""),"",ROUND(SUMIFS(업무일지!$I$3:$I$3002,업무일지!$C$3:$C$3002,프로젝트목록!$A11,업무일지!$B$3:$B$3002,I$5,업무일지!$A$3:$A$3002,">="&DATE($B$3,1,1),업무일지!$A$3:$A$3002,"<="&DATE($B$3,12,31)),2)) | ... K14: =IF(OR($A14="",K$5=""),"",ROUND(SUMIFS(업무일지!$I$3:$I$3002,업무일지!$C$3:$C$3002,프로젝트목록!$A11,업무일지!$B$3:$B$3002,K$5,업무일지!$A$3:$A$3002,">="&DATE($B$3,1,1),업무일지!$A$3:$A$3002,"<="&DATE($B$3,12,31)),2)) | L14: =IF($A14="","",ROUND(SUM(B14:K14),2))
A15: =IF(프로젝트목록!$A12="","",프로젝트목록!$B12) | B15: =IF(OR($A15="",B$5=""),"",ROUND(SUMIFS(업무일지!$I$3:$I$3002,업무일지!$C$3:$C$3002,프로젝트목록!$A12,업무일지!$B$3:$B$3002,B$5,업무일지!$A$3:$A$3002,">="&DATE($B$3,1,1),업무일지!$A$3:$A$3002,"<="&DATE($B$3,12,31)),2)) | C15: =IF(OR($A15="",C$5=""),"",ROUND(SUMIFS(업무일지!$I$3:$I$3002,업무일지!$C$3:$C$3002,프로젝트목록!$A12,업무일지!$B$3:$B$3002,C$5,업무일지!$A$3:$A$3002,">="&DATE($B$3,1,1),업무일지!$A$3:$A$3002,"<="&DATE($B$3,12,31)),2)) | D15: =IF(OR($A15="",D$5=""),"",ROUND(SUMIFS(업무일지!$I$3:$I$3002,업무일지!$C$3:$C$3002,프로젝트목록!$A12,업무일지!$B$3:$B$3002,D$5,업무일지!$A$3:$A$3002,">="&DATE($B$3,1,1),업무일지!$A$3:$A$3002,"<="&DATE($B$3,12,31)),2)) | E15: =IF(OR($A15="",E$5=""),"",ROUND(SUMIFS(업무일지!$I$3:$I$3002,업무일지!$C$3:$C$3002,프로젝트목록!$A12,업무일지!$B$3:$B$3002,E$5,업무일지!$A$3:$A$3002,">="&DATE($B$3,1,1),업무일지!$A$3:$A$3002,"<="&DATE($B$3,12,31)),2)) | F15: =IF(OR($A15="",F$5=""),"",ROUND(SUMIFS(업무일지!$I$3:$I$3002,업무일지!$C$3:$C$3002,프로젝트목록!$A12,업무일지!$B$3:$B$3002,F$5,업무일지!$A$3:$A$3002,">="&DATE($B$3,1,1),업무일지!$A$3:$A$3002,"<="&DATE($B$3,12,31)),2)) | G15: =IF(OR($A15="",G$5=""),"",ROUND(SUMIFS(업무일지!$I$3:$I$3002,업무일지!$C$3:$C$3002,프로젝트목록!$A12,업무일지!$B$3:$B$3002,G$5,업무일지!$A$3:$A$3002,">="&DATE($B$3,1,1),업무일지!$A$3:$A$3002,"<="&DATE($B$3,12,31)),2)) | H15: =IF(OR($A15="",H$5=""),"",ROUND(SUMIFS(업무일지!$I$3:$I$3002,업무일지!$C$3:$C$3002,프로젝트목록!$A12,업무일지!$B$3:$B$3002,H$5,업무일지!$A$3:$A$3002,">="&DATE($B$3,1,1),업무일지!$A$3:$A$3002,"<="&DATE($B$3,12,31)),2)) | I15: =IF(OR($A15="",I$5=""),"",ROUND(SUMIFS(업무일지!$I$3:$I$3002,업무일지!$C$3:$C$3002,프로젝트목록!$A12,업무일지!$B$3:$B$3002,I$5,업무일지!$A$3:$A$3002,">="&DATE($B$3,1,1),업무일지!$A$3:$A$3002,"<="&DATE($B$3,12,31)),2)) | ... K15: =IF(OR($A15="",K$5=""),"",ROUND(SUMIFS(업무일지!$I$3:$I$3002,업무일지!$C$3:$C$3002,프로젝트목록!$A12,업무일지!$B$3:$B$3002,K$5,업무일지!$A$3:$A$3002,">="&DATE($B$3,1,1),업무일지!$A$3:$A$3002,"<="&DATE($B$3,12,31)),2)) | L15: =IF($A15="","",ROUND(SUM(B15:K15),2))
A16: =IF(프로젝트목록!$A13="","",프로젝트목록!$B13) | B16: =IF(OR($A16="",B$5=""),"",ROUND(SUMIFS(업무일지!$I$3:$I$3002,업무일지!$C$3:$C$3002,프로젝트목록!$A13,업무일지!$B$3:$B$3002,B$5,업무일지!$A$3:$A$3002,">="&DATE($B$3,1,1),업무일지!$A$3:$A$3002,"<="&DATE($B$3,12,31)),2)) | C16: =IF(OR($A16="",C$5=""),"",ROUND(SUMIFS(업무일지!$I$3:$I$3002,업무일지!$C$3:$C$3002,프로젝트목록!$A13,업무일지!$B$3:$B$3002,C$5,업무일지!$A$3:$A$3002,">="&DATE($B$3,1,1),업무일지!$A$3:$A$3002,"<="&DATE($B$3,12,31)),2)) | D16: =IF(OR($A16="",D$5=""),"",ROUND(SUMIFS(업무일지!$I$3:$I$3002,업무일지!$C$3:$C$3002,프로젝트목록!$A13,업무일지!$B$3:$B$3002,D$5,업무일지!$A$3:$A$3002,">="&DATE($B$3,1,1),업무일지!$A$3:$A$3002,"<="&DATE($B$3,12,31)),2)) | E16: =IF(OR($A16="",E$5=""),"",ROUND(SUMIFS(업무일지!$I$3:$I$3002,업무일지!$C$3:$C$3002,프로젝트목록!$A13,업무일지!$B$3:$B$3002,E$5,업무일지!$A$3:$A$3002,">="&DATE($B$3,1,1),업무일지!$A$3:$A$3002,"<="&DATE($B$3,12,31)),2)) | F16: =IF(OR($A16="",F$5=""),"",ROUND(SUMIFS(업무일지!$I$3:$I$3002,업무일지!$C$3:$C$3002,프로젝트목록!$A13,업무일지!$B$3:$B$3002,F$5,업무일지!$A$3:$A$3002,">="&DATE($B$3,1,1),업무일지!$A$3:$A$3002,"<="&DATE($B$3,12,31)),2)) | G16: =IF(OR($A16="",G$5=""),"",ROUND(SUMIFS(업무일지!$I$3:$I$3002,업무일지!$C$3:$C$3002,프로젝트목록!$A13,업무일지!$B$3:$B$3002,G$5,업무일지!$A$3:$A$3002,">="&DATE($B$3,1,1),업무일지!$A$3:$A$3002,"<="&DATE($B$3,12,31)),2)) | H16: =IF(OR($A16="",H$5=""),"",ROUND(SUMIFS(업무일지!$I$3:$I$3002,업무일지!$C$3:$C$3002,프로젝트목록!$A13,업무일지!$B$3:$B$3002,H$5,업무일지!$A$3:$A$3002,">="&DATE($B$3,1,1),업무일지!$A$3:$A$3002,"<="&DATE($B$3,12,31)),2)) | I16: =IF(OR($A16="",I$5=""),"",ROUND(SUMIFS(업무일지!$I$3:$I$3002,업무일지!$C$3:$C$3002,프로젝트목록!$A13,업무일지!$B$3:$B$3002,I$5,업무일지!$A$3:$A$3002,">="&DATE($B$3,1,1),업무일지!$A$3:$A$3002,"<="&DATE($B$3,12,31)),2)) | ... K16: =IF(OR($A16="",K$5=""),"",ROUND(SUMIFS(업무일지!$I$3:$I$3002,업무일지!$C$3:$C$3002,프로젝트목록!$A13,업무일지!$B$3:$B$3002,K$5,업무일지!$A$3:$A$3002,">="&DATE($B$3,1,1),업무일지!$A$3:$A$3002,"<="&DATE($B$3,12,31)),2)) | L16: =IF($A16="","",ROUND(SUM(B16:K16),2))
A17: =IF(프로젝트목록!$A14="","",프로젝트목록!$B14) | B17: =IF(OR($A17="",B$5=""),"",ROUND(SUMIFS(업무일지!$I$3:$I$3002,업무일지!$C$3:$C$3002,프로젝트목록!$A14,업무일지!$B$3:$B$3002,B$5,업무일지!$A$3:$A$3002,">="&DATE($B$3,1,1),업무일지!$A$3:$A$3002,"<="&DATE($B$3,12,31)),2)) | C17: =IF(OR($A17="",C$5=""),"",ROUND(SUMIFS(업무일지!$I$3:$I$3002,업무일지!$C$3:$C$3002,프로젝트목록!$A14,업무일지!$B$3:$B$3002,C$5,업무일지!$A$3:$A$3002,">="&DATE($B$3,1,1),업무일지!$A$3:$A$3002,"<="&DATE($B$3,12,31)),2)) | D17: =IF(OR($A17="",D$5=""),"",ROUND(SUMIFS(업무일지!$I$3:$I$3002,업무일지!$C$3:$C$3002,프로젝트목록!$A14,업무일지!$B$3:$B$3002,D$5,업무일지!$A$3:$A$3002,">="&DATE($B$3,1,1),업무일지!$A$3:$A$3002,"<="&DATE($B$3,12,31)),2)) | E17: =IF(OR($A17="",E$5=""),"",ROUND(SUMIFS(업무일지!$I$3:$I$3002,업무일지!$C$3:$C$3002,프로젝트목록!$A14,업무일지!$B$3:$B$3002,E$5,업무일지!$A$3:$A$3002,">="&DATE($B$3,1,1),업무일지!$A$3:$A$3002,"<="&DATE($B$3,12,31)),2)) | F17: =IF(OR($A17="",F$5=""),"",ROUND(SUMIFS(업무일지!$I$3:$I$3002,업무일지!$C$3:$C$3002,프로젝트목록!$A14,업무일지!$B$3:$B$3002,F$5,업무일지!$A$3:$A$3002,">="&DATE($B$3,1,1),업무일지!$A$3:$A$3002,"<="&DATE($B$3,12,31)),2)) | G17: =IF(OR($A17="",G$5=""),"",ROUND(SUMIFS(업무일지!$I$3:$I$3002,업무일지!$C$3:$C$3002,프로젝트목록!$A14,업무일지!$B$3:$B$3002,G$5,업무일지!$A$3:$A$3002,">="&DATE($B$3,1,1),업무일지!$A$3:$A$3002,"<="&DATE($B$3,12,31)),2)) | H17: =IF(OR($A17="",H$5=""),"",ROUND(SUMIFS(업무일지!$I$3:$I$3002,업무일지!$C$3:$C$3002,프로젝트목록!$A14,업무일지!$B$3:$B$3002,H$5,업무일지!$A$3:$A$3002,">="&DATE($B$3,1,1),업무일지!$A$3:$A$3002,"<="&DATE($B$3,12,31)),2)) | I17: =IF(OR($A17="",I$5=""),"",ROUND(SUMIFS(업무일지!$I$3:$I$3002,업무일지!$C$3:$C$3002,프로젝트목록!$A14,업무일지!$B$3:$B$3002,I$5,업무일지!$A$3:$A$3002,">="&DATE($B$3,1,1),업무일지!$A$3:$A$3002,"<="&DATE($B$3,12,31)),2)) | ... K17: =IF(OR($A17="",K$5=""),"",ROUND(SUMIFS(업무일지!$I$3:$I$3002,업무일지!$C$3:$C$3002,프로젝트목록!$A14,업무일지!$B$3:$B$3002,K$5,업무일지!$A$3:$A$3002,">="&DATE($B$3,1,1),업무일지!$A$3:$A$3002,"<="&DATE($B$3,12,31)),2)) | L17: =IF($A17="","",ROUND(SUM(B17:K17),2))
